Workbook
Name ADM_Day_Select: Parameters_Public!C8
Name BaseAid_per_ADM: Parameters_Public!C18
Name Capex_ArtsHub: Parameters_Public!C28
Name Capex_in_MO_Toggle: Parameters_Public!C30
Name Capex_InnovHub: Parameters_Public!C29
Name Echo_ADM0: Parameters_Public!C10
Name EchoFixed_FY25_Total: Site_Fixed!C8
Name M_O_per_ADM_Audited: Parameters_Public!C14
Name Override_per_ADM_proxy: Parameters_Public!C19
Name Override_Percent: Parameters_Public!C17
Name Override_Toggle: Parameters_Public!C20
Name Pima_ADM0: Parameters_Public!C11
Name PimaFixed_FY25_Total: Site_Fixed!C15
Name TI_in_MO_Toggle: Parameters_Public!C26
Name TI_per_Site: Parameters_Public!C27

Sheet Workbook_Purpose_Overview

Sheet Summary_Figures
A1: Base (for comparison) | B1: H_StatusQuo_Decline | M1: Chart title
M2: ="Change in ops net $ by scenario compared to "&B1&" (Positive = savings)" -> Change in ops net $ by scenario compared to H_StatusQuo_Decline (Positive = savings)
A4: Scenario | B4: One-time Capital (FY26) | C4: NET2026 | D4: NET2028 | E4: NET2030 | F4: AVG5 | G4: DISP | H4: SRV2030 | I4: Δ vs Base (FY2030 Net) | J4: Δ vs Base (5-yr Avg Net)
A5: D_CUSTOM1 | B5: =SUMIFS(Capital_Summary!$H$4:$H$83, Capital_Summary!$A$4:$A$83, A5, Capital_Summary!$B$4:$B$83, "FY2026") -> 0 | C5: =SUMIFS(MultiYear_ProForma!$AF$2:$AF$66, MultiYear_ProForma!$B$2:$B$66, A5, MultiYear_ProForma!$C$2:$C$66, "FY2026") -> -459335.03 | D5: =SUMIFS(MultiYear_ProForma!$AF$2:$AF$66, MultiYear_ProForma!$B$2:$B$66, A5, MultiYear_ProForma!$C$2:$C$66, "FY2028") -> -482588.87 | E5: =SUMIFS(MultiYear_ProForma!$AF$2:$AF$66, MultiYear_ProForma!$B$2:$B$66, A5, MultiYear_ProForma!$C$2:$C$66, "FY2030") -> -507019.93 | F5: =(SUMIFS(MultiYear_ProForma!$AF$2:$AF$66, MultiYear_ProForma!$B$2:$B$66, A5, MultiYear_ProForma!$C$2:$C$66, "FY2026")+SUMIFS(MultiYear_ProForma!$AF$2:$AF$66, MultiYear_ProForma!$B$2:$B$66, A5, MultiYear_ProForma!$C$2:$C$66, "FY2027")+SUMIFS(MultiYear_ProForma!$AF$2:$AF$66, MultiYear_ProForma!$B$2:$B$66, A5, MultiYear_ProForma!$C$2:$C$66, "FY2028")+SUMIFS(MultiYear_ProForma!$AF$2:$AF$66, MultiYear_ProForma!$B$2:$B$66, A5, MultiYear_ProForma!$C$2:$C$66, "FY2029")+SUMIFS(MultiYear_ProForma!$AF$2:$AF$66, MultiYear_ProForma!$B$2:$B$66, A5, MultiYear_ProForma!$C$2:$C$66, "FY2030"))/5 -> -482883.16 | G5: =SUMIFS(MultiYear_ProForma!$N$2:$N$66, MultiYear_ProForma!$B$2:$B$66, A5, MultiYear_ProForma!$C$2:$C$66, "FY2026") -> 0 | H5: =SUMIFS(MultiYear_ProForma!$AC$2:$AC$66, MultiYear_ProForma!$B$2:$B$66, A5, MultiYear_ProForma!$C$2:$C$66, "FY2030") -> 553 | I5: =E5-(VLOOKUP($B$1,$A$5:$F$17,5, 0)) -> 217760.01 | J5: =F5-(VLOOKUP($B$1,$A$5:$H$17,6, 0)) -> 107303.43
A6: E_StatusQuo_Targets | B6: =SUMIFS(Capital_Summary!$H$4:$H$83, Capital_Summary!$A$4:$A$83, A6, Capital_Summary!$B$4:$B$83, "FY2026") -> 0 | C6: =SUMIFS(MultiYear_ProForma!$AF$2:$AF$66, MultiYear_ProForma!$B$2:$B$66, A6, MultiYear_ProForma!$C$2:$C$66, "FY2030") -> 703305.39 | D6: =SUMIFS(MultiYear_ProForma!$AF$2:$AF$66, MultiYear_ProForma!$B$2:$B$66, A6, MultiYear_ProForma!$C$2:$C$66, "FY2028") -> 669416.19 | E6: =SUMIFS(MultiYear_ProForma!$AF$2:$AF$66, MultiYear_ProForma!$B$2:$B$66, A6, MultiYear_ProForma!$C$2:$C$66, "FY2030") -> 703305.39 | F6: =(SUMIFS(MultiYear_ProForma!$AF$2:$AF$66, MultiYear_ProForma!$B$2:$B$66, A6, MultiYear_ProForma!$C$2:$C$66, "FY2026")+SUMIFS(MultiYear_ProForma!$AF$2:$AF$66, MultiYear_ProForma!$B$2:$B$66, A6, MultiYear_ProForma!$C$2:$C$66, "FY2027")+SUMIFS(MultiYear_ProForma!$AF$2:$AF$66, MultiYear_ProForma!$B$2:$B$66, A6, MultiYear_ProForma!$C$2:$C$66, "FY2028")+SUMIFS(MultiYear_ProForma!$AF$2:$AF$66, MultiYear_ProForma!$B$2:$B$66, A6, MultiYear_ProForma!$C$2:$C$66, "FY2029")+SUMIFS(MultiYear_ProForma!$AF$2:$AF$66, MultiYear_ProForma!$B$2:$B$66, A6, MultiYear_ProForma!$C$2:$C$66, "FY2030"))/5 -> 448697.93 | G6: =SUMIFS(MultiYear_ProForma!$N$2:$N$66, MultiYear_ProForma!$B$2:$B$66, A6, MultiYear_ProForma!$C$2:$C$66, "FY2026") -> 0 | H6: =SUMIFS(MultiYear_ProForma!$AC$2:$AC$66, MultiYear_ProForma!$B$2:$B$66, A6, MultiYear_ProForma!$C$2:$C$66, "FY2030") -> 653 | I6: =E6-(VLOOKUP($B$1,$A$5:$F$17,5, 0)) -> 1428085.3 | J6: =F6-(VLOOKUP($B$1,$A$5:$H$17,6, 0)) -> 1038884.5
A7: F_CoLocation_Echo_Targets | B7: =SUMIFS(Capital_Summary!$H$4:$H$83, Capital_Summary!$A$4:$A$83, A7, Capital_Summary!$B$4:$B$83, "FY2026") -> 0 | C7: =SUMIFS(MultiYear_ProForma!$AF$2:$AF$66, MultiYear_ProForma!$B$2:$B$66, A7, MultiYear_ProForma!$C$2:$C$66, "FY2030") -> 1063311.3 | D7: =SUMIFS(MultiYear_ProForma!$AF$2:$AF$66, MultiYear_ProForma!$B$2:$B$66, A7, MultiYear_ProForma!$C$2:$C$66, "FY2028") -> 1012075 | E7: =SUMIFS(MultiYear_ProForma!$AF$2:$AF$66, MultiYear_ProForma!$B$2:$B$66, A7, MultiYear_ProForma!$C$2:$C$66, "FY2030") -> 1063311.3 | F7: =(SUMIFS(MultiYear_ProForma!$AF$2:$AF$66, MultiYear_ProForma!$B$2:$B$66, A7, MultiYear_ProForma!$C$2:$C$66, "FY2026")+SUMIFS(MultiYear_ProForma!$AF$2:$AF$66, MultiYear_ProForma!$B$2:$B$66, A7, MultiYear_ProForma!$C$2:$C$66, "FY2027")+SUMIFS(MultiYear_ProForma!$AF$2:$AF$66, MultiYear_ProForma!$B$2:$B$66, A7, MultiYear_ProForma!$C$2:$C$66, "FY2028")+SUMIFS(MultiYear_ProForma!$AF$2:$AF$66, MultiYear_ProForma!$B$2:$B$66, A7, MultiYear_ProForma!$C$2:$C$66, "FY2029")+SUMIFS(MultiYear_ProForma!$AF$2:$AF$66, MultiYear_ProForma!$B$2:$B$66, A7, MultiYear_ProForma!$C$2:$C$66, "FY2030"))/5 -> 791565.74 | G7: =SUMIFS(MultiYear_ProForma!$N$2:$N$66, MultiYear_ProForma!$B$2:$B$66, A7, MultiYear_ProForma!$C$2:$C$66, "FY2026") -> 0 | H7: =SUMIFS(MultiYear_ProForma!$AC$2:$AC$66, MultiYear_ProForma!$B$2:$B$66, A7, MultiYear_ProForma!$C$2:$C$66, "FY2030") -> 653 | I7: =E7-(VLOOKUP($B$1,$A$5:$F$17,5, 0)) -> 1788091.3 | J7: =F7-(VLOOKUP($B$1,$A$5:$H$17,6, 0)) -> 1381752.3
A8: D_Grow_Both_Targets | B8: =SUMIFS(Capital_Summary!$H$4:$H$83, Capital_Summary!$A$4:$A$83, A8, Capital_Summary!$B$4:$B$83, "FY2026") -> 1200000 | C8: =SUMIFS(MultiYear_ProForma!$AF$2:$AF$66, MultiYear_ProForma!$B$2:$B$66, A8, MultiYear_ProForma!$C$2:$C$66, "FY2030") -> 1913630.7 | D8: =SUMIFS(MultiYear_ProForma!$AF$2:$AF$66, MultiYear_ProForma!$B$2:$B$66, A8, MultiYear_ProForma!$C$2:$C$66, "FY2028") -> 1821421.3 | E8: =SUMIFS(MultiYear_ProForma!$AF$2:$AF$66, MultiYear_ProForma!$B$2:$B$66, A8, MultiYear_ProForma!$C$2:$C$66, "FY2030") -> 1913630.7 | F8: =(SUMIFS(MultiYear_ProForma!$AF$2:$AF$66, MultiYear_ProForma!$B$2:$B$66, A8, MultiYear_ProForma!$C$2:$C$66, "FY2026")+SUMIFS(MultiYear_ProForma!$AF$2:$AF$66, MultiYear_ProForma!$B$2:$B$66, A8, MultiYear_ProForma!$C$2:$C$66, "FY2027")+SUMIFS(MultiYear_ProForma!$AF$2:$AF$66, MultiYear_ProForma!$B$2:$B$66, A8, MultiYear_ProForma!$C$2:$C$66, "FY2028")+SUMIFS(MultiYear_ProForma!$AF$2:$AF$66, MultiYear_ProForma!$B$2:$B$66, A8, MultiYear_ProForma!$C$2:$C$66, "FY2029")+SUMIFS(MultiYear_ProForma!$AF$2:$AF$66, MultiYear_ProForma!$B$2:$B$66, A8, MultiYear_ProForma!$C$2:$C$66, "FY2030"))/5 -> 1380279 | G8: =SUMIFS(MultiYear_ProForma!$N$2:$N$66, MultiYear_ProForma!$B$2:$B$66, A8, MultiYear_ProForma!$C$2:$C$66, "FY2026") -> 0 | H8: =SUMIFS(MultiYear_ProForma!$AC$2:$AC$66, MultiYear_ProForma!$B$2:$B$66, A8, MultiYear_ProForma!$C$2:$C$66, "FY2030") -> 753 | I8: =E8-(VLOOKUP($B$1,$A$5:$F$17,5, 0)) -> 2638410.6 | J8: =F8-(VLOOKUP($B$1,$A$5:$H$17,6, 0)) -> 1970465.6
A9: D_CUSTOM2 | B9: =SUMIFS(Capital_Summary!$H$4:$H$83, Capital_Summary!$A$4:$A$83, A9, Capital_Summary!$B$4:$B$83, "FY2026") -> 0 | C9: =SUMIFS(MultiYear_ProForma!$AF$2:$AF$66, MultiYear_ProForma!$B$2:$B$66, A9, MultiYear_ProForma!$C$2:$C$66, "FY2030") -> -507019.93 | D9: =SUMIFS(MultiYear_ProForma!$AF$2:$AF$66, MultiYear_ProForma!$B$2:$B$66, A9, MultiYear_ProForma!$C$2:$C$66, "FY2028") -> -482588.87 | E9: =SUMIFS(MultiYear_ProForma!$AF$2:$AF$66, MultiYear_ProForma!$B$2:$B$66, A9, MultiYear_ProForma!$C$2:$C$66, "FY2030") -> -507019.93 | F9: =(SUMIFS(MultiYear_ProForma!$AF$2:$AF$66, MultiYear_ProForma!$B$2:$B$66, A9, MultiYear_ProForma!$C$2:$C$66, "FY2026")+SUMIFS(MultiYear_ProForma!$AF$2:$AF$66, MultiYear_ProForma!$B$2:$B$66, A9, MultiYear_ProForma!$C$2:$C$66, "FY2027")+SUMIFS(MultiYear_ProForma!$AF$2:$AF$66, MultiYear_ProForma!$B$2:$B$66, A9, MultiYear_ProForma!$C$2:$C$66, "FY2028")+SUMIFS(MultiYear_ProForma!$AF$2:$AF$66, MultiYear_ProForma!$B$2:$B$66, A9, MultiYear_ProForma!$C$2:$C$66, "FY2029")+SUMIFS(MultiYear_ProForma!$AF$2:$AF$66, MultiYear_ProForma!$B$2:$B$66, A9, MultiYear_ProForma!$C$2:$C$66, "FY2030"))/5 -> -482883.16 | G9: =SUMIFS(MultiYear_ProForma!$N$2:$N$66, MultiYear_ProForma!$B$2:$B$66, A9, MultiYear_ProForma!$C$2:$C$66, "FY2026") -> 0 | H9: =SUMIFS(MultiYear_ProForma!$AC$2:$AC$66, MultiYear_ProForma!$B$2:$B$66, A9, MultiYear_ProForma!$C$2:$C$66, "FY2030") -> 553 | I9: =E9-(VLOOKUP($B$1,$A$5:$F$17,5, 0)) -> 217760.01 | J9: =F9-(VLOOKUP($B$1,$A$5:$H$17,6, 0)) -> 107303.43
A10: G_EchoGHubRamp_PimaTargets | B10: =SUMIFS(Capital_Summary!$H$4:$H$83, Capital_Summary!$A$4:$A$83, A10, Capital_Summary!$B$4:$B$83, "FY2026") -> 0 | C10: =SUMIFS(MultiYear_ProForma!$AF$2:$AF$66, MultiYear_ProForma!$B$2:$B$66, A10, MultiYear_ProForma!$C$2:$C$66, "FY2030") -> 1308468 | D10: =SUMIFS(MultiYear_ProForma!$AF$2:$AF$66, MultiYear_ProForma!$B$2:$B$66, A10, MultiYear_ProForma!$C$2:$C$66, "FY2028") -> 1245418.7 | E10: =SUMIFS(MultiYear_ProForma!$AF$2:$AF$66, MultiYear_ProForma!$B$2:$B$66, A10, MultiYear_ProForma!$C$2:$C$66, "FY2030") -> 1308468 | F10: =(SUMIFS(MultiYear_ProForma!$AF$2:$AF$66, MultiYear_ProForma!$B$2:$B$66, A10, MultiYear_ProForma!$C$2:$C$66, "FY2026")+SUMIFS(MultiYear_ProForma!$AF$2:$AF$66, MultiYear_ProForma!$B$2:$B$66, A10, MultiYear_ProForma!$C$2:$C$66, "FY2027")+SUMIFS(MultiYear_ProForma!$AF$2:$AF$66, MultiYear_ProForma!$B$2:$B$66, A10, MultiYear_ProForma!$C$2:$C$66, "FY2028")+SUMIFS(MultiYear_ProForma!$AF$2:$AF$66, MultiYear_ProForma!$B$2:$B$66, A10, MultiYear_ProForma!$C$2:$C$66, "FY2029")+SUMIFS(MultiYear_ProForma!$AF$2:$AF$66, MultiYear_ProForma!$B$2:$B$66, A10, MultiYear_ProForma!$C$2:$C$66, "FY2030"))/5 -> 914488.48 | G10: =SUMIFS(MultiYear_ProForma!$N$2:$N$66, MultiYear_ProForma!$B$2:$B$66, A10, MultiYear_ProForma!$C$2:$C$66, "FY2026") -> 0 | H10: =SUMIFS(MultiYear_ProForma!$AC$2:$AC$66, MultiYear_ProForma!$B$2:$B$66, A10, MultiYear_ProForma!$C$2:$C$66, "FY2030") -> 703 | I10: =E10-(VLOOKUP($B$1,$A$5:$F$17,5, 0)) -> 2033248 | J10: =F10-(VLOOKUP($B$1,$A$5:$H$17,6, 0)) -> 1504675.1
A11: A_Repurpose_Both_lease | B11: =SUMIFS(Capital_Summary!$H$4:$H$83, Capital_Summary!$A$4:$A$83, A11, Capital_Summary!$B$4:$B$83, "FY2026") -> 2400000 | C11: =SUMIFS(MultiYear_ProForma!$AF$2:$AF$66, MultiYear_ProForma!$B$2:$B$66, A11, MultiYear_ProForma!$C$2:$C$66, "FY2030") -> 537913.81 | D11: =SUMIFS(MultiYear_ProForma!$AF$2:$AF$66, MultiYear_ProForma!$B$2:$B$66, A11, MultiYear_ProForma!$C$2:$C$66, "FY2028") -> 138880.27 | E11: =SUMIFS(MultiYear_ProForma!$AF$2:$AF$66, MultiYear_ProForma!$B$2:$B$66, A11, MultiYear_ProForma!$C$2:$C$66, "FY2030") -> 537913.81 | F11: =(SUMIFS(MultiYear_ProForma!$AF$2:$AF$66, MultiYear_ProForma!$B$2:$B$66, A11, MultiYear_ProForma!$C$2:$C$66, "FY2026")+SUMIFS(MultiYear_ProForma!$AF$2:$AF$66, MultiYear_ProForma!$B$2:$B$66, A11, MultiYear_ProForma!$C$2:$C$66, "FY2027")+SUMIFS(MultiYear_ProForma!$AF$2:$AF$66, MultiYear_ProForma!$B$2:$B$66, A11, MultiYear_ProForma!$C$2:$C$66, "FY2028")+SUMIFS(MultiYear_ProForma!$AF$2:$AF$66, MultiYear_ProForma!$B$2:$B$66, A11, MultiYear_ProForma!$C$2:$C$66, "FY2029")+SUMIFS(MultiYear_ProForma!$AF$2:$AF$66, MultiYear_ProForma!$B$2:$B$66, A11, MultiYear_ProForma!$C$2:$C$66, "FY2030"))/5 -> 81004.084 | G11: =SUMIFS(MultiYear_ProForma!$N$2:$N$66, MultiYear_ProForma!$B$2:$B$66, A11, MultiYear_ProForma!$C$2:$C$66, "FY2026") -> 553 | H11: =SUMIFS(MultiYear_ProForma!$AC$2:$AC$66, MultiYear_ProForma!$B$2:$B$66, A11, MultiYear_ProForma!$C$2:$C$66, "FY2030") -> 184.025 | I11: =E11-(VLOOKUP($B$1,$A$5:$F$17,5, 0)) -> 1262693.8 | J11: =F11-(VLOOKUP($B$1,$A$5:$H$17,6, 0)) -> 671190.68
A12: A_Repurpose_Both_ops | B12: =SUMIFS(Capital_Summary!$H$4:$H$83, Capital_Summary!$A$4:$A$83, A12, Capital_Summary!$B$4:$B$83, "FY2026") -> 0 | C12: =SUMIFS(MultiYear_ProForma!$AF$2:$AF$66, MultiYear_ProForma!$B$2:$B$66, A12, MultiYear_ProForma!$C$2:$C$66, "FY2030") -> -124497.13 | D12: =SUMIFS(MultiYear_ProForma!$AF$2:$AF$66, MultiYear_ProForma!$B$2:$B$66, A12, MultiYear_ProForma!$C$2:$C$66, "FY2028") -> -333988.93 | E12: =SUMIFS(MultiYear_ProForma!$AF$2:$AF$66, MultiYear_ProForma!$B$2:$B$66, A12, MultiYear_ProForma!$C$2:$C$66, "FY2030") -> -124497.13 | F12: =(SUMIFS(MultiYear_ProForma!$AF$2:$AF$66, MultiYear_ProForma!$B$2:$B$66, A12, MultiYear_ProForma!$C$2:$C$66, "FY2026")+SUMIFS(MultiYear_ProForma!$AF$2:$AF$66, MultiYear_ProForma!$B$2:$B$66, A12, MultiYear_ProForma!$C$2:$C$66, "FY2027")+SUMIFS(MultiYear_ProForma!$AF$2:$AF$66, MultiYear_ProForma!$B$2:$B$66, A12, MultiYear_ProForma!$C$2:$C$66, "FY2028")+SUMIFS(MultiYear_ProForma!$AF$2:$AF$66, MultiYear_ProForma!$B$2:$B$66, A12, MultiYear_ProForma!$C$2:$C$66, "FY2029")+SUMIFS(MultiYear_ProForma!$AF$2:$AF$66, MultiYear_ProForma!$B$2:$B$66, A12, MultiYear_ProForma!$C$2:$C$66, "FY2030"))/5 -> -396825.46 | G12: =SUMIFS(MultiYear_ProForma!$N$2:$N$66, MultiYear_ProForma!$B$2:$B$66, A12, MultiYear_ProForma!$C$2:$C$66, "FY2026") -> 553 | H12: =SUMIFS(MultiYear_ProForma!$AC$2:$AC$66, MultiYear_ProForma!$B$2:$B$66, A12, MultiYear_ProForma!$C$2:$C$66, "FY2030") -> 184.025 | I12: =E12-(VLOOKUP($B$1,$A$5:$F$17,5, 0)) -> 600282.81 | J12: =F12-(VLOOKUP($B$1,$A$5:$H$17,6, 0)) -> 193361.13
A13: B_Repurpose_Echo_lease_PimaTargets | B13: =SUMIFS(Capital_Summary!$H$4:$H$83, Capital_Summary!$A$4:$A$83, A13, Capital_Summary!$B$4:$B$83, "FY2026") -> 1200000 | C13: =SUMIFS(MultiYear_ProForma!$AF$2:$AF$66, MultiYear_ProForma!$B$2:$B$66, A13, MultiYear_ProForma!$C$2:$C$66, "FY2030") -> -394968.1 | D13: =SUMIFS(MultiYear_ProForma!$AF$2:$AF$66, MultiYear_ProForma!$B$2:$B$66, A13, MultiYear_ProForma!$C$2:$C$66, "FY2028") -> -524463.5 | E13: =SUMIFS(MultiYear_ProForma!$AF$2:$AF$66, MultiYear_ProForma!$B$2:$B$66, A13, MultiYear_ProForma!$C$2:$C$66, "FY2030") -> -394968.1 | F13: =(SUMIFS(MultiYear_ProForma!$AF$2:$AF$66, MultiYear_ProForma!$B$2:$B$66, A13, MultiYear_ProForma!$C$2:$C$66, "FY2026")+SUMIFS(MultiYear_ProForma!$AF$2:$AF$66, MultiYear_ProForma!$B$2:$B$66, A13, MultiYear_ProForma!$C$2:$C$66, "FY2027")+SUMIFS(MultiYear_ProForma!$AF$2:$AF$66, MultiYear_ProForma!$B$2:$B$66, A13, MultiYear_ProForma!$C$2:$C$66, "FY2028")+SUMIFS(MultiYear_ProForma!$AF$2:$AF$66, MultiYear_ProForma!$B$2:$B$66, A13, MultiYear_ProForma!$C$2:$C$66, "FY2029")+SUMIFS(MultiYear_ProForma!$AF$2:$AF$66, MultiYear_ProForma!$B$2:$B$66, A13, MultiYear_ProForma!$C$2:$C$66, "FY2030"))/5 -> -548584.95 | G13: =SUMIFS(MultiYear_ProForma!$N$2:$N$66, MultiYear_ProForma!$B$2:$B$66, A13, MultiYear_ProForma!$C$2:$C$66, "FY2026") -> 257 | H13: =SUMIFS(MultiYear_ProForma!$AC$2:$AC$66, MultiYear_ProForma!$B$2:$B$66, A13, MultiYear_ProForma!$C$2:$C$66, "FY2030") -> 302.425 | I13: =E13-(VLOOKUP($B$1,$A$5:$F$17,5, 0)) -> 329811.83 | J13: =F13-(VLOOKUP($B$1,$A$5:$H$17,6, 0)) -> 41601.641
A14: B_Repurpose_Echo_ops_PimaTargets | B14: =SUMIFS(Capital_Summary!$H$4:$H$83, Capital_Summary!$A$4:$A$83, A14, Capital_Summary!$B$4:$B$83, "FY2026") -> 0 | C14: =SUMIFS(MultiYear_ProForma!$AF$2:$AF$66, MultiYear_ProForma!$B$2:$B$66, A14, MultiYear_ProForma!$C$2:$C$66, "FY2030") -> -97652.846 | D14: =SUMIFS(MultiYear_ProForma!$AF$2:$AF$66, MultiYear_ProForma!$B$2:$B$66, A14, MultiYear_ProForma!$C$2:$C$66, "FY2028") -> -168221.16 | E14: =SUMIFS(MultiYear_ProForma!$AF$2:$AF$66, MultiYear_ProForma!$B$2:$B$66, A14, MultiYear_ProForma!$C$2:$C$66, "FY2030") -> -97652.846 | F14: =(SUMIFS(MultiYear_ProForma!$AF$2:$AF$66, MultiYear_ProForma!$B$2:$B$66, A14, MultiYear_ProForma!$C$2:$C$66, "FY2026")+SUMIFS(MultiYear_ProForma!$AF$2:$AF$66, MultiYear_ProForma!$B$2:$B$66, A14, MultiYear_ProForma!$C$2:$C$66, "FY2027")+SUMIFS(MultiYear_ProForma!$AF$2:$AF$66, MultiYear_ProForma!$B$2:$B$66, A14, MultiYear_ProForma!$C$2:$C$66, "FY2028")+SUMIFS(MultiYear_ProForma!$AF$2:$AF$66, MultiYear_ProForma!$B$2:$B$66, A14, MultiYear_ProForma!$C$2:$C$66, "FY2029")+SUMIFS(MultiYear_ProForma!$AF$2:$AF$66, MultiYear_ProForma!$B$2:$B$66, A14, MultiYear_ProForma!$C$2:$C$66, "FY2030"))/5 -> -304859.85 | G14: =SUMIFS(MultiYear_ProForma!$N$2:$N$66, MultiYear_ProForma!$B$2:$B$66, A14, MultiYear_ProForma!$C$2:$C$66, "FY2026") -> 257 | H14: =SUMIFS(MultiYear_ProForma!$AC$2:$AC$66, MultiYear_ProForma!$B$2:$B$66, A14, MultiYear_ProForma!$C$2:$C$66, "FY2030") -> 352.425 | I14: =E14-(VLOOKUP($B$1,$A$5:$F$17,5, 0)) -> 627127.09 | J14: =F14-(VLOOKUP($B$1,$A$5:$H$17,6, 0)) -> 285326.74
A15: C_Repurpose_Pima_lease_EchoGHub_EchoTargets | B15: =SUMIFS(Capital_Summary!$H$4:$H$83, Capital_Summary!$A$4:$A$83, A15, Capital_Summary!$B$4:$B$83, "FY2026") -> 1200000 | C15: =SUMIFS(MultiYear_ProForma!$AF$2:$AF$66, MultiYear_ProForma!$B$2:$B$66, A15, MultiYear_ProForma!$C$2:$C$66, "FY2030") -> 425861.99 | D15: =SUMIFS(MultiYear_ProForma!$AF$2:$AF$66, MultiYear_ProForma!$B$2:$B$66, A15, MultiYear_ProForma!$C$2:$C$66, "FY2028") -> 180754.9 | E15: =SUMIFS(MultiYear_ProForma!$AF$2:$AF$66, MultiYear_ProForma!$B$2:$B$66, A15, MultiYear_ProForma!$C$2:$C$66, "FY2030") -> 425861.99 | F15: =(SUMIFS(MultiYear_ProForma!$AF$2:$AF$66, MultiYear_ProForma!$B$2:$B$66, A15, MultiYear_ProForma!$C$2:$C$66, "FY2026")+SUMIFS(MultiYear_ProForma!$AF$2:$AF$66, MultiYear_ProForma!$B$2:$B$66, A15, MultiYear_ProForma!$C$2:$C$66, "FY2027")+SUMIFS(MultiYear_ProForma!$AF$2:$AF$66, MultiYear_ProForma!$B$2:$B$66, A15, MultiYear_ProForma!$C$2:$C$66, "FY2028")+SUMIFS(MultiYear_ProForma!$AF$2:$AF$66, MultiYear_ProForma!$B$2:$B$66, A15, MultiYear_ProForma!$C$2:$C$66, "FY2029")+SUMIFS(MultiYear_ProForma!$AF$2:$AF$66, MultiYear_ProForma!$B$2:$B$66, A15, MultiYear_ProForma!$C$2:$C$66, "FY2030"))/5 -> 146705.87 | G15: =SUMIFS(MultiYear_ProForma!$N$2:$N$66, MultiYear_ProForma!$B$2:$B$66, A15, MultiYear_ProForma!$C$2:$C$66, "FY2026") -> 296 | H15: =SUMIFS(MultiYear_ProForma!$AC$2:$AC$66, MultiYear_ProForma!$B$2:$B$66, A15, MultiYear_ProForma!$C$2:$C$66, "FY2030") -> 434.6 | I15: =E15-(VLOOKUP($B$1,$A$5:$F$17,5, 0)) -> 1150641.9 | J15: =F15-(VLOOKUP($B$1,$A$5:$H$17,6, 0)) -> 736892.46
A16: C_Repurpose_Pima_ops_EchoGHub_EchoTargets | B16: =SUMIFS(Capital_Summary!$H$4:$H$83, Capital_Summary!$A$4:$A$83, A16, Capital_Summary!$B$4:$B$83, "FY2026") -> 0 | C16: =SUMIFS(MultiYear_ProForma!$AF$2:$AF$66, MultiYear_ProForma!$B$2:$B$66, A16, MultiYear_ProForma!$C$2:$C$66, "FY2030") -> 1281623.8 | D16: =SUMIFS(MultiYear_ProForma!$AF$2:$AF$66, MultiYear_ProForma!$B$2:$B$66, A16, MultiYear_ProForma!$C$2:$C$66, "FY2028") -> 1079650.9 | E16: =SUMIFS(MultiYear_ProForma!$AF$2:$AF$66, MultiYear_ProForma!$B$2:$B$66, A16, MultiYear_ProForma!$C$2:$C$66, "FY2030") -> 1281623.8 | F16: =(SUMIFS(MultiYear_ProForma!$AF$2:$AF$66, MultiYear_ProForma!$B$2:$B$66, A16, MultiYear_ProForma!$C$2:$C$66, "FY2026")+SUMIFS(MultiYear_ProForma!$AF$2:$AF$66, MultiYear_ProForma!$B$2:$B$66, A16, MultiYear_ProForma!$C$2:$C$66, "FY2027")+SUMIFS(MultiYear_ProForma!$AF$2:$AF$66, MultiYear_ProForma!$B$2:$B$66, A16, MultiYear_ProForma!$C$2:$C$66, "FY2028")+SUMIFS(MultiYear_ProForma!$AF$2:$AF$66, MultiYear_ProForma!$B$2:$B$66, A16, MultiYear_ProForma!$C$2:$C$66, "FY2029")+SUMIFS(MultiYear_ProForma!$AF$2:$AF$66, MultiYear_ProForma!$B$2:$B$66, A16, MultiYear_ProForma!$C$2:$C$66, "FY2030"))/5 -> 822528.59 | G16: =SUMIFS(MultiYear_ProForma!$N$2:$N$66, MultiYear_ProForma!$B$2:$B$66, A16, MultiYear_ProForma!$C$2:$C$66, "FY2026") -> 296.33333 | H16: =SUMIFS(MultiYear_ProForma!$AC$2:$AC$66, MultiYear_ProForma!$B$2:$B$66, A16, MultiYear_ProForma!$C$2:$C$66, "FY2030") -> 534.6 | I16: =E16-(VLOOKUP($B$1,$A$5:$F$17,5, 0)) -> 2006403.7 | J16: =F16-(VLOOKUP($B$1,$A$5:$H$17,6, 0)) -> 1412715.2
A17: H_StatusQuo_Decline | B17: =SUMIFS(Capital_Summary!$H$4:$H$83, Capital_Summary!$A$4:$A$83, A17, Capital_Summary!$B$4:$B$83, "FY2026") -> 0 | C17: =SUMIFS(MultiYear_ProForma!$AF$2:$AF$66, MultiYear_ProForma!$B$2:$B$66, A17, MultiYear_ProForma!$C$2:$C$66, "FY2030") -> -724779.94 | D17: =SUMIFS(MultiYear_ProForma!$AF$2:$AF$66, MultiYear_ProForma!$B$2:$B$66, A17, MultiYear_ProForma!$C$2:$C$66, "FY2028") -> -588315.82 | E17: =SUMIFS(MultiYear_ProForma!$AF$2:$AF$66, MultiYear_ProForma!$B$2:$B$66, A17, MultiYear_ProForma!$C$2:$C$66, "FY2030") -> -724779.94 | F17: =(SUMIFS(MultiYear_ProForma!$AF$2:$AF$66, MultiYear_ProForma!$B$2:$B$66, A17, MultiYear_ProForma!$C$2:$C$66, "FY2026")+SUMIFS(MultiYear_ProForma!$AF$2:$AF$66, MultiYear_ProForma!$B$2:$B$66, A17, MultiYear_ProForma!$C$2:$C$66, "FY2027")+SUMIFS(MultiYear_ProForma!$AF$2:$AF$66, MultiYear_ProForma!$B$2:$B$66, A17, MultiYear_ProForma!$C$2:$C$66, "FY2028")+SUMIFS(MultiYear_ProForma!$AF$2:$AF$66, MultiYear_ProForma!$B$2:$B$66, A17, MultiYear_ProForma!$C$2:$C$66, "FY2029")+SUMIFS(MultiYear_ProForma!$AF$2:$AF$66, MultiYear_ProForma!$B$2:$B$66, A17, MultiYear_ProForma!$C$2:$C$66, "FY2030"))/5 -> -590186.59 | G17: =SUMIFS(MultiYear_ProForma!$N$2:$N$66, MultiYear_ProForma!$B$2:$B$66, A17, MultiYear_ProForma!$C$2:$C$66, "FY2026") -> 0 | H17: =SUMIFS(MultiYear_ProForma!$AC$2:$AC$66, MultiYear_ProForma!$B$2:$B$66, A17, MultiYear_ProForma!$C$2:$C$66, "FY2030") -> 510.06959 | I17: =E17-(VLOOKUP($B$1,$A$5:$F$17,5, 0)) -> 0 | J17: =F17-(VLOOKUP($B$1,$A$5:$H$17,6, 0)) -> 0
A19: Note: Displaced = FY26; Served = FY30. Net = M&O − (Aid + Override + Uplift)

Sheet Board_OnePager
A1: Echo & Pima — Baseline vs Comparator (Operating Net, FY26–FY30)
A3: Baseline (Base) | B3: A_Repurpose_Both_lease
A4: Comparator | B4: H_StatusQuo_Decline
A6: Year | B6: Operating Net$ (Base) | C6: Operating Net$ (Comparator)
A7: FY2026 | B7: =SUMIFS(MultiYear_ProForma!$AF$2:$AF$66, MultiYear_ProForma!$B$2:$B$66, $B$3, MultiYear_ProForma!$C$2:$C$66, "FY2026") -> -546853.79 | C7: =SUMIFS(MultiYear_ProForma!$AF$2:$AF$66, MultiYear_ProForma!$B$2:$B$66, $B$4, MultiYear_ProForma!$C$2:$C$66, "FY2026") -> -459335.03
A8: FY2027 | B8: =SUMIFS(MultiYear_ProForma!$AF$2:$AF$66, MultiYear_ProForma!$B$2:$B$66, $B$3, MultiYear_ProForma!$C$2:$C$66, "FY2027") -> -211562.31 | C8: =SUMIFS(MultiYear_ProForma!$AF$2:$AF$66, MultiYear_ProForma!$B$2:$B$66, $B$4, MultiYear_ProForma!$C$2:$C$66, "FY2027") -> -522913.48
A9: FY2028 | B9: =SUMIFS(MultiYear_ProForma!$AF$2:$AF$66, MultiYear_ProForma!$B$2:$B$66, $B$3, MultiYear_ProForma!$C$2:$C$66, "FY2028") -> 138880.27 | C9: =SUMIFS(MultiYear_ProForma!$AF$2:$AF$66, MultiYear_ProForma!$B$2:$B$66, $B$4, MultiYear_ProForma!$C$2:$C$66, "FY2028") -> -588315.82
A10: FY2029 | B10: =SUMIFS(MultiYear_ProForma!$AF$2:$AF$66, MultiYear_ProForma!$B$2:$B$66, $B$3, MultiYear_ProForma!$C$2:$C$66, "FY2029") -> 486642.44 | C10: =SUMIFS(MultiYear_ProForma!$AF$2:$AF$66, MultiYear_ProForma!$B$2:$B$66, $B$4, MultiYear_ProForma!$C$2:$C$66, "FY2029") -> -655588.7
A11: FY2030 | B11: =SUMIFS(MultiYear_ProForma!$AF$2:$AF$66, MultiYear_ProForma!$B$2:$B$66, $B$3, MultiYear_ProForma!$C$2:$C$66, "FY2030") -> 537913.81 | C11: =SUMIFS(MultiYear_ProForma!$AF$2:$AF$66, MultiYear_ProForma!$B$2:$B$66, $B$4, MultiYear_ProForma!$C$2:$C$66, "FY2030") -> -724779.94
A16: Notes: No receiving site exceeds spare seats + portables; assumptions reflect: r, override, marginal factor, trend flags; h tapers yearly
A18: FY2030 Net (Base) | B18: =SUMIFS(MultiYear_ProForma!$AF$2:$AF$66, MultiYear_ProForma!$B$2:$B$66, $B$3, MultiYear_ProForma!$C$2:$C$66, "FY2030") -> 537913.81
A19: FY2030 Net (Comparator) | B19: =SUMIFS(MultiYear_ProForma!$AF$2:$AF$66, MultiYear_ProForma!$B$2:$B$66, $B$4, MultiYear_ProForma!$C$2:$C$66, "FY2030") -> -724779.94
A20: Δ vs Base (FY2030) | B20: =B19-B18 -> -1262693.8
A22: Avg Net (FY26–30) (Base) | B22: =(SUMIFS(MultiYear_ProForma!$AF$2:$AF$66, MultiYear_ProForma!$B$2:$B$66, $B$3, MultiYear_ProForma!$C$2:$C$66, "FY2026")+SUMIFS(MultiYear_ProForma!$AF$2:$AF$66, MultiYear_ProForma!$B$2:$B$66, $B$3, MultiYear_ProForma!$C$2:$C$66, "FY2027")+SUMIFS(MultiYear_ProForma!$AF$2:$AF$66, MultiYear_ProForma!$B$2:$B$66, $B$3, MultiYear_ProForma!$C$2:$C$66, "FY2028")+SUMIFS(MultiYear_ProForma!$AF$2:$AF$66, MultiYear_ProForma!$B$2:$B$66, $B$3, MultiYear_ProForma!$C$2:$C$66, "FY2029")+SUMIFS(MultiYear_ProForma!$AF$2:$AF$66, MultiYear_ProForma!$B$2:$B$66, $B$3, MultiYear_ProForma!$C$2:$C$66, "FY2030"))/5 -> 81004.084
A23: Avg Net (FY26–30) (Comparator) | B23: =(SUMIFS(MultiYear_ProForma!$AF$2:$AF$66, MultiYear_ProForma!$B$2:$B$66, $B$4, MultiYear_ProForma!$C$2:$C$66, "FY2026")+SUMIFS(MultiYear_ProForma!$AF$2:$AF$66, MultiYear_ProForma!$B$2:$B$66, $B$4, MultiYear_ProForma!$C$2:$C$66, "FY2027")+SUMIFS(MultiYear_ProForma!$AF$2:$AF$66, MultiYear_ProForma!$B$2:$B$66, $B$4, MultiYear_ProForma!$C$2:$C$66, "FY2028")+SUMIFS(MultiYear_ProForma!$AF$2:$AF$66, MultiYear_ProForma!$B$2:$B$66, $B$4, MultiYear_ProForma!$C$2:$C$66, "FY2029")+SUMIFS(MultiYear_ProForma!$AF$2:$AF$66, MultiYear_ProForma!$B$2:$B$66, $B$4, MultiYear_ProForma!$C$2:$C$66, "FY2030"))/5 -> -590186.59
A24: Δ vs Base (Avg FY26–30) | B24: =B23-B22 -> -671190.68
A26: Displaced (FY26) (Base) | B26: =SUMIFS(MultiYear_ProForma!$N$2:$N$66, MultiYear_ProForma!$B$2:$B$66, $B$3, MultiYear_ProForma!$C$2:$C$66, "FY2026") -> 553
A27: Displaced (FY26) (Comparator) | B27: =SUMIFS(MultiYear_ProForma!$N$2:$N$66, MultiYear_ProForma!$B$2:$B$66, $B$4, MultiYear_ProForma!$C$2:$C$66, "FY2026") -> 0
A29: Served (FY2030) (Base) | B29: =SUMIFS(MultiYear_ProForma!$AC$2:$AC$66, MultiYear_ProForma!$B$2:$B$66, $B$3, MultiYear_ProForma!$C$2:$C$66, "FY2030") -> 184.025
A30: Served (FY2030) (Comparator) | B30: =SUMIFS(MultiYear_ProForma!$AC$2:$AC$66, MultiYear_ProForma!$B$2:$B$66, $B$4, MultiYear_ProForma!$C$2:$C$66, "FY2030") -> 510.06959
A32: One-time Capital FY 2026 (Base) | B32: =SUMIFS(Capital_Summary!$H$4:$H$83, Capital_Summary!$A$4:$A$83, B3, Capital_Summary!$B$4:$B$83, "FY2026") -> 2400000
A33: One-time Capital FY 2026 (Comparator) | B33: =SUMIFS(Capital_Summary!$H$4:$H$83, Capital_Summary!$A$4:$A$83, B4, Capital_Summary!$B$4:$B$83, "FY2026") -> 0

Sheet One_to_One_Comparison
A1: Echo & Pima Decision Dashboard — one comparator vs A_Repurpose_Both_ops
D2: OPERATING | K2: CAPITAL — FY2026 only
D3: FY2030 Net ($) | E3: 5-yr Avg Net ($) | F3: Δ vs Base (FY2030 Net) | G3: Δ vs Base (5-yr Avg Net) | H3: Students displaced | I3: FY2030 students served | K3: FY2026 Capital ($) | L3: Δ vs Base
A4: Baseline (Base) | B4: H_StatusQuo_Decline | D4: =INDEX(Summary_Figures!$E$5:$E$17, MATCH($B$4, Summary_Figures!$A$5:$A$17, 0)) -> -724779.94 | E4: =INDEX(Summary_Figures!$F$5:$F$17, MATCH($B$4, Summary_Figures!$A$5:$A$17, 0)) -> -590186.59 | H4: =INDEX(Summary_Figures!$G$5:$G$17, MATCH($B$4, Summary_Figures!$A$5:$A$17, 0)) -> 0 | I4: =INDEX(Summary_Figures!$H$5:$H$17, MATCH($B$4, Summary_Figures!$A$5:$A$17, 0)) -> 510.06959 | K4: =SUMIFS(Capital_Summary!$H$4:$H$63, Capital_Summary!$A$4:$A$63, $B$4, Capital_Summary!$B$4:$B$63, "FY2026") -> 0
A5: Comparator (ScenarioKey) | B5: A_Repurpose_Both_lease | D5: =INDEX(Summary_Figures!$E$5:$E$17, MATCH($B$5, Summary_Figures!$A$5:$A$17, 0)) -> 537913.81 | E5: =INDEX(Summary_Figures!$F$5:$F$17, MATCH($B$5, Summary_Figures!$A$5:$A$17, 0)) -> 81004.084 | F5: =D5-D4 -> 1262693.8 | G5: =E5-E4 -> 671190.68 | H5: =INDEX(Summary_Figures!$G$5:$G$17, MATCH($B$5, Summary_Figures!$A$5:$A$17, 0)) -> 553 | I5: =INDEX(Summary_Figures!$H$5:$H$17, MATCH($B$5, Summary_Figures!$A$5:$A$17, 0)) -> 184.025 | K5: =SUMIFS(Capital_Summary!$H$4:$H$63, Capital_Summary!$A$4:$A$63, $B$5, Capital_Summary!$B$4:$B$63, "FY2026") -> 2400000 | L5: =K5-K4 -> 2400000
A7: Assumptions (from Parameters_Public / Control_Center)
A8: Retention r (Echo central) | B8: =Parameters_Public!C22 -> 0.025
A9: Retention r (Pima central) | B9: =Parameters_Public!C23 -> 0.6
A10: MarginalFactor_for_Overlay | B10: =Parameters_Public!$C42 -> 0
A11: Override % | B11: =Parameters_Public!C17 -> 0.15
A12: Override toggle (0/1) | B12: =Parameters_Public!C20 -> 1
A14: Assumption notes:
A15: • Routing/admin overhead h tapers by year (see YearMap). Try ±20% sensitivity when routing assumptions are uncertain.
A16: • Keep-open ops savings (fraction of MO): | B16: =Control_Center!C10 -> 0.007
A17: • Extra savings for co-location (fraction of MO): | B17: =Control_Center!C11 -> 0.015

Sheet Scenarios
A1: ScenarioKey | B1: Label | C1: Overlay | D1: CloseEcho | E1: ClosePima | F1: EchoShareDist | G1: ExtraSave | H1: Notes | I1: Overlay_FY26 | J1: Overlay_FY27 | K1: Overlay_FY28 | L1: Overlay_FY29 | M1: Overlay_FY30 | N1: Carry | O1: Growth_Echo | P1: Growth_Pima | Q1: Apply_Echo_Trend | R1: Apply_Pima_Trend
A2: D_CUSTOM1 | B2: =Control_Center!B31 -> CUSTOM_KeepOpen_v1 | C2: =Control_Center!C31 -> 0 | D2: =Control_Center!D31 -> 0 | E2: =Control_Center!E31 -> 0 | F2: =Control_Center!F31 -> 0.5 | G2: =Control_Center!G31 -> 0 | H2: Baseline + outreach; no closures | I2: =C2/3 -> 0 | J2: =I2+C2/3 -> 0 | K2: =J2+C2/3 -> 0 | L2: =C2 -> 0 | M2: =C2 -> 0 | O2: None | P2: None | Q2: 0 | R2: 0
A3: E_StatusQuo_Targets | B3: =Control_Center!B32 -> Status‑Quo + Op Growth Targets | C3: =Control_Center!C32 -> 100 | D3: =Control_Center!D32 -> 0 | E3: =Control_Center!E32 -> 0 | F3: =Control_Center!F32 -> 0.5 | G3: =Control_Center!G32 -> 0 | H3: Baseline + targets; no closures | I3: =C3/3 -> 33.333333 | J3: =I3+C3/3 -> 66.666667 | K3: =J3+C3/3 -> 100 | L3: =C3 -> 100 | M3: =C3 -> 100 | O3: None | P3: None | Q3: 0 | R3: 0
A4: F_CoLocation_Echo_Targets | B4: =Control_Center!B33 -> Co‑Location @ Echo + Op Growth Targets | C4: =Control_Center!C33 -> 100 | D4: =Control_Center!D33 -> 0 | E4: =Control_Center!E33 -> 0 | F4: =Control_Center!F33 -> 0.5 | G4: =Control_Center!G33 -> 0.05 | H4: Shared‑use efficiencies later (no closure) | I4: =C4/3 -> 33.333333 | J4: =I4+C4/3 -> 66.666667 | K4: =J4+C4/3 -> 100 | L4: =C4 -> 100 | M4: =C4 -> 100 | O4: None | P4: None | Q4: 0 | R4: 0
A5: D_Grow_Both_Targets | B5: =Control_Center!B34 -> Grow Both + Op Growth Targets | C5: =Control_Center!C34 -> 200 | D5: =Control_Center!D34 -> 0 | E5: =Control_Center!E34 -> 0 | F5: =Control_Center!F34 -> 0.5 | G5: =Control_Center!G34 -> 0 | H5: Baseline +100 overlay | I5: =C5/3 -> 66.666667 | J5: =I5+C5/3 -> 133.33333 | K5: =J5+C5/3 -> 200 | L5: =C5 -> 200 | M5: =C5 -> 200 | O5: Innov | P5: Arts | Q5: 0 | R5: 0
A6: D_CUSTOM2 | B6: =Control_Center!B35 -> CUSTOM_KeepOpen_v2 | C6: =Control_Center!C35 -> 0 | D6: =Control_Center!D35 -> 0 | E6: =Control_Center!E35 -> 0 | F6: =Control_Center!F35 -> 0.5 | G6: =Control_Center!G35 -> 0 | H6: Baseline +150 overlay | I6: =C6/3 -> 0 | J6: =I6+C6/3 -> 0 | K6: =J6+C6/3 -> 0 | L6: =C6 -> 0 | M6: =C6 -> 0 | O6: None | P6: None | Q6: 0 | R6: 0
A7: G_EchoGHubRamp_PimaTargets | B7: =Control_Center!B36 -> Growth Hub @ Echo + Status-Quo Pima + Op Growth Targets | C7: =Control_Center!C36 -> 150 | D7: =Control_Center!D36 -> 0 | E7: =Control_Center!E36 -> 0 | F7: =Control_Center!F36 -> 0.7 | G7: =Control_Center!G36 -> 0 | H7: Time‑phased ramp (+50,+100,+150 years 1–3) | I7: =C7/3 -> 50 | J7: =I7+C7/3 -> 100 | K7: =J7+C7/3 -> 150 | L7: =C7 -> 150 | M7: =C7 -> 150 | O7: Arts | P7: None | Q7: 0 | R7: 0
A8: A_Repurpose_Both_lease | B8: =Control_Center!B37 -> Repurpose BOTH (lease) | C8: =Control_Center!C37 -> 0 | D8: =Control_Center!D37 -> 1 | E8: =Control_Center!E37 -> 1 | F8: =Control_Center!F37 -> 0.5 | G8: =Control_Center!G37 -> 0 | H8: Repurpose both; lease/sale glide | I8: =C8/3 -> 0 | J8: =I8+C8/3 -> 0 | K8: =J8+C8/3 -> 0 | L8: =C8 -> 0 | M8: =C8 -> 0 | N8: lease | O8: None | P8: None | Q8: 0 | R8: 0
A9: A_Repurpose_Both_ops | B9: =Control_Center!B38 -> Repurpose BOTH (ops) | C9: =Control_Center!C38 -> 0 | D9: =Control_Center!D38 -> 1 | E9: =Control_Center!E38 -> 1 | F9: =Control_Center!F38 -> 0.5 | G9: =Control_Center!G38 -> 0 | H9: Repurpose both; operations carry | I9: =C9/3 -> 0 | J9: =I9+C9/3 -> 0 | K9: =J9+C9/3 -> 0 | L9: =C9 -> 0 | M9: =C9 -> 0 | N9: ops | O9: None | P9: None | Q9: 0 | R9: 0
A10: B_Repurpose_Echo_lease_PimaTargets | B10: =Control_Center!B39 -> Repurpose ECHO (lease) + Status-Quo Pima + Pima Op Growth Targets | C10: =Control_Center!C39 -> 0 | D10: =Control_Center!D39 -> 1 | E10: =Control_Center!E39 -> 0 | F10: =Control_Center!F39 -> 0 | G10: =Control_Center!G39 -> 0 | H10: Repurpose Echo only; lease glide | I10: =C10/3 -> 0 | J10: =I10+C10/3 -> 0 | K10: =J10+C10/3 -> 0 | L10: =C10 -> 0 | M10: =C10 -> 0 | N10: lease | O10: None | P10: None | Q10: 0 | R10: 0
A11: B_Repurpose_Echo_ops_PimaTargets | B11: =Control_Center!B40 -> Repurpose ECHO (ops) + Status-Quo Pima + Pima Op Growth Targets | C11: =Control_Center!C40 -> 50 | D11: =Control_Center!D40 -> 1 | E11: =Control_Center!E40 -> 0 | F11: =Control_Center!F40 -> 0 | G11: =Control_Center!G40 -> 0 | H11: Repurpose Echo only; ops carry | I11: =C11/3 -> 16.666667 | J11: =I11+C11/3 -> 33.333333 | K11: =J11+C11/3 -> 50 | L11: =C11 -> 50 | M11: =C11 -> 50 | N11: ops | O11: None | P11: None | Q11: 0 | R11: 0
A12: C_Repurpose_Pima_lease_EchoGHub_EchoTargets | B12: =Control_Center!B41 -> Repurpose PIMA (lease) + Growth Hub @ Echo + Echo Op Growth Targets | C12: =Control_Center!C41 -> 0 | D12: =Control_Center!D41 -> 0 | E12: =Control_Center!E41 -> 1 | F12: =Control_Center!F41 -> 1 | G12: =Control_Center!G41 -> 0 | H12: Repurpose Pima only; lease glide | I12: =C12/3 -> 0 | J12: =I12+C12/3 -> 0 | K12: =J12+C12/3 -> 0 | L12: =C12 -> 0 | M12: =C12 -> 0 | N12: lease | O12: Arts | P12: None | Q12: 0 | R12: 0
A13: C_Repurpose_Pima_ops_EchoGHub_EchoTargets | B13: =Control_Center!B42 -> Repurpose PIMA (ops) + Growth Hub @ Echo + Echo Op Growth Targets | C13: =Control_Center!C42 -> 100 | D13: =Control_Center!D42 -> 0 | E13: =Control_Center!E42 -> 1 | F13: =Control_Center!F42 -> 1 | G13: =Control_Center!G42 -> 0 | H13: Repurpose Pima only; ops carry | I13: =C13/3 -> 33.333333 | J13: =I13+C13/3 -> 66.666667 | K13: =J13+C13/3 -> 100 | L13: =C13 -> 100 | M13: =C13 -> 100 | N13: ops | O13: Arts | P13: None | Q13: 0 | R13: 0
A14: H_StatusQuo_Decline | B14: Status-Quo + DeclineTrend | C14: 0 | D14: 0 | E14: 0 | F14: 0 | G14: 0 | H14: Keep open but decline per district forecast | I14: =C14/3 -> 0 | J14: =I14+C14/3 -> 0 | K14: =J14+C14/3 -> 0 | L14: =C14 -> 0 | M14: =C14 -> 0 | O14: None | P14: None | Q14: 1 | R14: 1
A16: ScenarioKey | B16: Year | C16: Echo_ADM | D16: Pima_ADM | E16: Total_ADM | F16: VarUnit$ | G16: EchoFixed$ | H16: PimaFixed$ | I16: Key | O16: None | P16: None
A17: =A2 -> D_CUSTOM1 | B17: FY2026 | C17: =IF(D2=1,0, BaselineCalc!$B$7 + ROUND(I2*F2,0)) -> 257 | D17: =IF(E2=1,0, BaselineCalc!$B$8 + I2 - ROUND(I2*F2,0)) -> 296 | E17: =C17+D17 -> 553 | F17: =YearMap!B2 -> 6414.5115 | G17: =YearMap!C2 -> 1404302.9 | H17: =YearMap!D2 -> 1617407.2 | I17: =A17&"|"&B17 -> D_CUSTOM1|FY2026 | O17: None | P17: None
A18: =A2 -> D_CUSTOM1 | B18: FY2027 | C18: =IF(D2=1,0, BaselineCalc!$B$7 + ROUND(J2*F2,0)) -> 257 | D18: =IF(E2=1,0, BaselineCalc!$B$8 + J2 - ROUND(J2*F2,0)) -> 296 | E18: =C18+D18 -> 553 | F18: =YearMap!B3 -> 6574.8743 | G18: =YearMap!C3 -> 1439410.4 | H18: =YearMap!D3 -> 1657842.4 | I18: =A18&"|"&B18 -> D_CUSTOM1|FY2027 | O18: None | P18: None
A19: =A2 -> D_CUSTOM1 | B19: FY2028 | C19: =IF(D2=1,0, BaselineCalc!$B$7 + ROUND(K2*F2,0)) -> 257 | D19: =IF(E2=1,0, BaselineCalc!$B$8 + K2 - ROUND(K2*F2,0)) -> 296 | E19: =C19+D19 -> 553 | F19: =YearMap!B4 -> 6739.2461 | G19: =YearMap!C4 -> 1475395.7 | H19: =YearMap!D4 -> 1699288.4 | I19: =A19&"|"&B19 -> D_CUSTOM1|FY2028 | O19: None | P19: None
A20: =A2 -> D_CUSTOM1 | B20: FY2029 | C20: =IF(D2=1,0, BaselineCalc!$B$7 + ROUND(L2*F2,0)) -> 257 | D20: =IF(E2=1,0, BaselineCalc!$B$8 + L2 - ROUND(L2*F2,0)) -> 296 | E20: =C20+D20 -> 553 | F20: =YearMap!B5 -> 6907.7273 | G20: =YearMap!C5 -> 1512280.6 | H20: =YearMap!D5 -> 1741770.6 | I20: =A20&"|"&B20 -> D_CUSTOM1|FY2029 | O20: None | P20: None
A21: =A2 -> D_CUSTOM1 | B21: FY2030 | C21: =IF(D2=1,0, BaselineCalc!$B$7 + ROUND(M2*F2,0)) -> 257 | D21: =IF(E2=1,0, BaselineCalc!$B$8 + M2 - ROUND(M2*F2,0)) -> 296 | E21: =C21+D21 -> 553 | F21: =YearMap!B6 -> 7080.4205 | G21: =YearMap!C6 -> 1550087.6 | H21: =YearMap!D6 -> 1785314.9 | I21: =A21&"|"&B21 -> D_CUSTOM1|FY2030 | O21: None | P21: None
A22: =A3 -> E_StatusQuo_Targets | B22: FY2026 | C22: =IF(D3=1,0, BaselineCalc!$B$7 + ROUND(I3*F3,0)) -> 274 | D22: =IF(E3=1,0, BaselineCalc!$B$8 + I3 - ROUND(I3*F3,0)) -> 312.33333 | E22: =C22+D22 -> 586.33333 | F22: =YearMap!B2 -> 6414.5115 | G22: =YearMap!C2 -> 1404302.9 | H22: =YearMap!D2 -> 1617407.2 | I22: =A22&"|"&B22 -> E_StatusQuo_Targets|FY2026 | O22: None | P22: None
A23: =A3 -> E_StatusQuo_Targets | B23: FY2027 | C23: =IF(D3=1,0, BaselineCalc!$B$7 + ROUND(J3*F3,0)) -> 290 | D23: =IF(E3=1,0, BaselineCalc!$B$8 + J3 - ROUND(J3*F3,0)) -> 329.66667 | E23: =C23+D23 -> 619.66667 | F23: =YearMap!B3 -> 6574.8743 | G23: =YearMap!C3 -> 1439410.4 | H23: =YearMap!D3 -> 1657842.4 | I23: =A23&"|"&B23 -> E_StatusQuo_Targets|FY2027 | O23: None | P23: None
A24: =A3 -> E_StatusQuo_Targets | B24: FY2028 | C24: =IF(D3=1,0, BaselineCalc!$B$7 + ROUND(K3*F3,0)) -> 307 | D24: =IF(E3=1,0, BaselineCalc!$B$8 + K3 - ROUND(K3*F3,0)) -> 346 | E24: =C24+D24 -> 653 | F24: =YearMap!B4 -> 6739.2461 | G24: =YearMap!C4 -> 1475395.7 | H24: =YearMap!D4 -> 1699288.4 | I24: =A24&"|"&B24 -> E_StatusQuo_Targets|FY2028 | O24: None | P24: None
A25: =A3 -> E_StatusQuo_Targets | B25: FY2029 | C25: =IF(D3=1,0, BaselineCalc!$B$7 + ROUND(L3*F3,0)) -> 307 | D25: =IF(E3=1,0, BaselineCalc!$B$8 + L3 - ROUND(L3*F3,0)) -> 346 | E25: =C25+D25 -> 653 | F25: =YearMap!B5 -> 6907.7273 | G25: =YearMap!C5 -> 1512280.6 | H25: =YearMap!D5 -> 1741770.6 | I25: =A25&"|"&B25 -> E_StatusQuo_Targets|FY2029 | O25: None | P25: None
A26: =A3 -> E_StatusQuo_Targets | B26: FY2030 | C26: =IF(D3=1,0, BaselineCalc!$B$7 + ROUND(M3*F3,0)) -> 307 | D26: =IF(E3=1,0, BaselineCalc!$B$8 + M3 - ROUND(M3*F3,0)) -> 346 | E26: =C26+D26 -> 653 | F26: =YearMap!B6 -> 7080.4205 | G26: =YearMap!C6 -> 1550087.6 | H26: =YearMap!D6 -> 1785314.9 | I26: =A26&"|"&B26 -> E_StatusQuo_Targets|FY2030 | O26: None | P26: None
A27: =A4 -> F_CoLocation_Echo_Targets | B27: FY2026 | C27: =IF(D4=1,0, BaselineCalc!$B$7 + ROUND(I4*F4,0)) -> 274 | D27: =IF(E4=1,0, BaselineCalc!$B$8 + I4 - ROUND(I4*F4,0)) -> 312.33333 | E27: =C27+D27 -> 586.33333 | F27: =YearMap!B2 -> 6414.5115 | G27: =YearMap!C2 -> 1404302.9 | H27: =YearMap!D2 -> 1617407.2 | I27: =A27&"|"&B27 -> F_CoLocation_Echo_Targets|FY2026 | O27: None | P27: None
A28: =A4 -> F_CoLocation_Echo_Targets | B28: FY2027 | C28: =IF(D4=1,0, BaselineCalc!$B$7 + ROUND(J4*F4,0)) -> 290 | D28: =IF(E4=1,0, BaselineCalc!$B$8 + J4 - ROUND(J4*F4,0)) -> 329.66667 | E28: =C28+D28 -> 619.66667 | F28: =YearMap!B3 -> 6574.8743 | G28: =YearMap!C3 -> 1439410.4 | H28: =YearMap!D3 -> 1657842.4 | I28: =A28&"|"&B28 -> F_CoLocation_Echo_Targets|FY2027 | O28: None | P28: None
A29: =A4 -> F_CoLocation_Echo_Targets | B29: FY2028 | C29: =IF(D4=1,0, BaselineCalc!$B$7 + ROUND(K4*F4,0)) -> 307 | D29: =IF(E4=1,0, BaselineCalc!$B$8 + K4 - ROUND(K4*F4,0)) -> 346 | E29: =C29+D29 -> 653 | F29: =YearMap!B4 -> 6739.2461 | G29: =YearMap!C4 -> 1475395.7 | H29: =YearMap!D4 -> 1699288.4 | I29: =A29&"|"&B29 -> F_CoLocation_Echo_Targets|FY2028 | O29: None | P29: None
A30: =A4 -> F_CoLocation_Echo_Targets | B30: FY2029 | C30: =IF(D4=1,0, BaselineCalc!$B$7 + ROUND(L4*F4,0)) -> 307 | D30: =IF(E4=1,0, BaselineCalc!$B$8 + L4 - ROUND(L4*F4,0)) -> 346 | E30: =C30+D30 -> 653 | F30: =YearMap!B5 -> 6907.7273 | G30: =YearMap!C5 -> 1512280.6 | H30: =YearMap!D5 -> 1741770.6 | I30: =A30&"|"&B30 -> F_CoLocation_Echo_Targets|FY2029 | O30: None | P30: None
A31: =A4 -> F_CoLocation_Echo_Targets | B31: FY2030 | C31: =IF(D4=1,0, BaselineCalc!$B$7 + ROUND(M4*F4,0)) -> 307 | D31: =IF(E4=1,0, BaselineCalc!$B$8 + M4 - ROUND(M4*F4,0)) -> 346 | E31: =C31+D31 -> 653 | F31: =YearMap!B6 -> 7080.4205 | G31: =YearMap!C6 -> 1550087.6 | H31: =YearMap!D6 -> 1785314.9 | I31: =A31&"|"&B31 -> F_CoLocation_Echo_Targets|FY2030 | O31: None | P31: None
A32: =A5 -> D_Grow_Both_Targets | B32: FY2026 | C32: =IF(D5=1,0, BaselineCalc!$B$7 + ROUND(I5*F5,0)) -> 290 | D32: =IF(E5=1,0, BaselineCalc!$B$8 + I5 - ROUND(I5*F5,0)) -> 329.66667 | E32: =C32+D32 -> 619.66667 | F32: =YearMap!B2 -> 6414.5115 | G32: =YearMap!C2 -> 1404302.9 | H32: =YearMap!D2 -> 1617407.2 | I32: =A32&"|"&B32 -> D_Grow_Both_Targets|FY2026 | O32: None | P32: None
A33: =A5 -> D_Grow_Both_Targets | B33: FY2027 | C33: =IF(D5=1,0, BaselineCalc!$B$7 + ROUND(J5*F5,0)) -> 324 | D33: =IF(E5=1,0, BaselineCalc!$B$8 + J5 - ROUND(J5*F5,0)) -> 362.33333 | E33: =C33+D33 -> 686.33333 | F33: =YearMap!B3 -> 6574.8743 | G33: =YearMap!C3 -> 1439410.4 | H33: =YearMap!D3 -> 1657842.4 | I33: =A33&"|"&B33 -> D_Grow_Both_Targets|FY2027 | O33: None | P33: None
A34: =A5 -> D_Grow_Both_Targets | B34: FY2028 | C34: =IF(D5=1,0, BaselineCalc!$B$7 + ROUND(K5*F5,0)) -> 357 | D34: =IF(E5=1,0, BaselineCalc!$B$8 + K5 - ROUND(K5*F5,0)) -> 396 | E34: =C34+D34 -> 753 | F34: =YearMap!B4 -> 6739.2461 | G34: =YearMap!C4 -> 1475395.7 | H34: =YearMap!D4 -> 1699288.4 | I34: =A34&"|"&B34 -> D_Grow_Both_Targets|FY2028 | O34: None | P34: None
A35: =A5 -> D_Grow_Both_Targets | B35: FY2029 | C35: =IF(D5=1,0, BaselineCalc!$B$7 + ROUND(L5*F5,0)) -> 357 | D35: =IF(E5=1,0, BaselineCalc!$B$8 + L5 - ROUND(L5*F5,0)) -> 396 | E35: =C35+D35 -> 753 | F35: =YearMap!B5 -> 6907.7273 | G35: =YearMap!C5 -> 1512280.6 | H35: =YearMap!D5 -> 1741770.6 | I35: =A35&"|"&B35 -> D_Grow_Both_Targets|FY2029 | O35: None | P35: None
A36: =A5 -> D_Grow_Both_Targets | B36: FY2030 | C36: =IF(D5=1,0, BaselineCalc!$B$7 + ROUND(M5*F5,0)) -> 357 | D36: =IF(E5=1,0, BaselineCalc!$B$8 + M5 - ROUND(M5*F5,0)) -> 396 | E36: =C36+D36 -> 753 | F36: =YearMap!B6 -> 7080.4205 | G36: =YearMap!C6 -> 1550087.6 | H36: =YearMap!D6 -> 1785314.9 | I36: =A36&"|"&B36 -> D_Grow_Both_Targets|FY2030 | O36: None | P36: None
A37: =A6 -> D_CUSTOM2 | B37: FY2026 | C37: =IF(D6=1,0, BaselineCalc!$B$7 + ROUND(I6*F6,0)) -> 257 | D37: =IF(E6=1,0, BaselineCalc!$B$8 + I6 - ROUND(I6*F6,0)) -> 296 | E37: =C37+D37 -> 553 | F37: =YearMap!B2 -> 6414.5115 | G37: =YearMap!C2 -> 1404302.9 | H37: =YearMap!D2 -> 1617407.2 | I37: =A37&"|"&B37 -> D_CUSTOM2|FY2026 | O37: None | P37: None
A38: =A6 -> D_CUSTOM2 | B38: FY2027 | C38: =IF(D6=1,0, BaselineCalc!$B$7 + ROUND(J6*F6,0)) -> 257 | D38: =IF(E6=1,0, BaselineCalc!$B$8 + J6 - ROUND(J6*F6,0)) -> 296 | E38: =C38+D38 -> 553 | F38: =YearMap!B3 -> 6574.8743 | G38: =YearMap!C3 -> 1439410.4 | H38: =YearMap!D3 -> 1657842.4 | I38: =A38&"|"&B38 -> D_CUSTOM2|FY2027 | O38: None | P38: None
A39: =A6 -> D_CUSTOM2 | B39: FY2028 | C39: =IF(D6=1,0, BaselineCalc!$B$7 + ROUND(K6*F6,0)) -> 257 | D39: =IF(E6=1,0, BaselineCalc!$B$8 + K6 - ROUND(K6*F6,0)) -> 296 | E39: =C39+D39 -> 553 | F39: =YearMap!B4 -> 6739.2461 | G39: =YearMap!C4 -> 1475395.7 | H39: =YearMap!D4 -> 1699288.4 | I39: =A39&"|"&B39 -> D_CUSTOM2|FY2028 | O39: None | P39: None
A40: =A6 -> D_CUSTOM2 | B40: FY2029 | C40: =IF(D6=1,0, BaselineCalc!$B$7 + ROUND(L6*F6,0)) -> 257 | D40: =IF(E6=1,0, BaselineCalc!$B$8 + L6 - ROUND(L6*F6,0)) -> 296 | E40: =C40+D40 -> 553 | F40: =YearMap!B5 -> 6907.7273 | G40: =YearMap!C5 -> 1512280.6 | H40: =YearMap!D5 -> 1741770.6 | I40: =A40&"|"&B40 -> D_CUSTOM2|FY2029 | O40: None | P40: None
A41: =A6 -> D_CUSTOM2 | B41: FY2030 | C41: =IF(D6=1,0, BaselineCalc!$B$7 + ROUND(M6*F6,0)) -> 257 | D41: =IF(E6=1,0, BaselineCalc!$B$8 + M6 - ROUND(M6*F6,0)) -> 296 | E41: =C41+D41 -> 553 | F41: =YearMap!B6 -> 7080.4205 | G41: =YearMap!C6 -> 1550087.6 | H41: =YearMap!D6 -> 1785314.9 | I41: =A41&"|"&B41 -> D_CUSTOM2|FY2030 | O41: None | P41: None
...

Sheet MultiYear_ProForma
A1: =AG1 -> Key | B1: ScenarioKey | C1: Year | D1: Echo_ADM | E1: Pima_ADM | F1: Total_ADM | G1: VarUnit$ | H1: EchoFixed$ | I1: PimaFixed$ | J1: OpsFactor | K1: ExtraSave | L1: EchoPotential_ADM | M1: PimaPotential_ADM | N1: Displaced_ADM | O1: Retained_ADM | P1: h | Q1: CarryFrac | R1: EchoFixedEff$ | S1: PimaFixedEff$ | T1: TI_adds$ | U1: SiteCost$ | V1: RetainedSvc$ | W1: Comparable_MO$ | X1: Comparable_per_Student$ | Y1: Aid_per_ADM | Z1: Net_MO_after_aid$ | AA1: Net_per_served$ | AB1: Overlay_ADM | AC1: Served_ADM | AD1: Revenue$ | AE1: Adj_MO$ | AF1: Net$ | AG1: Key
A2: =AG2 -> D_CUSTOM1|FY2026 | B2: =Scenarios!A2 -> D_CUSTOM1 | C2: FY2026 | D2: =IF(Scenarios!D2=1,0, L2) -> 257 | E2: =IF(Scenarios!E2=1,0, M2) -> 296 | F2: =D2+E2 -> 553 | G2: =YearMap!B2 -> 6414.5115 | H2: =YearMap!C2 -> 1404302.9 | I2: =YearMap!D2 -> 1617407.2 | J2: =1-BaselineCalc!$B$5 -> 0.993 | K2: =Scenarios!G2 -> 0 | L2: =IF(Scenarios!$Q2=1,BaselineCalc!$B$7*(1+Parameters_Public!$C44)^(IF($C2="FY2026",0,IF($C2="FY2027",1,IF($C2="FY2028",2,IF($C2="FY2029",3,IF($C2="FY2030",4,0))))))+ROUND(Scenarios!I2*Scenarios!$F2,0),BaselineCalc!$B$7+ROUND(Scenarios!I2*Scenarios!$F2,0)) -> 257 | M2: =IF(Scenarios!$R2=1,BaselineCalc!$B$8*(1+Parameters_Public!$C45)^(IF($C2="FY2026",0,IF($C2="FY2027",1,IF($C2="FY2028",2,IF($C2="FY2029",3,IF($C2="FY2030",4,0))))))+Scenarios!I2-ROUND(Scenarios!I2*Scenarios!$F2,0),BaselineCalc!$B$8+Scenarios!I2-ROUND(Scenarios!I2*Scenarios!$F2,0)) -> 296 | N2: =(L2-D2) + (M2-E2) -> 0 | O2: =(Parameters_Public!$C$22*(L2-D2)+Parameters_Public!$C$23*(M2-E2)) -> 0 | P2: =YearMap!E2 -> 1000 | Q2: =IF(Scenarios!N2="lease", YearMap!F2, YearMap!G2) -> 0.5 | R2: =IF(Scenarios!D2=1, Q2*H2, H2) -> 1404302.9 | S2: =IF(Scenarios!E2=1, Q2*I2, I2) -> 1617407.2 | T2: =IF(C2="FY2026", (Scenarios!D2+Scenarios!E2)*BaselineCalc!$B$22, 0) -> 0 | U2: =(R2+S2+G2*F2)*J2*(1-K2) -> 6522952.4 | V2: =O2*(G2+P2) -> 0 | W2: =U2+V2+IF(Parameters_Public!$C$26=1, T2, 0) -> 6522952.4 | X2: =IF(F2+O2>0, W2/(F2+O2),"") -> 11795.574 | Y2: =INDEX(YearMap!$I$2:$I$6, MATCH(C2, YearMap!$A$2:$A$6, 0)) -> 5013 | Z2: =W2 - ((Y2 + IF(Parameters_Public!$C$20=1, Parameters_Public!$C$19, 0))*AC2) -> 3334935 | AA2: =IF($AC2>0, $Z2/$AC2, 0) -> 6030.6239 | AB2: =MAX(0, (MAX(0, $D2-BaselineCalc!$B$7) + MAX(0, $E2-BaselineCalc!$B$8))) -> 0 | AC2: =IF(LEFT($B2,2)="A_", $O2, IF(LEFT($B2,2)="B_", $M2+$O2, IF(LEFT($B2,2)="C_", $L2+$O2, $F2))) -> 553 | AD2: =((Y2 + IF(Parameters_Public!$C$20=1, INDEX(YearMap!$O$2:$O$6, MATCH(C2, YearMap!$A$2:$A$6, 0)), 0))*AC2) + AC2*INDEX(YearMap!$P$2:$P$6, MATCH(C2, YearMap!$A$2:$A$6, 0)) -> 6063617.3 | AE2: =W2 - (1-Parameters_Public!$C42)*$G2*$AB2*$J2*(1-$K2) -> 6522952.4 | AF2: =AD2-AE2 -> -459335.03 | AG2: =B2&"|"&C2 -> D_CUSTOM1|FY2026
A3: =AG3 -> D_CUSTOM1|FY2027 | B3: =Scenarios!A2 -> D_CUSTOM1 | C3: FY2027 | D3: =IF(Scenarios!D2=1,0, L3) -> 257 | E3: =IF(Scenarios!E2=1,0, M3) -> 296 | F3: =D3+E3 -> 553 | G3: =YearMap!B3 -> 6574.8743 | H3: =YearMap!C3 -> 1439410.4 | I3: =YearMap!D3 -> 1657842.4 | J3: =1-BaselineCalc!$B$5 -> 0.993 | K3: =Scenarios!G2 -> 0 | L3: =IF(Scenarios!$Q2=1,BaselineCalc!$B$7*(1+Parameters_Public!$C44)^(IF($C3="FY2026",0,IF($C3="FY2027",1,IF($C3="FY2028",2,IF($C3="FY2029",3,IF($C3="FY2030",4,0))))))+ROUND(Scenarios!J2*Scenarios!$F2,0),BaselineCalc!$B$7+ROUND(Scenarios!J2*Scenarios!$F2,0)) -> 257 | M3: =IF(Scenarios!$R2=1,BaselineCalc!$B$8*(1+Parameters_Public!$C45)^(IF($C3="FY2026",0,IF($C3="FY2027",1,IF($C3="FY2028",2,IF($C3="FY2029",3,IF($C3="FY2030",4,0))))))+Scenarios!J2-ROUND(Scenarios!J2*Scenarios!$F2,0),BaselineCalc!$B$8+Scenarios!J2-ROUND(Scenarios!J2*Scenarios!$F2,0)) -> 296 | N3: =(L3-D3) + (M3-E3) -> 0 | O3: =(Parameters_Public!$C$22*(L3-D3)+Parameters_Public!$C$23*(M3-E3)) -> 0 | P3: =YearMap!E3 -> 800 | Q3: =IF(Scenarios!N2="lease", YearMap!F3, YearMap!G3) -> 0.4 | R3: =IF(Scenarios!D2=1, Q3*H3, H3) -> 1439410.4 | S3: =IF(Scenarios!E2=1, Q3*I3, I3) -> 1657842.4 | T3: =IF(C3="FY2026", (Scenarios!D2+Scenarios!E2)*BaselineCalc!$B$22, 0) -> 0 | U3: =(R3+S3+G3*F3)*J3*(1-K3) -> 6686026.2 | V3: =O3*(G3+P3) -> 0 | W3: =U3+V3+IF(Parameters_Public!$C$26=1, T3, 0) -> 6686026.2 | X3: =IF(F3+O3>0, W3/(F3+O3),"") -> 12090.463 | Y3: =INDEX(YearMap!$I$2:$I$6, MATCH(C3, YearMap!$A$2:$A$6, 0)) -> 5138.325 | Z3: =W3 - ((Y3 + IF(Parameters_Public!$C$20=1, Parameters_Public!$C$19, 0))*AC3) -> 3428704.1 | AA3: =IF($AC3>0, $Z3/$AC3, 0) -> 6200.1883 | AB3: =MAX(0, (MAX(0, $D3-BaselineCalc!$B$7) + MAX(0, $E3-BaselineCalc!$B$8))) -> 0 | AC3: =IF(LEFT($B3,2)="A_", $O3, IF(LEFT($B3,2)="B_", $M3+$O3, IF(LEFT($B3,2)="C_", $L3+$O3, $F3))) -> 553 | AD3: =((Y3 + IF(Parameters_Public!$C$20=1, INDEX(YearMap!$O$2:$O$6, MATCH(C3, YearMap!$A$2:$A$6, 0)), 0))*AC3) + AC3*INDEX(YearMap!$P$2:$P$6, MATCH(C3, YearMap!$A$2:$A$6, 0)) -> 6215207.8 | AE3: =W3 - (1-Parameters_Public!$C42)*$G3*$AB3*$J3*(1-$K3) -> 6686026.2 | AF3: =AD3-AE3 -> -470818.41 | AG3: =B3&"|"&C3 -> D_CUSTOM1|FY2027
A4: =AG4 -> D_CUSTOM1|FY2028 | B4: =Scenarios!A2 -> D_CUSTOM1 | C4: FY2028 | D4: =IF(Scenarios!D2=1,0, L4) -> 257 | E4: =IF(Scenarios!E2=1,0, M4) -> 296 | F4: =D4+E4 -> 553 | G4: =YearMap!B4 -> 6739.2461 | H4: =YearMap!C4 -> 1475395.7 | I4: =YearMap!D4 -> 1699288.4 | J4: =1-BaselineCalc!$B$5 -> 0.993 | K4: =Scenarios!G2 -> 0 | L4: =IF(Scenarios!$Q2=1,BaselineCalc!$B$7*(1+Parameters_Public!$C44)^(IF($C4="FY2026",0,IF($C4="FY2027",1,IF($C4="FY2028",2,IF($C4="FY2029",3,IF($C4="FY2030",4,0))))))+ROUND(Scenarios!K2*Scenarios!$F2,0),BaselineCalc!$B$7+ROUND(Scenarios!K2*Scenarios!$F2,0)) -> 257 | M4: =IF(Scenarios!$R2=1,BaselineCalc!$B$8*(1+Parameters_Public!$C45)^(IF($C4="FY2026",0,IF($C4="FY2027",1,IF($C4="FY2028",2,IF($C4="FY2029",3,IF($C4="FY2030",4,0))))))+Scenarios!K2-ROUND(Scenarios!K2*Scenarios!$F2,0),BaselineCalc!$B$8+Scenarios!K2-ROUND(Scenarios!K2*Scenarios!$F2,0)) -> 296 | N4: =(L4-D4) + (M4-E4) -> 0 | O4: =(Parameters_Public!$C$22*(L4-D4)+Parameters_Public!$C$23*(M4-E4)) -> 0 | P4: =YearMap!E4 -> 600 | Q4: =IF(Scenarios!N2="lease", YearMap!F4, YearMap!G4) -> 0.35 | R4: =IF(Scenarios!D2=1, Q4*H4, H4) -> 1475395.7 | S4: =IF(Scenarios!E2=1, Q4*I4, I4) -> 1699288.4 | T4: =IF(C4="FY2026", (Scenarios!D2+Scenarios!E2)*BaselineCalc!$B$22, 0) -> 0 | U4: =(R4+S4+G4*F4)*J4*(1-K4) -> 6853176.8 | V4: =O4*(G4+P4) -> 0 | W4: =U4+V4+IF(Parameters_Public!$C$26=1, T4, 0) -> 6853176.8 | X4: =IF(F4+O4>0, W4/(F4+O4),"") -> 12392.725 | Y4: =INDEX(YearMap!$I$2:$I$6, MATCH(C4, YearMap!$A$2:$A$6, 0)) -> 5266.7831 | Z4: =W4 - ((Y4 + IF(Parameters_Public!$C$20=1, Parameters_Public!$C$19, 0))*AC4) -> 3524817.4 | AA4: =IF($AC4>0, $Z4/$AC4, 0) -> 6373.9917 | AB4: =MAX(0, (MAX(0, $D4-BaselineCalc!$B$7) + MAX(0, $E4-BaselineCalc!$B$8))) -> 0 | AC4: =IF(LEFT($B4,2)="A_", $O4, IF(LEFT($B4,2)="B_", $M4+$O4, IF(LEFT($B4,2)="C_", $L4+$O4, $F4))) -> 553 | AD4: =((Y4 + IF(Parameters_Public!$C$20=1, INDEX(YearMap!$O$2:$O$6, MATCH(C4, YearMap!$A$2:$A$6, 0)), 0))*AC4) + AC4*INDEX(YearMap!$P$2:$P$6, MATCH(C4, YearMap!$A$2:$A$6, 0)) -> 6370588 | AE4: =W4 - (1-Parameters_Public!$C42)*$G4*$AB4*$J4*(1-$K4) -> 6853176.8 | AF4: =AD4-AE4 -> -482588.87 | AG4: =B4&"|"&C4 -> D_CUSTOM1|FY2028
A5: =AG5 -> D_CUSTOM1|FY2029 | B5: =Scenarios!A2 -> D_CUSTOM1 | C5: FY2029 | D5: =IF(Scenarios!D2=1,0, L5) -> 257 | E5: =IF(Scenarios!E2=1,0, M5) -> 296 | F5: =D5+E5 -> 553 | G5: =YearMap!B5 -> 6907.7273 | H5: =YearMap!C5 -> 1512280.6 | I5: =YearMap!D5 -> 1741770.6 | J5: =1-BaselineCalc!$B$5 -> 0.993 | K5: =Scenarios!G2 -> 0 | L5: =IF(Scenarios!$Q2=1,BaselineCalc!$B$7*(1+Parameters_Public!$C44)^(IF($C5="FY2026",0,IF($C5="FY2027",1,IF($C5="FY2028",2,IF($C5="FY2029",3,IF($C5="FY2030",4,0))))))+ROUND(Scenarios!L2*Scenarios!$F2,0),BaselineCalc!$B$7+ROUND(Scenarios!L2*Scenarios!$F2,0)) -> 257 | M5: =IF(Scenarios!$R2=1,BaselineCalc!$B$8*(1+Parameters_Public!$C45)^(IF($C5="FY2026",0,IF($C5="FY2027",1,IF($C5="FY2028",2,IF($C5="FY2029",3,IF($C5="FY2030",4,0))))))+Scenarios!L2-ROUND(Scenarios!L2*Scenarios!$F2,0),BaselineCalc!$B$8+Scenarios!L2-ROUND(Scenarios!L2*Scenarios!$F2,0)) -> 296 | N5: =(L5-D5) + (M5-E5) -> 0 | O5: =(Parameters_Public!$C$22*(L5-D5)+Parameters_Public!$C$23*(M5-E5)) -> 0 | P5: =YearMap!E5 -> 500 | Q5: =IF(Scenarios!N2="lease", YearMap!F5, YearMap!G5) -> 0.3 | R5: =IF(Scenarios!D2=1, Q5*H5, H5) -> 1512280.6 | S5: =IF(Scenarios!E2=1, Q5*I5, I5) -> 1741770.6 | T5: =IF(C5="FY2026", (Scenarios!D2+Scenarios!E2)*BaselineCalc!$B$22, 0) -> 0 | U5: =(R5+S5+G5*F5)*J5*(1-K5) -> 7024506.3 | V5: =O5*(G5+P5) -> 0 | W5: =U5+V5+IF(Parameters_Public!$C$26=1, T5, 0) -> 7024506.3 | X5: =IF(F5+O5>0, W5/(F5+O5),"") -> 12702.543 | Y5: =INDEX(YearMap!$I$2:$I$6, MATCH(C5, YearMap!$A$2:$A$6, 0)) -> 5398.4527 | Z5: =W5 - ((Y5 + IF(Parameters_Public!$C$20=1, Parameters_Public!$C$19, 0))*AC5) -> 3623333.6 | AA5: =IF($AC5>0, $Z5/$AC5, 0) -> 6552.1403 | AB5: =MAX(0, (MAX(0, $D5-BaselineCalc!$B$7) + MAX(0, $E5-BaselineCalc!$B$8))) -> 0 | AC5: =IF(LEFT($B5,2)="A_", $O5, IF(LEFT($B5,2)="B_", $M5+$O5, IF(LEFT($B5,2)="C_", $L5+$O5, $F5))) -> 553 | AD5: =((Y5 + IF(Parameters_Public!$C$20=1, INDEX(YearMap!$O$2:$O$6, MATCH(C5, YearMap!$A$2:$A$6, 0)), 0))*AC5) + AC5*INDEX(YearMap!$P$2:$P$6, MATCH(C5, YearMap!$A$2:$A$6, 0)) -> 6529852.7 | AE5: =W5 - (1-Parameters_Public!$C42)*$G5*$AB5*$J5*(1-$K5) -> 7024506.3 | AF5: =AD5-AE5 -> -494653.59 | AG5: =B5&"|"&C5 -> D_CUSTOM1|FY2029
A6: =AG6 -> D_CUSTOM1|FY2030 | B6: =Scenarios!A2 -> D_CUSTOM1 | C6: FY2030 | D6: =IF(Scenarios!D2=1,0, L6) -> 257 | E6: =IF(Scenarios!E2=1,0, M6) -> 296 | F6: =D6+E6 -> 553 | G6: =YearMap!B6 -> 7080.4205 | H6: =YearMap!C6 -> 1550087.6 | I6: =YearMap!D6 -> 1785314.9 | J6: =1-BaselineCalc!$B$5 -> 0.993 | K6: =Scenarios!G2 -> 0 | L6: =IF(Scenarios!$Q2=1,BaselineCalc!$B$7*(1+Parameters_Public!$C44)^(IF($C6="FY2026",0,IF($C6="FY2027",1,IF($C6="FY2028",2,IF($C6="FY2029",3,IF($C6="FY2030",4,0))))))+ROUND(Scenarios!M2*Scenarios!$F2,0),BaselineCalc!$B$7+ROUND(Scenarios!M2*Scenarios!$F2,0)) -> 257 | M6: =IF(Scenarios!$R2=1,BaselineCalc!$B$8*(1+Parameters_Public!$C45)^(IF($C6="FY2026",0,IF($C6="FY2027",1,IF($C6="FY2028",2,IF($C6="FY2029",3,IF($C6="FY2030",4,0))))))+Scenarios!M2-ROUND(Scenarios!M2*Scenarios!$F2,0),BaselineCalc!$B$8+Scenarios!M2-ROUND(Scenarios!M2*Scenarios!$F2,0)) -> 296 | N6: =(L6-D6) + (M6-E6) -> 0 | O6: =(Parameters_Public!$C$22*(L6-D6)+Parameters_Public!$C$23*(M6-E6)) -> 0 | P6: =YearMap!E6 -> 300 | Q6: =IF(Scenarios!N2="lease", YearMap!F6, YearMap!G6) -> 0.3 | R6: =IF(Scenarios!D2=1, Q6*H6, H6) -> 1550087.6 | S6: =IF(Scenarios!E2=1, Q6*I6, I6) -> 1785314.9 | T6: =IF(C6="FY2026", (Scenarios!D2+Scenarios!E2)*BaselineCalc!$B$22, 0) -> 0 | U6: =(R6+S6+G6*F6)*J6*(1-K6) -> 7200118.9 | V6: =O6*(G6+P6) -> 0 | W6: =U6+V6+IF(Parameters_Public!$C$26=1, T6, 0) -> 7200118.9 | X6: =IF(F6+O6>0, W6/(F6+O6),"") -> 13020.107 | Y6: =INDEX(YearMap!$I$2:$I$6, MATCH(C6, YearMap!$A$2:$A$6, 0)) -> 5533.414 | Z6: =W6 - ((Y6 + IF(Parameters_Public!$C$20=1, Parameters_Public!$C$19, 0))*AC6) -> 3724312.6 | AA6: =IF($AC6>0, $Z6/$AC6, 0) -> 6734.7425 | AB6: =MAX(0, (MAX(0, $D6-BaselineCalc!$B$7) + MAX(0, $E6-BaselineCalc!$B$8))) -> 0 | AC6: =IF(LEFT($B6,2)="A_", $O6, IF(LEFT($B6,2)="B_", $M6+$O6, IF(LEFT($B6,2)="C_", $L6+$O6, $F6))) -> 553 | AD6: =((Y6 + IF(Parameters_Public!$C$20=1, INDEX(YearMap!$O$2:$O$6, MATCH(C6, YearMap!$A$2:$A$6, 0)), 0))*AC6) + AC6*INDEX(YearMap!$P$2:$P$6, MATCH(C6, YearMap!$A$2:$A$6, 0)) -> 6693099 | AE6: =W6 - (1-Parameters_Public!$C42)*$G6*$AB6*$J6*(1-$K6) -> 7200118.9 | AF6: =AD6-AE6 -> -507019.93 | AG6: =B6&"|"&C6 -> D_CUSTOM1|FY2030
A7: =AG7 -> E_StatusQuo_Targets|FY2026 | B7: =Scenarios!A3 -> E_StatusQuo_Targets | C7: FY2026 | D7: =IF(Scenarios!D3=1,0, L7) -> 274 | E7: =IF(Scenarios!E3=1,0, M7) -> 312.33333 | F7: =D7+E7 -> 586.33333 | G7: =YearMap!B2 -> 6414.5115 | H7: =YearMap!C2 -> 1404302.9 | I7: =YearMap!D2 -> 1617407.2 | J7: =1-BaselineCalc!$B$5 -> 0.993 | K7: =Scenarios!G3 -> 0 | L7: =IF(Scenarios!$Q3=1,BaselineCalc!$B$7*(1+Parameters_Public!$C44)^(IF($C7="FY2026",0,IF($C7="FY2027",1,IF($C7="FY2028",2,IF($C7="FY2029",3,IF($C7="FY2030",4,0))))))+ROUND(Scenarios!I3*Scenarios!$F3,0),BaselineCalc!$B$7+ROUND(Scenarios!I3*Scenarios!$F3,0)) -> 274 | M7: =IF(Scenarios!$R3=1,BaselineCalc!$B$8*(1+Parameters_Public!$C45)^(IF($C7="FY2026",0,IF($C7="FY2027",1,IF($C7="FY2028",2,IF($C7="FY2029",3,IF($C7="FY2030",4,0))))))+Scenarios!I3-ROUND(Scenarios!I3*Scenarios!$F3,0),BaselineCalc!$B$8+Scenarios!I3-ROUND(Scenarios!I3*Scenarios!$F3,0)) -> 312.33333 | N7: =(L7-D7) + (M7-E7) -> 0 | O7: =(Parameters_Public!$C$22*(L7-D7)+Parameters_Public!$C$23*(M7-E7)) -> 0 | P7: =YearMap!E2 -> 1000 | Q7: =IF(Scenarios!N3="lease", YearMap!F2, YearMap!G2) -> 0.5 | R7: =IF(Scenarios!D3=1, Q7*H7, H7) -> 1404302.9 | S7: =IF(Scenarios!E3=1, Q7*I7, I7) -> 1617407.2 | T7: =IF(C7="FY2026", (Scenarios!D3+Scenarios!E3)*BaselineCalc!$B$22, 0) -> 0 | U7: =(R7+S7+G7*F7)*J7*(1-K7) -> 6735272.7 | V7: =O7*(G7+P7) -> 0 | W7: =U7+V7+IF(Parameters_Public!$C$26=1, T7, 0) -> 6735272.7 | X7: =IF(F7+O7>0, W7/(F7+O7),"") -> 11487.105 | Y7: =INDEX(YearMap!$I$2:$I$6, MATCH(C7, YearMap!$A$2:$A$6, 0)) -> 5013 | Z7: =W7 - ((Y7 + IF(Parameters_Public!$C$20=1, Parameters_Public!$C$19, 0))*AC7) -> 3355090.4 | AA7: =IF($AC7>0, $Z7/$AC7, 0) -> 5722.1552 | AB7: =MAX(0, (MAX(0, $D7-BaselineCalc!$B$7) + MAX(0, $E7-BaselineCalc!$B$8))) -> 33.333333 | AC7: =IF(LEFT($B7,2)="A_", $O7, IF(LEFT($B7,2)="B_", $M7+$O7, IF(LEFT($B7,2)="C_", $L7+$O7, $F7))) -> 586.33333 | AD7: =((Y7 + IF(Parameters_Public!$C$20=1, INDEX(YearMap!$O$2:$O$6, MATCH(C7, YearMap!$A$2:$A$6, 0)), 0))*AC7) + AC7*INDEX(YearMap!$P$2:$P$6, MATCH(C7, YearMap!$A$2:$A$6, 0)) -> 6429115.7 | AE7: =W7 - (1-Parameters_Public!$C42)*$G7*$AB7*$J7*(1-$K7) -> 6522952.4 | AF7: =AD7-AE7 -> -93836.697 | AG7: =B7&"|"&C7 -> E_StatusQuo_Targets|FY2026
A8: =AG8 -> E_StatusQuo_Targets|FY2027 | B8: =Scenarios!A3 -> E_StatusQuo_Targets | C8: FY2027 | D8: =IF(Scenarios!D3=1,0, L8) -> 290 | E8: =IF(Scenarios!E3=1,0, M8) -> 329.66667 | F8: =D8+E8 -> 619.66667 | G8: =YearMap!B3 -> 6574.8743 | H8: =YearMap!C3 -> 1439410.4 | I8: =YearMap!D3 -> 1657842.4 | J8: =1-BaselineCalc!$B$5 -> 0.993 | K8: =Scenarios!G3 -> 0 | L8: =IF(Scenarios!$Q3=1,BaselineCalc!$B$7*(1+Parameters_Public!$C44)^(IF($C8="FY2026",0,IF($C8="FY2027",1,IF($C8="FY2028",2,IF($C8="FY2029",3,IF($C8="FY2030",4,0))))))+ROUND(Scenarios!J3*Scenarios!$F3,0),BaselineCalc!$B$7+ROUND(Scenarios!J3*Scenarios!$F3,0)) -> 290 | M8: =IF(Scenarios!$R3=1,BaselineCalc!$B$8*(1+Parameters_Public!$C45)^(IF($C8="FY2026",0,IF($C8="FY2027",1,IF($C8="FY2028",2,IF($C8="FY2029",3,IF($C8="FY2030",4,0))))))+Scenarios!J3-ROUND(Scenarios!J3*Scenarios!$F3,0),BaselineCalc!$B$8+Scenarios!J3-ROUND(Scenarios!J3*Scenarios!$F3,0)) -> 329.66667 | N8: =(L8-D8) + (M8-E8) -> 0 | O8: =(Parameters_Public!$C$22*(L8-D8)+Parameters_Public!$C$23*(M8-E8)) -> 0 | P8: =YearMap!E3 -> 800 | Q8: =IF(Scenarios!N3="lease", YearMap!F3, YearMap!G3) -> 0.4 | R8: =IF(Scenarios!D3=1, Q8*H8, H8) -> 1439410.4 | S8: =IF(Scenarios!E3=1, Q8*I8, I8) -> 1657842.4 | T8: =IF(C8="FY2026", (Scenarios!D3+Scenarios!E3)*BaselineCalc!$B$22, 0) -> 0 | U8: =(R8+S8+G8*F8)*J8*(1-K8) -> 7121282.9 | V8: =O8*(G8+P8) -> 0 | W8: =U8+V8+IF(Parameters_Public!$C$26=1, T8, 0) -> 7121282.9 | X8: =IF(F8+O8>0, W8/(F8+O8),"") -> 11492.119 | Y8: =INDEX(YearMap!$I$2:$I$6, MATCH(C8, YearMap!$A$2:$A$6, 0)) -> 5138.325 | Z8: =W8 - ((Y8 + IF(Parameters_Public!$C$20=1, Parameters_Public!$C$19, 0))*AC8) -> 3471275.8 | AA8: =IF($AC8>0, $Z8/$AC8, 0) -> 5601.8437 | AB8: =MAX(0, (MAX(0, $D8-BaselineCalc!$B$7) + MAX(0, $E8-BaselineCalc!$B$8))) -> 66.666667 | AC8: =IF(LEFT($B8,2)="A_", $O8, IF(LEFT($B8,2)="B_", $M8+$O8, IF(LEFT($B8,2)="C_", $L8+$O8, $F8))) -> 619.66667 | AD8: =((Y8 + IF(Parameters_Public!$C$20=1, INDEX(YearMap!$O$2:$O$6, MATCH(C8, YearMap!$A$2:$A$6, 0)), 0))*AC8) + AC8*INDEX(YearMap!$P$2:$P$6, MATCH(C8, YearMap!$A$2:$A$6, 0)) -> 6964479.4 | AE8: =W8 - (1-Parameters_Public!$C42)*$G8*$AB8*$J8*(1-$K8) -> 6686026.2 | AF8: =AD8-AE8 -> 278453.18 | AG8: =B8&"|"&C8 -> E_StatusQuo_Targets|FY2027
