Workbook
Name ADM_Day_Select: Parameters_Public!C8
Name Aid_growth: BaselineCalc!B28
Name Base_Aid_per_ADM: Parameters_Public!C18
Name BaseAid_per_ADM: Parameters_Public!C18
Name Capex_ArtsHub: Parameters_Public!C28
Name Capex_in_MO_Toggle: Parameters_Public!C30
Name Capex_InnovHub: Parameters_Public!C29
Name Echo_ADM0: Parameters_Public!C10
Name Echo_ADM0_selected: Parameters_Public!C10
Name Echo_retention_r: Parameters_Public!C23
Name EchoFixed_FY25_Total: Site_Fixed!C8
Name f_lease_profile: Control_Center!$D$23:$H$23
Name f_ops_profile: Control_Center!$D$22:$H$22
Name Growth_overhead_alpha: Parameters_Public!C47
Name h_taper_profile: Control_Center!$C$22:$G$26
Name Incremental_uplift_alpha: Parameters_Public!C49
Name M_O_per_ADM_Audited: Parameters_Public!C14
Name MarginalFactor_for_Overlay: Parameters_Public!C43
Name MO_inflation: Control_Center!C6
Name Override_per_ADM_proxy: Parameters_Public!C19
Name Override_percent: Parameters_Public!C17
Name Override_toggle: Parameters_Public!C20
Name Pima_ADM0: Parameters_Public!C11
Name Pima_ADM0_selected: Parameters_Public!C11
Name Pima_retention_r: Parameters_Public!C24
Name PimaFixed_FY25_Total: Site_Fixed!C15
Name Portable_seat_cost: Parameters_Public!C34
Name TI_in_MO_Toggle: Parameters_Public!C26
Name TI_per_Site: Parameters_Public!C27
Name Uplift_base_per_ADM: Parameters_Public!C21

Sheet Workbook_Purpose_Overview

Sheet How_To_Use_The_Workbook
B1: How to use the workbook
B2: Start on Scenario_Comparison: choose two scenarios to compare; review the operational, capital, and student-related results.
B3: Test assumptions (override switch, retention r, trend flags) only if you would like to check sensitivity.
B4: Check capacity gates (receiving bands).
B5: Open Budget_Neutral_Calculator if you’re considering a non‑repurpose plan: it shows N⁰—how many students are needed to be Net ≥ 0.
B6: Look at Summary_Figures to scan all scenarios with the same signals.
B7: Use Inputs_Definitions_Sources for terms, references, and what’s still awaiting audited paste.
B8: Check What_Is_$900K_Savings if you are curious xxxxxx

Sheet Scenario_Comparison
B1: Echo & Pima — Go-forward scenario comparison view
B3: Scenarios (CHOOSE) | C3: Description | I3: Assumed enrollment change (over 3 yrs)
B4: A2_Repurpose_Both_lease | C4: =VLOOKUP($B4,Scenarios!$A$2:$C$15, 2, 0) -> Repurpose both Echo & Pima; lease both properties; fixed cost reduction rate, retention %, and transition cost assumptions are key drivers | J4: =IF(ROUND(SUMIFS(MultiYear_ProForma!$AC:$AC,MultiYear_ProForma!$B:$B,$B4,MultiYear_ProForma!$C:$C,"FY2030")-BaselineCalc!$B$9, 0)>0, "+"&ROUND(SUMIFS(MultiYear_ProForma!$AC:$AC,MultiYear_ProForma!$B:$B,$B4,MultiYear_ProForma!$C:$C,"FY2030")-BaselineCalc!$B$9, 0), ROUND(SUMIFS(MultiYear_ProForma!$AC:$AC,MultiYear_ProForma!$B:$B,$B4,MultiYear_ProForma!$C:$C,"FY2030")-BaselineCalc!$B$9, 0)) -> -147
B5: E1_StatusQuo_Decline | C5: =VLOOKUP($B5,Scenarios!$A$2:$C$15, 2, 0) -> Echo & Pima open; no operational or strategic growth actions; enrollment decline trend continues | J5: =IF(ROUND(SUMIFS(MultiYear_ProForma!$AC:$AC,MultiYear_ProForma!$B:$B,$B5,MultiYear_ProForma!$C:$C,"FY2030")-BaselineCalc!$B$9, 0)>0, "+"&ROUND(SUMIFS(MultiYear_ProForma!$AC:$AC,MultiYear_ProForma!$B:$B,$B5,MultiYear_ProForma!$C:$C,"FY2030")-BaselineCalc!$B$9, 0), ROUND(SUMIFS(MultiYear_ProForma!$AC:$AC,MultiYear_ProForma!$B:$B,$B5,MultiYear_ProForma!$C:$C,"FY2030")-BaselineCalc!$B$9, 0)) -> -43
B24: Notes: Assumptions reflect: r (retention assumptions), override, marginal factor (e.g. assumed reduced variable cost to add new students), trend flags; h (receiving schools transportation route adjustment premium) tapers yearly. Receiving site should not exceed spare seats + portables
B26: Year | C26: Operating Net$ (Base) | D26: Operating Net$ (Comparator)
B27: FY2026 | C27: =SUMIFS(MultiYear_ProForma!$AF$2:$AF$66, MultiYear_ProForma!$B$2:$B$66, $B$4, MultiYear_ProForma!$C$2:$C$66, "FY2026") -> 840656.32 | D27: =SUMIFS(MultiYear_ProForma!$AF$2:$AF$66, MultiYear_ProForma!$B$2:$B$66, $B$5, MultiYear_ProForma!$C$2:$C$66, "FY2026") -> -459335.03
B28: FY2027 | C28: =SUMIFS(MultiYear_ProForma!$AF$2:$AF$66, MultiYear_ProForma!$B$2:$B$66, $B$4, MultiYear_ProForma!$C$2:$C$66, "FY2027") -> 952977.73 | D28: =SUMIFS(MultiYear_ProForma!$AF$2:$AF$66, MultiYear_ProForma!$B$2:$B$66, $B$5, MultiYear_ProForma!$C$2:$C$66, "FY2027") -> -522913.48
B29: FY2028 | C29: =SUMIFS(MultiYear_ProForma!$AF$2:$AF$66, MultiYear_ProForma!$B$2:$B$66, $B$4, MultiYear_ProForma!$C$2:$C$66, "FY2028") -> 1223701.2 | D29: =SUMIFS(MultiYear_ProForma!$AF$2:$AF$66, MultiYear_ProForma!$B$2:$B$66, $B$5, MultiYear_ProForma!$C$2:$C$66, "FY2028") -> -588315.82
B30: FY2029 | C30: =SUMIFS(MultiYear_ProForma!$AF$2:$AF$66, MultiYear_ProForma!$B$2:$B$66, $B$4, MultiYear_ProForma!$C$2:$C$66, "FY2029") -> 1462524.4 | D30: =SUMIFS(MultiYear_ProForma!$AF$2:$AF$66, MultiYear_ProForma!$B$2:$B$66, $B$5, MultiYear_ProForma!$C$2:$C$66, "FY2029") -> -655588.7
B31: FY2030 | C31: =SUMIFS(MultiYear_ProForma!$AF$2:$AF$66, MultiYear_ProForma!$B$2:$B$66, $B$4, MultiYear_ProForma!$C$2:$C$66, "FY2030") -> 1585320 | D31: =SUMIFS(MultiYear_ProForma!$AF$2:$AF$66, MultiYear_ProForma!$B$2:$B$66, $B$5, MultiYear_ProForma!$C$2:$C$66, "FY2030") -> -724779.94
B33: Assumptions (from Parameters_Public / Control_Center)
B34: Retention r (Echo central) | C34: =Parameters_Public!C23 -> 0.6
B35: Retention r (Pima central) | C35: =Parameters_Public!C24 -> 0.85
B36: MarginalFactor_for_Overlay | C36: =Parameters_Public!C43 -> 0.6
B37: Override % | C37: =Parameters_Public!C17 -> 0.15
B38: Override toggle (0/1) | C38: =Parameters_Public!C20 -> 1
B39: Keep-open ops savings (fraction of MO) | C39: =Control_Center!C10 -> 0.007
B40: Extra savings for co-location (fraction of MO) | C40: =Control_Center!C11 -> 0.015
B41: • Routing/admin overhead h tapers by year (see YearMap). Try ±20% sensitivity when routing assumptions are uncertain.
D43: Interpretation
B44: One-time Capital FY 2026 (Base) | C44: =SUMIFS(Capital_Summary!$H$4:$H$83, Capital_Summary!$A$4:$A$83, B4, Capital_Summary!$B$4:$B$83, "FY2026") -> 2314480 | D44: =""&$B$5&" will be $"&TEXT(ROUND(ABS(C45-C44),0), "#,##0")&" "&IF(C45>C44,"MORE COSTLY","LESS COSTLY")&" than "&$B$4&" in terms of capital investment required " -> E1_StatusQuo_Decline will be $2,314,480 LESS COSTLY than A2_Repurpose_Both_lease in terms of capital investment required
B45: One-time Capital FY 2026 (Comparator) | C45: =SUMIFS(Capital_Summary!$H$4:$H$83, Capital_Summary!$A$4:$A$83, B5, Capital_Summary!$B$4:$B$83, "FY2026") -> 0
B47: Avg Net (FY26–30) (Base)—rounded | C47: =ROUND((SUMIFS(MultiYear_ProForma!$AF$2:$AF$66,MultiYear_ProForma!$B$2:$B$66,$B$4,MultiYear_ProForma!$C$2:$C$66,"FY2026")+SUMIFS(MultiYear_ProForma!$AF$2:$AF$66,MultiYear_ProForma!$B$2:$B$66,$B$4,MultiYear_ProForma!$C$2:$C$66,"FY2027")+SUMIFS(MultiYear_ProForma!$AF$2:$AF$66,MultiYear_ProForma!$B$2:$B$66,$B$4,MultiYear_ProForma!$C$2:$C$66,"FY2028")+SUMIFS(MultiYear_ProForma!$AF$2:$AF$66,MultiYear_ProForma!$B$2:$B$66,$B$4,MultiYear_ProForma!$C$2:$C$66,"FY2029")+SUMIFS(MultiYear_ProForma!$AF$2:$AF$66,MultiYear_ProForma!$B$2:$B$66,$B$4,MultiYear_ProForma!$C$2:$C$66,"FY2030"))/5,-4) -> 1210000 | D47: ="On average from 2026 through 2030, "&$B$5&" will be $"&TEXT(ABS(ROUND(C49,0)), "#,##0")&" "&IF(C49<0,"MORE COSTLY","LESS COSTLY")&" to operate annually than "&$B$4&"" -> On average from 2026 through 2030, E1_StatusQuo_Decline will be $1,700,000 MORE COSTLY to operate annually than A2_Repurpose_Both_lease
B48: Avg Net (FY26–30) (Comparator)—rounded | C48: =ROUND((SUMIFS(MultiYear_ProForma!$AF$2:$AF$66, MultiYear_ProForma!$B$2:$B$66, $B$5, MultiYear_ProForma!$C$2:$C$66, "FY2026")+SUMIFS(MultiYear_ProForma!$AF$2:$AF$66, MultiYear_ProForma!$B$2:$B$66, $C$5, MultiYear_ProForma!$C$2:$C$66, "FY2027")+SUMIFS(MultiYear_ProForma!$AF$2:$AF$66, MultiYear_ProForma!$B$2:$B$66, $B$5, MultiYear_ProForma!$C$2:$C$66, "FY2028")+SUMIFS(MultiYear_ProForma!$AF$2:$AF$66, MultiYear_ProForma!$B$2:$B$66, $B$5, MultiYear_ProForma!$C$2:$C$66, "FY2029")+SUMIFS(MultiYear_ProForma!$AF$2:$AF$66, MultiYear_ProForma!$B$2:$B$66, $B$5, MultiYear_ProForma!$C$2:$C$66, "FY2030"))/5, -4) -> -490000
B49: Δ vs Base (Avg FY26–30)—rounded | C49: =ROUND(C48-C47, -4) -> -1700000
B52: FY2030 Net (Base)—rounded | C52: =ROUND(SUMIFS(MultiYear_ProForma!$AF$2:$AF$66, MultiYear_ProForma!$B$2:$B$66, $B$4, MultiYear_ProForma!$C$2:$C$66, "FY2030"), -4) -> 1590000 | D52: ="By 2030, "&$B$5&" will be $"&TEXT(ABS(ROUND(C54,0)), "#,##0")&" "&IF(C54<0,"MORE COSTLY","LESS COSTLY")&" to operate annually than "&$B$4&"" -> By 2030, E1_StatusQuo_Decline will be $2,310,000 MORE COSTLY to operate annually than A2_Repurpose_Both_lease
B53: FY2030 Net (Comparator)—rounded | C53: =ROUND(SUMIFS(MultiYear_ProForma!$AF$2:$AF$66, MultiYear_ProForma!$B$2:$B$66, $B$5, MultiYear_ProForma!$C$2:$C$66, "FY2030"), -4) -> -720000
B54: Δ vs Base (FY2030)—rounded | C54: =ROUND(C53-C52, -4) -> -2310000
B56: Students displaced (FY26) (Base) | C56: =SUMIFS(MultiYear_ProForma!$N$2:$N$66, MultiYear_ProForma!$B$2:$B$66, $B$4, MultiYear_ProForma!$C$2:$C$66, "FY2026") -> 553 | D56: =""&$B$5&" will displace "&ROUND(ABS(C57-C56),0)&" "&IF(C57>C56,"MORE STUDENTS","FEWER STUDENTS")&" than "&$B$4&"" -> E1_StatusQuo_Decline will displace 553 FEWER STUDENTS than A2_Repurpose_Both_lease
B57: Students displaced (FY26) (Comparator) | C57: =SUMIFS(MultiYear_ProForma!$N$2:$N$66, MultiYear_ProForma!$B$2:$B$66, $B$5, MultiYear_ProForma!$C$2:$C$66, "FY2026") -> 0
B59: Students served (FY2030) (Base) | C59: =SUMIFS(MultiYear_ProForma!$AC$2:$AC$66, MultiYear_ProForma!$B$2:$B$66, $B$4, MultiYear_ProForma!$C$2:$C$66, "FY2030") -> 405.8 | D59: =""&$B$5&" will serve "&ROUND(ABS(C60-C59),0)&" "&IF(C60>C59,"MORE STUDENTS","FEWER STUDENTS")&" than "&$B$4&"" -> E1_StatusQuo_Decline will serve 104 MORE STUDENTS than A2_Repurpose_Both_lease
B60: Students served (FY2030) (Comparator) | C60: =SUMIFS(MultiYear_ProForma!$AC$2:$AC$66, MultiYear_ProForma!$B$2:$B$66, $B$5, MultiYear_ProForma!$C$2:$C$66, "FY2030") -> 510.06959

Sheet What_Is_The_$900K_Savings

Sheet Budget_Neutral_Calculator
B1: Budget‑Neutral Calculator (Operating $)
B3: Scenario (Choose one): | C3: E1_StatusQuo_Decline
B5: Metric | C5: FY2026 | D5: FY2030
B6: mᵗ: Incremental margin per added ADM | C6: =INDEX(YearMap!$I$2:$I$6, MATCH("FY2026",YearMap!$A$2:$A$6,0))+IF(Override_toggle=1, INDEX(YearMap!$O$2:$O$6, MATCH("FY2026",YearMap!$A$2:$A$6,0)),0)+INDEX(YearMap!$P$2:$P$6, MATCH("FY2026",YearMap!$A$2:$A$6,0))-INDEX(YearMap!$B$2:$B$6, MATCH("FY2026",YearMap!$A$2:$A$6,0))-INDEX(YearMap!$Q$2:$Q$6, MATCH("FY2026",YearMap!$A$2:$A$6,0)) -> 3598.4885 | D6: =INDEX(YearMap!$I$2:$I$6, MATCH("FY2030",YearMap!$A$2:$A$6,0))+IF(Override_toggle=1, INDEX(YearMap!$O$2:$O$6, MATCH("FY2030",YearMap!$A$2:$A$6,0)),0)+INDEX(YearMap!$P$2:$P$6, MATCH("FY2030",YearMap!$A$2:$A$6,0))-INDEX(YearMap!$B$2:$B$6, MATCH("FY2030",YearMap!$A$2:$A$6,0))-INDEX(YearMap!$Q$2:$Q$6, MATCH("FY2030",YearMap!$A$2:$A$6,0)) -> 4132.8206
B7: Net (operating) | C7: =SUMIFS(MultiYear_ProForma!$AF$2:$AF$66,MultiYear_ProForma!$B$2:$B$66,$C$3,MultiYear_ProForma!$C$2:$C$66,"FY2026") -> -459335.03 | D7: =SUMIFS(MultiYear_ProForma!$AF$2:$AF$66,MultiYear_ProForma!$B$2:$B$66,$C$3,MultiYear_ProForma!$C$2:$C$66,"FY2030") -> -724779.94
B8: N⁰: Additional students needed for Net ≥ 0 | C8: =IFERROR(MAX(0,-$C$7/$C$6),"") -> 127.64666 | D8: =IFERROR(MAX(0,-$D$7/$D$6),"") -> 175.37174
B10: Interpretation
B11: =IF(D8=0, "The "&C3&" is budget neutral or better given current assumptions in the model; additional enrollment is not necessary.", "Given current assumptions in the model, to be budget neutral by FY2030, the "&C3&" scenario requires enrollment of "&ROUND(D8, 0)&" additional students.") -> Given current assumptions in the model, to be budget neutral by FY2030, the E1_StatusQuo_Decline scenario requires enrollment of 175 additional students.
B13: Notes:
B14: This tool tests budget neutrality for any scenario: N⁰ = max(0, −Netₜ / mᵗ).
B15: mᵗ uses YearMap (Aid + Override_if_on + Uplift − VarUnit$ − Growth_overhead). Net excludes capital.

Sheet Summary_Figures
B1: Choose base scenario (for comparison): | C1: E1_StatusQuo_Decline | N1: Chart titles
A2: Net = (M&O operating) − (Aid + Override + Uplift). Capital is excluded. Uplift is indexed to Aid growth. | N2: ="(Comparison) Change in ops net $ by scenario compared to "&C1&" (Positive = savings)" -> (Comparison) Change in ops net $ by scenario compared to E1_StatusQuo_Decline (Positive = savings)
A3: Students: Displaced = FY2026; Served = FY2030 (open + retained). | N3: ="(Nominal) One-time capital (FY26) & Average 5-yr net ops $ by scenario" -> (Nominal) One-time capital (FY26) & Average 5-yr net ops $ by scenario
A4: Scenario key | B4: Scenario | C4: One-time Capital (FY26) | D4: Net FY26 Operational $ | E4: Net FY28 Operational $ | F4: Net FY30 Operational $ | G4: AVG 5-yr net operational $ | H4: Displaced students | I4: Served students FY30 | J4: Δ vs Base (FY2030 Net) | K4: Δ vs Base (5-yr Avg Net)
A5: =LEFT(B5, 2) -> F1 | B5: F1_CUSTOM1 | C5: =SUMIFS(Capital_Summary!$H$4:$H$83, Capital_Summary!$A$4:$A$83, B5, Capital_Summary!$B$4:$B$83, "FY2026")*-1 -> 0 | D5: =SUMIFS(MultiYear_ProForma!$AF$2:$AF$66, MultiYear_ProForma!$B$2:$B$66, B5, MultiYear_ProForma!$C$2:$C$66, "FY2026") -> -459335.03 | E5: =SUMIFS(MultiYear_ProForma!$AF$2:$AF$66, MultiYear_ProForma!$B$2:$B$66, B5, MultiYear_ProForma!$C$2:$C$66, "FY2028") -> -482588.87 | F5: =SUMIFS(MultiYear_ProForma!$AF$2:$AF$66, MultiYear_ProForma!$B$2:$B$66, B5, MultiYear_ProForma!$C$2:$C$66, "FY2030") -> -507019.93 | G5: =(SUMIFS(MultiYear_ProForma!$AF$2:$AF$66, MultiYear_ProForma!$B$2:$B$66, B5, MultiYear_ProForma!$C$2:$C$66, "FY2026")+SUMIFS(MultiYear_ProForma!$AF$2:$AF$66, MultiYear_ProForma!$B$2:$B$66, B5, MultiYear_ProForma!$C$2:$C$66, "FY2027")+SUMIFS(MultiYear_ProForma!$AF$2:$AF$66, MultiYear_ProForma!$B$2:$B$66, B5, MultiYear_ProForma!$C$2:$C$66, "FY2028")+SUMIFS(MultiYear_ProForma!$AF$2:$AF$66, MultiYear_ProForma!$B$2:$B$66, B5, MultiYear_ProForma!$C$2:$C$66, "FY2029")+SUMIFS(MultiYear_ProForma!$AF$2:$AF$66, MultiYear_ProForma!$B$2:$B$66, B5, MultiYear_ProForma!$C$2:$C$66, "FY2030"))/5 -> -482883.16 | H5: =SUMIFS(MultiYear_ProForma!$N$2:$N$66, MultiYear_ProForma!$B$2:$B$66, B5, MultiYear_ProForma!$C$2:$C$66, "FY2026") -> 0 | I5: =SUMIFS(MultiYear_ProForma!$AC$2:$AC$66, MultiYear_ProForma!$B$2:$B$66, B5, MultiYear_ProForma!$C$2:$C$66, "FY2030") -> 553 | J5: =F5-(VLOOKUP($C$1,$B$5:$G$17,5, 0)) -> 217760.01 | K5: =G5-(VLOOKUP($C$1,$B$5:$I$17,6, 0)) -> 107303.43
A6: =LEFT(B6, 2) -> E3 | B6: E3_StatusQuo_Targets | C6: =SUMIFS(Capital_Summary!$H$4:$H$83, Capital_Summary!$A$4:$A$83, B6, Capital_Summary!$B$4:$B$83, "FY2026")*-1 -> 0 | D6: =SUMIFS(MultiYear_ProForma!$AF$2:$AF$66, MultiYear_ProForma!$B$2:$B$66, B6, MultiYear_ProForma!$C$2:$C$66, "FY2030") -> 0 | E6: =SUMIFS(MultiYear_ProForma!$AF$2:$AF$66, MultiYear_ProForma!$B$2:$B$66, B6, MultiYear_ProForma!$C$2:$C$66, "FY2028") -> 0 | F6: =SUMIFS(MultiYear_ProForma!$AF$2:$AF$66, MultiYear_ProForma!$B$2:$B$66, B6, MultiYear_ProForma!$C$2:$C$66, "FY2030") -> 0 | G6: =(SUMIFS(MultiYear_ProForma!$AF$2:$AF$66, MultiYear_ProForma!$B$2:$B$66, B6, MultiYear_ProForma!$C$2:$C$66, "FY2026")+SUMIFS(MultiYear_ProForma!$AF$2:$AF$66, MultiYear_ProForma!$B$2:$B$66, B6, MultiYear_ProForma!$C$2:$C$66, "FY2027")+SUMIFS(MultiYear_ProForma!$AF$2:$AF$66, MultiYear_ProForma!$B$2:$B$66, B6, MultiYear_ProForma!$C$2:$C$66, "FY2028")+SUMIFS(MultiYear_ProForma!$AF$2:$AF$66, MultiYear_ProForma!$B$2:$B$66, B6, MultiYear_ProForma!$C$2:$C$66, "FY2029")+SUMIFS(MultiYear_ProForma!$AF$2:$AF$66, MultiYear_ProForma!$B$2:$B$66, B6, MultiYear_ProForma!$C$2:$C$66, "FY2030"))/5 -> 0 | H6: =SUMIFS(MultiYear_ProForma!$N$2:$N$66, MultiYear_ProForma!$B$2:$B$66, B6, MultiYear_ProForma!$C$2:$C$66, "FY2026") -> 0 | I6: =SUMIFS(MultiYear_ProForma!$AC$2:$AC$66, MultiYear_ProForma!$B$2:$B$66, B6, MultiYear_ProForma!$C$2:$C$66, "FY2030") -> 0 | J6: =F6-(VLOOKUP($C$1,$B$5:$G$17,5, 0)) -> 724779.94 | K6: =G6-(VLOOKUP($C$1,$B$5:$I$17,6, 0)) -> 590186.59
A7: =LEFT(B7, 2) -> D3 | B7: D3_CoLocation_Echo_Targets | C7: =SUMIFS(Capital_Summary!$H$4:$H$83, Capital_Summary!$A$4:$A$83, B7, Capital_Summary!$B$4:$B$83, "FY2026")*-1 -> 0 | D7: =SUMIFS(MultiYear_ProForma!$AF$2:$AF$66, MultiYear_ProForma!$B$2:$B$66, B7, MultiYear_ProForma!$C$2:$C$66, "FY2030") -> 412099.97 | E7: =SUMIFS(MultiYear_ProForma!$AF$2:$AF$66, MultiYear_ProForma!$B$2:$B$66, B7, MultiYear_ProForma!$C$2:$C$66, "FY2028") -> 389098.13 | F7: =SUMIFS(MultiYear_ProForma!$AF$2:$AF$66, MultiYear_ProForma!$B$2:$B$66, B7, MultiYear_ProForma!$C$2:$C$66, "FY2030") -> 412099.97 | G7: =(SUMIFS(MultiYear_ProForma!$AF$2:$AF$66, MultiYear_ProForma!$B$2:$B$66, B7, MultiYear_ProForma!$C$2:$C$66, "FY2026")+SUMIFS(MultiYear_ProForma!$AF$2:$AF$66, MultiYear_ProForma!$B$2:$B$66, B7, MultiYear_ProForma!$C$2:$C$66, "FY2027")+SUMIFS(MultiYear_ProForma!$AF$2:$AF$66, MultiYear_ProForma!$B$2:$B$66, B7, MultiYear_ProForma!$C$2:$C$66, "FY2028")+SUMIFS(MultiYear_ProForma!$AF$2:$AF$66, MultiYear_ProForma!$B$2:$B$66, B7, MultiYear_ProForma!$C$2:$C$66, "FY2029")+SUMIFS(MultiYear_ProForma!$AF$2:$AF$66, MultiYear_ProForma!$B$2:$B$66, B7, MultiYear_ProForma!$C$2:$C$66, "FY2030"))/5 -> 288107.49 | H7: =SUMIFS(MultiYear_ProForma!$N$2:$N$66, MultiYear_ProForma!$B$2:$B$66, B7, MultiYear_ProForma!$C$2:$C$66, "FY2026") -> 0 | I7: =SUMIFS(MultiYear_ProForma!$AC$2:$AC$66, MultiYear_ProForma!$B$2:$B$66, B7, MultiYear_ProForma!$C$2:$C$66, "FY2030") -> 603 | J7: =F7-(VLOOKUP($C$1,$B$5:$G$17,5, 0)) -> 1136879.9 | K7: =G7-(VLOOKUP($C$1,$B$5:$I$17,6, 0)) -> 878294.09
A8: =LEFT(B8, 2) -> D1 | B8: D1_Grow_Both_Targets | C8: =SUMIFS(Capital_Summary!$H$4:$H$83, Capital_Summary!$A$4:$A$83, B8, Capital_Summary!$B$4:$B$83, "FY2026")*-1 -> -2000000 | D8: =SUMIFS(MultiYear_ProForma!$AF$2:$AF$66, MultiYear_ProForma!$B$2:$B$66, B8, MultiYear_ProForma!$C$2:$C$66, "FY2030") -> 1170321.9 | E8: =SUMIFS(MultiYear_ProForma!$AF$2:$AF$66, MultiYear_ProForma!$B$2:$B$66, B8, MultiYear_ProForma!$C$2:$C$66, "FY2028") -> 1104495.6 | F8: =SUMIFS(MultiYear_ProForma!$AF$2:$AF$66, MultiYear_ProForma!$B$2:$B$66, B8, MultiYear_ProForma!$C$2:$C$66, "FY2030") -> 1170321.9 | G8: =(SUMIFS(MultiYear_ProForma!$AF$2:$AF$66, MultiYear_ProForma!$B$2:$B$66, B8, MultiYear_ProForma!$C$2:$C$66, "FY2026")+SUMIFS(MultiYear_ProForma!$AF$2:$AF$66, MultiYear_ProForma!$B$2:$B$66, B8, MultiYear_ProForma!$C$2:$C$66, "FY2027")+SUMIFS(MultiYear_ProForma!$AF$2:$AF$66, MultiYear_ProForma!$B$2:$B$66, B8, MultiYear_ProForma!$C$2:$C$66, "FY2028")+SUMIFS(MultiYear_ProForma!$AF$2:$AF$66, MultiYear_ProForma!$B$2:$B$66, B8, MultiYear_ProForma!$C$2:$C$66, "FY2029")+SUMIFS(MultiYear_ProForma!$AF$2:$AF$66, MultiYear_ProForma!$B$2:$B$66, B8, MultiYear_ProForma!$C$2:$C$66, "FY2030"))/5 -> 801485.39 | H8: =SUMIFS(MultiYear_ProForma!$N$2:$N$66, MultiYear_ProForma!$B$2:$B$66, B8, MultiYear_ProForma!$C$2:$C$66, "FY2026") -> 0 | I8: =SUMIFS(MultiYear_ProForma!$AC$2:$AC$66, MultiYear_ProForma!$B$2:$B$66, B8, MultiYear_ProForma!$C$2:$C$66, "FY2030") -> 703 | J8: =F8-(VLOOKUP($C$1,$B$5:$G$17,5, 0)) -> 1895101.9 | K8: =G8-(VLOOKUP($C$1,$B$5:$I$17,6, 0)) -> 1391672
A9: =LEFT(B9, 2) -> E2 | B9: E2_StatusQuo_Steady | C9: =SUMIFS(Capital_Summary!$H$4:$H$83, Capital_Summary!$A$4:$A$83, B9, Capital_Summary!$B$4:$B$83, "FY2026")*-1 -> 0 | D9: =SUMIFS(MultiYear_ProForma!$AF$2:$AF$66, MultiYear_ProForma!$B$2:$B$66, B9, MultiYear_ProForma!$C$2:$C$66, "FY2030") -> -507019.93 | E9: =SUMIFS(MultiYear_ProForma!$AF$2:$AF$66, MultiYear_ProForma!$B$2:$B$66, B9, MultiYear_ProForma!$C$2:$C$66, "FY2028") -> -482588.87 | F9: =SUMIFS(MultiYear_ProForma!$AF$2:$AF$66, MultiYear_ProForma!$B$2:$B$66, B9, MultiYear_ProForma!$C$2:$C$66, "FY2030") -> -507019.93 | G9: =(SUMIFS(MultiYear_ProForma!$AF$2:$AF$66, MultiYear_ProForma!$B$2:$B$66, B9, MultiYear_ProForma!$C$2:$C$66, "FY2026")+SUMIFS(MultiYear_ProForma!$AF$2:$AF$66, MultiYear_ProForma!$B$2:$B$66, B9, MultiYear_ProForma!$C$2:$C$66, "FY2027")+SUMIFS(MultiYear_ProForma!$AF$2:$AF$66, MultiYear_ProForma!$B$2:$B$66, B9, MultiYear_ProForma!$C$2:$C$66, "FY2028")+SUMIFS(MultiYear_ProForma!$AF$2:$AF$66, MultiYear_ProForma!$B$2:$B$66, B9, MultiYear_ProForma!$C$2:$C$66, "FY2029")+SUMIFS(MultiYear_ProForma!$AF$2:$AF$66, MultiYear_ProForma!$B$2:$B$66, B9, MultiYear_ProForma!$C$2:$C$66, "FY2030"))/5 -> -482883.16 | H9: =SUMIFS(MultiYear_ProForma!$N$2:$N$66, MultiYear_ProForma!$B$2:$B$66, B9, MultiYear_ProForma!$C$2:$C$66, "FY2026") -> 0 | I9: =SUMIFS(MultiYear_ProForma!$AC$2:$AC$66, MultiYear_ProForma!$B$2:$B$66, B9, MultiYear_ProForma!$C$2:$C$66, "FY2030") -> 553 | J9: =F9-(VLOOKUP($C$1,$B$5:$G$17,5, 0)) -> 217760.01 | K9: =G9-(VLOOKUP($C$1,$B$5:$I$17,6, 0)) -> 107303.43
A10: =LEFT(B10, 2) -> D2 | B10: D2_EchoGHubRamp_PimaTargets | C10: =SUMIFS(Capital_Summary!$H$4:$H$83, Capital_Summary!$A$4:$A$83, B10, Capital_Summary!$B$4:$B$83, "FY2026")*-1 -> -800000 | D10: =SUMIFS(MultiYear_ProForma!$AF$2:$AF$66, MultiYear_ProForma!$B$2:$B$66, B10, MultiYear_ProForma!$C$2:$C$66, "FY2030") -> 890764.96 | E10: =SUMIFS(MultiYear_ProForma!$AF$2:$AF$66, MultiYear_ProForma!$B$2:$B$66, B10, MultiYear_ProForma!$C$2:$C$66, "FY2028") -> 839981.52 | F10: =SUMIFS(MultiYear_ProForma!$AF$2:$AF$66, MultiYear_ProForma!$B$2:$B$66, B10, MultiYear_ProForma!$C$2:$C$66, "FY2030") -> 890764.96 | G10: =(SUMIFS(MultiYear_ProForma!$AF$2:$AF$66, MultiYear_ProForma!$B$2:$B$66, B10, MultiYear_ProForma!$C$2:$C$66, "FY2026")+SUMIFS(MultiYear_ProForma!$AF$2:$AF$66, MultiYear_ProForma!$B$2:$B$66, B10, MultiYear_ProForma!$C$2:$C$66, "FY2027")+SUMIFS(MultiYear_ProForma!$AF$2:$AF$66, MultiYear_ProForma!$B$2:$B$66, B10, MultiYear_ProForma!$C$2:$C$66, "FY2028")+SUMIFS(MultiYear_ProForma!$AF$2:$AF$66, MultiYear_ProForma!$B$2:$B$66, B10, MultiYear_ProForma!$C$2:$C$66, "FY2029")+SUMIFS(MultiYear_ProForma!$AF$2:$AF$66, MultiYear_ProForma!$B$2:$B$66, B10, MultiYear_ProForma!$C$2:$C$66, "FY2030"))/5 -> 587423.97 | H10: =SUMIFS(MultiYear_ProForma!$N$2:$N$66, MultiYear_ProForma!$B$2:$B$66, B10, MultiYear_ProForma!$C$2:$C$66, "FY2026") -> 0 | I10: =SUMIFS(MultiYear_ProForma!$AC$2:$AC$66, MultiYear_ProForma!$B$2:$B$66, B10, MultiYear_ProForma!$C$2:$C$66, "FY2030") -> 678 | J10: =F10-(VLOOKUP($C$1,$B$5:$G$17,5, 0)) -> 1615544.9 | K10: =G10-(VLOOKUP($C$1,$B$5:$I$17,6, 0)) -> 1177610.6
A11: =LEFT(B11, 2) -> A2 | B11: A2_Repurpose_Both_lease | C11: =SUMIFS(Capital_Summary!$H$4:$H$83, Capital_Summary!$A$4:$A$83, B11, Capital_Summary!$B$4:$B$83, "FY2026")*-1 -> -2314480 | D11: =SUMIFS(MultiYear_ProForma!$AF$2:$AF$66, MultiYear_ProForma!$B$2:$B$66, B11, MultiYear_ProForma!$C$2:$C$66, "FY2030") -> 1585320 | E11: =SUMIFS(MultiYear_ProForma!$AF$2:$AF$66, MultiYear_ProForma!$B$2:$B$66, B11, MultiYear_ProForma!$C$2:$C$66, "FY2028") -> 1223701.2 | F11: =SUMIFS(MultiYear_ProForma!$AF$2:$AF$66, MultiYear_ProForma!$B$2:$B$66, B11, MultiYear_ProForma!$C$2:$C$66, "FY2030") -> 1585320 | G11: =(SUMIFS(MultiYear_ProForma!$AF$2:$AF$66, MultiYear_ProForma!$B$2:$B$66, B11, MultiYear_ProForma!$C$2:$C$66, "FY2026")+SUMIFS(MultiYear_ProForma!$AF$2:$AF$66, MultiYear_ProForma!$B$2:$B$66, B11, MultiYear_ProForma!$C$2:$C$66, "FY2027")+SUMIFS(MultiYear_ProForma!$AF$2:$AF$66, MultiYear_ProForma!$B$2:$B$66, B11, MultiYear_ProForma!$C$2:$C$66, "FY2028")+SUMIFS(MultiYear_ProForma!$AF$2:$AF$66, MultiYear_ProForma!$B$2:$B$66, B11, MultiYear_ProForma!$C$2:$C$66, "FY2029")+SUMIFS(MultiYear_ProForma!$AF$2:$AF$66, MultiYear_ProForma!$B$2:$B$66, B11, MultiYear_ProForma!$C$2:$C$66, "FY2030"))/5 -> 1213035.9 | H11: =SUMIFS(MultiYear_ProForma!$N$2:$N$66, MultiYear_ProForma!$B$2:$B$66, B11, MultiYear_ProForma!$C$2:$C$66, "FY2026") -> 553 | I11: =SUMIFS(MultiYear_ProForma!$AC$2:$AC$66, MultiYear_ProForma!$B$2:$B$66, B11, MultiYear_ProForma!$C$2:$C$66, "FY2030") -> 405.8 | J11: =F11-(VLOOKUP($C$1,$B$5:$G$17,5, 0)) -> 2310100 | K11: =G11-(VLOOKUP($C$1,$B$5:$I$17,6, 0)) -> 1803222.5
A12: =LEFT(B12, 2) -> A1 | B12: A1_Repurpose_Both_ops | C12: =SUMIFS(Capital_Summary!$H$4:$H$83, Capital_Summary!$A$4:$A$83, B12, Capital_Summary!$B$4:$B$83, "FY2026")*-1 -> -3114480 | D12: =SUMIFS(MultiYear_ProForma!$AF$2:$AF$66, MultiYear_ProForma!$B$2:$B$66, B12, MultiYear_ProForma!$C$2:$C$66, "FY2030") -> 922909.09 | E12: =SUMIFS(MultiYear_ProForma!$AF$2:$AF$66, MultiYear_ProForma!$B$2:$B$66, B12, MultiYear_ProForma!$C$2:$C$66, "FY2028") -> 593208.97 | F12: =SUMIFS(MultiYear_ProForma!$AF$2:$AF$66, MultiYear_ProForma!$B$2:$B$66, B12, MultiYear_ProForma!$C$2:$C$66, "FY2030") -> 922909.09 | G12: =(SUMIFS(MultiYear_ProForma!$AF$2:$AF$66, MultiYear_ProForma!$B$2:$B$66, B12, MultiYear_ProForma!$C$2:$C$66, "FY2026")+SUMIFS(MultiYear_ProForma!$AF$2:$AF$66, MultiYear_ProForma!$B$2:$B$66, B12, MultiYear_ProForma!$C$2:$C$66, "FY2027")+SUMIFS(MultiYear_ProForma!$AF$2:$AF$66, MultiYear_ProForma!$B$2:$B$66, B12, MultiYear_ProForma!$C$2:$C$66, "FY2028")+SUMIFS(MultiYear_ProForma!$AF$2:$AF$66, MultiYear_ProForma!$B$2:$B$66, B12, MultiYear_ProForma!$C$2:$C$66, "FY2029")+SUMIFS(MultiYear_ProForma!$AF$2:$AF$66, MultiYear_ProForma!$B$2:$B$66, B12, MultiYear_ProForma!$C$2:$C$66, "FY2030"))/5 -> 552153.61 | H12: =SUMIFS(MultiYear_ProForma!$N$2:$N$66, MultiYear_ProForma!$B$2:$B$66, B12, MultiYear_ProForma!$C$2:$C$66, "FY2026") -> 553 | I12: =SUMIFS(MultiYear_ProForma!$AC$2:$AC$66, MultiYear_ProForma!$B$2:$B$66, B12, MultiYear_ProForma!$C$2:$C$66, "FY2030") -> 405.8 | J12: =F12-(VLOOKUP($C$1,$B$5:$G$17,5, 0)) -> 1647689 | K12: =G12-(VLOOKUP($C$1,$B$5:$I$17,6, 0)) -> 1142340.2
A13: =LEFT(B13, 2) -> B2 | B13: B2_Repurpose_Echo_lease_PimaTargets | C13: =SUMIFS(Capital_Summary!$H$4:$H$83, Capital_Summary!$A$4:$A$83, B13, Capital_Summary!$B$4:$B$83, "FY2026")*-1 -> -800000 | D13: =SUMIFS(MultiYear_ProForma!$AF$2:$AF$66, MultiYear_ProForma!$B$2:$B$66, B13, MultiYear_ProForma!$C$2:$C$66, "FY2030") -> 302948.49 | E13: =SUMIFS(MultiYear_ProForma!$AF$2:$AF$66, MultiYear_ProForma!$B$2:$B$66, B13, MultiYear_ProForma!$C$2:$C$66, "FY2028") -> 166608.27 | F13: =SUMIFS(MultiYear_ProForma!$AF$2:$AF$66, MultiYear_ProForma!$B$2:$B$66, B13, MultiYear_ProForma!$C$2:$C$66, "FY2030") -> 302948.49 | G13: =(SUMIFS(MultiYear_ProForma!$AF$2:$AF$66, MultiYear_ProForma!$B$2:$B$66, B13, MultiYear_ProForma!$C$2:$C$66, "FY2026")+SUMIFS(MultiYear_ProForma!$AF$2:$AF$66, MultiYear_ProForma!$B$2:$B$66, B13, MultiYear_ProForma!$C$2:$C$66, "FY2027")+SUMIFS(MultiYear_ProForma!$AF$2:$AF$66, MultiYear_ProForma!$B$2:$B$66, B13, MultiYear_ProForma!$C$2:$C$66, "FY2028")+SUMIFS(MultiYear_ProForma!$AF$2:$AF$66, MultiYear_ProForma!$B$2:$B$66, B13, MultiYear_ProForma!$C$2:$C$66, "FY2029")+SUMIFS(MultiYear_ProForma!$AF$2:$AF$66, MultiYear_ProForma!$B$2:$B$66, B13, MultiYear_ProForma!$C$2:$C$66, "FY2030"))/5 -> 162769.54 | H13: =SUMIFS(MultiYear_ProForma!$N$2:$N$66, MultiYear_ProForma!$B$2:$B$66, B13, MultiYear_ProForma!$C$2:$C$66, "FY2026") -> 257 | I13: =SUMIFS(MultiYear_ProForma!$AC$2:$AC$66, MultiYear_ProForma!$B$2:$B$66, B13, MultiYear_ProForma!$C$2:$C$66, "FY2030") -> 450.2 | J13: =F13-(VLOOKUP($C$1,$B$5:$G$17,5, 0)) -> 1027728.4 | K13: =G13-(VLOOKUP($C$1,$B$5:$I$17,6, 0)) -> 752956.13
A14: =LEFT(B14, 2) -> B1 | B14: B1_Repurpose_Echo_ops_PimaTargets | C14: =SUMIFS(Capital_Summary!$H$4:$H$83, Capital_Summary!$A$4:$A$83, B14, Capital_Summary!$B$4:$B$83, "FY2026")*-1 -> -1200000 | D14: =SUMIFS(MultiYear_ProForma!$AF$2:$AF$66, MultiYear_ProForma!$B$2:$B$66, B14, MultiYear_ProForma!$C$2:$C$66, "FY2030") -> 408845.42 | E14: =SUMIFS(MultiYear_ProForma!$AF$2:$AF$66, MultiYear_ProForma!$B$2:$B$66, B14, MultiYear_ProForma!$C$2:$C$66, "FY2028") -> 265075.52 | F14: =SUMIFS(MultiYear_ProForma!$AF$2:$AF$66, MultiYear_ProForma!$B$2:$B$66, B14, MultiYear_ProForma!$C$2:$C$66, "FY2030") -> 408845.42 | G14: =(SUMIFS(MultiYear_ProForma!$AF$2:$AF$66, MultiYear_ProForma!$B$2:$B$66, B14, MultiYear_ProForma!$C$2:$C$66, "FY2026")+SUMIFS(MultiYear_ProForma!$AF$2:$AF$66, MultiYear_ProForma!$B$2:$B$66, B14, MultiYear_ProForma!$C$2:$C$66, "FY2027")+SUMIFS(MultiYear_ProForma!$AF$2:$AF$66, MultiYear_ProForma!$B$2:$B$66, B14, MultiYear_ProForma!$C$2:$C$66, "FY2028")+SUMIFS(MultiYear_ProForma!$AF$2:$AF$66, MultiYear_ProForma!$B$2:$B$66, B14, MultiYear_ProForma!$C$2:$C$66, "FY2029")+SUMIFS(MultiYear_ProForma!$AF$2:$AF$66, MultiYear_ProForma!$B$2:$B$66, B14, MultiYear_ProForma!$C$2:$C$66, "FY2030"))/5 -> 172443.45 | H14: =SUMIFS(MultiYear_ProForma!$N$2:$N$66, MultiYear_ProForma!$B$2:$B$66, B14, MultiYear_ProForma!$C$2:$C$66, "FY2026") -> 257 | I14: =SUMIFS(MultiYear_ProForma!$AC$2:$AC$66, MultiYear_ProForma!$B$2:$B$66, B14, MultiYear_ProForma!$C$2:$C$66, "FY2030") -> 487.2 | J14: =F14-(VLOOKUP($C$1,$B$5:$G$17,5, 0)) -> 1133625.4 | K14: =G14-(VLOOKUP($C$1,$B$5:$I$17,6, 0)) -> 762630.04
A15: =LEFT(B15, 2) -> C2 | B15: C2_Repurpose_Pima_lease_EchoGHub_EchoTargets | C15: =SUMIFS(Capital_Summary!$H$4:$H$83, Capital_Summary!$A$4:$A$83, B15, Capital_Summary!$B$4:$B$83, "FY2026")*-1 -> -1600000 | D15: =SUMIFS(MultiYear_ProForma!$AF$2:$AF$66, MultiYear_ProForma!$B$2:$B$66, B15, MultiYear_ProForma!$C$2:$C$66, "FY2030") -> 775351.61 | E15: =SUMIFS(MultiYear_ProForma!$AF$2:$AF$66, MultiYear_ProForma!$B$2:$B$66, B15, MultiYear_ProForma!$C$2:$C$66, "FY2028") -> 574504.1 | F15: =SUMIFS(MultiYear_ProForma!$AF$2:$AF$66, MultiYear_ProForma!$B$2:$B$66, B15, MultiYear_ProForma!$C$2:$C$66, "FY2030") -> 775351.61 | G15: =(SUMIFS(MultiYear_ProForma!$AF$2:$AF$66, MultiYear_ProForma!$B$2:$B$66, B15, MultiYear_ProForma!$C$2:$C$66, "FY2026")+SUMIFS(MultiYear_ProForma!$AF$2:$AF$66, MultiYear_ProForma!$B$2:$B$66, B15, MultiYear_ProForma!$C$2:$C$66, "FY2027")+SUMIFS(MultiYear_ProForma!$AF$2:$AF$66, MultiYear_ProForma!$B$2:$B$66, B15, MultiYear_ProForma!$C$2:$C$66, "FY2028")+SUMIFS(MultiYear_ProForma!$AF$2:$AF$66, MultiYear_ProForma!$B$2:$B$66, B15, MultiYear_ProForma!$C$2:$C$66, "FY2029")+SUMIFS(MultiYear_ProForma!$AF$2:$AF$66, MultiYear_ProForma!$B$2:$B$66, B15, MultiYear_ProForma!$C$2:$C$66, "FY2030"))/5 -> 567383.24 | H15: =SUMIFS(MultiYear_ProForma!$N$2:$N$66, MultiYear_ProForma!$B$2:$B$66, B15, MultiYear_ProForma!$C$2:$C$66, "FY2026") -> 296 | I15: =SUMIFS(MultiYear_ProForma!$AC$2:$AC$66, MultiYear_ProForma!$B$2:$B$66, B15, MultiYear_ProForma!$C$2:$C$66, "FY2030") -> 508.6 | J15: =F15-(VLOOKUP($C$1,$B$5:$G$17,5, 0)) -> 1500131.5 | K15: =G15-(VLOOKUP($C$1,$B$5:$I$17,6, 0)) -> 1157569.8
A16: =LEFT(B16, 2) -> C1 | B16: C1_Repurpose_Pima_ops_EchoGHub_EchoTargets | C16: =SUMIFS(Capital_Summary!$H$4:$H$83, Capital_Summary!$A$4:$A$83, B16, Capital_Summary!$B$4:$B$83, "FY2026")*-1 -> -2000000 | D16: =SUMIFS(MultiYear_ProForma!$AF$2:$AF$66, MultiYear_ProForma!$B$2:$B$66, B16, MultiYear_ProForma!$C$2:$C$66, "FY2030") -> 979902.02 | E16: =SUMIFS(MultiYear_ProForma!$AF$2:$AF$66, MultiYear_ProForma!$B$2:$B$66, B16, MultiYear_ProForma!$C$2:$C$66, "FY2028") -> 766053.57 | F16: =SUMIFS(MultiYear_ProForma!$AF$2:$AF$66, MultiYear_ProForma!$B$2:$B$66, B16, MultiYear_ProForma!$C$2:$C$66, "FY2030") -> 979902.02 | G16: =(SUMIFS(MultiYear_ProForma!$AF$2:$AF$66, MultiYear_ProForma!$B$2:$B$66, B16, MultiYear_ProForma!$C$2:$C$66, "FY2026")+SUMIFS(MultiYear_ProForma!$AF$2:$AF$66, MultiYear_ProForma!$B$2:$B$66, B16, MultiYear_ProForma!$C$2:$C$66, "FY2027")+SUMIFS(MultiYear_ProForma!$AF$2:$AF$66, MultiYear_ProForma!$B$2:$B$66, B16, MultiYear_ProForma!$C$2:$C$66, "FY2028")+SUMIFS(MultiYear_ProForma!$AF$2:$AF$66, MultiYear_ProForma!$B$2:$B$66, B16, MultiYear_ProForma!$C$2:$C$66, "FY2029")+SUMIFS(MultiYear_ProForma!$AF$2:$AF$66, MultiYear_ProForma!$B$2:$B$66, B16, MultiYear_ProForma!$C$2:$C$66, "FY2030"))/5 -> 641758.89 | H16: =SUMIFS(MultiYear_ProForma!$N$2:$N$66, MultiYear_ProForma!$B$2:$B$66, B16, MultiYear_ProForma!$C$2:$C$66, "FY2026") -> 295.66667 | I16: =SUMIFS(MultiYear_ProForma!$AC$2:$AC$66, MultiYear_ProForma!$B$2:$B$66, B16, MultiYear_ProForma!$C$2:$C$66, "FY2030") -> 558.6 | J16: =F16-(VLOOKUP($C$1,$B$5:$G$17,5, 0)) -> 1704682 | K16: =G16-(VLOOKUP($C$1,$B$5:$I$17,6, 0)) -> 1231945.5
A17: =LEFT(B17, 2) -> E1 | B17: E1_StatusQuo_Decline | C17: =SUMIFS(Capital_Summary!$H$4:$H$83, Capital_Summary!$A$4:$A$83, B17, Capital_Summary!$B$4:$B$83, "FY2026")*-1 -> 0 | D17: =SUMIFS(MultiYear_ProForma!$AF$2:$AF$66, MultiYear_ProForma!$B$2:$B$66, B17, MultiYear_ProForma!$C$2:$C$66, "FY2030") -> -724779.94 | E17: =SUMIFS(MultiYear_ProForma!$AF$2:$AF$66, MultiYear_ProForma!$B$2:$B$66, B17, MultiYear_ProForma!$C$2:$C$66, "FY2028") -> -588315.82 | F17: =SUMIFS(MultiYear_ProForma!$AF$2:$AF$66, MultiYear_ProForma!$B$2:$B$66, B17, MultiYear_ProForma!$C$2:$C$66, "FY2030") -> -724779.94 | G17: =(SUMIFS(MultiYear_ProForma!$AF$2:$AF$66, MultiYear_ProForma!$B$2:$B$66, B17, MultiYear_ProForma!$C$2:$C$66, "FY2026")+SUMIFS(MultiYear_ProForma!$AF$2:$AF$66, MultiYear_ProForma!$B$2:$B$66, B17, MultiYear_ProForma!$C$2:$C$66, "FY2027")+SUMIFS(MultiYear_ProForma!$AF$2:$AF$66, MultiYear_ProForma!$B$2:$B$66, B17, MultiYear_ProForma!$C$2:$C$66, "FY2028")+SUMIFS(MultiYear_ProForma!$AF$2:$AF$66, MultiYear_ProForma!$B$2:$B$66, B17, MultiYear_ProForma!$C$2:$C$66, "FY2029")+SUMIFS(MultiYear_ProForma!$AF$2:$AF$66, MultiYear_ProForma!$B$2:$B$66, B17, MultiYear_ProForma!$C$2:$C$66, "FY2030"))/5 -> -590186.59 | H17: =SUMIFS(MultiYear_ProForma!$N$2:$N$66, MultiYear_ProForma!$B$2:$B$66, B17, MultiYear_ProForma!$C$2:$C$66, "FY2026") -> 0 | I17: =SUMIFS(MultiYear_ProForma!$AC$2:$AC$66, MultiYear_ProForma!$B$2:$B$66, B17, MultiYear_ProForma!$C$2:$C$66, "FY2030") -> 510.06959 | J17: =F17-(VLOOKUP($C$1,$B$5:$G$17,5, 0)) -> 0 | K17: =G17-(VLOOKUP($C$1,$B$5:$I$17,6, 0)) -> 0
B19: Note: Displaced = FY26; Served = FY30. Net = M&O − (Aid + Override + Uplift); showing one-time capital (fy26) as negative number for visualization purposes

Sheet Parameters_Public
A1: Public Inputs — Audited Baselines and Overrides (Phase A) | C1: Yellow fields are editable
A3: ADM (official) | C3: Values | E3: Notes | I3: Notes2
B4: Echo 40th | C4: 257 | E4: Estimate used at this point; need to replace. Find official 40th day ADM for Echo (enter audited)
B5: Echo 100th | C5: 257 | E5: Estimate used at this point; need to replace. Find official 100th day ADM for Echo (enter audited)
B6: Pima 40th | C6: 296 | E6: Estimate used at this point; need to replace. Find official 40th day ADM for Pima (enter audited)
B7: Pima 100th | C7: 296 | E7: Estimate used at this point; need to replace. Find official 100th day ADM for Pima (enter audited)
B8: Use Day (40 or 100) | C8: 40 | E8: Choose which count the model uses (40 or 100).
B10: Echo_ADM0 (selected) | C10: =IF(C8=40,C4,C5) -> 257 | E10: Model‑read Echo_ADM0 selected based on 40/100 day switch.
B11: Pima_ADM0 (selected) | C11: =IF(C8=40,C6,C7) -> 296 | E11: Model‑read Pima_ADM0 selected based on 40/100 day switch.
A13: M&O/ADM (district), audited (ACFR)
B14: M_O_per_ADM_Audited | C14: 11589 | E14: Estimate used at this point. Enter the audited districtwide Maintenance & Operations cost per ADM from the latest ACFR/Adopted Budget. Used as the FY25 base.
A16: Override — property‑tax override
B17: Override percent | C17: 0.15 | E17: Districtwide override percent (e.g., 15%).
B18: Base aid per ADM (proxy for RCL per pupil) | C18: 5013 | E18: Proxy base for calculating per‑ADM override; replace with RCL per pupil if available.
B19: Override per ADM (proxy) | C19: =C17*C18 -> 751.95 | E19: Computed per‑ADM amount used wherever the model needs a per‑student override term.
B20: Override toggle (1=on, 0=off) | C20: 1 | E20: Global on/off switch for including override in revenue calculations.
B21: Other General Fund revenue per served ADM (optional uplift) | C21: 5200 | E21: Everything not in “Base Aid + Override”: add‑on weights (e.g., SPED Group A/B), Transportation Support Level (TSL), and District Additional Assistance (DAA) — all components of the Equalization Base. (The Legislature’s primer shows Equalization Base = BSL + TSL + DAA, BLA = $5,013.33 in FY25. General Fund (Fund 001) revenues, FY2024 (actual): $192.213M (property taxes + state aid & grants). resources.finalsite.net Using SUSD’s FY2024 ACFR (audited): General Fund revenues (FY2024) = $215.4M (MD&A notes), General Fund expenditures = $233.7M. Scottsdale Unified School District Average Daily Membership (FY2024) = 19,748 (Operating Statistics table). Scottsdale Unified School District → GF revenue per ADM ≈ $215.4M / 19,748 ≈ $10,900/ADM. | I21: Using SUSD’s FY2024 ACFR (audited): General Fund revenues (FY2024) = $215.4M (MD&A notes), General Fund expenditures = $233.7M. Scottsdale Unified School District Average Daily Membership (FY2024) = 19,748 (Operating Statistics table). Scottsdale Unified School District → GF revenue per ADM ≈ $215.4M / 19,748 ≈ $10,900/ADM. State base amounts (policy context): FY2024 Base Level Amount (BLA) = $4,914.71. Arizona Department of Education FY2025 BLA = $5,013.33 (Senate research issue brief; also reiterates Equalization Base = BSL + TSL + DAA). Arizona Legislature Your model treats revenue as Aid (BLA‑based) + Override (+ optional uplift). To reconcile absolute Nets with audited magnitudes, we add an uplift that approximates everything in GF that isn’t “base + override,” e.g., TSL, DAA, formula add‑ons/weights, Prop 123 allocations, etc. (that’s what the Equalization Base framework is capturing when you aggregate components). Arizona Legislature Two reasonable calibration anchors: FY2024 basis: Uplift ≈ GF revenue per ADM − (BLA + Override) ≈ 10,900 − (4,914.71 + 0.15 × 4,914.71) ≈ 10,900 − (4,914.71 + 737) ≈ $5,250/ADM (rounded). Scottsdale Unified School District +2 Scottsdale Unified School District +2 FY2025 basis: Uplift ≈ 10,900 − (5,013.33 + 0.15 × 5,013.33) ≈ 10,900 − (5,013.33 + 752) ≈ $5,135/ADM (rounded). Scottsdale Unified School District +2 Scottsdale Unified School District +2 Uplift $5,100–$5,300/ADM is defensible on FY24 data and the state’s formula structure.
B22: Aid per ADM annual growth | C22: 0.025 | E22: Assuming aid grows around the same rate as cost inflation.
B23: Retention r — Echo (central) | C23: 0.6 | E23: Share of displaced Echo students re-enrolling in SUSD (0–1). As a choice school with 50% or more of families living outside the district, we can assume this will be lower than Pima.
B24: Retention r — Pima (central) | C24: 0.85 | E24: Share of displaced Pima students re-enrolling in SUSD (0–1). Not a significant amount of research on retention from closed schools; Chicago public retained 90%+ of students who were majority in boundaries when closing schools.
A26: Capital Treatment & Growth Capex (DRAFT placeholders)
B28: Include TI in Operating M&O? (0/1) | C28: 0 | E28: 0 = treat TI as capital (exclude from operating nets); 1 = include TI in Comparable_MO$
B29: TI per closed site (one-time) | C29: =BaselineCalc!$B$22 -> 1200000 | E29: “TI” = tenant improvements / transition investments needed to convert a K‑8 to a different use (early learning, admin consolidation) and carry costs in year one (e.g., abatement, doors/security, low‑voltage re‑work, furniture, swing space); DRAFT Ops TI: Mirrors BaselineCalc TI unit; replace with capital plan when available
B30: Growth Capex — Arts Hub (one-time) | C30: 800000 | E30: DRAFT placeholder; enter benchmarked capital required to enable Arts hub
B31: Growth Capex — Innovation Hub (one-time) | C31: 1200000 | E31: DRAFT placeholder; enter benchmarked capital required for Innovation hub
B32: Include Growth Capex in Operating? (0/1) | C32: 0 | E32: 0 = treat growth capex as capital (recommended); 1 = include in Comparable_MO$ (what‑if only)
B33: TI per closed site (lease case) | C33: 800000 | E33: DRAFT: lease TI placeholder; separate from ops TI (C27)
B34: Portable seat cost (capital $ per seat) | C34: 12000 | E34: DRAFT: per-seat portables or TI to add seats at receivers
B35: Spare K–5 seats across receivers (FY26) | C35: 300 | E35: User input: available elementary seats to absorb retained K–5
B36: Spare 6–8 seats across receivers (FY26) | C36: 100 | E36: User input: available middle seats to absorb retained 6–8
B38: Echo K–5 share of ADM | C38: 0.7 | E38: DRAFT: distribution of Echo ADM by grade band
B39: Echo 6–8 share of ADM | C39: 0.3
B40: Pima K–5 share of ADM | C40: 1
B41: Pima 6–8 share of ADM | C41: 0
B43: MarginalFactor_for_Overlay (central source) | C43: 0.6 | E43: Assuming marginal cost of new students from growth (assuming there is available capacity in Echo and Pima; ideally, this would be a step function)
B44: Echo ADM trend default | C44: -0.02 | E44: Default enrollment trend from forecasts; placeholder value for now -- need to verify this
B45: Pima ADM trend default | C45: -0.02 | E45: Default enrollment trend from forecasts; placeholder value for now -- need to verify this
B47: Growth overhead per added ADM (α × h) | C47: 0.2 | E47: Assuming some incremental transportation overhead for growth-related new students; we model it as a percentage of closed school transition-related incremental transportation overhead
B49: Incremental uplift alpha (overlay share of base uplift) | C49: 0.85 | E49: Applied only to Overlay_ADM; keeps marginal revenue conservative because some ‘other GF’ (weights/TSL/DAA) don’t scale 1:1. Typical range 0.70–0.90 (default 0.85).

Sheet Inputs_Definitions_Sources
A1: Audited & Policy Anchors (paste into Parameters when available)
A2: Anchor | B2: Value / Status | C2: Source (short) | D2: Used for | E2: Owner | F2: Paste location | G2: Source URL
A3: BLA (Base Level Amount) FY2025 | B3: 5,013.33 | C3: AZ Senate Issue Brief / ADE update | D3: YearMap → Aid$ | E3: Finance | F3: Parameters_Public!C18 or BaselineCalc | G3: https://www.azleg.gov/Briefs/Senate/ARIZONA%27S%20SCHOOL%20FINANCE%20SYSTEM%202024.PDF
A4: M&O Override % | B4: 15% (RCL) | C4: SUSD M&O Override page | D4: Override per ADM; Revenue$ | E4: Finance | F4: Parameters_Public!C17 | G4: https://www.susd.org/Page/658
A5: Override toggle | B5: 0/1 (board policy) | C5: Model control | D5: Revenue$ switch | E5: Model | F5: Parameters_Public!C20
A6: District M&O per ADM (audited) | B6: FY2024 value (e.g., 14,049) | C6: SUSD ACFR FY2024, Operating Statistics | D6: Sanity checks / narratives | E6: Finance | F6: Parameters_Public!C14
A7: Transportation Support Level (TSL) | B7: Per route‑mile schedule | C7: AZ Senate Issue Brief / ADE | D7: Revenue context | E7: Finance | F7: Definitions_Sources | G7: https://www.azed.gov/finance/fy2025-school-finance-fiscal-operations-updates
A8: Transport cost per eligible rider | B8: ≈ 3,183 (FY2024 anchor) | C8: City of Scottsdale Auditor report | D8: h₀ (retention overhead) anchor | E8: Ops | F8: Control_Center | G8: https://www.scottsdaleaz.gov/docs/default-source/scottsdaleaz/auditor/2025-reports/susd-transportation---audit-2508.pdf?sfvrsn=144e4f2d_1
A9: Echo/Pima 40th & 100th (FY2025) | B9: To paste (AzEDS export SDADMS72/75) | C9: ADE School Finance / District export | D9: Base ADM by site | E9: Data | F9: Parameters_Public | G9: https://www.ade.az.gov/schoolfinance/Reports
A10: Site‑fixed ledgers (Fund 001, by site) | B10: To paste (Echo & Pima) | C10: SUSD Finance site/cost‑center ledgers | D10: Replace fallback fixed | E10: Finance | F10: Site_Fixed | G10: https://www.azauditor.gov/arizona-school-district-spending-fiscal-year-2024-analysis-and-data-file
A12: Core Definitions & Derivations
A13: Term | B13: Definition / Formula | C13: Appears on | D13: Depends on | E13: Notes | F13: Named range (if any)
A14: Operating Net ($) | B14: M&O − (Aid + Override + Uplift); capital excluded. | C14: Summary_Figures; Scenario_Comparison; Board_OnePager | D14: YearMap revenues, MultiYear_ProForma costs | E14: Fund 001 lens only.
A15: Δ vs Base (FY2030) | B15: Comparator FY2030 Net − Base FY2030 Net. | C15: Summary_Figures; Scenario_Comparison | D15: Net$
A16: Δ vs Base (Avg FY26–30) | B16: Comparator 5‑yr Avg Net − Base 5‑yr Avg Net. | C16: Summary_Figures; Scenario_Comparison | D16: Net$ FY26..30
A17: Displaced (FY26) | B17: Displaced students in first action year. | C17: Summary_Figures; Scenario_Comparison | D17: Scenario mechanics
A18: Served (FY2030) | B18: Open + retained ADM in FY2030. | C18: Summary_Figures; Scenario_Comparison | D18: Served_ADM (MPF col AC)
A19: Comparable net per served | B19: FY2030 Net ÷ FY2030 Served_ADM. | C19: Optional on Summary_Figures | D19: Net$, Served_ADM | E19: Normalization when served counts differ.
A20: mᵗ (incremental margin per ADM) | B20: Aid + Override_if_on + Uplift − VarUnit$ − g | C20: Budget_Neutral_Calculator | D20: YearMap; Override_toggle | E20: Year‑specific.
A21: N⁰ (budget‑neutral students) | B21: max(0, −Netₜ / mᵗ) | C21: Budget_Neutral_Calculator | D21: mᵗ; Netₜ | E21: Shown for FY26 & FY30.
A22: Uplift (base) | B22: Other GF per served ADM; indexed with Aid growth. | C22: YearMap (Uplift_per_ADM) | D22: Aid_growth; Uplift_base_per_ADM | F22: Uplift_base_per_ADM
A23: Uplift (incremental) | B23: α × Uplift(base) applied to Overlay_ADM only. | C23: YearMap; Revenue$ | D23: Incremental_uplift_alpha | E23: Keeps marginal revenue conservative. | F23: Incremental_uplift_alpha
A24: Retention overhead (h) | B24: Routing/admin overhead per retained student; tapers annually. | C24: YearMap (h) | D24: h_taper_profile | E24: First‑year set from transport cost anchor. | F24: h_taper_profile
A25: Growth overhead (g) | B25: α × h applied to Overlay_ADM. | C25: YearMap (Growth_overhead_per_ADM) | D25: Growth_overhead_alpha; h_taper_profile | E25: Smaller than h; symmetry with repurpose. | F25: Growth_overhead_alpha
A26: Fixed savings realization | B26: Savings = (1−f)×SiteFixed$; f_ops, f_lease ramp FY26→FY30. | C26: MPF (EchoFixedEff$, PimaFixedEff$) | D26: f_ops_profile; f_lease_profile; Site_Fixed | E26: Replace fallback with audited site‑fixed. | F26: f_ops_profile; f_lease_profile
A27: Trend gates | B27: Apply_Echo_Trend / Apply_Pima_Trend toggle Potential_ADM by site. | C27: Scenarios; MPF | D27: Scenarios columns R/S; Parameters_Public trends | E27: On by scenario.
A28: ADM (Average Daily Membership) | B28: Unweighted attendance measure used for funding: membership days through the first 100 instructional days (or 200 for year-round) divided by days in period; see A.R.S. 15-901(1). | C28: Parameters; Baselines; Narrative | D28: ADE statute/SDADMS calculations | E28: Pre-K typically excluded from ADM for formula funding.
A29: Variable unit cost (VarUnit$) | B29: $ per served student covering incremental staffing, aides, supplies, and a small transport slice; indexed by MO inflation. | C29: YearMap; Revenue$/Adj_MO$ | D29: MO inflation; baseline unit cost | E29: Used in mᵗ = revenues − VarUnit$ − g.
A30: Marginal-cost factor for overlay seats | B30: Factor (<1) scaling VarUnit$ on overlay ADM to reflect partial sectioning in slack capacity years. | C30: MultiYear_Pro_Forma | D30: Parameters_Public MarginalFactor_for_Overlay | E30: Default 0.50; tune with scheduling/sectioning review.
A31: Retention rate r | B31: Share of displaced students who stay in SUSD and are re-routed to receiving sites; they remain in Served_ADM and incur h. | C31: Scenarios; MultiYear_Pro_Forma | D31: Parameters_Public r values | E31: Higher r keeps revenue but increases overhead h.
A32: Co-location extra savings | B32: Additional operating savings (beyond standard f_ops) modeled when consolidating two programs on one site. | C32: Scenarios; MultiYear_Pro_Forma | D32: Control_Center setting; scenario flags | E32: Small effect; fine-tune with facilities/ops.
A33: Keep-open ops savings | B33: Minor efficiency factor applied to scenarios that keep a site open (e.g., utilities, scheduling refinements). | C33: Scenarios; MultiYear_Pro_Forma | D33: Control_Center setting | E33: Small symmetric adjustment for fairness.
A35: Repurpose-related pathway parameters
A36: Gate / Mechanism | B36: How enforced in model | C36: What to watch | D36: Where implemented | E36: Notes | F36: Owner
A37: Receiving capacity gate | B37: Band‑level spare seats + portables; flag if exceeded. | C37: No site over capacity. | D37: Receiving_Capacity; Scenario_Comparison | F37: Planning
A38: Quality gate (optional) | B38: Receiving schools must meet program‑quality threshold. | C38: Define threshold. | D38: TBD (outside model) | E38: Narrative tie‑in. | F38: Academics
A39: Retention gate | B39: Retention r applied to displaced cohorts. | C39: Measure r achieved. | D39: Parameters_Public; MPF | E39: Supports r* framing if needed. | F39: Enrollment
A40: Budget neutrality | B40: N⁰ calculator for FY26/FY30. | C40: N⁰ = 0 means Net≥0. | D40: Budget_Neutral_Calculator | E40: Scenario‑specific. | F40: Finance
A41: Fixed savings realization | B41: f_ops/f_lease ramp applied to site‑fixed. | C41: Use audited site‑fixed; avoid over‑crediting. | D41: YearMap; MPF | F41: Finance/Ops
A43: Audit paste checklist (to finalize model)
...

Sheet Scenarios
C1: Yellow fields are editable
A2: ScenarioKey | B2: Label | C2: Enrollment add over 3 years | D2: CloseEcho (0 = no; 1 = yes) | E2: ClosePima (0 = no; 1 = yes) | F2: EchoShareDist (share of enrollment adds) | G2: ExtraSave (cost efficiency assumption) | H2: Notes | I2: Overlay_FY26 | J2: Overlay_FY27 | K2: Overlay_FY28 | L2: Overlay_FY29 | M2: Overlay_FY30 | N2: Carry | O2: Growth_Echo | P2: Growth_Pima | Q2: Apply_Echo_Trend | R2: Apply_Pima_Trend
A3: F1_CUSTOM1 | B3: CUSTOM_KeepOpen_v1 | C3: 0 | D3: 0 | E3: 0 | F3: 0.5 | G3: 0 | H3: Baseline + outreach; no closures | I3: =C3/3 -> 0 | J3: =I3+C3/3 -> 0 | K3: =J3+C3/3 -> 0 | L3: =C3 -> 0 | M3: =C3 -> 0 | O3: None | P3: None | Q3: 0 | R3: 0
A4: D4_StatusQuo_Targets | B4: Echo & Pima open; uplift warm handoff effort (intra-SUSD); initiate cross-district marketing | C4: 75 | D4: 0 | E4: 0 | F4: 0.5 | G4: 0 | H4: Baseline + targets; no closures | I4: =C4/3 -> 25 | J4: =I4+C4/3 -> 50 | K4: =J4+C4/3 -> 75 | L4: =C4 -> 75 | M4: =C4 -> 75 | O4: None | P4: None | Q4: 0 | R4: 0
A5: D3_CoLocation_Echo_Targets | B5: Echo & Pima open; co-locate e.g. district teacher learning center at Echo; uplift warm handoff effort (intra-SUSD); initiate cross-district marketing | C5: 50 | D5: 0 | E5: 0 | F5: 0.5 | G5: 0.05 | H5: Shared‑use efficiencies (no closure) | I5: =C5/3 -> 16.666667 | J5: =I5+C5/3 -> 33.333333 | K5: =J5+C5/3 -> 50 | L5: =C5 -> 50 | M5: =C5 -> 50 | O5: None | P5: None | Q5: 0 | R5: 0
A6: D1_Grow_Both_Targets | B6: Echo & Pima open; growth initiatives Echo (e.g. innovation) & Pima (e.g. arts); uplift warm handoff effort (intra-SUSD); initiate cross-district marketing | C6: 150 | D6: 0 | E6: 0 | F6: 0.5 | G6: 0 | H6: Baseline + growth initiatives | I6: =C6/3 -> 50 | J6: =I6+C6/3 -> 100 | K6: =J6+C6/3 -> 150 | L6: =C6 -> 150 | M6: =C6 -> 150 | O6: Innov | P6: Arts | Q6: 0 | R6: 0
A7: E2_StatusQuo_Steady | B7: Echo & Pima open; no operational or strategic growth actions; no change in enrollment | C7: 0 | D7: 0 | E7: 0 | F7: 0.5 | G7: 0 | H7: Baseline steady enrollment | I7: =C7/3 -> 0 | J7: =I7+C7/3 -> 0 | K7: =J7+C7/3 -> 0 | L7: =C7 -> 0 | M7: =C7 -> 0 | O7: None | P7: None | Q7: 0 | R7: 0
A8: D2_EchoGHubRamp_PimaTargets | B8: Echo & Pima open; growth initiative Echo (e.g. innovation); no growth initiative Pima; uplift warm handoff effort (intra-SUSD); initiate cross-district marketing | C8: 125 | D8: 0 | E8: 0 | F8: 0.7 | G8: 0 | H8: Time‑phased ramp over years 1-3 | I8: =C8/3 -> 41.666667 | J8: =I8+C8/3 -> 83.333333 | K8: =J8+C8/3 -> 125 | L8: =C8 -> 125 | M8: =C8 -> 125 | O8: Arts | P8: None | Q8: 0 | R8: 0
A9: A2_Repurpose_Both_lease | B9: Repurpose both Echo & Pima; lease both properties; fixed cost reduction rate, retention %, and transition cost assumptions are key drivers | C9: 0 | D9: 1 | E9: 1 | F9: 0.5 | G9: 0 | H9: Repurpose both; lease/sale glide | I9: =C9/3 -> 0 | J9: =I9+C9/3 -> 0 | K9: =J9+C9/3 -> 0 | L9: =C9 -> 0 | M9: =C9 -> 0 | N9: lease | O9: None | P9: None | Q9: 0 | R9: 0
A10: A1_Repurpose_Both_ops | B10: Repurpose both Echo & Pima; operationally convert both properties (e.g. early learning center); fixed cost reduction rate, retention %, and transition cost assumptions are key drivers | C10: 0 | D10: 1 | E10: 1 | F10: 0.5 | G10: 0 | H10: Repurpose both; operations carry | I10: =C10/3 -> 0 | J10: =I10+C10/3 -> 0 | K10: =J10+C10/3 -> 0 | L10: =C10 -> 0 | M10: =C10 -> 0 | N10: ops | O10: None | P10: None | Q10: 0 | R10: 0
A11: B2_Repurpose_Echo_lease_PimaTargets | B11: Repurpose ECHO (lease) + Status-Quo Pima + Pima Op Growth Targets | C11: 0 | D11: 1 | E11: 0 | F11: 0 | G11: 0 | H11: Repurpose Echo only; lease glide | I11: =C11/3 -> 0 | J11: =I11+C11/3 -> 0 | K11: =J11+C11/3 -> 0 | L11: =C11 -> 0 | M11: =C11 -> 0 | N11: lease | O11: None | P11: None | Q11: 0 | R11: 0
A12: B1_Repurpose_Echo_ops_PimaTargets | B12: Repurpose ECHO (ops) + Status-Quo Pima + Pima Op Growth Targets | C12: 37 | D12: 1 | E12: 0 | F12: 0 | G12: 0 | H12: Repurpose Echo only; ops carry | I12: =C12/3 -> 12.333333 | J12: =I12+C12/3 -> 24.666667 | K12: =J12+C12/3 -> 37 | L12: =C12 -> 37 | M12: =C12 -> 37 | N12: ops | O12: None | P12: None | Q12: 0 | R12: 0
A13: C2_Repurpose_Pima_lease_EchoGHub_EchoTargets | B13: Repurpose PIMA (lease) + Growth Hub @ Echo + Echo Op Growth Targets | C13: 0 | D13: 0 | E13: 1 | F13: 1 | G13: 0 | H13: Repurpose Pima only; lease glide | I13: =C13/3 -> 0 | J13: =I13+C13/3 -> 0 | K13: =J13+C13/3 -> 0 | L13: =C13 -> 0 | M13: =C13 -> 0 | N13: lease | O13: Arts | P13: None | Q13: 0 | R13: 0
A14: C1_Repurpose_Pima_ops_EchoGHub_EchoTargets | B14: Repurpose PIMA (ops) + Growth Hub @ Echo + Echo Op Growth Targets | C14: 50 | D14: 0 | E14: 1 | F14: 1 | G14: 0 | H14: Repurpose Pima only; ops carry | I14: =C14/3 -> 16.666667 | J14: =I14+C14/3 -> 33.333333 | K14: =J14+C14/3 -> 50 | L14: =C14 -> 50 | M14: =C14 -> 50 | N14: ops | O14: Arts | P14: None | Q14: 0 | R14: 0
A15: E1_StatusQuo_Decline | B15: Echo & Pima open; no operational or strategic growth actions; enrollment decline trend continues | C15: 0 | D15: 0 | E15: 0 | F15: 0 | G15: 0 | H15: Keep open but decline per district forecast | I15: =C15/3 -> 0 | J15: =I15+C15/3 -> 0 | K15: =J15+C15/3 -> 0 | L15: =C15 -> 0 | M15: =C15 -> 0 | O15: None | P15: None | Q15: 1 | R15: 1
A27: ScenarioKey | B27: Year | C27: Echo_ADM | D27: Pima_ADM | E27: Total_ADM | F27: VarUnit$ | G27: EchoFixed$ | H27: PimaFixed$ | I27: Key | O27: None | P27: None
A28: =A3 -> F1_CUSTOM1 | B28: FY2026 | C28: =IF(D3=1,0, BaselineCalc!$B$7 + ROUND(I3*F3,0)) -> 257 | D28: =IF(E3=1,0, BaselineCalc!$B$8 + I3 - ROUND(I3*F3,0)) -> 296 | E28: =C28+D28 -> 553 | F28: =YearMap!B2 -> 6414.5115 | G28: =YearMap!C2 -> 1404302.9 | H28: =YearMap!D2 -> 1617407.2 | I28: =A28&"|"&B28 -> F1_CUSTOM1|FY2026 | O28: None | P28: None
A29: =A3 -> F1_CUSTOM1 | B29: FY2027 | C29: =IF(D3=1,0, BaselineCalc!$B$7 + ROUND(J3*F3,0)) -> 257 | D29: =IF(E3=1,0, BaselineCalc!$B$8 + J3 - ROUND(J3*F3,0)) -> 296 | E29: =C29+D29 -> 553 | F29: =YearMap!B3 -> 6574.8743 | G29: =YearMap!C3 -> 1439410.4 | H29: =YearMap!D3 -> 1657842.4 | I29: =A29&"|"&B29 -> F1_CUSTOM1|FY2027 | O29: None | P29: None
A30: =A3 -> F1_CUSTOM1 | B30: FY2028 | C30: =IF(D3=1,0, BaselineCalc!$B$7 + ROUND(K3*F3,0)) -> 257 | D30: =IF(E3=1,0, BaselineCalc!$B$8 + K3 - ROUND(K3*F3,0)) -> 296 | E30: =C30+D30 -> 553 | F30: =YearMap!B4 -> 6739.2461 | G30: =YearMap!C4 -> 1475395.7 | H30: =YearMap!D4 -> 1699288.4 | I30: =A30&"|"&B30 -> F1_CUSTOM1|FY2028 | O30: None | P30: None
A31: =A3 -> F1_CUSTOM1 | B31: FY2029 | C31: =IF(D3=1,0, BaselineCalc!$B$7 + ROUND(L3*F3,0)) -> 257 | D31: =IF(E3=1,0, BaselineCalc!$B$8 + L3 - ROUND(L3*F3,0)) -> 296 | E31: =C31+D31 -> 553 | F31: =YearMap!B5 -> 6907.7273 | G31: =YearMap!C5 -> 1512280.6 | H31: =YearMap!D5 -> 1741770.6 | I31: =A31&"|"&B31 -> F1_CUSTOM1|FY2029 | O31: None | P31: None
A32: =A3 -> F1_CUSTOM1 | B32: FY2030 | C32: =IF(D3=1,0, BaselineCalc!$B$7 + ROUND(M3*F3,0)) -> 257 | D32: =IF(E3=1,0, BaselineCalc!$B$8 + M3 - ROUND(M3*F3,0)) -> 296 | E32: =C32+D32 -> 553 | F32: =YearMap!B6 -> 7080.4205 | G32: =YearMap!C6 -> 1550087.6 | H32: =YearMap!D6 -> 1785314.9 | I32: =A32&"|"&B32 -> F1_CUSTOM1|FY2030 | O32: None | P32: None
A33: =A4 -> D4_StatusQuo_Targets | B33: FY2026 | C33: =IF(D4=1,0, BaselineCalc!$B$7 + ROUND(I4*F4,0)) -> 270 | D33: =IF(E4=1,0, BaselineCalc!$B$8 + I4 - ROUND(I4*F4,0)) -> 308 | E33: =C33+D33 -> 578 | F33: =YearMap!B2 -> 6414.5115 | G33: =YearMap!C2 -> 1404302.9 | H33: =YearMap!D2 -> 1617407.2 | I33: =A33&"|"&B33 -> D4_StatusQuo_Targets|FY2026 | O33: None | P33: None
A34: =A4 -> D4_StatusQuo_Targets | B34: FY2027 | C34: =IF(D4=1,0, BaselineCalc!$B$7 + ROUND(J4*F4,0)) -> 282 | D34: =IF(E4=1,0, BaselineCalc!$B$8 + J4 - ROUND(J4*F4,0)) -> 321 | E34: =C34+D34 -> 603 | F34: =YearMap!B3 -> 6574.8743 | G34: =YearMap!C3 -> 1439410.4 | H34: =YearMap!D3 -> 1657842.4 | I34: =A34&"|"&B34 -> D4_StatusQuo_Targets|FY2027 | O34: None | P34: None
A35: =A4 -> D4_StatusQuo_Targets | B35: FY2028 | C35: =IF(D4=1,0, BaselineCalc!$B$7 + ROUND(K4*F4,0)) -> 295 | D35: =IF(E4=1,0, BaselineCalc!$B$8 + K4 - ROUND(K4*F4,0)) -> 333 | E35: =C35+D35 -> 628 | F35: =YearMap!B4 -> 6739.2461 | G35: =YearMap!C4 -> 1475395.7 | H35: =YearMap!D4 -> 1699288.4 | I35: =A35&"|"&B35 -> D4_StatusQuo_Targets|FY2028 | O35: None | P35: None
A36: =A4 -> D4_StatusQuo_Targets | B36: FY2029 | C36: =IF(D4=1,0, BaselineCalc!$B$7 + ROUND(L4*F4,0)) -> 295 | D36: =IF(E4=1,0, BaselineCalc!$B$8 + L4 - ROUND(L4*F4,0)) -> 333 | E36: =C36+D36 -> 628 | F36: =YearMap!B5 -> 6907.7273 | G36: =YearMap!C5 -> 1512280.6 | H36: =YearMap!D5 -> 1741770.6 | I36: =A36&"|"&B36 -> D4_StatusQuo_Targets|FY2029 | O36: None | P36: None
A37: =A4 -> D4_StatusQuo_Targets | B37: FY2030 | C37: =IF(D4=1,0, BaselineCalc!$B$7 + ROUND(M4*F4,0)) -> 295 | D37: =IF(E4=1,0, BaselineCalc!$B$8 + M4 - ROUND(M4*F4,0)) -> 333 | E37: =C37+D37 -> 628 | F37: =YearMap!B6 -> 7080.4205 | G37: =YearMap!C6 -> 1550087.6 | H37: =YearMap!D6 -> 1785314.9 | I37: =A37&"|"&B37 -> D4_StatusQuo_Targets|FY2030 | O37: None | P37: None
A38: =A5 -> D3_CoLocation_Echo_Targets | B38: FY2026 | C38: =IF(D5=1,0, BaselineCalc!$B$7 + ROUND(I5*F5,0)) -> 265 | D38: =IF(E5=1,0, BaselineCalc!$B$8 + I5 - ROUND(I5*F5,0)) -> 304.66667 | E38: =C38+D38 -> 569.66667 | F38: =YearMap!B2 -> 6414.5115 | G38: =YearMap!C2 -> 1404302.9 | H38: =YearMap!D2 -> 1617407.2 | I38: =A38&"|"&B38 -> D3_CoLocation_Echo_Targets|FY2026 | O38: None | P38: None
A39: =A5 -> D3_CoLocation_Echo_Targets | B39: FY2027 | C39: =IF(D5=1,0, BaselineCalc!$B$7 + ROUND(J5*F5,0)) -> 274 | D39: =IF(E5=1,0, BaselineCalc!$B$8 + J5 - ROUND(J5*F5,0)) -> 312.33333 | E39: =C39+D39 -> 586.33333 | F39: =YearMap!B3 -> 6574.8743 | G39: =YearMap!C3 -> 1439410.4 | H39: =YearMap!D3 -> 1657842.4 | I39: =A39&"|"&B39 -> D3_CoLocation_Echo_Targets|FY2027 | O39: None | P39: None
A40: =A5 -> D3_CoLocation_Echo_Targets | B40: FY2028 | C40: =IF(D5=1,0, BaselineCalc!$B$7 + ROUND(K5*F5,0)) -> 282 | D40: =IF(E5=1,0, BaselineCalc!$B$8 + K5 - ROUND(K5*F5,0)) -> 321 | E40: =C40+D40 -> 603 | F40: =YearMap!B4 -> 6739.2461 | G40: =YearMap!C4 -> 1475395.7 | H40: =YearMap!D4 -> 1699288.4 | I40: =A40&"|"&B40 -> D3_CoLocation_Echo_Targets|FY2028 | O40: None | P40: None
A41: =A5 -> D3_CoLocation_Echo_Targets | B41: FY2029 | C41: =IF(D5=1,0, BaselineCalc!$B$7 + ROUND(L5*F5,0)) -> 282 | D41: =IF(E5=1,0, BaselineCalc!$B$8 + L5 - ROUND(L5*F5,0)) -> 321 | E41: =C41+D41 -> 603 | F41: =YearMap!B5 -> 6907.7273 | G41: =YearMap!C5 -> 1512280.6 | H41: =YearMap!D5 -> 1741770.6 | I41: =A41&"|"&B41 -> D3_CoLocation_Echo_Targets|FY2029 | O41: None | P41: None
A42: =A5 -> D3_CoLocation_Echo_Targets | B42: FY2030 | C42: =IF(D5=1,0, BaselineCalc!$B$7 + ROUND(M5*F5,0)) -> 282 | D42: =IF(E5=1,0, BaselineCalc!$B$8 + M5 - ROUND(M5*F5,0)) -> 321 | E42: =C42+D42 -> 603 | F42: =YearMap!B6 -> 7080.4205 | G42: =YearMap!C6 -> 1550087.6 | H42: =YearMap!D6 -> 1785314.9 | I42: =A42&"|"&B42 -> D3_CoLocation_Echo_Targets|FY2030 | O42: None | P42: None
