Workbook

Sheet Parameters
A1: Parameter | B1: Value | C1: Notes
A2: MO inflation | B2: 0.025 | C2: Annual inflation applied to M&O components
A3: Base MO per ADM (FY25) | B3: 9936 | C3: Auditor General/ACFR context; working base
A4: Fixed share of MO | B4: 0.3 | C4: Share of M&O treated as fixed plant/insurance
A5: Ops savings (keep-open) | B5: 0.007 | C5: Light ops discipline applied to keep-open scenarios
A6: Extra savings (Co-location) | B6: 0.015 | C6: Additional savings for F (co-location)
A7: Echo base ADM | B7: 257
A8: Pima base ADM | B8: 296
A9: Total base ADM | B9: 553 | C9: =B6+B7 -> 257.015
A10: Repurpose TI per closed site (FY26) | B10: 1200000 | C10: One-time tenant improvement/carry add in FY26
A13: Receiving overhead taper (h $/retained student) | B13: FY2026 | C13: FY2027 | D13: FY2028 | E13: FY2029 | F13: FY2030
A14: h | B14: 1000 | C14: 800 | D14: 600 | E14: 400 | F14: 300
A16: Fixed-carry path - Lease/Sale (f) | B16: FY2026 | C16: FY2027 | D16: FY2028 | E16: FY2029 | F16: FY2030
A17: f_lease | B17: 0.4 | C17: 0.3 | D17: 0.2 | E17: 0.1 | F17: 0
A19: Fixed-carry path - Ops Repurpose (f) | B19: FY2026 | C19: FY2027 | D19: FY2028 | E19: FY2029 | F19: FY2030
A20: f_ops | B20: 0.4 | C20: 0.35 | D20: 0.3 | E20: 0.25 | F20: 0.2

Sheet Calc
A1: Helper | B1: FY26 | C1: FY27 | D1: FY28 | E1: FY29 | F1: FY30
A2: Fixed total ($) | B2: 1689592 | C2: 1731831.8 | D2: 1775127.6 | E2: 1819505.7 | F2: 1864993.4
A3: Var unit ($/student) | B3: 7129.08 | C3: 7307.307 | D3: 7489.9897 | E3: 7677.2394 | F3: 7869.1704
A4: Echo fixed ($) | B4: 785217.24 | C4: 804847.67 | D4: 824968.86 | E4: 845593.08 | F4: 866732.91
A5: Pima fixed ($) | B5: 904374.72 | C5: 926984.09 | D5: 950158.69 | E5: 973912.66 | F5: 998260.47
A7: Receiving overhead h ($/retained) | B7: 1000 | C7: 800 | D7: 600 | E7: 400 | F7: 300
A8: Lease f (fraction) | B8: 0.4 | C8: 0.3 | D8: 0.2 | E8: 0.1 | F8: 0
A9: Ops f (fraction) | B9: 0.4 | C9: 0.35 | D9: 0.3 | E9: 0.25 | F9: 0.2
A11: Total base ADM | B11: 553

Sheet Scenarios
A1: ScenarioKey | B1: Label | C1: Overlay | D1: CloseEcho | E1: ClosePima | F1: EchoShareDist | G1: ExtraSave | H1: Ramp | I1: Umbrella
A2: A_Repurpose_Both_lease | B2: A. Repurpose Both (Lease/Sale) | C2: 0 | D2: 1 | E2: 1 | F2: 0.5 | G2: 0 | H2: 0 | I2: lease
A3: A_Repurpose_Both_ops | B3: A. Repurpose Both (Ops) | C3: 0 | D3: 1 | E3: 1 | F3: 0.5 | G3: 0 | H3: 0 | I3: ops
A4: B_Repurpose_Echo_Grow_Pima_lease | B4: B. Repurpose Echo; Grow Pima (Lease) | C4: 0 | D4: 1 | E4: 0 | F4: 0.5 | G4: 0 | H4: 0 | I4: lease
A5: B_Repurpose_Echo_Grow_Pima_ops | B5: B. Repurpose Echo; Grow Pima (Ops) | C5: 0 | D5: 1 | E5: 0 | F5: 0.5 | G5: 0 | H5: 0 | I5: ops
A6: C_Repurpose_Pima_Grow_Echo_lease | B6: C. Repurpose Pima; Grow Echo (Lease) | C6: 0 | D6: 0 | E6: 1 | F6: 0.5 | G6: 0 | H6: 0 | I6: lease
A7: C_Repurpose_Pima_Grow_Echo_ops | B7: C. Repurpose Pima; Grow Echo (Ops) | C7: 0 | D7: 0 | E7: 1 | F7: 0.5 | G7: 0 | H7: 0 | I7: ops
A8: D_Grow_Both_0 | B8: D. Grow Both (Overlay 0) | C8: 0 | D8: 0 | E8: 0 | F8: 0.5 | G8: 0 | H8: 0
A9: D_Grow_Both_100 | B9: D. Grow Both (Overlay 100) | C9: 100 | D9: 0 | E9: 0 | F9: 0.5 | G9: 0 | H9: 0
A10: D_Grow_Both_150 | B10: D. Grow Both (Overlay 150) | C10: 150 | D10: 0 | E10: 0 | F10: 0.5 | G10: 0 | H10: 0
A11: E_StatusQuo_Targets_0 | B11: E. Status-Quo + Targets (0) | C11: 0 | D11: 0 | E11: 0 | F11: 0.5 | G11: 0 | H11: 0
A12: E_StatusQuo_Targets_100 | B12: E. Status-Quo + Targets (100) | C12: 100 | D12: 0 | E12: 0 | F12: 0.5 | G12: 0 | H12: 0
A13: E_StatusQuo_Targets_150 | B13: E. Status-Quo + Targets (150) | C13: 150 | D13: 0 | E13: 0 | F13: 0.5 | G13: 0 | H13: 0
A14: F_CoLocation_Echo_0 | B14: F. Co-Location @ Echo (0) | C14: 0 | D14: 0 | E14: 0 | F14: 0.7 | G14: 0.015 | H14: 0
A15: F_CoLocation_Echo_100 | B15: F. Co-Location @ Echo (100) | C15: 100 | D15: 0 | E15: 0 | F15: 0.7 | G15: 0.015 | H15: 0
A16: F_CoLocation_Echo_150 | B16: F. Co-Location @ Echo (150) | C16: 150 | D16: 0 | E16: 0 | F16: 0.7 | G16: 0.015 | H16: 0
A17: G_DHub_EchoRamp | B17: G. D-Hub @ Echo (Ramp 70/30) | C17: 150 | D17: 0 | E17: 0 | F17: 0.7 | G17: 0 | H17: 1

Sheet MultiYear_ProForma
A1: ScenarioKey | B1: Year | C1: Overlay | D1: Echo_ADM | E1: Pima_ADM | F1: Total_ADM | G1: EchoFixed$ | H1: PimaFixed$ | I1: VarUnit$ | J1: TI_add$ | K1: OpsFactor | L1: ExtraSave | M1: Total_MO$ | N1: MO_per_ADM$
A2: =Scenarios!A2 -> A_Repurpose_Both_lease | B2: FY2026 | C2: =Scenarios!C2 -> 0 | F2: =D2+E2 -> 0 | G2: =IF(Scenarios!D2=1, IF(Scenarios!I2="lease", INDEX(Calc!B4:F4,1,1)*INDEX(Calc!B8:F8,1,1), INDEX(Calc!B4:F4,1,1)*INDEX(Calc!B9:F9,1,1)), INDEX(Calc!B4:F4,1,1)) -> 314086.9 | H2: =IF(Scenarios!E2=1, IF(Scenarios!I2="lease", INDEX(Calc!B5:F5,1,1)*INDEX(Calc!B8:F8,1,1), INDEX(Calc!B5:F5,1,1)*INDEX(Calc!B9:F9,1,1)), INDEX(Calc!B5:F5,1,1)) -> 361749.89 | I2: =INDEX(Calc!B3:F3,1,1) -> 7129.08 | J2: =IF("FY2026"="FY2026", (IF(Scenarios!D2=1, Parameters!B9,0) + IF(Scenarios!E2=1, Parameters!B9,0)), 0) -> 1106 | K2: =1-Parameters!B4 -> 0.7 | L2: =Scenarios!G2 -> 0 | N2: =IF(F2>0, L2/F2, NA()) -> #N/A
A3: =Scenarios!A2 -> A_Repurpose_Both_lease | B3: FY2027 | C3: =Scenarios!C2 -> 0 | F3: =D3+E3 -> 0 | G3: =IF(Scenarios!D2=1, IF(Scenarios!I2="lease", INDEX(Calc!B4:F4,1,2)*INDEX(Calc!B8:F8,1,2), INDEX(Calc!B4:F4,1,2)*INDEX(Calc!B9:F9,1,2)), INDEX(Calc!B4:F4,1,2)) -> 241454.3 | H3: =IF(Scenarios!E2=1, IF(Scenarios!I2="lease", INDEX(Calc!B5:F5,1,2)*INDEX(Calc!B8:F8,1,2), INDEX(Calc!B5:F5,1,2)*INDEX(Calc!B9:F9,1,2)), INDEX(Calc!B5:F5,1,2)) -> 278095.23 | I3: =INDEX(Calc!B3:F3,1,2) -> 7307.307 | J3: =IF("FY2027"="FY2026", (IF(Scenarios!D2=1, Parameters!B9,0) + IF(Scenarios!E2=1, Parameters!B9,0)), 0) -> 0 | K3: =1-Parameters!B4 -> 0.7 | L3: =Scenarios!G2 -> 0 | N3: =IF(F3>0, L3/F3, NA()) -> #N/A
A4: =Scenarios!A2 -> A_Repurpose_Both_lease | B4: FY2028 | C4: =Scenarios!C2 -> 0 | F4: =D4+E4 -> 0 | G4: =IF(Scenarios!D2=1, IF(Scenarios!I2="lease", INDEX(Calc!B4:F4,1,3)*INDEX(Calc!B8:F8,1,3), INDEX(Calc!B4:F4,1,3)*INDEX(Calc!B9:F9,1,3)), INDEX(Calc!B4:F4,1,3)) -> 164993.77 | H4: =IF(Scenarios!E2=1, IF(Scenarios!I2="lease", INDEX(Calc!B5:F5,1,3)*INDEX(Calc!B8:F8,1,3), INDEX(Calc!B5:F5,1,3)*INDEX(Calc!B9:F9,1,3)), INDEX(Calc!B5:F5,1,3)) -> 190031.74 | I4: =INDEX(Calc!B3:F3,1,3) -> 7489.9897 | J4: =IF("FY2028"="FY2026", (IF(Scenarios!D2=1, Parameters!B9,0) + IF(Scenarios!E2=1, Parameters!B9,0)), 0) -> 0 | K4: =1-Parameters!B4 -> 0.7 | L4: =Scenarios!G2 -> 0 | N4: =IF(F4>0, L4/F4, NA()) -> #N/A
A5: =Scenarios!A2 -> A_Repurpose_Both_lease | B5: FY2029 | C5: =Scenarios!C2 -> 0 | F5: =D5+E5 -> 0 | G5: =IF(Scenarios!D2=1, IF(Scenarios!I2="lease", INDEX(Calc!B4:F4,1,4)*INDEX(Calc!B8:F8,1,4), INDEX(Calc!B4:F4,1,4)*INDEX(Calc!B9:F9,1,4)), INDEX(Calc!B4:F4,1,4)) -> 84559.308 | H5: =IF(Scenarios!E2=1, IF(Scenarios!I2="lease", INDEX(Calc!B5:F5,1,4)*INDEX(Calc!B8:F8,1,4), INDEX(Calc!B5:F5,1,4)*INDEX(Calc!B9:F9,1,4)), INDEX(Calc!B5:F5,1,4)) -> 97391.266 | I5: =INDEX(Calc!B3:F3,1,4) -> 7677.2394 | J5: =IF("FY2029"="FY2026", (IF(Scenarios!D2=1, Parameters!B9,0) + IF(Scenarios!E2=1, Parameters!B9,0)), 0) -> 0 | K5: =1-Parameters!B4 -> 0.7 | L5: =Scenarios!G2 -> 0 | N5: =IF(F5>0, L5/F5, NA()) -> #N/A
A6: =Scenarios!A2 -> A_Repurpose_Both_lease | B6: FY2030 | C6: =Scenarios!C2 -> 0 | F6: =D6+E6 -> 0 | G6: =IF(Scenarios!D2=1, IF(Scenarios!I2="lease", INDEX(Calc!B4:F4,1,5)*INDEX(Calc!B8:F8,1,5), INDEX(Calc!B4:F4,1,5)*INDEX(Calc!B9:F9,1,5)), INDEX(Calc!B4:F4,1,5)) -> 0 | H6: =IF(Scenarios!E2=1, IF(Scenarios!I2="lease", INDEX(Calc!B5:F5,1,5)*INDEX(Calc!B8:F8,1,5), INDEX(Calc!B5:F5,1,5)*INDEX(Calc!B9:F9,1,5)), INDEX(Calc!B5:F5,1,5)) -> 0 | I6: =INDEX(Calc!B3:F3,1,5) -> 7869.1704 | J6: =IF("FY2030"="FY2026", (IF(Scenarios!D2=1, Parameters!B9,0) + IF(Scenarios!E2=1, Parameters!B9,0)), 0) -> 0 | K6: =1-Parameters!B4 -> 0.7 | L6: =Scenarios!G2 -> 0 | N6: =IF(F6>0, L6/F6, NA()) -> #N/A
A7: =Scenarios!A3 -> A_Repurpose_Both_ops | B7: FY2026 | C7: =Scenarios!C3 -> 0 | F7: =D7+E7 -> 0 | G7: =IF(Scenarios!D3=1, IF(Scenarios!I3="lease", INDEX(Calc!B4:F4,1,1)*INDEX(Calc!B8:F8,1,1), INDEX(Calc!B4:F4,1,1)*INDEX(Calc!B9:F9,1,1)), INDEX(Calc!B4:F4,1,1)) -> 314086.9 | H7: =IF(Scenarios!E3=1, IF(Scenarios!I3="lease", INDEX(Calc!B5:F5,1,1)*INDEX(Calc!B8:F8,1,1), INDEX(Calc!B5:F5,1,1)*INDEX(Calc!B9:F9,1,1)), INDEX(Calc!B5:F5,1,1)) -> 361749.89 | I7: =INDEX(Calc!B3:F3,1,1) -> 7129.08 | J7: =IF("FY2026"="FY2026", (IF(Scenarios!D3=1, Parameters!B9,0) + IF(Scenarios!E3=1, Parameters!B9,0)), 0) -> 1106 | K7: =1-Parameters!B4 -> 0.7 | L7: =Scenarios!G3 -> 0 | N7: =IF(F7>0, L7/F7, NA()) -> #N/A
A8: =Scenarios!A3 -> A_Repurpose_Both_ops | B8: FY2027 | C8: =Scenarios!C3 -> 0 | F8: =D8+E8 -> 0 | G8: =IF(Scenarios!D3=1, IF(Scenarios!I3="lease", INDEX(Calc!B4:F4,1,2)*INDEX(Calc!B8:F8,1,2), INDEX(Calc!B4:F4,1,2)*INDEX(Calc!B9:F9,1,2)), INDEX(Calc!B4:F4,1,2)) -> 281696.68 | H8: =IF(Scenarios!E3=1, IF(Scenarios!I3="lease", INDEX(Calc!B5:F5,1,2)*INDEX(Calc!B8:F8,1,2), INDEX(Calc!B5:F5,1,2)*INDEX(Calc!B9:F9,1,2)), INDEX(Calc!B5:F5,1,2)) -> 324444.43 | I8: =INDEX(Calc!B3:F3,1,2) -> 7307.307 | J8: =IF("FY2027"="FY2026", (IF(Scenarios!D3=1, Parameters!B9,0) + IF(Scenarios!E3=1, Parameters!B9,0)), 0) -> 0 | K8: =1-Parameters!B4 -> 0.7 | L8: =Scenarios!G3 -> 0 | N8: =IF(F8>0, L8/F8, NA()) -> #N/A
A9: =Scenarios!A3 -> A_Repurpose_Both_ops | B9: FY2028 | C9: =Scenarios!C3 -> 0 | F9: =D9+E9 -> 0 | G9: =IF(Scenarios!D3=1, IF(Scenarios!I3="lease", INDEX(Calc!B4:F4,1,3)*INDEX(Calc!B8:F8,1,3), INDEX(Calc!B4:F4,1,3)*INDEX(Calc!B9:F9,1,3)), INDEX(Calc!B4:F4,1,3)) -> 247490.66 | H9: =IF(Scenarios!E3=1, IF(Scenarios!I3="lease", INDEX(Calc!B5:F5,1,3)*INDEX(Calc!B8:F8,1,3), INDEX(Calc!B5:F5,1,3)*INDEX(Calc!B9:F9,1,3)), INDEX(Calc!B5:F5,1,3)) -> 285047.61 | I9: =INDEX(Calc!B3:F3,1,3) -> 7489.9897 | J9: =IF("FY2028"="FY2026", (IF(Scenarios!D3=1, Parameters!B9,0) + IF(Scenarios!E3=1, Parameters!B9,0)), 0) -> 0 | K9: =1-Parameters!B4 -> 0.7 | L9: =Scenarios!G3 -> 0 | N9: =IF(F9>0, L9/F9, NA()) -> #N/A
A10: =Scenarios!A3 -> A_Repurpose_Both_ops | B10: FY2029 | C10: =Scenarios!C3 -> 0 | F10: =D10+E10 -> 0 | G10: =IF(Scenarios!D3=1, IF(Scenarios!I3="lease", INDEX(Calc!B4:F4,1,4)*INDEX(Calc!B8:F8,1,4), INDEX(Calc!B4:F4,1,4)*INDEX(Calc!B9:F9,1,4)), INDEX(Calc!B4:F4,1,4)) -> 211398.27 | H10: =IF(Scenarios!E3=1, IF(Scenarios!I3="lease", INDEX(Calc!B5:F5,1,4)*INDEX(Calc!B8:F8,1,4), INDEX(Calc!B5:F5,1,4)*INDEX(Calc!B9:F9,1,4)), INDEX(Calc!B5:F5,1,4)) -> 243478.16 | I10: =INDEX(Calc!B3:F3,1,4) -> 7677.2394 | J10: =IF("FY2029"="FY2026", (IF(Scenarios!D3=1, Parameters!B9,0) + IF(Scenarios!E3=1, Parameters!B9,0)), 0) -> 0 | K10: =1-Parameters!B4 -> 0.7 | L10: =Scenarios!G3 -> 0 | N10: =IF(F10>0, L10/F10, NA()) -> #N/A
A11: =Scenarios!A3 -> A_Repurpose_Both_ops | B11: FY2030 | C11: =Scenarios!C3 -> 0 | F11: =D11+E11 -> 0 | G11: =IF(Scenarios!D3=1, IF(Scenarios!I3="lease", INDEX(Calc!B4:F4,1,5)*INDEX(Calc!B8:F8,1,5), INDEX(Calc!B4:F4,1,5)*INDEX(Calc!B9:F9,1,5)), INDEX(Calc!B4:F4,1,5)) -> 173346.58 | H11: =IF(Scenarios!E3=1, IF(Scenarios!I3="lease", INDEX(Calc!B5:F5,1,5)*INDEX(Calc!B8:F8,1,5), INDEX(Calc!B5:F5,1,5)*INDEX(Calc!B9:F9,1,5)), INDEX(Calc!B5:F5,1,5)) -> 199652.09 | I11: =INDEX(Calc!B3:F3,1,5) -> 7869.1704 | J11: =IF("FY2030"="FY2026", (IF(Scenarios!D3=1, Parameters!B9,0) + IF(Scenarios!E3=1, Parameters!B9,0)), 0) -> 0 | K11: =1-Parameters!B4 -> 0.7 | L11: =Scenarios!G3 -> 0 | N11: =IF(F11>0, L11/F11, NA()) -> #N/A
A12: =Scenarios!A4 -> B_Repurpose_Echo_Grow_Pima_lease | B12: FY2026 | C12: =Scenarios!C4 -> 0 | F12: =D12+E12 -> 0 | G12: =IF(Scenarios!D4=1, IF(Scenarios!I4="lease", INDEX(Calc!B4:F4,1,1)*INDEX(Calc!B8:F8,1,1), INDEX(Calc!B4:F4,1,1)*INDEX(Calc!B9:F9,1,1)), INDEX(Calc!B4:F4,1,1)) -> 314086.9 | H12: =IF(Scenarios!E4=1, IF(Scenarios!I4="lease", INDEX(Calc!B5:F5,1,1)*INDEX(Calc!B8:F8,1,1), INDEX(Calc!B5:F5,1,1)*INDEX(Calc!B9:F9,1,1)), INDEX(Calc!B5:F5,1,1)) -> 904374.72 | I12: =INDEX(Calc!B3:F3,1,1) -> 7129.08 | J12: =IF("FY2026"="FY2026", (IF(Scenarios!D4=1, Parameters!B9,0) + IF(Scenarios!E4=1, Parameters!B9,0)), 0) -> 553 | K12: =1-Parameters!B4 -> 0.7 | L12: =Scenarios!G4 -> 0 | N12: =IF(F12>0, L12/F12, NA()) -> #N/A
A13: =Scenarios!A4 -> B_Repurpose_Echo_Grow_Pima_lease | B13: FY2027 | C13: =Scenarios!C4 -> 0 | F13: =D13+E13 -> 0 | G13: =IF(Scenarios!D4=1, IF(Scenarios!I4="lease", INDEX(Calc!B4:F4,1,2)*INDEX(Calc!B8:F8,1,2), INDEX(Calc!B4:F4,1,2)*INDEX(Calc!B9:F9,1,2)), INDEX(Calc!B4:F4,1,2)) -> 241454.3 | H13: =IF(Scenarios!E4=1, IF(Scenarios!I4="lease", INDEX(Calc!B5:F5,1,2)*INDEX(Calc!B8:F8,1,2), INDEX(Calc!B5:F5,1,2)*INDEX(Calc!B9:F9,1,2)), INDEX(Calc!B5:F5,1,2)) -> 926984.09 | I13: =INDEX(Calc!B3:F3,1,2) -> 7307.307 | J13: =IF("FY2027"="FY2026", (IF(Scenarios!D4=1, Parameters!B9,0) + IF(Scenarios!E4=1, Parameters!B9,0)), 0) -> 0 | K13: =1-Parameters!B4 -> 0.7 | L13: =Scenarios!G4 -> 0 | N13: =IF(F13>0, L13/F13, NA()) -> #N/A
A14: =Scenarios!A4 -> B_Repurpose_Echo_Grow_Pima_lease | B14: FY2028 | C14: =Scenarios!C4 -> 0 | F14: =D14+E14 -> 0 | G14: =IF(Scenarios!D4=1, IF(Scenarios!I4="lease", INDEX(Calc!B4:F4,1,3)*INDEX(Calc!B8:F8,1,3), INDEX(Calc!B4:F4,1,3)*INDEX(Calc!B9:F9,1,3)), INDEX(Calc!B4:F4,1,3)) -> 164993.77 | H14: =IF(Scenarios!E4=1, IF(Scenarios!I4="lease", INDEX(Calc!B5:F5,1,3)*INDEX(Calc!B8:F8,1,3), INDEX(Calc!B5:F5,1,3)*INDEX(Calc!B9:F9,1,3)), INDEX(Calc!B5:F5,1,3)) -> 950158.69 | I14: =INDEX(Calc!B3:F3,1,3) -> 7489.9897 | J14: =IF("FY2028"="FY2026", (IF(Scenarios!D4=1, Parameters!B9,0) + IF(Scenarios!E4=1, Parameters!B9,0)), 0) -> 0 | K14: =1-Parameters!B4 -> 0.7 | L14: =Scenarios!G4 -> 0 | N14: =IF(F14>0, L14/F14, NA()) -> #N/A
A15: =Scenarios!A4 -> B_Repurpose_Echo_Grow_Pima_lease | B15: FY2029 | C15: =Scenarios!C4 -> 0 | F15: =D15+E15 -> 0 | G15: =IF(Scenarios!D4=1, IF(Scenarios!I4="lease", INDEX(Calc!B4:F4,1,4)*INDEX(Calc!B8:F8,1,4), INDEX(Calc!B4:F4,1,4)*INDEX(Calc!B9:F9,1,4)), INDEX(Calc!B4:F4,1,4)) -> 84559.308 | H15: =IF(Scenarios!E4=1, IF(Scenarios!I4="lease", INDEX(Calc!B5:F5,1,4)*INDEX(Calc!B8:F8,1,4), INDEX(Calc!B5:F5,1,4)*INDEX(Calc!B9:F9,1,4)), INDEX(Calc!B5:F5,1,4)) -> 973912.66 | I15: =INDEX(Calc!B3:F3,1,4) -> 7677.2394 | J15: =IF("FY2029"="FY2026", (IF(Scenarios!D4=1, Parameters!B9,0) + IF(Scenarios!E4=1, Parameters!B9,0)), 0) -> 0 | K15: =1-Parameters!B4 -> 0.7 | L15: =Scenarios!G4 -> 0 | N15: =IF(F15>0, L15/F15, NA()) -> #N/A
A16: =Scenarios!A4 -> B_Repurpose_Echo_Grow_Pima_lease | B16: FY2030 | C16: =Scenarios!C4 -> 0 | F16: =D16+E16 -> 0 | G16: =IF(Scenarios!D4=1, IF(Scenarios!I4="lease", INDEX(Calc!B4:F4,1,5)*INDEX(Calc!B8:F8,1,5), INDEX(Calc!B4:F4,1,5)*INDEX(Calc!B9:F9,1,5)), INDEX(Calc!B4:F4,1,5)) -> 0 | H16: =IF(Scenarios!E4=1, IF(Scenarios!I4="lease", INDEX(Calc!B5:F5,1,5)*INDEX(Calc!B8:F8,1,5), INDEX(Calc!B5:F5,1,5)*INDEX(Calc!B9:F9,1,5)), INDEX(Calc!B5:F5,1,5)) -> 998260.47 | I16: =INDEX(Calc!B3:F3,1,5) -> 7869.1704 | J16: =IF("FY2030"="FY2026", (IF(Scenarios!D4=1, Parameters!B9,0) + IF(Scenarios!E4=1, Parameters!B9,0)), 0) -> 0 | K16: =1-Parameters!B4 -> 0.7 | L16: =Scenarios!G4 -> 0 | N16: =IF(F16>0, L16/F16, NA()) -> #N/A
A17: =Scenarios!A5 -> B_Repurpose_Echo_Grow_Pima_ops | B17: FY2026 | C17: =Scenarios!C5 -> 0 | F17: =D17+E17 -> 0 | G17: =IF(Scenarios!D5=1, IF(Scenarios!I5="lease", INDEX(Calc!B4:F4,1,1)*INDEX(Calc!B8:F8,1,1), INDEX(Calc!B4:F4,1,1)*INDEX(Calc!B9:F9,1,1)), INDEX(Calc!B4:F4,1,1)) -> 314086.9 | H17: =IF(Scenarios!E5=1, IF(Scenarios!I5="lease", INDEX(Calc!B5:F5,1,1)*INDEX(Calc!B8:F8,1,1), INDEX(Calc!B5:F5,1,1)*INDEX(Calc!B9:F9,1,1)), INDEX(Calc!B5:F5,1,1)) -> 904374.72 | I17: =INDEX(Calc!B3:F3,1,1) -> 7129.08 | J17: =IF("FY2026"="FY2026", (IF(Scenarios!D5=1, Parameters!B9,0) + IF(Scenarios!E5=1, Parameters!B9,0)), 0) -> 553 | K17: =1-Parameters!B4 -> 0.7 | L17: =Scenarios!G5 -> 0 | N17: =IF(F17>0, L17/F17, NA()) -> #N/A
A18: =Scenarios!A5 -> B_Repurpose_Echo_Grow_Pima_ops | B18: FY2027 | C18: =Scenarios!C5 -> 0 | F18: =D18+E18 -> 0 | G18: =IF(Scenarios!D5=1, IF(Scenarios!I5="lease", INDEX(Calc!B4:F4,1,2)*INDEX(Calc!B8:F8,1,2), INDEX(Calc!B4:F4,1,2)*INDEX(Calc!B9:F9,1,2)), INDEX(Calc!B4:F4,1,2)) -> 281696.68 | H18: =IF(Scenarios!E5=1, IF(Scenarios!I5="lease", INDEX(Calc!B5:F5,1,2)*INDEX(Calc!B8:F8,1,2), INDEX(Calc!B5:F5,1,2)*INDEX(Calc!B9:F9,1,2)), INDEX(Calc!B5:F5,1,2)) -> 926984.09 | I18: =INDEX(Calc!B3:F3,1,2) -> 7307.307 | J18: =IF("FY2027"="FY2026", (IF(Scenarios!D5=1, Parameters!B9,0) + IF(Scenarios!E5=1, Parameters!B9,0)), 0) -> 0 | K18: =1-Parameters!B4 -> 0.7 | L18: =Scenarios!G5 -> 0 | N18: =IF(F18>0, L18/F18, NA()) -> #N/A
A19: =Scenarios!A5 -> B_Repurpose_Echo_Grow_Pima_ops | B19: FY2028 | C19: =Scenarios!C5 -> 0 | F19: =D19+E19 -> 0 | G19: =IF(Scenarios!D5=1, IF(Scenarios!I5="lease", INDEX(Calc!B4:F4,1,3)*INDEX(Calc!B8:F8,1,3), INDEX(Calc!B4:F4,1,3)*INDEX(Calc!B9:F9,1,3)), INDEX(Calc!B4:F4,1,3)) -> 247490.66 | H19: =IF(Scenarios!E5=1, IF(Scenarios!I5="lease", INDEX(Calc!B5:F5,1,3)*INDEX(Calc!B8:F8,1,3), INDEX(Calc!B5:F5,1,3)*INDEX(Calc!B9:F9,1,3)), INDEX(Calc!B5:F5,1,3)) -> 950158.69 | I19: =INDEX(Calc!B3:F3,1,3) -> 7489.9897 | J19: =IF("FY2028"="FY2026", (IF(Scenarios!D5=1, Parameters!B9,0) + IF(Scenarios!E5=1, Parameters!B9,0)), 0) -> 0 | K19: =1-Parameters!B4 -> 0.7 | L19: =Scenarios!G5 -> 0 | N19: =IF(F19>0, L19/F19, NA()) -> #N/A
A20: =Scenarios!A5 -> B_Repurpose_Echo_Grow_Pima_ops | B20: FY2029 | C20: =Scenarios!C5 -> 0 | F20: =D20+E20 -> 0 | G20: =IF(Scenarios!D5=1, IF(Scenarios!I5="lease", INDEX(Calc!B4:F4,1,4)*INDEX(Calc!B8:F8,1,4), INDEX(Calc!B4:F4,1,4)*INDEX(Calc!B9:F9,1,4)), INDEX(Calc!B4:F4,1,4)) -> 211398.27 | H20: =IF(Scenarios!E5=1, IF(Scenarios!I5="lease", INDEX(Calc!B5:F5,1,4)*INDEX(Calc!B8:F8,1,4), INDEX(Calc!B5:F5,1,4)*INDEX(Calc!B9:F9,1,4)), INDEX(Calc!B5:F5,1,4)) -> 973912.66 | I20: =INDEX(Calc!B3:F3,1,4) -> 7677.2394 | J20: =IF("FY2029"="FY2026", (IF(Scenarios!D5=1, Parameters!B9,0) + IF(Scenarios!E5=1, Parameters!B9,0)), 0) -> 0 | K20: =1-Parameters!B4 -> 0.7 | L20: =Scenarios!G5 -> 0 | N20: =IF(F20>0, L20/F20, NA()) -> #N/A
A21: =Scenarios!A5 -> B_Repurpose_Echo_Grow_Pima_ops | B21: FY2030 | C21: =Scenarios!C5 -> 0 | F21: =D21+E21 -> 0 | G21: =IF(Scenarios!D5=1, IF(Scenarios!I5="lease", INDEX(Calc!B4:F4,1,5)*INDEX(Calc!B8:F8,1,5), INDEX(Calc!B4:F4,1,5)*INDEX(Calc!B9:F9,1,5)), INDEX(Calc!B4:F4,1,5)) -> 173346.58 | H21: =IF(Scenarios!E5=1, IF(Scenarios!I5="lease", INDEX(Calc!B5:F5,1,5)*INDEX(Calc!B8:F8,1,5), INDEX(Calc!B5:F5,1,5)*INDEX(Calc!B9:F9,1,5)), INDEX(Calc!B5:F5,1,5)) -> 998260.47 | I21: =INDEX(Calc!B3:F3,1,5) -> 7869.1704 | J21: =IF("FY2030"="FY2026", (IF(Scenarios!D5=1, Parameters!B9,0) + IF(Scenarios!E5=1, Parameters!B9,0)), 0) -> 0 | K21: =1-Parameters!B4 -> 0.7 | L21: =Scenarios!G5 -> 0 | N21: =IF(F21>0, L21/F21, NA()) -> #N/A
A22: =Scenarios!A6 -> C_Repurpose_Pima_Grow_Echo_lease | B22: FY2026 | C22: =Scenarios!C6 -> 0 | F22: =D22+E22 -> 0 | G22: =IF(Scenarios!D6=1, IF(Scenarios!I6="lease", INDEX(Calc!B4:F4,1,1)*INDEX(Calc!B8:F8,1,1), INDEX(Calc!B4:F4,1,1)*INDEX(Calc!B9:F9,1,1)), INDEX(Calc!B4:F4,1,1)) -> 785217.24 | H22: =IF(Scenarios!E6=1, IF(Scenarios!I6="lease", INDEX(Calc!B5:F5,1,1)*INDEX(Calc!B8:F8,1,1), INDEX(Calc!B5:F5,1,1)*INDEX(Calc!B9:F9,1,1)), INDEX(Calc!B5:F5,1,1)) -> 361749.89 | I22: =INDEX(Calc!B3:F3,1,1) -> 7129.08 | J22: =IF("FY2026"="FY2026", (IF(Scenarios!D6=1, Parameters!B9,0) + IF(Scenarios!E6=1, Parameters!B9,0)), 0) -> 553 | K22: =1-Parameters!B4 -> 0.7 | L22: =Scenarios!G6 -> 0 | N22: =IF(F22>0, L22/F22, NA()) -> #N/A
A23: =Scenarios!A6 -> C_Repurpose_Pima_Grow_Echo_lease | B23: FY2027 | C23: =Scenarios!C6 -> 0 | F23: =D23+E23 -> 0 | G23: =IF(Scenarios!D6=1, IF(Scenarios!I6="lease", INDEX(Calc!B4:F4,1,2)*INDEX(Calc!B8:F8,1,2), INDEX(Calc!B4:F4,1,2)*INDEX(Calc!B9:F9,1,2)), INDEX(Calc!B4:F4,1,2)) -> 804847.67 | H23: =IF(Scenarios!E6=1, IF(Scenarios!I6="lease", INDEX(Calc!B5:F5,1,2)*INDEX(Calc!B8:F8,1,2), INDEX(Calc!B5:F5,1,2)*INDEX(Calc!B9:F9,1,2)), INDEX(Calc!B5:F5,1,2)) -> 278095.23 | I23: =INDEX(Calc!B3:F3,1,2) -> 7307.307 | J23: =IF("FY2027"="FY2026", (IF(Scenarios!D6=1, Parameters!B9,0) + IF(Scenarios!E6=1, Parameters!B9,0)), 0) -> 0 | K23: =1-Parameters!B4 -> 0.7 | L23: =Scenarios!G6 -> 0 | N23: =IF(F23>0, L23/F23, NA()) -> #N/A
A24: =Scenarios!A6 -> C_Repurpose_Pima_Grow_Echo_lease | B24: FY2028 | C24: =Scenarios!C6 -> 0 | F24: =D24+E24 -> 0 | G24: =IF(Scenarios!D6=1, IF(Scenarios!I6="lease", INDEX(Calc!B4:F4,1,3)*INDEX(Calc!B8:F8,1,3), INDEX(Calc!B4:F4,1,3)*INDEX(Calc!B9:F9,1,3)), INDEX(Calc!B4:F4,1,3)) -> 824968.86 | H24: =IF(Scenarios!E6=1, IF(Scenarios!I6="lease", INDEX(Calc!B5:F5,1,3)*INDEX(Calc!B8:F8,1,3), INDEX(Calc!B5:F5,1,3)*INDEX(Calc!B9:F9,1,3)), INDEX(Calc!B5:F5,1,3)) -> 190031.74 | I24: =INDEX(Calc!B3:F3,1,3) -> 7489.9897 | J24: =IF("FY2028"="FY2026", (IF(Scenarios!D6=1, Parameters!B9,0) + IF(Scenarios!E6=1, Parameters!B9,0)), 0) -> 0 | K24: =1-Parameters!B4 -> 0.7 | L24: =Scenarios!G6 -> 0 | N24: =IF(F24>0, L24/F24, NA()) -> #N/A
A25: =Scenarios!A6 -> C_Repurpose_Pima_Grow_Echo_lease | B25: FY2029 | C25: =Scenarios!C6 -> 0 | F25: =D25+E25 -> 0 | G25: =IF(Scenarios!D6=1, IF(Scenarios!I6="lease", INDEX(Calc!B4:F4,1,4)*INDEX(Calc!B8:F8,1,4), INDEX(Calc!B4:F4,1,4)*INDEX(Calc!B9:F9,1,4)), INDEX(Calc!B4:F4,1,4)) -> 845593.08 | H25: =IF(Scenarios!E6=1, IF(Scenarios!I6="lease", INDEX(Calc!B5:F5,1,4)*INDEX(Calc!B8:F8,1,4), INDEX(Calc!B5:F5,1,4)*INDEX(Calc!B9:F9,1,4)), INDEX(Calc!B5:F5,1,4)) -> 97391.266 | I25: =INDEX(Calc!B3:F3,1,4) -> 7677.2394 | J25: =IF("FY2029"="FY2026", (IF(Scenarios!D6=1, Parameters!B9,0) + IF(Scenarios!E6=1, Parameters!B9,0)), 0) -> 0 | K25: =1-Parameters!B4 -> 0.7 | L25: =Scenarios!G6 -> 0 | N25: =IF(F25>0, L25/F25, NA()) -> #N/A
A26: =Scenarios!A6 -> C_Repurpose_Pima_Grow_Echo_lease | B26: FY2030 | C26: =Scenarios!C6 -> 0 | F26: =D26+E26 -> 0 | G26: =IF(Scenarios!D6=1, IF(Scenarios!I6="lease", INDEX(Calc!B4:F4,1,5)*INDEX(Calc!B8:F8,1,5), INDEX(Calc!B4:F4,1,5)*INDEX(Calc!B9:F9,1,5)), INDEX(Calc!B4:F4,1,5)) -> 866732.91 | H26: =IF(Scenarios!E6=1, IF(Scenarios!I6="lease", INDEX(Calc!B5:F5,1,5)*INDEX(Calc!B8:F8,1,5), INDEX(Calc!B5:F5,1,5)*INDEX(Calc!B9:F9,1,5)), INDEX(Calc!B5:F5,1,5)) -> 0 | I26: =INDEX(Calc!B3:F3,1,5) -> 7869.1704 | J26: =IF("FY2030"="FY2026", (IF(Scenarios!D6=1, Parameters!B9,0) + IF(Scenarios!E6=1, Parameters!B9,0)), 0) -> 0 | K26: =1-Parameters!B4 -> 0.7 | L26: =Scenarios!G6 -> 0 | N26: =IF(F26>0, L26/F26, NA()) -> #N/A
A27: =Scenarios!A7 -> C_Repurpose_Pima_Grow_Echo_ops | B27: FY2026 | C27: =Scenarios!C7 -> 0 | F27: =D27+E27 -> 0 | G27: =IF(Scenarios!D7=1, IF(Scenarios!I7="lease", INDEX(Calc!B4:F4,1,1)*INDEX(Calc!B8:F8,1,1), INDEX(Calc!B4:F4,1,1)*INDEX(Calc!B9:F9,1,1)), INDEX(Calc!B4:F4,1,1)) -> 785217.24 | H27: =IF(Scenarios!E7=1, IF(Scenarios!I7="lease", INDEX(Calc!B5:F5,1,1)*INDEX(Calc!B8:F8,1,1), INDEX(Calc!B5:F5,1,1)*INDEX(Calc!B9:F9,1,1)), INDEX(Calc!B5:F5,1,1)) -> 361749.89 | I27: =INDEX(Calc!B3:F3,1,1) -> 7129.08 | J27: =IF("FY2026"="FY2026", (IF(Scenarios!D7=1, Parameters!B9,0) + IF(Scenarios!E7=1, Parameters!B9,0)), 0) -> 553 | K27: =1-Parameters!B4 -> 0.7 | L27: =Scenarios!G7 -> 0 | N27: =IF(F27>0, L27/F27, NA()) -> #N/A
A28: =Scenarios!A7 -> C_Repurpose_Pima_Grow_Echo_ops | B28: FY2027 | C28: =Scenarios!C7 -> 0 | F28: =D28+E28 -> 0 | G28: =IF(Scenarios!D7=1, IF(Scenarios!I7="lease", INDEX(Calc!B4:F4,1,2)*INDEX(Calc!B8:F8,1,2), INDEX(Calc!B4:F4,1,2)*INDEX(Calc!B9:F9,1,2)), INDEX(Calc!B4:F4,1,2)) -> 804847.67 | H28: =IF(Scenarios!E7=1, IF(Scenarios!I7="lease", INDEX(Calc!B5:F5,1,2)*INDEX(Calc!B8:F8,1,2), INDEX(Calc!B5:F5,1,2)*INDEX(Calc!B9:F9,1,2)), INDEX(Calc!B5:F5,1,2)) -> 324444.43 | I28: =INDEX(Calc!B3:F3,1,2) -> 7307.307 | J28: =IF("FY2027"="FY2026", (IF(Scenarios!D7=1, Parameters!B9,0) + IF(Scenarios!E7=1, Parameters!B9,0)), 0) -> 0 | K28: =1-Parameters!B4 -> 0.7 | L28: =Scenarios!G7 -> 0 | N28: =IF(F28>0, L28/F28, NA()) -> #N/A
A29: =Scenarios!A7 -> C_Repurpose_Pima_Grow_Echo_ops | B29: FY2028 | C29: =Scenarios!C7 -> 0 | F29: =D29+E29 -> 0 | G29: =IF(Scenarios!D7=1, IF(Scenarios!I7="lease", INDEX(Calc!B4:F4,1,3)*INDEX(Calc!B8:F8,1,3), INDEX(Calc!B4:F4,1,3)*INDEX(Calc!B9:F9,1,3)), INDEX(Calc!B4:F4,1,3)) -> 824968.86 | H29: =IF(Scenarios!E7=1, IF(Scenarios!I7="lease", INDEX(Calc!B5:F5,1,3)*INDEX(Calc!B8:F8,1,3), INDEX(Calc!B5:F5,1,3)*INDEX(Calc!B9:F9,1,3)), INDEX(Calc!B5:F5,1,3)) -> 285047.61 | I29: =INDEX(Calc!B3:F3,1,3) -> 7489.9897 | J29: =IF("FY2028"="FY2026", (IF(Scenarios!D7=1, Parameters!B9,0) + IF(Scenarios!E7=1, Parameters!B9,0)), 0) -> 0 | K29: =1-Parameters!B4 -> 0.7 | L29: =Scenarios!G7 -> 0 | N29: =IF(F29>0, L29/F29, NA()) -> #N/A
A30: =Scenarios!A7 -> C_Repurpose_Pima_Grow_Echo_ops | B30: FY2029 | C30: =Scenarios!C7 -> 0 | F30: =D30+E30 -> 0 | G30: =IF(Scenarios!D7=1, IF(Scenarios!I7="lease", INDEX(Calc!B4:F4,1,4)*INDEX(Calc!B8:F8,1,4), INDEX(Calc!B4:F4,1,4)*INDEX(Calc!B9:F9,1,4)), INDEX(Calc!B4:F4,1,4)) -> 845593.08 | H30: =IF(Scenarios!E7=1, IF(Scenarios!I7="lease", INDEX(Calc!B5:F5,1,4)*INDEX(Calc!B8:F8,1,4), INDEX(Calc!B5:F5,1,4)*INDEX(Calc!B9:F9,1,4)), INDEX(Calc!B5:F5,1,4)) -> 243478.16 | I30: =INDEX(Calc!B3:F3,1,4) -> 7677.2394 | J30: =IF("FY2029"="FY2026", (IF(Scenarios!D7=1, Parameters!B9,0) + IF(Scenarios!E7=1, Parameters!B9,0)), 0) -> 0 | K30: =1-Parameters!B4 -> 0.7 | L30: =Scenarios!G7 -> 0 | N30: =IF(F30>0, L30/F30, NA()) -> #N/A
A31: =Scenarios!A7 -> C_Repurpose_Pima_Grow_Echo_ops | B31: FY2030 | C31: =Scenarios!C7 -> 0 | F31: =D31+E31 -> 0 | G31: =IF(Scenarios!D7=1, IF(Scenarios!I7="lease", INDEX(Calc!B4:F4,1,5)*INDEX(Calc!B8:F8,1,5), INDEX(Calc!B4:F4,1,5)*INDEX(Calc!B9:F9,1,5)), INDEX(Calc!B4:F4,1,5)) -> 866732.91 | H31: =IF(Scenarios!E7=1, IF(Scenarios!I7="lease", INDEX(Calc!B5:F5,1,5)*INDEX(Calc!B8:F8,1,5), INDEX(Calc!B5:F5,1,5)*INDEX(Calc!B9:F9,1,5)), INDEX(Calc!B5:F5,1,5)) -> 199652.09 | I31: =INDEX(Calc!B3:F3,1,5) -> 7869.1704 | J31: =IF("FY2030"="FY2026", (IF(Scenarios!D7=1, Parameters!B9,0) + IF(Scenarios!E7=1, Parameters!B9,0)), 0) -> 0 | K31: =1-Parameters!B4 -> 0.7 | L31: =Scenarios!G7 -> 0 | N31: =IF(F31>0, L31/F31, NA()) -> #N/A
A32: =Scenarios!A8 -> D_Grow_Both_0 | B32: FY2026 | C32: =Scenarios!C8 -> 0 | F32: =D32+E32 -> 0 | G32: =IF(Scenarios!D8=1, IF(Scenarios!I8="lease", INDEX(Calc!B4:F4,1,1)*INDEX(Calc!B8:F8,1,1), INDEX(Calc!B4:F4,1,1)*INDEX(Calc!B9:F9,1,1)), INDEX(Calc!B4:F4,1,1)) -> 785217.24 | H32: =IF(Scenarios!E8=1, IF(Scenarios!I8="lease", INDEX(Calc!B5:F5,1,1)*INDEX(Calc!B8:F8,1,1), INDEX(Calc!B5:F5,1,1)*INDEX(Calc!B9:F9,1,1)), INDEX(Calc!B5:F5,1,1)) -> 904374.72 | I32: =INDEX(Calc!B3:F3,1,1) -> 7129.08 | J32: =IF("FY2026"="FY2026", (IF(Scenarios!D8=1, Parameters!B9,0) + IF(Scenarios!E8=1, Parameters!B9,0)), 0) -> 0 | K32: =1-Parameters!B4 -> 0.7 | L32: =Scenarios!G8 -> 0 | N32: =IF(F32>0, L32/F32, NA()) -> #N/A
A33: =Scenarios!A8 -> D_Grow_Both_0 | B33: FY2027 | C33: =Scenarios!C8 -> 0 | F33: =D33+E33 -> 0 | G33: =IF(Scenarios!D8=1, IF(Scenarios!I8="lease", INDEX(Calc!B4:F4,1,2)*INDEX(Calc!B8:F8,1,2), INDEX(Calc!B4:F4,1,2)*INDEX(Calc!B9:F9,1,2)), INDEX(Calc!B4:F4,1,2)) -> 804847.67 | H33: =IF(Scenarios!E8=1, IF(Scenarios!I8="lease", INDEX(Calc!B5:F5,1,2)*INDEX(Calc!B8:F8,1,2), INDEX(Calc!B5:F5,1,2)*INDEX(Calc!B9:F9,1,2)), INDEX(Calc!B5:F5,1,2)) -> 926984.09 | I33: =INDEX(Calc!B3:F3,1,2) -> 7307.307 | J33: =IF("FY2027"="FY2026", (IF(Scenarios!D8=1, Parameters!B9,0) + IF(Scenarios!E8=1, Parameters!B9,0)), 0) -> 0 | K33: =1-Parameters!B4 -> 0.7 | L33: =Scenarios!G8 -> 0 | N33: =IF(F33>0, L33/F33, NA()) -> #N/A
A34: =Scenarios!A8 -> D_Grow_Both_0 | B34: FY2028 | C34: =Scenarios!C8 -> 0 | F34: =D34+E34 -> 0 | G34: =IF(Scenarios!D8=1, IF(Scenarios!I8="lease", INDEX(Calc!B4:F4,1,3)*INDEX(Calc!B8:F8,1,3), INDEX(Calc!B4:F4,1,3)*INDEX(Calc!B9:F9,1,3)), INDEX(Calc!B4:F4,1,3)) -> 824968.86 | H34: =IF(Scenarios!E8=1, IF(Scenarios!I8="lease", INDEX(Calc!B5:F5,1,3)*INDEX(Calc!B8:F8,1,3), INDEX(Calc!B5:F5,1,3)*INDEX(Calc!B9:F9,1,3)), INDEX(Calc!B5:F5,1,3)) -> 950158.69 | I34: =INDEX(Calc!B3:F3,1,3) -> 7489.9897 | J34: =IF("FY2028"="FY2026", (IF(Scenarios!D8=1, Parameters!B9,0) + IF(Scenarios!E8=1, Parameters!B9,0)), 0) -> 0 | K34: =1-Parameters!B4 -> 0.7 | L34: =Scenarios!G8 -> 0 | N34: =IF(F34>0, L34/F34, NA()) -> #N/A
A35: =Scenarios!A8 -> D_Grow_Both_0 | B35: FY2029 | C35: =Scenarios!C8 -> 0 | F35: =D35+E35 -> 0 | G35: =IF(Scenarios!D8=1, IF(Scenarios!I8="lease", INDEX(Calc!B4:F4,1,4)*INDEX(Calc!B8:F8,1,4), INDEX(Calc!B4:F4,1,4)*INDEX(Calc!B9:F9,1,4)), INDEX(Calc!B4:F4,1,4)) -> 845593.08 | H35: =IF(Scenarios!E8=1, IF(Scenarios!I8="lease", INDEX(Calc!B5:F5,1,4)*INDEX(Calc!B8:F8,1,4), INDEX(Calc!B5:F5,1,4)*INDEX(Calc!B9:F9,1,4)), INDEX(Calc!B5:F5,1,4)) -> 973912.66 | I35: =INDEX(Calc!B3:F3,1,4) -> 7677.2394 | J35: =IF("FY2029"="FY2026", (IF(Scenarios!D8=1, Parameters!B9,0) + IF(Scenarios!E8=1, Parameters!B9,0)), 0) -> 0 | K35: =1-Parameters!B4 -> 0.7 | L35: =Scenarios!G8 -> 0 | N35: =IF(F35>0, L35/F35, NA()) -> #N/A
A36: =Scenarios!A8 -> D_Grow_Both_0 | B36: FY2030 | C36: =Scenarios!C8 -> 0 | F36: =D36+E36 -> 0 | G36: =IF(Scenarios!D8=1, IF(Scenarios!I8="lease", INDEX(Calc!B4:F4,1,5)*INDEX(Calc!B8:F8,1,5), INDEX(Calc!B4:F4,1,5)*INDEX(Calc!B9:F9,1,5)), INDEX(Calc!B4:F4,1,5)) -> 866732.91 | H36: =IF(Scenarios!E8=1, IF(Scenarios!I8="lease", INDEX(Calc!B5:F5,1,5)*INDEX(Calc!B8:F8,1,5), INDEX(Calc!B5:F5,1,5)*INDEX(Calc!B9:F9,1,5)), INDEX(Calc!B5:F5,1,5)) -> 998260.47 | I36: =INDEX(Calc!B3:F3,1,5) -> 7869.1704 | J36: =IF("FY2030"="FY2026", (IF(Scenarios!D8=1, Parameters!B9,0) + IF(Scenarios!E8=1, Parameters!B9,0)), 0) -> 0 | K36: =1-Parameters!B4 -> 0.7 | L36: =Scenarios!G8 -> 0 | N36: =IF(F36>0, L36/F36, NA()) -> #N/A
A37: =Scenarios!A9 -> D_Grow_Both_100 | B37: FY2026 | C37: =Scenarios!C9 -> 100 | F37: =D37+E37 -> 0 | G37: =IF(Scenarios!D9=1, IF(Scenarios!I9="lease", INDEX(Calc!B4:F4,1,1)*INDEX(Calc!B8:F8,1,1), INDEX(Calc!B4:F4,1,1)*INDEX(Calc!B9:F9,1,1)), INDEX(Calc!B4:F4,1,1)) -> 785217.24 | H37: =IF(Scenarios!E9=1, IF(Scenarios!I9="lease", INDEX(Calc!B5:F5,1,1)*INDEX(Calc!B8:F8,1,1), INDEX(Calc!B5:F5,1,1)*INDEX(Calc!B9:F9,1,1)), INDEX(Calc!B5:F5,1,1)) -> 904374.72 | I37: =INDEX(Calc!B3:F3,1,1) -> 7129.08 | J37: =IF("FY2026"="FY2026", (IF(Scenarios!D9=1, Parameters!B9,0) + IF(Scenarios!E9=1, Parameters!B9,0)), 0) -> 0 | K37: =1-Parameters!B4 -> 0.7 | L37: =Scenarios!G9 -> 0 | N37: =IF(F37>0, L37/F37, NA()) -> #N/A
A38: =Scenarios!A9 -> D_Grow_Both_100 | B38: FY2027 | C38: =Scenarios!C9 -> 100 | F38: =D38+E38 -> 0 | G38: =IF(Scenarios!D9=1, IF(Scenarios!I9="lease", INDEX(Calc!B4:F4,1,2)*INDEX(Calc!B8:F8,1,2), INDEX(Calc!B4:F4,1,2)*INDEX(Calc!B9:F9,1,2)), INDEX(Calc!B4:F4,1,2)) -> 804847.67 | H38: =IF(Scenarios!E9=1, IF(Scenarios!I9="lease", INDEX(Calc!B5:F5,1,2)*INDEX(Calc!B8:F8,1,2), INDEX(Calc!B5:F5,1,2)*INDEX(Calc!B9:F9,1,2)), INDEX(Calc!B5:F5,1,2)) -> 926984.09 | I38: =INDEX(Calc!B3:F3,1,2) -> 7307.307 | J38: =IF("FY2027"="FY2026", (IF(Scenarios!D9=1, Parameters!B9,0) + IF(Scenarios!E9=1, Parameters!B9,0)), 0) -> 0 | K38: =1-Parameters!B4 -> 0.7 | L38: =Scenarios!G9 -> 0 | N38: =IF(F38>0, L38/F38, NA()) -> #N/A
A39: =Scenarios!A9 -> D_Grow_Both_100 | B39: FY2028 | C39: =Scenarios!C9 -> 100 | F39: =D39+E39 -> 0 | G39: =IF(Scenarios!D9=1, IF(Scenarios!I9="lease", INDEX(Calc!B4:F4,1,3)*INDEX(Calc!B8:F8,1,3), INDEX(Calc!B4:F4,1,3)*INDEX(Calc!B9:F9,1,3)), INDEX(Calc!B4:F4,1,3)) -> 824968.86 | H39: =IF(Scenarios!E9=1, IF(Scenarios!I9="lease", INDEX(Calc!B5:F5,1,3)*INDEX(Calc!B8:F8,1,3), INDEX(Calc!B5:F5,1,3)*INDEX(Calc!B9:F9,1,3)), INDEX(Calc!B5:F5,1,3)) -> 950158.69 | I39: =INDEX(Calc!B3:F3,1,3) -> 7489.9897 | J39: =IF("FY2028"="FY2026", (IF(Scenarios!D9=1, Parameters!B9,0) + IF(Scenarios!E9=1, Parameters!B9,0)), 0) -> 0 | K39: =1-Parameters!B4 -> 0.7 | L39: =Scenarios!G9 -> 0 | N39: =IF(F39>0, L39/F39, NA()) -> #N/A
A40: =Scenarios!A9 -> D_Grow_Both_100 | B40: FY2029 | C40: =Scenarios!C9 -> 100 | F40: =D40+E40 -> 0 | G40: =IF(Scenarios!D9=1, IF(Scenarios!I9="lease", INDEX(Calc!B4:F4,1,4)*INDEX(Calc!B8:F8,1,4), INDEX(Calc!B4:F4,1,4)*INDEX(Calc!B9:F9,1,4)), INDEX(Calc!B4:F4,1,4)) -> 845593.08 | H40: =IF(Scenarios!E9=1, IF(Scenarios!I9="lease", INDEX(Calc!B5:F5,1,4)*INDEX(Calc!B8:F8,1,4), INDEX(Calc!B5:F5,1,4)*INDEX(Calc!B9:F9,1,4)), INDEX(Calc!B5:F5,1,4)) -> 973912.66 | I40: =INDEX(Calc!B3:F3,1,4) -> 7677.2394 | J40: =IF("FY2029"="FY2026", (IF(Scenarios!D9=1, Parameters!B9,0) + IF(Scenarios!E9=1, Parameters!B9,0)), 0) -> 0 | K40: =1-Parameters!B4 -> 0.7 | L40: =Scenarios!G9 -> 0 | N40: =IF(F40>0, L40/F40, NA()) -> #N/A
...

Sheet Summary_Costs
A1: ScenarioKey | B1: Overlay | C1: Key | D1: Comparable_$FY2028 | E1: Comparable_$FY2030 | F1: Comparable_3yrAvg_$ | G1: NPV5_MO_$
A2: A_Repurpose_Both_lease | B2: 0 | C2: A_Repurpose_Both_lease|0 | D2: =IFERROR( (SUMPRODUCT((MultiYear_ProForma!$A:$A="A_Repurpose_Both_lease")*(MultiYear_ProForma!$B:$B="FY2028")*(MultiYear_ProForma!$L:$L)) + (IFERROR(VLOOKUP("A_Repurpose_Both_lease",$H$4:$I$9,2,FALSE),0)*$I$19*(VLOOKUP("FY2028",$H$11:$J$15,3,TRUE)+VLOOKUP("FY2028",$H$11:$J$15,2,TRUE))) ) / ( SUMPRODUCT((MultiYear_ProForma!$A:$A="A_Repurpose_Both_lease")*(MultiYear_ProForma!$B:$B="FY2028")*(MultiYear_ProForma!$F:$F)) + IFERROR(VLOOKUP("A_Repurpose_Both_lease",$H$4:$I$9,2,FALSE),0)*$I$19 ), "") | E2: =IFERROR( (SUMPRODUCT((MultiYear_ProForma!$A:$A="A_Repurpose_Both_lease")*(MultiYear_ProForma!$B:$B="FY2030")*(MultiYear_ProForma!$L:$L)) + (IFERROR(VLOOKUP("A_Repurpose_Both_lease",$H$4:$I$9,2,FALSE),0)*$I$19*(VLOOKUP("FY2030",$H$11:$J$15,3,TRUE)+VLOOKUP("FY2030",$H$11:$J$15,2,TRUE))) ) / ( SUMPRODUCT((MultiYear_ProForma!$A:$A="A_Repurpose_Both_lease")*(MultiYear_ProForma!$B:$B="FY2030")*(MultiYear_ProForma!$F:$F)) + IFERROR(VLOOKUP("A_Repurpose_Both_lease",$H$4:$I$9,2,FALSE),0)*$I$19 ), "") | F2: =AVERAGE(IFERROR( (SUMPRODUCT((MultiYear_ProForma!$A:$A="A_Repurpose_Both_lease")*(MultiYear_ProForma!$B:$B="FY2026")*(MultiYear_ProForma!$L:$L)) + (IFERROR(VLOOKUP("A_Repurpose_Both_lease",$H$4:$I$9,2,FALSE),0)*$I$19*(VLOOKUP("FY2026",$H$11:$J$15,3,TRUE)+VLOOKUP("FY2026",$H$11:$J$15,2,TRUE))) ) / ( SUMPRODUCT((MultiYear_ProForma!$A:$A="A_Repurpose_Both_lease")*(MultiYear_ProForma!$B:$B="FY2026")*(MultiYear_ProForma!$F:$F)) + IFERROR(VLOOKUP("A_Repurpose_Both_lease",$H$4:$I$9,2,FALSE),0)*$I$19 ), ""),IFERROR( (SUMPRODUCT((MultiYear_ProForma!$A:$A="A_Repurpose_Both_lease")*(MultiYear_ProForma!$B:$B="FY2027")*(MultiYear_ProForma!$L:$L)) + (IFERROR(VLOOKUP("A_Repurpose_Both_lease",$H$4:$I$9,2,FALSE),0)*$I$19*(VLOOKUP("FY2027",$H$11:$J$15,3,TRUE)+VLOOKUP("FY2027",$H$11:$J$15,2,TRUE))) ) / ( SUMPRODUCT((MultiYear_ProForma!$A:$A="A_Repurpose_Both_lease")*(MultiYear_ProForma!$B:$B="FY2027")*(MultiYear_ProForma!$F:$F)) + IFERROR(VLOOKUP("A_Repurpose_Both_lease",$H$4:$I$9,2,FALSE),0)*$I$19 ), ""),IFERROR( (SUMPRODUCT((MultiYear_ProForma!$A:$A="A_Repurpose_Both_lease")*(MultiYear_ProForma!$B:$B="FY2028")*(MultiYear_ProForma!$L:$L)) + (IFERROR(VLOOKUP("A_Repurpose_Both_lease",$H$4:$I$9,2,FALSE),0)*$I$19*(VLOOKUP("FY2028",$H$11:$J$15,3,TRUE)+VLOOKUP("FY2028",$H$11:$J$15,2,TRUE))) ) / ( SUMPRODUCT((MultiYear_ProForma!$A:$A="A_Repurpose_Both_lease")*(MultiYear_ProForma!$B:$B="FY2028")*(MultiYear_ProForma!$F:$F)) + IFERROR(VLOOKUP("A_Repurpose_Both_lease",$H$4:$I$9,2,FALSE),0)*$I$19 ), "")) -> #VALUE!
A3: A_Repurpose_Both_ops | B3: 0 | C3: A_Repurpose_Both_ops|0 | D3: =IFERROR( (SUMPRODUCT((MultiYear_ProForma!$A:$A="A_Repurpose_Both_ops")*(MultiYear_ProForma!$B:$B="FY2028")*(MultiYear_ProForma!$L:$L)) + (IFERROR(VLOOKUP("A_Repurpose_Both_ops",$H$4:$I$9,2,FALSE),0)*$I$19*(VLOOKUP("FY2028",$H$11:$J$15,3,TRUE)+VLOOKUP("FY2028",$H$11:$J$15,2,TRUE))) ) / ( SUMPRODUCT((MultiYear_ProForma!$A:$A="A_Repurpose_Both_ops")*(MultiYear_ProForma!$B:$B="FY2028")*(MultiYear_ProForma!$F:$F)) + IFERROR(VLOOKUP("A_Repurpose_Both_ops",$H$4:$I$9,2,FALSE),0)*$I$19 ), "") | E3: =IFERROR( (SUMPRODUCT((MultiYear_ProForma!$A:$A="A_Repurpose_Both_ops")*(MultiYear_ProForma!$B:$B="FY2030")*(MultiYear_ProForma!$L:$L)) + (IFERROR(VLOOKUP("A_Repurpose_Both_ops",$H$4:$I$9,2,FALSE),0)*$I$19*(VLOOKUP("FY2030",$H$11:$J$15,3,TRUE)+VLOOKUP("FY2030",$H$11:$J$15,2,TRUE))) ) / ( SUMPRODUCT((MultiYear_ProForma!$A:$A="A_Repurpose_Both_ops")*(MultiYear_ProForma!$B:$B="FY2030")*(MultiYear_ProForma!$F:$F)) + IFERROR(VLOOKUP("A_Repurpose_Both_ops",$H$4:$I$9,2,FALSE),0)*$I$19 ), "") | F3: =AVERAGE(IFERROR( (SUMPRODUCT((MultiYear_ProForma!$A:$A="A_Repurpose_Both_ops")*(MultiYear_ProForma!$B:$B="FY2026")*(MultiYear_ProForma!$L:$L)) + (IFERROR(VLOOKUP("A_Repurpose_Both_ops",$H$4:$I$9,2,FALSE),0)*$I$19*(VLOOKUP("FY2026",$H$11:$J$15,3,TRUE)+VLOOKUP("FY2026",$H$11:$J$15,2,TRUE))) ) / ( SUMPRODUCT((MultiYear_ProForma!$A:$A="A_Repurpose_Both_ops")*(MultiYear_ProForma!$B:$B="FY2026")*(MultiYear_ProForma!$F:$F)) + IFERROR(VLOOKUP("A_Repurpose_Both_ops",$H$4:$I$9,2,FALSE),0)*$I$19 ), ""),IFERROR( (SUMPRODUCT((MultiYear_ProForma!$A:$A="A_Repurpose_Both_ops")*(MultiYear_ProForma!$B:$B="FY2027")*(MultiYear_ProForma!$L:$L)) + (IFERROR(VLOOKUP("A_Repurpose_Both_ops",$H$4:$I$9,2,FALSE),0)*$I$19*(VLOOKUP("FY2027",$H$11:$J$15,3,TRUE)+VLOOKUP("FY2027",$H$11:$J$15,2,TRUE))) ) / ( SUMPRODUCT((MultiYear_ProForma!$A:$A="A_Repurpose_Both_ops")*(MultiYear_ProForma!$B:$B="FY2027")*(MultiYear_ProForma!$F:$F)) + IFERROR(VLOOKUP("A_Repurpose_Both_ops",$H$4:$I$9,2,FALSE),0)*$I$19 ), ""),IFERROR( (SUMPRODUCT((MultiYear_ProForma!$A:$A="A_Repurpose_Both_ops")*(MultiYear_ProForma!$B:$B="FY2028")*(MultiYear_ProForma!$L:$L)) + (IFERROR(VLOOKUP("A_Repurpose_Both_ops",$H$4:$I$9,2,FALSE),0)*$I$19*(VLOOKUP("FY2028",$H$11:$J$15,3,TRUE)+VLOOKUP("FY2028",$H$11:$J$15,2,TRUE))) ) / ( SUMPRODUCT((MultiYear_ProForma!$A:$A="A_Repurpose_Both_ops")*(MultiYear_ProForma!$B:$B="FY2028")*(MultiYear_ProForma!$F:$F)) + IFERROR(VLOOKUP("A_Repurpose_Both_ops",$H$4:$I$9,2,FALSE),0)*$I$19 ), "")) -> #VALUE! | I3: Helper: displaced by scenario (Echo+Pima)
A4: B_Repurpose_Echo_Grow_Pima_lease | B4: 0 | C4: B_Repurpose_Echo_Grow_Pima_lease|0 | D4: =IFERROR( (SUMPRODUCT((MultiYear_ProForma!$A:$A="B_Repurpose_Echo_Grow_Pima_lease")*(MultiYear_ProForma!$B:$B="FY2028")*(MultiYear_ProForma!$L:$L)) + (IFERROR(VLOOKUP("B_Repurpose_Echo_Grow_Pima_lease",$H$4:$I$9,2,FALSE),0)*$I$19*(VLOOKUP("FY2028",$H$11:$J$15,3,TRUE)+VLOOKUP("FY2028",$H$11:$J$15,2,TRUE))) ) / ( SUMPRODUCT((MultiYear_ProForma!$A:$A="B_Repurpose_Echo_Grow_Pima_lease")*(MultiYear_ProForma!$B:$B="FY2028")*(MultiYear_ProForma!$F:$F)) + IFERROR(VLOOKUP("B_Repurpose_Echo_Grow_Pima_lease",$H$4:$I$9,2,FALSE),0)*$I$19 ), "") | E4: =IFERROR( (SUMPRODUCT((MultiYear_ProForma!$A:$A="B_Repurpose_Echo_Grow_Pima_lease")*(MultiYear_ProForma!$B:$B="FY2030")*(MultiYear_ProForma!$L:$L)) + (IFERROR(VLOOKUP("B_Repurpose_Echo_Grow_Pima_lease",$H$4:$I$9,2,FALSE),0)*$I$19*(VLOOKUP("FY2030",$H$11:$J$15,3,TRUE)+VLOOKUP("FY2030",$H$11:$J$15,2,TRUE))) ) / ( SUMPRODUCT((MultiYear_ProForma!$A:$A="B_Repurpose_Echo_Grow_Pima_lease")*(MultiYear_ProForma!$B:$B="FY2030")*(MultiYear_ProForma!$F:$F)) + IFERROR(VLOOKUP("B_Repurpose_Echo_Grow_Pima_lease",$H$4:$I$9,2,FALSE),0)*$I$19 ), "") | F4: =AVERAGE(IFERROR( (SUMPRODUCT((MultiYear_ProForma!$A:$A="B_Repurpose_Echo_Grow_Pima_lease")*(MultiYear_ProForma!$B:$B="FY2026")*(MultiYear_ProForma!$L:$L)) + (IFERROR(VLOOKUP("B_Repurpose_Echo_Grow_Pima_lease",$H$4:$I$9,2,FALSE),0)*$I$19*(VLOOKUP("FY2026",$H$11:$J$15,3,TRUE)+VLOOKUP("FY2026",$H$11:$J$15,2,TRUE))) ) / ( SUMPRODUCT((MultiYear_ProForma!$A:$A="B_Repurpose_Echo_Grow_Pima_lease")*(MultiYear_ProForma!$B:$B="FY2026")*(MultiYear_ProForma!$F:$F)) + IFERROR(VLOOKUP("B_Repurpose_Echo_Grow_Pima_lease",$H$4:$I$9,2,FALSE),0)*$I$19 ), ""),IFERROR( (SUMPRODUCT((MultiYear_ProForma!$A:$A="B_Repurpose_Echo_Grow_Pima_lease")*(MultiYear_ProForma!$B:$B="FY2027")*(MultiYear_ProForma!$L:$L)) + (IFERROR(VLOOKUP("B_Repurpose_Echo_Grow_Pima_lease",$H$4:$I$9,2,FALSE),0)*$I$19*(VLOOKUP("FY2027",$H$11:$J$15,3,TRUE)+VLOOKUP("FY2027",$H$11:$J$15,2,TRUE))) ) / ( SUMPRODUCT((MultiYear_ProForma!$A:$A="B_Repurpose_Echo_Grow_Pima_lease")*(MultiYear_ProForma!$B:$B="FY2027")*(MultiYear_ProForma!$F:$F)) + IFERROR(VLOOKUP("B_Repurpose_Echo_Grow_Pima_lease",$H$4:$I$9,2,FALSE),0)*$I$19 ), ""),IFERROR( (SUMPRODUCT((MultiYear_ProForma!$A:$A="B_Repurpose_Echo_Grow_Pima_lease")*(MultiYear_ProForma!$B:$B="FY2028")*(MultiYear_ProForma!$L:$L)) + (IFERROR(VLOOKUP("B_Repurpose_Echo_Grow_Pima_lease",$H$4:$I$9,2,FALSE),0)*$I$19*(VLOOKUP("FY2028",$H$11:$J$15,3,TRUE)+VLOOKUP("FY2028",$H$11:$J$15,2,TRUE))) ) / ( SUMPRODUCT((MultiYear_ProForma!$A:$A="B_Repurpose_Echo_Grow_Pima_lease")*(MultiYear_ProForma!$B:$B="FY2028")*(MultiYear_ProForma!$F:$F)) + IFERROR(VLOOKUP("B_Repurpose_Echo_Grow_Pima_lease",$H$4:$I$9,2,FALSE),0)*$I$19 ), "")) -> #VALUE! | I4: ScenarioKey | J4: Displaced_T
A5: B_Repurpose_Echo_Grow_Pima_ops | B5: 0 | C5: B_Repurpose_Echo_Grow_Pima_ops|0 | D5: =IFERROR( (SUMPRODUCT((MultiYear_ProForma!$A:$A="B_Repurpose_Echo_Grow_Pima_ops")*(MultiYear_ProForma!$B:$B="FY2028")*(MultiYear_ProForma!$L:$L)) + (IFERROR(VLOOKUP("B_Repurpose_Echo_Grow_Pima_ops",$H$4:$I$9,2,FALSE),0)*$I$19*(VLOOKUP("FY2028",$H$11:$J$15,3,TRUE)+VLOOKUP("FY2028",$H$11:$J$15,2,TRUE))) ) / ( SUMPRODUCT((MultiYear_ProForma!$A:$A="B_Repurpose_Echo_Grow_Pima_ops")*(MultiYear_ProForma!$B:$B="FY2028")*(MultiYear_ProForma!$F:$F)) + IFERROR(VLOOKUP("B_Repurpose_Echo_Grow_Pima_ops",$H$4:$I$9,2,FALSE),0)*$I$19 ), "") | E5: =IFERROR( (SUMPRODUCT((MultiYear_ProForma!$A:$A="B_Repurpose_Echo_Grow_Pima_ops")*(MultiYear_ProForma!$B:$B="FY2030")*(MultiYear_ProForma!$L:$L)) + (IFERROR(VLOOKUP("B_Repurpose_Echo_Grow_Pima_ops",$H$4:$I$9,2,FALSE),0)*$I$19*(VLOOKUP("FY2030",$H$11:$J$15,3,TRUE)+VLOOKUP("FY2030",$H$11:$J$15,2,TRUE))) ) / ( SUMPRODUCT((MultiYear_ProForma!$A:$A="B_Repurpose_Echo_Grow_Pima_ops")*(MultiYear_ProForma!$B:$B="FY2030")*(MultiYear_ProForma!$F:$F)) + IFERROR(VLOOKUP("B_Repurpose_Echo_Grow_Pima_ops",$H$4:$I$9,2,FALSE),0)*$I$19 ), "") | F5: =AVERAGE(IFERROR( (SUMPRODUCT((MultiYear_ProForma!$A:$A="B_Repurpose_Echo_Grow_Pima_ops")*(MultiYear_ProForma!$B:$B="FY2026")*(MultiYear_ProForma!$L:$L)) + (IFERROR(VLOOKUP("B_Repurpose_Echo_Grow_Pima_ops",$H$4:$I$9,2,FALSE),0)*$I$19*(VLOOKUP("FY2026",$H$11:$J$15,3,TRUE)+VLOOKUP("FY2026",$H$11:$J$15,2,TRUE))) ) / ( SUMPRODUCT((MultiYear_ProForma!$A:$A="B_Repurpose_Echo_Grow_Pima_ops")*(MultiYear_ProForma!$B:$B="FY2026")*(MultiYear_ProForma!$F:$F)) + IFERROR(VLOOKUP("B_Repurpose_Echo_Grow_Pima_ops",$H$4:$I$9,2,FALSE),0)*$I$19 ), ""),IFERROR( (SUMPRODUCT((MultiYear_ProForma!$A:$A="B_Repurpose_Echo_Grow_Pima_ops")*(MultiYear_ProForma!$B:$B="FY2027")*(MultiYear_ProForma!$L:$L)) + (IFERROR(VLOOKUP("B_Repurpose_Echo_Grow_Pima_ops",$H$4:$I$9,2,FALSE),0)*$I$19*(VLOOKUP("FY2027",$H$11:$J$15,3,TRUE)+VLOOKUP("FY2027",$H$11:$J$15,2,TRUE))) ) / ( SUMPRODUCT((MultiYear_ProForma!$A:$A="B_Repurpose_Echo_Grow_Pima_ops")*(MultiYear_ProForma!$B:$B="FY2027")*(MultiYear_ProForma!$F:$F)) + IFERROR(VLOOKUP("B_Repurpose_Echo_Grow_Pima_ops",$H$4:$I$9,2,FALSE),0)*$I$19 ), ""),IFERROR( (SUMPRODUCT((MultiYear_ProForma!$A:$A="B_Repurpose_Echo_Grow_Pima_ops")*(MultiYear_ProForma!$B:$B="FY2028")*(MultiYear_ProForma!$L:$L)) + (IFERROR(VLOOKUP("B_Repurpose_Echo_Grow_Pima_ops",$H$4:$I$9,2,FALSE),0)*$I$19*(VLOOKUP("FY2028",$H$11:$J$15,3,TRUE)+VLOOKUP("FY2028",$H$11:$J$15,2,TRUE))) ) / ( SUMPRODUCT((MultiYear_ProForma!$A:$A="B_Repurpose_Echo_Grow_Pima_ops")*(MultiYear_ProForma!$B:$B="FY2028")*(MultiYear_ProForma!$F:$F)) + IFERROR(VLOOKUP("B_Repurpose_Echo_Grow_Pima_ops",$H$4:$I$9,2,FALSE),0)*$I$19 ), "")) -> #VALUE! | I5: A_Repurpose_Both_lease | J5: 553
A6: C_Repurpose_Pima_Grow_Echo_lease | B6: 0 | C6: C_Repurpose_Pima_Grow_Echo_lease|0 | D6: =IFERROR( (SUMPRODUCT((MultiYear_ProForma!$A:$A="C_Repurpose_Pima_Grow_Echo_lease")*(MultiYear_ProForma!$B:$B="FY2028")*(MultiYear_ProForma!$L:$L)) + (IFERROR(VLOOKUP("C_Repurpose_Pima_Grow_Echo_lease",$H$4:$I$9,2,FALSE),0)*$I$19*(VLOOKUP("FY2028",$H$11:$J$15,3,TRUE)+VLOOKUP("FY2028",$H$11:$J$15,2,TRUE))) ) / ( SUMPRODUCT((MultiYear_ProForma!$A:$A="C_Repurpose_Pima_Grow_Echo_lease")*(MultiYear_ProForma!$B:$B="FY2028")*(MultiYear_ProForma!$F:$F)) + IFERROR(VLOOKUP("C_Repurpose_Pima_Grow_Echo_lease",$H$4:$I$9,2,FALSE),0)*$I$19 ), "") | E6: =IFERROR( (SUMPRODUCT((MultiYear_ProForma!$A:$A="C_Repurpose_Pima_Grow_Echo_lease")*(MultiYear_ProForma!$B:$B="FY2030")*(MultiYear_ProForma!$L:$L)) + (IFERROR(VLOOKUP("C_Repurpose_Pima_Grow_Echo_lease",$H$4:$I$9,2,FALSE),0)*$I$19*(VLOOKUP("FY2030",$H$11:$J$15,3,TRUE)+VLOOKUP("FY2030",$H$11:$J$15,2,TRUE))) ) / ( SUMPRODUCT((MultiYear_ProForma!$A:$A="C_Repurpose_Pima_Grow_Echo_lease")*(MultiYear_ProForma!$B:$B="FY2030")*(MultiYear_ProForma!$F:$F)) + IFERROR(VLOOKUP("C_Repurpose_Pima_Grow_Echo_lease",$H$4:$I$9,2,FALSE),0)*$I$19 ), "") | F6: =AVERAGE(IFERROR( (SUMPRODUCT((MultiYear_ProForma!$A:$A="C_Repurpose_Pima_Grow_Echo_lease")*(MultiYear_ProForma!$B:$B="FY2026")*(MultiYear_ProForma!$L:$L)) + (IFERROR(VLOOKUP("C_Repurpose_Pima_Grow_Echo_lease",$H$4:$I$9,2,FALSE),0)*$I$19*(VLOOKUP("FY2026",$H$11:$J$15,3,TRUE)+VLOOKUP("FY2026",$H$11:$J$15,2,TRUE))) ) / ( SUMPRODUCT((MultiYear_ProForma!$A:$A="C_Repurpose_Pima_Grow_Echo_lease")*(MultiYear_ProForma!$B:$B="FY2026")*(MultiYear_ProForma!$F:$F)) + IFERROR(VLOOKUP("C_Repurpose_Pima_Grow_Echo_lease",$H$4:$I$9,2,FALSE),0)*$I$19 ), ""),IFERROR( (SUMPRODUCT((MultiYear_ProForma!$A:$A="C_Repurpose_Pima_Grow_Echo_lease")*(MultiYear_ProForma!$B:$B="FY2027")*(MultiYear_ProForma!$L:$L)) + (IFERROR(VLOOKUP("C_Repurpose_Pima_Grow_Echo_lease",$H$4:$I$9,2,FALSE),0)*$I$19*(VLOOKUP("FY2027",$H$11:$J$15,3,TRUE)+VLOOKUP("FY2027",$H$11:$J$15,2,TRUE))) ) / ( SUMPRODUCT((MultiYear_ProForma!$A:$A="C_Repurpose_Pima_Grow_Echo_lease")*(MultiYear_ProForma!$B:$B="FY2027")*(MultiYear_ProForma!$F:$F)) + IFERROR(VLOOKUP("C_Repurpose_Pima_Grow_Echo_lease",$H$4:$I$9,2,FALSE),0)*$I$19 ), ""),IFERROR( (SUMPRODUCT((MultiYear_ProForma!$A:$A="C_Repurpose_Pima_Grow_Echo_lease")*(MultiYear_ProForma!$B:$B="FY2028")*(MultiYear_ProForma!$L:$L)) + (IFERROR(VLOOKUP("C_Repurpose_Pima_Grow_Echo_lease",$H$4:$I$9,2,FALSE),0)*$I$19*(VLOOKUP("FY2028",$H$11:$J$15,3,TRUE)+VLOOKUP("FY2028",$H$11:$J$15,2,TRUE))) ) / ( SUMPRODUCT((MultiYear_ProForma!$A:$A="C_Repurpose_Pima_Grow_Echo_lease")*(MultiYear_ProForma!$B:$B="FY2028")*(MultiYear_ProForma!$F:$F)) + IFERROR(VLOOKUP("C_Repurpose_Pima_Grow_Echo_lease",$H$4:$I$9,2,FALSE),0)*$I$19 ), "")) -> #VALUE! | I6: A_Repurpose_Both_ops | J6: 553
A7: C_Repurpose_Pima_Grow_Echo_ops | B7: 0 | C7: C_Repurpose_Pima_Grow_Echo_ops|0 | D7: =IFERROR( (SUMPRODUCT((MultiYear_ProForma!$A:$A="C_Repurpose_Pima_Grow_Echo_ops")*(MultiYear_ProForma!$B:$B="FY2028")*(MultiYear_ProForma!$L:$L)) + (IFERROR(VLOOKUP("C_Repurpose_Pima_Grow_Echo_ops",$H$4:$I$9,2,FALSE),0)*$I$19*(VLOOKUP("FY2028",$H$11:$J$15,3,TRUE)+VLOOKUP("FY2028",$H$11:$J$15,2,TRUE))) ) / ( SUMPRODUCT((MultiYear_ProForma!$A:$A="C_Repurpose_Pima_Grow_Echo_ops")*(MultiYear_ProForma!$B:$B="FY2028")*(MultiYear_ProForma!$F:$F)) + IFERROR(VLOOKUP("C_Repurpose_Pima_Grow_Echo_ops",$H$4:$I$9,2,FALSE),0)*$I$19 ), "") | E7: =IFERROR( (SUMPRODUCT((MultiYear_ProForma!$A:$A="C_Repurpose_Pima_Grow_Echo_ops")*(MultiYear_ProForma!$B:$B="FY2030")*(MultiYear_ProForma!$L:$L)) + (IFERROR(VLOOKUP("C_Repurpose_Pima_Grow_Echo_ops",$H$4:$I$9,2,FALSE),0)*$I$19*(VLOOKUP("FY2030",$H$11:$J$15,3,TRUE)+VLOOKUP("FY2030",$H$11:$J$15,2,TRUE))) ) / ( SUMPRODUCT((MultiYear_ProForma!$A:$A="C_Repurpose_Pima_Grow_Echo_ops")*(MultiYear_ProForma!$B:$B="FY2030")*(MultiYear_ProForma!$F:$F)) + IFERROR(VLOOKUP("C_Repurpose_Pima_Grow_Echo_ops",$H$4:$I$9,2,FALSE),0)*$I$19 ), "") | F7: =AVERAGE(IFERROR( (SUMPRODUCT((MultiYear_ProForma!$A:$A="C_Repurpose_Pima_Grow_Echo_ops")*(MultiYear_ProForma!$B:$B="FY2026")*(MultiYear_ProForma!$L:$L)) + (IFERROR(VLOOKUP("C_Repurpose_Pima_Grow_Echo_ops",$H$4:$I$9,2,FALSE),0)*$I$19*(VLOOKUP("FY2026",$H$11:$J$15,3,TRUE)+VLOOKUP("FY2026",$H$11:$J$15,2,TRUE))) ) / ( SUMPRODUCT((MultiYear_ProForma!$A:$A="C_Repurpose_Pima_Grow_Echo_ops")*(MultiYear_ProForma!$B:$B="FY2026")*(MultiYear_ProForma!$F:$F)) + IFERROR(VLOOKUP("C_Repurpose_Pima_Grow_Echo_ops",$H$4:$I$9,2,FALSE),0)*$I$19 ), ""),IFERROR( (SUMPRODUCT((MultiYear_ProForma!$A:$A="C_Repurpose_Pima_Grow_Echo_ops")*(MultiYear_ProForma!$B:$B="FY2027")*(MultiYear_ProForma!$L:$L)) + (IFERROR(VLOOKUP("C_Repurpose_Pima_Grow_Echo_ops",$H$4:$I$9,2,FALSE),0)*$I$19*(VLOOKUP("FY2027",$H$11:$J$15,3,TRUE)+VLOOKUP("FY2027",$H$11:$J$15,2,TRUE))) ) / ( SUMPRODUCT((MultiYear_ProForma!$A:$A="C_Repurpose_Pima_Grow_Echo_ops")*(MultiYear_ProForma!$B:$B="FY2027")*(MultiYear_ProForma!$F:$F)) + IFERROR(VLOOKUP("C_Repurpose_Pima_Grow_Echo_ops",$H$4:$I$9,2,FALSE),0)*$I$19 ), ""),IFERROR( (SUMPRODUCT((MultiYear_ProForma!$A:$A="C_Repurpose_Pima_Grow_Echo_ops")*(MultiYear_ProForma!$B:$B="FY2028")*(MultiYear_ProForma!$L:$L)) + (IFERROR(VLOOKUP("C_Repurpose_Pima_Grow_Echo_ops",$H$4:$I$9,2,FALSE),0)*$I$19*(VLOOKUP("FY2028",$H$11:$J$15,3,TRUE)+VLOOKUP("FY2028",$H$11:$J$15,2,TRUE))) ) / ( SUMPRODUCT((MultiYear_ProForma!$A:$A="C_Repurpose_Pima_Grow_Echo_ops")*(MultiYear_ProForma!$B:$B="FY2028")*(MultiYear_ProForma!$F:$F)) + IFERROR(VLOOKUP("C_Repurpose_Pima_Grow_Echo_ops",$H$4:$I$9,2,FALSE),0)*$I$19 ), "")) -> #VALUE! | I7: B_Repurpose_Echo_Grow_Pima_lease | J7: 257
A8: D_Grow_Both_0 | B8: 0 | C8: D_Grow_Both_0|0 | D8: =IFERROR( (SUMPRODUCT((MultiYear_ProForma!$A:$A="D_Grow_Both_0")*(MultiYear_ProForma!$B:$B="FY2028")*(MultiYear_ProForma!$L:$L)) + (IFERROR(VLOOKUP("D_Grow_Both_0",$H$4:$I$9,2,FALSE),0)*$I$19*(VLOOKUP("FY2028",$H$11:$J$15,3,TRUE)+VLOOKUP("FY2028",$H$11:$J$15,2,TRUE))) ) / ( SUMPRODUCT((MultiYear_ProForma!$A:$A="D_Grow_Both_0")*(MultiYear_ProForma!$B:$B="FY2028")*(MultiYear_ProForma!$F:$F)) + IFERROR(VLOOKUP("D_Grow_Both_0",$H$4:$I$9,2,FALSE),0)*$I$19 ), "") | E8: =IFERROR( (SUMPRODUCT((MultiYear_ProForma!$A:$A="D_Grow_Both_0")*(MultiYear_ProForma!$B:$B="FY2030")*(MultiYear_ProForma!$L:$L)) + (IFERROR(VLOOKUP("D_Grow_Both_0",$H$4:$I$9,2,FALSE),0)*$I$19*(VLOOKUP("FY2030",$H$11:$J$15,3,TRUE)+VLOOKUP("FY2030",$H$11:$J$15,2,TRUE))) ) / ( SUMPRODUCT((MultiYear_ProForma!$A:$A="D_Grow_Both_0")*(MultiYear_ProForma!$B:$B="FY2030")*(MultiYear_ProForma!$F:$F)) + IFERROR(VLOOKUP("D_Grow_Both_0",$H$4:$I$9,2,FALSE),0)*$I$19 ), "") | F8: =AVERAGE(IFERROR( (SUMPRODUCT((MultiYear_ProForma!$A:$A="D_Grow_Both_0")*(MultiYear_ProForma!$B:$B="FY2026")*(MultiYear_ProForma!$L:$L)) + (IFERROR(VLOOKUP("D_Grow_Both_0",$H$4:$I$9,2,FALSE),0)*$I$19*(VLOOKUP("FY2026",$H$11:$J$15,3,TRUE)+VLOOKUP("FY2026",$H$11:$J$15,2,TRUE))) ) / ( SUMPRODUCT((MultiYear_ProForma!$A:$A="D_Grow_Both_0")*(MultiYear_ProForma!$B:$B="FY2026")*(MultiYear_ProForma!$F:$F)) + IFERROR(VLOOKUP("D_Grow_Both_0",$H$4:$I$9,2,FALSE),0)*$I$19 ), ""),IFERROR( (SUMPRODUCT((MultiYear_ProForma!$A:$A="D_Grow_Both_0")*(MultiYear_ProForma!$B:$B="FY2027")*(MultiYear_ProForma!$L:$L)) + (IFERROR(VLOOKUP("D_Grow_Both_0",$H$4:$I$9,2,FALSE),0)*$I$19*(VLOOKUP("FY2027",$H$11:$J$15,3,TRUE)+VLOOKUP("FY2027",$H$11:$J$15,2,TRUE))) ) / ( SUMPRODUCT((MultiYear_ProForma!$A:$A="D_Grow_Both_0")*(MultiYear_ProForma!$B:$B="FY2027")*(MultiYear_ProForma!$F:$F)) + IFERROR(VLOOKUP("D_Grow_Both_0",$H$4:$I$9,2,FALSE),0)*$I$19 ), ""),IFERROR( (SUMPRODUCT((MultiYear_ProForma!$A:$A="D_Grow_Both_0")*(MultiYear_ProForma!$B:$B="FY2028")*(MultiYear_ProForma!$L:$L)) + (IFERROR(VLOOKUP("D_Grow_Both_0",$H$4:$I$9,2,FALSE),0)*$I$19*(VLOOKUP("FY2028",$H$11:$J$15,3,TRUE)+VLOOKUP("FY2028",$H$11:$J$15,2,TRUE))) ) / ( SUMPRODUCT((MultiYear_ProForma!$A:$A="D_Grow_Both_0")*(MultiYear_ProForma!$B:$B="FY2028")*(MultiYear_ProForma!$F:$F)) + IFERROR(VLOOKUP("D_Grow_Both_0",$H$4:$I$9,2,FALSE),0)*$I$19 ), "")) -> #VALUE! | I8: B_Repurpose_Echo_Grow_Pima_ops | J8: 257
A9: D_Grow_Both_100 | B9: 100 | C9: D_Grow_Both_100|100 | D9: =IFERROR( (SUMPRODUCT((MultiYear_ProForma!$A:$A="D_Grow_Both_100")*(MultiYear_ProForma!$B:$B="FY2028")*(MultiYear_ProForma!$L:$L)) + (IFERROR(VLOOKUP("D_Grow_Both_100",$H$4:$I$9,2,FALSE),0)*$I$19*(VLOOKUP("FY2028",$H$11:$J$15,3,TRUE)+VLOOKUP("FY2028",$H$11:$J$15,2,TRUE))) ) / ( SUMPRODUCT((MultiYear_ProForma!$A:$A="D_Grow_Both_100")*(MultiYear_ProForma!$B:$B="FY2028")*(MultiYear_ProForma!$F:$F)) + IFERROR(VLOOKUP("D_Grow_Both_100",$H$4:$I$9,2,FALSE),0)*$I$19 ), "") | E9: =IFERROR( (SUMPRODUCT((MultiYear_ProForma!$A:$A="D_Grow_Both_100")*(MultiYear_ProForma!$B:$B="FY2030")*(MultiYear_ProForma!$L:$L)) + (IFERROR(VLOOKUP("D_Grow_Both_100",$H$4:$I$9,2,FALSE),0)*$I$19*(VLOOKUP("FY2030",$H$11:$J$15,3,TRUE)+VLOOKUP("FY2030",$H$11:$J$15,2,TRUE))) ) / ( SUMPRODUCT((MultiYear_ProForma!$A:$A="D_Grow_Both_100")*(MultiYear_ProForma!$B:$B="FY2030")*(MultiYear_ProForma!$F:$F)) + IFERROR(VLOOKUP("D_Grow_Both_100",$H$4:$I$9,2,FALSE),0)*$I$19 ), "") | F9: =AVERAGE(IFERROR( (SUMPRODUCT((MultiYear_ProForma!$A:$A="D_Grow_Both_100")*(MultiYear_ProForma!$B:$B="FY2026")*(MultiYear_ProForma!$L:$L)) + (IFERROR(VLOOKUP("D_Grow_Both_100",$H$4:$I$9,2,FALSE),0)*$I$19*(VLOOKUP("FY2026",$H$11:$J$15,3,TRUE)+VLOOKUP("FY2026",$H$11:$J$15,2,TRUE))) ) / ( SUMPRODUCT((MultiYear_ProForma!$A:$A="D_Grow_Both_100")*(MultiYear_ProForma!$B:$B="FY2026")*(MultiYear_ProForma!$F:$F)) + IFERROR(VLOOKUP("D_Grow_Both_100",$H$4:$I$9,2,FALSE),0)*$I$19 ), ""),IFERROR( (SUMPRODUCT((MultiYear_ProForma!$A:$A="D_Grow_Both_100")*(MultiYear_ProForma!$B:$B="FY2027")*(MultiYear_ProForma!$L:$L)) + (IFERROR(VLOOKUP("D_Grow_Both_100",$H$4:$I$9,2,FALSE),0)*$I$19*(VLOOKUP("FY2027",$H$11:$J$15,3,TRUE)+VLOOKUP("FY2027",$H$11:$J$15,2,TRUE))) ) / ( SUMPRODUCT((MultiYear_ProForma!$A:$A="D_Grow_Both_100")*(MultiYear_ProForma!$B:$B="FY2027")*(MultiYear_ProForma!$F:$F)) + IFERROR(VLOOKUP("D_Grow_Both_100",$H$4:$I$9,2,FALSE),0)*$I$19 ), ""),IFERROR( (SUMPRODUCT((MultiYear_ProForma!$A:$A="D_Grow_Both_100")*(MultiYear_ProForma!$B:$B="FY2028")*(MultiYear_ProForma!$L:$L)) + (IFERROR(VLOOKUP("D_Grow_Both_100",$H$4:$I$9,2,FALSE),0)*$I$19*(VLOOKUP("FY2028",$H$11:$J$15,3,TRUE)+VLOOKUP("FY2028",$H$11:$J$15,2,TRUE))) ) / ( SUMPRODUCT((MultiYear_ProForma!$A:$A="D_Grow_Both_100")*(MultiYear_ProForma!$B:$B="FY2028")*(MultiYear_ProForma!$F:$F)) + IFERROR(VLOOKUP("D_Grow_Both_100",$H$4:$I$9,2,FALSE),0)*$I$19 ), "")) -> #VALUE! | I9: C_Repurpose_Pima_Grow_Echo_lease | J9: 296
A10: D_Grow_Both_150 | B10: 150 | C10: D_Grow_Both_150|150 | D10: =IFERROR( (SUMPRODUCT((MultiYear_ProForma!$A:$A="D_Grow_Both_150")*(MultiYear_ProForma!$B:$B="FY2028")*(MultiYear_ProForma!$L:$L)) + (IFERROR(VLOOKUP("D_Grow_Both_150",$H$4:$I$9,2,FALSE),0)*$I$19*(VLOOKUP("FY2028",$H$11:$J$15,3,TRUE)+VLOOKUP("FY2028",$H$11:$J$15,2,TRUE))) ) / ( SUMPRODUCT((MultiYear_ProForma!$A:$A="D_Grow_Both_150")*(MultiYear_ProForma!$B:$B="FY2028")*(MultiYear_ProForma!$F:$F)) + IFERROR(VLOOKUP("D_Grow_Both_150",$H$4:$I$9,2,FALSE),0)*$I$19 ), "") | E10: =IFERROR( (SUMPRODUCT((MultiYear_ProForma!$A:$A="D_Grow_Both_150")*(MultiYear_ProForma!$B:$B="FY2030")*(MultiYear_ProForma!$L:$L)) + (IFERROR(VLOOKUP("D_Grow_Both_150",$H$4:$I$9,2,FALSE),0)*$I$19*(VLOOKUP("FY2030",$H$11:$J$15,3,TRUE)+VLOOKUP("FY2030",$H$11:$J$15,2,TRUE))) ) / ( SUMPRODUCT((MultiYear_ProForma!$A:$A="D_Grow_Both_150")*(MultiYear_ProForma!$B:$B="FY2030")*(MultiYear_ProForma!$F:$F)) + IFERROR(VLOOKUP("D_Grow_Both_150",$H$4:$I$9,2,FALSE),0)*$I$19 ), "") | F10: =AVERAGE(IFERROR( (SUMPRODUCT((MultiYear_ProForma!$A:$A="D_Grow_Both_150")*(MultiYear_ProForma!$B:$B="FY2026")*(MultiYear_ProForma!$L:$L)) + (IFERROR(VLOOKUP("D_Grow_Both_150",$H$4:$I$9,2,FALSE),0)*$I$19*(VLOOKUP("FY2026",$H$11:$J$15,3,TRUE)+VLOOKUP("FY2026",$H$11:$J$15,2,TRUE))) ) / ( SUMPRODUCT((MultiYear_ProForma!$A:$A="D_Grow_Both_150")*(MultiYear_ProForma!$B:$B="FY2026")*(MultiYear_ProForma!$F:$F)) + IFERROR(VLOOKUP("D_Grow_Both_150",$H$4:$I$9,2,FALSE),0)*$I$19 ), ""),IFERROR( (SUMPRODUCT((MultiYear_ProForma!$A:$A="D_Grow_Both_150")*(MultiYear_ProForma!$B:$B="FY2027")*(MultiYear_ProForma!$L:$L)) + (IFERROR(VLOOKUP("D_Grow_Both_150",$H$4:$I$9,2,FALSE),0)*$I$19*(VLOOKUP("FY2027",$H$11:$J$15,3,TRUE)+VLOOKUP("FY2027",$H$11:$J$15,2,TRUE))) ) / ( SUMPRODUCT((MultiYear_ProForma!$A:$A="D_Grow_Both_150")*(MultiYear_ProForma!$B:$B="FY2027")*(MultiYear_ProForma!$F:$F)) + IFERROR(VLOOKUP("D_Grow_Both_150",$H$4:$I$9,2,FALSE),0)*$I$19 ), ""),IFERROR( (SUMPRODUCT((MultiYear_ProForma!$A:$A="D_Grow_Both_150")*(MultiYear_ProForma!$B:$B="FY2028")*(MultiYear_ProForma!$L:$L)) + (IFERROR(VLOOKUP("D_Grow_Both_150",$H$4:$I$9,2,FALSE),0)*$I$19*(VLOOKUP("FY2028",$H$11:$J$15,3,TRUE)+VLOOKUP("FY2028",$H$11:$J$15,2,TRUE))) ) / ( SUMPRODUCT((MultiYear_ProForma!$A:$A="D_Grow_Both_150")*(MultiYear_ProForma!$B:$B="FY2028")*(MultiYear_ProForma!$F:$F)) + IFERROR(VLOOKUP("D_Grow_Both_150",$H$4:$I$9,2,FALSE),0)*$I$19 ), "")) -> #VALUE! | I10: C_Repurpose_Pima_Grow_Echo_ops | J10: 296
A11: E_StatusQuo_Targets_0 | B11: 0 | C11: E_StatusQuo_Targets_0|0 | D11: =IFERROR( (SUMPRODUCT((MultiYear_ProForma!$A:$A="E_StatusQuo_Targets_0")*(MultiYear_ProForma!$B:$B="FY2028")*(MultiYear_ProForma!$L:$L)) + (IFERROR(VLOOKUP("E_StatusQuo_Targets_0",$H$4:$I$9,2,FALSE),0)*$I$19*(VLOOKUP("FY2028",$H$11:$J$15,3,TRUE)+VLOOKUP("FY2028",$H$11:$J$15,2,TRUE))) ) / ( SUMPRODUCT((MultiYear_ProForma!$A:$A="E_StatusQuo_Targets_0")*(MultiYear_ProForma!$B:$B="FY2028")*(MultiYear_ProForma!$F:$F)) + IFERROR(VLOOKUP("E_StatusQuo_Targets_0",$H$4:$I$9,2,FALSE),0)*$I$19 ), "") | E11: =IFERROR( (SUMPRODUCT((MultiYear_ProForma!$A:$A="E_StatusQuo_Targets_0")*(MultiYear_ProForma!$B:$B="FY2030")*(MultiYear_ProForma!$L:$L)) + (IFERROR(VLOOKUP("E_StatusQuo_Targets_0",$H$4:$I$9,2,FALSE),0)*$I$19*(VLOOKUP("FY2030",$H$11:$J$15,3,TRUE)+VLOOKUP("FY2030",$H$11:$J$15,2,TRUE))) ) / ( SUMPRODUCT((MultiYear_ProForma!$A:$A="E_StatusQuo_Targets_0")*(MultiYear_ProForma!$B:$B="FY2030")*(MultiYear_ProForma!$F:$F)) + IFERROR(VLOOKUP("E_StatusQuo_Targets_0",$H$4:$I$9,2,FALSE),0)*$I$19 ), "") | F11: =AVERAGE(IFERROR( (SUMPRODUCT((MultiYear_ProForma!$A:$A="E_StatusQuo_Targets_0")*(MultiYear_ProForma!$B:$B="FY2026")*(MultiYear_ProForma!$L:$L)) + (IFERROR(VLOOKUP("E_StatusQuo_Targets_0",$H$4:$I$9,2,FALSE),0)*$I$19*(VLOOKUP("FY2026",$H$11:$J$15,3,TRUE)+VLOOKUP("FY2026",$H$11:$J$15,2,TRUE))) ) / ( SUMPRODUCT((MultiYear_ProForma!$A:$A="E_StatusQuo_Targets_0")*(MultiYear_ProForma!$B:$B="FY2026")*(MultiYear_ProForma!$F:$F)) + IFERROR(VLOOKUP("E_StatusQuo_Targets_0",$H$4:$I$9,2,FALSE),0)*$I$19 ), ""),IFERROR( (SUMPRODUCT((MultiYear_ProForma!$A:$A="E_StatusQuo_Targets_0")*(MultiYear_ProForma!$B:$B="FY2027")*(MultiYear_ProForma!$L:$L)) + (IFERROR(VLOOKUP("E_StatusQuo_Targets_0",$H$4:$I$9,2,FALSE),0)*$I$19*(VLOOKUP("FY2027",$H$11:$J$15,3,TRUE)+VLOOKUP("FY2027",$H$11:$J$15,2,TRUE))) ) / ( SUMPRODUCT((MultiYear_ProForma!$A:$A="E_StatusQuo_Targets_0")*(MultiYear_ProForma!$B:$B="FY2027")*(MultiYear_ProForma!$F:$F)) + IFERROR(VLOOKUP("E_StatusQuo_Targets_0",$H$4:$I$9,2,FALSE),0)*$I$19 ), ""),IFERROR( (SUMPRODUCT((MultiYear_ProForma!$A:$A="E_StatusQuo_Targets_0")*(MultiYear_ProForma!$B:$B="FY2028")*(MultiYear_ProForma!$L:$L)) + (IFERROR(VLOOKUP("E_StatusQuo_Targets_0",$H$4:$I$9,2,FALSE),0)*$I$19*(VLOOKUP("FY2028",$H$11:$J$15,3,TRUE)+VLOOKUP("FY2028",$H$11:$J$15,2,TRUE))) ) / ( SUMPRODUCT((MultiYear_ProForma!$A:$A="E_StatusQuo_Targets_0")*(MultiYear_ProForma!$B:$B="FY2028")*(MultiYear_ProForma!$F:$F)) + IFERROR(VLOOKUP("E_StatusQuo_Targets_0",$H$4:$I$9,2,FALSE),0)*$I$19 ), "")) -> #VALUE! | I11: FY | J11: h | K11: var_unit
