Workbook

Sheet Dashboard
A1: SUSD Keep-Open vs Repurpose — Interactive Dashboard (v4.4)
A3: Pick scenarios & assumptions | B3: Pick scenarios & assumptions (A vs X)
D4: Metric | E4: A (baseline) | F4: X (compare)
A5: Baseline A (auto): | B5: A_Repurpose_Both_ops | D5: FY2030 Net ($) | E5: =SUMIFS(MultiYear_ProForma!$AF:$AF, MultiYear_ProForma!$B:$B, $B$5, MultiYear_ProForma!$C:$C, "FY2030") -> -1689796.2 | F5: =SUMIFS(MultiYear_ProForma!$AF:$AF, MultiYear_ProForma!$B:$B, $B$6, MultiYear_ProForma!$C:$C, "FY2030") -> -2634025.6
A6: Compare to (X): | B6: G_DHub_EchoRamp | C6: D_Grow_Both_150 | D6: 5‑yr Avg Net ($) | E6: =(SUMIFS(MultiYear_ProForma!$AF:$AF, MultiYear_ProForma!$B:$B, $B$5, MultiYear_ProForma!$C:$C, "FY2026")+SUMIFS(MultiYear_ProForma!$AF:$AF, MultiYear_ProForma!$B:$B, $B$5, MultiYear_ProForma!$C:$C, "FY2027")+SUMIFS(MultiYear_ProForma!$AF:$AF, MultiYear_ProForma!$B:$B, $B$5, MultiYear_ProForma!$C:$C, "FY2028")+SUMIFS(MultiYear_ProForma!$AF:$AF, MultiYear_ProForma!$B:$B, $B$5, MultiYear_ProForma!$C:$C, "FY2029")+SUMIFS(MultiYear_ProForma!$AF:$AF, MultiYear_ProForma!$B:$B, $B$5, MultiYear_ProForma!$C:$C, "FY2030"))/5 -> -2303212.5 | F6: =(SUMIFS(MultiYear_ProForma!$AF:$AF, MultiYear_ProForma!$B:$B, $B$6, MultiYear_ProForma!$C:$C, "FY2026")+SUMIFS(MultiYear_ProForma!$AF:$AF, MultiYear_ProForma!$B:$B, $B$6, MultiYear_ProForma!$C:$C, "FY2027")+SUMIFS(MultiYear_ProForma!$AF:$AF, MultiYear_ProForma!$B:$B, $B$6, MultiYear_ProForma!$C:$C, "FY2028")+SUMIFS(MultiYear_ProForma!$AF:$AF, MultiYear_ProForma!$B:$B, $B$6, MultiYear_ProForma!$C:$C, "FY2029")+SUMIFS(MultiYear_ProForma!$AF:$AF, MultiYear_ProForma!$B:$B, $B$6, MultiYear_ProForma!$C:$C, "FY2030"))/5 -> -2563197.7
A7: Compare to (Y) [optional]: | D7: # students displaced | E7: =INDEX(Summary_Costs!$F$2:$F$13, MATCH($B$5, Summary_Costs!$A$2:$A$13, 0)) -> 553 | F7: =INDEX(Summary_Costs!$F$2:$F$13, MATCH($B$6, Summary_Costs!$A$2:$A$13, 0)) -> 0
D8: FY2030 # served (open & retained) | E8: =INDEX(Summary_Costs!$G$2:$G$13, MATCH($B$5, Summary_Costs!$A$2:$A$13, 0)) -> 414.75 | F8: =INDEX(Summary_Costs!$G$2:$G$13, MATCH($B$6, Summary_Costs!$A$2:$A$13, 0)) -> 703
D10: Δ vs A by FY2030 ($) | F10: =F5-E5 -> -944229.43
D11: Δ vs A (5‑yr Avg) ($) | F11: =F6-E6 -> -259985.28
A15: Year | B15: Year | C15: A Net ($) | D15: X Net ($)
A16: FY2026 | B16: FY2026 | C16: =SUMIFS(MultiYear_ProForma!$AF:$AF, MultiYear_ProForma!$B:$B, $B$5, MultiYear_ProForma!$C:$C, "FY2026") -> -4489801.6 | D16: =SUMIFS(MultiYear_ProForma!$AF:$AF, MultiYear_ProForma!$B:$B, $B$6, MultiYear_ProForma!$C:$C, "FY2026") -> -2615598
A17: FY2027 | B17: FY2027 | C17: =SUMIFS(MultiYear_ProForma!$AF:$AF, MultiYear_ProForma!$B:$B, $B$5, MultiYear_ProForma!$C:$C, "FY2027") -> -1887360.1 | D17: =SUMIFS(MultiYear_ProForma!$AF:$AF, MultiYear_ProForma!$B:$B, $B$6, MultiYear_ProForma!$C:$C, "FY2027") -> -2544483
A18: FY2028 | B18: FY2028 | C18: =SUMIFS(MultiYear_ProForma!$AF:$AF, MultiYear_ProForma!$B:$B, $B$5, MultiYear_ProForma!$C:$C, "FY2028") -> -1765979.1 | D18: =SUMIFS(MultiYear_ProForma!$AF:$AF, MultiYear_ProForma!$B:$B, $B$6, MultiYear_ProForma!$C:$C, "FY2028") -> -2470708.1
A19: FY2029 | B19: FY2029 | C19: =SUMIFS(MultiYear_ProForma!$AF:$AF, MultiYear_ProForma!$B:$B, $B$5, MultiYear_ProForma!$C:$C, "FY2029") -> -1683125.3 | D19: =SUMIFS(MultiYear_ProForma!$AF:$AF, MultiYear_ProForma!$B:$B, $B$6, MultiYear_ProForma!$C:$C, "FY2029") -> -2551174
A20: FY2030 | B20: FY2030 | C20: =SUMIFS(MultiYear_ProForma!$AF:$AF, MultiYear_ProForma!$B:$B, $B$5, MultiYear_ProForma!$C:$C, "FY2030") -> -1689796.2 | D20: =SUMIFS(MultiYear_ProForma!$AF:$AF, MultiYear_ProForma!$B:$B, $B$6, MultiYear_ProForma!$C:$C, "FY2030") -> -2634025.6
A25: Notes
A26: • 'Net ($)' = Comparable M&O costs minus base state aid on students served (open & retained). This is a two‑site view (Echo+Pima), not the entire district budget. • Positive Δ vs A means the comparator is more expensive than 'A_Repurpose_Both_ops' under the Parameters tab assumptions.

Sheet Cards
A1: Mini-Cards: A (Repurpose-Both) vs X and Y
A3: Comparator X | B3: =Dashboard!$B$6 -> G_DHub_EchoRamp | D3: Comparator Y | E3: =Dashboard!$B$7 -> 0
A4: r* needed (year/mode/h) | B4: =Dashboard!$I$23 -> 0 | D4: r* needed (year/mode/h) | E4: =Dashboard!$I$24 -> 0
A5: Δ FY2030 $/student | B5: =Dashboard!$I$26 -> 0 | D5: Δ FY2030 $/student | E5: =Dashboard!$I$27 -> 0
A6: Δ 5-yr Avg $/student | B6: =Dashboard!$I$28 -> 0 | D6: Δ 5-yr Avg $/student | E6: =Dashboard!$I$29 -> 0
A7: # displaced (A) | B7: =INDEX(Summary_Costs!$F:$F, MATCH(Dashboard!$B$5, Summary_Costs!$A:$A,0)) -> 553 | D7: # displaced (A) | E7: =INDEX(Summary_Costs!$F:$F, MATCH(Dashboard!$B$5, Summary_Costs!$A:$A,0)) -> 553
A8: # displaced (X) | B8: =INDEX(Summary_Costs!$F:$F, MATCH(Dashboard!$B$6, Summary_Costs!$A:$A,0)) -> 0 | D8: # displaced (Y) | E8: =INDEX(Summary_Costs!$F:$F, MATCH(Dashboard!$B$7, Summary_Costs!$A:$A,0)) -> #N/A
A9: Distinctiveness / Reversibility | B9: =Dashboard!$E$26 & " / " & Dashboard!$F$26 -> / | D9: Distinctiveness / Reversibility | E9: =Dashboard!$E$33 & " / " & Dashboard!$F$33 -> /

Sheet BaselineCalc
A1: Parameter | B1: Value | C1: Notes
A2: MO inflation | B2: 0.025 | C2: Annual inflation factor.
A3: Base MO per ADM (FY25) | B3: 9936 | C3: Working base for FY25.
A4: Fixed share of MO | B4: 0.3 | C4: Share treated as semi‑fixed (plant/insurance).
A5: Ops savings (keep‑open) | B5: 0.007 | C5: Light discipline if sites remain open (not used here).
A6: Extra savings (Co‑location) | B6: 0.015 | C6: Incremental savings for co‑location (not used here).
A7: Echo base ADM | B7: 257
A8: Pima base ADM | B8: 296
A9: Total base ADM | B9: =B7+B8 -> 553 | C9: Echo base ADM + Pima base ADM
A12: Helper / Derivation | B12: FY26 | C12: FY27 | D12: FY28 | E12: FY29 | F12: FY30 | G12: Notes
A13: Base total MO (FY25) | B13: =B9*B3 -> 5494608 | C13: =C14/$B$4 -> 5631973.2 | D13: =D14/$B$4 -> 5772772.5 | E13: =E14/$B$4 -> 5917091.8 | F13: =F14/$B$4 -> 6065019.1 | G13: Total ADM × Base MO/ADM | K13: B13 = B9*B3 (Base total MO, FY25)
A14: Fixed MO (FY25) | B14: =B13*B4 -> 1648382.4 | C14: =B17 -> 1689592 | D14: =C17 -> 1731831.8 | E14: =D17 -> 1775127.6 | F14: =E17 -> 1819505.7 | G14: Fixed = Base total × Fixed share | K14: B14 = B13*B4 (Fixed MO, FY25)
A15: Var per student (FY25) | B15: =(B13-B14)/B9 -> 6955.2 | C15: =B18 -> 7129.08 | D15: =C18 -> 7307.307 | E15: =D18 -> 7489.9897 | F15: =E18 -> 7677.2394 | G15: Variable = (Base total − Fixed)/Total ADM | K15: B15 = (B13–B14)/B9 (Variable $/student, FY25)
A17: Fixed total ($) | B17: =$B$14*(1+$B$2)^1 -> 1689592 | C17: =$B$14*(1+$B$2)^2 -> 1731831.8 | D17: =$B$14*(1+$B$2)^3 -> 1775127.6 | E17: =$B$14*(1+$B$2)^4 -> 1819505.7 | F17: =$B$14*(1+$B$2)^5 -> 1864993.4
A18: Var unit ($/student) | B18: =$B$15*(1+$B$2)^1 -> 7129.08 | C18: =$B$15*(1+$B$2)^2 -> 7307.307 | D18: =$B$15*(1+$B$2)^3 -> 7489.9897 | E18: =$B$15*(1+$B$2)^4 -> 7677.2394 | F18: =$B$15*(1+$B$2)^5 -> 7869.1704
A19: Echo fixed ($) | B19: =B17*($B$7/$B$9) -> 785217.24 | C19: =C17*($B$7/$B$9) -> 804847.67 | D19: =D17*($B$7/$B$9) -> 824968.86 | E19: =E17*($B$7/$B$9) -> 845593.08 | F19: =F17*($B$7/$B$9) -> 866732.91
A20: Pima fixed ($) | B20: =B17*($B$8/$B$9) -> 904374.72 | C20: =C17*($B$8/$B$9) -> 926984.09 | D20: =D17*($B$8/$B$9) -> 950158.69 | E20: =E17*($B$8/$B$9) -> 973912.66 | F20: =F17*($B$8/$B$9) -> 998260.47
A21: Repurpose TI per closed site (FY26) | B21: 1200000
A22: Retention r (central) | B22: 0.75
A24: Notes
A25: All formulas are same‑sheet and reference the Parameter cells above.
A26: Base State Aid per ADM (FY26) | B26: 5113 | C26: Editable; ADE base aid.
A27: Aid inflation (annual) | B27: 0.02 | C27: Editable; assumed growth in base aid.

Sheet YearMap
A1: Year | B1: VarUnit$ | C1: EchoFixed$ | D1: PimaFixed$ | E1: h | F1: f_lease | G1: f_ops | H1: YearIdx | I1: Aid$ | L1: Orig h | M1: Orig f_lease | N1: Orig f_ops
A2: FY2026 | B2: =BaselineCalc!B18 -> 7129.08 | C2: =BaselineCalc!B19 -> 785217.24 | D2: =BaselineCalc!B20 -> 904374.72 | E2: 1000 | F2: 0.4 | G2: 0.5 | H2: 1 | I2: =BaselineCalc!$B$26*(1+BaselineCalc!$B$27)^(H2-1) -> 5113 | L2: 1000 | M2: 0.4 | N2: 0.4
A3: FY2027 | B3: =BaselineCalc!C18 -> 7307.307 | C3: =BaselineCalc!C19 -> 804847.67 | D3: =BaselineCalc!C20 -> 926984.09 | E3: 800 | F3: 0.3 | G3: 0.4 | H3: 2 | I3: =BaselineCalc!$B$26*(1+BaselineCalc!$B$27)^(H3-1) -> 5215.26 | L3: 800 | M3: 0.3 | N3: 0.35
A4: FY2028 | B4: =BaselineCalc!D18 -> 7489.9897 | C4: =BaselineCalc!D19 -> 824968.86 | D4: =BaselineCalc!D20 -> 950158.69 | E4: 600 | F4: 0.2 | G4: 0.35 | H4: 3 | I4: =BaselineCalc!$B$26*(1+BaselineCalc!$B$27)^(H4-1) -> 5319.5652 | L4: 600 | M4: 0.2 | N4: 0.3
A5: FY2029 | B5: =BaselineCalc!E18 -> 7677.2394 | C5: =BaselineCalc!E19 -> 845593.08 | D5: =BaselineCalc!E20 -> 973912.66 | E5: 500 | F5: 0.1 | G5: 0.3 | H5: 4 | I5: =BaselineCalc!$B$26*(1+BaselineCalc!$B$27)^(H5-1) -> 5425.9565 | L5: 400 | M5: 0.1 | N5: 0.25
A6: FY2030 | B6: =BaselineCalc!F18 -> 7869.1704 | C6: =BaselineCalc!F19 -> 866732.91 | D6: =BaselineCalc!F20 -> 998260.47 | E6: 400 | F6: 0 | G6: 0.3 | H6: 5 | I6: =BaselineCalc!$B$26*(1+BaselineCalc!$B$27)^(H6-1) -> 5534.4756 | L6: 300 | M6: 0 | N6: 0.2

Sheet MultiYear_ProForma
A1: =AG1 -> Key | B1: ScenarioKey | C1: Year | D1: Echo_ADM | E1: Pima_ADM | F1: Total_ADM | G1: VarUnit$ | H1: EchoFixed$ | I1: PimaFixed$ | J1: OpsFactor | K1: ExtraSave | L1: EchoPotential_ADM | M1: PimaPotential_ADM | N1: Displaced_ADM | O1: Retained_ADM | P1: h | Q1: CarryFrac | R1: EchoFixedEff$ | S1: PimaFixedEff$ | T1: TI_adds$ | U1: SiteCost$ | V1: RetainedSvc$ | W1: Comparable_MO$ | X1: Comparable_per_Student$ | Y1: Aid_per_ADM | Z1: Net_MO_after_aid$ | AA1: Net_per_served$ | AB1: Overlay_ADM | AC1: Served_ADM | AD1: Revenue$ | AE1: Adj_MO$ | AF1: Net$ | AG1: Key
A2: =AG2 -> D_Grow_Both_0|FY2026 | B2: =Scenarios!A2 -> D_Grow_Both_0 | C2: FY2026 | D2: =IF(Scenarios!D2=1,0, L2) -> 257 | E2: =IF(Scenarios!E2=1,0, M2) -> 296 | F2: =D2+E2 -> 553 | G2: =YearMap!B2 -> 7129.08 | H2: =YearMap!C2 -> 785217.24 | I2: =YearMap!D2 -> 904374.72 | J2: =1-BaselineCalc!$B$5 -> 0.993 | K2: =Scenarios!G2 -> 0 | L2: =BaselineCalc!$B$7 + ROUND(Scenarios!I2*Scenarios!F2,0) -> 257 | M2: =BaselineCalc!$B$8 + Scenarios!I2 - ROUND(Scenarios!I2*Scenarios!F2,0) -> 296 | N2: =(L2-D2) + (M2-E2) -> 0 | O2: =BaselineCalc!$B$22 * N2 -> 0 | P2: =YearMap!E2 -> 1000 | Q2: =IF(Scenarios!N2="lease", YearMap!F2, YearMap!G2) -> 0.5 | R2: =IF(Scenarios!D2=1, Q2*H2, H2) -> 785217.24 | S2: =IF(Scenarios!E2=1, Q2*I2, I2) -> 904374.72 | T2: =IF(C2="FY2026", (Scenarios!D2+Scenarios!E2)*BaselineCalc!$B$21, 0) -> 0 | U2: =(R2+S2+G2*F2)*J2*(1-K2) -> 5592549.4 | V2: =O2*(G2+P2) -> 0 | W2: =U2+V2+T2 -> 5592549.4 | X2: =IF(F2+O2>0, W2/(F2+O2),"") -> 10113.109 | Y2: =INDEX(YearMap!$I$2:$I$6, MATCH(C2, YearMap!$A$2:$A$6, 0)) -> 5113 | Z2: =$W2-$Y2*$AC2 -> 2765060.4 | AA2: =IF($AC2>0, $Z2/$AC2, 0) -> 5000.1092 | AB2: =MAX(0, (MAX(0, $D2-BaselineCalc!$B$7) + MAX(0, $E2-BaselineCalc!$B$8))) -> 0 | AC2: =IF(LEFT($B2,2)="A_", $O2, IF(LEFT($B2,2)="B_", $M2+$O2, IF(LEFT($B2,2)="C_", $L2+$O2, $F2))) -> 553 | AD2: =$Y2*$AC2 -> 2827489 | AE2: =W2 - (1-Parameters!$B$2)*$G2*$AB2*$J2*(1-$K2) -> 5592549.4 | AF2: =AD2-AE2 -> -2765060.4 | AG2: =B2&"|"&C2 -> D_Grow_Both_0|FY2026
A3: =AG3 -> D_Grow_Both_0|FY2027 | B3: =Scenarios!A2 -> D_Grow_Both_0 | C3: FY2027 | D3: =IF(Scenarios!D2=1,0, L3) -> 257 | E3: =IF(Scenarios!E2=1,0, M3) -> 296 | F3: =D3+E3 -> 553 | G3: =YearMap!B3 -> 7307.307 | H3: =YearMap!C3 -> 804847.67 | I3: =YearMap!D3 -> 926984.09 | J3: =1-BaselineCalc!$B$5 -> 0.993 | K3: =Scenarios!G2 -> 0 | L3: =BaselineCalc!$B$7 + ROUND(Scenarios!J2*Scenarios!F2,0) -> 257 | M3: =BaselineCalc!$B$8 + Scenarios!J2 - ROUND(Scenarios!J2*Scenarios!F2,0) -> 296 | N3: =(L3-D3) + (M3-E3) -> 0 | O3: =BaselineCalc!$B$22 * N3 -> 0 | P3: =YearMap!E3 -> 800 | Q3: =IF(Scenarios!N2="lease", YearMap!F3, YearMap!G3) -> 0.4 | R3: =IF(Scenarios!D2=1, Q3*H3, H3) -> 804847.67 | S3: =IF(Scenarios!E2=1, Q3*I3, I3) -> 926984.09 | T3: =IF(C3="FY2026", (Scenarios!D2+Scenarios!E2)*BaselineCalc!$B$21, 0) -> 0 | U3: =(R3+S3+G3*F3)*J3*(1-K3) -> 5732363.1 | V3: =O3*(G3+P3) -> 0 | W3: =U3+V3+T3 -> 5732363.1 | X3: =IF(F3+O3>0, W3/(F3+O3),"") -> 10365.937 | Y3: =INDEX(YearMap!$I$2:$I$6, MATCH(C3, YearMap!$A$2:$A$6, 0)) -> 5215.26 | Z3: =$W3-$Y3*$AC3 -> 2848324.3 | AA3: =IF($AC3>0, $Z3/$AC3, 0) -> 5150.6769 | AB3: =MAX(0, (MAX(0, $D3-BaselineCalc!$B$7) + MAX(0, $E3-BaselineCalc!$B$8))) -> 0 | AC3: =IF(LEFT($B3,2)="A_", $O3, IF(LEFT($B3,2)="B_", $M3+$O3, IF(LEFT($B3,2)="C_", $L3+$O3, $F3))) -> 553 | AD3: =$Y3*$AC3 -> 2884038.8 | AE3: =W3 - (1-Parameters!$B$2)*$G3*$AB3*$J3*(1-$K3) -> 5732363.1 | AF3: =AD3-AE3 -> -2848324.3 | AG3: =B3&"|"&C3 -> D_Grow_Both_0|FY2027
A4: =AG4 -> D_Grow_Both_0|FY2028 | B4: =Scenarios!A2 -> D_Grow_Both_0 | C4: FY2028 | D4: =IF(Scenarios!D2=1,0, L4) -> 257 | E4: =IF(Scenarios!E2=1,0, M4) -> 296 | F4: =D4+E4 -> 553 | G4: =YearMap!B4 -> 7489.9897 | H4: =YearMap!C4 -> 824968.86 | I4: =YearMap!D4 -> 950158.69 | J4: =1-BaselineCalc!$B$5 -> 0.993 | K4: =Scenarios!G2 -> 0 | L4: =BaselineCalc!$B$7 + ROUND(Scenarios!K2*Scenarios!F2,0) -> 257 | M4: =BaselineCalc!$B$8 + Scenarios!K2 - ROUND(Scenarios!K2*Scenarios!F2,0) -> 296 | N4: =(L4-D4) + (M4-E4) -> 0 | O4: =BaselineCalc!$B$22 * N4 -> 0 | P4: =YearMap!E4 -> 600 | Q4: =IF(Scenarios!N2="lease", YearMap!F4, YearMap!G4) -> 0.35 | R4: =IF(Scenarios!D2=1, Q4*H4, H4) -> 824968.86 | S4: =IF(Scenarios!E2=1, Q4*I4, I4) -> 950158.69 | T4: =IF(C4="FY2026", (Scenarios!D2+Scenarios!E2)*BaselineCalc!$B$21, 0) -> 0 | U4: =(R4+S4+G4*F4)*J4*(1-K4) -> 5875672.2 | V4: =O4*(G4+P4) -> 0 | W4: =U4+V4+T4 -> 5875672.2 | X4: =IF(F4+O4>0, W4/(F4+O4),"") -> 10625.085 | Y4: =INDEX(YearMap!$I$2:$I$6, MATCH(C4, YearMap!$A$2:$A$6, 0)) -> 5319.5652 | Z4: =$W4-$Y4*$AC4 -> 2933952.6 | AA4: =IF($AC4>0, $Z4/$AC4, 0) -> 5305.5202 | AB4: =MAX(0, (MAX(0, $D4-BaselineCalc!$B$7) + MAX(0, $E4-BaselineCalc!$B$8))) -> 0 | AC4: =IF(LEFT($B4,2)="A_", $O4, IF(LEFT($B4,2)="B_", $M4+$O4, IF(LEFT($B4,2)="C_", $L4+$O4, $F4))) -> 553 | AD4: =$Y4*$AC4 -> 2941719.6 | AE4: =W4 - (1-Parameters!$B$2)*$G4*$AB4*$J4*(1-$K4) -> 5875672.2 | AF4: =AD4-AE4 -> -2933952.6 | AG4: =B4&"|"&C4 -> D_Grow_Both_0|FY2028
A5: =AG5 -> D_Grow_Both_0|FY2029 | B5: =Scenarios!A2 -> D_Grow_Both_0 | C5: FY2029 | D5: =IF(Scenarios!D2=1,0, L5) -> 257 | E5: =IF(Scenarios!E2=1,0, M5) -> 296 | F5: =D5+E5 -> 553 | G5: =YearMap!B5 -> 7677.2394 | H5: =YearMap!C5 -> 845593.08 | I5: =YearMap!D5 -> 973912.66 | J5: =1-BaselineCalc!$B$5 -> 0.993 | K5: =Scenarios!G2 -> 0 | L5: =BaselineCalc!$B$7 + ROUND(Scenarios!L2*Scenarios!F2,0) -> 257 | M5: =BaselineCalc!$B$8 + Scenarios!L2 - ROUND(Scenarios!L2*Scenarios!F2,0) -> 296 | N5: =(L5-D5) + (M5-E5) -> 0 | O5: =BaselineCalc!$B$22 * N5 -> 0 | P5: =YearMap!E5 -> 500 | Q5: =IF(Scenarios!N2="lease", YearMap!F5, YearMap!G5) -> 0.3 | R5: =IF(Scenarios!D2=1, Q5*H5, H5) -> 845593.08 | S5: =IF(Scenarios!E2=1, Q5*I5, I5) -> 973912.66 | T5: =IF(C5="FY2026", (Scenarios!D2+Scenarios!E2)*BaselineCalc!$B$21, 0) -> 0 | U5: =(R5+S5+G5*F5)*J5*(1-K5) -> 6022564 | V5: =O5*(G5+P5) -> 0 | W5: =U5+V5+T5 -> 6022564 | X5: =IF(F5+O5>0, W5/(F5+O5),"") -> 10890.712 | Y5: =INDEX(YearMap!$I$2:$I$6, MATCH(C5, YearMap!$A$2:$A$6, 0)) -> 5425.9565 | Z5: =$W5-$Y5*$AC5 -> 3022010.1 | AA5: =IF($AC5>0, $Z5/$AC5, 0) -> 5464.756 | AB5: =MAX(0, (MAX(0, $D5-BaselineCalc!$B$7) + MAX(0, $E5-BaselineCalc!$B$8))) -> 0 | AC5: =IF(LEFT($B5,2)="A_", $O5, IF(LEFT($B5,2)="B_", $M5+$O5, IF(LEFT($B5,2)="C_", $L5+$O5, $F5))) -> 553 | AD5: =$Y5*$AC5 -> 3000553.9 | AE5: =W5 - (1-Parameters!$B$2)*$G5*$AB5*$J5*(1-$K5) -> 6022564 | AF5: =AD5-AE5 -> -3022010.1 | AG5: =B5&"|"&C5 -> D_Grow_Both_0|FY2029
A6: =AG6 -> D_Grow_Both_0|FY2030 | B6: =Scenarios!A2 -> D_Grow_Both_0 | C6: FY2030 | D6: =IF(Scenarios!D2=1,0, L6) -> 257 | E6: =IF(Scenarios!E2=1,0, M6) -> 296 | F6: =D6+E6 -> 553 | G6: =YearMap!B6 -> 7869.1704 | H6: =YearMap!C6 -> 866732.91 | I6: =YearMap!D6 -> 998260.47 | J6: =1-BaselineCalc!$B$5 -> 0.993 | K6: =Scenarios!G2 -> 0 | L6: =BaselineCalc!$B$7 + ROUND(Scenarios!M2*Scenarios!F2,0) -> 257 | M6: =BaselineCalc!$B$8 + Scenarios!M2 - ROUND(Scenarios!M2*Scenarios!F2,0) -> 296 | N6: =(L6-D6) + (M6-E6) -> 0 | O6: =BaselineCalc!$B$22 * N6 -> 0 | P6: =YearMap!E6 -> 400 | Q6: =IF(Scenarios!N2="lease", YearMap!F6, YearMap!G6) -> 0.3 | R6: =IF(Scenarios!D2=1, Q6*H6, H6) -> 866732.91 | S6: =IF(Scenarios!E2=1, Q6*I6, I6) -> 998260.47 | T6: =IF(C6="FY2026", (Scenarios!D2+Scenarios!E2)*BaselineCalc!$B$21, 0) -> 0 | U6: =(R6+S6+G6*F6)*J6*(1-K6) -> 6173128.1 | V6: =O6*(G6+P6) -> 0 | W6: =U6+V6+T6 -> 6173128.1 | X6: =IF(F6+O6>0, W6/(F6+O6),"") -> 11162.98 | Y6: =INDEX(YearMap!$I$2:$I$6, MATCH(C6, YearMap!$A$2:$A$6, 0)) -> 5534.4756 | Z6: =$W6-$Y6*$AC6 -> 3112563.1 | AA6: =IF($AC6>0, $Z6/$AC6, 0) -> 5628.5047 | AB6: =MAX(0, (MAX(0, $D6-BaselineCalc!$B$7) + MAX(0, $E6-BaselineCalc!$B$8))) -> 0 | AC6: =IF(LEFT($B6,2)="A_", $O6, IF(LEFT($B6,2)="B_", $M6+$O6, IF(LEFT($B6,2)="C_", $L6+$O6, $F6))) -> 553 | AD6: =$Y6*$AC6 -> 3060565 | AE6: =W6 - (1-Parameters!$B$2)*$G6*$AB6*$J6*(1-$K6) -> 6173128.1 | AF6: =AD6-AE6 -> -3112563.1 | AG6: =B6&"|"&C6 -> D_Grow_Both_0|FY2030
A7: =AG7 -> E_StatusQuo_Targets_0|FY2026 | B7: =Scenarios!A3 -> E_StatusQuo_Targets_0 | C7: FY2026 | D7: =IF(Scenarios!D3=1,0, L7) -> 257 | E7: =IF(Scenarios!E3=1,0, M7) -> 296 | F7: =D7+E7 -> 553 | G7: =YearMap!B2 -> 7129.08 | H7: =YearMap!C2 -> 785217.24 | I7: =YearMap!D2 -> 904374.72 | J7: =1-BaselineCalc!$B$5 -> 0.993 | K7: =Scenarios!G3 -> 0 | L7: =BaselineCalc!$B$7 + ROUND(Scenarios!I3*Scenarios!F3,0) -> 257 | M7: =BaselineCalc!$B$8 + Scenarios!I3 - ROUND(Scenarios!J3*Scenarios!F3,0) -> 296 | N7: =(L7-D7) + (M7-E7) -> 0 | O7: =BaselineCalc!$B$22 * N7 -> 0 | P7: =YearMap!E2 -> 1000 | Q7: =IF(Scenarios!N3="lease", YearMap!F2, YearMap!G2) -> 0.5 | R7: =IF(Scenarios!D3=1, Q7*H7, H7) -> 785217.24 | S7: =IF(Scenarios!E3=1, Q7*I7, I7) -> 904374.72 | T7: =IF(C7="FY2026", (Scenarios!D3+Scenarios!E3)*BaselineCalc!$B$21, 0) -> 0 | U7: =(R7+S7+G7*F7)*J7*(1-K7) -> 5592549.4 | V7: =O7*(G7+P7) -> 0 | W7: =U7+V7+T7 -> 5592549.4 | X7: =IF(F7+O7>0, W7/(F7+O7),"") -> 10113.109 | Y7: =INDEX(YearMap!$I$2:$I$6, MATCH(C7, YearMap!$A$2:$A$6, 0)) -> 5113 | Z7: =$W7-$Y7*$AC7 -> 2765060.4 | AA7: =IF($AC7>0, $Z7/$AC7, 0) -> 5000.1092 | AB7: =MAX(0, (MAX(0, $D7-BaselineCalc!$B$7) + MAX(0, $E7-BaselineCalc!$B$8))) -> 0 | AC7: =IF(LEFT($B7,2)="A_", $O7, IF(LEFT($B7,2)="B_", $M7+$O7, IF(LEFT($B7,2)="C_", $L7+$O7, $F7))) -> 553 | AD7: =$Y7*$AC7 -> 2827489 | AE7: =W7 - (1-Parameters!$B$2)*$G7*$AB7*$J7*(1-$K7) -> 5592549.4 | AF7: =AD7-AE7 -> -2765060.4 | AG7: =B7&"|"&C7 -> E_StatusQuo_Targets_0|FY2026
A8: =AG8 -> E_StatusQuo_Targets_0|FY2027 | B8: =Scenarios!A3 -> E_StatusQuo_Targets_0 | C8: FY2027 | D8: =IF(Scenarios!D3=1,0, L8) -> 257 | E8: =IF(Scenarios!E3=1,0, M8) -> 296 | F8: =D8+E8 -> 553 | G8: =YearMap!B3 -> 7307.307 | H8: =YearMap!C3 -> 804847.67 | I8: =YearMap!D3 -> 926984.09 | J8: =1-BaselineCalc!$B$5 -> 0.993 | K8: =Scenarios!G3 -> 0 | L8: =BaselineCalc!$B$7 + ROUND(Scenarios!J3*Scenarios!F3,0) -> 257 | M8: =BaselineCalc!$B$8 + Scenarios!J3 - ROUND(Scenarios!J3*Scenarios!F3,0) -> 296 | N8: =(L8-D8) + (M8-E8) -> 0 | O8: =BaselineCalc!$B$22 * N8 -> 0 | P8: =YearMap!E3 -> 800 | Q8: =IF(Scenarios!N3="lease", YearMap!F3, YearMap!G3) -> 0.4 | R8: =IF(Scenarios!D3=1, Q8*H8, H8) -> 804847.67 | S8: =IF(Scenarios!E3=1, Q8*I8, I8) -> 926984.09 | T8: =IF(C8="FY2026", (Scenarios!D3+Scenarios!E3)*BaselineCalc!$B$21, 0) -> 0 | U8: =(R8+S8+G8*F8)*J8*(1-K8) -> 5732363.1 | V8: =O8*(G8+P8) -> 0 | W8: =U8+V8+T8 -> 5732363.1 | X8: =IF(F8+O8>0, W8/(F8+O8),"") -> 10365.937 | Y8: =INDEX(YearMap!$I$2:$I$6, MATCH(C8, YearMap!$A$2:$A$6, 0)) -> 5215.26 | Z8: =$W8-$Y8*$AC8 -> 2848324.3 | AA8: =IF($AC8>0, $Z8/$AC8, 0) -> 5150.6769 | AB8: =MAX(0, (MAX(0, $D8-BaselineCalc!$B$7) + MAX(0, $E8-BaselineCalc!$B$8))) -> 0 | AC8: =IF(LEFT($B8,2)="A_", $O8, IF(LEFT($B8,2)="B_", $M8+$O8, IF(LEFT($B8,2)="C_", $L8+$O8, $F8))) -> 553 | AD8: =$Y8*$AC8 -> 2884038.8 | AE8: =W8 - (1-Parameters!$B$2)*$G8*$AB8*$J8*(1-$K8) -> 5732363.1 | AF8: =AD8-AE8 -> -2848324.3 | AG8: =B8&"|"&C8 -> E_StatusQuo_Targets_0|FY2027
A9: =AG9 -> E_StatusQuo_Targets_0|FY2028 | B9: =Scenarios!A3 -> E_StatusQuo_Targets_0 | C9: FY2028 | D9: =IF(Scenarios!D3=1,0, L9) -> 257 | E9: =IF(Scenarios!E3=1,0, M9) -> 296 | F9: =D9+E9 -> 553 | G9: =YearMap!B4 -> 7489.9897 | H9: =YearMap!C4 -> 824968.86 | I9: =YearMap!D4 -> 950158.69 | J9: =1-BaselineCalc!$B$5 -> 0.993 | K9: =Scenarios!G3 -> 0 | L9: =BaselineCalc!$B$7 + ROUND(Scenarios!K3*Scenarios!F3,0) -> 257 | M9: =BaselineCalc!$B$8 + Scenarios!K3 - ROUND(Scenarios!K3*Scenarios!F3,0) -> 296 | N9: =(L9-D9) + (M9-E9) -> 0 | O9: =BaselineCalc!$B$22 * N9 -> 0 | P9: =YearMap!E4 -> 600 | Q9: =IF(Scenarios!N3="lease", YearMap!F4, YearMap!G4) -> 0.35 | R9: =IF(Scenarios!D3=1, Q9*H9, H9) -> 824968.86 | S9: =IF(Scenarios!E3=1, Q9*I9, I9) -> 950158.69 | T9: =IF(C9="FY2026", (Scenarios!D3+Scenarios!E3)*BaselineCalc!$B$21, 0) -> 0 | U9: =(R9+S9+G9*F9)*J9*(1-K9) -> 5875672.2 | V9: =O9*(G9+P9) -> 0 | W9: =U9+V9+T9 -> 5875672.2 | X9: =IF(F9+O9>0, W9/(F9+O9),"") -> 10625.085 | Y9: =INDEX(YearMap!$I$2:$I$6, MATCH(C9, YearMap!$A$2:$A$6, 0)) -> 5319.5652 | Z9: =$W9-$Y9*$AC9 -> 2933952.6 | AA9: =IF($AC9>0, $Z9/$AC9, 0) -> 5305.5202 | AB9: =MAX(0, (MAX(0, $D9-BaselineCalc!$B$7) + MAX(0, $E9-BaselineCalc!$B$8))) -> 0 | AC9: =IF(LEFT($B9,2)="A_", $O9, IF(LEFT($B9,2)="B_", $M9+$O9, IF(LEFT($B9,2)="C_", $L9+$O9, $F9))) -> 553 | AD9: =$Y9*$AC9 -> 2941719.6 | AE9: =W9 - (1-Parameters!$B$2)*$G9*$AB9*$J9*(1-$K9) -> 5875672.2 | AF9: =AD9-AE9 -> -2933952.6 | AG9: =B9&"|"&C9 -> E_StatusQuo_Targets_0|FY2028
A10: =AG10 -> E_StatusQuo_Targets_0|FY2029 | B10: =Scenarios!A3 -> E_StatusQuo_Targets_0 | C10: FY2029 | D10: =IF(Scenarios!D3=1,0, L10) -> 257 | E10: =IF(Scenarios!E3=1,0, M10) -> 296 | F10: =D10+E10 -> 553 | G10: =YearMap!B5 -> 7677.2394 | H10: =YearMap!C5 -> 845593.08 | I10: =YearMap!D5 -> 973912.66 | J10: =1-BaselineCalc!$B$5 -> 0.993 | K10: =Scenarios!G3 -> 0 | L10: =BaselineCalc!$B$7 + ROUND(Scenarios!L3*Scenarios!F3,0) -> 257 | M10: =BaselineCalc!$B$8 + Scenarios!L3 - ROUND(Scenarios!L3*Scenarios!F3,0) -> 296 | N10: =(L10-D10) + (M10-E10) -> 0 | O10: =BaselineCalc!$B$22 * N10 -> 0 | P10: =YearMap!E5 -> 500 | Q10: =IF(Scenarios!N3="lease", YearMap!F5, YearMap!G5) -> 0.3 | R10: =IF(Scenarios!D3=1, Q10*H10, H10) -> 845593.08 | S10: =IF(Scenarios!E3=1, Q10*I10, I10) -> 973912.66 | T10: =IF(C10="FY2026", (Scenarios!D3+Scenarios!E3)*BaselineCalc!$B$21, 0) -> 0 | U10: =(R10+S10+G10*F10)*J10*(1-K10) -> 6022564 | V10: =O10*(G10+P10) -> 0 | W10: =U10+V10+T10 -> 6022564 | X10: =IF(F10+O10>0, W10/(F10+O10),"") -> 10890.712 | Y10: =INDEX(YearMap!$I$2:$I$6, MATCH(C10, YearMap!$A$2:$A$6, 0)) -> 5425.9565 | Z10: =$W10-$Y10*$AC10 -> 3022010.1 | AA10: =IF($AC10>0, $Z10/$AC10, 0) -> 5464.756 | AB10: =MAX(0, (MAX(0, $D10-BaselineCalc!$B$7) + MAX(0, $E10-BaselineCalc!$B$8))) -> 0 | AC10: =IF(LEFT($B10,2)="A_", $O10, IF(LEFT($B10,2)="B_", $M10+$O10, IF(LEFT($B10,2)="C_", $L10+$O10, $F10))) -> 553 | AD10: =$Y10*$AC10 -> 3000553.9 | AE10: =W10 - (1-Parameters!$B$2)*$G10*$AB10*$J10*(1-$K10) -> 6022564 | AF10: =AD10-AE10 -> -3022010.1 | AG10: =B10&"|"&C10 -> E_StatusQuo_Targets_0|FY2029
A11: =AG11 -> E_StatusQuo_Targets_0|FY2030 | B11: =Scenarios!A3 -> E_StatusQuo_Targets_0 | C11: FY2030 | D11: =IF(Scenarios!D3=1,0, L11) -> 257 | E11: =IF(Scenarios!E3=1,0, M11) -> 296 | F11: =D11+E11 -> 553 | G11: =YearMap!B6 -> 7869.1704 | H11: =YearMap!C6 -> 866732.91 | I11: =YearMap!D6 -> 998260.47 | J11: =1-BaselineCalc!$B$5 -> 0.993 | K11: =Scenarios!G3 -> 0 | L11: =BaselineCalc!$B$7 + ROUND(Scenarios!M3*Scenarios!F3,0) -> 257 | M11: =BaselineCalc!$B$8 + Scenarios!M3 - ROUND(Scenarios!M3*Scenarios!F3,0) -> 296 | N11: =(L11-D11) + (M11-E11) -> 0 | O11: =BaselineCalc!$B$22 * N11 -> 0 | P11: =YearMap!E6 -> 400 | Q11: =IF(Scenarios!N3="lease", YearMap!F6, YearMap!G6) -> 0.3 | R11: =IF(Scenarios!D3=1, Q11*H11, H11) -> 866732.91 | S11: =IF(Scenarios!E3=1, Q11*I11, I11) -> 998260.47 | T11: =IF(C11="FY2026", (Scenarios!D3+Scenarios!E3)*BaselineCalc!$B$21, 0) -> 0 | U11: =(R11+S11+G11*F11)*J11*(1-K11) -> 6173128.1 | V11: =O11*(G11+P11) -> 0 | W11: =U11+V11+T11 -> 6173128.1 | X11: =IF(F11+O11>0, W11/(F11+O11),"") -> 11162.98 | Y11: =INDEX(YearMap!$I$2:$I$6, MATCH(C11, YearMap!$A$2:$A$6, 0)) -> 5534.4756 | Z11: =$W11-$Y11*$AC11 -> 3112563.1 | AA11: =IF($AC11>0, $Z11/$AC11, 0) -> 5628.5047 | AB11: =MAX(0, (MAX(0, $D11-BaselineCalc!$B$7) + MAX(0, $E11-BaselineCalc!$B$8))) -> 0 | AC11: =IF(LEFT($B11,2)="A_", $O11, IF(LEFT($B11,2)="B_", $M11+$O11, IF(LEFT($B11,2)="C_", $L11+$O11, $F11))) -> 553 | AD11: =$Y11*$AC11 -> 3060565 | AE11: =W11 - (1-Parameters!$B$2)*$G11*$AB11*$J11*(1-$K11) -> 6173128.1 | AF11: =AD11-AE11 -> -3112563.1 | AG11: =B11&"|"&C11 -> E_StatusQuo_Targets_0|FY2030
A12: =AG12 -> F_CoLocation_Echo_0|FY2026 | B12: =Scenarios!A4 -> F_CoLocation_Echo_0 | C12: FY2026 | D12: =IF(Scenarios!D4=1,0, L12) -> 362 | E12: =IF(Scenarios!E4=1,0, M12) -> 341 | F12: =D12+E12 -> 703 | G12: =YearMap!B2 -> 7129.08 | H12: =YearMap!C2 -> 785217.24 | I12: =YearMap!D2 -> 904374.72 | J12: =1-BaselineCalc!$B$5 -> 0.993 | K12: =Scenarios!G4 -> 0.05 | L12: =BaselineCalc!$B$7 + ROUND(Scenarios!I4*Scenarios!F4,0) -> 362 | M12: =BaselineCalc!$B$8 + Scenarios!I4 - ROUND(Scenarios!I4*Scenarios!F4,0) -> 341 | N12: =(L12-D12) + (M12-E12) -> 0 | O12: =BaselineCalc!$B$22 * N12 -> 0 | P12: =YearMap!E2 -> 1000 | Q12: =IF(Scenarios!N4="lease", YearMap!F2, YearMap!G2) -> 0.5 | R12: =IF(Scenarios!D4=1, Q12*H12, H12) -> 785217.24 | S12: =IF(Scenarios!E4=1, Q12*I12, I12) -> 904374.72 | T12: =IF(C12="FY2026", (Scenarios!D4+Scenarios!E4)*BaselineCalc!$B$21, 0) -> 0 | U12: =(R12+S12+G12*F12)*J12*(1-K12) -> 6321704.6 | V12: =O12*(G12+P12) -> 0 | W12: =U12+V12+T12 -> 6321704.6 | X12: =IF(F12+O12>0, W12/(F12+O12),"") -> 8992.4674 | Y12: =INDEX(YearMap!$I$2:$I$6, MATCH(C12, YearMap!$A$2:$A$6, 0)) -> 5113 | Z12: =$W12-$Y12*$AC12 -> 2727265.6 | AA12: =IF($AC12>0, $Z12/$AC12, 0) -> 3879.4674 | AB12: =MAX(0, (MAX(0, $D12-BaselineCalc!$B$7) + MAX(0, $E12-BaselineCalc!$B$8))) -> 150 | AC12: =IF(LEFT($B12,2)="A_", $O12, IF(LEFT($B12,2)="B_", $M12+$O12, IF(LEFT($B12,2)="C_", $L12+$O12, $F12))) -> 703 | AD12: =$Y12*$AC12 -> 3594439 | AE12: =W12 - (1-Parameters!$B$2)*$G12*$AB12*$J12*(1-$K12) -> 5615556.7 | AF12: =AD12-AE12 -> -2021117.7 | AG12: =B12&"|"&C12 -> F_CoLocation_Echo_0|FY2026
A13: =AG13 -> F_CoLocation_Echo_0|FY2027 | B13: =Scenarios!A4 -> F_CoLocation_Echo_0 | C13: FY2027 | D13: =IF(Scenarios!D4=1,0, L13) -> 362 | E13: =IF(Scenarios!E4=1,0, M13) -> 341 | F13: =D13+E13 -> 703 | G13: =YearMap!B3 -> 7307.307 | H13: =YearMap!C3 -> 804847.67 | I13: =YearMap!D3 -> 926984.09 | J13: =1-BaselineCalc!$B$5 -> 0.993 | K13: =Scenarios!G4 -> 0.05 | L13: =BaselineCalc!$B$7 + ROUND(Scenarios!J4*Scenarios!F4,0) -> 362 | M13: =BaselineCalc!$B$8 + Scenarios!J4 - ROUND(Scenarios!J4*Scenarios!F4,0) -> 341 | N13: =(L13-D13) + (M13-E13) -> 0 | O13: =BaselineCalc!$B$22 * N13 -> 0 | P13: =YearMap!E3 -> 800 | Q13: =IF(Scenarios!N4="lease", YearMap!F3, YearMap!G3) -> 0.4 | R13: =IF(Scenarios!D4=1, Q13*H13, H13) -> 804847.67 | S13: =IF(Scenarios!E4=1, Q13*I13, I13) -> 926984.09 | T13: =IF(C13="FY2026", (Scenarios!D4+Scenarios!E4)*BaselineCalc!$B$21, 0) -> 0 | U13: =(R13+S13+G13*F13)*J13*(1-K13) -> 6479747.2 | V13: =O13*(G13+P13) -> 0 | W13: =U13+V13+T13 -> 6479747.2 | X13: =IF(F13+O13>0, W13/(F13+O13),"") -> 9217.2791 | Y13: =INDEX(YearMap!$I$2:$I$6, MATCH(C13, YearMap!$A$2:$A$6, 0)) -> 5215.26 | Z13: =$W13-$Y13*$AC13 -> 2813419.4 | AA13: =IF($AC13>0, $Z13/$AC13, 0) -> 4002.0191 | AB13: =MAX(0, (MAX(0, $D13-BaselineCalc!$B$7) + MAX(0, $E13-BaselineCalc!$B$8))) -> 150 | AC13: =IF(LEFT($B13,2)="A_", $O13, IF(LEFT($B13,2)="B_", $M13+$O13, IF(LEFT($B13,2)="C_", $L13+$O13, $F13))) -> 703 | AD13: =$Y13*$AC13 -> 3666327.8 | AE13: =W13 - (1-Parameters!$B$2)*$G13*$AB13*$J13*(1-$K13) -> 5755945.6 | AF13: =AD13-AE13 -> -2089617.8 | AG13: =B13&"|"&C13 -> F_CoLocation_Echo_0|FY2027
A14: =AG14 -> F_CoLocation_Echo_0|FY2028 | B14: =Scenarios!A4 -> F_CoLocation_Echo_0 | C14: FY2028 | D14: =IF(Scenarios!D4=1,0, L14) -> 362 | E14: =IF(Scenarios!E4=1,0, M14) -> 341 | F14: =D14+E14 -> 703 | G14: =YearMap!B4 -> 7489.9897 | H14: =YearMap!C4 -> 824968.86 | I14: =YearMap!D4 -> 950158.69 | J14: =1-BaselineCalc!$B$5 -> 0.993 | K14: =Scenarios!G4 -> 0.05 | L14: =BaselineCalc!$B$7 + ROUND(Scenarios!K4*Scenarios!F4,0) -> 362 | M14: =BaselineCalc!$B$8 + Scenarios!K4 - ROUND(Scenarios!K4*Scenarios!F4,0) -> 341 | N14: =(L14-D14) + (M14-E14) -> 0 | O14: =BaselineCalc!$B$22 * N14 -> 0 | P14: =YearMap!E4 -> 600 | Q14: =IF(Scenarios!N4="lease", YearMap!F4, YearMap!G4) -> 0.35 | R14: =IF(Scenarios!D4=1, Q14*H14, H14) -> 824968.86 | S14: =IF(Scenarios!E4=1, Q14*I14, I14) -> 950158.69 | T14: =IF(C14="FY2026", (Scenarios!D4+Scenarios!E4)*BaselineCalc!$B$21, 0) -> 0 | U14: =(R14+S14+G14*F14)*J14*(1-K14) -> 6641740.9 | V14: =O14*(G14+P14) -> 0 | W14: =U14+V14+T14 -> 6641740.9 | X14: =IF(F14+O14>0, W14/(F14+O14),"") -> 9447.711 | Y14: =INDEX(YearMap!$I$2:$I$6, MATCH(C14, YearMap!$A$2:$A$6, 0)) -> 5319.5652 | Z14: =$W14-$Y14*$AC14 -> 2902086.5 | AA14: =IF($AC14>0, $Z14/$AC14, 0) -> 4128.1458 | AB14: =MAX(0, (MAX(0, $D14-BaselineCalc!$B$7) + MAX(0, $E14-BaselineCalc!$B$8))) -> 150 | AC14: =IF(LEFT($B14,2)="A_", $O14, IF(LEFT($B14,2)="B_", $M14+$O14, IF(LEFT($B14,2)="C_", $L14+$O14, $F14))) -> 703 | AD14: =$Y14*$AC14 -> 3739654.3 | AE14: =W14 - (1-Parameters!$B$2)*$G14*$AB14*$J14*(1-$K14) -> 5899844.3 | AF14: =AD14-AE14 -> -2160189.9 | AG14: =B14&"|"&C14 -> F_CoLocation_Echo_0|FY2028
A15: =AG15 -> F_CoLocation_Echo_0|FY2029 | B15: =Scenarios!A4 -> F_CoLocation_Echo_0 | C15: FY2029 | D15: =IF(Scenarios!D4=1,0, L15) -> 362 | E15: =IF(Scenarios!E4=1,0, M15) -> 341 | F15: =D15+E15 -> 703 | G15: =YearMap!B5 -> 7677.2394 | H15: =YearMap!C5 -> 845593.08 | I15: =YearMap!D5 -> 973912.66 | J15: =1-BaselineCalc!$B$5 -> 0.993 | K15: =Scenarios!G4 -> 0.05 | L15: =BaselineCalc!$B$7 + ROUND(Scenarios!L4*Scenarios!F4,0) -> 362 | M15: =BaselineCalc!$B$8 + Scenarios!L4 - ROUND(Scenarios!L4*Scenarios!F4,0) -> 341 | N15: =(L15-D15) + (M15-E15) -> 0 | O15: =BaselineCalc!$B$22 * N15 -> 0 | P15: =YearMap!E5 -> 500 | Q15: =IF(Scenarios!N4="lease", YearMap!F5, YearMap!G5) -> 0.3 | R15: =IF(Scenarios!D4=1, Q15*H15, H15) -> 845593.08 | S15: =IF(Scenarios!E4=1, Q15*I15, I15) -> 973912.66 | T15: =IF(C15="FY2026", (Scenarios!D4+Scenarios!E4)*BaselineCalc!$B$21, 0) -> 0 | U15: =(R15+S15+G15*F15)*J15*(1-K15) -> 6807784.4 | V15: =O15*(G15+P15) -> 0 | W15: =U15+V15+T15 -> 6807784.4 | X15: =IF(F15+O15>0, W15/(F15+O15),"") -> 9683.9038 | Y15: =INDEX(YearMap!$I$2:$I$6, MATCH(C15, YearMap!$A$2:$A$6, 0)) -> 5425.9565 | Z15: =$W15-$Y15*$AC15 -> 2993337 | AA15: =IF($AC15>0, $Z15/$AC15, 0) -> 4257.9473 | AB15: =MAX(0, (MAX(0, $D15-BaselineCalc!$B$7) + MAX(0, $E15-BaselineCalc!$B$8))) -> 150 | AC15: =IF(LEFT($B15,2)="A_", $O15, IF(LEFT($B15,2)="B_", $M15+$O15, IF(LEFT($B15,2)="C_", $L15+$O15, $F15))) -> 703 | AD15: =$Y15*$AC15 -> 3814447.4 | AE15: =W15 - (1-Parameters!$B$2)*$G15*$AB15*$J15*(1-$K15) -> 6047340.4 | AF15: =AD15-AE15 -> -2232893 | AG15: =B15&"|"&C15 -> F_CoLocation_Echo_0|FY2029
A16: =AG16 -> F_CoLocation_Echo_0|FY2030 | B16: =Scenarios!A4 -> F_CoLocation_Echo_0 | C16: FY2030 | D16: =IF(Scenarios!D4=1,0, L16) -> 362 | E16: =IF(Scenarios!E4=1,0, M16) -> 341 | F16: =D16+E16 -> 703 | G16: =YearMap!B6 -> 7869.1704 | H16: =YearMap!C6 -> 866732.91 | I16: =YearMap!D6 -> 998260.47 | J16: =1-BaselineCalc!$B$5 -> 0.993 | K16: =Scenarios!G4 -> 0.05 | L16: =BaselineCalc!$B$7 + ROUND(Scenarios!M4*Scenarios!F4,0) -> 362 | M16: =BaselineCalc!$B$8 + Scenarios!M4 - ROUND(Scenarios!M4*Scenarios!F4,0) -> 341 | N16: =(L16-D16) + (M16-E16) -> 0 | O16: =BaselineCalc!$B$22 * N16 -> 0 | P16: =YearMap!E6 -> 400 | Q16: =IF(Scenarios!N4="lease", YearMap!F6, YearMap!G6) -> 0.3 | R16: =IF(Scenarios!D4=1, Q16*H16, H16) -> 866732.91 | S16: =IF(Scenarios!E4=1, Q16*I16, I16) -> 998260.47 | T16: =IF(C16="FY2026", (Scenarios!D4+Scenarios!E4)*BaselineCalc!$B$21, 0) -> 0 | U16: =(R16+S16+G16*F16)*J16*(1-K16) -> 6977979 | V16: =O16*(G16+P16) -> 0 | W16: =U16+V16+T16 -> 6977979 | X16: =IF(F16+O16>0, W16/(F16+O16),"") -> 9926.0014 | Y16: =INDEX(YearMap!$I$2:$I$6, MATCH(C16, YearMap!$A$2:$A$6, 0)) -> 5534.4756 | Z16: =$W16-$Y16*$AC16 -> 3087242.6 | AA16: =IF($AC16>0, $Z16/$AC16, 0) -> 4391.5258 | AB16: =MAX(0, (MAX(0, $D16-BaselineCalc!$B$7) + MAX(0, $E16-BaselineCalc!$B$8))) -> 150 | AC16: =IF(LEFT($B16,2)="A_", $O16, IF(LEFT($B16,2)="B_", $M16+$O16, IF(LEFT($B16,2)="C_", $L16+$O16, $F16))) -> 703 | AD16: =$Y16*$AC16 -> 3890736.4 | AE16: =W16 - (1-Parameters!$B$2)*$G16*$AB16*$J16*(1-$K16) -> 6198523.9 | AF16: =AD16-AE16 -> -2307787.5 | AG16: =B16&"|"&C16 -> F_CoLocation_Echo_0|FY2030
A17: =AG17 -> D_Grow_Both_100|FY2026 | B17: =Scenarios!A5 -> D_Grow_Both_100 | C17: FY2026 | D17: =IF(Scenarios!D5=1,0, L17) -> 307 | E17: =IF(Scenarios!E5=1,0, M17) -> 346 | F17: =D17+E17 -> 653 | G17: =YearMap!B2 -> 7129.08 | H17: =YearMap!C2 -> 785217.24 | I17: =YearMap!D2 -> 904374.72 | J17: =1-BaselineCalc!$B$5 -> 0.993 | K17: =Scenarios!G5 -> 0 | L17: =BaselineCalc!$B$7 + ROUND(Scenarios!I5*Scenarios!F5,0) -> 307 | M17: =BaselineCalc!$B$8 + Scenarios!I5 - ROUND(Scenarios!I5*Scenarios!F5,0) -> 346 | N17: =(L17-D17) + (M17-E17) -> 0 | O17: =BaselineCalc!$B$22 * N17 -> 0 | P17: =YearMap!E2 -> 1000 | Q17: =IF(Scenarios!N5="lease", YearMap!F2, YearMap!G2) -> 0.5 | R17: =IF(Scenarios!D5=1, Q17*H17, H17) -> 785217.24 | S17: =IF(Scenarios!E5=1, Q17*I17, I17) -> 904374.72 | T17: =IF(C17="FY2026", (Scenarios!D5+Scenarios!E5)*BaselineCalc!$B$21, 0) -> 0 | U17: =(R17+S17+G17*F17)*J17*(1-K17) -> 6300467 | V17: =O17*(G17+P17) -> 0 | W17: =U17+V17+T17 -> 6300467 | X17: =IF(F17+O17>0, W17/(F17+O17),"") -> 9648.4947 | Y17: =INDEX(YearMap!$I$2:$I$6, MATCH(C17, YearMap!$A$2:$A$6, 0)) -> 5113 | Z17: =$W17-$Y17*$AC17 -> 2961678 | AA17: =IF($AC17>0, $Z17/$AC17, 0) -> 4535.4947 | AB17: =MAX(0, (MAX(0, $D17-BaselineCalc!$B$7) + MAX(0, $E17-BaselineCalc!$B$8))) -> 100 | AC17: =IF(LEFT($B17,2)="A_", $O17, IF(LEFT($B17,2)="B_", $M17+$O17, IF(LEFT($B17,2)="C_", $L17+$O17, $F17))) -> 653 | AD17: =$Y17*$AC17 -> 3338789 | AE17: =W17 - (1-Parameters!$B$2)*$G17*$AB17*$J17*(1-$K17) -> 5804924.7 | AF17: =AD17-AE17 -> -2466135.7 | AG17: =B17&"|"&C17 -> D_Grow_Both_100|FY2026
A18: =AG18 -> D_Grow_Both_100|FY2027 | B18: =Scenarios!A5 -> D_Grow_Both_100 | C18: FY2027 | D18: =IF(Scenarios!D5=1,0, L18) -> 307 | E18: =IF(Scenarios!E5=1,0, M18) -> 346 | F18: =D18+E18 -> 653 | G18: =YearMap!B3 -> 7307.307 | H18: =YearMap!C3 -> 804847.67 | I18: =YearMap!D3 -> 926984.09 | J18: =1-BaselineCalc!$B$5 -> 0.993 | K18: =Scenarios!G5 -> 0 | L18: =BaselineCalc!$B$7 + ROUND(Scenarios!J5*Scenarios!F5,0) -> 307 | M18: =BaselineCalc!$B$8 + Scenarios!J5 - ROUND(Scenarios!J5*Scenarios!F5,0) -> 346 | N18: =(L18-D18) + (M18-E18) -> 0 | O18: =BaselineCalc!$B$22 * N18 -> 0 | P18: =YearMap!E3 -> 800 | Q18: =IF(Scenarios!N5="lease", YearMap!F3, YearMap!G3) -> 0.4 | R18: =IF(Scenarios!D5=1, Q18*H18, H18) -> 804847.67 | S18: =IF(Scenarios!E5=1, Q18*I18, I18) -> 926984.09 | T18: =IF(C18="FY2026", (Scenarios!D5+Scenarios!E5)*BaselineCalc!$B$21, 0) -> 0 | U18: =(R18+S18+G18*F18)*J18*(1-K18) -> 6457978.7 | V18: =O18*(G18+P18) -> 0 | W18: =U18+V18+T18 -> 6457978.7 | X18: =IF(F18+O18>0, W18/(F18+O18),"") -> 9889.7071 | Y18: =INDEX(YearMap!$I$2:$I$6, MATCH(C18, YearMap!$A$2:$A$6, 0)) -> 5215.26 | Z18: =$W18-$Y18*$AC18 -> 3052413.9 | AA18: =IF($AC18>0, $Z18/$AC18, 0) -> 4674.4471 | AB18: =MAX(0, (MAX(0, $D18-BaselineCalc!$B$7) + MAX(0, $E18-BaselineCalc!$B$8))) -> 100 | AC18: =IF(LEFT($B18,2)="A_", $O18, IF(LEFT($B18,2)="B_", $M18+$O18, IF(LEFT($B18,2)="C_", $L18+$O18, $F18))) -> 653 | AD18: =$Y18*$AC18 -> 3405564.8 | AE18: =W18 - (1-Parameters!$B$2)*$G18*$AB18*$J18*(1-$K18) -> 5950047.8 | AF18: =AD18-AE18 -> -2544483 | AG18: =B18&"|"&C18 -> D_Grow_Both_100|FY2027
A19: =AG19 -> D_Grow_Both_100|FY2028 | B19: =Scenarios!A5 -> D_Grow_Both_100 | C19: FY2028 | D19: =IF(Scenarios!D5=1,0, L19) -> 307 | E19: =IF(Scenarios!E5=1,0, M19) -> 346 | F19: =D19+E19 -> 653 | G19: =YearMap!B4 -> 7489.9897 | H19: =YearMap!C4 -> 824968.86 | I19: =YearMap!D4 -> 950158.69 | J19: =1-BaselineCalc!$B$5 -> 0.993 | K19: =Scenarios!G5 -> 0 | L19: =BaselineCalc!$B$7 + ROUND(Scenarios!K5*Scenarios!F5,0) -> 307 | M19: =BaselineCalc!$B$8 + Scenarios!K5 - ROUND(Scenarios!K5*Scenarios!F5,0) -> 346 | N19: =(L19-D19) + (M19-E19) -> 0 | O19: =BaselineCalc!$B$22 * N19 -> 0 | P19: =YearMap!E4 -> 600 | Q19: =IF(Scenarios!N5="lease", YearMap!F4, YearMap!G4) -> 0.35 | R19: =IF(Scenarios!D5=1, Q19*H19, H19) -> 824968.86 | S19: =IF(Scenarios!E5=1, Q19*I19, I19) -> 950158.69 | T19: =IF(C19="FY2026", (Scenarios!D5+Scenarios!E5)*BaselineCalc!$B$21, 0) -> 0 | U19: =(R19+S19+G19*F19)*J19*(1-K19) -> 6619428.2 | V19: =O19*(G19+P19) -> 0 | W19: =U19+V19+T19 -> 6619428.2 | X19: =IF(F19+O19>0, W19/(F19+O19),"") -> 10136.95 | Y19: =INDEX(YearMap!$I$2:$I$6, MATCH(C19, YearMap!$A$2:$A$6, 0)) -> 5319.5652 | Z19: =$W19-$Y19*$AC19 -> 3145752.1 | AA19: =IF($AC19>0, $Z19/$AC19, 0) -> 4817.3845 | AB19: =MAX(0, (MAX(0, $D19-BaselineCalc!$B$7) + MAX(0, $E19-BaselineCalc!$B$8))) -> 100 | AC19: =IF(LEFT($B19,2)="A_", $O19, IF(LEFT($B19,2)="B_", $M19+$O19, IF(LEFT($B19,2)="C_", $L19+$O19, $F19))) -> 653 | AD19: =$Y19*$AC19 -> 3473676.1 | AE19: =W19 - (1-Parameters!$B$2)*$G19*$AB19*$J19*(1-$K19) -> 6098799 | AF19: =AD19-AE19 -> -2625122.9 | AG19: =B19&"|"&C19 -> D_Grow_Both_100|FY2028
A20: =AG20 -> D_Grow_Both_100|FY2029 | B20: =Scenarios!A5 -> D_Grow_Both_100 | C20: FY2029 | D20: =IF(Scenarios!D5=1,0, L20) -> 307 | E20: =IF(Scenarios!E5=1,0, M20) -> 346 | F20: =D20+E20 -> 653 | G20: =YearMap!B5 -> 7677.2394 | H20: =YearMap!C5 -> 845593.08 | I20: =YearMap!D5 -> 973912.66 | J20: =1-BaselineCalc!$B$5 -> 0.993 | K20: =Scenarios!G5 -> 0 | L20: =BaselineCalc!$B$7 + ROUND(Scenarios!L5*Scenarios!F5,0) -> 307 | M20: =BaselineCalc!$B$8 + Scenarios!L5 - ROUND(Scenarios!L5*Scenarios!F5,0) -> 346 | N20: =(L20-D20) + (M20-E20) -> 0 | O20: =BaselineCalc!$B$22 * N20 -> 0 | P20: =YearMap!E5 -> 500 | Q20: =IF(Scenarios!N5="lease", YearMap!F5, YearMap!G5) -> 0.3 | R20: =IF(Scenarios!D5=1, Q20*H20, H20) -> 845593.08 | S20: =IF(Scenarios!E5=1, Q20*I20, I20) -> 973912.66 | T20: =IF(C20="FY2026", (Scenarios!D5+Scenarios!E5)*BaselineCalc!$B$21, 0) -> 0 | U20: =(R20+S20+G20*F20)*J20*(1-K20) -> 6784913.9 | V20: =O20*(G20+P20) -> 0 | W20: =U20+V20+T20 -> 6784913.9 | X20: =IF(F20+O20>0, W20/(F20+O20),"") -> 10390.373 | Y20: =INDEX(YearMap!$I$2:$I$6, MATCH(C20, YearMap!$A$2:$A$6, 0)) -> 5425.9565 | Z20: =$W20-$Y20*$AC20 -> 3241764.3 | AA20: =IF($AC20>0, $Z20/$AC20, 0) -> 4964.417 | AB20: =MAX(0, (MAX(0, $D20-BaselineCalc!$B$7) + MAX(0, $E20-BaselineCalc!$B$8))) -> 100 | AC20: =IF(LEFT($B20,2)="A_", $O20, IF(LEFT($B20,2)="B_", $M20+$O20, IF(LEFT($B20,2)="C_", $L20+$O20, $F20))) -> 653 | AD20: =$Y20*$AC20 -> 3543149.6 | AE20: =W20 - (1-Parameters!$B$2)*$G20*$AB20*$J20*(1-$K20) -> 6251269 | AF20: =AD20-AE20 -> -2708119.4 | AG20: =B20&"|"&C20 -> D_Grow_Both_100|FY2029
A21: =AG21 -> D_Grow_Both_100|FY2030 | B21: =Scenarios!A5 -> D_Grow_Both_100 | C21: FY2030 | D21: =IF(Scenarios!D5=1,0, L21) -> 307 | E21: =IF(Scenarios!E5=1,0, M21) -> 346 | F21: =D21+E21 -> 653 | G21: =YearMap!B6 -> 7869.1704 | H21: =YearMap!C6 -> 866732.91 | I21: =YearMap!D6 -> 998260.47 | J21: =1-BaselineCalc!$B$5 -> 0.993 | K21: =Scenarios!G5 -> 0 | L21: =BaselineCalc!$B$7 + ROUND(Scenarios!M5*Scenarios!F5,0) -> 307 | M21: =BaselineCalc!$B$8 + Scenarios!M5 - ROUND(Scenarios!M5*Scenarios!F5,0) -> 346 | N21: =(L21-D21) + (M21-E21) -> 0 | O21: =BaselineCalc!$B$22 * N21 -> 0 | P21: =YearMap!E6 -> 400 | Q21: =IF(Scenarios!N5="lease", YearMap!F6, YearMap!G6) -> 0.3 | R21: =IF(Scenarios!D5=1, Q21*H21, H21) -> 866732.91 | S21: =IF(Scenarios!E5=1, Q21*I21, I21) -> 998260.47 | T21: =IF(C21="FY2026", (Scenarios!D5+Scenarios!E5)*BaselineCalc!$B$21, 0) -> 0 | U21: =(R21+S21+G21*F21)*J21*(1-K21) -> 6954536.7 | V21: =O21*(G21+P21) -> 0 | W21: =U21+V21+T21 -> 6954536.7 | X21: =IF(F21+O21>0, W21/(F21+O21),"") -> 10650.133 | Y21: =INDEX(YearMap!$I$2:$I$6, MATCH(C21, YearMap!$A$2:$A$6, 0)) -> 5534.4756 | Z21: =$W21-$Y21*$AC21 -> 3340524.1 | AA21: =IF($AC21>0, $Z21/$AC21, 0) -> 5115.6572 | AB21: =MAX(0, (MAX(0, $D21-BaselineCalc!$B$7) + MAX(0, $E21-BaselineCalc!$B$8))) -> 100 | AC21: =IF(LEFT($B21,2)="A_", $O21, IF(LEFT($B21,2)="B_", $M21+$O21, IF(LEFT($B21,2)="C_", $L21+$O21, $F21))) -> 653 | AD21: =$Y21*$AC21 -> 3614012.6 | AE21: =W21 - (1-Parameters!$B$2)*$G21*$AB21*$J21*(1-$K21) -> 6407550.7 | AF21: =AD21-AE21 -> -2793538.1 | AG21: =B21&"|"&C21 -> D_Grow_Both_100|FY2030
A22: =AG22 -> D_Grow_Both_150|FY2026 | B22: =Scenarios!A6 -> D_Grow_Both_150 | C22: FY2026 | D22: =IF(Scenarios!D6=1,0, L22) -> 382 | E22: =IF(Scenarios!E6=1,0, M22) -> 421 | F22: =D22+E22 -> 803 | G22: =YearMap!B2 -> 7129.08 | H22: =YearMap!C2 -> 785217.24 | I22: =YearMap!D2 -> 904374.72 | J22: =1-BaselineCalc!$B$5 -> 0.993 | K22: =Scenarios!G6 -> 0 | L22: =BaselineCalc!$B$7 + ROUND(Scenarios!I6*Scenarios!F6,0) -> 382 | M22: =BaselineCalc!$B$8 + Scenarios!I6 - ROUND(Scenarios!I6*Scenarios!F6,0) -> 421 | N22: =(L22-D22) + (M22-E22) -> 0 | O22: =BaselineCalc!$B$22 * N22 -> 0 | P22: =YearMap!E2 -> 1000 | Q22: =IF(Scenarios!N6="lease", YearMap!F2, YearMap!G2) -> 0.5 | R22: =IF(Scenarios!D6=1, Q22*H22, H22) -> 785217.24 | S22: =IF(Scenarios!E6=1, Q22*I22, I22) -> 904374.72 | T22: =IF(C22="FY2026", (Scenarios!D6+Scenarios!E6)*BaselineCalc!$B$21, 0) -> 0 | U22: =(R22+S22+G22*F22)*J22*(1-K22) -> 7362343.5 | V22: =O22*(G22+P22) -> 0 | W22: =U22+V22+T22 -> 7362343.5 | X22: =IF(F22+O22>0, W22/(F22+O22),"") -> 9168.5473 | Y22: =INDEX(YearMap!$I$2:$I$6, MATCH(C22, YearMap!$A$2:$A$6, 0)) -> 5113 | Z22: =$W22-$Y22*$AC22 -> 3256604.5 | AA22: =IF($AC22>0, $Z22/$AC22, 0) -> 4055.5473 | AB22: =MAX(0, (MAX(0, $D22-BaselineCalc!$B$7) + MAX(0, $E22-BaselineCalc!$B$8))) -> 250 | AC22: =IF(LEFT($B22,2)="A_", $O22, IF(LEFT($B22,2)="B_", $M22+$O22, IF(LEFT($B22,2)="C_", $L22+$O22, $F22))) -> 803 | AD22: =$Y22*$AC22 -> 4105739 | AE22: =W22 - (1-Parameters!$B$2)*$G22*$AB22*$J22*(1-$K22) -> 6123487.6 | AF22: =AD22-AE22 -> -2017748.6 | AG22: =B22&"|"&C22 -> D_Grow_Both_150|FY2026
A23: =AG23 -> D_Grow_Both_150|FY2027 | B23: =Scenarios!A6 -> D_Grow_Both_150 | C23: FY2027 | D23: =IF(Scenarios!D6=1,0, L23) -> 382 | E23: =IF(Scenarios!E6=1,0, M23) -> 421 | F23: =D23+E23 -> 803 | G23: =YearMap!B3 -> 7307.307 | H23: =YearMap!C3 -> 804847.67 | I23: =YearMap!D3 -> 926984.09 | J23: =1-BaselineCalc!$B$5 -> 0.993 | K23: =Scenarios!G6 -> 0 | L23: =BaselineCalc!$B$7 + ROUND(Scenarios!J6*Scenarios!F6,0) -> 382 | M23: =BaselineCalc!$B$8 + Scenarios!J6 - ROUND(Scenarios!J6*Scenarios!F6,0) -> 421 | N23: =(L23-D23) + (M23-E23) -> 0 | O23: =BaselineCalc!$B$22 * N23 -> 0 | P23: =YearMap!E3 -> 800 | Q23: =IF(Scenarios!N6="lease", YearMap!F3, YearMap!G3) -> 0.4 | R23: =IF(Scenarios!D6=1, Q23*H23, H23) -> 804847.67 | S23: =IF(Scenarios!E6=1, Q23*I23, I23) -> 926984.09 | T23: =IF(C23="FY2026", (Scenarios!D6+Scenarios!E6)*BaselineCalc!$B$21, 0) -> 0 | U23: =(R23+S23+G23*F23)*J23*(1-K23) -> 7546402.1 | V23: =O23*(G23+P23) -> 0 | W23: =U23+V23+T23 -> 7546402.1 | X23: =IF(F23+O23>0, W23/(F23+O23),"") -> 9397.761 | Y23: =INDEX(YearMap!$I$2:$I$6, MATCH(C23, YearMap!$A$2:$A$6, 0)) -> 5215.26 | Z23: =$W23-$Y23*$AC23 -> 3358548.3 | AA23: =IF($AC23>0, $Z23/$AC23, 0) -> 4182.501 | AB23: =MAX(0, (MAX(0, $D23-BaselineCalc!$B$7) + MAX(0, $E23-BaselineCalc!$B$8))) -> 250 | AC23: =IF(LEFT($B23,2)="A_", $O23, IF(LEFT($B23,2)="B_", $M23+$O23, IF(LEFT($B23,2)="C_", $L23+$O23, $F23))) -> 803 | AD23: =$Y23*$AC23 -> 4187853.8 | AE23: =W23 - (1-Parameters!$B$2)*$G23*$AB23*$J23*(1-$K23) -> 6276574.8 | AF23: =AD23-AE23 -> -2088721 | AG23: =B23&"|"&C23 -> D_Grow_Both_150|FY2027
A24: =AG24 -> D_Grow_Both_150|FY2028 | B24: =Scenarios!A6 -> D_Grow_Both_150 | C24: FY2028 | D24: =IF(Scenarios!D6=1,0, L24) -> 382 | E24: =IF(Scenarios!E6=1,0, M24) -> 421 | F24: =D24+E24 -> 803 | G24: =YearMap!B4 -> 7489.9897 | H24: =YearMap!C4 -> 824968.86 | I24: =YearMap!D4 -> 950158.69 | J24: =1-BaselineCalc!$B$5 -> 0.993 | K24: =Scenarios!G6 -> 0 | L24: =BaselineCalc!$B$7 + ROUND(Scenarios!K6*Scenarios!F6,0) -> 382 | M24: =BaselineCalc!$B$8 + Scenarios!K6 - ROUND(Scenarios!K6*Scenarios!F6,0) -> 421 | N24: =(L24-D24) + (M24-E24) -> 0 | O24: =BaselineCalc!$B$22 * N24 -> 0 | P24: =YearMap!E4 -> 600 | Q24: =IF(Scenarios!N6="lease", YearMap!F4, YearMap!G4) -> 0.35 | R24: =IF(Scenarios!D6=1, Q24*H24, H24) -> 824968.86 | S24: =IF(Scenarios!E6=1, Q24*I24, I24) -> 950158.69 | T24: =IF(C24="FY2026", (Scenarios!D6+Scenarios!E6)*BaselineCalc!$B$21, 0) -> 0 | U24: =(R24+S24+G24*F24)*J24*(1-K24) -> 7735062.1 | V24: =O24*(G24+P24) -> 0 | W24: =U24+V24+T24 -> 7735062.1 | X24: =IF(F24+O24>0, W24/(F24+O24),"") -> 9632.705 | Y24: =INDEX(YearMap!$I$2:$I$6, MATCH(C24, YearMap!$A$2:$A$6, 0)) -> 5319.5652 | Z24: =$W24-$Y24*$AC24 -> 3463451.3 | AA24: =IF($AC24>0, $Z24/$AC24, 0) -> 4313.1398 | AB24: =MAX(0, (MAX(0, $D24-BaselineCalc!$B$7) + MAX(0, $E24-BaselineCalc!$B$8))) -> 250 | AC24: =IF(LEFT($B24,2)="A_", $O24, IF(LEFT($B24,2)="B_", $M24+$O24, IF(LEFT($B24,2)="C_", $L24+$O24, $F24))) -> 803 | AD24: =$Y24*$AC24 -> 4271610.9 | AE24: =W24 - (1-Parameters!$B$2)*$G24*$AB24*$J24*(1-$K24) -> 6433489.2 | AF24: =AD24-AE24 -> -2161878.3 | AG24: =B24&"|"&C24 -> D_Grow_Both_150|FY2028
A25: =AG25 -> D_Grow_Both_150|FY2029 | B25: =Scenarios!A6 -> D_Grow_Both_150 | C25: FY2029 | D25: =IF(Scenarios!D6=1,0, L25) -> 382 | E25: =IF(Scenarios!E6=1,0, M25) -> 421 | F25: =D25+E25 -> 803 | G25: =YearMap!B5 -> 7677.2394 | H25: =YearMap!C5 -> 845593.08 | I25: =YearMap!D5 -> 973912.66 | J25: =1-BaselineCalc!$B$5 -> 0.993 | K25: =Scenarios!G6 -> 0 | L25: =BaselineCalc!$B$7 + ROUND(Scenarios!L6*Scenarios!F6,0) -> 382 | M25: =BaselineCalc!$B$8 + Scenarios!L6 - ROUND(Scenarios!L6*Scenarios!F6,0) -> 421 | N25: =(L25-D25) + (M25-E25) -> 0 | O25: =BaselineCalc!$B$22 * N25 -> 0 | P25: =YearMap!E5 -> 500 | Q25: =IF(Scenarios!N6="lease", YearMap!F5, YearMap!G5) -> 0.3 | R25: =IF(Scenarios!D6=1, Q25*H25, H25) -> 845593.08 | S25: =IF(Scenarios!E6=1, Q25*I25, I25) -> 973912.66 | T25: =IF(C25="FY2026", (Scenarios!D6+Scenarios!E6)*BaselineCalc!$B$21, 0) -> 0 | U25: =(R25+S25+G25*F25)*J25*(1-K25) -> 7928438.7 | V25: =O25*(G25+P25) -> 0 | W25: =U25+V25+T25 -> 7928438.7 | X25: =IF(F25+O25>0, W25/(F25+O25),"") -> 9873.5227 | Y25: =INDEX(YearMap!$I$2:$I$6, MATCH(C25, YearMap!$A$2:$A$6, 0)) -> 5425.9565 | Z25: =$W25-$Y25*$AC25 -> 3571395.6 | AA25: =IF($AC25>0, $Z25/$AC25, 0) -> 4447.5661 | AB25: =MAX(0, (MAX(0, $D25-BaselineCalc!$B$7) + MAX(0, $E25-BaselineCalc!$B$8))) -> 250 | AC25: =IF(LEFT($B25,2)="A_", $O25, IF(LEFT($B25,2)="B_", $M25+$O25, IF(LEFT($B25,2)="C_", $L25+$O25, $F25))) -> 803 | AD25: =$Y25*$AC25 -> 4357043.1 | AE25: =W25 - (1-Parameters!$B$2)*$G25*$AB25*$J25*(1-$K25) -> 6594326.4 | AF25: =AD25-AE25 -> -2237283.3 | AG25: =B25&"|"&C25 -> D_Grow_Both_150|FY2029
A26: =AG26 -> D_Grow_Both_150|FY2030 | B26: =Scenarios!A6 -> D_Grow_Both_150 | C26: FY2030 | D26: =IF(Scenarios!D6=1,0, L26) -> 382 | E26: =IF(Scenarios!E6=1,0, M26) -> 421 | F26: =D26+E26 -> 803 | G26: =YearMap!B6 -> 7869.1704 | H26: =YearMap!C6 -> 866732.91 | I26: =YearMap!D6 -> 998260.47 | J26: =1-BaselineCalc!$B$5 -> 0.993 | K26: =Scenarios!G6 -> 0 | L26: =BaselineCalc!$B$7 + ROUND(Scenarios!M6*Scenarios!F6,0) -> 382 | M26: =BaselineCalc!$B$8 + Scenarios!M6 - ROUND(Scenarios!M6*Scenarios!F6,0) -> 421 | N26: =(L26-D26) + (M26-E26) -> 0 | O26: =BaselineCalc!$B$22 * N26 -> 0 | P26: =YearMap!E6 -> 400 | Q26: =IF(Scenarios!N6="lease", YearMap!F6, YearMap!G6) -> 0.3 | R26: =IF(Scenarios!D6=1, Q26*H26, H26) -> 866732.91 | S26: =IF(Scenarios!E6=1, Q26*I26, I26) -> 998260.47 | T26: =IF(C26="FY2026", (Scenarios!D6+Scenarios!E6)*BaselineCalc!$B$21, 0) -> 0 | U26: =(R26+S26+G26*F26)*J26*(1-K26) -> 8126649.7 | V26: =O26*(G26+P26) -> 0 | W26: =U26+V26+T26 -> 8126649.7 | X26: =IF(F26+O26>0, W26/(F26+O26),"") -> 10120.361 | Y26: =INDEX(YearMap!$I$2:$I$6, MATCH(C26, YearMap!$A$2:$A$6, 0)) -> 5534.4756 | Z26: =$W26-$Y26*$AC26 -> 3682465.7 | AA26: =IF($AC26>0, $Z26/$AC26, 0) -> 4585.8851 | AB26: =MAX(0, (MAX(0, $D26-BaselineCalc!$B$7) + MAX(0, $E26-BaselineCalc!$B$8))) -> 250 | AC26: =IF(LEFT($B26,2)="A_", $O26, IF(LEFT($B26,2)="B_", $M26+$O26, IF(LEFT($B26,2)="C_", $L26+$O26, $F26))) -> 803 | AD26: =$Y26*$AC26 -> 4444183.9 | AE26: =W26 - (1-Parameters!$B$2)*$G26*$AB26*$J26*(1-$K26) -> 6759184.6 | AF26: =AD26-AE26 -> -2315000.6 | AG26: =B26&"|"&C26 -> D_Grow_Both_150|FY2030
A27: =AG27 -> G_DHub_EchoRamp|FY2026 | B27: =Scenarios!A7 -> G_DHub_EchoRamp | C27: FY2026 | D27: =IF(Scenarios!D7=1,0, L27) -> 292 | E27: =IF(Scenarios!E7=1,0, M27) -> 311 | F27: =D27+E27 -> 603 | G27: =YearMap!B2 -> 7129.08 | H27: =YearMap!C2 -> 785217.24 | I27: =YearMap!D2 -> 904374.72 | J27: =1-BaselineCalc!$B$5 -> 0.993 | K27: =Scenarios!G7 -> 0 | L27: =BaselineCalc!$B$7 + ROUND(Scenarios!I7*Scenarios!F7,0) -> 292 | M27: =BaselineCalc!$B$8 + Scenarios!I7 - ROUND(Scenarios!I7*Scenarios!F7,0) -> 311 | N27: =(L27-D27) + (M27-E27) -> 0 | O27: =BaselineCalc!$B$22 * N27 -> 0 | P27: =YearMap!E2 -> 1000 | Q27: =IF(Scenarios!N7="lease", YearMap!F2, YearMap!G2) -> 0.5 | R27: =IF(Scenarios!D7=1, Q27*H27, H27) -> 785217.24 | S27: =IF(Scenarios!E7=1, Q27*I27, I27) -> 904374.72 | T27: =IF(C27="FY2026", (Scenarios!D7+Scenarios!E7)*BaselineCalc!$B$21, 0) -> 0 | U27: =(R27+S27+G27*F27)*J27*(1-K27) -> 5946508.2 | V27: =O27*(G27+P27) -> 0 | W27: =U27+V27+T27 -> 5946508.2 | X27: =IF(F27+O27>0, W27/(F27+O27),"") -> 9861.5393 | Y27: =INDEX(YearMap!$I$2:$I$6, MATCH(C27, YearMap!$A$2:$A$6, 0)) -> 5113 | Z27: =$W27-$Y27*$AC27 -> 2863369.2 | AA27: =IF($AC27>0, $Z27/$AC27, 0) -> 4748.5393 | AB27: =MAX(0, (MAX(0, $D27-BaselineCalc!$B$7) + MAX(0, $E27-BaselineCalc!$B$8))) -> 50 | AC27: =IF(LEFT($B27,2)="A_", $O27, IF(LEFT($B27,2)="B_", $M27+$O27, IF(LEFT($B27,2)="C_", $L27+$O27, $F27))) -> 603 | AD27: =$Y27*$AC27 -> 3083139 | AE27: =W27 - (1-Parameters!$B$2)*$G27*$AB27*$J27*(1-$K27) -> 5698737 | AF27: =AD27-AE27 -> -2615598 | AG27: =B27&"|"&C27 -> G_DHub_EchoRamp|FY2026
A28: =AG28 -> G_DHub_EchoRamp|FY2027 | B28: =Scenarios!A7 -> G_DHub_EchoRamp | C28: FY2027 | D28: =IF(Scenarios!D7=1,0, L28) -> 327 | E28: =IF(Scenarios!E7=1,0, M28) -> 326 | F28: =D28+E28 -> 653 | G28: =YearMap!B3 -> 7307.307 | H28: =YearMap!C3 -> 804847.67 | I28: =YearMap!D3 -> 926984.09 | J28: =1-BaselineCalc!$B$5 -> 0.993 | K28: =Scenarios!G7 -> 0 | L28: =BaselineCalc!$B$7 + ROUND(Scenarios!J7*Scenarios!F7,0) -> 327 | M28: =BaselineCalc!$B$8 + Scenarios!J7 - ROUND(Scenarios!J7*Scenarios!F7,0) -> 326 | N28: =(L28-D28) + (M28-E28) -> 0 | O28: =BaselineCalc!$B$22 * N28 -> 0 | P28: =YearMap!E3 -> 800 | Q28: =IF(Scenarios!N7="lease", YearMap!F3, YearMap!G3) -> 0.4 | R28: =IF(Scenarios!D7=1, Q28*H28, H28) -> 804847.67 | S28: =IF(Scenarios!E7=1, Q28*I28, I28) -> 926984.09 | T28: =IF(C28="FY2026", (Scenarios!D7+Scenarios!E7)*BaselineCalc!$B$21, 0) -> 0 | U28: =(R28+S28+G28*F28)*J28*(1-K28) -> 6457978.7 | V28: =O28*(G28+P28) -> 0 | W28: =U28+V28+T28 -> 6457978.7 | X28: =IF(F28+O28>0, W28/(F28+O28),"") -> 9889.7071 | Y28: =INDEX(YearMap!$I$2:$I$6, MATCH(C28, YearMap!$A$2:$A$6, 0)) -> 5215.26 | Z28: =$W28-$Y28*$AC28 -> 3052413.9 | AA28: =IF($AC28>0, $Z28/$AC28, 0) -> 4674.4471 | AB28: =MAX(0, (MAX(0, $D28-BaselineCalc!$B$7) + MAX(0, $E28-BaselineCalc!$B$8))) -> 100 | AC28: =IF(LEFT($B28,2)="A_", $O28, IF(LEFT($B28,2)="B_", $M28+$O28, IF(LEFT($B28,2)="C_", $L28+$O28, $F28))) -> 653 | AD28: =$Y28*$AC28 -> 3405564.8 | AE28: =W28 - (1-Parameters!$B$2)*$G28*$AB28*$J28*(1-$K28) -> 5950047.8 | AF28: =AD28-AE28 -> -2544483 | AG28: =B28&"|"&C28 -> G_DHub_EchoRamp|FY2027
A29: =AG29 -> G_DHub_EchoRamp|FY2028 | B29: =Scenarios!A7 -> G_DHub_EchoRamp | C29: FY2028 | D29: =IF(Scenarios!D7=1,0, L29) -> 362 | E29: =IF(Scenarios!E7=1,0, M29) -> 341 | F29: =D29+E29 -> 703 | G29: =YearMap!B4 -> 7489.9897 | H29: =YearMap!C4 -> 824968.86 | I29: =YearMap!D4 -> 950158.69 | J29: =1-BaselineCalc!$B$5 -> 0.993 | K29: =Scenarios!G7 -> 0 | L29: =BaselineCalc!$B$7 + ROUND(Scenarios!K7*Scenarios!F7,0) -> 362 | M29: =BaselineCalc!$B$8 + Scenarios!K7 - ROUND(Scenarios!K7*Scenarios!F7,0) -> 341 | N29: =(L29-D29) + (M29-E29) -> 0 | O29: =BaselineCalc!$B$22 * N29 -> 0 | P29: =YearMap!E4 -> 600 | Q29: =IF(Scenarios!N7="lease", YearMap!F4, YearMap!G4) -> 0.35 | R29: =IF(Scenarios!D7=1, Q29*H29, H29) -> 824968.86 | S29: =IF(Scenarios!E7=1, Q29*I29, I29) -> 950158.69 | T29: =IF(C29="FY2026", (Scenarios!D7+Scenarios!E7)*BaselineCalc!$B$21, 0) -> 0 | U29: =(R29+S29+G29*F29)*J29*(1-K29) -> 6991306.2 | V29: =O29*(G29+P29) -> 0 | W29: =U29+V29+T29 -> 6991306.2 | X29: =IF(F29+O29>0, W29/(F29+O29),"") -> 9944.959 | Y29: =INDEX(YearMap!$I$2:$I$6, MATCH(C29, YearMap!$A$2:$A$6, 0)) -> 5319.5652 | Z29: =$W29-$Y29*$AC29 -> 3251651.8 | AA29: =IF($AC29>0, $Z29/$AC29, 0) -> 4625.3938 | AB29: =MAX(0, (MAX(0, $D29-BaselineCalc!$B$7) + MAX(0, $E29-BaselineCalc!$B$8))) -> 150 | AC29: =IF(LEFT($B29,2)="A_", $O29, IF(LEFT($B29,2)="B_", $M29+$O29, IF(LEFT($B29,2)="C_", $L29+$O29, $F29))) -> 703 | AD29: =$Y29*$AC29 -> 3739654.3 | AE29: =W29 - (1-Parameters!$B$2)*$G29*$AB29*$J29*(1-$K29) -> 6210362.4 | AF29: =AD29-AE29 -> -2470708.1 | AG29: =B29&"|"&C29 -> G_DHub_EchoRamp|FY2028
A30: =AG30 -> G_DHub_EchoRamp|FY2029 | B30: =Scenarios!A7 -> G_DHub_EchoRamp | C30: FY2029 | D30: =IF(Scenarios!D7=1,0, L30) -> 362 | E30: =IF(Scenarios!E7=1,0, M30) -> 341 | F30: =D30+E30 -> 703 | G30: =YearMap!B5 -> 7677.2394 | H30: =YearMap!C5 -> 845593.08 | I30: =YearMap!D5 -> 973912.66 | J30: =1-BaselineCalc!$B$5 -> 0.993 | K30: =Scenarios!G7 -> 0 | L30: =BaselineCalc!$B$7 + ROUND(Scenarios!L7*Scenarios!F7,0) -> 362 | M30: =BaselineCalc!$B$8 + Scenarios!L7 - ROUND(Scenarios!L7*Scenarios!F7,0) -> 341 | N30: =(L30-D30) + (M30-E30) -> 0 | O30: =BaselineCalc!$B$22 * N30 -> 0 | P30: =YearMap!E5 -> 500 | Q30: =IF(Scenarios!N7="lease", YearMap!F5, YearMap!G5) -> 0.3 | R30: =IF(Scenarios!D7=1, Q30*H30, H30) -> 845593.08 | S30: =IF(Scenarios!E7=1, Q30*I30, I30) -> 973912.66 | T30: =IF(C30="FY2026", (Scenarios!D7+Scenarios!E7)*BaselineCalc!$B$21, 0) -> 0 | U30: =(R30+S30+G30*F30)*J30*(1-K30) -> 7166088.8 | V30: =O30*(G30+P30) -> 0 | W30: =U30+V30+T30 -> 7166088.8 | X30: =IF(F30+O30>0, W30/(F30+O30),"") -> 10193.583 | Y30: =INDEX(YearMap!$I$2:$I$6, MATCH(C30, YearMap!$A$2:$A$6, 0)) -> 5425.9565 | Z30: =$W30-$Y30*$AC30 -> 3351641.4 | AA30: =IF($AC30>0, $Z30/$AC30, 0) -> 4767.6264 | AB30: =MAX(0, (MAX(0, $D30-BaselineCalc!$B$7) + MAX(0, $E30-BaselineCalc!$B$8))) -> 150 | AC30: =IF(LEFT($B30,2)="A_", $O30, IF(LEFT($B30,2)="B_", $M30+$O30, IF(LEFT($B30,2)="C_", $L30+$O30, $F30))) -> 703 | AD30: =$Y30*$AC30 -> 3814447.4 | AE30: =W30 - (1-Parameters!$B$2)*$G30*$AB30*$J30*(1-$K30) -> 6365621.4 | AF30: =AD30-AE30 -> -2551174 | AG30: =B30&"|"&C30 -> G_DHub_EchoRamp|FY2029
A31: =AG31 -> G_DHub_EchoRamp|FY2030 | B31: =Scenarios!A7 -> G_DHub_EchoRamp | C31: FY2030 | D31: =IF(Scenarios!D7=1,0, L31) -> 362 | E31: =IF(Scenarios!E7=1,0, M31) -> 341 | F31: =D31+E31 -> 703 | G31: =YearMap!B6 -> 7869.1704 | H31: =YearMap!C6 -> 866732.91 | I31: =YearMap!D6 -> 998260.47 | J31: =1-BaselineCalc!$B$5 -> 0.993 | K31: =Scenarios!G7 -> 0 | L31: =BaselineCalc!$B$7 + ROUND(Scenarios!M7*Scenarios!F7,0) -> 362 | M31: =BaselineCalc!$B$8 + Scenarios!M7 - ROUND(Scenarios!M7*Scenarios!F7,0) -> 341 | N31: =(L31-D31) + (M31-E31) -> 0 | O31: =BaselineCalc!$B$22 * N31 -> 0 | P31: =YearMap!E6 -> 400 | Q31: =IF(Scenarios!N7="lease", YearMap!F6, YearMap!G6) -> 0.3 | R31: =IF(Scenarios!D7=1, Q31*H31, H31) -> 866732.91 | S31: =IF(Scenarios!E7=1, Q31*I31, I31) -> 998260.47 | T31: =IF(C31="FY2026", (Scenarios!D7+Scenarios!E7)*BaselineCalc!$B$21, 0) -> 0 | U31: =(R31+S31+G31*F31)*J31*(1-K31) -> 7345241 | V31: =O31*(G31+P31) -> 0 | W31: =U31+V31+T31 -> 7345241 | X31: =IF(F31+O31>0, W31/(F31+O31),"") -> 10448.423 | Y31: =INDEX(YearMap!$I$2:$I$6, MATCH(C31, YearMap!$A$2:$A$6, 0)) -> 5534.4756 | Z31: =$W31-$Y31*$AC31 -> 3454504.7 | AA31: =IF($AC31>0, $Z31/$AC31, 0) -> 4913.9469 | AB31: =MAX(0, (MAX(0, $D31-BaselineCalc!$B$7) + MAX(0, $E31-BaselineCalc!$B$8))) -> 150 | AC31: =IF(LEFT($B31,2)="A_", $O31, IF(LEFT($B31,2)="B_", $M31+$O31, IF(LEFT($B31,2)="C_", $L31+$O31, $F31))) -> 703 | AD31: =$Y31*$AC31 -> 3890736.4 | AE31: =W31 - (1-Parameters!$B$2)*$G31*$AB31*$J31*(1-$K31) -> 6524762 | AF31: =AD31-AE31 -> -2634025.6 | AG31: =B31&"|"&C31 -> G_DHub_EchoRamp|FY2030
A32: =AG32 -> A_Repurpose_Both_lease|FY2026 | B32: =Scenarios!A8 -> A_Repurpose_Both_lease | C32: FY2026 | D32: =IF(Scenarios!D8=1,0, L32) -> 0 | E32: =IF(Scenarios!E8=1,0, M32) -> 0 | F32: =D32+E32 -> 0 | G32: =YearMap!B2 -> 7129.08 | H32: =YearMap!C2 -> 785217.24 | I32: =YearMap!D2 -> 904374.72 | J32: =1-BaselineCalc!$B$5 -> 0.993 | K32: =Scenarios!G8 -> 0 | L32: =BaselineCalc!$B$7 + ROUND(Scenarios!I8*Scenarios!F8,0) -> 257 | M32: =BaselineCalc!$B$8 + Scenarios!I8 - ROUND(Scenarios!I8*Scenarios!F8,0) -> 296 | N32: =(L32-D32) + (M32-E32) -> 553 | O32: =BaselineCalc!$B$22 * N32 -> 414.75 | P32: =YearMap!E2 -> 1000 | Q32: =IF(Scenarios!N8="lease", YearMap!F2, YearMap!G2) -> 0.4 | R32: =IF(Scenarios!D8=1, Q32*H32, H32) -> 314086.9 | S32: =IF(Scenarios!E8=1, Q32*I32, I32) -> 361749.89 | T32: =IF(C32="FY2026", (Scenarios!D8+Scenarios!E8)*BaselineCalc!$B$21, 0) -> 2400000 | U32: =(R32+S32+G32*F32)*J32*(1-K32) -> 671105.93 | V32: =O32*(G32+P32) -> 3371535.9 | W32: =U32+V32+T32 -> 6442641.9 | X32: =IF(F32+O32>0, W32/(F32+O32),"") -> 15533.796 | Y32: =INDEX(YearMap!$I$2:$I$6, MATCH(C32, YearMap!$A$2:$A$6, 0)) -> 5113 | Z32: =$W32-$Y32*$AC32 -> 4322025.1 | AA32: =IF($AC32>0, $Z32/$AC32, 0) -> 10420.796 | AB32: =MAX(0, (MAX(0, $D32-BaselineCalc!$B$7) + MAX(0, $E32-BaselineCalc!$B$8))) -> 0 | AC32: =IF(LEFT($B32,2)="A_", $O32, IF(LEFT($B32,2)="B_", $M32+$O32, IF(LEFT($B32,2)="C_", $L32+$O32, $F32))) -> 414.75 | AD32: =$Y32*$AC32 -> 2120616.8 | AE32: =W32 - (1-Parameters!$B$2)*$G32*$AB32*$J32*(1-$K32) -> 6442641.9 | AF32: =AD32-AE32 -> -4322025.1 | AG32: =B32&"|"&C32 -> A_Repurpose_Both_lease|FY2026
A33: =AG33 -> A_Repurpose_Both_lease|FY2027 | B33: =Scenarios!A8 -> A_Repurpose_Both_lease | C33: FY2027 | D33: =IF(Scenarios!D8=1,0, L33) -> 0 | E33: =IF(Scenarios!E8=1,0, M33) -> 0 | F33: =D33+E33 -> 0 | G33: =YearMap!B3 -> 7307.307 | H33: =YearMap!C3 -> 804847.67 | I33: =YearMap!D3 -> 926984.09 | J33: =1-BaselineCalc!$B$5 -> 0.993 | K33: =Scenarios!G8 -> 0 | L33: =BaselineCalc!$B$7 + ROUND(Scenarios!J8*Scenarios!F8,0) -> 257 | M33: =BaselineCalc!$B$8 + Scenarios!J8 - ROUND(Scenarios!J8*Scenarios!F8,0) -> 296 | N33: =(L33-D33) + (M33-E33) -> 553 | O33: =BaselineCalc!$B$22 * N33 -> 414.75 | P33: =YearMap!E3 -> 800 | Q33: =IF(Scenarios!N8="lease", YearMap!F3, YearMap!G3) -> 0.3 | R33: =IF(Scenarios!D8=1, Q33*H33, H33) -> 241454.3 | S33: =IF(Scenarios!E8=1, Q33*I33, I33) -> 278095.23 | T33: =IF(C33="FY2026", (Scenarios!D8+Scenarios!E8)*BaselineCalc!$B$21, 0) -> 0 | U33: =(R33+S33+G33*F33)*J33*(1-K33) -> 515912.68 | V33: =O33*(G33+P33) -> 3362505.6 | W33: =U33+V33+T33 -> 3878418.3 | X33: =IF(F33+O33>0, W33/(F33+O33),"") -> 9351.2194 | Y33: =INDEX(YearMap!$I$2:$I$6, MATCH(C33, YearMap!$A$2:$A$6, 0)) -> 5215.26 | Z33: =$W33-$Y33*$AC33 -> 1715389.2 | AA33: =IF($AC33>0, $Z33/$AC33, 0) -> 4135.9594 | AB33: =MAX(0, (MAX(0, $D33-BaselineCalc!$B$7) + MAX(0, $E33-BaselineCalc!$B$8))) -> 0 | AC33: =IF(LEFT($B33,2)="A_", $O33, IF(LEFT($B33,2)="B_", $M33+$O33, IF(LEFT($B33,2)="C_", $L33+$O33, $F33))) -> 414.75 | AD33: =$Y33*$AC33 -> 2163029.1 | AE33: =W33 - (1-Parameters!$B$2)*$G33*$AB33*$J33*(1-$K33) -> 3878418.3 | AF33: =AD33-AE33 -> -1715389.2 | AG33: =B33&"|"&C33 -> A_Repurpose_Both_lease|FY2027
