Workbook
Name ADM_Day_Select: Parameters_Public!C8
Name Aid_growth: BaselineCalc!B28
Name Base_Aid_per_ADM: Parameters_Public!C18
Name BaseAid_per_ADM: Parameters_Public!C18
Name Capex_ArtsHub: Parameters_Public!C28
Name Capex_in_MO_Toggle: Parameters_Public!C30
Name Capex_InnovHub: Parameters_Public!C29
Name Echo_ADM0: Parameters_Public!C10
Name Echo_ADM0_selected: Parameters_Public!C10
Name Echo_retention_r: Parameters_Public!C23
Name EchoFixed_FY25_Total: Site_Fixed!C8
Name f_lease_profile: Control_Center!$D$23:$H$23
Name f_ops_profile: Control_Center!$D$22:$H$22
Name Growth_overhead_alpha: Parameters_Public!C47
Name h_taper_profile: Control_Center!$C$22:$G$26
Name Incremental_uplift_alpha: Parameters_Public!C49
Name M_O_per_ADM_Audited: Parameters_Public!C14
Name MarginalFactor_for_Overlay: Parameters_Public!C43
Name MO_inflation: Control_Center!C6
Name Override_per_ADM_proxy: Parameters_Public!C19
Name Override_percent: Parameters_Public!C17
Name Override_toggle: Parameters_Public!C20
Name Pima_ADM0: Parameters_Public!C11
Name Pima_ADM0_selected: Parameters_Public!C11
Name Pima_retention_r: Parameters_Public!C24
Name PimaFixed_FY25_Total: Site_Fixed!C15
Name Portable_seat_cost: Parameters_Public!C34
Name TI_in_MO_Toggle: Parameters_Public!C26
Name TI_per_Site: Parameters_Public!C27
Name Uplift_base_per_ADM: Parameters_Public!C21

Sheet Workbook_Purpose_Overview

Sheet How_To_Use_The_Workbook
B1: How to use the workbook
B2: Start on Scenario_Comparison: choose two scenarios to compare; review the operational, capital, and student-related results.
B3: Test assumptions (override switch, retention r, trend flags) only if you would like to check sensitivity.
B4: Check capacity gates (receiving bands).
B5: Open Budget_Neutral_Calculator if you’re considering a non‑repurpose plan: it shows N⁰—how many students are needed to be Net ≥ 0.
B6: Look at Summary_Figures to scan all scenarios with the same signals.
B7: Use Inputs_Definitions_Sources for terms, references, and what’s still awaiting audited paste.
B8: Check What_Is_$900K_Savings if you are curious xxxxxx

Sheet Headline_Numbers
C2: Scenario A (Repurpose Both Operationally) | D2: Scenario B (Continued Decline) | E2: Scenario C (Grow Both) | F2: Scenario D (Repurpose Echo Operationally; Grow Pima) | G2: Scenario E (Repurpose Pima Operationally; Grow Echo) | H2: Scenario A2 (Repurpose Both as Lease or Sale**) | I2: Scenario D2 (Repurpose Echo as Lease or Sale; Grow Pima) | J2: Scenario E2 (Repurpose Pima as Lease or Sale; Grow Echo)
A3: Operating performance (Fund 001)
B4: 5‑yr Operating Net (no capital) | C4: =Summary_Figures!H11 -> -2435553 | D4: =Summary_Figures!H17 -> -2720355.1 | E4: =Summary_Figures!H8 -> 817146.13 | F4: =Summary_Figures!H14 -> -1692773.7 | G4: =Summary_Figures!H16 -> -1002802.1 | H4: =Summary_Figures!H12 -> 2675514.3 | I4: =Summary_Figures!H13 -> 698552.08 | J4: =Summary_Figures!H15 -> 1716939.4
B5: Δ 5-yr Op Net vs Scenario A | C5: =C4-$C$4 -> 0 | D5: =D4-$C$4 -> -284802.14 | E5: =E4-$C$4 -> 3252699.1 | F5: =F4-$C$4 -> 742779.22 | G5: =G4-$C$4 -> 1432750.9 | H5: =H4-$C$4 -> 5111067.3 | I5: =I4-$C$4 -> 3134105 | J5: =J4-$C$4 -> 4152492.3
A7: Reference (outside 001 unless confirmed otherwise)
B8: Memo-5-yr Lease Avoidance (District Admin)* | C8: =SUM(Lease_Avoidance!$B$14:$F$14) -> 604500 | D8: =0 -> 0 | E8: =0 -> 0 | F8: =SUM(Lease_Avoidance!$B$14:$F$14) -> 604500 | G8: =0 -> 0 | H8: =0 -> 0 | I8: =0 -> 0 | J8: =0 -> 0
B9: Memo-5-yr Pre-K / Community Programs Net* | C9: =SUM(Pre_K!$B$22:$F$22) -> 24000 | D9: =0 -> 0 | E9: =0 -> 0 | F9: =SUM(Pre_K!$B$22:$F$22) -> 24000 | G9: =0 -> 0 | H9: =0 -> 0 | I9: =0 -> 0 | J9: =0 -> 0
B11: Memo-5-yr Operating Net + (Lease Avoidance + Pre-K / Community Programs Net) | C11: =C4+C8 -> -1831053 | D11: =D4+D8 -> -2720355.1 | E11: =E4+E8 -> 817146.13 | F11: =F4+F8 -> -1088273.7 | G11: =G4+G8 -> -1002802.1 | H11: =H4+H8 -> 2675514.3 | I11: =I4+I8 -> 698552.08 | J11: =J4+J8 -> 1716939.4
A13: People
B14: FY26 Displaced (students) | C14: =Summary_Figures!I11 -> 553 | D14: =Summary_Figures!I17 -> 0 | E14: =Summary_Figures!I8 -> 0 | F14: =Summary_Figures!I14 -> 257 | G14: =Summary_Figures!I16 -> 295.66667 | H14: =Summary_Figures!I12 -> 553 | I14: =Summary_Figures!I13 -> 257 | J14: =Summary_Figures!I15 -> 295.66667
B15: FY30 Served (students) | C15: =Summary_Figures!J11 -> 405.8 | D15: =Summary_Figures!J17 -> 510.06959 | E15: =Summary_Figures!J8 -> 703 | F15: =Summary_Figures!J14 -> 500.2 | G15: =Summary_Figures!J16 -> 558.6 | H15: =Summary_Figures!J12 -> 405.8 | I15: =Summary_Figures!J13 -> 500.2 | J15: =Summary_Figures!J15 -> 558.6
B16: Net per served (FY30)*** | C16: =Summary_Figures!K11 -> -587.13622 | D16: =Summary_Figures!K17 -> -1237.4658 | E16: =Summary_Figures!K8 -> 485.56043 | F16: =Summary_Figures!K14 -> -372.35105 | G16: =Summary_Figures!K16 -> 11.724788 | H16: =Summary_Figures!K12 -> 2008.4043 | I16: =Summary_Figures!K13 -> 606.24657 | J16: =Summary_Figures!K15 -> 1020.9905
A18: Capital
B19: FY26 Capital Investment (One-time) | C19: =Capital_Summary!H34*-1 -> -2714480 | D19: =Capital_Summary!H64*-1 -> 0 | E19: =Capital_Summary!H19*-1 -> -1800000 | F19: =Capital_Summary!H49*-1 -> -1800000 | G19: =Capital_Summary!H59*-1 -> -1800000 | H19: =Capital_Summary!H39*-1 -> -2314480 | I19: =Capital_Summary!H44*-1 -> -1600000 | J19: =Capital_Summary!H54*-1 -> -1600000
A21: Risk & Strategy
B22: Implementation complexity & delivery risk | C22: Medium-High | D22: Low | E22: High | F22: Medium | G22: Medium | H22: Medium | I22: Medium | J22: Medium
B23: Community (negative) impact & reputational risk | C23: High | D23: Medium | E23: Low-Medium | F23: Medium | G23: Medium | H23: High | I23: Medium | J23: Medium
B24: Strategic value & district resilience | C24: Medium | D24: Low | E24: High | F24: High | G24: High | H24: Medium | I24: High | J24: High
B25: Reversibility | C25: Low-Medium | D25: High | E25: Medium | F25: Low-Medium | G25: Low-Medium | H25: Low | I25: Low-Medium | J25: Low-Medium
C27: Fixed‑cost savings only if site is dark/leased; result depends on retention; includes temporary routing/admin. | E27: No transition overhead; starts negative if base deficit > year‑1 contribution; improves as cohorts accumulate. | F27: Fixed savings on one campus + positive contribution from added students at the other.
B29: *Showing as separate from operating net as may be accounted for outside 001; suggestion was that Echo would have district offices, pre-K focus, and some 'shared use' rent of space
B30: **Ideally would de-couple lease & sale, but combined for model simplifcation; can imagine that sale is cleaner from a balance sheet perspective and can reduce overall admin burden over time if can execute sale quickly, but sale is likely more difficult to get approved; conversely, lease would be less clean but might be easier to get approved. Both have similar negative reputation impact, presumably.
B31: ***Operating Net ÷ FY30 served (Fund 001)
B32: “Operating Net = Fund 001 only; Lease‑avoidance and Pre‑K/community are displayed as memo items.”
B33: “All figures tie to MultiYear_Pro_Forma / Summary_Figures; FY‑specific checks appear below the fold.”
B35: Key | C35: 🟥 = adverse, 🟨 = mixed, 🟩 = favorable (vs. base)
C37: Implementation complexity & delivery risk
C38: What it means: number/size of moving parts—closures, conversions, lease/sale actions, routing changes, and program build.
C40: Community impact & reputational risk
C41: What it means: visible disruption (displaced students), likelihood of controversy, and communications load.
C43: Strategic value & district resilience
C44: What it means: ability to attract/retain families, strengthen SUSD’s brand/program mix, and reduce long‑run fragility.
A53: Risk & Strategy
B54: Implementation complexity & delivery risk | C54: Medium-High | D54: Low | E54: High | F54: Medium | G54: Medium | H54: Medium-High | I54: Medium | J54: Medium
B55: Community (negative) impact & reputational risk | C55: High | D55: Medium | E55: Low-Medium | F55: Medium | G55: Medium | H55: High | I55: Medium | J55: Medium
B56: Strategic value & district resilience | C56: Low | D56: Low | E56: High | F56: High | G56: High | H56: Low-Medium | I56: High | J56: High
B57: Reversibility | C57: Low-Medium | D57: High | E57: Medium | F57: Low-Medium | G57: Low-Medium | H57: Low | I57: Low-Medium | J57: Low-Medium

Sheet Dashboard
B1: Go-forward scenario summary view* | C1: *SUSD-sourced data used wherever possible. Sources and assumptions are noted in Inputs_Definitions_Sources
B2: Choose view >> | C2: 2026
L3: SUMMARY (Selected View) | P3: INTUITION (quick read)
B4: ="FY"&IF(C2=2026, "26", IF(C2=2030, "30", "Average 2026-2030"))&" simulated P&L and capital spend by scenario" -> FY26 simulated P&L and capital spend by scenario | C4: A1 | D4: B1 | E4: C1 | F4: D1 | G4: E1 | L4: Operating Net | M4: =C33 -> -797624.54 | N4: =F33 -> -76179.355 | P4: B2<C2 in FY26: Echo r lower → fewer served; h applies.
C5: Scenario A (Repurpose Both Operationally) | D5: Scenario B (Continued Decline) | E5: Scenario C (Grow Both) | F5: Scenario D (Repurpose Echo Operationally; Grow Pima) | G5: Scenario E (Repurpose Pima Operationally; Grow Echo) | J5: Source / Confidence Level | K5: Model sensitivity | L5: Revenue | M5: =C14 -> 4449576.7 | N5: =F14 -> 5106169.7 | P5: Grow Both FY26 negative: Yr‑1 deficit + small overlay; improves by FY30.
B6: Baseline ADM Echo | C6: =IF($C$2=2026,C$67,IF($C$2=2030,C$103,C$67)) -> 257 | D6: =IF($C$2=2026,D$67,IF($C$2=2030,D$103,D$67)) -> 257 | E6: =IF($C$2=2026,E$67,IF($C$2=2030,E$103,E$67)) -> 257 | F6: =IF($C$2=2026,F$67,IF($C$2=2030,F$103,F$67)) -> 257 | G6: =IF($C$2=2026,G$67,IF($C$2=2030,G$103,G$67)) -> 257 | J6: *** | L6: Variable M&O + h | M6: =C28 -> 3805795 | N6: =F28 -> 4050770.9
B7: Baseline ADM Pima | C7: =IF($C$2=2026,C$68,IF($C$2=2030,C$104,C$68)) -> 296 | D7: =IF($C$2=2026,D$68,IF($C$2=2030,D$104,D$68)) -> 296 | E7: =IF($C$2=2026,E$68,IF($C$2=2030,E$104,E$68)) -> 296 | F7: =IF($C$2=2026,F$68,IF($C$2=2030,F$104,F$68)) -> 296 | G7: =IF($C$2=2026,G$68,IF($C$2=2030,G$104,G$68)) -> 296 | L7: Fixed M&O (net) | M7: =C31 -> 1441406.2 | N7: =F31 -> 1183875
B8: ADM change FY26 | C8: =IF($C$2=2026,C$69,IF($C$2=2030,C$105,C$69)) -> 0 | D8: =IF($C$2=2026,D$69,IF($C$2=2030,D$105,D$69)) -> 0 | E8: =IF($C$2=2026,E$69,IF($C$2=2030,E$105,E$69)) -> 50 | F8: =IF($C$2=2026,F$69,IF($C$2=2030,F$105,F$69)) -> 16.666667 | G8: =IF($C$2=2026,G$69,IF($C$2=2030,G$105,G$69)) -> 17 | L8: One-time Capital (FY26) | M8: =C36 -> 2714480 | N8: =F36 -> 1600000
B9: Echo retention ratio | C9: =IF($C$2=2026,C$70,IF($C$2=2030,C$106,C$70)) -> 0.6 | D9: =IF($C$2=2026,D$70,IF($C$2=2030,D$106,D$70)) -> N/A | E9: =IF($C$2=2026,E$70,IF($C$2=2030,E$106,E$70)) -> N/A | F9: =IF($C$2=2026,F$70,IF($C$2=2030,F$106,F$70)) -> 0.6 | G9: =IF($C$2=2026,G$70,IF($C$2=2030,G$106,G$70)) -> N/A | J9: *
B10: Pima retention ratio | C10: =IF($C$2=2026,C$71,IF($C$2=2030,C$107,C$71)) -> 0.85 | D10: =IF($C$2=2026,D$71,IF($C$2=2030,D$107,D$71)) -> N/A | E10: =IF($C$2=2026,E$71,IF($C$2=2030,E$107,E$71)) -> N/A | F10: =IF($C$2=2026,F$71,IF($C$2=2030,F$107,F$71)) -> N/A | G10: =IF($C$2=2026,G$71,IF($C$2=2030,G$107,G$71)) -> 0.85 | J10: **
B11: Number of students transitioning | C11: =IF($C$2=2026,C$72,IF($C$2=2030,C$108,C$72)) -> 405.8 | D11: =IF($C$2=2026,D$72,IF($C$2=2030,D$108,D$72)) -> 0 | E11: =IF($C$2=2026,E$72,IF($C$2=2030,E$108,E$72)) -> 0 | F11: =IF($C$2=2026,F$72,IF($C$2=2030,F$108,F$72)) -> 154.2 | G11: =IF($C$2=2026,G$72,IF($C$2=2030,G$108,G$72)) -> 251.31667
B12: Students served FY26 | C12: =IF($C$2=2026,C$73,IF($C$2=2030,C$109,C$73)) -> 405.8 | D12: =IF($C$2=2026,D$73,IF($C$2=2030,D$109,D$73)) -> 553 | E12: =IF($C$2=2026,E$73,IF($C$2=2030,E$109,E$73)) -> 603 | F12: =IF($C$2=2026,F$73,IF($C$2=2030,F$109,F$73)) -> 466.86667 | G12: =IF($C$2=2026,G$73,IF($C$2=2030,G$109,G$73)) -> 525.31667 | L12: Sensitivity (Δ Net FY2030)
B13: Revenue per served student ($/ADM) | C13: =IF($C$2=2026,C$74,IF($C$2=2030,C$110,"")) -> 10964.95 | D13: =IF($C$2=2026,D$74,IF($C$2=2030,D$110,"")) -> 10964.95 | E13: =IF($C$2=2026,E$74,IF($C$2=2030,E$110,"")) -> 10900.273 | F13: =IF($C$2=2026,F$74,IF($C$2=2030,F$110,"")) -> 10937.105 | G13: =IF($C$2=2026,G$74,IF($C$2=2030,G$110,"")) -> 10939.708 | L13: Site‑Fixed ±$100k/site
B14: Total 'revenue' | C14: =IF($C$2=2026,C$75,IF($C$2=2030,C$111,C$75)) -> 4449576.7 | D14: =IF($C$2=2026,D$75,IF($C$2=2030,D$111,D$75)) -> 6063617.3 | E14: =IF($C$2=2026,E$75,IF($C$2=2030,E$111,E$75)) -> 6572864.9 | F14: =IF($C$2=2026,F$75,IF($C$2=2030,F$111,F$75)) -> 5106169.7 | G14: =IF($C$2=2026,G$75,IF($C$2=2030,G$111,G$75)) -> 5746811 | L14: f_ops / f_lease ±0.05
B15: Districtwide gross Maint & Operations cost per non-new ADM | C15: =IF($C$2=2026,C$76,IF($C$2=2030,C$112,C$76)) -> 11589 | D15: =IF($C$2=2026,D$76,IF($C$2=2030,D$112,D$76)) -> 11589 | E15: =IF($C$2=2026,E$76,IF($C$2=2030,E$112,E$76)) -> 11589 | F15: =IF($C$2=2026,F$76,IF($C$2=2030,F$112,F$76)) -> 11589 | G15: =IF($C$2=2026,G$76,IF($C$2=2030,G$112,G$76)) -> 11589 | L15: Retention r ±10 pp
B16: Variable M&O per non-new student ($/ADM) | C16: =IF($C$2=2026,C$77,IF($C$2=2030,C$113,"")) -> 8403.3633 | D16: =IF($C$2=2026,D$77,IF($C$2=2030,D$113,"")) -> 8344.5398 | E16: =IF($C$2=2026,E$77,IF($C$2=2030,E$113,"")) -> 8344.5398 | F16: =IF($C$2=2026,F$77,IF($C$2=2030,F$113,"")) -> 8364.6877 | G16: =IF($C$2=2026,G$77,IF($C$2=2030,G$113,"")) -> 8373.6227 | L16: MFO {0.5, 0.6, 0.8}
B17: Non-new students | C17: =IF($C$2=2026,C$78,IF($C$2=2030,C$114,C$78)) -> 405.8 | D17: =IF($C$2=2026,D$78,IF($C$2=2030,D$114,D$78)) -> 553 | E17: =IF($C$2=2026,E$78,IF($C$2=2030,E$114,E$78)) -> 553 | F17: =IF($C$2=2026,F$78,IF($C$2=2030,F$114,F$78)) -> 450.2 | G17: =IF($C$2=2026,G$78,IF($C$2=2030,G$114,G$78)) -> 508.31667 | L17: Uplift ±10%
B18: Total variable gross cost of non-new students | C18: =IF($C$2=2026,C$79,IF($C$2=2030,C$115,C$79)) -> 3410084.8 | D18: =IF($C$2=2026,D$79,IF($C$2=2030,D$115,D$79)) -> 4614530.5 | E18: =IF($C$2=2026,E$79,IF($C$2=2030,E$115,E$79)) -> 4614530.5 | F18: =IF($C$2=2026,F$79,IF($C$2=2030,F$115,F$79)) -> 3765782.4 | G18: =IF($C$2=2026,G$79,IF($C$2=2030,G$115,G$79)) -> 4256452 | L18: After discounting estimated fixed, adjusting for inflation
B19: New students | C19: =IF($C$2=2026,C$80,IF($C$2=2030,C$116,C$80)) -> 0 | D19: =IF($C$2=2026,D$80,IF($C$2=2030,D$116,D$80)) -> 0 | E19: =IF($C$2=2026,E$80,IF($C$2=2030,E$116,E$80)) -> 50 | F19: =IF($C$2=2026,F$80,IF($C$2=2030,F$116,F$80)) -> 16.666667 | G19: =IF($C$2=2026,G$80,IF($C$2=2030,G$116,G$80)) -> 17
B20: Marginal variable cost to add new students | C20: =IF($C$2=2026,C$81,IF($C$2=2030,C$117,C$81)) -> 0.6 | D20: =IF($C$2=2026,D$81,IF($C$2=2030,D$117,D$81)) -> 0.6 | E20: =IF($C$2=2026,E$81,IF($C$2=2030,E$117,E$81)) -> 0.6 | F20: =IF($C$2=2026,F$81,IF($C$2=2030,F$117,F$81)) -> 0.6 | G20: =IF($C$2=2026,G$81,IF($C$2=2030,G$117,G$81)) -> 0.6 | J20: ** | L20: Estimated proportion of full cost
B21: Variable gross M&O / new student | C21: =IF($C$2=2026,C$82,IF($C$2=2030,C$118,C$82)) -> 5042.018 | D21: =IF($C$2=2026,D$82,IF($C$2=2030,D$118,D$82)) -> 5006.7239 | E21: =IF($C$2=2026,E$82,IF($C$2=2030,E$118,E$82)) -> 5006.7239 | F21: =IF($C$2=2026,F$82,IF($C$2=2030,F$118,F$82)) -> 5018.8126 | G21: =IF($C$2=2026,G$82,IF($C$2=2030,G$118,G$82)) -> 5024.1736 | L21: M&O = Maintenance & Operations cost
B22: Incremental overhead per new student | C22: =IF($C$2=2026,C$83,IF($C$2=2030,C$119,C$83)) -> $200/student | D22: =IF($C$2=2026,D$83,IF($C$2=2030,D$119,D$83)) -> $200/student | E22: =IF($C$2=2026,E$83,IF($C$2=2030,E$119,E$83)) -> $200/student | F22: =IF($C$2=2026,F$83,IF($C$2=2030,F$119,F$83)) -> $200/student | G22: =IF($C$2=2026,G$83,IF($C$2=2030,G$119,G$83)) -> $200/student | L22: Estimted in model as proportion of repurpose transition cost
B23: Per new student cost (m + routing) | C23: =IF($C$2=2026,C$84,IF($C$2=2030,C$120,"")) -> 5206.7239 | D23: =IF($C$2=2026,D$84,IF($C$2=2030,D$120,"")) -> 5206.7239 | E23: =IF($C$2=2026,E$84,IF($C$2=2030,E$120,"")) -> 5206.7239 | F23: =IF($C$2=2026,F$84,IF($C$2=2030,F$120,"")) -> 5206.7239 | G23: =IF($C$2=2026,G$84,IF($C$2=2030,G$120,"")) -> 5206.7239
B24: Total variable gross cost of new students | C24: =IF($C$2=2026,C$85,IF($C$2=2030,C$121,C$85)) -> N/A | D24: =IF($C$2=2026,D$85,IF($C$2=2030,D$121,D$85)) -> N/A | E24: =IF($C$2=2026,E$85,IF($C$2=2030,E$121,E$85)) -> 260336.19 | F24: =IF($C$2=2026,F$85,IF($C$2=2030,F$121,F$85)) -> 86778.731 | G24: =IF($C$2=2026,G$85,IF($C$2=2030,G$121,G$85)) -> 88514.306
B25: Total variable gross M&O cost | C25: =IF($C$2=2026,C$86,IF($C$2=2030,C$122,C$86)) -> 3399995 | D25: =IF($C$2=2026,D$86,IF($C$2=2030,D$122,D$86)) -> 4601077.4 | E25: =IF($C$2=2026,E$86,IF($C$2=2030,E$122,E$86)) -> 5018304.4 | F25: =IF($C$2=2026,F$86,IF($C$2=2030,F$122,F$86)) -> 3896570.9 | G25: =IF($C$2=2026,G$86,IF($C$2=2030,G$122,G$86)) -> 4390452.5
B26: Transition cost (routing, transportation, etc.) FY26 | C26: =IF($C$2=2026,C$87,IF($C$2=2030,C$123,C$87)) -> $1000/student | D26: =IF($C$2=2026,D$87,IF($C$2=2030,D$123,D$87)) -> N/A | E26: =IF($C$2=2026,E$87,IF($C$2=2030,E$123,E$87)) -> N/A | F26: =IF($C$2=2026,F$87,IF($C$2=2030,F$123,F$87)) -> $1000/student | G26: =IF($C$2=2026,G$87,IF($C$2=2030,G$123,G$87)) -> $1000/student | J26: ** | L26: Assuming adjustments in routing or other transportation investment needed for students displaced from repurpose; tapers over time
B27: Routing/Admin cost FYxx (h) | C27: =IF($C$2=2026,C$88,IF($C$2=2030,C$124,"")) -> 405800 | D27: =IF($C$2=2026,D$88,IF($C$2=2030,D$124,"")) -> 0 | E27: =IF($C$2=2026,E$88,IF($C$2=2030,E$124,"")) -> 0 | F27: =IF($C$2=2026,F$88,IF($C$2=2030,F$124,"")) -> 154200 | G27: =IF($C$2=2026,G$88,IF($C$2=2030,G$124,"")) -> 251316.67
B28: Total gross M&O + transition cost | C28: =IF($C$2=2026,C$89,IF($C$2=2030,C$125,C$89)) -> 3805795 | D28: =IF($C$2=2026,D$89,IF($C$2=2030,D$125,D$89)) -> 4601077.4 | E28: =IF($C$2=2026,E$89,IF($C$2=2030,E$125,E$89)) -> 5018304.4 | F28: =IF($C$2=2026,F$89,IF($C$2=2030,F$125,F$89)) -> 4050770.9 | G28: =IF($C$2=2026,G$89,IF($C$2=2030,G$125,G$89)) -> 4641769.2
B29: Base open site fixed total | C29: =IF($C$2=2026,C$90,IF($C$2=2030,C$126,C$90)) -> 1921875 | D29: =IF($C$2=2026,D$90,IF($C$2=2030,D$126,D$90)) -> 1921875 | E29: =IF($C$2=2026,E$90,IF($C$2=2030,E$126,E$90)) -> 1921875 | F29: =IF($C$2=2026,F$90,IF($C$2=2030,F$126,F$90)) -> 1921875 | G29: =IF($C$2=2026,G$90,IF($C$2=2030,G$126,G$90)) -> 1921875 | J29: *
B30: Estimated repurpose site fixed cost carry ratio | C30: =IF($C$2=2026,C$91,IF($C$2=2030,C$127,C$91)) -> 0.2 | D30: =IF($C$2=2026,D$91,IF($C$2=2030,D$127,D$91)) -> N/A | E30: =IF($C$2=2026,E$91,IF($C$2=2030,E$127,E$91)) -> N/A | F30: =IF($C$2=2026,F$91,IF($C$2=2030,F$127,F$91)) -> 0.2 | G30: =IF($C$2=2026,G$91,IF($C$2=2030,G$127,G$91)) -> 0.2 | J30: **
B31: Fixed M&O (net) | C31: =IF($C$2=2026,C$92,IF($C$2=2030,C$128,"")) -> 1441406.2 | D31: =IF($C$2=2026,D$92,IF($C$2=2030,D$128,"")) -> 1921875 | E31: =IF($C$2=2026,E$92,IF($C$2=2030,E$128,"")) -> 1921875 | F31: =IF($C$2=2026,F$92,IF($C$2=2030,F$128,"")) -> 1183875 | G31: =IF($C$2=2026,G$92,IF($C$2=2030,G$128,"")) -> 1122375
B32: Net total cost | C32: =IF($C$2=2026,C$93,IF($C$2=2030,C$129,C$93)) -> 5247201.2 | D32: =IF($C$2=2026,D$93,IF($C$2=2030,D$129,D$93)) -> 6522952.4 | E32: =IF($C$2=2026,E$93,IF($C$2=2030,E$129,E$93)) -> 6940179.4 | F32: =IF($C$2=2026,F$93,IF($C$2=2030,F$129,F$93)) -> 5234645.9 | G32: =IF($C$2=2026,G$93,IF($C$2=2030,G$129,G$93)) -> 5764144.2
B33: Net operating $ FY26 | C33: =IF($C$2=2026,C$94,IF($C$2=2030,C$130,C$94)) -> -797624.54 | D33: =IF($C$2=2026,D$94,IF($C$2=2030,D$130,D$94)) -> -459335.03 | E33: =IF($C$2=2026,E$94,IF($C$2=2030,E$130,E$94)) -> -210423.72 | F33: =IF($C$2=2026,F$94,IF($C$2=2030,F$130,F$94)) -> -76179.355 | G33: =IF($C$2=2026,G$94,IF($C$2=2030,G$130,G$94)) -> 36009.647
B36: FY26 Capital investment | C36: =IF($C$2=2026,C$97,IF($C$2=2030,C$133,C$97)) -> 2714480 | D36: =IF($C$2=2026,D$97,IF($C$2=2030,D$133,D$97)) -> 0 | E36: =IF($C$2=2026,E$97,IF($C$2=2030,E$133,E$97)) -> 1800000 | F36: =IF($C$2=2026,F$97,IF($C$2=2030,F$133,F$97)) -> 1600000 | G36: =IF($C$2=2026,G$97,IF($C$2=2030,G$133,G$97)) -> 1600000
B41: (Check-MultiYear_Proforma) Net operating $ / year | C41: =IF($C$2=2026,MultiYear_ProForma!$AF$32,IF($C$2=2030,MultiYear_ProForma!$AF$36,"")) -> -797624.54 | D41: =IF($C$2=2026,MultiYear_ProForma!$AF$62,IF($C$2=2030,MultiYear_ProForma!$AF$66,"")) -> -459335.03 | E41: =IF($C$2=2026,MultiYear_ProForma!$AF$17,IF($C$2=2030,MultiYear_ProForma!$AF$21,"")) -> -210423.72 | F41: =IF($C$2=2026,MultiYear_ProForma!$AF$42,IF($C$2=2030,MultiYear_ProForma!$AF$46,"")) -> -76179.355 | G41: =IF($C$2=2026,MultiYear_ProForma!$AF$52,IF($C$2=2030,MultiYear_ProForma!$AF$56,"")) -> 36009.647
B42: Difference in MYP net vs. Dashboard net | C42: =C41-C33 -> 0 | D42: =D41-D33 -> 0 | E42: =E41-E33 -> 0 | F42: =F41-F33 -> 0 | G42: =G41-G33 -> 0
B43: % difference in MYP net vs. Dashboard net | C43: =C42/C41 -> 0 | D43: =D42/D41 -> 0 | E43: =E42/E41 -> 0 | F43: =F42/F41 -> 0 | G43: =G42/G41 -> 0
B65: FY2026 | C65: A2 | D65: E1 | E65: D1 | F65: B2 | G65: C2
C66: Scenario A (Repurpose Both Lease) | D66: Scenario E (Continued Decline) | E66: Scenario D (Grow Both) | F66: Scenario B (Repurpose Echo Lease; Grow Pima) | G66: Scenario C (Repurpose Pima Lease; Grow Echo) | J66: Source / Confidence Level | K66: Model sensitivity | L66: Note
B67: Baseline ADM Echo | C67: =Parameters_Public!$C$10 -> 257 | D67: =Parameters_Public!$C$10 -> 257 | E67: =Parameters_Public!$C$10 -> 257 | F67: =Parameters_Public!$C$10 -> 257 | G67: =Parameters_Public!$C$10 -> 257 | J67: ***
...

Sheet Working_test
B1: FY26 simulated P&L by scenario
C2: Scenario A2 (Repurpose Both Lease) | D2: Scenario D1 (Grow Both) | E2: Scenario E1 (Continued Decline) | F2: Scenario B2 (Repurpose Echo Lease; Grow Pima) | G2: Scenario C2 (Repurpose Pima Lease; Grow Echo) | H2: Source / Confidence Level
B3: Baseline ADM Echo | C3: =Parameters_Public!$C$10 -> 257 | D3: =Parameters_Public!$C$10 -> 257 | E3: =Parameters_Public!$C$10 -> 257 | F3: =Parameters_Public!$C$10 -> 257 | G3: =Parameters_Public!$C$10 -> 257 | H3: ***
B4: Baseline ADM Pima | C4: =Parameters_Public!$C$11 -> 296 | D4: =Parameters_Public!$C$11 -> 296 | E4: =Parameters_Public!$C$11 -> 296 | F4: =Parameters_Public!$C$11 -> 296 | G4: =Parameters_Public!$C$11 -> 296
B5: ADM change FY26 | C5: 0 | D5: =MultiYear_ProForma!$AB$17 -> 50 | E5: 0 | F5: =MultiYear_ProForma!$AB$42 -> 16.666667 | G5: =MultiYear_ProForma!$AB$52 -> 17
B6: r_e (Echo retention ratio) | C6: =Parameters_Public!$C$23 -> 0.6 | D6: ="N/A" -> N/A | E6: ="N/A" -> N/A | F6: =Parameters_Public!$C$23 -> 0.6 | G6: ="N/A" -> N/A | H6: *
B7: r_p (Pima retention ratio) | C7: =Parameters_Public!$C$24 -> 0.85 | D7: ="N/A" -> N/A | E7: ="N/A" -> N/A | F7: N/A | G7: =Parameters_Public!$C$24 -> 0.85 | H7: **
B8: Number of students transitioning | C8: =Parameters_Public!$C$10*Parameters_Public!$C$23+Parameters_Public!$C$11*Parameters_Public!$C$24 -> 405.8 | D8: ="N/A" -> N/A | E8: ="N/A" -> N/A | F8: =Parameters_Public!$C$10*Parameters_Public!$C$23 -> 154.2 | G8: =Parameters_Public!$C$11*Parameters_Public!$C$24 -> 251.6
B9: Students served FY26 | C9: =C8+C5 -> 405.8 | D9: =D5+D4+D3 -> 603 | E9: =E4+E3+E5 -> 553 | F9: =F4+F8+F5 -> 466.86667 | G9: =G8+G3+G5 -> 525.6
B10: Funding/student (base+override; to be conservative, small adjustment down for new students) | C10: =MultiYear_ProForma!$AD$32/Working_test!C9 -> 10964.95 | D10: =MultiYear_ProForma!$AD$17/Working_test!D9 -> 10900.273 | E10: =MultiYear_ProForma!$AD$62/Working_test!E9 -> 10964.95 | F10: =MultiYear_ProForma!$AD$42/Working_test!F9 -> 10937.105 | G10: =MultiYear_ProForma!$AD$52/Working_test!G9 -> 10933.811
B11: Implied total 'revenue' | C11: =C10*C9 -> 4449576.7 | D11: =D10*D9 -> 6572864.9 | E11: =E10*E9 -> 6063617.3 | F11: =F10*F9 -> 5106169.7 | G11: =G10*G9 -> 5746811
B12: Districtwide gross Maintenance & Operations cost per non-new ADM | C12: =Parameters_Public!$C$14 -> 11589 | D12: =Parameters_Public!$C$14 -> 11589 | E12: =Parameters_Public!$C$14 -> 11589 | F12: =Parameters_Public!$C$14 -> 11589 | G12: =Parameters_Public!$C$14 -> 11589
B13: Variable cost / non-new ADM after discounting estimated fixed, adjusting for inflation | C13: =BaselineCalc!$B$18 -> 8403.3633 | D13: =BaselineCalc!$B$18 -> 8403.3633 | E13: =BaselineCalc!$B$18 -> 8403.3633 | F13: =BaselineCalc!$B$18 -> 8403.3633 | G13: =BaselineCalc!$B$18 -> 8403.3633
B14: Non-new students | C14: =C8 -> 405.8 | D14: =D3+D4 -> 553 | E14: =E9 -> 553 | F14: =F3+F4 -> 553 | G14: =G3+G4 -> 553
B15: Implied total variable gross cost of non-new students | C15: =C14*C13 -> 3410084.8 | D15: =D14*D13 -> 4647059.9 | E15: =E14*E13 -> 4647059.9 | F15: =F14*F13 -> 4647059.9 | G15: =G14*G13 -> 4647059.9
B16: New students | C16: =C5 -> 0 | D16: =D5 -> 50 | E16: =E5 -> 0 | F16: =F5 -> 16.666667 | G16: =G5 -> 17
B17: Marginal variable cost to add new students (as proportion of full cost) | C17: =Parameters_Public!$C$43 -> 0.6 | D17: =Parameters_Public!$C$43 -> 0.6 | E17: =Parameters_Public!$C$43 -> 0.6 | F17: =Parameters_Public!$C$43 -> 0.6 | G17: =Parameters_Public!$C$43 -> 0.6 | H17: **
B18: Implied variable gross M&O / new student | C18: =IFERROR((C13*C17), "N/A") -> 5042.018 | D18: =IFERROR((D13*D17), "N/A") -> 5042.018 | E18: =IFERROR((E13*E17), "N/A") -> 5042.018 | F18: =IFERROR((F13*F17), "N/A") -> 5042.018 | G18: =IFERROR((G13*G17), "N/A") -> 5042.018
B19: Implied total variable gross cost of new students | C19: =IF(C18*C5=0, "N/A", C18*C5) -> N/A | D19: =IF(D18*D5=0, "N/A", D18*D5) -> 252100.9 | E19: =IF(E18*E5=0, "N/A", E18*E5) -> N/A | F19: =IF(F18*F5=0, "N/A", F18*F5) -> 84033.633 | G19: =IF(G18*G5=0, "N/A", G18*G5) -> 85714.306
B20: Total variable gross M&O | C20: =IF(C19="N/A", 0, C19)+C15 -> 3410084.8 | D20: =IF(D19="N/A", 0, D19)+D15 -> 4899160.8 | E20: =IF(E19="N/A", 0, E19)+E15 -> 4647059.9 | F20: =IF(F19="N/A", 0, F19)+F15 -> 4731093.6 | G20: =IF(G19="N/A", 0, G19)+G15 -> 4732774.2
B21: h (Transition cost (routing, transportation, etc.) FY26) | C21: ="$"&YearMap!$E$2&"/student" -> $1000/student | D21: ="N/A" -> N/A | E21: ="N/A" -> N/A | F21: ="$"&YearMap!$E$2&"/student" -> $1000/student | G21: ="$"&YearMap!$E$2&"/student" -> $1000/student | H21: **
B22: Implied total transition cost FY26 | C22: =YearMap!$E$2*C8 -> 405800 | D22: ="N/A" -> N/A | E22: ="N/A" -> N/A | F22: =YearMap!$E$2*F8 -> 154200 | G22: =YearMap!$E$2*G8 -> 251600
B23: Total gross M&O + transition cost | C23: =C20+IF(C22="N/A", 0, C22) -> 3815884.8 | D23: =D20+IF(D22="N/A", 0, D22) -> 4899160.8 | E23: =E20+IF(E22="N/A", 0, E22) -> 4647059.9 | F23: =F20+IF(F22="N/A", 0, F22) -> 4885293.6 | G23: =G20+IF(G22="N/A", 0, G22) -> 4984374.2
B24: Base open site fixed total | C24: =Site_Fixed!$D$10+Site_Fixed!$D$17 -> 1875000 | D24: =Site_Fixed!$D$10+Site_Fixed!$D$17 -> 1875000 | E24: =Site_Fixed!$D$10+Site_Fixed!$D$17 -> 1875000 | F24: =Site_Fixed!$D$10 -> 900000 | G24: =Site_Fixed!$D$17 -> 975000 | H24: *
B25: Estimated repurpose site fixed carry ratio | C25: =YearMap!$F$2 -> 0.2 | D25: ="N/A" -> N/A | E25: ="N/A" -> N/A | F25: =YearMap!$F$2 -> 0.2 | G25: =YearMap!$F$2 -> 0.2 | H25: **
B26: Net fixed total | C26: =IFERROR(C24*(C25), C24) -> 375000 | D26: =IFERROR(D24*(D25), D24) -> 1875000 | E26: =IFERROR(E24*(E25), E24) -> 1875000 | F26: =F24+IFERROR(G24*(F25), G24) -> 1095000 | G26: =F24+IFERROR(F24*(G25), F24) -> 1080000
B27: Net total cost | C27: =C26+C23 -> 4190884.8 | D27: =D26+D23 -> 6774160.8 | E27: =E26+E23 -> 6522059.9 | F27: =F26+F23 -> 5980293.6 | G27: =G26+G23 -> 6064374.2
B28: Net operating $ / year FY26 | C28: =C11-C27 -> 258691.87 | D28: =D11-D27 -> -201295.98 | E28: =E11-E27 -> -458442.58 | F28: =F11-F27 -> -874123.9 | G28: =G11-G27 -> -317563.25
B31: Net cost | C31: =C23-C26 -> 3440884.8
B33: Net operating $ / year FY26 | C33: =MultiYear_ProForma!$AF$32 -> -797624.54 | D33: =MultiYear_ProForma!$AF$17 -> -210423.72 | E33: =MultiYear_ProForma!$AF$62 -> -459335.03 | F33: =MultiYear_ProForma!$AF$42 -> -76179.355 | G33: =MultiYear_ProForma!$AF$52 -> 36009.647
B35: Implied fixed cost savings / student | C35: =IFERROR(C26/C9, 0) -> 924.10054 | D35: =IFERROR(D26/D9, 0) -> 3109.4527 | E35: =IFERROR(E26/E9, 0) -> 3390.5967 | F35: =IFERROR(F26/F9, 0) -> 2345.4234 | G35: =IFERROR(G26/G9, 0) -> 2054.7945
B36: Net cost / student | C36: =C18-C35 -> 4117.9175
B37: Total net cost
B39: FY26 Capital Cost | H39: **
B40: Execution Feasibility | C40: HIGH RISK (Logistics / Community) | D40: HIGH RISK (Marketing / Enrollment) | E40: LOW RISK (Passive) | F40: MEDIUM RISK | G40: MEDIUM RISK | H40: **
B41: Distinctiveness / reputation impact | C41: Very negative | D41: Very positive | E41: Positive | F41: Neutral to positive | G41: Neutral to positive
B42: District financial 'health' impact | C42: Positive | D42: Positive | E42: Negative | F42: Neutral to positive | G42: Neutral to positive
B44: h (Transition cost (routing, transportation, etc.) FY30) | C44: ="$"&YearMap!$E$6&"/student" -> $300/student | D44: ="N/A" -> N/A | E44: ="N/A" -> N/A | F44: ="$"&YearMap!$E$6&"/student" -> $300/student | G44: ="$"&YearMap!$E$6&"/student" -> $300/student
B45: Implied total transition cost FY30 | C45: =YearMap!$E$6*C8 -> 121740 | D45: ="N/A" -> N/A | E45: ="N/A" -> N/A | F45: =YearMap!$E$6*F8 -> 46260 | G45: =YearMap!$E$6*G8 -> 75480
B47: f_lease (Proportion of fixed cost carried FY30) | C47: =YearMap!$F$6 -> 0.1 | D47: ="N/A" -> N/A | E47: ="N/A" -> N/A | F47: =YearMap!$F$6 -> 0.1 | G47: =YearMap!$F$6 -> 0.1 | H47: **
...

Sheet Scenario_Comparison
B1: Echo & Pima — Go-forward scenario comparison view
B3: Scenarios (CHOOSE) | C3: Description | I3: Assumed enrollment change (over 3 yrs)
B4: A2_Repurpose_Both_lease | C4: =VLOOKUP($B4,Scenarios!$A$2:$C$15, 2, 0) -> Repurpose both Echo & Pima; lease both properties; fixed cost reduction rate, retention %, and transition cost assumptions are key drivers | J4: =IF(ROUND(SUMIFS(MultiYear_ProForma!$AC:$AC,MultiYear_ProForma!$B:$B,$B4,MultiYear_ProForma!$C:$C,"FY2030")-BaselineCalc!$B$9, 0)>0, "+"&ROUND(SUMIFS(MultiYear_ProForma!$AC:$AC,MultiYear_ProForma!$B:$B,$B4,MultiYear_ProForma!$C:$C,"FY2030")-BaselineCalc!$B$9, 0), ROUND(SUMIFS(MultiYear_ProForma!$AC:$AC,MultiYear_ProForma!$B:$B,$B4,MultiYear_ProForma!$C:$C,"FY2030")-BaselineCalc!$B$9, 0)) -> -147
B5: B1_StatusQuo_Decline | C5: =VLOOKUP($B5,Scenarios!$A$2:$C$15, 2, 0) -> Echo & Pima open; no operational or strategic growth actions; enrollment decline trend continues | J5: =IF(ROUND(SUMIFS(MultiYear_ProForma!$AC:$AC,MultiYear_ProForma!$B:$B,$B5,MultiYear_ProForma!$C:$C,"FY2030")-BaselineCalc!$B$9, 0)>0, "+"&ROUND(SUMIFS(MultiYear_ProForma!$AC:$AC,MultiYear_ProForma!$B:$B,$B5,MultiYear_ProForma!$C:$C,"FY2030")-BaselineCalc!$B$9, 0), ROUND(SUMIFS(MultiYear_ProForma!$AC:$AC,MultiYear_ProForma!$B:$B,$B5,MultiYear_ProForma!$C:$C,"FY2030")-BaselineCalc!$B$9, 0)) -> -43
B24: Notes: Assumptions reflect: r (retention assumptions), override, marginal factor (e.g. assumed reduced variable cost to add new students), trend flags; h (receiving schools transportation route adjustment premium) tapers yearly. Receiving site should not exceed spare seats + portables
B26: Year | C26: Operating Net$ (Base) | D26: Operating Net$ (Comparator)
B27: FY2026 | C27: =SUMIFS(MultiYear_ProForma!$AF$2:$AF$66, MultiYear_ProForma!$B$2:$B$66, $B$4, MultiYear_ProForma!$C$2:$C$66, "FY2026") -> 252007.49 | D27: =SUMIFS(MultiYear_ProForma!$AF$2:$AF$66, MultiYear_ProForma!$B$2:$B$66, $B$5, MultiYear_ProForma!$C$2:$C$66, "FY2026") -> -459335.03
B28: FY2027 | C28: =SUMIFS(MultiYear_ProForma!$AF$2:$AF$66, MultiYear_ProForma!$B$2:$B$66, $B$4, MultiYear_ProForma!$C$2:$C$66, "FY2027") -> 349612.68 | D28: =SUMIFS(MultiYear_ProForma!$AF$2:$AF$66, MultiYear_ProForma!$B$2:$B$66, $B$5, MultiYear_ProForma!$C$2:$C$66, "FY2027") -> -500524.69
B29: FY2028 | C29: =SUMIFS(MultiYear_ProForma!$AF$2:$AF$66, MultiYear_ProForma!$B$2:$B$66, $B$4, MultiYear_ProForma!$C$2:$C$66, "FY2028") -> 547880.78 | D29: =SUMIFS(MultiYear_ProForma!$AF$2:$AF$66, MultiYear_ProForma!$B$2:$B$66, $B$5, MultiYear_ProForma!$C$2:$C$66, "FY2028") -> -542877.76
B30: FY2029 | C30: =SUMIFS(MultiYear_ProForma!$AF$2:$AF$66, MultiYear_ProForma!$B$2:$B$66, $B$4, MultiYear_ProForma!$C$2:$C$66, "FY2029") -> 711002.88 | D30: =SUMIFS(MultiYear_ProForma!$AF$2:$AF$66, MultiYear_ProForma!$B$2:$B$66, $B$5, MultiYear_ProForma!$C$2:$C$66, "FY2029") -> -586423.94
B31: FY2030 | C31: =SUMIFS(MultiYear_ProForma!$AF$2:$AF$66, MultiYear_ProForma!$B$2:$B$66, $B$4, MultiYear_ProForma!$C$2:$C$66, "FY2030") -> 815010.46 | D31: =SUMIFS(MultiYear_ProForma!$AF$2:$AF$66, MultiYear_ProForma!$B$2:$B$66, $B$5, MultiYear_ProForma!$C$2:$C$66, "FY2030") -> -631193.67
B33: Assumptions (from Parameters_Public / Control_Center)
B34: Retention r (Echo central) | C34: =Parameters_Public!C23 -> 0.6
B35: Retention r (Pima central) | C35: =Parameters_Public!C24 -> 0.85
B36: MarginalFactor_for_Overlay | C36: =Parameters_Public!C43 -> 0.6
B37: Override % | C37: =Parameters_Public!C17 -> 0.15
B38: Override toggle (0/1) | C38: =Parameters_Public!C20 -> 1
B39: Keep-open ops savings (fraction of MO) | C39: =Control_Center!C10 -> 0.007
B40: Extra savings for co-location (fraction of MO) | C40: =Control_Center!C11 -> 0.015
B41: • Routing/admin overhead h tapers by year (see YearMap). Try ±20% sensitivity when routing assumptions are uncertain.
D43: Interpretation
B44: One-time Capital FY 2026 (Base) | C44: =SUMIFS(Capital_Summary!$H$4:$H$83, Capital_Summary!$A$4:$A$83, B4, Capital_Summary!$B$4:$B$83, "FY2026") -> 2314480 | D44: =""&$B$5&" will be $"&TEXT(ROUND(ABS(C45-C44),0), "#,##0")&" "&IF(C45>C44,"MORE COSTLY","LESS COSTLY")&" than "&$B$4&" in terms of capital investment required " -> B1_StatusQuo_Decline will be $2,314,480 LESS COSTLY than A2_Repurpose_Both_lease in terms of capital investment required
B45: One-time Capital FY 2026 (Comparator) | C45: =SUMIFS(Capital_Summary!$H$4:$H$83, Capital_Summary!$A$4:$A$83, B5, Capital_Summary!$B$4:$B$83, "FY2026") -> 0
B47: Avg Net (FY26–30) (Base)—rounded | C47: =ROUND((SUMIFS(MultiYear_ProForma!$AF$2:$AF$66,MultiYear_ProForma!$B$2:$B$66,$B$4,MultiYear_ProForma!$C$2:$C$66,"FY2026")+SUMIFS(MultiYear_ProForma!$AF$2:$AF$66,MultiYear_ProForma!$B$2:$B$66,$B$4,MultiYear_ProForma!$C$2:$C$66,"FY2027")+SUMIFS(MultiYear_ProForma!$AF$2:$AF$66,MultiYear_ProForma!$B$2:$B$66,$B$4,MultiYear_ProForma!$C$2:$C$66,"FY2028")+SUMIFS(MultiYear_ProForma!$AF$2:$AF$66,MultiYear_ProForma!$B$2:$B$66,$B$4,MultiYear_ProForma!$C$2:$C$66,"FY2029")+SUMIFS(MultiYear_ProForma!$AF$2:$AF$66,MultiYear_ProForma!$B$2:$B$66,$B$4,MultiYear_ProForma!$C$2:$C$66,"FY2030"))/5,-4) -> 540000 | D47: ="On average from 2026 through 2030, "&$B$5&" will be $"&TEXT(ABS(ROUND(C49,0)), "#,##0")&" "&IF(C49<0,"MORE COSTLY","LESS COSTLY")&" to operate annually than "&$B$4&"" -> On average from 2026 through 2030, B1_StatusQuo_Decline will be $980,000 MORE COSTLY to operate annually than A2_Repurpose_Both_lease
B48: Avg Net (FY26–30) (Comparator)—rounded | C48: =ROUND((SUMIFS(MultiYear_ProForma!$AF$2:$AF$66, MultiYear_ProForma!$B$2:$B$66, $B$5, MultiYear_ProForma!$C$2:$C$66, "FY2026")+SUMIFS(MultiYear_ProForma!$AF$2:$AF$66, MultiYear_ProForma!$B$2:$B$66, $C$5, MultiYear_ProForma!$C$2:$C$66, "FY2027")+SUMIFS(MultiYear_ProForma!$AF$2:$AF$66, MultiYear_ProForma!$B$2:$B$66, $B$5, MultiYear_ProForma!$C$2:$C$66, "FY2028")+SUMIFS(MultiYear_ProForma!$AF$2:$AF$66, MultiYear_ProForma!$B$2:$B$66, $B$5, MultiYear_ProForma!$C$2:$C$66, "FY2029")+SUMIFS(MultiYear_ProForma!$AF$2:$AF$66, MultiYear_ProForma!$B$2:$B$66, $B$5, MultiYear_ProForma!$C$2:$C$66, "FY2030"))/5, -4) -> -440000
B49: Δ vs Base (Avg FY26–30)—rounded | C49: =ROUND(C48-C47, -4) -> -980000
B52: FY2030 Net (Base)—rounded | C52: =ROUND(SUMIFS(MultiYear_ProForma!$AF$2:$AF$66, MultiYear_ProForma!$B$2:$B$66, $B$4, MultiYear_ProForma!$C$2:$C$66, "FY2030"), -4) -> 820000 | D52: ="By 2030, "&$B$5&" will be $"&TEXT(ABS(ROUND(C54,0)), "#,##0")&" "&IF(C54<0,"MORE COSTLY","LESS COSTLY")&" to operate annually than "&$B$4&"" -> By 2030, B1_StatusQuo_Decline will be $1,450,000 MORE COSTLY to operate annually than A2_Repurpose_Both_lease
B53: FY2030 Net (Comparator)—rounded | C53: =ROUND(SUMIFS(MultiYear_ProForma!$AF$2:$AF$66, MultiYear_ProForma!$B$2:$B$66, $B$5, MultiYear_ProForma!$C$2:$C$66, "FY2030"), -4) -> -630000
B54: Δ vs Base (FY2030)—rounded | C54: =ROUND(C53-C52, -4) -> -1450000
B56: Students displaced (FY26) (Base) | C56: =SUMIFS(MultiYear_ProForma!$N$2:$N$66, MultiYear_ProForma!$B$2:$B$66, $B$4, MultiYear_ProForma!$C$2:$C$66, "FY2026") -> 553 | D56: =""&$B$5&" will displace "&ROUND(ABS(C57-C56),0)&" "&IF(C57>C56,"MORE STUDENTS","FEWER STUDENTS")&" than "&$B$4&"" -> B1_StatusQuo_Decline will displace 553 FEWER STUDENTS than A2_Repurpose_Both_lease
B57: Students displaced (FY26) (Comparator) | C57: =SUMIFS(MultiYear_ProForma!$N$2:$N$66, MultiYear_ProForma!$B$2:$B$66, $B$5, MultiYear_ProForma!$C$2:$C$66, "FY2026") -> 0
B59: Students served (FY2030) (Base) | C59: =SUMIFS(MultiYear_ProForma!$AC$2:$AC$66, MultiYear_ProForma!$B$2:$B$66, $B$4, MultiYear_ProForma!$C$2:$C$66, "FY2030") -> 405.8 | D59: =""&$B$5&" will serve "&ROUND(ABS(C60-C59),0)&" "&IF(C60>C59,"MORE STUDENTS","FEWER STUDENTS")&" than "&$B$4&"" -> B1_StatusQuo_Decline will serve 104 MORE STUDENTS than A2_Repurpose_Both_lease
B60: Students served (FY2030) (Comparator) | C60: =SUMIFS(MultiYear_ProForma!$AC$2:$AC$66, MultiYear_ProForma!$B$2:$B$66, $B$5, MultiYear_ProForma!$C$2:$C$66, "FY2030") -> 510.06959

Sheet Budget_Neutral_Calculator
B1: Budget‑Neutral Calculator (Operating $)
B3: Scenario (Choose one): | C3: D2_Repurpose_Pima_lease_EchoGHub_EchoTargets
B5: Metric | C5: FY2026 | D5: FY2030
B6: mᵗ: Incremental margin per added ADM | C6: =INDEX(YearMap!$I$2:$I$6, MATCH("FY2026",YearMap!$A$2:$A$6,0))+IF(Override_toggle=1, INDEX(YearMap!$O$2:$O$6, MATCH("FY2026",YearMap!$A$2:$A$6,0)),0)+INDEX(YearMap!$P$2:$P$6, MATCH("FY2026",YearMap!$A$2:$A$6,0))-INDEX(YearMap!$B$2:$B$6, MATCH("FY2026",YearMap!$A$2:$A$6,0))-INDEX(YearMap!$Q$2:$Q$6, MATCH("FY2026",YearMap!$A$2:$A$6,0)) -> 1609.6367 | D6: =INDEX(YearMap!$I$2:$I$6, MATCH("FY2030",YearMap!$A$2:$A$6,0))+IF(Override_toggle=1, INDEX(YearMap!$O$2:$O$6, MATCH("FY2030",YearMap!$A$2:$A$6,0)),0)+INDEX(YearMap!$P$2:$P$6, MATCH("FY2030",YearMap!$A$2:$A$6,0))-INDEX(YearMap!$B$2:$B$6, MATCH("FY2030",YearMap!$A$2:$A$6,0))-INDEX(YearMap!$Q$2:$Q$6, MATCH("FY2030",YearMap!$A$2:$A$6,0)) -> 1937.5003
B7: Net (operating) | C7: =SUMIFS(MultiYear_ProForma!$AF$2:$AF$66,MultiYear_ProForma!$B$2:$B$66,$C$3,MultiYear_ProForma!$C$2:$C$66,"FY2026") -> 36009.647 | D7: =SUMIFS(MultiYear_ProForma!$AF$2:$AF$66,MultiYear_ProForma!$B$2:$B$66,$C$3,MultiYear_ProForma!$C$2:$C$66,"FY2030") -> 570325.27
B8: N⁰: Additional students needed for Net ≥ 0 | C8: =IFERROR(MAX(0,-$C$7/$C$6),"") -> 0 | D8: =IFERROR(MAX(0,-$D$7/$D$6),"") -> 0
B10: Interpretation
B11: =IF(D8=0, "The "&C3&" is budget neutral or better given current assumptions in the model; additional enrollment is not necessary.", "Given current assumptions in the model, to be budget neutral by FY2030, the "&C3&" scenario requires enrollment of "&ROUND(D8, 0)&" additional students.") -> The D2_Repurpose_Pima_lease_EchoGHub_EchoTargets is budget neutral or better given current assumptions in the model; additional enrollment is not necessary.
B13: Notes:
B14: This tool tests budget neutrality for any scenario: N⁰ = max(0, −Netₜ / mᵗ).
B15: mᵗ uses YearMap (Aid + Override_if_on + Uplift − VarUnit$ − Growth_overhead). Net excludes capital.

Sheet Summary_Figures
B1: Choose base scenario (for comparison): | C1: E1_StatusQuo_Decline | P1: Chart titles
A2: Net = (M&O operating) − (Aid + Override + Uplift). Capital is excluded. Uplift is indexed to Aid growth. | P2: ="(Comparison) Change in ops net $ by scenario compared to "&C1&" (Positive = savings)" -> (Comparison) Change in ops net $ by scenario compared to E1_StatusQuo_Decline (Positive = savings)
A3: Students: Displaced = FY2026; Served = FY2030 (open + retained). | P3: ="(Nominal) One-time capital (FY26) & Average 5-yr net ops $ by scenario" -> (Nominal) One-time capital (FY26) & Average 5-yr net ops $ by scenario
A4: Scenario key | B4: Scenario | C4: One-time Capital (FY26) | D4: Net FY26 Operational $ | E4: Net FY28 Operational $ | F4: Net FY30 Operational $ | G4: AVG 5-yr net operational $ | H4: 5-yr Operating Net $ (sum FY26-30) | I4: Displaced students | J4: Served students FY30 | K4: Net Op $ / Served (FY2030) | L4: Δ vs Base (FY2030 Net) | M4: Δ vs Base (5-yr Avg Net)
A5: =LEFT(B5, 2) -> F1 | B5: =Scenarios!A3 -> F1_CUSTOM1 | C5: =SUMIFS(Capital_Summary!$H$4:$H$83, Capital_Summary!$A$4:$A$83, B5, Capital_Summary!$B$4:$B$83, "FY2026")*-1 -> 0 | D5: =SUMIFS(MultiYear_ProForma!$AF$2:$AF$66, MultiYear_ProForma!$B$2:$B$66, B5, MultiYear_ProForma!$C$2:$C$66, "FY2026") -> -459335.03 | E5: =SUMIFS(MultiYear_ProForma!$AF$2:$AF$66, MultiYear_ProForma!$B$2:$B$66, B5, MultiYear_ProForma!$C$2:$C$66, "FY2028") -> -482588.87 | F5: =SUMIFS(MultiYear_ProForma!$AF$2:$AF$66, MultiYear_ProForma!$B$2:$B$66, B5, MultiYear_ProForma!$C$2:$C$66, "FY2030") -> -507019.93 | G5: =(SUMIFS(MultiYear_ProForma!$AF$2:$AF$66, MultiYear_ProForma!$B$2:$B$66, B5, MultiYear_ProForma!$C$2:$C$66, "FY2026")+SUMIFS(MultiYear_ProForma!$AF$2:$AF$66, MultiYear_ProForma!$B$2:$B$66, B5, MultiYear_ProForma!$C$2:$C$66, "FY2027")+SUMIFS(MultiYear_ProForma!$AF$2:$AF$66, MultiYear_ProForma!$B$2:$B$66, B5, MultiYear_ProForma!$C$2:$C$66, "FY2028")+SUMIFS(MultiYear_ProForma!$AF$2:$AF$66, MultiYear_ProForma!$B$2:$B$66, B5, MultiYear_ProForma!$C$2:$C$66, "FY2029")+SUMIFS(MultiYear_ProForma!$AF$2:$AF$66, MultiYear_ProForma!$B$2:$B$66, B5, MultiYear_ProForma!$C$2:$C$66, "FY2030"))/5 -> -482883.16 | H5: =(SUMIFS(MultiYear_ProForma!$AF$2:$AF$66, MultiYear_ProForma!$B$2:$B$66, B5, MultiYear_ProForma!$C$2:$C$66, "FY2026")+SUMIFS(MultiYear_ProForma!$AF$2:$AF$66, MultiYear_ProForma!$B$2:$B$66, B5, MultiYear_ProForma!$C$2:$C$66, "FY2027")+SUMIFS(MultiYear_ProForma!$AF$2:$AF$66, MultiYear_ProForma!$B$2:$B$66, B5, MultiYear_ProForma!$C$2:$C$66, "FY2028")+SUMIFS(MultiYear_ProForma!$AF$2:$AF$66, MultiYear_ProForma!$B$2:$B$66, B5, MultiYear_ProForma!$C$2:$C$66, "FY2029")+SUMIFS(MultiYear_ProForma!$AF$2:$AF$66, MultiYear_ProForma!$B$2:$B$66, B5, MultiYear_ProForma!$C$2:$C$66, "FY2030")) -> -2414415.8 | I5: =SUMIFS(MultiYear_ProForma!$N$2:$N$66, MultiYear_ProForma!$B$2:$B$66, B5, MultiYear_ProForma!$C$2:$C$66, "FY2026") -> 0 | J5: =SUMIFS(MultiYear_ProForma!$AC$2:$AC$66, MultiYear_ProForma!$B$2:$B$66, B5, MultiYear_ProForma!$C$2:$C$66, "FY2030") -> 553 | K5: =F5/J5 -> -916.8534 | L5: =F5-(VLOOKUP($C$1,$B$5:$G$17,5, 0)) -> #N/A | M5: =G5-(VLOOKUP($C$1,$B$5:$J$17,6, 0)) -> #N/A
A6: =LEFT(B6, 2) -> B3 | B6: =Scenarios!A4 -> B3_StatusQuo_Targets | C6: =SUMIFS(Capital_Summary!$H$4:$H$83, Capital_Summary!$A$4:$A$83, B6, Capital_Summary!$B$4:$B$83, "FY2026")*-1 -> 0 | D6: =SUMIFS(MultiYear_ProForma!$AF$2:$AF$66, MultiYear_ProForma!$B$2:$B$66, B6, MultiYear_ProForma!$C$2:$C$66, "FY2026") -> -334879.38 | E6: =SUMIFS(MultiYear_ProForma!$AF$2:$AF$66, MultiYear_ProForma!$B$2:$B$66, B6, MultiYear_ProForma!$C$2:$C$66, "FY2028") -> -83560.83 | F6: =SUMIFS(MultiYear_ProForma!$AF$2:$AF$66, MultiYear_ProForma!$B$2:$B$66, B6, MultiYear_ProForma!$C$2:$C$66, "FY2030") -> -82835.472 | G6: =(SUMIFS(MultiYear_ProForma!$AF$2:$AF$66, MultiYear_ProForma!$B$2:$B$66, B6, MultiYear_ProForma!$C$2:$C$66, "FY2026")+SUMIFS(MultiYear_ProForma!$AF$2:$AF$66, MultiYear_ProForma!$B$2:$B$66, B6, MultiYear_ProForma!$C$2:$C$66, "FY2027")+SUMIFS(MultiYear_ProForma!$AF$2:$AF$66, MultiYear_ProForma!$B$2:$B$66, B6, MultiYear_ProForma!$C$2:$C$66, "FY2028")+SUMIFS(MultiYear_ProForma!$AF$2:$AF$66, MultiYear_ProForma!$B$2:$B$66, B6, MultiYear_ProForma!$C$2:$C$66, "FY2029")+SUMIFS(MultiYear_ProForma!$AF$2:$AF$66, MultiYear_ProForma!$B$2:$B$66, B6, MultiYear_ProForma!$C$2:$C$66, "FY2030"))/5 -> -159726.97 | H6: =(SUMIFS(MultiYear_ProForma!$AF$2:$AF$66, MultiYear_ProForma!$B$2:$B$66, B6, MultiYear_ProForma!$C$2:$C$66, "FY2026")+SUMIFS(MultiYear_ProForma!$AF$2:$AF$66, MultiYear_ProForma!$B$2:$B$66, B6, MultiYear_ProForma!$C$2:$C$66, "FY2027")+SUMIFS(MultiYear_ProForma!$AF$2:$AF$66, MultiYear_ProForma!$B$2:$B$66, B6, MultiYear_ProForma!$C$2:$C$66, "FY2028")+SUMIFS(MultiYear_ProForma!$AF$2:$AF$66, MultiYear_ProForma!$B$2:$B$66, B6, MultiYear_ProForma!$C$2:$C$66, "FY2029")+SUMIFS(MultiYear_ProForma!$AF$2:$AF$66, MultiYear_ProForma!$B$2:$B$66, B6, MultiYear_ProForma!$C$2:$C$66, "FY2030")) -> -798634.85 | I6: =SUMIFS(MultiYear_ProForma!$N$2:$N$66, MultiYear_ProForma!$B$2:$B$66, B6, MultiYear_ProForma!$C$2:$C$66, "FY2026") -> 0 | J6: =SUMIFS(MultiYear_ProForma!$AC$2:$AC$66, MultiYear_ProForma!$B$2:$B$66, B6, MultiYear_ProForma!$C$2:$C$66, "FY2030") -> 628 | K6: =F6/J6 -> -131.90362 | L6: =F6-(VLOOKUP($C$1,$B$5:$G$17,5, 0)) -> #N/A | M6: =G6-(VLOOKUP($C$1,$B$5:$J$17,6, 0)) -> #N/A
A7: =LEFT(B7, 2) -> C2 | B7: =Scenarios!A5 -> C2_CoLocation_Echo_Targets | C7: =SUMIFS(Capital_Summary!$H$4:$H$83, Capital_Summary!$A$4:$A$83, B7, Capital_Summary!$B$4:$B$83, "FY2026")*-1 -> 0 | D7: =SUMIFS(MultiYear_ProForma!$AF$2:$AF$66, MultiYear_ProForma!$B$2:$B$66, B7, MultiYear_ProForma!$C$2:$C$66, "FY2026") -> -46044.706 | E7: =SUMIFS(MultiYear_ProForma!$AF$2:$AF$66, MultiYear_ProForma!$B$2:$B$66, B7, MultiYear_ProForma!$C$2:$C$66, "FY2028") -> 139239.14 | F7: =SUMIFS(MultiYear_ProForma!$AF$2:$AF$66, MultiYear_ProForma!$B$2:$B$66, B7, MultiYear_ProForma!$C$2:$C$66, "FY2030") -> 149591.87 | G7: =(SUMIFS(MultiYear_ProForma!$AF$2:$AF$66, MultiYear_ProForma!$B$2:$B$66, B7, MultiYear_ProForma!$C$2:$C$66, "FY2026")+SUMIFS(MultiYear_ProForma!$AF$2:$AF$66, MultiYear_ProForma!$B$2:$B$66, B7, MultiYear_ProForma!$C$2:$C$66, "FY2027")+SUMIFS(MultiYear_ProForma!$AF$2:$AF$66, MultiYear_ProForma!$B$2:$B$66, B7, MultiYear_ProForma!$C$2:$C$66, "FY2028")+SUMIFS(MultiYear_ProForma!$AF$2:$AF$66, MultiYear_ProForma!$B$2:$B$66, B7, MultiYear_ProForma!$C$2:$C$66, "FY2029")+SUMIFS(MultiYear_ProForma!$AF$2:$AF$66, MultiYear_ProForma!$B$2:$B$66, B7, MultiYear_ProForma!$C$2:$C$66, "FY2030"))/5 -> 86056.375 | H7: =(SUMIFS(MultiYear_ProForma!$AF$2:$AF$66, MultiYear_ProForma!$B$2:$B$66, B7, MultiYear_ProForma!$C$2:$C$66, "FY2026")+SUMIFS(MultiYear_ProForma!$AF$2:$AF$66, MultiYear_ProForma!$B$2:$B$66, B7, MultiYear_ProForma!$C$2:$C$66, "FY2027")+SUMIFS(MultiYear_ProForma!$AF$2:$AF$66, MultiYear_ProForma!$B$2:$B$66, B7, MultiYear_ProForma!$C$2:$C$66, "FY2028")+SUMIFS(MultiYear_ProForma!$AF$2:$AF$66, MultiYear_ProForma!$B$2:$B$66, B7, MultiYear_ProForma!$C$2:$C$66, "FY2029")+SUMIFS(MultiYear_ProForma!$AF$2:$AF$66, MultiYear_ProForma!$B$2:$B$66, B7, MultiYear_ProForma!$C$2:$C$66, "FY2030")) -> 430281.87 | I7: =SUMIFS(MultiYear_ProForma!$N$2:$N$66, MultiYear_ProForma!$B$2:$B$66, B7, MultiYear_ProForma!$C$2:$C$66, "FY2026") -> 0 | J7: =SUMIFS(MultiYear_ProForma!$AC$2:$AC$66, MultiYear_ProForma!$B$2:$B$66, B7, MultiYear_ProForma!$C$2:$C$66, "FY2030") -> 603 | K7: =F7/J7 -> 248.07939 | L7: =F7-(VLOOKUP($C$1,$B$5:$G$17,5, 0)) -> #N/A | M7: =G7-(VLOOKUP($C$1,$B$5:$J$17,6, 0)) -> #N/A
A8: =LEFT(B8, 2) -> C1 | B8: =Scenarios!A6 -> C1_Grow_Both_Targets | C8: =SUMIFS(Capital_Summary!$H$4:$H$83, Capital_Summary!$A$4:$A$83, B8, Capital_Summary!$B$4:$B$83, "FY2026")*-1 -> -1800000 | D8: =SUMIFS(MultiYear_ProForma!$AF$2:$AF$66, MultiYear_ProForma!$B$2:$B$66, B8, MultiYear_ProForma!$C$2:$C$66, "FY2026") -> -210423.72 | E8: =SUMIFS(MultiYear_ProForma!$AF$2:$AF$66, MultiYear_ProForma!$B$2:$B$66, B8, MultiYear_ProForma!$C$2:$C$66, "FY2028") -> 315467.21 | F8: =SUMIFS(MultiYear_ProForma!$AF$2:$AF$66, MultiYear_ProForma!$B$2:$B$66, B8, MultiYear_ProForma!$C$2:$C$66, "FY2030") -> 341348.98 | G8: =(SUMIFS(MultiYear_ProForma!$AF$2:$AF$66, MultiYear_ProForma!$B$2:$B$66, B8, MultiYear_ProForma!$C$2:$C$66, "FY2026")+SUMIFS(MultiYear_ProForma!$AF$2:$AF$66, MultiYear_ProForma!$B$2:$B$66, B8, MultiYear_ProForma!$C$2:$C$66, "FY2027")+SUMIFS(MultiYear_ProForma!$AF$2:$AF$66, MultiYear_ProForma!$B$2:$B$66, B8, MultiYear_ProForma!$C$2:$C$66, "FY2028")+SUMIFS(MultiYear_ProForma!$AF$2:$AF$66, MultiYear_ProForma!$B$2:$B$66, B8, MultiYear_ProForma!$C$2:$C$66, "FY2029")+SUMIFS(MultiYear_ProForma!$AF$2:$AF$66, MultiYear_ProForma!$B$2:$B$66, B8, MultiYear_ProForma!$C$2:$C$66, "FY2030"))/5 -> 163429.23 | H8: =(SUMIFS(MultiYear_ProForma!$AF$2:$AF$66, MultiYear_ProForma!$B$2:$B$66, B8, MultiYear_ProForma!$C$2:$C$66, "FY2026")+SUMIFS(MultiYear_ProForma!$AF$2:$AF$66, MultiYear_ProForma!$B$2:$B$66, B8, MultiYear_ProForma!$C$2:$C$66, "FY2027")+SUMIFS(MultiYear_ProForma!$AF$2:$AF$66, MultiYear_ProForma!$B$2:$B$66, B8, MultiYear_ProForma!$C$2:$C$66, "FY2028")+SUMIFS(MultiYear_ProForma!$AF$2:$AF$66, MultiYear_ProForma!$B$2:$B$66, B8, MultiYear_ProForma!$C$2:$C$66, "FY2029")+SUMIFS(MultiYear_ProForma!$AF$2:$AF$66, MultiYear_ProForma!$B$2:$B$66, B8, MultiYear_ProForma!$C$2:$C$66, "FY2030")) -> 817146.13 | I8: =SUMIFS(MultiYear_ProForma!$N$2:$N$66, MultiYear_ProForma!$B$2:$B$66, B8, MultiYear_ProForma!$C$2:$C$66, "FY2026") -> 0 | J8: =SUMIFS(MultiYear_ProForma!$AC$2:$AC$66, MultiYear_ProForma!$B$2:$B$66, B8, MultiYear_ProForma!$C$2:$C$66, "FY2030") -> 703 | K8: =F8/J8 -> 485.56043 | L8: =F8-(VLOOKUP($C$1,$B$5:$G$17,5, 0)) -> #N/A | M8: =G8-(VLOOKUP($C$1,$B$5:$J$17,6, 0)) -> #N/A
A9: =LEFT(B9, 2) -> B2 | B9: =Scenarios!A7 -> B2_StatusQuo_Steady | C9: =SUMIFS(Capital_Summary!$H$4:$H$83, Capital_Summary!$A$4:$A$83, B9, Capital_Summary!$B$4:$B$83, "FY2026")*-1 -> 0 | D9: =SUMIFS(MultiYear_ProForma!$AF$2:$AF$66, MultiYear_ProForma!$B$2:$B$66, B9, MultiYear_ProForma!$C$2:$C$66, "FY2026") -> -459335.03 | E9: =SUMIFS(MultiYear_ProForma!$AF$2:$AF$66, MultiYear_ProForma!$B$2:$B$66, B9, MultiYear_ProForma!$C$2:$C$66, "FY2028") -> -482588.87 | F9: =SUMIFS(MultiYear_ProForma!$AF$2:$AF$66, MultiYear_ProForma!$B$2:$B$66, B9, MultiYear_ProForma!$C$2:$C$66, "FY2030") -> -507019.93 | G9: =(SUMIFS(MultiYear_ProForma!$AF$2:$AF$66, MultiYear_ProForma!$B$2:$B$66, B9, MultiYear_ProForma!$C$2:$C$66, "FY2026")+SUMIFS(MultiYear_ProForma!$AF$2:$AF$66, MultiYear_ProForma!$B$2:$B$66, B9, MultiYear_ProForma!$C$2:$C$66, "FY2027")+SUMIFS(MultiYear_ProForma!$AF$2:$AF$66, MultiYear_ProForma!$B$2:$B$66, B9, MultiYear_ProForma!$C$2:$C$66, "FY2028")+SUMIFS(MultiYear_ProForma!$AF$2:$AF$66, MultiYear_ProForma!$B$2:$B$66, B9, MultiYear_ProForma!$C$2:$C$66, "FY2029")+SUMIFS(MultiYear_ProForma!$AF$2:$AF$66, MultiYear_ProForma!$B$2:$B$66, B9, MultiYear_ProForma!$C$2:$C$66, "FY2030"))/5 -> -482883.16 | H9: =(SUMIFS(MultiYear_ProForma!$AF$2:$AF$66, MultiYear_ProForma!$B$2:$B$66, B9, MultiYear_ProForma!$C$2:$C$66, "FY2026")+SUMIFS(MultiYear_ProForma!$AF$2:$AF$66, MultiYear_ProForma!$B$2:$B$66, B9, MultiYear_ProForma!$C$2:$C$66, "FY2027")+SUMIFS(MultiYear_ProForma!$AF$2:$AF$66, MultiYear_ProForma!$B$2:$B$66, B9, MultiYear_ProForma!$C$2:$C$66, "FY2028")+SUMIFS(MultiYear_ProForma!$AF$2:$AF$66, MultiYear_ProForma!$B$2:$B$66, B9, MultiYear_ProForma!$C$2:$C$66, "FY2029")+SUMIFS(MultiYear_ProForma!$AF$2:$AF$66, MultiYear_ProForma!$B$2:$B$66, B9, MultiYear_ProForma!$C$2:$C$66, "FY2030")) -> -2414415.8 | I9: =SUMIFS(MultiYear_ProForma!$N$2:$N$66, MultiYear_ProForma!$B$2:$B$66, B9, MultiYear_ProForma!$C$2:$C$66, "FY2026") -> 0 | J9: =SUMIFS(MultiYear_ProForma!$AC$2:$AC$66, MultiYear_ProForma!$B$2:$B$66, B9, MultiYear_ProForma!$C$2:$C$66, "FY2030") -> 553 | K9: =F9/J9 -> -916.8534 | L9: =F9-(VLOOKUP($C$1,$B$5:$G$17,5, 0)) -> #N/A | M9: =G9-(VLOOKUP($C$1,$B$5:$J$17,6, 0)) -> #N/A
A10: =LEFT(B10, 2) -> D2 | B10: =Scenarios!A8 -> D2_EchoGHubRamp_PimaTargets | C10: =SUMIFS(Capital_Summary!$H$4:$H$83, Capital_Summary!$A$4:$A$83, B10, Capital_Summary!$B$4:$B$83, "FY2026")*-1 -> -800000 | D10: =SUMIFS(MultiYear_ProForma!$AF$2:$AF$66, MultiYear_ProForma!$B$2:$B$66, B10, MultiYear_ProForma!$C$2:$C$66, "FY2026") -> -251908.94 | E10: =SUMIFS(MultiYear_ProForma!$AF$2:$AF$66, MultiYear_ProForma!$B$2:$B$66, B10, MultiYear_ProForma!$C$2:$C$66, "FY2028") -> 182457.86 | F10: =SUMIFS(MultiYear_ProForma!$AF$2:$AF$66, MultiYear_ProForma!$B$2:$B$66, B10, MultiYear_ProForma!$C$2:$C$66, "FY2030") -> 199954.17 | G10: =(SUMIFS(MultiYear_ProForma!$AF$2:$AF$66, MultiYear_ProForma!$B$2:$B$66, B10, MultiYear_ProForma!$C$2:$C$66, "FY2026")+SUMIFS(MultiYear_ProForma!$AF$2:$AF$66, MultiYear_ProForma!$B$2:$B$66, B10, MultiYear_ProForma!$C$2:$C$66, "FY2027")+SUMIFS(MultiYear_ProForma!$AF$2:$AF$66, MultiYear_ProForma!$B$2:$B$66, B10, MultiYear_ProForma!$C$2:$C$66, "FY2028")+SUMIFS(MultiYear_ProForma!$AF$2:$AF$66, MultiYear_ProForma!$B$2:$B$66, B10, MultiYear_ProForma!$C$2:$C$66, "FY2029")+SUMIFS(MultiYear_ProForma!$AF$2:$AF$66, MultiYear_ProForma!$B$2:$B$66, B10, MultiYear_ProForma!$C$2:$C$66, "FY2030"))/5 -> 55710.494 | H10: =(SUMIFS(MultiYear_ProForma!$AF$2:$AF$66, MultiYear_ProForma!$B$2:$B$66, B10, MultiYear_ProForma!$C$2:$C$66, "FY2026")+SUMIFS(MultiYear_ProForma!$AF$2:$AF$66, MultiYear_ProForma!$B$2:$B$66, B10, MultiYear_ProForma!$C$2:$C$66, "FY2027")+SUMIFS(MultiYear_ProForma!$AF$2:$AF$66, MultiYear_ProForma!$B$2:$B$66, B10, MultiYear_ProForma!$C$2:$C$66, "FY2028")+SUMIFS(MultiYear_ProForma!$AF$2:$AF$66, MultiYear_ProForma!$B$2:$B$66, B10, MultiYear_ProForma!$C$2:$C$66, "FY2029")+SUMIFS(MultiYear_ProForma!$AF$2:$AF$66, MultiYear_ProForma!$B$2:$B$66, B10, MultiYear_ProForma!$C$2:$C$66, "FY2030")) -> 278552.47 | I10: =SUMIFS(MultiYear_ProForma!$N$2:$N$66, MultiYear_ProForma!$B$2:$B$66, B10, MultiYear_ProForma!$C$2:$C$66, "FY2026") -> 0 | J10: =SUMIFS(MultiYear_ProForma!$AC$2:$AC$66, MultiYear_ProForma!$B$2:$B$66, B10, MultiYear_ProForma!$C$2:$C$66, "FY2030") -> 678 | K10: =F10/J10 -> 294.91765 | L10: =F10-(VLOOKUP($C$1,$B$5:$G$17,5, 0)) -> #N/A | M10: =G10-(VLOOKUP($C$1,$B$5:$J$17,6, 0)) -> #N/A
A11: =LEFT(B11, 2) -> A1 | B11: =Scenarios!A9 -> A1_Repurpose_Both_ops | C11: =SUMIFS(Capital_Summary!$H$4:$H$83, Capital_Summary!$A$4:$A$83, B11, Capital_Summary!$B$4:$B$83, "FY2026")*-1 -> -2714480 | D11: =SUMIFS(MultiYear_ProForma!$AF$2:$AF$66, MultiYear_ProForma!$B$2:$B$66, B11, MultiYear_ProForma!$C$2:$C$66, "FY2026") -> -797624.54 | E11: =SUMIFS(MultiYear_ProForma!$AF$2:$AF$66, MultiYear_ProForma!$B$2:$B$66, B11, MultiYear_ProForma!$C$2:$C$66, "FY2028") -> -454637.08 | F11: =SUMIFS(MultiYear_ProForma!$AF$2:$AF$66, MultiYear_ProForma!$B$2:$B$66, B11, MultiYear_ProForma!$C$2:$C$66, "FY2030") -> -238259.88 | G11: =(SUMIFS(MultiYear_ProForma!$AF$2:$AF$66, MultiYear_ProForma!$B$2:$B$66, B11, MultiYear_ProForma!$C$2:$C$66, "FY2026")+SUMIFS(MultiYear_ProForma!$AF$2:$AF$66, MultiYear_ProForma!$B$2:$B$66, B11, MultiYear_ProForma!$C$2:$C$66, "FY2027")+SUMIFS(MultiYear_ProForma!$AF$2:$AF$66, MultiYear_ProForma!$B$2:$B$66, B11, MultiYear_ProForma!$C$2:$C$66, "FY2028")+SUMIFS(MultiYear_ProForma!$AF$2:$AF$66, MultiYear_ProForma!$B$2:$B$66, B11, MultiYear_ProForma!$C$2:$C$66, "FY2029")+SUMIFS(MultiYear_ProForma!$AF$2:$AF$66, MultiYear_ProForma!$B$2:$B$66, B11, MultiYear_ProForma!$C$2:$C$66, "FY2030"))/5 -> -487110.59 | H11: =(SUMIFS(MultiYear_ProForma!$AF$2:$AF$66, MultiYear_ProForma!$B$2:$B$66, B11, MultiYear_ProForma!$C$2:$C$66, "FY2026")+SUMIFS(MultiYear_ProForma!$AF$2:$AF$66, MultiYear_ProForma!$B$2:$B$66, B11, MultiYear_ProForma!$C$2:$C$66, "FY2027")+SUMIFS(MultiYear_ProForma!$AF$2:$AF$66, MultiYear_ProForma!$B$2:$B$66, B11, MultiYear_ProForma!$C$2:$C$66, "FY2028")+SUMIFS(MultiYear_ProForma!$AF$2:$AF$66, MultiYear_ProForma!$B$2:$B$66, B11, MultiYear_ProForma!$C$2:$C$66, "FY2029")+SUMIFS(MultiYear_ProForma!$AF$2:$AF$66, MultiYear_ProForma!$B$2:$B$66, B11, MultiYear_ProForma!$C$2:$C$66, "FY2030")) -> -2435553 | I11: =SUMIFS(MultiYear_ProForma!$N$2:$N$66, MultiYear_ProForma!$B$2:$B$66, B11, MultiYear_ProForma!$C$2:$C$66, "FY2026") -> 553 | J11: =SUMIFS(MultiYear_ProForma!$AC$2:$AC$66, MultiYear_ProForma!$B$2:$B$66, B11, MultiYear_ProForma!$C$2:$C$66, "FY2030") -> 405.8 | K11: =F11/J11 -> -587.13622 | L11: =F11-(VLOOKUP($C$1,$B$5:$G$17,5, 0)) -> #N/A | M11: =G11-(VLOOKUP($C$1,$B$5:$J$17,6, 0)) -> #N/A
A12: =LEFT(B12, 2) -> A2 | B12: =Scenarios!A10 -> A2_Repurpose_Both_lease | C12: =SUMIFS(Capital_Summary!$H$4:$H$83, Capital_Summary!$A$4:$A$83, B12, Capital_Summary!$B$4:$B$83, "FY2026")*-1 -> -2314480 | D12: =SUMIFS(MultiYear_ProForma!$AF$2:$AF$66, MultiYear_ProForma!$B$2:$B$66, B12, MultiYear_ProForma!$C$2:$C$66, "FY2026") -> 252007.49 | E12: =SUMIFS(MultiYear_ProForma!$AF$2:$AF$66, MultiYear_ProForma!$B$2:$B$66, B12, MultiYear_ProForma!$C$2:$C$66, "FY2028") -> 547880.78 | F12: =SUMIFS(MultiYear_ProForma!$AF$2:$AF$66, MultiYear_ProForma!$B$2:$B$66, B12, MultiYear_ProForma!$C$2:$C$66, "FY2030") -> 815010.46 | G12: =(SUMIFS(MultiYear_ProForma!$AF$2:$AF$66, MultiYear_ProForma!$B$2:$B$66, B12, MultiYear_ProForma!$C$2:$C$66, "FY2026")+SUMIFS(MultiYear_ProForma!$AF$2:$AF$66, MultiYear_ProForma!$B$2:$B$66, B12, MultiYear_ProForma!$C$2:$C$66, "FY2027")+SUMIFS(MultiYear_ProForma!$AF$2:$AF$66, MultiYear_ProForma!$B$2:$B$66, B12, MultiYear_ProForma!$C$2:$C$66, "FY2028")+SUMIFS(MultiYear_ProForma!$AF$2:$AF$66, MultiYear_ProForma!$B$2:$B$66, B12, MultiYear_ProForma!$C$2:$C$66, "FY2029")+SUMIFS(MultiYear_ProForma!$AF$2:$AF$66, MultiYear_ProForma!$B$2:$B$66, B12, MultiYear_ProForma!$C$2:$C$66, "FY2030"))/5 -> 535102.86 | H12: =(SUMIFS(MultiYear_ProForma!$AF$2:$AF$66, MultiYear_ProForma!$B$2:$B$66, B12, MultiYear_ProForma!$C$2:$C$66, "FY2026")+SUMIFS(MultiYear_ProForma!$AF$2:$AF$66, MultiYear_ProForma!$B$2:$B$66, B12, MultiYear_ProForma!$C$2:$C$66, "FY2027")+SUMIFS(MultiYear_ProForma!$AF$2:$AF$66, MultiYear_ProForma!$B$2:$B$66, B12, MultiYear_ProForma!$C$2:$C$66, "FY2028")+SUMIFS(MultiYear_ProForma!$AF$2:$AF$66, MultiYear_ProForma!$B$2:$B$66, B12, MultiYear_ProForma!$C$2:$C$66, "FY2029")+SUMIFS(MultiYear_ProForma!$AF$2:$AF$66, MultiYear_ProForma!$B$2:$B$66, B12, MultiYear_ProForma!$C$2:$C$66, "FY2030")) -> 2675514.3 | I12: =SUMIFS(MultiYear_ProForma!$N$2:$N$66, MultiYear_ProForma!$B$2:$B$66, B12, MultiYear_ProForma!$C$2:$C$66, "FY2026") -> 553 | J12: =SUMIFS(MultiYear_ProForma!$AC$2:$AC$66, MultiYear_ProForma!$B$2:$B$66, B12, MultiYear_ProForma!$C$2:$C$66, "FY2030") -> 405.8 | K12: =F12/J12 -> 2008.4043 | L12: =F12-(VLOOKUP($C$1,$B$5:$G$17,5, 0)) -> #N/A | M12: =G12-(VLOOKUP($C$1,$B$5:$J$17,6, 0)) -> #N/A
