Workbook
Name ADM_Day_Select: Parameters_Public!C8
Name Aid_growth: BaselineCalc!B28
Name Base_Aid_per_ADM: Parameters_Public!C18
Name BaseAid_per_ADM: Parameters_Public!C18
Name Capex_ArtsHub: Parameters_Public!C28
Name Capex_in_MO_Toggle: Parameters_Public!C30
Name Capex_InnovHub: Parameters_Public!C29
Name Echo_ADM0: Parameters_Public!C10
Name Echo_ADM0_selected: Parameters_Public!C10
Name Echo_retention_r: Parameters_Public!C23
Name EchoFixed_FY25_Total: Site_Fixed!C8
Name f_lease_profile: Control_Center!$D$23:$H$23
Name f_ops_profile: Control_Center!$D$22:$H$22
Name Growth_overhead_alpha: Parameters_Public!C47
Name h_taper_profile: Control_Center!$C$22:$G$26
Name Incremental_uplift_alpha: Parameters_Public!C49
Name M_O_per_ADM_Audited: Parameters_Public!C14
Name MarginalFactor_for_Overlay: Parameters_Public!C43
Name MO_inflation: Control_Center!C6
Name Override_per_ADM_proxy: Parameters_Public!C19
Name Override_percent: Parameters_Public!C17
Name Override_toggle: Parameters_Public!C20
Name Pima_ADM0: Parameters_Public!C11
Name Pima_ADM0_selected: Parameters_Public!C11
Name Pima_retention_r: Parameters_Public!C24
Name PimaFixed_FY25_Total: Site_Fixed!C15
Name Portable_seat_cost: Parameters_Public!C34
Name TI_in_MO_Toggle: Parameters_Public!C26
Name TI_per_Site: Parameters_Public!C27
Name Uplift_base_per_ADM: Parameters_Public!C21

Sheet Workbook_Purpose_Overview

Sheet How_To_Use_The_Workbook
B1: How to use the workbook
B2: Start on Scenario_Comparison: choose two scenarios to compare; review the operational, capital, and student-related results.
B3: Test assumptions (override switch, retention r, trend flags) only if you would like to check sensitivity.
B4: Check capacity gates (receiving bands).
B5: Open Budget_Neutral_Calculator if you’re considering a non‑repurpose plan: it shows N⁰—how many students are needed to be Net ≥ 0.
B6: Look at Summary_Figures to scan all scenarios with the same signals.
B7: Use Inputs_Definitions_Sources for terms, references, and what’s still awaiting audited paste.
B8: Check What_Is_$900K_Savings if you are curious xxxxxx

Sheet Dashboard
B1: FY26 simulated P&L by scenario
C2: Scenario A2 (Repurpose Both Lease) | D2: Scenario D1 (Grow Both) | E2: Scenario E1 (Continued Decline) | F2: Scenario B2 (Repurpose Echo Lease; Grow Pima) | G2: Scenario C2 (Repurpose Pima Lease; Grow Echo) | H2: Source / Confidence Level
B3: Baseline ADM Echo | C3: =Parameters_Public!$C$10 -> 257 | D3: =Parameters_Public!$C$10 -> 257 | E3: =Parameters_Public!$C$10 -> 257 | F3: =Parameters_Public!$C$10 -> 257 | G3: =Parameters_Public!$C$10 -> 257 | H3: ***
B4: Baseline ADM Pima | C4: =Parameters_Public!$C$11 -> 296 | D4: =Parameters_Public!$C$11 -> 296 | E4: =Parameters_Public!$C$11 -> 296 | F4: =Parameters_Public!$C$11 -> 296 | G4: =Parameters_Public!$C$11 -> 296
B5: ADM change FY26 | C5: 0 | D5: =MultiYear_ProForma!$AB$17 -> 50 | E5: 0 | F5: =MultiYear_ProForma!$AB$42 -> 12.333333 | G5: =MultiYear_ProForma!$AB$52 -> 17
B6: r_e (Echo retention ratio) | C6: =Parameters_Public!$C$23 -> 0.6 | D6: ="N/A" -> N/A | E6: ="N/A" -> N/A | F6: =Parameters_Public!$C$23 -> 0.6 | G6: ="N/A" -> N/A | H6: *
B7: r_p (Pima retention ratio) | C7: =Parameters_Public!$C$24 -> 0.85 | D7: ="N/A" -> N/A | E7: ="N/A" -> N/A | F7: N/A | G7: =Parameters_Public!$C$24 -> 0.85 | H7: **
B8: Number of students transitioning | C8: =Parameters_Public!$C$10*Parameters_Public!$C$23+Parameters_Public!$C$11*Parameters_Public!$C$24 -> 405.8 | D8: ="N/A" -> N/A | E8: ="N/A" -> N/A | F8: =Parameters_Public!$C$10*Parameters_Public!$C$23 -> 154.2 | G8: =Parameters_Public!$C$11*Parameters_Public!$C$24 -> 251.6
B9: Students served FY26 | C9: =C8+C5 -> 405.8 | D9: =D5+D4+D3 -> 603 | E9: =E4+E3+E5 -> 553 | F9: =F4+F8+F5 -> 462.53333 | G9: =G8+G3+G5 -> 525.6
B10: Per‑served revenue ($/ADM) <base+override; to be conservative, small adjustment down for new students> | C10: =MultiYear_ProForma!$AD$32/Dashboard!C9 -> 10964.95 | D10: =MultiYear_ProForma!$AD$17/Dashboard!D9 -> 10900.273 | E10: =MultiYear_ProForma!$AD$62/Dashboard!E9 -> 10964.95 | F10: =MultiYear_ProForma!$AD$42/Dashboard!F9 -> 10944.151 | G10: =MultiYear_ProForma!$AD$52/Dashboard!G9 -> 10933.811
B11: Implied total 'revenue' | C11: =C10*C9 -> 4449576.7 | D11: =D10*D9 -> 6572864.9 | E11: =E10*E9 -> 6063617.3 | F11: =F10*F9 -> 5062034.9 | G11: =G10*G9 -> 5746811
B12: Districtwide gross Maintenance & Operations cost per non-new ADM | C12: =Parameters_Public!$C$14 -> 11589 | D12: =Parameters_Public!$C$14 -> 11589 | E12: =Parameters_Public!$C$14 -> 11589 | F12: =Parameters_Public!$C$14 -> 11589 | G12: =Parameters_Public!$C$14 -> 11589
B13: Variable cost / non-new ADM after discounting estimated fixed, adjusting for inflation | C13: =BaselineCalc!$B$18*(1-BaselineCalc!$B$5) -> 8344.5398 | D13: =BaselineCalc!$B$18*(1-BaselineCalc!$B$5) -> 8344.5398 | E13: =BaselineCalc!$B$18*(1-BaselineCalc!$B$5) -> 8344.5398 | F13: =BaselineCalc!$B$18*(1-BaselineCalc!$B$5) -> 8344.5398 | G13: =BaselineCalc!$B$18*(1-BaselineCalc!$B$5) -> 8344.5398
B14: Non-new students | C14: =MAX(C9 - C5, 0) -> 405.8 | D14: =MAX(D9 - D5, 0) -> 553 | E14: =MAX(E9 - E5, 0) -> 553 | F14: =MAX(F9 - F5, 0) -> 450.2 | G14: =MAX(G9 - G5, 0) -> 508.6
B15: Implied total variable gross cost of non-new students | C15: =C14*C13 -> 3386214.2 | D15: =D14*D13 -> 4614530.5 | E15: =E14*E13 -> 4614530.5 | F15: =F14*F13 -> 3756711.8 | G15: =G14*G13 -> 4244032.9
B16: New students | C16: =C5 -> 0 | D16: =D5 -> 50 | E16: =E5 -> 0 | F16: =F5 -> 12.333333 | G16: =G5 -> 17
B17: Marginal variable cost to add new students (as proportion of full cost) | C17: =Parameters_Public!$C$43 -> 0.6 | D17: =Parameters_Public!$C$43 -> 0.6 | E17: =Parameters_Public!$C$43 -> 0.6 | F17: =Parameters_Public!$C$43 -> 0.6 | G17: =Parameters_Public!$C$43 -> 0.6 | H17: **
B18: Implied variable gross M&O / new student | C18: =IFERROR((C13*C17), "N/A") -> 5006.7239 | D18: =IFERROR((D13*D17), "N/A") -> 5006.7239 | E18: =IFERROR((E13*E17), "N/A") -> 5006.7239 | F18: =IFERROR((F13*F17), "N/A") -> 5006.7239 | G18: =IFERROR((G13*G17), "N/A") -> 5006.7239
B19: Incremental overhead per new student (estiamted as proportion of repurpose transition cost) | C19: ="$"&YearMap!$E$2*Parameters_Public!$C$47&"/student" -> $200/student | D19: ="$"&YearMap!$E$2*Parameters_Public!$C$47&"/student" -> $200/student | E19: ="$"&YearMap!$E$2*Parameters_Public!$C$47&"/student" -> $200/student | F19: ="$"&YearMap!$E$2*Parameters_Public!$C$47&"/student" -> $200/student | G19: ="$"&YearMap!$E$2*Parameters_Public!$C$47&"/student" -> $200/student
B20: Implied variable gross M&O + growth overhead / new student | C20: =C18+YearMap!$E$2*Parameters_Public!$C$47 -> 5206.7239 | D20: =D18+YearMap!$E$2*Parameters_Public!$C$47 -> 5206.7239 | E20: =E18+YearMap!$E$2*Parameters_Public!$C$47 -> 5206.7239 | F20: =F18+YearMap!$E$2*Parameters_Public!$C$47 -> 5206.7239 | G20: =G18+YearMap!$E$2*Parameters_Public!$C$47 -> 5206.7239
B21: Implied total variable gross cost of new students | C21: =IF(C20*C5=0, "N/A", C20*C5) -> N/A | D21: =IF(D20*D5=0, "N/A", D20*D5) -> 260336.19 | E21: =IF(E20*E5=0, "N/A", E20*E5) -> N/A | F21: =IF(F20*F5=0, "N/A", F20*F5) -> 64216.261 | G21: =IF(G20*G5=0, "N/A", G20*G5) -> 88514.306
B22: Total variable gross M&O | C22: =IF(C21="N/A", 0, C21)+C15 -> 3386214.2 | D22: =IF(D21="N/A", 0, D21)+D15 -> 4874866.7 | E22: =IF(E21="N/A", 0, E21)+E15 -> 4614530.5 | F22: =IF(F21="N/A", 0, F21)+F15 -> 3820928.1 | G22: =IF(G21="N/A", 0, G21)+G15 -> 4332547.2
B23: h (Transition cost (routing, transportation, etc.) FY26) | C23: ="$"&YearMap!$E$2&"/student" -> $1000/student | D23: ="N/A" -> N/A | E23: ="N/A" -> N/A | F23: ="$"&YearMap!$E$2&"/student" -> $1000/student | G23: ="$"&YearMap!$E$2&"/student" -> $1000/student | H23: **
B24: Implied total transition cost FY26 | C24: =YearMap!$E$2*C8 -> 405800 | D24: ="N/A" -> N/A | E24: ="N/A" -> N/A | F24: =YearMap!$E$2*F8 -> 154200 | G24: =YearMap!$E$2*G8 -> 251600
B25: Total gross M&O + transition cost | C25: =C22+IF(C24="N/A", 0, C24) -> 3792014.2 | D25: =D22+IF(D24="N/A", 0, D24) -> 4874866.7 | E25: =E22+IF(E24="N/A", 0, E24) -> 4614530.5 | F25: =F22+IF(F24="N/A", 0, F24) -> 3975128.1 | G25: =G22+IF(G24="N/A", 0, G24) -> 4584147.2
B26: Base open site fixed total | C26: =BaselineCalc!$B$19+BaselineCalc!$B$20 -> 1921875 | D26: =BaselineCalc!$B$19+BaselineCalc!$B$20 -> 1921875 | E26: =BaselineCalc!$B$19+BaselineCalc!$B$20 -> 1921875 | F26: =BaselineCalc!$B$20 -> 999375 | G26: =BaselineCalc!$B$19 -> 922500 | H26: *
B27: Estimated repurpose site fixed carry ratio | C27: =YearMap!$F$2 -> 0.2 | D27: ="N/A" -> N/A | E27: ="N/A" -> N/A | F27: =YearMap!$F$2 -> 0.2 | G27: =YearMap!$F$2 -> 0.2 | H27: **
B28: Net fixed total | C28: =IFERROR(C26*(C27), C26) -> 384375 | D28: =IFERROR(D26*(D27), D26) -> 1921875 | E28: =IFERROR(E26*(E27), E26) -> 1921875 | F28: =BaselineCalc!$B$20+IFERROR(BaselineCalc!$B$19*(F27), BaselineCalc!$B$19) -> 1183875 | G28: =BaselineCalc!$B$19+IFERROR(BaselineCalc!$B$20*(F27), BaselineCalc!$B$20) -> 1122375
B29: Net total cost | C29: =C28+C25 -> 4176389.2 | D29: =D28+D25 -> 6796741.7 | E29: =E28+E25 -> 6536405.5 | F29: =F28+F25 -> 5159003.1 | G29: =G28+G25 -> 5706522.2
B30: DASHBOARD CALCULATED Net operating $ / year FY26 | C30: =C11-C29 -> 273187.46 | D30: =D11-D29 -> -223876.85 | E30: =E11-E29 -> -472788.16 | F30: =F11-F29 -> -96968.203 | G30: =G11-G29 -> 40288.74
B33: REAL Net operating $ / year FY26 | C33: =MultiYear_ProForma!$AF$32 -> 252007.49 | D33: =MultiYear_ProForma!$AF$17 -> -210423.72 | E33: =MultiYear_ProForma!$AF$62 -> -459335.03 | F33: =MultiYear_ProForma!$AF$42 -> -97751.668 | G33: =MultiYear_ProForma!$AF$52 -> 36009.647
B35: difference in real net vs. dashboard net | C35: =C33-C30 -> -21179.969 | D35: =D33-D30 -> 13453.125 | E35: =E33-E30 -> 13453.125 | F35: =F33-F30 -> -783.46539 | G35: =G33-G30 -> -4279.0922
B36: %difference in real net vs. dashboard net | C36: =C35/C33 -> -0.084044997 | D36: =D35/D33 -> -0.063933499 | E36: =E35/E33 -> -0.029288263 | F36: =F35/F33 -> 0.0080148544 | G36: =G35/G33 -> -0.11883183
B38: FY30 simulated P&L by scenario
B40: Sensitivity analysis

Sheet Working_test
B1: FY26 simulated P&L by scenario
C2: Scenario A2 (Repurpose Both Lease) | D2: Scenario D1 (Grow Both) | E2: Scenario E1 (Continued Decline) | F2: Scenario B2 (Repurpose Echo Lease; Grow Pima) | G2: Scenario C2 (Repurpose Pima Lease; Grow Echo) | H2: Source / Confidence Level
B3: Baseline ADM Echo | C3: =Parameters_Public!$C$10 -> 257 | D3: =Parameters_Public!$C$10 -> 257 | E3: =Parameters_Public!$C$10 -> 257 | F3: =Parameters_Public!$C$10 -> 257 | G3: =Parameters_Public!$C$10 -> 257 | H3: ***
B4: Baseline ADM Pima | C4: =Parameters_Public!$C$11 -> 296 | D4: =Parameters_Public!$C$11 -> 296 | E4: =Parameters_Public!$C$11 -> 296 | F4: =Parameters_Public!$C$11 -> 296 | G4: =Parameters_Public!$C$11 -> 296
B5: ADM change FY26 | C5: 0 | D5: =MultiYear_ProForma!$AB$17 -> 50 | E5: 0 | F5: =MultiYear_ProForma!$AB$42 -> 12.333333 | G5: =MultiYear_ProForma!$AB$52 -> 17
B6: r_e (Echo retention ratio) | C6: =Parameters_Public!$C$23 -> 0.6 | D6: ="N/A" -> N/A | E6: ="N/A" -> N/A | F6: =Parameters_Public!$C$23 -> 0.6 | G6: ="N/A" -> N/A | H6: *
B7: r_p (Pima retention ratio) | C7: =Parameters_Public!$C$24 -> 0.85 | D7: ="N/A" -> N/A | E7: ="N/A" -> N/A | F7: N/A | G7: =Parameters_Public!$C$24 -> 0.85 | H7: **
B8: Number of students transitioning | C8: =Parameters_Public!$C$10*Parameters_Public!$C$23+Parameters_Public!$C$11*Parameters_Public!$C$24 -> 405.8 | D8: ="N/A" -> N/A | E8: ="N/A" -> N/A | F8: =Parameters_Public!$C$10*Parameters_Public!$C$23 -> 154.2 | G8: =Parameters_Public!$C$11*Parameters_Public!$C$24 -> 251.6
B9: Students served FY26 | C9: =C8+C5 -> 405.8 | D9: =D5+D4+D3 -> 603 | E9: =E4+E3+E5 -> 553 | F9: =F4+F8+F5 -> 462.53333 | G9: =G8+G3+G5 -> 525.6
B10: Funding/student (base+override; to be conservative, small adjustment down for new students) | C10: =MultiYear_ProForma!$AD$32/Working_test!C9 -> 10964.95 | D10: =MultiYear_ProForma!$AD$17/Working_test!D9 -> 10900.273 | E10: =MultiYear_ProForma!$AD$62/Working_test!E9 -> 10964.95 | F10: =MultiYear_ProForma!$AD$42/Working_test!F9 -> 10944.151 | G10: =MultiYear_ProForma!$AD$52/Working_test!G9 -> 10933.811
B11: Implied total 'revenue' | C11: =C10*C9 -> 4449576.7 | D11: =D10*D9 -> 6572864.9 | E11: =E10*E9 -> 6063617.3 | F11: =F10*F9 -> 5062034.9 | G11: =G10*G9 -> 5746811
B12: Districtwide gross Maintenance & Operations cost per non-new ADM | C12: =Parameters_Public!$C$14 -> 11589 | D12: =Parameters_Public!$C$14 -> 11589 | E12: =Parameters_Public!$C$14 -> 11589 | F12: =Parameters_Public!$C$14 -> 11589 | G12: =Parameters_Public!$C$14 -> 11589
B13: Variable cost / non-new ADM after discounting estimated fixed, adjusting for inflation | C13: =BaselineCalc!$B$18 -> 8403.3633 | D13: =BaselineCalc!$B$18 -> 8403.3633 | E13: =BaselineCalc!$B$18 -> 8403.3633 | F13: =BaselineCalc!$B$18 -> 8403.3633 | G13: =BaselineCalc!$B$18 -> 8403.3633
B14: Non-new students | C14: =C8 -> 405.8 | D14: =D3+D4 -> 553 | E14: =E9 -> 553 | F14: =F3+F4 -> 553 | G14: =G3+G4 -> 553
B15: Implied total variable gross cost of non-new students | C15: =C14*C13 -> 3410084.8 | D15: =D14*D13 -> 4647059.9 | E15: =E14*E13 -> 4647059.9 | F15: =F14*F13 -> 4647059.9 | G15: =G14*G13 -> 4647059.9
B16: New students | C16: =C5 -> 0 | D16: =D5 -> 50 | E16: =E5 -> 0 | F16: =F5 -> 12.333333 | G16: =G5 -> 17
B17: Marginal variable cost to add new students (as proportion of full cost) | C17: =Parameters_Public!$C$43 -> 0.6 | D17: =Parameters_Public!$C$43 -> 0.6 | E17: =Parameters_Public!$C$43 -> 0.6 | F17: =Parameters_Public!$C$43 -> 0.6 | G17: =Parameters_Public!$C$43 -> 0.6 | H17: **
B18: Implied variable gross M&O / new student | C18: =IFERROR((C13*C17), "N/A") -> 5042.018 | D18: =IFERROR((D13*D17), "N/A") -> 5042.018 | E18: =IFERROR((E13*E17), "N/A") -> 5042.018 | F18: =IFERROR((F13*F17), "N/A") -> 5042.018 | G18: =IFERROR((G13*G17), "N/A") -> 5042.018
B19: Implied total variable gross cost of new students | C19: =IF(C18*C5=0, "N/A", C18*C5) -> N/A | D19: =IF(D18*D5=0, "N/A", D18*D5) -> 252100.9 | E19: =IF(E18*E5=0, "N/A", E18*E5) -> N/A | F19: =IF(F18*F5=0, "N/A", F18*F5) -> 62184.889 | G19: =IF(G18*G5=0, "N/A", G18*G5) -> 85714.306
B20: Total variable gross M&O | C20: =IF(C19="N/A", 0, C19)+C15 -> 3410084.8 | D20: =IF(D19="N/A", 0, D19)+D15 -> 4899160.8 | E20: =IF(E19="N/A", 0, E19)+E15 -> 4647059.9 | F20: =IF(F19="N/A", 0, F19)+F15 -> 4709244.8 | G20: =IF(G19="N/A", 0, G19)+G15 -> 4732774.2
B21: h (Transition cost (routing, transportation, etc.) FY26) | C21: ="$"&YearMap!$E$2&"/student" -> $1000/student | D21: ="N/A" -> N/A | E21: ="N/A" -> N/A | F21: ="$"&YearMap!$E$2&"/student" -> $1000/student | G21: ="$"&YearMap!$E$2&"/student" -> $1000/student | H21: **
B22: Implied total transition cost FY26 | C22: =YearMap!$E$2*C8 -> 405800 | D22: ="N/A" -> N/A | E22: ="N/A" -> N/A | F22: =YearMap!$E$2*F8 -> 154200 | G22: =YearMap!$E$2*G8 -> 251600
B23: Total gross M&O + transition cost | C23: =C20+IF(C22="N/A", 0, C22) -> 3815884.8 | D23: =D20+IF(D22="N/A", 0, D22) -> 4899160.8 | E23: =E20+IF(E22="N/A", 0, E22) -> 4647059.9 | F23: =F20+IF(F22="N/A", 0, F22) -> 4863444.8 | G23: =G20+IF(G22="N/A", 0, G22) -> 4984374.2
B24: Base open site fixed total | C24: =Site_Fixed!$D$10+Site_Fixed!$D$17 -> 1875000 | D24: =Site_Fixed!$D$10+Site_Fixed!$D$17 -> 1875000 | E24: =Site_Fixed!$D$10+Site_Fixed!$D$17 -> 1875000 | F24: =Site_Fixed!$D$10 -> 900000 | G24: =Site_Fixed!$D$17 -> 975000 | H24: *
B25: Estimated repurpose site fixed carry ratio | C25: =YearMap!$F$2 -> 0.2 | D25: ="N/A" -> N/A | E25: ="N/A" -> N/A | F25: =YearMap!$F$2 -> 0.2 | G25: =YearMap!$F$2 -> 0.2 | H25: **
B26: Net fixed total | C26: =IFERROR(C24*(C25), C24) -> 375000 | D26: =IFERROR(D24*(D25), D24) -> 1875000 | E26: =IFERROR(E24*(E25), E24) -> 1875000 | F26: =F24+IFERROR(G24*(F25), G24) -> 1095000 | G26: =F24+IFERROR(F24*(G25), F24) -> 1080000
B27: Net total cost | C27: =C26+C23 -> 4190884.8 | D27: =D26+D23 -> 6774160.8 | E27: =E26+E23 -> 6522059.9 | F27: =F26+F23 -> 5958444.8 | G27: =G26+G23 -> 6064374.2
B28: Net operating $ / year FY26 | C28: =C11-C27 -> 258691.87 | D28: =D11-D27 -> -201295.98 | E28: =E11-E27 -> -458442.58 | F28: =F11-F27 -> -896409.94 | G28: =G11-G27 -> -317563.25
B31: Net cost | C31: =C23-C26 -> 3440884.8
B33: Net operating $ / year FY26 | C33: =MultiYear_ProForma!$AF$32 -> 252007.49 | D33: =MultiYear_ProForma!$AF$17 -> -210423.72 | E33: =MultiYear_ProForma!$AF$62 -> -459335.03 | F33: =MultiYear_ProForma!$AF$42 -> -97751.668 | G33: =MultiYear_ProForma!$AF$52 -> 36009.647
B35: Implied fixed cost savings / student | C35: =IFERROR(C26/C9, 0) -> 924.10054 | D35: =IFERROR(D26/D9, 0) -> 3109.4527 | E35: =IFERROR(E26/E9, 0) -> 3390.5967 | F35: =IFERROR(F26/F9, 0) -> 2367.3969 | G35: =IFERROR(G26/G9, 0) -> 2054.7945
B36: Net cost / student | C36: =C18-C35 -> 4117.9175
B37: Total net cost
B39: FY26 Capital Cost | H39: **
B40: Execution Feasibility | C40: HIGH RISK (Logistics / Community) | D40: HIGH RISK (Marketing / Enrollment) | E40: LOW RISK (Passive) | F40: MEDIUM RISK | G40: MEDIUM RISK | H40: **
B41: Distinctiveness / reputation impact | C41: Very negative | D41: Very positive | E41: Positive | F41: Neutral to positive | G41: Neutral to positive
B42: District financial 'health' impact | C42: Positive | D42: Positive | E42: Negative | F42: Neutral to positive | G42: Neutral to positive
B44: h (Transition cost (routing, transportation, etc.) FY30) | C44: ="$"&YearMap!$E$6&"/student" -> $300/student | D44: ="N/A" -> N/A | E44: ="N/A" -> N/A | F44: ="$"&YearMap!$E$6&"/student" -> $300/student | G44: ="$"&YearMap!$E$6&"/student" -> $300/student
B45: Implied total transition cost FY30 | C45: =YearMap!$E$6*C8 -> 121740 | D45: ="N/A" -> N/A | E45: ="N/A" -> N/A | F45: =YearMap!$E$6*F8 -> 46260 | G45: =YearMap!$E$6*G8 -> 75480
B47: f_lease (Proportion of fixed cost carried FY30) | C47: =YearMap!$F$6 -> 0.1 | D47: ="N/A" -> N/A | E47: ="N/A" -> N/A | F47: =YearMap!$F$6 -> 0.1 | G47: =YearMap!$F$6 -> 0.1 | H47: **
...

Sheet Scenario_Comparison
B1: Echo & Pima — Go-forward scenario comparison view
B3: Scenarios (CHOOSE) | C3: Description | I3: Assumed enrollment change (over 3 yrs)
B4: A2_Repurpose_Both_lease | C4: =VLOOKUP($B4,Scenarios!$A$2:$C$15, 2, 0) -> Repurpose both Echo & Pima; lease both properties; fixed cost reduction rate, retention %, and transition cost assumptions are key drivers | J4: =IF(ROUND(SUMIFS(MultiYear_ProForma!$AC:$AC,MultiYear_ProForma!$B:$B,$B4,MultiYear_ProForma!$C:$C,"FY2030")-BaselineCalc!$B$9, 0)>0, "+"&ROUND(SUMIFS(MultiYear_ProForma!$AC:$AC,MultiYear_ProForma!$B:$B,$B4,MultiYear_ProForma!$C:$C,"FY2030")-BaselineCalc!$B$9, 0), ROUND(SUMIFS(MultiYear_ProForma!$AC:$AC,MultiYear_ProForma!$B:$B,$B4,MultiYear_ProForma!$C:$C,"FY2030")-BaselineCalc!$B$9, 0)) -> -147
B5: E1_StatusQuo_Decline | C5: =VLOOKUP($B5,Scenarios!$A$2:$C$15, 2, 0) -> Echo & Pima open; no operational or strategic growth actions; enrollment decline trend continues | J5: =IF(ROUND(SUMIFS(MultiYear_ProForma!$AC:$AC,MultiYear_ProForma!$B:$B,$B5,MultiYear_ProForma!$C:$C,"FY2030")-BaselineCalc!$B$9, 0)>0, "+"&ROUND(SUMIFS(MultiYear_ProForma!$AC:$AC,MultiYear_ProForma!$B:$B,$B5,MultiYear_ProForma!$C:$C,"FY2030")-BaselineCalc!$B$9, 0), ROUND(SUMIFS(MultiYear_ProForma!$AC:$AC,MultiYear_ProForma!$B:$B,$B5,MultiYear_ProForma!$C:$C,"FY2030")-BaselineCalc!$B$9, 0)) -> -43
B24: Notes: Assumptions reflect: r (retention assumptions), override, marginal factor (e.g. assumed reduced variable cost to add new students), trend flags; h (receiving schools transportation route adjustment premium) tapers yearly. Receiving site should not exceed spare seats + portables
B26: Year | C26: Operating Net$ (Base) | D26: Operating Net$ (Comparator)
B27: FY2026 | C27: =SUMIFS(MultiYear_ProForma!$AF$2:$AF$66, MultiYear_ProForma!$B$2:$B$66, $B$4, MultiYear_ProForma!$C$2:$C$66, "FY2026") -> 252007.49 | D27: =SUMIFS(MultiYear_ProForma!$AF$2:$AF$66, MultiYear_ProForma!$B$2:$B$66, $B$5, MultiYear_ProForma!$C$2:$C$66, "FY2026") -> -459335.03
B28: FY2027 | C28: =SUMIFS(MultiYear_ProForma!$AF$2:$AF$66, MultiYear_ProForma!$B$2:$B$66, $B$4, MultiYear_ProForma!$C$2:$C$66, "FY2027") -> 349612.68 | D28: =SUMIFS(MultiYear_ProForma!$AF$2:$AF$66, MultiYear_ProForma!$B$2:$B$66, $B$5, MultiYear_ProForma!$C$2:$C$66, "FY2027") -> -500524.69
B29: FY2028 | C29: =SUMIFS(MultiYear_ProForma!$AF$2:$AF$66, MultiYear_ProForma!$B$2:$B$66, $B$4, MultiYear_ProForma!$C$2:$C$66, "FY2028") -> 547880.78 | D29: =SUMIFS(MultiYear_ProForma!$AF$2:$AF$66, MultiYear_ProForma!$B$2:$B$66, $B$5, MultiYear_ProForma!$C$2:$C$66, "FY2028") -> -542877.76
B30: FY2029 | C30: =SUMIFS(MultiYear_ProForma!$AF$2:$AF$66, MultiYear_ProForma!$B$2:$B$66, $B$4, MultiYear_ProForma!$C$2:$C$66, "FY2029") -> 711002.88 | D30: =SUMIFS(MultiYear_ProForma!$AF$2:$AF$66, MultiYear_ProForma!$B$2:$B$66, $B$5, MultiYear_ProForma!$C$2:$C$66, "FY2029") -> -586423.94
B31: FY2030 | C31: =SUMIFS(MultiYear_ProForma!$AF$2:$AF$66, MultiYear_ProForma!$B$2:$B$66, $B$4, MultiYear_ProForma!$C$2:$C$66, "FY2030") -> 815010.46 | D31: =SUMIFS(MultiYear_ProForma!$AF$2:$AF$66, MultiYear_ProForma!$B$2:$B$66, $B$5, MultiYear_ProForma!$C$2:$C$66, "FY2030") -> -631193.67
B33: Assumptions (from Parameters_Public / Control_Center)
B34: Retention r (Echo central) | C34: =Parameters_Public!C23 -> 0.6
B35: Retention r (Pima central) | C35: =Parameters_Public!C24 -> 0.85
B36: MarginalFactor_for_Overlay | C36: =Parameters_Public!C43 -> 0.6
B37: Override % | C37: =Parameters_Public!C17 -> 0.15
B38: Override toggle (0/1) | C38: =Parameters_Public!C20 -> 1
B39: Keep-open ops savings (fraction of MO) | C39: =Control_Center!C10 -> 0.007
B40: Extra savings for co-location (fraction of MO) | C40: =Control_Center!C11 -> 0.015
B41: • Routing/admin overhead h tapers by year (see YearMap). Try ±20% sensitivity when routing assumptions are uncertain.
D43: Interpretation
B44: One-time Capital FY 2026 (Base) | C44: =SUMIFS(Capital_Summary!$H$4:$H$83, Capital_Summary!$A$4:$A$83, B4, Capital_Summary!$B$4:$B$83, "FY2026") -> 2314480 | D44: =""&$B$5&" will be $"&TEXT(ROUND(ABS(C45-C44),0), "#,##0")&" "&IF(C45>C44,"MORE COSTLY","LESS COSTLY")&" than "&$B$4&" in terms of capital investment required " -> E1_StatusQuo_Decline will be $2,314,480 LESS COSTLY than A2_Repurpose_Both_lease in terms of capital investment required
B45: One-time Capital FY 2026 (Comparator) | C45: =SUMIFS(Capital_Summary!$H$4:$H$83, Capital_Summary!$A$4:$A$83, B5, Capital_Summary!$B$4:$B$83, "FY2026") -> 0
B47: Avg Net (FY26–30) (Base)—rounded | C47: =ROUND((SUMIFS(MultiYear_ProForma!$AF$2:$AF$66,MultiYear_ProForma!$B$2:$B$66,$B$4,MultiYear_ProForma!$C$2:$C$66,"FY2026")+SUMIFS(MultiYear_ProForma!$AF$2:$AF$66,MultiYear_ProForma!$B$2:$B$66,$B$4,MultiYear_ProForma!$C$2:$C$66,"FY2027")+SUMIFS(MultiYear_ProForma!$AF$2:$AF$66,MultiYear_ProForma!$B$2:$B$66,$B$4,MultiYear_ProForma!$C$2:$C$66,"FY2028")+SUMIFS(MultiYear_ProForma!$AF$2:$AF$66,MultiYear_ProForma!$B$2:$B$66,$B$4,MultiYear_ProForma!$C$2:$C$66,"FY2029")+SUMIFS(MultiYear_ProForma!$AF$2:$AF$66,MultiYear_ProForma!$B$2:$B$66,$B$4,MultiYear_ProForma!$C$2:$C$66,"FY2030"))/5,-4) -> 540000 | D47: ="On average from 2026 through 2030, "&$B$5&" will be $"&TEXT(ABS(ROUND(C49,0)), "#,##0")&" "&IF(C49<0,"MORE COSTLY","LESS COSTLY")&" to operate annually than "&$B$4&"" -> On average from 2026 through 2030, E1_StatusQuo_Decline will be $980,000 MORE COSTLY to operate annually than A2_Repurpose_Both_lease
B48: Avg Net (FY26–30) (Comparator)—rounded | C48: =ROUND((SUMIFS(MultiYear_ProForma!$AF$2:$AF$66, MultiYear_ProForma!$B$2:$B$66, $B$5, MultiYear_ProForma!$C$2:$C$66, "FY2026")+SUMIFS(MultiYear_ProForma!$AF$2:$AF$66, MultiYear_ProForma!$B$2:$B$66, $C$5, MultiYear_ProForma!$C$2:$C$66, "FY2027")+SUMIFS(MultiYear_ProForma!$AF$2:$AF$66, MultiYear_ProForma!$B$2:$B$66, $B$5, MultiYear_ProForma!$C$2:$C$66, "FY2028")+SUMIFS(MultiYear_ProForma!$AF$2:$AF$66, MultiYear_ProForma!$B$2:$B$66, $B$5, MultiYear_ProForma!$C$2:$C$66, "FY2029")+SUMIFS(MultiYear_ProForma!$AF$2:$AF$66, MultiYear_ProForma!$B$2:$B$66, $B$5, MultiYear_ProForma!$C$2:$C$66, "FY2030"))/5, -4) -> -440000
B49: Δ vs Base (Avg FY26–30)—rounded | C49: =ROUND(C48-C47, -4) -> -980000
B52: FY2030 Net (Base)—rounded | C52: =ROUND(SUMIFS(MultiYear_ProForma!$AF$2:$AF$66, MultiYear_ProForma!$B$2:$B$66, $B$4, MultiYear_ProForma!$C$2:$C$66, "FY2030"), -4) -> 820000 | D52: ="By 2030, "&$B$5&" will be $"&TEXT(ABS(ROUND(C54,0)), "#,##0")&" "&IF(C54<0,"MORE COSTLY","LESS COSTLY")&" to operate annually than "&$B$4&"" -> By 2030, E1_StatusQuo_Decline will be $1,450,000 MORE COSTLY to operate annually than A2_Repurpose_Both_lease
B53: FY2030 Net (Comparator)—rounded | C53: =ROUND(SUMIFS(MultiYear_ProForma!$AF$2:$AF$66, MultiYear_ProForma!$B$2:$B$66, $B$5, MultiYear_ProForma!$C$2:$C$66, "FY2030"), -4) -> -630000
B54: Δ vs Base (FY2030)—rounded | C54: =ROUND(C53-C52, -4) -> -1450000
B56: Students displaced (FY26) (Base) | C56: =SUMIFS(MultiYear_ProForma!$N$2:$N$66, MultiYear_ProForma!$B$2:$B$66, $B$4, MultiYear_ProForma!$C$2:$C$66, "FY2026") -> 553 | D56: =""&$B$5&" will displace "&ROUND(ABS(C57-C56),0)&" "&IF(C57>C56,"MORE STUDENTS","FEWER STUDENTS")&" than "&$B$4&"" -> E1_StatusQuo_Decline will displace 553 FEWER STUDENTS than A2_Repurpose_Both_lease
B57: Students displaced (FY26) (Comparator) | C57: =SUMIFS(MultiYear_ProForma!$N$2:$N$66, MultiYear_ProForma!$B$2:$B$66, $B$5, MultiYear_ProForma!$C$2:$C$66, "FY2026") -> 0
B59: Students served (FY2030) (Base) | C59: =SUMIFS(MultiYear_ProForma!$AC$2:$AC$66, MultiYear_ProForma!$B$2:$B$66, $B$4, MultiYear_ProForma!$C$2:$C$66, "FY2030") -> 405.8 | D59: =""&$B$5&" will serve "&ROUND(ABS(C60-C59),0)&" "&IF(C60>C59,"MORE STUDENTS","FEWER STUDENTS")&" than "&$B$4&"" -> E1_StatusQuo_Decline will serve 104 MORE STUDENTS than A2_Repurpose_Both_lease
B60: Students served (FY2030) (Comparator) | C60: =SUMIFS(MultiYear_ProForma!$AC$2:$AC$66, MultiYear_ProForma!$B$2:$B$66, $B$5, MultiYear_ProForma!$C$2:$C$66, "FY2030") -> 510.06959

Sheet Budget_Neutral_Calculator
B1: Budget‑Neutral Calculator (Operating $)
B3: Scenario (Choose one): | C3: E1_StatusQuo_Decline
B5: Metric | C5: FY2026 | D5: FY2030
B6: mᵗ: Incremental margin per added ADM | C6: =INDEX(YearMap!$I$2:$I$6, MATCH("FY2026",YearMap!$A$2:$A$6,0))+IF(Override_toggle=1, INDEX(YearMap!$O$2:$O$6, MATCH("FY2026",YearMap!$A$2:$A$6,0)),0)+INDEX(YearMap!$P$2:$P$6, MATCH("FY2026",YearMap!$A$2:$A$6,0))-INDEX(YearMap!$B$2:$B$6, MATCH("FY2026",YearMap!$A$2:$A$6,0))-INDEX(YearMap!$Q$2:$Q$6, MATCH("FY2026",YearMap!$A$2:$A$6,0)) -> 1609.6367 | D6: =INDEX(YearMap!$I$2:$I$6, MATCH("FY2030",YearMap!$A$2:$A$6,0))+IF(Override_toggle=1, INDEX(YearMap!$O$2:$O$6, MATCH("FY2030",YearMap!$A$2:$A$6,0)),0)+INDEX(YearMap!$P$2:$P$6, MATCH("FY2030",YearMap!$A$2:$A$6,0))-INDEX(YearMap!$B$2:$B$6, MATCH("FY2030",YearMap!$A$2:$A$6,0))-INDEX(YearMap!$Q$2:$Q$6, MATCH("FY2030",YearMap!$A$2:$A$6,0)) -> 1937.5003
B7: Net (operating) | C7: =SUMIFS(MultiYear_ProForma!$AF$2:$AF$66,MultiYear_ProForma!$B$2:$B$66,$C$3,MultiYear_ProForma!$C$2:$C$66,"FY2026") -> -459335.03 | D7: =SUMIFS(MultiYear_ProForma!$AF$2:$AF$66,MultiYear_ProForma!$B$2:$B$66,$C$3,MultiYear_ProForma!$C$2:$C$66,"FY2030") -> -631193.67
B8: N⁰: Additional students needed for Net ≥ 0 | C8: =IFERROR(MAX(0,-$C$7/$C$6),"") -> 285.36566 | D8: =IFERROR(MAX(0,-$D$7/$D$6),"") -> 325.77733
B10: Interpretation
B11: =IF(D8=0, "The "&C3&" is budget neutral or better given current assumptions in the model; additional enrollment is not necessary.", "Given current assumptions in the model, to be budget neutral by FY2030, the "&C3&" scenario requires enrollment of "&ROUND(D8, 0)&" additional students.") -> Given current assumptions in the model, to be budget neutral by FY2030, the E1_StatusQuo_Decline scenario requires enrollment of 326 additional students.
B13: Notes:
B14: This tool tests budget neutrality for any scenario: N⁰ = max(0, −Netₜ / mᵗ).
B15: mᵗ uses YearMap (Aid + Override_if_on + Uplift − VarUnit$ − Growth_overhead). Net excludes capital.

Sheet Summary_Figures
B1: Choose base scenario (for comparison): | C1: E1_StatusQuo_Decline | N1: Chart titles
A2: Net = (M&O operating) − (Aid + Override + Uplift). Capital is excluded. Uplift is indexed to Aid growth. | N2: ="(Comparison) Change in ops net $ by scenario compared to "&C1&" (Positive = savings)" -> (Comparison) Change in ops net $ by scenario compared to E1_StatusQuo_Decline (Positive = savings)
A3: Students: Displaced = FY2026; Served = FY2030 (open + retained). | N3: ="(Nominal) One-time capital (FY26) & Average 5-yr net ops $ by scenario" -> (Nominal) One-time capital (FY26) & Average 5-yr net ops $ by scenario
A4: Scenario key | B4: Scenario | C4: One-time Capital (FY26) | D4: Net FY26 Operational $ | E4: Net FY28 Operational $ | F4: Net FY30 Operational $ | G4: AVG 5-yr net operational $ | H4: Displaced students | I4: Served students FY30 | J4: Δ vs Base (FY2030 Net) | K4: Δ vs Base (5-yr Avg Net)
A5: =LEFT(B5, 2) -> F1 | B5: F1_CUSTOM1 | C5: =SUMIFS(Capital_Summary!$H$4:$H$83, Capital_Summary!$A$4:$A$83, B5, Capital_Summary!$B$4:$B$83, "FY2026")*-1 -> 0 | D5: =SUMIFS(MultiYear_ProForma!$AF$2:$AF$66, MultiYear_ProForma!$B$2:$B$66, B5, MultiYear_ProForma!$C$2:$C$66, "FY2026") -> -459335.03 | E5: =SUMIFS(MultiYear_ProForma!$AF$2:$AF$66, MultiYear_ProForma!$B$2:$B$66, B5, MultiYear_ProForma!$C$2:$C$66, "FY2028") -> -482588.87 | F5: =SUMIFS(MultiYear_ProForma!$AF$2:$AF$66, MultiYear_ProForma!$B$2:$B$66, B5, MultiYear_ProForma!$C$2:$C$66, "FY2030") -> -507019.93 | G5: =(SUMIFS(MultiYear_ProForma!$AF$2:$AF$66, MultiYear_ProForma!$B$2:$B$66, B5, MultiYear_ProForma!$C$2:$C$66, "FY2026")+SUMIFS(MultiYear_ProForma!$AF$2:$AF$66, MultiYear_ProForma!$B$2:$B$66, B5, MultiYear_ProForma!$C$2:$C$66, "FY2027")+SUMIFS(MultiYear_ProForma!$AF$2:$AF$66, MultiYear_ProForma!$B$2:$B$66, B5, MultiYear_ProForma!$C$2:$C$66, "FY2028")+SUMIFS(MultiYear_ProForma!$AF$2:$AF$66, MultiYear_ProForma!$B$2:$B$66, B5, MultiYear_ProForma!$C$2:$C$66, "FY2029")+SUMIFS(MultiYear_ProForma!$AF$2:$AF$66, MultiYear_ProForma!$B$2:$B$66, B5, MultiYear_ProForma!$C$2:$C$66, "FY2030"))/5 -> -482883.16 | H5: =SUMIFS(MultiYear_ProForma!$N$2:$N$66, MultiYear_ProForma!$B$2:$B$66, B5, MultiYear_ProForma!$C$2:$C$66, "FY2026") -> 0 | I5: =SUMIFS(MultiYear_ProForma!$AC$2:$AC$66, MultiYear_ProForma!$B$2:$B$66, B5, MultiYear_ProForma!$C$2:$C$66, "FY2030") -> 553 | J5: =F5-(VLOOKUP($C$1,$B$5:$G$17,5, 0)) -> 124173.74 | K5: =G5-(VLOOKUP($C$1,$B$5:$I$17,6, 0)) -> 61187.854
A6: =LEFT(B6, 2) -> E3 | B6: E3_StatusQuo_Targets | C6: =SUMIFS(Capital_Summary!$H$4:$H$83, Capital_Summary!$A$4:$A$83, B6, Capital_Summary!$B$4:$B$83, "FY2026")*-1 -> 0 | D6: =SUMIFS(MultiYear_ProForma!$AF$2:$AF$66, MultiYear_ProForma!$B$2:$B$66, B6, MultiYear_ProForma!$C$2:$C$66, "FY2026") -> 0 | E6: =SUMIFS(MultiYear_ProForma!$AF$2:$AF$66, MultiYear_ProForma!$B$2:$B$66, B6, MultiYear_ProForma!$C$2:$C$66, "FY2028") -> 0 | F6: =SUMIFS(MultiYear_ProForma!$AF$2:$AF$66, MultiYear_ProForma!$B$2:$B$66, B6, MultiYear_ProForma!$C$2:$C$66, "FY2030") -> 0 | G6: =(SUMIFS(MultiYear_ProForma!$AF$2:$AF$66, MultiYear_ProForma!$B$2:$B$66, B6, MultiYear_ProForma!$C$2:$C$66, "FY2026")+SUMIFS(MultiYear_ProForma!$AF$2:$AF$66, MultiYear_ProForma!$B$2:$B$66, B6, MultiYear_ProForma!$C$2:$C$66, "FY2027")+SUMIFS(MultiYear_ProForma!$AF$2:$AF$66, MultiYear_ProForma!$B$2:$B$66, B6, MultiYear_ProForma!$C$2:$C$66, "FY2028")+SUMIFS(MultiYear_ProForma!$AF$2:$AF$66, MultiYear_ProForma!$B$2:$B$66, B6, MultiYear_ProForma!$C$2:$C$66, "FY2029")+SUMIFS(MultiYear_ProForma!$AF$2:$AF$66, MultiYear_ProForma!$B$2:$B$66, B6, MultiYear_ProForma!$C$2:$C$66, "FY2030"))/5 -> 0 | H6: =SUMIFS(MultiYear_ProForma!$N$2:$N$66, MultiYear_ProForma!$B$2:$B$66, B6, MultiYear_ProForma!$C$2:$C$66, "FY2026") -> 0 | I6: =SUMIFS(MultiYear_ProForma!$AC$2:$AC$66, MultiYear_ProForma!$B$2:$B$66, B6, MultiYear_ProForma!$C$2:$C$66, "FY2030") -> 0 | J6: =F6-(VLOOKUP($C$1,$B$5:$G$17,5, 0)) -> 631193.67 | K6: =G6-(VLOOKUP($C$1,$B$5:$I$17,6, 0)) -> 544071.02
A7: =LEFT(B7, 2) -> D3 | B7: D3_CoLocation_Echo_Targets | C7: =SUMIFS(Capital_Summary!$H$4:$H$83, Capital_Summary!$A$4:$A$83, B7, Capital_Summary!$B$4:$B$83, "FY2026")*-1 -> 0 | D7: =SUMIFS(MultiYear_ProForma!$AF$2:$AF$66, MultiYear_ProForma!$B$2:$B$66, B7, MultiYear_ProForma!$C$2:$C$66, "FY2026") -> -46044.706 | E7: =SUMIFS(MultiYear_ProForma!$AF$2:$AF$66, MultiYear_ProForma!$B$2:$B$66, B7, MultiYear_ProForma!$C$2:$C$66, "FY2028") -> 139239.14 | F7: =SUMIFS(MultiYear_ProForma!$AF$2:$AF$66, MultiYear_ProForma!$B$2:$B$66, B7, MultiYear_ProForma!$C$2:$C$66, "FY2030") -> 149591.87 | G7: =(SUMIFS(MultiYear_ProForma!$AF$2:$AF$66, MultiYear_ProForma!$B$2:$B$66, B7, MultiYear_ProForma!$C$2:$C$66, "FY2026")+SUMIFS(MultiYear_ProForma!$AF$2:$AF$66, MultiYear_ProForma!$B$2:$B$66, B7, MultiYear_ProForma!$C$2:$C$66, "FY2027")+SUMIFS(MultiYear_ProForma!$AF$2:$AF$66, MultiYear_ProForma!$B$2:$B$66, B7, MultiYear_ProForma!$C$2:$C$66, "FY2028")+SUMIFS(MultiYear_ProForma!$AF$2:$AF$66, MultiYear_ProForma!$B$2:$B$66, B7, MultiYear_ProForma!$C$2:$C$66, "FY2029")+SUMIFS(MultiYear_ProForma!$AF$2:$AF$66, MultiYear_ProForma!$B$2:$B$66, B7, MultiYear_ProForma!$C$2:$C$66, "FY2030"))/5 -> 86056.375 | H7: =SUMIFS(MultiYear_ProForma!$N$2:$N$66, MultiYear_ProForma!$B$2:$B$66, B7, MultiYear_ProForma!$C$2:$C$66, "FY2026") -> 0 | I7: =SUMIFS(MultiYear_ProForma!$AC$2:$AC$66, MultiYear_ProForma!$B$2:$B$66, B7, MultiYear_ProForma!$C$2:$C$66, "FY2030") -> 603 | J7: =F7-(VLOOKUP($C$1,$B$5:$G$17,5, 0)) -> 780785.54 | K7: =G7-(VLOOKUP($C$1,$B$5:$I$17,6, 0)) -> 630127.39
A8: =LEFT(B8, 2) -> D1 | B8: D1_Grow_Both_Targets | C8: =SUMIFS(Capital_Summary!$H$4:$H$83, Capital_Summary!$A$4:$A$83, B8, Capital_Summary!$B$4:$B$83, "FY2026")*-1 -> -2000000 | D8: =SUMIFS(MultiYear_ProForma!$AF$2:$AF$66, MultiYear_ProForma!$B$2:$B$66, B8, MultiYear_ProForma!$C$2:$C$66, "FY2026") -> -210423.72 | E8: =SUMIFS(MultiYear_ProForma!$AF$2:$AF$66, MultiYear_ProForma!$B$2:$B$66, B8, MultiYear_ProForma!$C$2:$C$66, "FY2028") -> 315467.21 | F8: =SUMIFS(MultiYear_ProForma!$AF$2:$AF$66, MultiYear_ProForma!$B$2:$B$66, B8, MultiYear_ProForma!$C$2:$C$66, "FY2030") -> 341348.98 | G8: =(SUMIFS(MultiYear_ProForma!$AF$2:$AF$66, MultiYear_ProForma!$B$2:$B$66, B8, MultiYear_ProForma!$C$2:$C$66, "FY2026")+SUMIFS(MultiYear_ProForma!$AF$2:$AF$66, MultiYear_ProForma!$B$2:$B$66, B8, MultiYear_ProForma!$C$2:$C$66, "FY2027")+SUMIFS(MultiYear_ProForma!$AF$2:$AF$66, MultiYear_ProForma!$B$2:$B$66, B8, MultiYear_ProForma!$C$2:$C$66, "FY2028")+SUMIFS(MultiYear_ProForma!$AF$2:$AF$66, MultiYear_ProForma!$B$2:$B$66, B8, MultiYear_ProForma!$C$2:$C$66, "FY2029")+SUMIFS(MultiYear_ProForma!$AF$2:$AF$66, MultiYear_ProForma!$B$2:$B$66, B8, MultiYear_ProForma!$C$2:$C$66, "FY2030"))/5 -> 163429.23 | H8: =SUMIFS(MultiYear_ProForma!$N$2:$N$66, MultiYear_ProForma!$B$2:$B$66, B8, MultiYear_ProForma!$C$2:$C$66, "FY2026") -> 0 | I8: =SUMIFS(MultiYear_ProForma!$AC$2:$AC$66, MultiYear_ProForma!$B$2:$B$66, B8, MultiYear_ProForma!$C$2:$C$66, "FY2030") -> 703 | J8: =F8-(VLOOKUP($C$1,$B$5:$G$17,5, 0)) -> 972542.65 | K8: =G8-(VLOOKUP($C$1,$B$5:$I$17,6, 0)) -> 707500.24
A9: =LEFT(B9, 2) -> E2 | B9: E2_StatusQuo_Steady | C9: =SUMIFS(Capital_Summary!$H$4:$H$83, Capital_Summary!$A$4:$A$83, B9, Capital_Summary!$B$4:$B$83, "FY2026")*-1 -> 0 | D9: =SUMIFS(MultiYear_ProForma!$AF$2:$AF$66, MultiYear_ProForma!$B$2:$B$66, B9, MultiYear_ProForma!$C$2:$C$66, "FY2026") -> -459335.03 | E9: =SUMIFS(MultiYear_ProForma!$AF$2:$AF$66, MultiYear_ProForma!$B$2:$B$66, B9, MultiYear_ProForma!$C$2:$C$66, "FY2028") -> -482588.87 | F9: =SUMIFS(MultiYear_ProForma!$AF$2:$AF$66, MultiYear_ProForma!$B$2:$B$66, B9, MultiYear_ProForma!$C$2:$C$66, "FY2030") -> -507019.93 | G9: =(SUMIFS(MultiYear_ProForma!$AF$2:$AF$66, MultiYear_ProForma!$B$2:$B$66, B9, MultiYear_ProForma!$C$2:$C$66, "FY2026")+SUMIFS(MultiYear_ProForma!$AF$2:$AF$66, MultiYear_ProForma!$B$2:$B$66, B9, MultiYear_ProForma!$C$2:$C$66, "FY2027")+SUMIFS(MultiYear_ProForma!$AF$2:$AF$66, MultiYear_ProForma!$B$2:$B$66, B9, MultiYear_ProForma!$C$2:$C$66, "FY2028")+SUMIFS(MultiYear_ProForma!$AF$2:$AF$66, MultiYear_ProForma!$B$2:$B$66, B9, MultiYear_ProForma!$C$2:$C$66, "FY2029")+SUMIFS(MultiYear_ProForma!$AF$2:$AF$66, MultiYear_ProForma!$B$2:$B$66, B9, MultiYear_ProForma!$C$2:$C$66, "FY2030"))/5 -> -482883.16 | H9: =SUMIFS(MultiYear_ProForma!$N$2:$N$66, MultiYear_ProForma!$B$2:$B$66, B9, MultiYear_ProForma!$C$2:$C$66, "FY2026") -> 0 | I9: =SUMIFS(MultiYear_ProForma!$AC$2:$AC$66, MultiYear_ProForma!$B$2:$B$66, B9, MultiYear_ProForma!$C$2:$C$66, "FY2030") -> 553 | J9: =F9-(VLOOKUP($C$1,$B$5:$G$17,5, 0)) -> 124173.74 | K9: =G9-(VLOOKUP($C$1,$B$5:$I$17,6, 0)) -> 61187.854
A10: =LEFT(B10, 2) -> D2 | B10: D2_EchoGHubRamp_PimaTargets | C10: =SUMIFS(Capital_Summary!$H$4:$H$83, Capital_Summary!$A$4:$A$83, B10, Capital_Summary!$B$4:$B$83, "FY2026")*-1 -> -800000 | D10: =SUMIFS(MultiYear_ProForma!$AF$2:$AF$66, MultiYear_ProForma!$B$2:$B$66, B10, MultiYear_ProForma!$C$2:$C$66, "FY2026") -> -251908.94 | E10: =SUMIFS(MultiYear_ProForma!$AF$2:$AF$66, MultiYear_ProForma!$B$2:$B$66, B10, MultiYear_ProForma!$C$2:$C$66, "FY2028") -> 182457.86 | F10: =SUMIFS(MultiYear_ProForma!$AF$2:$AF$66, MultiYear_ProForma!$B$2:$B$66, B10, MultiYear_ProForma!$C$2:$C$66, "FY2030") -> 199954.17 | G10: =(SUMIFS(MultiYear_ProForma!$AF$2:$AF$66, MultiYear_ProForma!$B$2:$B$66, B10, MultiYear_ProForma!$C$2:$C$66, "FY2026")+SUMIFS(MultiYear_ProForma!$AF$2:$AF$66, MultiYear_ProForma!$B$2:$B$66, B10, MultiYear_ProForma!$C$2:$C$66, "FY2027")+SUMIFS(MultiYear_ProForma!$AF$2:$AF$66, MultiYear_ProForma!$B$2:$B$66, B10, MultiYear_ProForma!$C$2:$C$66, "FY2028")+SUMIFS(MultiYear_ProForma!$AF$2:$AF$66, MultiYear_ProForma!$B$2:$B$66, B10, MultiYear_ProForma!$C$2:$C$66, "FY2029")+SUMIFS(MultiYear_ProForma!$AF$2:$AF$66, MultiYear_ProForma!$B$2:$B$66, B10, MultiYear_ProForma!$C$2:$C$66, "FY2030"))/5 -> 55710.494 | H10: =SUMIFS(MultiYear_ProForma!$N$2:$N$66, MultiYear_ProForma!$B$2:$B$66, B10, MultiYear_ProForma!$C$2:$C$66, "FY2026") -> 0 | I10: =SUMIFS(MultiYear_ProForma!$AC$2:$AC$66, MultiYear_ProForma!$B$2:$B$66, B10, MultiYear_ProForma!$C$2:$C$66, "FY2030") -> 678 | J10: =F10-(VLOOKUP($C$1,$B$5:$G$17,5, 0)) -> 831147.83 | K10: =G10-(VLOOKUP($C$1,$B$5:$I$17,6, 0)) -> 599781.51
A11: =LEFT(B11, 2) -> A2 | B11: A2_Repurpose_Both_lease | C11: =SUMIFS(Capital_Summary!$H$4:$H$83, Capital_Summary!$A$4:$A$83, B11, Capital_Summary!$B$4:$B$83, "FY2026")*-1 -> -2314480 | D11: =SUMIFS(MultiYear_ProForma!$AF$2:$AF$66, MultiYear_ProForma!$B$2:$B$66, B11, MultiYear_ProForma!$C$2:$C$66, "FY2026") -> 252007.49 | E11: =SUMIFS(MultiYear_ProForma!$AF$2:$AF$66, MultiYear_ProForma!$B$2:$B$66, B11, MultiYear_ProForma!$C$2:$C$66, "FY2028") -> 547880.78 | F11: =SUMIFS(MultiYear_ProForma!$AF$2:$AF$66, MultiYear_ProForma!$B$2:$B$66, B11, MultiYear_ProForma!$C$2:$C$66, "FY2030") -> 815010.46 | G11: =(SUMIFS(MultiYear_ProForma!$AF$2:$AF$66, MultiYear_ProForma!$B$2:$B$66, B11, MultiYear_ProForma!$C$2:$C$66, "FY2026")+SUMIFS(MultiYear_ProForma!$AF$2:$AF$66, MultiYear_ProForma!$B$2:$B$66, B11, MultiYear_ProForma!$C$2:$C$66, "FY2027")+SUMIFS(MultiYear_ProForma!$AF$2:$AF$66, MultiYear_ProForma!$B$2:$B$66, B11, MultiYear_ProForma!$C$2:$C$66, "FY2028")+SUMIFS(MultiYear_ProForma!$AF$2:$AF$66, MultiYear_ProForma!$B$2:$B$66, B11, MultiYear_ProForma!$C$2:$C$66, "FY2029")+SUMIFS(MultiYear_ProForma!$AF$2:$AF$66, MultiYear_ProForma!$B$2:$B$66, B11, MultiYear_ProForma!$C$2:$C$66, "FY2030"))/5 -> 535102.86 | H11: =SUMIFS(MultiYear_ProForma!$N$2:$N$66, MultiYear_ProForma!$B$2:$B$66, B11, MultiYear_ProForma!$C$2:$C$66, "FY2026") -> 553 | I11: =SUMIFS(MultiYear_ProForma!$AC$2:$AC$66, MultiYear_ProForma!$B$2:$B$66, B11, MultiYear_ProForma!$C$2:$C$66, "FY2030") -> 405.8 | J11: =F11-(VLOOKUP($C$1,$B$5:$G$17,5, 0)) -> 1446204.1 | K11: =G11-(VLOOKUP($C$1,$B$5:$I$17,6, 0)) -> 1079173.9
A12: =LEFT(B12, 2) -> A1 | B12: A1_Repurpose_Both_ops | C12: =SUMIFS(Capital_Summary!$H$4:$H$83, Capital_Summary!$A$4:$A$83, B12, Capital_Summary!$B$4:$B$83, "FY2026")*-1 -> -3114480 | D12: =SUMIFS(MultiYear_ProForma!$AF$2:$AF$66, MultiYear_ProForma!$B$2:$B$66, B12, MultiYear_ProForma!$C$2:$C$66, "FY2026") -> -225097.98 | E12: =SUMIFS(MultiYear_ProForma!$AF$2:$AF$66, MultiYear_ProForma!$B$2:$B$66, B12, MultiYear_ProForma!$C$2:$C$66, "FY2028") -> 146873.64 | F12: =SUMIFS(MultiYear_ProForma!$AF$2:$AF$66, MultiYear_ProForma!$B$2:$B$66, B12, MultiYear_ProForma!$C$2:$C$66, "FY2030") -> 393702.32 | G12: =(SUMIFS(MultiYear_ProForma!$AF$2:$AF$66, MultiYear_ProForma!$B$2:$B$66, B12, MultiYear_ProForma!$C$2:$C$66, "FY2026")+SUMIFS(MultiYear_ProForma!$AF$2:$AF$66, MultiYear_ProForma!$B$2:$B$66, B12, MultiYear_ProForma!$C$2:$C$66, "FY2027")+SUMIFS(MultiYear_ProForma!$AF$2:$AF$66, MultiYear_ProForma!$B$2:$B$66, B12, MultiYear_ProForma!$C$2:$C$66, "FY2028")+SUMIFS(MultiYear_ProForma!$AF$2:$AF$66, MultiYear_ProForma!$B$2:$B$66, B12, MultiYear_ProForma!$C$2:$C$66, "FY2029")+SUMIFS(MultiYear_ProForma!$AF$2:$AF$66, MultiYear_ProForma!$B$2:$B$66, B12, MultiYear_ProForma!$C$2:$C$66, "FY2030"))/5 -> 114766.95 | H12: =SUMIFS(MultiYear_ProForma!$N$2:$N$66, MultiYear_ProForma!$B$2:$B$66, B12, MultiYear_ProForma!$C$2:$C$66, "FY2026") -> 553 | I12: =SUMIFS(MultiYear_ProForma!$AC$2:$AC$66, MultiYear_ProForma!$B$2:$B$66, B12, MultiYear_ProForma!$C$2:$C$66, "FY2030") -> 405.8 | J12: =F12-(VLOOKUP($C$1,$B$5:$G$17,5, 0)) -> 1024896 | K12: =G12-(VLOOKUP($C$1,$B$5:$I$17,6, 0)) -> 658837.97
A13: =LEFT(B13, 2) -> B2 | B13: B2_Repurpose_Echo_lease_PimaTargets | C13: =SUMIFS(Capital_Summary!$H$4:$H$83, Capital_Summary!$A$4:$A$83, B13, Capital_Summary!$B$4:$B$83, "FY2026")*-1 -> -800000 | D13: =SUMIFS(MultiYear_ProForma!$AF$2:$AF$66, MultiYear_ProForma!$B$2:$B$66, B13, MultiYear_ProForma!$C$2:$C$66, "FY2026") -> -97751.668 | E13: =SUMIFS(MultiYear_ProForma!$AF$2:$AF$66, MultiYear_ProForma!$B$2:$B$66, B13, MultiYear_ProForma!$C$2:$C$66, "FY2028") -> 121243.24 | F13: =SUMIFS(MultiYear_ProForma!$AF$2:$AF$66, MultiYear_ProForma!$B$2:$B$66, B13, MultiYear_ProForma!$C$2:$C$66, "FY2030") -> 229719.23 | G13: =(SUMIFS(MultiYear_ProForma!$AF$2:$AF$66, MultiYear_ProForma!$B$2:$B$66, B13, MultiYear_ProForma!$C$2:$C$66, "FY2026")+SUMIFS(MultiYear_ProForma!$AF$2:$AF$66, MultiYear_ProForma!$B$2:$B$66, B13, MultiYear_ProForma!$C$2:$C$66, "FY2027")+SUMIFS(MultiYear_ProForma!$AF$2:$AF$66, MultiYear_ProForma!$B$2:$B$66, B13, MultiYear_ProForma!$C$2:$C$66, "FY2028")+SUMIFS(MultiYear_ProForma!$AF$2:$AF$66, MultiYear_ProForma!$B$2:$B$66, B13, MultiYear_ProForma!$C$2:$C$66, "FY2029")+SUMIFS(MultiYear_ProForma!$AF$2:$AF$66, MultiYear_ProForma!$B$2:$B$66, B13, MultiYear_ProForma!$C$2:$C$66, "FY2030"))/5 -> 83696.676 | H13: =SUMIFS(MultiYear_ProForma!$N$2:$N$66, MultiYear_ProForma!$B$2:$B$66, B13, MultiYear_ProForma!$C$2:$C$66, "FY2026") -> 257 | I13: =SUMIFS(MultiYear_ProForma!$AC$2:$AC$66, MultiYear_ProForma!$B$2:$B$66, B13, MultiYear_ProForma!$C$2:$C$66, "FY2030") -> 487.2 | J13: =F13-(VLOOKUP($C$1,$B$5:$G$17,5, 0)) -> 860912.9 | K13: =G13-(VLOOKUP($C$1,$B$5:$I$17,6, 0)) -> 627767.69
A14: =LEFT(B14, 2) -> B1 | B14: B1_Repurpose_Echo_ops_PimaTargets | C14: =SUMIFS(Capital_Summary!$H$4:$H$83, Capital_Summary!$A$4:$A$83, B14, Capital_Summary!$B$4:$B$83, "FY2026")*-1 -> -1200000 | D14: =SUMIFS(MultiYear_ProForma!$AF$2:$AF$66, MultiYear_ProForma!$B$2:$B$66, B14, MultiYear_ProForma!$C$2:$C$66, "FY2026") -> -326762.29 | E14: =SUMIFS(MultiYear_ProForma!$AF$2:$AF$66, MultiYear_ProForma!$B$2:$B$66, B14, MultiYear_ProForma!$C$2:$C$66, "FY2028") -> -65119.939 | F14: =SUMIFS(MultiYear_ProForma!$AF$2:$AF$66, MultiYear_ProForma!$B$2:$B$66, B14, MultiYear_ProForma!$C$2:$C$66, "FY2030") -> 33921.417 | G14: =(SUMIFS(MultiYear_ProForma!$AF$2:$AF$66, MultiYear_ProForma!$B$2:$B$66, B14, MultiYear_ProForma!$C$2:$C$66, "FY2026")+SUMIFS(MultiYear_ProForma!$AF$2:$AF$66, MultiYear_ProForma!$B$2:$B$66, B14, MultiYear_ProForma!$C$2:$C$66, "FY2027")+SUMIFS(MultiYear_ProForma!$AF$2:$AF$66, MultiYear_ProForma!$B$2:$B$66, B14, MultiYear_ProForma!$C$2:$C$66, "FY2028")+SUMIFS(MultiYear_ProForma!$AF$2:$AF$66, MultiYear_ProForma!$B$2:$B$66, B14, MultiYear_ProForma!$C$2:$C$66, "FY2029")+SUMIFS(MultiYear_ProForma!$AF$2:$AF$66, MultiYear_ProForma!$B$2:$B$66, B14, MultiYear_ProForma!$C$2:$C$66, "FY2030"))/5 -> -113105.64 | H14: =SUMIFS(MultiYear_ProForma!$N$2:$N$66, MultiYear_ProForma!$B$2:$B$66, B14, MultiYear_ProForma!$C$2:$C$66, "FY2026") -> 257 | I14: =SUMIFS(MultiYear_ProForma!$AC$2:$AC$66, MultiYear_ProForma!$B$2:$B$66, B14, MultiYear_ProForma!$C$2:$C$66, "FY2030") -> 487.2 | J14: =F14-(VLOOKUP($C$1,$B$5:$G$17,5, 0)) -> 665115.08 | K14: =G14-(VLOOKUP($C$1,$B$5:$I$17,6, 0)) -> 430965.37
A15: =LEFT(B15, 2) -> C2 | B15: C2_Repurpose_Pima_lease_EchoGHub_EchoTargets | C15: =SUMIFS(Capital_Summary!$H$4:$H$83, Capital_Summary!$A$4:$A$83, B15, Capital_Summary!$B$4:$B$83, "FY2026")*-1 -> -1600000 | D15: =SUMIFS(MultiYear_ProForma!$AF$2:$AF$66, MultiYear_ProForma!$B$2:$B$66, B15, MultiYear_ProForma!$C$2:$C$66, "FY2026") -> 36009.647 | E15: =SUMIFS(MultiYear_ProForma!$AF$2:$AF$66, MultiYear_ProForma!$B$2:$B$66, B15, MultiYear_ProForma!$C$2:$C$66, "FY2028") -> 406921.2 | F15: =SUMIFS(MultiYear_ProForma!$AF$2:$AF$66, MultiYear_ProForma!$B$2:$B$66, B15, MultiYear_ProForma!$C$2:$C$66, "FY2030") -> 570325.27 | G15: =(SUMIFS(MultiYear_ProForma!$AF$2:$AF$66, MultiYear_ProForma!$B$2:$B$66, B15, MultiYear_ProForma!$C$2:$C$66, "FY2026")+SUMIFS(MultiYear_ProForma!$AF$2:$AF$66, MultiYear_ProForma!$B$2:$B$66, B15, MultiYear_ProForma!$C$2:$C$66, "FY2027")+SUMIFS(MultiYear_ProForma!$AF$2:$AF$66, MultiYear_ProForma!$B$2:$B$66, B15, MultiYear_ProForma!$C$2:$C$66, "FY2028")+SUMIFS(MultiYear_ProForma!$AF$2:$AF$66, MultiYear_ProForma!$B$2:$B$66, B15, MultiYear_ProForma!$C$2:$C$66, "FY2029")+SUMIFS(MultiYear_ProForma!$AF$2:$AF$66, MultiYear_ProForma!$B$2:$B$66, B15, MultiYear_ProForma!$C$2:$C$66, "FY2030"))/5 -> 343387.87 | H15: =SUMIFS(MultiYear_ProForma!$N$2:$N$66, MultiYear_ProForma!$B$2:$B$66, B15, MultiYear_ProForma!$C$2:$C$66, "FY2026") -> 295.66667 | I15: =SUMIFS(MultiYear_ProForma!$AC$2:$AC$66, MultiYear_ProForma!$B$2:$B$66, B15, MultiYear_ProForma!$C$2:$C$66, "FY2030") -> 558.6 | J15: =F15-(VLOOKUP($C$1,$B$5:$G$17,5, 0)) -> 1201518.9 | K15: =G15-(VLOOKUP($C$1,$B$5:$I$17,6, 0)) -> 887458.89
A16: =LEFT(B16, 2) -> C1 | B16: C1_Repurpose_Pima_ops_EchoGHub_EchoTargets | C16: =SUMIFS(Capital_Summary!$H$4:$H$83, Capital_Summary!$A$4:$A$83, B16, Capital_Summary!$B$4:$B$83, "FY2026")*-1 -> -2000000 | D16: =SUMIFS(MultiYear_ProForma!$AF$2:$AF$66, MultiYear_ProForma!$B$2:$B$66, B16, MultiYear_ProForma!$C$2:$C$66, "FY2026") -> -212085.2 | E16: =SUMIFS(MultiYear_ProForma!$AF$2:$AF$66, MultiYear_ProForma!$B$2:$B$66, B16, MultiYear_ProForma!$C$2:$C$66, "FY2028") -> 192277.23 | F16: =SUMIFS(MultiYear_ProForma!$AF$2:$AF$66, MultiYear_ProForma!$B$2:$B$66, B16, MultiYear_ProForma!$C$2:$C$66, "FY2030") -> 344814.95 | G16: =(SUMIFS(MultiYear_ProForma!$AF$2:$AF$66, MultiYear_ProForma!$B$2:$B$66, B16, MultiYear_ProForma!$C$2:$C$66, "FY2026")+SUMIFS(MultiYear_ProForma!$AF$2:$AF$66, MultiYear_ProForma!$B$2:$B$66, B16, MultiYear_ProForma!$C$2:$C$66, "FY2027")+SUMIFS(MultiYear_ProForma!$AF$2:$AF$66, MultiYear_ProForma!$B$2:$B$66, B16, MultiYear_ProForma!$C$2:$C$66, "FY2028")+SUMIFS(MultiYear_ProForma!$AF$2:$AF$66, MultiYear_ProForma!$B$2:$B$66, B16, MultiYear_ProForma!$C$2:$C$66, "FY2029")+SUMIFS(MultiYear_ProForma!$AF$2:$AF$66, MultiYear_ProForma!$B$2:$B$66, B16, MultiYear_ProForma!$C$2:$C$66, "FY2030"))/5 -> 119854.28 | H16: =SUMIFS(MultiYear_ProForma!$N$2:$N$66, MultiYear_ProForma!$B$2:$B$66, B16, MultiYear_ProForma!$C$2:$C$66, "FY2026") -> 295.66667 | I16: =SUMIFS(MultiYear_ProForma!$AC$2:$AC$66, MultiYear_ProForma!$B$2:$B$66, B16, MultiYear_ProForma!$C$2:$C$66, "FY2030") -> 558.6 | J16: =F16-(VLOOKUP($C$1,$B$5:$G$17,5, 0)) -> 976008.61 | K16: =G16-(VLOOKUP($C$1,$B$5:$I$17,6, 0)) -> 663925.3
A17: =LEFT(B17, 2) -> E1 | B17: E1_StatusQuo_Decline | C17: =SUMIFS(Capital_Summary!$H$4:$H$83, Capital_Summary!$A$4:$A$83, B17, Capital_Summary!$B$4:$B$83, "FY2026")*-1 -> 0 | D17: =SUMIFS(MultiYear_ProForma!$AF$2:$AF$66, MultiYear_ProForma!$B$2:$B$66, B17, MultiYear_ProForma!$C$2:$C$66, "FY2026") -> -459335.03 | E17: =SUMIFS(MultiYear_ProForma!$AF$2:$AF$66, MultiYear_ProForma!$B$2:$B$66, B17, MultiYear_ProForma!$C$2:$C$66, "FY2028") -> -542877.76 | F17: =SUMIFS(MultiYear_ProForma!$AF$2:$AF$66, MultiYear_ProForma!$B$2:$B$66, B17, MultiYear_ProForma!$C$2:$C$66, "FY2030") -> -631193.67 | G17: =(SUMIFS(MultiYear_ProForma!$AF$2:$AF$66, MultiYear_ProForma!$B$2:$B$66, B17, MultiYear_ProForma!$C$2:$C$66, "FY2026")+SUMIFS(MultiYear_ProForma!$AF$2:$AF$66, MultiYear_ProForma!$B$2:$B$66, B17, MultiYear_ProForma!$C$2:$C$66, "FY2027")+SUMIFS(MultiYear_ProForma!$AF$2:$AF$66, MultiYear_ProForma!$B$2:$B$66, B17, MultiYear_ProForma!$C$2:$C$66, "FY2028")+SUMIFS(MultiYear_ProForma!$AF$2:$AF$66, MultiYear_ProForma!$B$2:$B$66, B17, MultiYear_ProForma!$C$2:$C$66, "FY2029")+SUMIFS(MultiYear_ProForma!$AF$2:$AF$66, MultiYear_ProForma!$B$2:$B$66, B17, MultiYear_ProForma!$C$2:$C$66, "FY2030"))/5 -> -544071.02 | H17: =SUMIFS(MultiYear_ProForma!$N$2:$N$66, MultiYear_ProForma!$B$2:$B$66, B17, MultiYear_ProForma!$C$2:$C$66, "FY2026") -> 0 | I17: =SUMIFS(MultiYear_ProForma!$AC$2:$AC$66, MultiYear_ProForma!$B$2:$B$66, B17, MultiYear_ProForma!$C$2:$C$66, "FY2030") -> 510.06959 | J17: =F17-(VLOOKUP($C$1,$B$5:$G$17,5, 0)) -> 0 | K17: =G17-(VLOOKUP($C$1,$B$5:$I$17,6, 0)) -> 0
B19: Note: Displaced = FY26; Served = FY30. Net = M&O − (Aid + Override + Uplift); showing one-time capital (fy26) as negative number for visualization purposes

Sheet What_Is_The_$900K-$1M_Savings

Sheet Parameters_Public
A1: Public Inputs — Audited Baselines and Overrides (Phase A) | C1: Yellow fields are editable
A3: ADM (official) | C3: Values | E3: Notes | I3: Notes2
B4: Echo 40th | C4: 257 | E4: Estimate used at this point; need to replace. Find official 40th day ADM for Echo (enter audited)
B5: Echo 100th | C5: 257 | E5: Estimate used at this point; need to replace. Find official 100th day ADM for Echo (enter audited)
B6: Pima 40th | C6: 296 | E6: Estimate used at this point; need to replace. Find official 40th day ADM for Pima (enter audited)
B7: Pima 100th | C7: 296 | E7: Estimate used at this point; need to replace. Find official 100th day ADM for Pima (enter audited)
B8: Use Day (40 or 100) | C8: 40 | E8: Choose which count the model uses (40 or 100).
B10: Echo_ADM0 (selected) | C10: =IF(C8=40,C4,C5) -> 257 | E10: Model‑read Echo_ADM0 selected based on 40/100 day switch.
B11: Pima_ADM0 (selected) | C11: =IF(C8=40,C6,C7) -> 296 | E11: Model‑read Pima_ADM0 selected based on 40/100 day switch.
A13: M&O/ADM (district), audited (ACFR)
B14: M_O_per_ADM_Audited | C14: 11589 | E14: Estimate used at this point. Enter the audited districtwide Maintenance & Operations cost per ADM from the latest ACFR/Adopted Budget. Used as the FY25 base.
A16: Override — property‑tax override
B17: Override percent | C17: 0.15 | E17: Districtwide override percent (e.g., 15%).
B18: Base aid per ADM (proxy for RCL per pupil) | C18: 5013 | E18: Proxy base for calculating per‑ADM override; replace with RCL per pupil if available.
B19: Override per ADM (proxy) | C19: =C17*C18 -> 751.95 | E19: Computed per‑ADM amount used wherever the model needs a per‑student override term.
B20: Override toggle (1=on, 0=off) | C20: 1 | E20: Global on/off switch for including override in revenue calculations.
B21: Other General Fund revenue per served ADM (optional uplift) | C21: 5200 | E21: Everything not in “Base Aid + Override”: add‑on weights (e.g., SPED Group A/B), Transportation Support Level (TSL), and District Additional Assistance (DAA) — all components of the Equalization Base. (The Legislature’s primer shows Equalization Base = BSL + TSL + DAA, BLA = $5,013.33 in FY25. General Fund (Fund 001) revenues, FY2024 (actual): $192.213M (property taxes + state aid & grants). resources.finalsite.net Using SUSD’s FY2024 ACFR (audited): General Fund revenues (FY2024) = $215.4M (MD&A notes), General Fund expenditures = $233.7M. Scottsdale Unified School District Average Daily Membership (FY2024) = 19,748 (Operating Statistics table). Scottsdale Unified School District → GF revenue per ADM ≈ $215.4M / 19,748 ≈ $10,900/ADM. | I21: Using SUSD’s FY2024 ACFR (audited): General Fund revenues (FY2024) = $215.4M (MD&A notes), General Fund expenditures = $233.7M. Scottsdale Unified School District Average Daily Membership (FY2024) = 19,748 (Operating Statistics table). Scottsdale Unified School District → GF revenue per ADM ≈ $215.4M / 19,748 ≈ $10,900/ADM. State base amounts (policy context): FY2024 Base Level Amount (BLA) = $4,914.71. Arizona Department of Education FY2025 BLA = $5,013.33 (Senate research issue brief; also reiterates Equalization Base = BSL + TSL + DAA). Arizona Legislature Your model treats revenue as Aid (BLA‑based) + Override (+ optional uplift). To reconcile absolute Nets with audited magnitudes, we add an uplift that approximates everything in GF that isn’t “base + override,” e.g., TSL, DAA, formula add‑ons/weights, Prop 123 allocations, etc. (that’s what the Equalization Base framework is capturing when you aggregate components). Arizona Legislature Two reasonable calibration anchors: FY2024 basis: Uplift ≈ GF revenue per ADM − (BLA + Override) ≈ 10,900 − (4,914.71 + 0.15 × 4,914.71) ≈ 10,900 − (4,914.71 + 737) ≈ $5,250/ADM (rounded). Scottsdale Unified School District +2 Scottsdale Unified School District +2 FY2025 basis: Uplift ≈ 10,900 − (5,013.33 + 0.15 × 5,013.33) ≈ 10,900 − (5,013.33 + 752) ≈ $5,135/ADM (rounded). Scottsdale Unified School District +2 Scottsdale Unified School District +2 Uplift $5,100–$5,300/ADM is defensible on FY24 data and the state’s formula structure.
B22: Aid per ADM annual growth | C22: 0.025 | E22: Assuming aid grows around the same rate as cost inflation.
B23: Retention r — Echo (central) | C23: 0.6 | E23: Share of displaced Echo students re-enrolling in SUSD (0–1). As a choice school with 50% or more of families living outside the district, we can assume this will be lower than Pima.
B24: Retention r — Pima (central) | C24: 0.85 | E24: Share of displaced Pima students re-enrolling in SUSD (0–1). Not a significant amount of research on retention from closed schools; Chicago public retained 90%+ of students who were majority in boundaries when closing schools.
A26: Capital Treatment & Growth Capex (DRAFT placeholders)
B28: Include TI in Operating M&O? (0/1) | C28: 0 | E28: 0 = treat TI as capital (exclude from operating nets); 1 = include TI in Comparable_MO$
B29: TI per closed site (one-time) | C29: =BaselineCalc!$B$22 -> 1200000 | E29: “TI” = tenant improvements / transition investments needed to convert a K‑8 to a different use (early learning, admin consolidation) and carry costs in year one (e.g., abatement, doors/security, low‑voltage re‑work, furniture, swing space); DRAFT Ops TI: Mirrors BaselineCalc TI unit; replace with capital plan when available
B30: Growth Capex — Arts Hub (one-time) | C30: 800000 | E30: DRAFT placeholder; enter benchmarked capital required to enable Arts hub
B31: Growth Capex — Innovation Hub (one-time) | C31: 1200000 | E31: DRAFT placeholder; enter benchmarked capital required for Innovation hub
B32: Include Growth Capex in Operating? (0/1) | C32: 0 | E32: 0 = treat growth capex as capital (recommended); 1 = include in Comparable_MO$ (what‑if only)
B33: TI per closed site (lease case) | C33: 800000 | E33: DRAFT: lease TI placeholder; separate from ops TI (C27)
B34: Portable seat cost (capital $ per seat) | C34: 12000 | E34: DRAFT: per-seat portables or TI to add seats at receivers
B35: Spare K–5 seats across receivers (FY26) | C35: 300 | E35: User input: available elementary seats to absorb retained K–5
B36: Spare 6–8 seats across receivers (FY26) | C36: 100 | E36: User input: available middle seats to absorb retained 6–8
B38: Echo K–5 share of ADM | C38: 0.7 | E38: DRAFT: distribution of Echo ADM by grade band
B39: Echo 6–8 share of ADM | C39: 0.3
B40: Pima K–5 share of ADM | C40: 1
B41: Pima 6–8 share of ADM | C41: 0
B43: MarginalFactor_for_Overlay (central source) | C43: 0.6 | E43: Assuming marginal cost (as a function of standard variable cost per student) of new students from growth (assuming there is available capacity in Echo and Pima; ideally, this would be a step function)
B44: Echo ADM trend default | C44: -0.02 | E44: Default enrollment trend from forecasts; placeholder value for now -- need to verify this
B45: Pima ADM trend default | C45: -0.02 | E45: Default enrollment trend from forecasts; placeholder value for now -- need to verify this
B47: Growth overhead per added ADM (α × h) | C47: 0.2 | E47: Assuming some incremental transportation overhead for growth-related new students; we model it as a percentage of closed school transition-related incremental transportation overhead
B49: Incremental uplift alpha (overlay share of base uplift) | C49: 0.85 | E49: Applied only to Overlay_ADM; keeps marginal revenue conservative because some ‘other GF’ (weights/TSL/DAA) don’t scale 1:1. Typical range 0.70–0.90 (default 0.85).

Sheet Inputs_Definitions_Sources
A1: Audited & Policy Anchors (paste into Parameters when available)
A2: Anchor | B2: Value / Status | C2: Source (short) | D2: Used for | E2: Owner | F2: Paste location | G2: Source URL
A3: BLA (Base Level Amount) FY2025 | B3: 5,013.33 | C3: AZ Senate Issue Brief / ADE update | D3: YearMap → Aid$ | E3: Finance | F3: Parameters_Public!C18 or BaselineCalc | G3: https://www.azleg.gov/Briefs/Senate/ARIZONA%27S%20SCHOOL%20FINANCE%20SYSTEM%202024.PDF
A4: M&O Override % | B4: 15% (RCL) | C4: SUSD M&O Override page | D4: Override per ADM; Revenue$ | E4: Finance | F4: Parameters_Public!C17 | G4: https://www.susd.org/Page/658
A5: Override toggle | B5: 0/1 (board policy) | C5: Model control | D5: Revenue$ switch | E5: Model | F5: Parameters_Public!C20
A6: District M&O per ADM (audited) | B6: FY2024 value (e.g., 14,049) | C6: SUSD ACFR FY2024, Operating Statistics | D6: Sanity checks / narratives | E6: Finance | F6: Parameters_Public!C14
A7: Transportation Support Level (TSL) | B7: Per route‑mile schedule | C7: AZ Senate Issue Brief / ADE | D7: Revenue context | E7: Finance | F7: Definitions_Sources | G7: https://www.azed.gov/finance/fy2025-school-finance-fiscal-operations-updates
A8: Transport cost per eligible rider | B8: ≈ 3,183 (FY2024 anchor) | C8: City of Scottsdale Auditor report | D8: h₀ (retention overhead) anchor | E8: Ops | F8: Control_Center | G8: https://www.scottsdaleaz.gov/docs/default-source/scottsdaleaz/auditor/2025-reports/susd-transportation---audit-2508.pdf?sfvrsn=144e4f2d_1
A9: Echo/Pima 40th & 100th (FY2025) | B9: To paste (AzEDS export SDADMS72/75) | C9: ADE School Finance / District export | D9: Base ADM by site | E9: Data | F9: Parameters_Public | G9: https://www.ade.az.gov/schoolfinance/Reports
A10: Site‑fixed ledgers (Fund 001, by site) | B10: To paste (Echo & Pima) | C10: SUSD Finance site/cost‑center ledgers | D10: Replace fallback fixed | E10: Finance | F10: Site_Fixed | G10: https://www.azauditor.gov/arizona-school-district-spending-fiscal-year-2024-analysis-and-data-file
A12: Core Definitions & Derivations
A13: Term | B13: Definition / Formula | C13: Appears on | D13: Depends on | E13: Notes | F13: Named range (if any)
A14: Operating Net ($) | B14: M&O − (Aid + Override + Uplift); capital excluded. | C14: Summary_Figures; Scenario_Comparison; Board_OnePager | D14: YearMap revenues, MultiYear_ProForma costs | E14: Fund 001 lens only.
A15: Δ vs Base (FY2030) | B15: Comparator FY2030 Net − Base FY2030 Net. | C15: Summary_Figures; Scenario_Comparison | D15: Net$
A16: Δ vs Base (Avg FY26–30) | B16: Comparator 5‑yr Avg Net − Base 5‑yr Avg Net. | C16: Summary_Figures; Scenario_Comparison | D16: Net$ FY26..30
