Workbook
Name ADM_Day_Select: Parameters_Public!C8
Name BaseAid_per_ADM: Parameters_Public!C18
Name Capex_ArtsHub: Parameters_Public!C28
Name Capex_in_MO_Toggle: Parameters_Public!C30
Name Capex_InnovHub: Parameters_Public!C29
Name Echo_ADM0: Parameters_Public!C10
Name M_O_per_ADM_Audited: Parameters_Public!C14
Name Override_per_ADM_proxy: Parameters_Public!C19
Name Override_Percent: Parameters_Public!C17
Name Override_Toggle: Parameters_Public!C20
Name Pima_ADM0: Parameters_Public!C11
Name TI_in_MO_Toggle: Parameters_Public!C26
Name TI_per_Site: Parameters_Public!C27

Sheet Parameters_Public
A1: Public Inputs — Audited Baselines and Overrides (Phase A)
A3: ADM (official) | C3: Values | E3: Notes
B4: Echo 40th | C4: 257 | D4: Use Day (40 or 100) | E4: Estimate used at this point; need to replace. Official 40th day ADM for Echo (enter audited)
B5: Echo 100th | C5: 257 | D5: Echo_ADM0 (selected) | E5: Estimate used at this point; need to replace. Official 100th day ADM for Echo (enter audited)
B6: Pima 40th | C6: 296 | D6: Pima_ADM0 (selected) | E6: Estimate used at this point; need to replace. Official 40th day ADM for Pima (enter audited)
B7: Pima 100th | C7: 296 | E7: Estimate used at this point; need to replace. Official 100th day ADM for Pima (enter audited)
B8: Use Day (40 or 100) | C8: 40 | E8: Choose which count the model uses (40 or 100).
B10: Echo_ADM0 (selected) | C10: =IF(C8=40,C4,C5) -> 257 | E10: Model‑read Echo_ADM0 selected based on 40/100 day switch.
B11: Pima_ADM0 (selected) | C11: =IF(C8=40,C6,C7) -> 296 | E11: Model‑read Pima_ADM0 selected based on 40/100 day switch.
A13: M&O/ADM (district), audited (ACFR)
B14: M_O_per_ADM_Audited | C14: 11589 | E14: Enter the audited districtwide Maintenance & Operations cost per ADM from the latest ACFR/Adopted Budget. Used as the FY25 base.
A16: Override — property‑tax override
B17: Override percent | C17: 0.15 | E17: Districtwide override percent (e.g., 15%).
B18: Base aid per ADM (proxy for RCL per pupil) | C18: 5013 | E18: Proxy base for calculating per‑ADM override; replace with RCL per pupil if available.
B19: Override per ADM (proxy) | C19: =C17*C18 -> 751.95 | E19: Computed per‑ADM amount used wherever the model needs a per‑student override term.
B20: Override toggle (1=on, 0=off) | C20: 1 | E20: Global on/off switch for including override in revenue calculations (future phase).
B22: Retention r — Echo (central) | C22: 0.6 | E22: Share of displaced Echo students re-enrolling in SUSD (0–1).
B23: Retention r — Pima (central) | C23: 0.85 | E23: Share of displaced Pima students re-enrolling in SUSD (0–1).
A24: Capital Treatment & Growth Capex (DRAFT placeholders)
B26: Include TI in Operating M&O? (0/1) | C26: 0 | E26: 0 = treat TI as capital (exclude from operating nets); 1 = include TI in Comparable_MO$
B27: TI per closed site (one-time) | C27: =BaselineCalc!$B$22 -> 1200000 | E27: Mirrors BaselineCalc TI unit; replace with capital plan when available
B28: Growth Capex — Arts Hub (one-time) | C28: 800000 | E28: DRAFT placeholder; enter benchmarked capital required to enable Arts hub
B29: Growth Capex — Innovation Hub (one-time) | C29: 1200000 | E29: DRAFT placeholder; enter benchmarked capital required for Innovation hub
B30: Include Growth Capex in Operating? (0/1) | C30: 0 | E30: 0 = treat growth capex as capital (recommended); 1 = include in Comparable_MO$ (what‑if only)

Sheet Summary

Sheet Capital_Summary
A1: Capital Summary (TI and Growth Capex) — Cash, not Operating
A3: ScenarioKey | B3: Year | C3: ClosedSites | D3: TI_Cash$ | E3: GrowthCapex_Echo$ | F3: GrowthCapex_Pima$ | G3: Total_Capital$
A4: =Scenarios!A2 -> D_CUSTOM1 | B4: FY2026 | C4: 0 | D4: =IF(MultiYear_ProForma!C2="FY2026", 0*Parameters_Public!$C$27, 0) -> 0 | E4: 0 | F4: 0 | G4: =SUM(D4:F4) -> 0
A5: =Scenarios!A2 -> D_CUSTOM1 | B5: FY2027 | C5: 0 | D5: =IF(MultiYear_ProForma!C3="FY2026", 0*Parameters_Public!$C$27, 0) -> 0 | E5: 0 | F5: 0 | G5: =SUM(D5:F5) -> 0
A6: =Scenarios!A2 -> D_CUSTOM1 | B6: FY2028 | C6: 0 | D6: =IF(MultiYear_ProForma!C4="FY2026", 0*Parameters_Public!$C$27, 0) -> 0 | E6: 0 | F6: 0 | G6: =SUM(D6:F6) -> 0
A7: =Scenarios!A2 -> D_CUSTOM1 | B7: FY2029 | C7: 0 | D7: =IF(MultiYear_ProForma!C5="FY2026", 0*Parameters_Public!$C$27, 0) -> 0 | E7: 0 | F7: 0 | G7: =SUM(D7:F7) -> 0
A8: =Scenarios!A2 -> D_CUSTOM1 | B8: FY2030 | C8: 0 | D8: =IF(MultiYear_ProForma!C6="FY2026", 0*Parameters_Public!$C$27, 0) -> 0 | E8: 0 | F8: 0 | G8: =SUM(D8:F8) -> 0
A9: =Scenarios!A3 -> E_StatusQuo_Targets | B9: FY2026 | C9: 0 | D9: =IF(MultiYear_ProForma!C7="FY2026", 0*Parameters_Public!$C$27, 0) -> 0 | E9: 0 | F9: 0 | G9: =SUM(D9:F9) -> 0
A10: =Scenarios!A3 -> E_StatusQuo_Targets | B10: FY2027 | C10: 0 | D10: =IF(MultiYear_ProForma!C8="FY2026", 0*Parameters_Public!$C$27, 0) -> 0 | E10: 0 | F10: 0 | G10: =SUM(D10:F10) -> 0
A11: =Scenarios!A3 -> E_StatusQuo_Targets | B11: FY2028 | C11: 0 | D11: =IF(MultiYear_ProForma!C9="FY2026", 0*Parameters_Public!$C$27, 0) -> 0 | E11: 0 | F11: 0 | G11: =SUM(D11:F11) -> 0
A12: =Scenarios!A3 -> E_StatusQuo_Targets | B12: FY2029 | C12: 0 | D12: =IF(MultiYear_ProForma!C10="FY2026", 0*Parameters_Public!$C$27, 0) -> 0 | E12: 0 | F12: 0 | G12: =SUM(D12:F12) -> 0
A13: =Scenarios!A3 -> E_StatusQuo_Targets | B13: FY2030 | C13: 0 | D13: =IF(MultiYear_ProForma!C11="FY2026", 0*Parameters_Public!$C$27, 0) -> 0 | E13: 0 | F13: 0 | G13: =SUM(D13:F13) -> 0
A14: =Scenarios!A4 -> F_CoLocation_Echo_Targets | B14: FY2026 | C14: 0 | D14: =IF(MultiYear_ProForma!C12="FY2026", 0*Parameters_Public!$C$27, 0) -> 0 | E14: 0 | F14: 0 | G14: =SUM(D14:F14) -> 0
A15: =Scenarios!A4 -> F_CoLocation_Echo_Targets | B15: FY2027 | C15: 0 | D15: =IF(MultiYear_ProForma!C13="FY2026", 0*Parameters_Public!$C$27, 0) -> 0 | E15: 0 | F15: 0 | G15: =SUM(D15:F15) -> 0
A16: =Scenarios!A4 -> F_CoLocation_Echo_Targets | B16: FY2028 | C16: 0 | D16: =IF(MultiYear_ProForma!C14="FY2026", 0*Parameters_Public!$C$27, 0) -> 0 | E16: 0 | F16: 0 | G16: =SUM(D16:F16) -> 0
A17: =Scenarios!A4 -> F_CoLocation_Echo_Targets | B17: FY2029 | C17: 0 | D17: =IF(MultiYear_ProForma!C15="FY2026", 0*Parameters_Public!$C$27, 0) -> 0 | E17: 0 | F17: 0 | G17: =SUM(D17:F17) -> 0
A18: =Scenarios!A4 -> F_CoLocation_Echo_Targets | B18: FY2030 | C18: 0 | D18: =IF(MultiYear_ProForma!C16="FY2026", 0*Parameters_Public!$C$27, 0) -> 0 | E18: 0 | F18: 0 | G18: =SUM(D18:F18) -> 0
A19: =Scenarios!A5 -> D_Grow_Both_Targets | B19: FY2026 | C19: 0 | D19: =IF(MultiYear_ProForma!C17="FY2026", 0*Parameters_Public!$C$27, 0) -> 0 | E19: 0 | F19: 0 | G19: =SUM(D19:F19) -> 0
A20: =Scenarios!A5 -> D_Grow_Both_Targets | B20: FY2027 | C20: 0 | D20: =IF(MultiYear_ProForma!C18="FY2026", 0*Parameters_Public!$C$27, 0) -> 0 | E20: 0 | F20: 0 | G20: =SUM(D20:F20) -> 0
A21: =Scenarios!A5 -> D_Grow_Both_Targets | B21: FY2028 | C21: 0 | D21: =IF(MultiYear_ProForma!C19="FY2026", 0*Parameters_Public!$C$27, 0) -> 0 | E21: 0 | F21: 0 | G21: =SUM(D21:F21) -> 0
A22: =Scenarios!A5 -> D_Grow_Both_Targets | B22: FY2029 | C22: 0 | D22: =IF(MultiYear_ProForma!C20="FY2026", 0*Parameters_Public!$C$27, 0) -> 0 | E22: 0 | F22: 0 | G22: =SUM(D22:F22) -> 0
A23: =Scenarios!A5 -> D_Grow_Both_Targets | B23: FY2030 | C23: 0 | D23: =IF(MultiYear_ProForma!C21="FY2026", 0*Parameters_Public!$C$27, 0) -> 0 | E23: 0 | F23: 0 | G23: =SUM(D23:F23) -> 0
A24: =Scenarios!A6 -> D_CUSTOM2 | B24: FY2026 | C24: 0 | D24: =IF(MultiYear_ProForma!C22="FY2026", 0*Parameters_Public!$C$27, 0) -> 0 | E24: 0 | F24: 0 | G24: =SUM(D24:F24) -> 0
A25: =Scenarios!A6 -> D_CUSTOM2 | B25: FY2027 | C25: 0 | D25: =IF(MultiYear_ProForma!C23="FY2026", 0*Parameters_Public!$C$27, 0) -> 0 | E25: 0 | F25: 0 | G25: =SUM(D25:F25) -> 0
A26: =Scenarios!A6 -> D_CUSTOM2 | B26: FY2028 | C26: 0 | D26: =IF(MultiYear_ProForma!C24="FY2026", 0*Parameters_Public!$C$27, 0) -> 0 | E26: 0 | F26: 0 | G26: =SUM(D26:F26) -> 0
A27: =Scenarios!A6 -> D_CUSTOM2 | B27: FY2029 | C27: 0 | D27: =IF(MultiYear_ProForma!C25="FY2026", 0*Parameters_Public!$C$27, 0) -> 0 | E27: 0 | F27: 0 | G27: =SUM(D27:F27) -> 0
A28: =Scenarios!A6 -> D_CUSTOM2 | B28: FY2030 | C28: 0 | D28: =IF(MultiYear_ProForma!C26="FY2026", 0*Parameters_Public!$C$27, 0) -> 0 | E28: 0 | F28: 0 | G28: =SUM(D28:F28) -> 0
A29: =Scenarios!A7 -> G_EchoGHubRamp_PimaTargets | B29: FY2026 | C29: 0 | D29: =IF(MultiYear_ProForma!C27="FY2026", 0*Parameters_Public!$C$27, 0) -> 0 | E29: 0 | F29: 0 | G29: =SUM(D29:F29) -> 0
A30: =Scenarios!A7 -> G_EchoGHubRamp_PimaTargets | B30: FY2027 | C30: 0 | D30: =IF(MultiYear_ProForma!C28="FY2026", 0*Parameters_Public!$C$27, 0) -> 0 | E30: 0 | F30: 0 | G30: =SUM(D30:F30) -> 0
A31: =Scenarios!A7 -> G_EchoGHubRamp_PimaTargets | B31: FY2028 | C31: 0 | D31: =IF(MultiYear_ProForma!C29="FY2026", 0*Parameters_Public!$C$27, 0) -> 0 | E31: 0 | F31: 0 | G31: =SUM(D31:F31) -> 0
A32: =Scenarios!A7 -> G_EchoGHubRamp_PimaTargets | B32: FY2029 | C32: 0 | D32: =IF(MultiYear_ProForma!C30="FY2026", 0*Parameters_Public!$C$27, 0) -> 0 | E32: 0 | F32: 0 | G32: =SUM(D32:F32) -> 0
A33: =Scenarios!A7 -> G_EchoGHubRamp_PimaTargets | B33: FY2030 | C33: 0 | D33: =IF(MultiYear_ProForma!C31="FY2026", 0*Parameters_Public!$C$27, 0) -> 0 | E33: 0 | F33: 0 | G33: =SUM(D33:F33) -> 0
A34: =Scenarios!A8 -> A_Repurpose_Both_lease | B34: FY2026 | C34: 0 | D34: =IF(MultiYear_ProForma!C32="FY2026", 0*Parameters_Public!$C$27, 0) -> 0 | E34: 0 | F34: 0 | G34: =SUM(D34:F34) -> 0
A35: =Scenarios!A8 -> A_Repurpose_Both_lease | B35: FY2027 | C35: 0 | D35: =IF(MultiYear_ProForma!C33="FY2026", 0*Parameters_Public!$C$27, 0) -> 0 | E35: 0 | F35: 0 | G35: =SUM(D35:F35) -> 0
A36: =Scenarios!A8 -> A_Repurpose_Both_lease | B36: FY2028 | C36: 0 | D36: =IF(MultiYear_ProForma!C34="FY2026", 0*Parameters_Public!$C$27, 0) -> 0 | E36: 0 | F36: 0 | G36: =SUM(D36:F36) -> 0
A37: =Scenarios!A8 -> A_Repurpose_Both_lease | B37: FY2029 | C37: 0 | D37: =IF(MultiYear_ProForma!C35="FY2026", 0*Parameters_Public!$C$27, 0) -> 0 | E37: 0 | F37: 0 | G37: =SUM(D37:F37) -> 0
A38: =Scenarios!A8 -> A_Repurpose_Both_lease | B38: FY2030 | C38: 0 | D38: =IF(MultiYear_ProForma!C36="FY2026", 0*Parameters_Public!$C$27, 0) -> 0 | E38: 0 | F38: 0 | G38: =SUM(D38:F38) -> 0
A39: =Scenarios!A9 -> A_Repurpose_Both_ops | B39: FY2026 | C39: 0 | D39: =IF(MultiYear_ProForma!C37="FY2026", 0*Parameters_Public!$C$27, 0) -> 0 | E39: 0 | F39: 0 | G39: =SUM(D39:F39) -> 0
A40: =Scenarios!A9 -> A_Repurpose_Both_ops | B40: FY2027 | C40: 0 | D40: =IF(MultiYear_ProForma!C38="FY2026", 0*Parameters_Public!$C$27, 0) -> 0 | E40: 0 | F40: 0 | G40: =SUM(D40:F40) -> 0
A41: =Scenarios!A9 -> A_Repurpose_Both_ops | B41: FY2028 | C41: 0 | D41: =IF(MultiYear_ProForma!C39="FY2026", 0*Parameters_Public!$C$27, 0) -> 0 | E41: 0 | F41: 0 | G41: =SUM(D41:F41) -> 0
...

Sheet Control_Center
A1: Control center - yellow shaded fields are editable inputs
A3: Foundational inputs
B5: Parameter | C5: Value | H5: Notes
B6: MO inflation | C6: 0.025 | H6: Annual inflation factor.
B7: Base MO per ADM (FY25) | C7: 9936 | H7: "MO" = xx. Working base for FY25. Calculated from reported budget data and enrollment estimates - as relates to Echo Canyon and Pima only.
B8: Fixed share of MO | C8: 0.46 | H8: Share of MO treated as semi‑fixed (plant/insurance).
B9: Base State Aid per ADM (FY26) | C9: 5013 | H9: Editable; ADE base aid.
B10: Ops savings (keep‑open) | C10: 0.007 | H10: Light discipline if sites remain open (not used here).
B11: Extra savings (Co‑location) | C11: 0.015 | H11: Incremental savings for co‑location (not used here).
B12: Echo base ADM | C12: 257 | H12: "ADM" = average daily membership; roughly equivalent to enrollment. Approximate current Echo enrollment
B13: Pima base ADM | C13: 296 | H13: Approximate current Pima enrollment
B14: Total base ADM | C14: =C12+C13 -> 553 | H14: Echo base ADM + Pima base ADM
B15: Repurpose TI per closed site (FY26) | C15: 1200000 | H15: Research suggests a xx
B16: Retention r (in case of repurpose) | C16: 0.75 | H16: Research suggests a range in the 0.5-0.8 range. Since Echo is a choice school with high % of families from out of district, reality might be lower?
B17: MarginalFactor_for_Overlay | C17: 0.4 | H17: Assuming there is a reduced marginal cost of adding new (growth) students, especially when the schools (Echo and Pima) have capacity. In reality this is probably a complicated step function, but we can approximate.
A19: Repurpose trajectory assumptions
B21: Year | C21: h | D21: f_lease | E21: f_ops
B22: FY2026 | C22: 1000 | D22: 0.4 | E22: 0.5 | H22: (For 'h') Research suggests an incremental transition cost (largely related to bus transportation) that can start higher than $1000. Assumption is this is managed down over time
B23: FY2027 | C23: 800 | D23: 0.3 | E23: 0.4 | H23: (For 'f_lease') Assuming repurpose = lease… depending on lease timing and type / arrangement (e.g. triple net?), district will carry some percentage of fixed and semi-fixed costs for a certain period of time
B24: FY2028 | C24: 600 | D24: 0.2 | E24: 0.35 | H24: (For 'f_ops') Assuming repurpose = some operational repurpose (not lease or sale)… depending on timing and type of repurpose, district will still carry some percentage of fixed and semi-fixed costs
B25: FY2029 | C25: 500 | D25: 0.1 | E25: 0.3
B26: FY2030 | C26: 300 | D26: 0.1 | E26: 0.3
A28: Scenario assumptions
A30: (Reference) | B30: Scenario title | C30: TargetGrowth (#) | D30: CloseEcho (0 or 1) | E30: ClosePima (0 or 1) | F30: EchoShareGrowth (ratio) | G30: ExtraOpSavings (ratio)
A31: D. Grow Both (Overlay 0) | B31: CUSTOM_KeepOpen_v1 | C31: 0 | D31: 0 | E31: 0 | F31: 0.5 | G31: 0
A32: E. Status‑Quo + Targets (0) | B32: Status‑Quo + Op Growth Targets | C32: 150 | D32: 0 | E32: 0 | F32: 0.5 | G32: 0 | H32: Echo and Pima remain open; uplift warm handoff effort (intra-SUSD) and implement cross-district marketing initiative (e.g. capture ~10% of Kyrene's displaced families?)
A33: F. Co‑Location @ Echo (0) | B33: Co‑Location @ Echo + Op Growth Targets | C33: 150 | D33: 0 | E33: 0 | F33: 0.5 | G33: 0.05
A34: D. Grow Both (Overlay 100) | B34: Grow Both + Op Growth Targets | C34: 250 | D34: 0 | E34: 0 | F34: 0.5 | G34: 0
A35: D. Grow Both (Overlay 150) | B35: CUSTOM_KeepOpen_v2 | C35: 0 | D35: 0 | E35: 0 | F35: 0.5 | G35: 0
A36: G. D‑Hub @ Echo (Ramp 50→100→150) | B36: Growth Hub @ Echo + Status-Quo Pima + Op Growth Targets | C36: 150 | D36: 0 | E36: 0 | F36: 0.7 | G36: 0
A37: A. Repurpose BOTH (lease) | B37: Repurpose BOTH (lease) | C37: 0 | D37: 1 | E37: 1 | F37: 0.5 | G37: 0
A38: A. Repurpose BOTH (ops) | B38: Repurpose BOTH (ops) | C38: 0 | D38: 1 | E38: 1 | F38: 0.5 | G38: 0
A39: B. Repurpose ECHO (lease) | B39: Repurpose ECHO (lease) + Status-Quo Pima + Pima Op Growth Targets | C39: 0 | D39: 1 | E39: 0 | F39: 0 | G39: 0
A40: B. Repurpose ECHO (ops) | B40: Repurpose ECHO (ops) + Status-Quo Pima + Pima Op Growth Targets | C40: 150 | D40: 1 | E40: 0 | F40: 0 | G40: 0
A41: C. Repurpose PIMA (lease) | B41: Repurpose PIMA (lease) + Growth Hub @ Echo + Echo Op Growth Targets | C41: 0 | D41: 0 | E41: 1 | F41: 1 | G41: 0
A42: C. Repurpose PIMA (ops) | B42: Repurpose PIMA (ops) + Growth Hub @ Echo + Echo Op Growth Targets | C42: 200 | D42: 0 | E42: 1 | F42: 1 | G42: 0
A44: Qualitative assessment
B46: Scenario title | C46: Distinctiveness | D46: Reversibility | H46: Example qualitative metrics to consider. Possibly interesting as part of overall story.
B47: CUSTOM1 | C47: + | D47: Med
B48: Status‑Quo + Op Growth Targets | C48: o | D48: High
...

Sheet Dashboard
G1: Operational | I1: Qualitative | K1: Net figures ('revenue' - 'cost') | O1: Scenario net figures vs. Repurpose both (ops)
B2: ScenarioKey | C2: FY2028 Comparable $/Student | D2: FY2030 Comparable $/Student | E2: 3‑yr Avg Comparable $/Student (FY26–FY28) | F2: 5‑yr Avg Comparable $/Student (FY26–FY30) | G2: # Students displaced | H2: FY2030 # students served (open & retained) | I2: =Control_Center!C46 -> Distinctiveness | J2: =Control_Center!D46 -> Reversibility | K2: FY2028 Net ($) | L2: FY2030 Net ($) | M2: 5-yr Net Avg ($) | N2: (Ref) Control center labels | O2: Δ FY2030 Net ($) vs Repurpose BOTH (ops) | P2: Δ 5-yr Avg Net ($) vs Repurpose BOTH (ops)
B3: =Scenarios!A8 -> A_Repurpose_Both_lease | C3: =INDEX(MultiYear_ProForma!$X$2:$X$61, MATCH(Scenarios!A8&"|FY2028", MultiYear_ProForma!$AG$2:$AG$61, 0)) -> 8892.9481 | D3: =INDEX(MultiYear_ProForma!$X$2:$X$61, MATCH(Scenarios!A8&"|FY2030", MultiYear_ProForma!$AG$2:$AG$61, 0)) -> 8196.5996 | E3: =AVERAGE(INDEX(MultiYear_ProForma!$X$2:$X$61, MATCH(Scenarios!A8&"|FY2026", MultiYear_ProForma!$AG$2:$AG$61, 0)),INDEX(MultiYear_ProForma!$X$2:$X$61, MATCH(Scenarios!A8&"|FY2027", MultiYear_ProForma!$AG$2:$AG$61, 0)),INDEX(MultiYear_ProForma!$X$2:$X$61, MATCH(Scenarios!A8&"|FY2028", MultiYear_ProForma!$AG$2:$AG$61, 0))) -> 9637.9053 | F3: =AVERAGE(INDEX(MultiYear_ProForma!$X$2:$X$61, MATCH(Scenarios!A8&"|FY2026", MultiYear_ProForma!$AG$2:$AG$61, 0)),INDEX(MultiYear_ProForma!$X$2:$X$61, MATCH(Scenarios!A8&"|FY2027", MultiYear_ProForma!$AG$2:$AG$61, 0)),INDEX(MultiYear_ProForma!$X$2:$X$61, MATCH(Scenarios!A8&"|FY2028", MultiYear_ProForma!$AG$2:$AG$61, 0)),INDEX(MultiYear_ProForma!$X$2:$X$61, MATCH(Scenarios!A8&"|FY2029", MultiYear_ProForma!$AG$2:$AG$61, 0)),INDEX(MultiYear_ProForma!$X$2:$X$61, MATCH(Scenarios!A8&"|FY2030", MultiYear_ProForma!$AG$2:$AG$61, 0))) -> 9062.863 | G3: =IFERROR(VLOOKUP($B3&"|FY2026", MultiYear_ProForma!$A:$AG, 14, FALSE), "") -> 553 | H3: =IFERROR(VLOOKUP($B3&"|FY2030", MultiYear_ProForma!$A:$AG, 6, FALSE) + VLOOKUP($B3&"|FY2030", MultiYear_ProForma!$A:$AG, 15, FALSE), "") -> 405.8 | I3: =Control_Center!C48 -> o | J3: =Control_Center!D48 -> High | K3: =SUMIFS(MultiYear_ProForma!$AF:$AF, MultiYear_ProForma!$B:$B, $B3, MultiYear_ProForma!$C:$C, "FY2028") -> -1187156.9 | L3: =SUMIFS(MultiYear_ProForma!$AF:$AF, MultiYear_ProForma!$B:$B, $B3, MultiYear_ProForma!$C:$C, "FY2030") -> -819073.68 | M3: =(SUMIFS(MultiYear_ProForma!$AF:$AF, MultiYear_ProForma!$B:$B, $B3, MultiYear_ProForma!$C:$C, "FY2026")+SUMIFS(MultiYear_ProForma!$AF:$AF, MultiYear_ProForma!$B:$B, $B3, MultiYear_ProForma!$C:$C, "FY2027")+SUMIFS(MultiYear_ProForma!$AF:$AF, MultiYear_ProForma!$B:$B, $B3, MultiYear_ProForma!$C:$C, "FY2028")+SUMIFS(MultiYear_ProForma!$AF:$AF, MultiYear_ProForma!$B:$B, $B3, MultiYear_ProForma!$C:$C, "FY2029")+SUMIFS(MultiYear_ProForma!$AF:$AF, MultiYear_ProForma!$B:$B, $B3, MultiYear_ProForma!$C:$C, "FY2030"))/5 -> -1255278.3 | N3: =Control_Center!B37 -> Repurpose BOTH (lease) | O3: =L3 - INDEX(L:L, MATCH("A_Repurpose_Both_ops", $B:$B, 0)) -> 662410.94 | P3: =M3 - INDEX(M:M, MATCH("A_Repurpose_Both_ops", $B:$B, 0)) -> 477829.55
B4: =Scenarios!A13 -> C_Repurpose_Pima_ops_EchoGHub_EchoTargets | C4: =INDEX(MultiYear_ProForma!$X$2:$X$61, MATCH(Scenarios!A13&"|FY2028", MultiYear_ProForma!$AG$2:$AG$61, 0)) -> 9822.8713 | D4: =INDEX(MultiYear_ProForma!$X$2:$X$61, MATCH(Scenarios!A13&"|FY2030", MultiYear_ProForma!$AG$2:$AG$61, 0)) -> 10077.756 | E4: =AVERAGE(INDEX(MultiYear_ProForma!$X$2:$X$61, MATCH(Scenarios!A13&"|FY2026", MultiYear_ProForma!$AG$2:$AG$61, 0)),INDEX(MultiYear_ProForma!$X$2:$X$61, MATCH(Scenarios!A13&"|FY2027", MultiYear_ProForma!$AG$2:$AG$61, 0)),INDEX(MultiYear_ProForma!$X$2:$X$61, MATCH(Scenarios!A13&"|FY2028", MultiYear_ProForma!$AG$2:$AG$61, 0))) -> 9813.4525 | F4: =AVERAGE(INDEX(MultiYear_ProForma!$X$2:$X$61, MATCH(Scenarios!A13&"|FY2026", MultiYear_ProForma!$AG$2:$AG$61, 0)),INDEX(MultiYear_ProForma!$X$2:$X$61, MATCH(Scenarios!A13&"|FY2027", MultiYear_ProForma!$AG$2:$AG$61, 0)),INDEX(MultiYear_ProForma!$X$2:$X$61, MATCH(Scenarios!A13&"|FY2028", MultiYear_ProForma!$AG$2:$AG$61, 0)),INDEX(MultiYear_ProForma!$X$2:$X$61, MATCH(Scenarios!A13&"|FY2029", MultiYear_ProForma!$AG$2:$AG$61, 0)),INDEX(MultiYear_ProForma!$X$2:$X$61, MATCH(Scenarios!A13&"|FY2030", MultiYear_ProForma!$AG$2:$AG$61, 0))) -> 9884.7364 | G4: =IFERROR(VLOOKUP($B4&"|FY2026", MultiYear_ProForma!$A:$AG, 14, FALSE), "") -> 296 | H4: =IFERROR(VLOOKUP($B4&"|FY2030", MultiYear_ProForma!$A:$AG, 6, FALSE) + VLOOKUP($B4&"|FY2030", MultiYear_ProForma!$A:$AG, 15, FALSE), "") -> 708.6 | I4: =Control_Center!C47 -> + | J4: =Control_Center!D47 -> Med | K4: =SUMIFS(MultiYear_ProForma!$AF:$AF, MultiYear_ProForma!$B:$B, $B4, MultiYear_ProForma!$C:$C, "FY2028") -> -1928885.1 | L4: =SUMIFS(MultiYear_ProForma!$AF:$AF, MultiYear_ProForma!$B:$B, $B4, MultiYear_ProForma!$C:$C, "FY2030") -> -1919535 | M4: =(SUMIFS(MultiYear_ProForma!$AF:$AF, MultiYear_ProForma!$B:$B, $B4, MultiYear_ProForma!$C:$C, "FY2026")+SUMIFS(MultiYear_ProForma!$AF:$AF, MultiYear_ProForma!$B:$B, $B4, MultiYear_ProForma!$C:$C, "FY2027")+SUMIFS(MultiYear_ProForma!$AF:$AF, MultiYear_ProForma!$B:$B, $B4, MultiYear_ProForma!$C:$C, "FY2028")+SUMIFS(MultiYear_ProForma!$AF:$AF, MultiYear_ProForma!$B:$B, $B4, MultiYear_ProForma!$C:$C, "FY2029")+SUMIFS(MultiYear_ProForma!$AF:$AF, MultiYear_ProForma!$B:$B, $B4, MultiYear_ProForma!$C:$C, "FY2030"))/5 -> -1970783.6 | N4: =Control_Center!B42 -> Repurpose PIMA (ops) + Growth Hub @ Echo + Echo Op Growth Targets | O4: =L4 - INDEX(L:L, MATCH("A_Repurpose_Both_ops", $B:$B, 0)) -> -438050.41 | P4: =M4 - INDEX(M:M, MATCH("A_Repurpose_Both_ops", $B:$B, 0)) -> -237675.71
B5: =Scenarios!A4 -> F_CoLocation_Echo_Targets | C5: =INDEX(MultiYear_ProForma!$X$2:$X$61, MATCH(Scenarios!A4&"|FY2028", MultiYear_ProForma!$AG$2:$AG$61, 0)) -> 10617.551 | D5: =INDEX(MultiYear_ProForma!$X$2:$X$61, MATCH(Scenarios!A4&"|FY2030", MultiYear_ProForma!$AG$2:$AG$61, 0)) -> 11155.064 | E5: =AVERAGE(INDEX(MultiYear_ProForma!$X$2:$X$61, MATCH(Scenarios!A4&"|FY2026", MultiYear_ProForma!$AG$2:$AG$61, 0)),INDEX(MultiYear_ProForma!$X$2:$X$61, MATCH(Scenarios!A4&"|FY2027", MultiYear_ProForma!$AG$2:$AG$61, 0)),INDEX(MultiYear_ProForma!$X$2:$X$61, MATCH(Scenarios!A4&"|FY2028", MultiYear_ProForma!$AG$2:$AG$61, 0))) -> 10360.692 | F5: =AVERAGE(INDEX(MultiYear_ProForma!$X$2:$X$61, MATCH(Scenarios!A4&"|FY2026", MultiYear_ProForma!$AG$2:$AG$61, 0)),INDEX(MultiYear_ProForma!$X$2:$X$61, MATCH(Scenarios!A4&"|FY2027", MultiYear_ProForma!$AG$2:$AG$61, 0)),INDEX(MultiYear_ProForma!$X$2:$X$61, MATCH(Scenarios!A4&"|FY2028", MultiYear_ProForma!$AG$2:$AG$61, 0)),INDEX(MultiYear_ProForma!$X$2:$X$61, MATCH(Scenarios!A4&"|FY2029", MultiYear_ProForma!$AG$2:$AG$61, 0)),INDEX(MultiYear_ProForma!$X$2:$X$61, MATCH(Scenarios!A4&"|FY2030", MultiYear_ProForma!$AG$2:$AG$61, 0))) -> 10624.026 | G5: =IFERROR(VLOOKUP($B5&"|FY2026", MultiYear_ProForma!$A:$AG, 14, FALSE), "") -> 0 | H5: =IFERROR(VLOOKUP($B5&"|FY2030", MultiYear_ProForma!$A:$AG, 6, FALSE) + VLOOKUP($B5&"|FY2030", MultiYear_ProForma!$A:$AG, 15, FALSE), "") -> 703 | I5: =Control_Center!C50 -> ++ | J5: =Control_Center!D50 -> Med | K5: =SUMIFS(MultiYear_ProForma!$AF:$AF, MultiYear_ProForma!$B:$B, $B5, MultiYear_ProForma!$C:$C, "FY2028") -> -2696831 | L5: =SUMIFS(MultiYear_ProForma!$AF:$AF, MultiYear_ProForma!$B:$B, $B5, MultiYear_ProForma!$C:$C, "FY2030") -> -2897609.6 | M5: =(SUMIFS(MultiYear_ProForma!$AF:$AF, MultiYear_ProForma!$B:$B, $B5, MultiYear_ProForma!$C:$C, "FY2026")+SUMIFS(MultiYear_ProForma!$AF:$AF, MultiYear_ProForma!$B:$B, $B5, MultiYear_ProForma!$C:$C, "FY2027")+SUMIFS(MultiYear_ProForma!$AF:$AF, MultiYear_ProForma!$B:$B, $B5, MultiYear_ProForma!$C:$C, "FY2028")+SUMIFS(MultiYear_ProForma!$AF:$AF, MultiYear_ProForma!$B:$B, $B5, MultiYear_ProForma!$C:$C, "FY2029")+SUMIFS(MultiYear_ProForma!$AF:$AF, MultiYear_ProForma!$B:$B, $B5, MultiYear_ProForma!$C:$C, "FY2030"))/5 -> -2699596 | N5: =Control_Center!B33 -> Co‑Location @ Echo + Op Growth Targets | O5: =L5 - INDEX(L:L, MATCH("A_Repurpose_Both_ops", $B:$B, 0)) -> -1416125 | P5: =M5 - INDEX(M:M, MATCH("A_Repurpose_Both_ops", $B:$B, 0)) -> -966488.1
B6: =Scenarios!A9 -> A_Repurpose_Both_ops | C6: =INDEX(MultiYear_ProForma!$X$2:$X$61, MATCH(Scenarios!A9&"|FY2028", MultiYear_ProForma!$AG$2:$AG$61, 0)) -> 10058.225 | D6: =INDEX(MultiYear_ProForma!$X$2:$X$61, MATCH(Scenarios!A9&"|FY2030", MultiYear_ProForma!$AG$2:$AG$61, 0)) -> 9828.9577 | E6: =AVERAGE(INDEX(MultiYear_ProForma!$X$2:$X$61, MATCH(Scenarios!A9&"|FY2026", MultiYear_ProForma!$AG$2:$AG$61, 0)),INDEX(MultiYear_ProForma!$X$2:$X$61, MATCH(Scenarios!A9&"|FY2027", MultiYear_ProForma!$AG$2:$AG$61, 0)),INDEX(MultiYear_ProForma!$X$2:$X$61, MATCH(Scenarios!A9&"|FY2028", MultiYear_ProForma!$AG$2:$AG$61, 0))) -> 10525.438 | F6: =AVERAGE(INDEX(MultiYear_ProForma!$X$2:$X$61, MATCH(Scenarios!A9&"|FY2026", MultiYear_ProForma!$AG$2:$AG$61, 0)),INDEX(MultiYear_ProForma!$X$2:$X$61, MATCH(Scenarios!A9&"|FY2027", MultiYear_ProForma!$AG$2:$AG$61, 0)),INDEX(MultiYear_ProForma!$X$2:$X$61, MATCH(Scenarios!A9&"|FY2028", MultiYear_ProForma!$AG$2:$AG$61, 0)),INDEX(MultiYear_ProForma!$X$2:$X$61, MATCH(Scenarios!A9&"|FY2029", MultiYear_ProForma!$AG$2:$AG$61, 0)),INDEX(MultiYear_ProForma!$X$2:$X$61, MATCH(Scenarios!A9&"|FY2030", MultiYear_ProForma!$AG$2:$AG$61, 0))) -> 10240.363 | G6: =IFERROR(VLOOKUP($B6&"|FY2026", MultiYear_ProForma!$A:$AG, 14, FALSE), "") -> 553 | H6: =IFERROR(VLOOKUP($B6&"|FY2030", MultiYear_ProForma!$A:$AG, 6, FALSE) + VLOOKUP($B6&"|FY2030", MultiYear_ProForma!$A:$AG, 15, FALSE), "") -> 405.8 | I6: =Control_Center!C52 -> ++ | J6: =Control_Center!D52 -> Med | K6: =SUMIFS(MultiYear_ProForma!$AF:$AF, MultiYear_ProForma!$B:$B, $B6, MultiYear_ProForma!$C:$C, "FY2028") -> -1660026.1 | L6: =SUMIFS(MultiYear_ProForma!$AF:$AF, MultiYear_ProForma!$B:$B, $B6, MultiYear_ProForma!$C:$C, "FY2030") -> -1481484.6 | M6: =(SUMIFS(MultiYear_ProForma!$AF:$AF, MultiYear_ProForma!$B:$B, $B6, MultiYear_ProForma!$C:$C, "FY2026")+SUMIFS(MultiYear_ProForma!$AF:$AF, MultiYear_ProForma!$B:$B, $B6, MultiYear_ProForma!$C:$C, "FY2027")+SUMIFS(MultiYear_ProForma!$AF:$AF, MultiYear_ProForma!$B:$B, $B6, MultiYear_ProForma!$C:$C, "FY2028")+SUMIFS(MultiYear_ProForma!$AF:$AF, MultiYear_ProForma!$B:$B, $B6, MultiYear_ProForma!$C:$C, "FY2029")+SUMIFS(MultiYear_ProForma!$AF:$AF, MultiYear_ProForma!$B:$B, $B6, MultiYear_ProForma!$C:$C, "FY2030"))/5 -> -1733107.9 | N6: =Control_Center!B38 -> Repurpose BOTH (ops) | O6: =L6 - INDEX(L:L, MATCH("A_Repurpose_Both_ops", $B:$B, 0)) -> 0 | P6: =M6 - INDEX(M:M, MATCH("A_Repurpose_Both_ops", $B:$B, 0)) -> 0
B7: =Scenarios!A11 -> B_Repurpose_Echo_ops_PimaTargets | C7: =INDEX(MultiYear_ProForma!$X$2:$X$61, MATCH(Scenarios!A11&"|FY2028", MultiYear_ProForma!$AG$2:$AG$61, 0)) -> 10524.063 | D7: =INDEX(MultiYear_ProForma!$X$2:$X$61, MATCH(Scenarios!A11&"|FY2030", MultiYear_ProForma!$AG$2:$AG$61, 0)) -> 10843.739 | E7: =AVERAGE(INDEX(MultiYear_ProForma!$X$2:$X$61, MATCH(Scenarios!A11&"|FY2026", MultiYear_ProForma!$AG$2:$AG$61, 0)),INDEX(MultiYear_ProForma!$X$2:$X$61, MATCH(Scenarios!A11&"|FY2027", MultiYear_ProForma!$AG$2:$AG$61, 0)),INDEX(MultiYear_ProForma!$X$2:$X$61, MATCH(Scenarios!A11&"|FY2028", MultiYear_ProForma!$AG$2:$AG$61, 0))) -> 10480.436 | F7: =AVERAGE(INDEX(MultiYear_ProForma!$X$2:$X$61, MATCH(Scenarios!A11&"|FY2026", MultiYear_ProForma!$AG$2:$AG$61, 0)),INDEX(MultiYear_ProForma!$X$2:$X$61, MATCH(Scenarios!A11&"|FY2027", MultiYear_ProForma!$AG$2:$AG$61, 0)),INDEX(MultiYear_ProForma!$X$2:$X$61, MATCH(Scenarios!A11&"|FY2028", MultiYear_ProForma!$AG$2:$AG$61, 0)),INDEX(MultiYear_ProForma!$X$2:$X$61, MATCH(Scenarios!A11&"|FY2029", MultiYear_ProForma!$AG$2:$AG$61, 0)),INDEX(MultiYear_ProForma!$X$2:$X$61, MATCH(Scenarios!A11&"|FY2030", MultiYear_ProForma!$AG$2:$AG$61, 0))) -> 10583.513 | G7: =IFERROR(VLOOKUP($B7&"|FY2026", MultiYear_ProForma!$A:$AG, 14, FALSE), "") -> 257 | H7: =IFERROR(VLOOKUP($B7&"|FY2030", MultiYear_ProForma!$A:$AG, 6, FALSE) + VLOOKUP($B7&"|FY2030", MultiYear_ProForma!$A:$AG, 15, FALSE), "") -> 600.2 | I7: =Control_Center!C49 -> ++ | J7: =Control_Center!D49 -> Med | K7: =SUMIFS(MultiYear_ProForma!$AF:$AF, MultiYear_ProForma!$B:$B, $B7, MultiYear_ProForma!$C:$C, "FY2028") -> -2132577.8 | L7: =SUMIFS(MultiYear_ProForma!$AF:$AF, MultiYear_ProForma!$B:$B, $B7, MultiYear_ProForma!$C:$C, "FY2030") -> -2167489.8 | M7: =(SUMIFS(MultiYear_ProForma!$AF:$AF, MultiYear_ProForma!$B:$B, $B7, MultiYear_ProForma!$C:$C, "FY2026")+SUMIFS(MultiYear_ProForma!$AF:$AF, MultiYear_ProForma!$B:$B, $B7, MultiYear_ProForma!$C:$C, "FY2027")+SUMIFS(MultiYear_ProForma!$AF:$AF, MultiYear_ProForma!$B:$B, $B7, MultiYear_ProForma!$C:$C, "FY2028")+SUMIFS(MultiYear_ProForma!$AF:$AF, MultiYear_ProForma!$B:$B, $B7, MultiYear_ProForma!$C:$C, "FY2029")+SUMIFS(MultiYear_ProForma!$AF:$AF, MultiYear_ProForma!$B:$B, $B7, MultiYear_ProForma!$C:$C, "FY2030"))/5 -> -2166664.6 | N7: =Control_Center!B40 -> Repurpose ECHO (ops) + Status-Quo Pima + Pima Op Growth Targets | O7: =L7 - INDEX(L:L, MATCH("A_Repurpose_Both_ops", $B:$B, 0)) -> -686005.22 | P7: =M7 - INDEX(M:M, MATCH("A_Repurpose_Both_ops", $B:$B, 0)) -> -433556.71
B8: =Scenarios!A5 -> D_Grow_Both_Targets | C8: =INDEX(MultiYear_ProForma!$X$2:$X$61, MATCH(Scenarios!A5&"|FY2028", MultiYear_ProForma!$AG$2:$AG$61, 0)) -> 10617.926 | D8: =INDEX(MultiYear_ProForma!$X$2:$X$61, MATCH(Scenarios!A5&"|FY2030", MultiYear_ProForma!$AG$2:$AG$61, 0)) -> 11155.459 | E8: =AVERAGE(INDEX(MultiYear_ProForma!$X$2:$X$61, MATCH(Scenarios!A5&"|FY2026", MultiYear_ProForma!$AG$2:$AG$61, 0)),INDEX(MultiYear_ProForma!$X$2:$X$61, MATCH(Scenarios!A5&"|FY2027", MultiYear_ProForma!$AG$2:$AG$61, 0)),INDEX(MultiYear_ProForma!$X$2:$X$61, MATCH(Scenarios!A5&"|FY2028", MultiYear_ProForma!$AG$2:$AG$61, 0))) -> 10361.058 | F8: =AVERAGE(INDEX(MultiYear_ProForma!$X$2:$X$61, MATCH(Scenarios!A5&"|FY2026", MultiYear_ProForma!$AG$2:$AG$61, 0)),INDEX(MultiYear_ProForma!$X$2:$X$61, MATCH(Scenarios!A5&"|FY2027", MultiYear_ProForma!$AG$2:$AG$61, 0)),INDEX(MultiYear_ProForma!$X$2:$X$61, MATCH(Scenarios!A5&"|FY2028", MultiYear_ProForma!$AG$2:$AG$61, 0)),INDEX(MultiYear_ProForma!$X$2:$X$61, MATCH(Scenarios!A5&"|FY2029", MultiYear_ProForma!$AG$2:$AG$61, 0)),INDEX(MultiYear_ProForma!$X$2:$X$61, MATCH(Scenarios!A5&"|FY2030", MultiYear_ProForma!$AG$2:$AG$61, 0))) -> 10624.401 | G8: =IFERROR(VLOOKUP($B8&"|FY2026", MultiYear_ProForma!$A:$AG, 14, FALSE), "") -> 0 | H8: =IFERROR(VLOOKUP($B8&"|FY2030", MultiYear_ProForma!$A:$AG, 6, FALSE) + VLOOKUP($B8&"|FY2030", MultiYear_ProForma!$A:$AG, 15, FALSE), "") -> 803 | I8: =Control_Center!C56 -> o | J8: =Control_Center!D56 -> Low-Med | K8: =SUMIFS(MultiYear_ProForma!$AF:$AF, MultiYear_ProForma!$B:$B, $B8, MultiYear_ProForma!$C:$C, "FY2028") -> -2730501.4 | L8: =SUMIFS(MultiYear_ProForma!$AF:$AF, MultiYear_ProForma!$B:$B, $B8, MultiYear_ProForma!$C:$C, "FY2030") -> -2942124.2 | M8: =(SUMIFS(MultiYear_ProForma!$AF:$AF, MultiYear_ProForma!$B:$B, $B8, MultiYear_ProForma!$C:$C, "FY2026")+SUMIFS(MultiYear_ProForma!$AF:$AF, MultiYear_ProForma!$B:$B, $B8, MultiYear_ProForma!$C:$C, "FY2027")+SUMIFS(MultiYear_ProForma!$AF:$AF, MultiYear_ProForma!$B:$B, $B8, MultiYear_ProForma!$C:$C, "FY2028")+SUMIFS(MultiYear_ProForma!$AF:$AF, MultiYear_ProForma!$B:$B, $B8, MultiYear_ProForma!$C:$C, "FY2029")+SUMIFS(MultiYear_ProForma!$AF:$AF, MultiYear_ProForma!$B:$B, $B8, MultiYear_ProForma!$C:$C, "FY2030"))/5 -> -2733446.3 | N8: =Control_Center!B34 -> Grow Both + Op Growth Targets | O8: =L8 - INDEX(L:L, MATCH("A_Repurpose_Both_ops", $B:$B, 0)) -> -1460639.6 | P8: =M8 - INDEX(M:M, MATCH("A_Repurpose_Both_ops", $B:$B, 0)) -> -1000338.4
B9: =Scenarios!A12 -> C_Repurpose_Pima_lease_EchoGHub_EchoTargets | C9: =INDEX(MultiYear_ProForma!$X$2:$X$61, MATCH(Scenarios!A12&"|FY2028", MultiYear_ProForma!$AG$2:$AG$61, 0)) -> 10556.357 | D9: =INDEX(MultiYear_ProForma!$X$2:$X$61, MATCH(Scenarios!A12&"|FY2030", MultiYear_ProForma!$AG$2:$AG$61, 0)) -> 10578.771 | E9: =AVERAGE(INDEX(MultiYear_ProForma!$X$2:$X$61, MATCH(Scenarios!A12&"|FY2026", MultiYear_ProForma!$AG$2:$AG$61, 0)),INDEX(MultiYear_ProForma!$X$2:$X$61, MATCH(Scenarios!A12&"|FY2027", MultiYear_ProForma!$AG$2:$AG$61, 0)),INDEX(MultiYear_ProForma!$X$2:$X$61, MATCH(Scenarios!A12&"|FY2028", MultiYear_ProForma!$AG$2:$AG$61, 0))) -> 10725.514 | F9: =AVERAGE(INDEX(MultiYear_ProForma!$X$2:$X$61, MATCH(Scenarios!A12&"|FY2026", MultiYear_ProForma!$AG$2:$AG$61, 0)),INDEX(MultiYear_ProForma!$X$2:$X$61, MATCH(Scenarios!A12&"|FY2027", MultiYear_ProForma!$AG$2:$AG$61, 0)),INDEX(MultiYear_ProForma!$X$2:$X$61, MATCH(Scenarios!A12&"|FY2028", MultiYear_ProForma!$AG$2:$AG$61, 0)),INDEX(MultiYear_ProForma!$X$2:$X$61, MATCH(Scenarios!A12&"|FY2029", MultiYear_ProForma!$AG$2:$AG$61, 0)),INDEX(MultiYear_ProForma!$X$2:$X$61, MATCH(Scenarios!A12&"|FY2030", MultiYear_ProForma!$AG$2:$AG$61, 0))) -> 10635.725 | G9: =IFERROR(VLOOKUP($B9&"|FY2026", MultiYear_ProForma!$A:$AG, 14, FALSE), "") -> 296 | H9: =IFERROR(VLOOKUP($B9&"|FY2030", MultiYear_ProForma!$A:$AG, 6, FALSE) + VLOOKUP($B9&"|FY2030", MultiYear_ProForma!$A:$AG, 15, FALSE), "") -> 508.6 | I9: =Control_Center!C53 -> -- | J9: =Control_Center!D53 -> Low | K9: =SUMIFS(MultiYear_ProForma!$AF:$AF, MultiYear_ProForma!$B:$B, $B9, MultiYear_ProForma!$C:$C, "FY2028") -> -2333905.4 | L9: =SUMIFS(MultiYear_ProForma!$AF:$AF, MultiYear_ProForma!$B:$B, $B9, MultiYear_ProForma!$C:$C, "FY2030") -> -2238139.4 | M9: =(SUMIFS(MultiYear_ProForma!$AF:$AF, MultiYear_ProForma!$B:$B, $B9, MultiYear_ProForma!$C:$C, "FY2026")+SUMIFS(MultiYear_ProForma!$AF:$AF, MultiYear_ProForma!$B:$B, $B9, MultiYear_ProForma!$C:$C, "FY2027")+SUMIFS(MultiYear_ProForma!$AF:$AF, MultiYear_ProForma!$B:$B, $B9, MultiYear_ProForma!$C:$C, "FY2028")+SUMIFS(MultiYear_ProForma!$AF:$AF, MultiYear_ProForma!$B:$B, $B9, MultiYear_ProForma!$C:$C, "FY2029")+SUMIFS(MultiYear_ProForma!$AF:$AF, MultiYear_ProForma!$B:$B, $B9, MultiYear_ProForma!$C:$C, "FY2030"))/5 -> -2373231.4 | N9: =Control_Center!B41 -> Repurpose PIMA (lease) + Growth Hub @ Echo + Echo Op Growth Targets | O9: =L9 - INDEX(L:L, MATCH("A_Repurpose_Both_ops", $B:$B, 0)) -> -756654.75 | P9: =M9 - INDEX(M:M, MATCH("A_Repurpose_Both_ops", $B:$B, 0)) -> -640123.55
B10: =Scenarios!A10 -> B_Repurpose_Echo_lease_PimaTargets | C10: =INDEX(MultiYear_ProForma!$X$2:$X$61, MATCH(Scenarios!A10&"|FY2028", MultiYear_ProForma!$AG$2:$AG$61, 0)) -> 11312.687 | D10: =INDEX(MultiYear_ProForma!$X$2:$X$61, MATCH(Scenarios!A10&"|FY2030", MultiYear_ProForma!$AG$2:$AG$61, 0)) -> 11430.333 | E10: =AVERAGE(INDEX(MultiYear_ProForma!$X$2:$X$61, MATCH(Scenarios!A10&"|FY2026", MultiYear_ProForma!$AG$2:$AG$61, 0)),INDEX(MultiYear_ProForma!$X$2:$X$61, MATCH(Scenarios!A10&"|FY2027", MultiYear_ProForma!$AG$2:$AG$61, 0)),INDEX(MultiYear_ProForma!$X$2:$X$61, MATCH(Scenarios!A10&"|FY2028", MultiYear_ProForma!$AG$2:$AG$61, 0))) -> 11424.812 | F10: =AVERAGE(INDEX(MultiYear_ProForma!$X$2:$X$61, MATCH(Scenarios!A10&"|FY2026", MultiYear_ProForma!$AG$2:$AG$61, 0)),INDEX(MultiYear_ProForma!$X$2:$X$61, MATCH(Scenarios!A10&"|FY2027", MultiYear_ProForma!$AG$2:$AG$61, 0)),INDEX(MultiYear_ProForma!$X$2:$X$61, MATCH(Scenarios!A10&"|FY2028", MultiYear_ProForma!$AG$2:$AG$61, 0)),INDEX(MultiYear_ProForma!$X$2:$X$61, MATCH(Scenarios!A10&"|FY2029", MultiYear_ProForma!$AG$2:$AG$61, 0)),INDEX(MultiYear_ProForma!$X$2:$X$61, MATCH(Scenarios!A10&"|FY2030", MultiYear_ProForma!$AG$2:$AG$61, 0))) -> 11385.465 | G10: =IFERROR(VLOOKUP($B10&"|FY2026", MultiYear_ProForma!$A:$AG, 14, FALSE), "") -> 257 | H10: =IFERROR(VLOOKUP($B10&"|FY2030", MultiYear_ProForma!$A:$AG, 6, FALSE) + VLOOKUP($B10&"|FY2030", MultiYear_ProForma!$A:$AG, 15, FALSE), "") -> 450.2 | I10: =Control_Center!C54 -> - | J10: =Control_Center!D54 -> Low-Med | K10: =SUMIFS(MultiYear_ProForma!$AF:$AF, MultiYear_ProForma!$B:$B, $B10, MultiYear_ProForma!$C:$C, "FY2028") -> -2406414.6 | L10: =SUMIFS(MultiYear_ProForma!$AF:$AF, MultiYear_ProForma!$B:$B, $B10, MultiYear_ProForma!$C:$C, "FY2030") -> -2364518.4 | M10: =(SUMIFS(MultiYear_ProForma!$AF:$AF, MultiYear_ProForma!$B:$B, $B10, MultiYear_ProForma!$C:$C, "FY2026")+SUMIFS(MultiYear_ProForma!$AF:$AF, MultiYear_ProForma!$B:$B, $B10, MultiYear_ProForma!$C:$C, "FY2027")+SUMIFS(MultiYear_ProForma!$AF:$AF, MultiYear_ProForma!$B:$B, $B10, MultiYear_ProForma!$C:$C, "FY2028")+SUMIFS(MultiYear_ProForma!$AF:$AF, MultiYear_ProForma!$B:$B, $B10, MultiYear_ProForma!$C:$C, "FY2029")+SUMIFS(MultiYear_ProForma!$AF:$AF, MultiYear_ProForma!$B:$B, $B10, MultiYear_ProForma!$C:$C, "FY2030"))/5 -> -2438258.1 | N10: =Control_Center!B39 -> Repurpose ECHO (lease) + Status-Quo Pima + Pima Op Growth Targets | O10: =L10 - INDEX(L:L, MATCH("A_Repurpose_Both_ops", $B:$B, 0)) -> -883033.74 | P10: =M10 - INDEX(M:M, MATCH("A_Repurpose_Both_ops", $B:$B, 0)) -> -705150.21
B11: =Scenarios!A3 -> E_StatusQuo_Targets | C11: =INDEX(MultiYear_ProForma!$X$2:$X$61, MATCH(Scenarios!A3&"|FY2028", MultiYear_ProForma!$AG$2:$AG$61, 0)) -> 11176.369 | D11: =INDEX(MultiYear_ProForma!$X$2:$X$61, MATCH(Scenarios!A3&"|FY2030", MultiYear_ProForma!$AG$2:$AG$61, 0)) -> 11742.173 | E11: =AVERAGE(INDEX(MultiYear_ProForma!$X$2:$X$61, MATCH(Scenarios!A3&"|FY2026", MultiYear_ProForma!$AG$2:$AG$61, 0)),INDEX(MultiYear_ProForma!$X$2:$X$61, MATCH(Scenarios!A3&"|FY2027", MultiYear_ProForma!$AG$2:$AG$61, 0)),INDEX(MultiYear_ProForma!$X$2:$X$61, MATCH(Scenarios!A3&"|FY2028", MultiYear_ProForma!$AG$2:$AG$61, 0))) -> 10905.991 | F11: =AVERAGE(INDEX(MultiYear_ProForma!$X$2:$X$61, MATCH(Scenarios!A3&"|FY2026", MultiYear_ProForma!$AG$2:$AG$61, 0)),INDEX(MultiYear_ProForma!$X$2:$X$61, MATCH(Scenarios!A3&"|FY2027", MultiYear_ProForma!$AG$2:$AG$61, 0)),INDEX(MultiYear_ProForma!$X$2:$X$61, MATCH(Scenarios!A3&"|FY2028", MultiYear_ProForma!$AG$2:$AG$61, 0)),INDEX(MultiYear_ProForma!$X$2:$X$61, MATCH(Scenarios!A3&"|FY2029", MultiYear_ProForma!$AG$2:$AG$61, 0)),INDEX(MultiYear_ProForma!$X$2:$X$61, MATCH(Scenarios!A3&"|FY2030", MultiYear_ProForma!$AG$2:$AG$61, 0))) -> 11183.185 | G11: =IFERROR(VLOOKUP($B11&"|FY2026", MultiYear_ProForma!$A:$AG, 14, FALSE), "") -> 0 | H11: =IFERROR(VLOOKUP($B11&"|FY2030", MultiYear_ProForma!$A:$AG, 6, FALSE) + VLOOKUP($B11&"|FY2030", MultiYear_ProForma!$A:$AG, 15, FALSE), "") -> 703 | I11: =Control_Center!C58 -> o | J11: =Control_Center!D58 -> Low-Med | K11: =SUMIFS(MultiYear_ProForma!$AF:$AF, MultiYear_ProForma!$B:$B, $B11, MultiYear_ProForma!$C:$C, "FY2028") -> -3059566.1 | L11: =SUMIFS(MultiYear_ProForma!$AF:$AF, MultiYear_ProForma!$B:$B, $B11, MultiYear_ProForma!$C:$C, "FY2030") -> -3278708.1 | M11: =(SUMIFS(MultiYear_ProForma!$AF:$AF, MultiYear_ProForma!$B:$B, $B11, MultiYear_ProForma!$C:$C, "FY2026")+SUMIFS(MultiYear_ProForma!$AF:$AF, MultiYear_ProForma!$B:$B, $B11, MultiYear_ProForma!$C:$C, "FY2027")+SUMIFS(MultiYear_ProForma!$AF:$AF, MultiYear_ProForma!$B:$B, $B11, MultiYear_ProForma!$C:$C, "FY2028")+SUMIFS(MultiYear_ProForma!$AF:$AF, MultiYear_ProForma!$B:$B, $B11, MultiYear_ProForma!$C:$C, "FY2029")+SUMIFS(MultiYear_ProForma!$AF:$AF, MultiYear_ProForma!$B:$B, $B11, MultiYear_ProForma!$C:$C, "FY2030"))/5 -> -3062552.2 | N11: =Control_Center!B32 -> Status‑Quo + Op Growth Targets | O11: =L11 - INDEX(L:L, MATCH("A_Repurpose_Both_ops", $B:$B, 0)) -> -1797223.5 | P11: =M11 - INDEX(M:M, MATCH("A_Repurpose_Both_ops", $B:$B, 0)) -> -1329444.4
B12: =Scenarios!A7 -> G_EchoGHubRamp_PimaTargets | C12: =INDEX(MultiYear_ProForma!$X$2:$X$61, MATCH(Scenarios!A7&"|FY2028", MultiYear_ProForma!$AG$2:$AG$61, 0)) -> 11176.369 | D12: =INDEX(MultiYear_ProForma!$X$2:$X$61, MATCH(Scenarios!A7&"|FY2030", MultiYear_ProForma!$AG$2:$AG$61, 0)) -> 11742.173 | E12: =AVERAGE(INDEX(MultiYear_ProForma!$X$2:$X$61, MATCH(Scenarios!A7&"|FY2026", MultiYear_ProForma!$AG$2:$AG$61, 0)),INDEX(MultiYear_ProForma!$X$2:$X$61, MATCH(Scenarios!A7&"|FY2027", MultiYear_ProForma!$AG$2:$AG$61, 0)),INDEX(MultiYear_ProForma!$X$2:$X$61, MATCH(Scenarios!A7&"|FY2028", MultiYear_ProForma!$AG$2:$AG$61, 0))) -> 11253.597 | F12: =AVERAGE(INDEX(MultiYear_ProForma!$X$2:$X$61, MATCH(Scenarios!A7&"|FY2026", MultiYear_ProForma!$AG$2:$AG$61, 0)),INDEX(MultiYear_ProForma!$X$2:$X$61, MATCH(Scenarios!A7&"|FY2027", MultiYear_ProForma!$AG$2:$AG$61, 0)),INDEX(MultiYear_ProForma!$X$2:$X$61, MATCH(Scenarios!A7&"|FY2028", MultiYear_ProForma!$AG$2:$AG$61, 0)),INDEX(MultiYear_ProForma!$X$2:$X$61, MATCH(Scenarios!A7&"|FY2029", MultiYear_ProForma!$AG$2:$AG$61, 0)),INDEX(MultiYear_ProForma!$X$2:$X$61, MATCH(Scenarios!A7&"|FY2030", MultiYear_ProForma!$AG$2:$AG$61, 0))) -> 11391.748 | G12: =IFERROR(VLOOKUP($B12&"|FY2026", MultiYear_ProForma!$A:$AG, 14, FALSE), "") -> 0 | H12: =IFERROR(VLOOKUP($B12&"|FY2030", MultiYear_ProForma!$A:$AG, 6, FALSE) + VLOOKUP($B12&"|FY2030", MultiYear_ProForma!$A:$AG, 15, FALSE), "") -> 703 | I12: =Control_Center!C55 -> - | J12: =Control_Center!D55 -> Low-Med | K12: =SUMIFS(MultiYear_ProForma!$AF:$AF, MultiYear_ProForma!$B:$B, $B12, MultiYear_ProForma!$C:$C, "FY2028") -> -3059566.1 | L12: =SUMIFS(MultiYear_ProForma!$AF:$AF, MultiYear_ProForma!$B:$B, $B12, MultiYear_ProForma!$C:$C, "FY2030") -> -3278708.1 | M12: =(SUMIFS(MultiYear_ProForma!$AF:$AF, MultiYear_ProForma!$B:$B, $B12, MultiYear_ProForma!$C:$C, "FY2026")+SUMIFS(MultiYear_ProForma!$AF:$AF, MultiYear_ProForma!$B:$B, $B12, MultiYear_ProForma!$C:$C, "FY2027")+SUMIFS(MultiYear_ProForma!$AF:$AF, MultiYear_ProForma!$B:$B, $B12, MultiYear_ProForma!$C:$C, "FY2028")+SUMIFS(MultiYear_ProForma!$AF:$AF, MultiYear_ProForma!$B:$B, $B12, MultiYear_ProForma!$C:$C, "FY2029")+SUMIFS(MultiYear_ProForma!$AF:$AF, MultiYear_ProForma!$B:$B, $B12, MultiYear_ProForma!$C:$C, "FY2030"))/5 -> -3159431.1 | N12: =Control_Center!B36 -> Growth Hub @ Echo + Status-Quo Pima + Op Growth Targets | O12: =L12 - INDEX(L:L, MATCH("A_Repurpose_Both_ops", $B:$B, 0)) -> -1797223.5 | P12: =M12 - INDEX(M:M, MATCH("A_Repurpose_Both_ops", $B:$B, 0)) -> -1426323.2
B13: =Scenarios!A6 -> D_CUSTOM2 | C13: =INDEX(MultiYear_ProForma!$X$2:$X$61, MATCH(Scenarios!A6&"|FY2028", MultiYear_ProForma!$AG$2:$AG$61, 0)) -> 12392.725 | D13: =INDEX(MultiYear_ProForma!$X$2:$X$61, MATCH(Scenarios!A6&"|FY2030", MultiYear_ProForma!$AG$2:$AG$61, 0)) -> 13020.107 | E13: =AVERAGE(INDEX(MultiYear_ProForma!$X$2:$X$61, MATCH(Scenarios!A6&"|FY2026", MultiYear_ProForma!$AG$2:$AG$61, 0)),INDEX(MultiYear_ProForma!$X$2:$X$61, MATCH(Scenarios!A6&"|FY2027", MultiYear_ProForma!$AG$2:$AG$61, 0)),INDEX(MultiYear_ProForma!$X$2:$X$61, MATCH(Scenarios!A6&"|FY2028", MultiYear_ProForma!$AG$2:$AG$61, 0))) -> 12092.921 | F13: =AVERAGE(INDEX(MultiYear_ProForma!$X$2:$X$61, MATCH(Scenarios!A6&"|FY2026", MultiYear_ProForma!$AG$2:$AG$61, 0)),INDEX(MultiYear_ProForma!$X$2:$X$61, MATCH(Scenarios!A6&"|FY2027", MultiYear_ProForma!$AG$2:$AG$61, 0)),INDEX(MultiYear_ProForma!$X$2:$X$61, MATCH(Scenarios!A6&"|FY2028", MultiYear_ProForma!$AG$2:$AG$61, 0)),INDEX(MultiYear_ProForma!$X$2:$X$61, MATCH(Scenarios!A6&"|FY2029", MultiYear_ProForma!$AG$2:$AG$61, 0)),INDEX(MultiYear_ProForma!$X$2:$X$61, MATCH(Scenarios!A6&"|FY2030", MultiYear_ProForma!$AG$2:$AG$61, 0))) -> 12400.282 | G13: =IFERROR(VLOOKUP($B13&"|FY2026", MultiYear_ProForma!$A:$AG, 14, FALSE), "") -> 0 | H13: =IFERROR(VLOOKUP($B13&"|FY2030", MultiYear_ProForma!$A:$AG, 6, FALSE) + VLOOKUP($B13&"|FY2030", MultiYear_ProForma!$A:$AG, 15, FALSE), "") -> 553 | I13: =Control_Center!C51 -> + | J13: =Control_Center!D51 -> Med | K13: =SUMIFS(MultiYear_ProForma!$AF:$AF, MultiYear_ProForma!$B:$B, $B13, MultiYear_ProForma!$C:$C, "FY2028") -> -3553163.1 | L13: =SUMIFS(MultiYear_ProForma!$AF:$AF, MultiYear_ProForma!$B:$B, $B13, MultiYear_ProForma!$C:$C, "FY2030") -> -3783584 | M13: =(SUMIFS(MultiYear_ProForma!$AF:$AF, MultiYear_ProForma!$B:$B, $B13, MultiYear_ProForma!$C:$C, "FY2026")+SUMIFS(MultiYear_ProForma!$AF:$AF, MultiYear_ProForma!$B:$B, $B13, MultiYear_ProForma!$C:$C, "FY2027")+SUMIFS(MultiYear_ProForma!$AF:$AF, MultiYear_ProForma!$B:$B, $B13, MultiYear_ProForma!$C:$C, "FY2028")+SUMIFS(MultiYear_ProForma!$AF:$AF, MultiYear_ProForma!$B:$B, $B13, MultiYear_ProForma!$C:$C, "FY2029")+SUMIFS(MultiYear_ProForma!$AF:$AF, MultiYear_ProForma!$B:$B, $B13, MultiYear_ProForma!$C:$C, "FY2030"))/5 -> -3556211.2 | N13: =Control_Center!B35 -> CUSTOM_KeepOpen_v2 | O13: =L13 - INDEX(L:L, MATCH("A_Repurpose_Both_ops", $B:$B, 0)) -> -2302099.4 | P13: =M13 - INDEX(M:M, MATCH("A_Repurpose_Both_ops", $B:$B, 0)) -> -1823103.3
B14: =Scenarios!A2 -> D_CUSTOM1 | C14: =INDEX(MultiYear_ProForma!$X$2:$X$61, MATCH(Scenarios!A2&"|FY2028", MultiYear_ProForma!$AG$2:$AG$61, 0)) -> 12392.725 | D14: =INDEX(MultiYear_ProForma!$X$2:$X$61, MATCH(Scenarios!A2&"|FY2030", MultiYear_ProForma!$AG$2:$AG$61, 0)) -> 13020.107 | E14: =AVERAGE(INDEX(MultiYear_ProForma!$X$2:$X$61, MATCH(Scenarios!A2&"|FY2026", MultiYear_ProForma!$AG$2:$AG$61, 0)),INDEX(MultiYear_ProForma!$X$2:$X$61, MATCH(Scenarios!A2&"|FY2027", MultiYear_ProForma!$AG$2:$AG$61, 0)),INDEX(MultiYear_ProForma!$X$2:$X$61, MATCH(Scenarios!A2&"|FY2028", MultiYear_ProForma!$AG$2:$AG$61, 0))) -> 12092.921 | F14: =AVERAGE(INDEX(MultiYear_ProForma!$X$2:$X$61, MATCH(Scenarios!A2&"|FY2026", MultiYear_ProForma!$AG$2:$AG$61, 0)),INDEX(MultiYear_ProForma!$X$2:$X$61, MATCH(Scenarios!A2&"|FY2027", MultiYear_ProForma!$AG$2:$AG$61, 0)),INDEX(MultiYear_ProForma!$X$2:$X$61, MATCH(Scenarios!A2&"|FY2028", MultiYear_ProForma!$AG$2:$AG$61, 0)),INDEX(MultiYear_ProForma!$X$2:$X$61, MATCH(Scenarios!A2&"|FY2029", MultiYear_ProForma!$AG$2:$AG$61, 0)),INDEX(MultiYear_ProForma!$X$2:$X$61, MATCH(Scenarios!A2&"|FY2030", MultiYear_ProForma!$AG$2:$AG$61, 0))) -> 12400.282 | G14: =IFERROR(VLOOKUP($B14&"|FY2026", MultiYear_ProForma!$A:$AG, 14, FALSE), "") -> 0 | H14: =IFERROR(VLOOKUP($B14&"|FY2030", MultiYear_ProForma!$A:$AG, 6, FALSE) + VLOOKUP($B14&"|FY2030", MultiYear_ProForma!$A:$AG, 15, FALSE), "") -> 553 | I14: =Control_Center!C57 -> - | J14: =Control_Center!D57 -> Low-Med | K14: =SUMIFS(MultiYear_ProForma!$AF:$AF, MultiYear_ProForma!$B:$B, $B14, MultiYear_ProForma!$C:$C, "FY2028") -> -3553163.1 | L14: =SUMIFS(MultiYear_ProForma!$AF:$AF, MultiYear_ProForma!$B:$B, $B14, MultiYear_ProForma!$C:$C, "FY2030") -> -3783584 | M14: =(SUMIFS(MultiYear_ProForma!$AF:$AF, MultiYear_ProForma!$B:$B, $B14, MultiYear_ProForma!$C:$C, "FY2026")+SUMIFS(MultiYear_ProForma!$AF:$AF, MultiYear_ProForma!$B:$B, $B14, MultiYear_ProForma!$C:$C, "FY2027")+SUMIFS(MultiYear_ProForma!$AF:$AF, MultiYear_ProForma!$B:$B, $B14, MultiYear_ProForma!$C:$C, "FY2028")+SUMIFS(MultiYear_ProForma!$AF:$AF, MultiYear_ProForma!$B:$B, $B14, MultiYear_ProForma!$C:$C, "FY2029")+SUMIFS(MultiYear_ProForma!$AF:$AF, MultiYear_ProForma!$B:$B, $B14, MultiYear_ProForma!$C:$C, "FY2030"))/5 -> -3556211.2 | N14: =Control_Center!B31 -> CUSTOM_KeepOpen_v1 | O14: =L14 - INDEX(L:L, MATCH("A_Repurpose_Both_ops", $B:$B, 0)) -> -2302099.4 | P14: =M14 - INDEX(M:M, MATCH("A_Repurpose_Both_ops", $B:$B, 0)) -> -1823103.3

Sheet Definitions_Sources
B2: Parameter / input | C2: Description / how we used it | D2: Public source & how derived | E2: What to request to confirm / refine
B3: ADM | C3: ADM stands for Average Daily Membership. It is the primary metric used by the state of Arizona to determine funding for a school district. What it is: ADM is essentially the official student count. It is not based on how many students are present on any single day (that would be average daily attendance), but rather on how many students are officially enrolled in the district. | D3: How it's calculated: The state uses enrollment data from specific points in the school year to generate an average. This average, the ADM, becomes the official "student count" for that fiscal year. Why it matters: Nearly all state funding is allocated on a per-student basis using ADM. This number is multiplied by various weights (e.g., for high school students, special education, etc.) to create a "weighted student count," which is the foundational number for calculating the district's total state aid. An audit of SUSD's ADM, for example, is a check to ensure the district reported its enrollment correctly and received the proper amount of funding.
B4: M&O | C4: M&O stands for Maintenance and Operations. This is the largest and most important part of a school district's budget. What it is: The M&O budget is the "bucket" of money that pays for all the day-to-day, non-capital expenses of running the school district. It is the district's operating budget. | D4: What it pays for: Salaries and benefits for all employees (teachers, principals, support staff, administrators) Classroom supplies (textbooks, software, paper, etc.) Utilities (electricity, water, gas) Transportation (bus fuel and maintenance) Student services and athletics
B5: Base state aid per pupil (FY2025) | C5: Revenue per ADM in “Aid per ADM” line; grown by CPI in out‑years (model uses a placeholder near $5.1k) | D5: Arizona FY2025 budget bill (HB 2906) sets the base level per pupil at $5,013 for FY2025. Arizona Senate Issue Brief – K‑12 School Finance (official, widely used reference). Shows the Base Level Amount (FY 2024‑25 = $5,013.33), the factor that (with district weights) drives state aid. ADE lists the same figure in its finance materials. | E5: ADE School Finance memo for FY2025 base level (final), plus any FY2026 update; SUSD’s per‑pupil revenue schedule (by weight) if you want to add K‑8 weights locally.
B6: Echo Canyon base ADM (≈257) | C6: Baseline students “served” in keep‑open scenarios | D6: ADE School Report Cards / Arizona Education Profiles (school pages) + SUSD 40th‑day board reports for Echo Canyon’s latest K‑8 enrollment ADE school page data used. | E6: SUSD October (40th‑day) ADM sheet listing Echo Canyon K‑8 ADM (most recent year) and the same for the prior 3 years.
B7: Pima base ADM (≈296) | C7: Baseline students “served” in keep‑open scenarios | D7: ADE School Report Cards page for Pima Traditional (enrollment tile). The “Enrollment” 🛈 on that page for the specific year has enrollment data. | E7: Same 40th‑day ADM sheet as above, for Pima K‑8.
B8: District M&O (Fund 001) context | C8: Grounds the “M&O per ADM” baseline used in comparable $/student | D8: Scottsdale USD ACFR FY2024 (annual comprehensive financial report) — Fund statements and notes establish M&O (Fund 001) totals and function splits (instruction, plant ops, admin, etc.). We used it to sanity‑check the order of magnitude for per‑pupil operating cost. (Scottsdale Unified School District) | E8: From ACFR or adopted budget: Fund 001 totals and function detail by object/function; district ADM used in budget; site‑level M&O if available.
B9: “Fixed‑like” share of M&O ≈ 30–40% (used 30% as a conservative placeholder) | C9: Splits total M&O into “semi‑fixed” (plant ops, insurance, admin, central) vs “variable” (classroom sections, supplies, a slice of transport) to compute EchoFixed$ and PimaFixed$ | D9: Arizona Auditor General – Arizona School District Spending – FY2024 portal (official statewide analysis). The Overview and category definitions show the functional buckets (instruction, administration, plant operations & maintenance, student support, etc.) districts report and that we treat as the “more fixed‑like” categories. (sdspending.azauditor.gov) | E9: SUSD site‑level: plant ops/maintenance, insurance, utilities, admin FTE & benefits at Echo/Pima. Use that to replace the 30% proxy with real fixed amounts. The file allocates the fixed share across the two schools pro‑rata (by base ADM) as a temporary step. Replace with the actual plant ops/insurance/utilities/admin for each site from Fund 001 to remove that simplification.
B10: M&O Inflation
B11: AID inflation
B12: Overlay | C12: Using this term in the spreadsheet to mean growth of new students | D12: Not an official district term; just using in this spreadsheet
B13: Variable unit cost (VarUnit$) | C13: $ per student applied to “served ADM,” plus marginal‑cost factor on overlay seats | D13: Assumption derived from Fund 001 minus fixed share, divided by total ADM; then Marginal factor (see below) reduces cost for overlay seats. | E13: SUSD staffing ratios & actual sectioning at K–8; confirm what portion of M&O truly scales with added sections (teachers, aides, supplies, a slice of transport).
B14: Marginal‑cost factor for overlay seats (0.50) | C14: Applies only to overlay growth students in keep‑open scenarios; models that not every dollar is average cost | D14: Assumption w/ rationale: Roughly half of per‑pupil cost is staffing/supplies/transport that scale with sections; the remainder is semi‑fixed plant/admin. This aligns with Auditor General function splits and is intentionally conservative. We’ll replace with SUSD’s staffing & plant data if provided. (Sun Devil Central) | E14: SUSD’s teacher‑section & aide staffing rules, average class sizes, and any marginal staffing adders at K–8 (arts, specialists).
B15: Receiving overhead “h” (FY26 $1,000 → FY30 $300) | C15: Per retained student transition/route/admin cost added when a site is repurposed; tapers as routes stabilize | D15: Assumption with AZ context: AZ districts’ transport spend per rider is often $2k–$3k (statewide average $2,862 cited in a district budget narrative), so $1,000 tapering to $300 is a conservative placeholder for incremental cost, not full bus cost. | E15: SUSD transportation cost per route-hour, average riders per route, and the specific route changes proposed in the repurpose option. | F15: Transportation / receiving overhead order‑of‑magnitude | G15: Our h parameter adds incremental per‑retained‑student cost (routing/transition/admin) only when a repurpose occurs, tapering as routes stabilize | H15: AAG district audits show cost per rider varies (several audited districts fall near $900–$1,100 per rider; others higher depending on geography), demonstrating the right order of magnitude for incremental routing burden. Examples: Safford USD 2022 $893 per rider; Snowflake USD 2023 $1,008 per rider. | I15: Keeping h = $1,000 → $300 (FY26→FY30) is defensible as incremental overhead, not full bus cost. Leave Parameters!h_FY values editable; note they should be zero in keep‑open scenarios (no forced transfers).
B16: Retention rate “r” (central 0.75; sensitivities 0.65–0.85) | C16: Share of displaced Echo+Pima students who remain in SUSD (the rest leave to charters/other districts) | D16: Assumption, benchmarked to closure research: large‑district closure work (e.g., Chicago) shows most students remain in‑district the next year (CPS analyses place that figure well above half); retention varies with hand‑off quality and distance. We model 65–85% to bracket. (UChicago Consortium on School Research) Large‑district evidence: UChicago Consortium’s analyses of the 2013 CPS closures found most displaced students remained in district the next year; outcomes varied with the quality and distance of receiving schools. That supports using a central r ~ 0.75 with a band. UChicago Consortium on School Research What we could not find in AZ: districts rarely publish explicit post‑closure retention; you can proxy from post‑closure enrollment by receiving schools if SUSD shares it. Echo nuance: Because Echo is open‑enrollment and draws many out‑of‑district students, those families may be less likely to follow to a different SUSD school after a closure (they already cross a boundary by choice). That argues for running a lower Echo‑weighted r scenario (e.g., 0.55–0.65) in addition to the district‑wide 0.65–0.85 band. Make that explicit in the dashboard and in the sensitivity mini‑cards. | E16: SUSD post‑closure enrollment tracking (where displaced students re‑enroll), by receiving school; use that to set “r” from observed data.
B17: Carry fractions f_ops / f_lease (e.g., 0.40 → 0 by FY30) | C17: Share of each site’s fixed costs that persist after repurpose under ops mothball vs lease/sale | D17: Assumption pending facilities plan. The glide‑path (e.g., 40%→30%→20%→10%→0%) reflects how fast plant/insurance/utilities can be retired or passed to a tenant. | E17: SUSD facilities memo: timeline to partial/full mothball, target lease/sale timing, and which cost lines truly zero out under each scenario.
B18: TI / one‑time repurpose costs (e.g., $2.4M) | C18: “TI_adds$” in the pro‑forma for the first 1–2 years. Why “Repurpose TI per closed site (FY26) = $1.2M”? What is “one‑time carry/TI”? “TI” = tenant improvements / transition investments needed to convert a K‑8 to a different use (early learning, admin consolidation) and carry costs in year one (e.g., abatement, doors/security, low‑voltage re‑work, furniture, swing space). A light‑touch repurpose can easily run $10–$20/sq‑ft; Echo’s plant is ~77k sq ft, so $1.2M is a reasonable placeholder (we are not assuming a gut remodel). We’ll replace this with SUSD’s scope/estimate if they have one. | D18: Assumption (placeholder). | E18: SUSD engineering estimate for tenant improvements or district reconfiguration (scope, cost, which fund, and amortization).
B19: Extra cost savings for co-location scenario | C19: Why “Extra savings (co‑location) = 0.015 (1.5%)”? This reflects incremental savings from consolidating some services on one campus (custodial/grounds/partial routing). Again kept small and conservative; we’ll swap in real custodial (sq‑ft), grounds and route deltas when we get them.
B20: Ops savings (for keep-open scenarios) | C20: Ops savings (keep‑open) = 0.007 (0.7%)”? This represents “light discipline” (utilities/purchasing tweaks, route smoothing) that does not depend on closing a site. I set it very low on purpose so it doesn’t drive results. We’ll calibrate with SUSD data (e.g., last year’s utility audits) if provided.
B22: Scenario overlays (+0 / +100 / +150 / +200) | C22: Size of growth push in keep‑open options (D, F, G) | D22: Assumption based on capacity headroom + practical recruitment targets. | E22: SUSD SFB capacity for Echo/Pima and neighboring receiving schools; actual classroom/wing availability by grade band.
B23: K–8 capacity / square footage | C23: Context for “utilization” and whether overlay targets are feasible | D23: Not yet populated; to be anchored to SFB (AZ School Facilities Board) capacity files and SUSD construction docs. | E23: SUSD/SFB: design capacity and current utilization for Echo & Pima (post‑rebuild specs for Pima).
B24: Pre‑K contribution | C24: Excluded from ADM and revenue in the model (unless tuition/lease modeled) | D24: Supported by statute & ADE finance practice—general Pre‑K does not generate state ADM (exception: SPED preschool). (Arizona Department of Education) | E24: If SUSD intends district‑operated tuition Pre‑K on site, request pro forma for net contribution (tuition – staffing – TI).
B25: ADM definition (what “counts”) | C25: Explains why Pre‑K is excluded and why K can count at 0.5; supports “served” math | D25: A.R.S. §15‑901 and legislative fact sheet: Kindergarten generates 0.5 ADM unless full‑time; ADM is a statutory count, and preschool is generally not included in ADM (except some SPED programs). (LegiScan) | E25: SUSD’s 40th‑day and 100th‑day ADM certification for Echo and Pima (K–8 breakouts).
B28: Model input / claim | C28: How we’re using it in the model | D28: Public source to cite (what to grab) | E28: How to apply in the file
B32: Parameter / Input | C32: Description | D32: Where it lives | E32: Notes on logic / calculation | F32: Source to use for final vetting
B33: Base MO per ADM (FY25) | C33: Working average M&O per student at FY25 | D33: BaselineCalc | E33: Drives Base total MO = Total ADM × Base MO/ADM | F33: Replace with SUSD ACFR/Adopted Budget (FY24–FY25) for precision
B34: Fixed share of MO | C34: Semi‑fixed share (plant ops, admin, insurance, custodial) | D34: BaselineCalc | E34: Fixed MO = Base total MO × Fixed share | F34: Validate vs ACFR function split (% Plant/Admin/Insurance) | G34: Notes on Pima & Echo fixed $ placeholders: The file allocates the fixed share across the two schools pro‑rata (by base ADM) as a temporary step. Replace with the actual plant ops/insurance/utilities/admin for each site from Fund 001 to remove that simplification.
B35: Var per student (FY25) | C35: Derived variable cost per student | D35: BaselineCalc | E35: (Base total – Fixed) ÷ total ADM | F35: Derived
B36: MO inflation | C36: Annual inflation on M&O lines | D36: BaselineCalc | E36: Inflates VarUnit$ across YearMap | F36: Use district inflation guidance
B37: Echo/Pima base ADM | C37: Starting enrollment | D37: BaselineCalc | E37: Builds Total base ADM = Echo + Pima | F37: District official
