Workbook

Sheet Dashboard
A1: SUSD Keep-Open vs Repurpose — Interactive Dashboard (v4.0)
A3: Pick scenarios & assumptions | D3: Implications
A5: Baseline A (auto): | B5: =IF(B12="ops","A_Repurpose_Both_ops","A_Repurpose_Both_lease") -> A_Repurpose_Both_ops | D5: ="If "&B5&" instead of "&B6&", need to retain "&ROUND(I23*100, 0)&"% of students to achieve the same cost profile by 2030." -> If A_Repurpose_Both_ops instead of D_Grow_Both_150, need to retain 34% of students to achieve the same cost profile by 2030. | J5: Net Budget (Totals)
A6: Compare to (X) | B6: D_Grow_Both_150
A7: Compare to (Y) | B7: G_DHub_EchoRamp | J7: A FY2030 Net ($) | K7: =INDEX(Summary_Costs!$H:$H, MATCH($B$5, Summary_Costs!$A:$A,0)) -> 0
J8: X FY2030 Net ($) | K8: =INDEX(Summary_Costs!$H:$H, MATCH($B$6, Summary_Costs!$A:$A,0)) -> 0
A9: Retention r (central) | B9: =BaselineCalc!$B$22 -> 0.75 | D9: ="The difference in FY2030 $/student will be "&J26&""&ROUND(K26, 0)&"." -> The difference in FY2030 $/student will be -$1386. | J9: Δ FY2030 Net (X − A) | K9: =K8-K7 -> 0
A10: Receiving overhead h | B10: 600 | D10: ="The difference in 5-yr Avg $/student will be "&J28&""&ROUND(K28, 0)&"." -> The difference in 5-yr Avg $/student will be +$586.
A11: Carry year | B11: FY2030 | D11: ="Reversing this decision will be "&F20&"." -> Reversing this decision will be very difficult. | J11: A 5‑yr Net Avg ($) | K11: =INDEX(Summary_Costs!$I:$I, MATCH($B$5, Summary_Costs!$A:$A,0)) -> 0
A12: Carry mode | B12: ops | D12: ="The district's image will be impacted "&E20&"." -> The district's image will be impacted negatively. | J12: X 5‑yr Net Avg ($) | K12: =INDEX(Summary_Costs!$I:$I, MATCH($B$6, Summary_Costs!$A:$A,0)) -> 0
D13: <<the number of kids displaced would be…>>> | J13: Δ 5‑yr Net Avg (X − A) | K13: =K12-K11 -> 0
A14: Selected fixed-carry f | B14: =IF(B12="ops", INDEX(YearMap!$G$2:$G$6, MATCH(B11, YearMap!$A$2:$A$6,0)), INDEX(YearMap!$F$2:$F$6, MATCH(B11, YearMap!$A$2:$A$6,0))) -> 0.2 | D14: <<net impact to budget… are we netting out the funding / student vs. cost / student already… or need to incorporate?>>
J16: Targets to Save (editable)
J17: Served threshold FY2028 | K17: 300
J18: Meets? (X vs threshold) | K18: =IF(INDEX(MultiYear_ProForma!$O:$O, MATCH($B$6&"|"&"FY2028", MultiYear_ProForma!$B:$B&"|"&MultiYear_ProForma!$C:$C,0))>0, INDEX(MultiYear_ProForma!$O:$O, MATCH($B$6&"|"&"FY2028", MultiYear_ProForma!$B:$B&"|"&MultiYear_ProForma!$C:$C,0)), INDEX(MultiYear_ProForma!$F:$F, MATCH($B$6&"|"&"FY2028", MultiYear_ProForma!$B:$B&"|"&MultiYear_ProForma!$C:$C,0)))>=$K$17 -> #VALUE!
A19: A baseline (auto): | B19: $B$5 | D19: Distinctiveness / Reversibility: | E19: =IFERROR(INDEX(Attributes!$B:$B, MATCH($B$5, Attributes!$A:$A,0)),"") -> - | F19: =IFERROR(INDEX(Attributes!$C:$C, MATCH($B$5, Attributes!$A:$A,0)),"") -> Low
A20: FY2028 $/student | B20: =INDEX(Summary_Costs!$B:$B, MATCH($B$5, Summary_Costs!$A:$A, 0)) -> 9364.9999 | E20: =IF(E19="-", "negatively", "positively") -> negatively | F20: =IF(F19="Low", "very difficult", IF(F19="Med", "somewhat difficult", IF(F19="Med-High", "difficult", IF(F19="High", "not difficult", )))) -> very difficult
A21: FY2030 $/student | B21: =INDEX(Summary_Costs!$C:$C, MATCH($B$5, Summary_Costs!$A:$A, 0)) -> 9062.2088 | I21: Results
A22: 3-yr Avg $/student | B22: =INDEX(Summary_Costs!$D:$D, MATCH($B$5, Summary_Costs!$A:$A, 0)) -> 11485.778
A23: 5-yr Avg $/student | B23: =INDEX(Summary_Costs!$E:$E, MATCH($B$5, Summary_Costs!$A:$A, 0)) -> 10537.171 | H23: r* needed (X) | I23: =IF($B$11="FY2028", IF($B$12="ops", INDEX(BreakEven_X!$C$17:$J$17, MATCH($B$10, BreakEven_X!$C$16:$J$16,0)), INDEX(BreakEven_X!$C$18:$J$18, MATCH($B$10, BreakEven_X!$C$16:$J$16,0))), IF($B$12="ops", INDEX(BreakEven_X!$C$31:$J$31, MATCH($B$10, BreakEven_X!$C$30:$J$30,0)), INDEX(BreakEven_X!$C$32:$J$32, MATCH($B$10, BreakEven_X!$C$30:$J$30,0)))) -> 0.33839995
A24: # displaced | B24: =INDEX(Summary_Costs!$F:$F, MATCH($B$5, Summary_Costs!$A:$A, 0)) -> 553 | H24: r* needed (Y) | I24: =IF($B$11="FY2028", IF($B$12="ops", INDEX(BreakEven_Y!$C$17:$J$17, MATCH($B$10, BreakEven_Y!$C$16:$J$16,0)), INDEX(BreakEven_Y!$C$18:$J$18, MATCH($B$10, BreakEven_Y!$C$16:$J$16,0))), IF($B$12="ops", INDEX(BreakEven_Y!$C$31:$J$31, MATCH($B$10, BreakEven_Y!$C$30:$J$30,0)), INDEX(BreakEven_Y!$C$32:$J$32, MATCH($B$10, BreakEven_Y!$C$30:$J$30,0)))) -> 0.33839995
A25: FY2030 served (open+retained) | B25: =INDEX(Summary_Costs!$G:$G, MATCH($B$5, Summary_Costs!$A:$A, 0)) -> 414.75 | J25: Vs. X & Y | K25: Absolute
A26: Comparator X: | B26: $B$6 | D26: Distinctiveness / Reversibility: | E26: =IFERROR(INDEX(Attributes!$B:$B, MATCH($B$6, Attributes!$A:$A,0)),"") -> + | F26: =IFERROR(INDEX(Attributes!$C:$C, MATCH($B$6, Attributes!$A:$A,0)),"") -> Med | H26: Δ FY2030 $/student (X - A) | I26: =INDEX(Summary_Costs!$C:$C, MATCH($B$6, Summary_Costs!$A:$A,0)) - INDEX(Summary_Costs!$C:$C, MATCH($B$5, Summary_Costs!$A:$A,0)) -> 1386.2137 | J26: =IF((I26*-1)<0,"-$", "+$") -> -$ | K26: =ABS(I26*-1) -> 1386.2137
A27: FY2028 $/student | B27: =INDEX(Summary_Costs!$B:$B, MATCH($B$6, Summary_Costs!$A:$A, 0)) -> 9944.959 | E27: =IF(E26="-", "negatively", "positively") -> positively | F27: =IF(F26="Low", "very difficult", IF(F26="Med", "somewhat difficult", IF(F26="Med-High", "difficult", IF(F26="High", "not difficult", )))) -> somewhat difficult | H27: Δ FY2030 $/student (Y - A) | I27: =INDEX(Summary_Costs!$C:$C, MATCH($B$7, Summary_Costs!$A:$A,0)) - INDEX(Summary_Costs!$C:$C, MATCH($B$5, Summary_Costs!$A:$A,0)) -> 1386.2137 | J27: =IF((I27*-1)<0,"-$", "+$") -> -$ | K27: =ABS(I27*-1) -> 1386.2137
A28: FY2030 $/student | B28: =INDEX(Summary_Costs!$C:$C, MATCH($B$6, Summary_Costs!$A:$A, 0)) -> 10448.423 | H28: Δ 5-yr Avg $/student (X - A) | I28: =INDEX(Summary_Costs!$E:$E, MATCH($B$6, Summary_Costs!$A:$A,0)) - INDEX(Summary_Costs!$E:$E, MATCH($B$5, Summary_Costs!$A:$A,0)) -> -586.14698 | J28: =IF((I28*-1)<0,"-$", "+$") -> +$ | K28: =ABS(I28*-1) -> 586.14698
A29: 3-yr Avg $/student | B29: =INDEX(Summary_Costs!$D:$D, MATCH($B$6, Summary_Costs!$A:$A, 0)) -> 9704.371 | H29: Δ 5-yr Avg $/student (Y - A) | I29: =INDEX(Summary_Costs!$E:$E, MATCH($B$7, Summary_Costs!$A:$A,0)) - INDEX(Summary_Costs!$E:$E, MATCH($B$5, Summary_Costs!$A:$A,0)) -> -469.52853 | J29: =IF((I29*-1)<0,"-$", "+$") -> +$ | K29: =ABS(I29*-1) -> 469.52853
A30: 5-yr Avg $/student | B30: =INDEX(Summary_Costs!$E:$E, MATCH($B$6, Summary_Costs!$A:$A, 0)) -> 9951.0237
A31: # displaced | B31: =INDEX(Summary_Costs!$F:$F, MATCH($B$6, Summary_Costs!$A:$A, 0)) -> 0 | K31: =IF((I28*-1)<0,"-$"&I28*-1, "+$"&I28*-1) -> +$586.146981075031
A32: FY2030 served (open+retained) | B32: =INDEX(Summary_Costs!$G:$G, MATCH($B$6, Summary_Costs!$A:$A, 0)) -> 703
A33: Comparator Y: | B33: $B$7 | D33: Distinctiveness / Reversibility: | E33: =IFERROR(INDEX(Attributes!$B:$B, MATCH($B$7, Attributes!$A:$A,0)),"") -> + | F33: =IFERROR(INDEX(Attributes!$C:$C, MATCH($B$7, Attributes!$A:$A,0)),"") -> Med-High
A34: FY2028 $/student | B34: =INDEX(Summary_Costs!$B:$B, MATCH($B$7, Summary_Costs!$A:$A, 0)) -> 9944.959 | E34: =IF(E33="-", "negatively", "positively") -> positively | F34: =IF(F33="Low", "very difficult", IF(F33="Med", "somewhat difficult", IF(F33="Med-High", "difficult", IF(F33="High", "not difficult", )))) -> difficult
A35: FY2030 $/student | B35: =INDEX(Summary_Costs!$C:$C, MATCH($B$7, Summary_Costs!$A:$A, 0)) -> 10448.423
A36: 3-yr Avg $/student | B36: =INDEX(Summary_Costs!$D:$D, MATCH($B$7, Summary_Costs!$A:$A, 0)) -> 9898.7351
A37: 5-yr Avg $/student | B37: =INDEX(Summary_Costs!$E:$E, MATCH($B$7, Summary_Costs!$A:$A, 0)) -> 10067.642
A38: # displaced | B38: =INDEX(Summary_Costs!$F:$F, MATCH($B$7, Summary_Costs!$A:$A, 0)) -> 0
A39: FY2030 served (open+retained) | B39: =INDEX(Summary_Costs!$G:$G, MATCH($B$7, Summary_Costs!$A:$A, 0)) -> 703

Sheet Cards
A1: Mini-Cards: A (Repurpose-Both) vs X and Y
A3: Comparator X | B3: =Dashboard!$B$6 -> D_Grow_Both_150 | D3: Comparator Y | E3: =Dashboard!$B$7 -> G_DHub_EchoRamp
A4: r* needed (year/mode/h) | B4: =Dashboard!$I$23 -> 0.33839995 | D4: r* needed (year/mode/h) | E4: =Dashboard!$I$24 -> 0.33839995
A5: Δ FY2030 $/student | B5: =Dashboard!$I$26 -> 1386.2137 | D5: Δ FY2030 $/student | E5: =Dashboard!$I$27 -> 1386.2137
A6: Δ 5-yr Avg $/student | B6: =Dashboard!$I$28 -> -586.14698 | D6: Δ 5-yr Avg $/student | E6: =Dashboard!$I$29 -> -469.52853
A7: # displaced (A) | B7: =INDEX(Summary_Costs!$F:$F, MATCH(Dashboard!$B$5, Summary_Costs!$A:$A,0)) -> 553 | D7: # displaced (A) | E7: =INDEX(Summary_Costs!$F:$F, MATCH(Dashboard!$B$5, Summary_Costs!$A:$A,0)) -> 553
A8: # displaced (X) | B8: =INDEX(Summary_Costs!$F:$F, MATCH(Dashboard!$B$6, Summary_Costs!$A:$A,0)) -> 0 | D8: # displaced (Y) | E8: =INDEX(Summary_Costs!$F:$F, MATCH(Dashboard!$B$7, Summary_Costs!$A:$A,0)) -> 0
A9: Distinctiveness / Reversibility | B9: =Dashboard!$E$26 & " / " & Dashboard!$F$26 -> + / Med | D9: Distinctiveness / Reversibility | E9: =Dashboard!$E$33 & " / " & Dashboard!$F$33 -> + / Med-High

Sheet BaselineCalc
A1: Parameter | B1: Value | C1: Notes
A2: MO inflation | B2: 0.025 | C2: Annual inflation factor.
A3: Base MO per ADM (FY25) | B3: 9936 | C3: Working base for FY25.
A4: Fixed share of MO | B4: 0.3 | C4: Share treated as semi‑fixed (plant/insurance).
A5: Ops savings (keep‑open) | B5: 0.007 | C5: Light discipline if sites remain open (not used here).
A6: Extra savings (Co‑location) | B6: 0.015 | C6: Incremental savings for co‑location (not used here).
A7: Echo base ADM | B7: 257
A8: Pima base ADM | B8: 296
A9: Total base ADM | B9: =B7+B8 -> 553 | C9: Echo base ADM + Pima base ADM
A12: Helper / Derivation | B12: FY26 | C12: FY27 | D12: FY28 | E12: FY29 | F12: FY30 | G12: Notes
A13: Base total MO (FY25) | B13: =B9*B3 -> 5494608 | C13: =C14/$B$4 -> 5631973.2 | D13: =D14/$B$4 -> 5772772.5 | E13: =E14/$B$4 -> 5917091.8 | F13: =F14/$B$4 -> 6065019.1 | G13: Total ADM × Base MO/ADM | K13: B13 = B9*B3 (Base total MO, FY25)
A14: Fixed MO (FY25) | B14: =B13*B4 -> 1648382.4 | C14: =B17 -> 1689592 | D14: =C17 -> 1731831.8 | E14: =D17 -> 1775127.6 | F14: =E17 -> 1819505.7 | G14: Fixed = Base total × Fixed share | K14: B14 = B13*B4 (Fixed MO, FY25)
A15: Var per student (FY25) | B15: =(B13-B14)/B9 -> 6955.2 | C15: =B18 -> 7129.08 | D15: =C18 -> 7307.307 | E15: =D18 -> 7489.9897 | F15: =E18 -> 7677.2394 | G15: Variable = (Base total − Fixed)/Total ADM | K15: B15 = (B13–B14)/B9 (Variable $/student, FY25)
A17: Fixed total ($) | B17: =$B$14*(1+$B$2)^1 -> 1689592 | C17: =$B$14*(1+$B$2)^2 -> 1731831.8 | D17: =$B$14*(1+$B$2)^3 -> 1775127.6 | E17: =$B$14*(1+$B$2)^4 -> 1819505.7 | F17: =$B$14*(1+$B$2)^5 -> 1864993.4
A18: Var unit ($/student) | B18: =$B$15*(1+$B$2)^1 -> 7129.08 | C18: =$B$15*(1+$B$2)^2 -> 7307.307 | D18: =$B$15*(1+$B$2)^3 -> 7489.9897 | E18: =$B$15*(1+$B$2)^4 -> 7677.2394 | F18: =$B$15*(1+$B$2)^5 -> 7869.1704
A19: Echo fixed ($) | B19: =B17*($B$7/$B$9) -> 785217.24 | C19: =C17*($B$7/$B$9) -> 804847.67 | D19: =D17*($B$7/$B$9) -> 824968.86 | E19: =E17*($B$7/$B$9) -> 845593.08 | F19: =F17*($B$7/$B$9) -> 866732.91
A20: Pima fixed ($) | B20: =B17*($B$8/$B$9) -> 904374.72 | C20: =C17*($B$8/$B$9) -> 926984.09 | D20: =D17*($B$8/$B$9) -> 950158.69 | E20: =E17*($B$8/$B$9) -> 973912.66 | F20: =F17*($B$8/$B$9) -> 998260.47
A21: Repurpose TI per closed site (FY26) | B21: 1200000
A22: Retention r (central) | B22: 0.75
A24: Notes
A25: All formulas are same‑sheet and reference the Parameter cells above.
A26: Base State Aid per ADM (FY26) | B26: 5113 | C26: Editable; ADE base aid.
A27: Aid inflation (annual) | B27: 0.02 | C27: Editable; assumed growth in base aid.

Sheet YearMap
A1: Year | B1: VarUnit$ | C1: EchoFixed$ | D1: PimaFixed$ | E1: h | F1: f_lease | G1: f_ops | H1: YearIdx | I1: Aid$
A2: FY2026 | B2: =BaselineCalc!B18 -> 7129.08 | C2: =BaselineCalc!B19 -> 785217.24 | D2: =BaselineCalc!B20 -> 904374.72 | E2: 1000 | F2: 0.4 | G2: 0.4 | H2: 1 | I2: =BaselineCalc!$B$26*(1+BaselineCalc!$B$27)^(H2-1) -> 5113
A3: FY2027 | B3: =BaselineCalc!C18 -> 7307.307 | C3: =BaselineCalc!C19 -> 804847.67 | D3: =BaselineCalc!C20 -> 926984.09 | E3: 800 | F3: 0.3 | G3: 0.35 | H3: 2 | I3: =BaselineCalc!$B$26*(1+BaselineCalc!$B$27)^(H3-1) -> 5215.26
A4: FY2028 | B4: =BaselineCalc!D18 -> 7489.9897 | C4: =BaselineCalc!D19 -> 824968.86 | D4: =BaselineCalc!D20 -> 950158.69 | E4: 600 | F4: 0.2 | G4: 0.3 | H4: 3 | I4: =BaselineCalc!$B$26*(1+BaselineCalc!$B$27)^(H4-1) -> 5319.5652
A5: FY2029 | B5: =BaselineCalc!E18 -> 7677.2394 | C5: =BaselineCalc!E19 -> 845593.08 | D5: =BaselineCalc!E20 -> 973912.66 | E5: 400 | F5: 0.1 | G5: 0.25 | H5: 4 | I5: =BaselineCalc!$B$26*(1+BaselineCalc!$B$27)^(H5-1) -> 5425.9565
A6: FY2030 | B6: =BaselineCalc!F18 -> 7869.1704 | C6: =BaselineCalc!F19 -> 866732.91 | D6: =BaselineCalc!F20 -> 998260.47 | E6: 300 | F6: 0 | G6: 0.2 | H6: 5 | I6: =BaselineCalc!$B$26*(1+BaselineCalc!$B$27)^(H6-1) -> 5534.4756

Sheet Scenarios
A1: ScenarioKey | B1: Label | C1: Overlay | D1: CloseEcho | E1: ClosePima | F1: EchoShareDist | G1: ExtraSave | H1: Notes | I1: Overlay_FY26 | J1: Overlay_FY27 | K1: Overlay_FY28 | L1: Overlay_FY29 | M1: Overlay_FY30 | N1: Carry
A2: D_Grow_Both_0 | B2: D. Grow Both (Overlay 0) | C2: 0 | D2: 0 | E2: 0 | F2: 0.5 | G2: 0 | H2: Baseline + outreach; no closures | I2: =$C2 -> 0 | J2: =$C2 -> 0 | K2: =$C2 -> 0 | L2: =$C2 -> 0 | M2: =$C2 -> 0
A3: E_StatusQuo_Targets_0 | B3: E. Status‑Quo + Targets (0) | C3: 0 | D3: 0 | E3: 0 | F3: 0.5 | G3: 0 | H3: Baseline + targets; no closures | I3: =$C3 -> 0 | J3: =$C3 -> 0 | K3: =$C3 -> 0 | L3: =$C3 -> 0 | M3: =$C3 -> 0
A4: F_CoLocation_Echo_0 | B4: F. Co‑Location @ Echo (0) | C4: 0 | D4: 0 | E4: 0 | F4: 0.7 | G4: 0.015 | H4: Shared‑use efficiencies later (no closure) | I4: =$C4 -> 0 | J4: =$C4 -> 0 | K4: =$C4 -> 0 | L4: =$C4 -> 0 | M4: =$C4 -> 0
A5: D_Grow_Both_100 | B5: D. Grow Both (Overlay 100) | C5: 100 | D5: 0 | E5: 0 | F5: 0.5 | G5: 0 | H5: Baseline +100 overlay | I5: =$C5 -> 100 | J5: =$C5 -> 100 | K5: =$C5 -> 100 | L5: =$C5 -> 100 | M5: =$C5 -> 100
A6: D_Grow_Both_150 | B6: D. Grow Both (Overlay 150) | C6: 150 | D6: 0 | E6: 0 | F6: 0.5 | G6: 0 | H6: Baseline +150 overlay | I6: =$C6 -> 150 | J6: =$C6 -> 150 | K6: =$C6 -> 150 | L6: =$C6 -> 150 | M6: =$C6 -> 150
A7: G_DHub_EchoRamp | B7: G. D‑Hub @ Echo (Ramp 50→100→150) | C7: 150 | D7: 0 | E7: 0 | F7: 0.7 | G7: 0 | H7: Time‑phased ramp (+50,+100,+150 years 1–3) | I7: =C7/3 -> 50 | J7: =I7+C7/3 -> 100 | K7: =J7+C7/3 -> 150 | L7: =C7 -> 150 | M7: =C7 -> 150
A8: A_Repurpose_Both_lease | B8: A. Repurpose BOTH (lease) | C8: 0 | D8: 1 | E8: 1 | F8: 0.5 | G8: 0 | H8: Repurpose both; lease/sale glide | I8: =$C8 -> 0 | J8: =$C8 -> 0 | K8: =$C8 -> 0 | L8: =$C8 -> 0 | M8: =$C8 -> 0 | N8: lease
A9: A_Repurpose_Both_ops | B9: A. Repurpose BOTH (ops) | C9: 0 | D9: 1 | E9: 1 | F9: 0.5 | G9: 0 | H9: Repurpose both; operations carry | I9: =$C9 -> 0 | J9: =$C9 -> 0 | K9: =$C9 -> 0 | L9: =$C9 -> 0 | M9: =$C9 -> 0 | N9: ops
A10: B_Repurpose_Echo_lease | B10: B. Repurpose ECHO (lease) | C10: 0 | D10: 1 | E10: 0 | F10: 0.5 | G10: 0 | H10: Repurpose Echo only; lease glide | I10: =$C10 -> 0 | J10: =$C10 -> 0 | K10: =$C10 -> 0 | L10: =$C10 -> 0 | M10: =$C10 -> 0 | N10: lease
A11: B_Repurpose_Echo_ops | B11: B. Repurpose ECHO (ops) | C11: 0 | D11: 1 | E11: 0 | F11: 0.5 | G11: 0 | H11: Repurpose Echo only; ops carry | I11: =$C11 -> 0 | J11: =$C11 -> 0 | K11: =$C11 -> 0 | L11: =$C11 -> 0 | M11: =$C11 -> 0 | N11: ops
A12: C_Repurpose_Pima_lease | B12: C. Repurpose PIMA (lease) | C12: 0 | D12: 0 | E12: 1 | F12: 0.5 | G12: 0 | H12: Repurpose Pima only; lease glide | I12: =$C12 -> 0 | J12: =$C12 -> 0 | K12: =$C12 -> 0 | L12: =$C12 -> 0 | M12: =$C12 -> 0 | N12: lease
A13: C_Repurpose_Pima_ops | B13: C. Repurpose PIMA (ops) | C13: 0 | D13: 0 | E13: 1 | F13: 0.5 | G13: 0 | H13: Repurpose Pima only; ops carry | I13: =$C13 -> 0 | J13: =$C13 -> 0 | K13: =$C13 -> 0 | L13: =$C13 -> 0 | M13: =$C13 -> 0 | N13: ops
A15: ScenarioKey | B15: Year | C15: Echo_ADM | D15: Pima_ADM | E15: Total_ADM | F15: VarUnit$ | G15: EchoFixed$ | H15: PimaFixed$ | I15: Key
A16: =A2 -> D_Grow_Both_0 | B16: FY2026 | C16: =IF(D2=1,0, BaselineCalc!$B$7 + ROUND(I2*F2,0)) -> 257 | D16: =IF(E2=1,0, BaselineCalc!$B$8 + I2 - ROUND(I2*F2,0)) -> 296 | E16: =C16+D16 -> 553 | F16: =YearMap!B2 -> 7129.08 | G16: =YearMap!C2 -> 785217.24 | H16: =YearMap!D2 -> 904374.72 | I16: =A16&"|"&B16 -> D_Grow_Both_0|FY2026
A17: =A2 -> D_Grow_Both_0 | B17: FY2027 | C17: =IF(D2=1,0, BaselineCalc!$B$7 + ROUND(J2*F2,0)) -> 257 | D17: =IF(E2=1,0, BaselineCalc!$B$8 + J2 - ROUND(J2*F2,0)) -> 296 | E17: =C17+D17 -> 553 | F17: =YearMap!B3 -> 7307.307 | G17: =YearMap!C3 -> 804847.67 | H17: =YearMap!D3 -> 926984.09 | I17: =A17&"|"&B17 -> D_Grow_Both_0|FY2027
A18: =A2 -> D_Grow_Both_0 | B18: FY2028 | C18: =IF(D2=1,0, BaselineCalc!$B$7 + ROUND(K2*F2,0)) -> 257 | D18: =IF(E2=1,0, BaselineCalc!$B$8 + K2 - ROUND(K2*F2,0)) -> 296 | E18: =C18+D18 -> 553 | F18: =YearMap!B4 -> 7489.9897 | G18: =YearMap!C4 -> 824968.86 | H18: =YearMap!D4 -> 950158.69 | I18: =A18&"|"&B18 -> D_Grow_Both_0|FY2028
A19: =A2 -> D_Grow_Both_0 | B19: FY2029 | C19: =IF(D2=1,0, BaselineCalc!$B$7 + ROUND(L2*F2,0)) -> 257 | D19: =IF(E2=1,0, BaselineCalc!$B$8 + L2 - ROUND(L2*F2,0)) -> 296 | E19: =C19+D19 -> 553 | F19: =YearMap!B5 -> 7677.2394 | G19: =YearMap!C5 -> 845593.08 | H19: =YearMap!D5 -> 973912.66 | I19: =A19&"|"&B19 -> D_Grow_Both_0|FY2029
A20: =A2 -> D_Grow_Both_0 | B20: FY2030 | C20: =IF(D2=1,0, BaselineCalc!$B$7 + ROUND(M2*F2,0)) -> 257 | D20: =IF(E2=1,0, BaselineCalc!$B$8 + M2 - ROUND(M2*F2,0)) -> 296 | E20: =C20+D20 -> 553 | F20: =YearMap!B6 -> 7869.1704 | G20: =YearMap!C6 -> 866732.91 | H20: =YearMap!D6 -> 998260.47 | I20: =A20&"|"&B20 -> D_Grow_Both_0|FY2030
A21: =A3 -> E_StatusQuo_Targets_0 | B21: FY2026 | C21: =IF(D3=1,0, BaselineCalc!$B$7 + ROUND(I3*F3,0)) -> 257 | D21: =IF(E3=1,0, BaselineCalc!$B$8 + I3 - ROUND(I3*F3,0)) -> 296 | E21: =C21+D21 -> 553 | F21: =YearMap!B2 -> 7129.08 | G21: =YearMap!C2 -> 785217.24 | H21: =YearMap!D2 -> 904374.72 | I21: =A21&"|"&B21 -> E_StatusQuo_Targets_0|FY2026
A22: =A3 -> E_StatusQuo_Targets_0 | B22: FY2027 | C22: =IF(D3=1,0, BaselineCalc!$B$7 + ROUND(J3*F3,0)) -> 257 | D22: =IF(E3=1,0, BaselineCalc!$B$8 + J3 - ROUND(J3*F3,0)) -> 296 | E22: =C22+D22 -> 553 | F22: =YearMap!B3 -> 7307.307 | G22: =YearMap!C3 -> 804847.67 | H22: =YearMap!D3 -> 926984.09 | I22: =A22&"|"&B22 -> E_StatusQuo_Targets_0|FY2027
A23: =A3 -> E_StatusQuo_Targets_0 | B23: FY2028 | C23: =IF(D3=1,0, BaselineCalc!$B$7 + ROUND(K3*F3,0)) -> 257 | D23: =IF(E3=1,0, BaselineCalc!$B$8 + K3 - ROUND(K3*F3,0)) -> 296 | E23: =C23+D23 -> 553 | F23: =YearMap!B4 -> 7489.9897 | G23: =YearMap!C4 -> 824968.86 | H23: =YearMap!D4 -> 950158.69 | I23: =A23&"|"&B23 -> E_StatusQuo_Targets_0|FY2028
A24: =A3 -> E_StatusQuo_Targets_0 | B24: FY2029 | C24: =IF(D3=1,0, BaselineCalc!$B$7 + ROUND(L3*F3,0)) -> 257 | D24: =IF(E3=1,0, BaselineCalc!$B$8 + L3 - ROUND(L3*F3,0)) -> 296 | E24: =C24+D24 -> 553 | F24: =YearMap!B5 -> 7677.2394 | G24: =YearMap!C5 -> 845593.08 | H24: =YearMap!D5 -> 973912.66 | I24: =A24&"|"&B24 -> E_StatusQuo_Targets_0|FY2029
A25: =A3 -> E_StatusQuo_Targets_0 | B25: FY2030 | C25: =IF(D3=1,0, BaselineCalc!$B$7 + ROUND(M3*F3,0)) -> 257 | D25: =IF(E3=1,0, BaselineCalc!$B$8 + M3 - ROUND(M3*F3,0)) -> 296 | E25: =C25+D25 -> 553 | F25: =YearMap!B6 -> 7869.1704 | G25: =YearMap!C6 -> 866732.91 | H25: =YearMap!D6 -> 998260.47 | I25: =A25&"|"&B25 -> E_StatusQuo_Targets_0|FY2030
A26: =A4 -> F_CoLocation_Echo_0 | B26: FY2026 | C26: =IF(D4=1,0, BaselineCalc!$B$7 + ROUND(I4*F4,0)) -> 257 | D26: =IF(E4=1,0, BaselineCalc!$B$8 + I4 - ROUND(I4*F4,0)) -> 296 | E26: =C26+D26 -> 553 | F26: =YearMap!B2 -> 7129.08 | G26: =YearMap!C2 -> 785217.24 | H26: =YearMap!D2 -> 904374.72 | I26: =A26&"|"&B26 -> F_CoLocation_Echo_0|FY2026
A27: =A4 -> F_CoLocation_Echo_0 | B27: FY2027 | C27: =IF(D4=1,0, BaselineCalc!$B$7 + ROUND(J4*F4,0)) -> 257 | D27: =IF(E4=1,0, BaselineCalc!$B$8 + J4 - ROUND(J4*F4,0)) -> 296 | E27: =C27+D27 -> 553 | F27: =YearMap!B3 -> 7307.307 | G27: =YearMap!C3 -> 804847.67 | H27: =YearMap!D3 -> 926984.09 | I27: =A27&"|"&B27 -> F_CoLocation_Echo_0|FY2027
A28: =A4 -> F_CoLocation_Echo_0 | B28: FY2028 | C28: =IF(D4=1,0, BaselineCalc!$B$7 + ROUND(K4*F4,0)) -> 257 | D28: =IF(E4=1,0, BaselineCalc!$B$8 + K4 - ROUND(K4*F4,0)) -> 296 | E28: =C28+D28 -> 553 | F28: =YearMap!B4 -> 7489.9897 | G28: =YearMap!C4 -> 824968.86 | H28: =YearMap!D4 -> 950158.69 | I28: =A28&"|"&B28 -> F_CoLocation_Echo_0|FY2028
A29: =A4 -> F_CoLocation_Echo_0 | B29: FY2029 | C29: =IF(D4=1,0, BaselineCalc!$B$7 + ROUND(L4*F4,0)) -> 257 | D29: =IF(E4=1,0, BaselineCalc!$B$8 + L4 - ROUND(L4*F4,0)) -> 296 | E29: =C29+D29 -> 553 | F29: =YearMap!B5 -> 7677.2394 | G29: =YearMap!C5 -> 845593.08 | H29: =YearMap!D5 -> 973912.66 | I29: =A29&"|"&B29 -> F_CoLocation_Echo_0|FY2029
A30: =A4 -> F_CoLocation_Echo_0 | B30: FY2030 | C30: =IF(D4=1,0, BaselineCalc!$B$7 + ROUND(M4*F4,0)) -> 257 | D30: =IF(E4=1,0, BaselineCalc!$B$8 + M4 - ROUND(M4*F4,0)) -> 296 | E30: =C30+D30 -> 553 | F30: =YearMap!B6 -> 7869.1704 | G30: =YearMap!C6 -> 866732.91 | H30: =YearMap!D6 -> 998260.47 | I30: =A30&"|"&B30 -> F_CoLocation_Echo_0|FY2030
A31: =A5 -> D_Grow_Both_100 | B31: FY2026 | C31: =IF(D5=1,0, BaselineCalc!$B$7 + ROUND(I5*F5,0)) -> 307 | D31: =IF(E5=1,0, BaselineCalc!$B$8 + I5 - ROUND(I5*F5,0)) -> 346 | E31: =C31+D31 -> 653 | F31: =YearMap!B2 -> 7129.08 | G31: =YearMap!C2 -> 785217.24 | H31: =YearMap!D2 -> 904374.72 | I31: =A31&"|"&B31 -> D_Grow_Both_100|FY2026
A32: =A5 -> D_Grow_Both_100 | B32: FY2027 | C32: =IF(D5=1,0, BaselineCalc!$B$7 + ROUND(J5*F5,0)) -> 307 | D32: =IF(E5=1,0, BaselineCalc!$B$8 + J5 - ROUND(J5*F5,0)) -> 346 | E32: =C32+D32 -> 653 | F32: =YearMap!B3 -> 7307.307 | G32: =YearMap!C3 -> 804847.67 | H32: =YearMap!D3 -> 926984.09 | I32: =A32&"|"&B32 -> D_Grow_Both_100|FY2027
A33: =A5 -> D_Grow_Both_100 | B33: FY2028 | C33: =IF(D5=1,0, BaselineCalc!$B$7 + ROUND(K5*F5,0)) -> 307 | D33: =IF(E5=1,0, BaselineCalc!$B$8 + K5 - ROUND(K5*F5,0)) -> 346 | E33: =C33+D33 -> 653 | F33: =YearMap!B4 -> 7489.9897 | G33: =YearMap!C4 -> 824968.86 | H33: =YearMap!D4 -> 950158.69 | I33: =A33&"|"&B33 -> D_Grow_Both_100|FY2028
A34: =A5 -> D_Grow_Both_100 | B34: FY2029 | C34: =IF(D5=1,0, BaselineCalc!$B$7 + ROUND(L5*F5,0)) -> 307 | D34: =IF(E5=1,0, BaselineCalc!$B$8 + L5 - ROUND(L5*F5,0)) -> 346 | E34: =C34+D34 -> 653 | F34: =YearMap!B5 -> 7677.2394 | G34: =YearMap!C5 -> 845593.08 | H34: =YearMap!D5 -> 973912.66 | I34: =A34&"|"&B34 -> D_Grow_Both_100|FY2029
A35: =A5 -> D_Grow_Both_100 | B35: FY2030 | C35: =IF(D5=1,0, BaselineCalc!$B$7 + ROUND(M5*F5,0)) -> 307 | D35: =IF(E5=1,0, BaselineCalc!$B$8 + M5 - ROUND(M5*F5,0)) -> 346 | E35: =C35+D35 -> 653 | F35: =YearMap!B6 -> 7869.1704 | G35: =YearMap!C6 -> 866732.91 | H35: =YearMap!D6 -> 998260.47 | I35: =A35&"|"&B35 -> D_Grow_Both_100|FY2030
A36: =A6 -> D_Grow_Both_150 | B36: FY2026 | C36: =IF(D6=1,0, BaselineCalc!$B$7 + ROUND(I6*F6,0)) -> 332 | D36: =IF(E6=1,0, BaselineCalc!$B$8 + I6 - ROUND(I6*F6,0)) -> 371 | E36: =C36+D36 -> 703 | F36: =YearMap!B2 -> 7129.08 | G36: =YearMap!C2 -> 785217.24 | H36: =YearMap!D2 -> 904374.72 | I36: =A36&"|"&B36 -> D_Grow_Both_150|FY2026
A37: =A6 -> D_Grow_Both_150 | B37: FY2027 | C37: =IF(D6=1,0, BaselineCalc!$B$7 + ROUND(J6*F6,0)) -> 332 | D37: =IF(E6=1,0, BaselineCalc!$B$8 + J6 - ROUND(J6*F6,0)) -> 371 | E37: =C37+D37 -> 703 | F37: =YearMap!B3 -> 7307.307 | G37: =YearMap!C3 -> 804847.67 | H37: =YearMap!D3 -> 926984.09 | I37: =A37&"|"&B37 -> D_Grow_Both_150|FY2027
A38: =A6 -> D_Grow_Both_150 | B38: FY2028 | C38: =IF(D6=1,0, BaselineCalc!$B$7 + ROUND(K6*F6,0)) -> 332 | D38: =IF(E6=1,0, BaselineCalc!$B$8 + K6 - ROUND(K6*F6,0)) -> 371 | E38: =C38+D38 -> 703 | F38: =YearMap!B4 -> 7489.9897 | G38: =YearMap!C4 -> 824968.86 | H38: =YearMap!D4 -> 950158.69 | I38: =A38&"|"&B38 -> D_Grow_Both_150|FY2028
A39: =A6 -> D_Grow_Both_150 | B39: FY2029 | C39: =IF(D6=1,0, BaselineCalc!$B$7 + ROUND(L6*F6,0)) -> 332 | D39: =IF(E6=1,0, BaselineCalc!$B$8 + L6 - ROUND(L6*F6,0)) -> 371 | E39: =C39+D39 -> 703 | F39: =YearMap!B5 -> 7677.2394 | G39: =YearMap!C5 -> 845593.08 | H39: =YearMap!D5 -> 973912.66 | I39: =A39&"|"&B39 -> D_Grow_Both_150|FY2029
A40: =A6 -> D_Grow_Both_150 | B40: FY2030 | C40: =IF(D6=1,0, BaselineCalc!$B$7 + ROUND(M6*F6,0)) -> 332 | D40: =IF(E6=1,0, BaselineCalc!$B$8 + M6 - ROUND(M6*F6,0)) -> 371 | E40: =C40+D40 -> 703 | F40: =YearMap!B6 -> 7869.1704 | G40: =YearMap!C6 -> 866732.91 | H40: =YearMap!D6 -> 998260.47 | I40: =A40&"|"&B40 -> D_Grow_Both_150|FY2030
A41: =A7 -> G_DHub_EchoRamp | B41: FY2026 | C41: =IF(D7=1,0, BaselineCalc!$B$7 + ROUND(I7*F7,0)) -> 292 | D41: =IF(E7=1,0, BaselineCalc!$B$8 + I7 - ROUND(I7*F7,0)) -> 311 | E41: =C41+D41 -> 603 | F41: =YearMap!B2 -> 7129.08 | G41: =YearMap!C2 -> 785217.24 | H41: =YearMap!D2 -> 904374.72 | I41: =A41&"|"&B41 -> G_DHub_EchoRamp|FY2026
...

Sheet MultiYear_ProForma
A1: =Y1 -> Key | B1: ScenarioKey | C1: Year | D1: Echo_ADM | E1: Pima_ADM | F1: Total_ADM | G1: VarUnit$ | H1: EchoFixed$ | I1: PimaFixed$ | J1: OpsFactor | K1: ExtraSave | L1: EchoPotential_ADM | M1: PimaPotential_ADM | N1: Displaced_ADM | O1: Retained_ADM | P1: h | Q1: CarryFrac | R1: EchoFixedEff$ | S1: PimaFixedEff$ | T1: TI_adds$ | U1: SiteCost$ | V1: RetainedSvc$ | W1: Comparable_MO$ | X1: Comparable_per_Student$ | Y1: Key | Z1: Aid_per_ADM | AA1: Net_MO_after_aid$ | AB1: Net_per_served$
A2: =Y2 -> D_Grow_Both_0|FY2026 | B2: =Scenarios!A2 -> D_Grow_Both_0 | C2: FY2026 | D2: =IF(Scenarios!D2=1,0, L2) -> 257 | E2: =IF(Scenarios!E2=1,0, M2) -> 296 | F2: =D2+E2 -> 553 | G2: =YearMap!B2 -> 7129.08 | H2: =YearMap!C2 -> 785217.24 | I2: =YearMap!D2 -> 904374.72 | J2: =1-BaselineCalc!$B$5 -> 0.993 | K2: =Scenarios!G2 -> 0 | L2: =BaselineCalc!$B$7 + ROUND(Scenarios!I2*Scenarios!F2,0) -> 257 | M2: =BaselineCalc!$B$8 + Scenarios!I2 - ROUND(Scenarios!I2*Scenarios!F2,0) -> 296 | N2: =(L2-D2) + (M2-E2) -> 0 | O2: =BaselineCalc!$B$22 * N2 -> 0 | P2: =YearMap!E2 -> 1000 | Q2: =IF(Scenarios!N2="lease", YearMap!F2, YearMap!G2) -> 0.4 | R2: =IF(Scenarios!D2=1, Q2*H2, H2) -> 785217.24 | S2: =IF(Scenarios!E2=1, Q2*I2, I2) -> 904374.72 | T2: =IF(C2="FY2026", (Scenarios!D2+Scenarios!E2)*BaselineCalc!$B$21, 0) -> 0 | U2: =(R2+S2+G2*F2)*J2*(1-K2) -> 5592549.4 | V2: =O2*(G2+P2) -> 0 | W2: =U2+V2+T2 -> 5592549.4 | X2: =IF(F2+O2>0, W2/(F2+O2),"") -> 10113.109 | Y2: =B2&"|"&C2 -> D_Grow_Both_0|FY2026 | Z2: =INDEX(YearMap!$I$2:$I$6, MATCH(C2, YearMap!$A$2:$A$6, 0)) -> 5113 | AA2: =W2-Z2*O2 -> 5592549.4
A3: =Y3 -> D_Grow_Both_0|FY2027 | B3: =Scenarios!A2 -> D_Grow_Both_0 | C3: FY2027 | D3: =IF(Scenarios!D2=1,0, L3) -> 257 | E3: =IF(Scenarios!E2=1,0, M3) -> 296 | F3: =D3+E3 -> 553 | G3: =YearMap!B3 -> 7307.307 | H3: =YearMap!C3 -> 804847.67 | I3: =YearMap!D3 -> 926984.09 | J3: =1-BaselineCalc!$B$5 -> 0.993 | K3: =Scenarios!G2 -> 0 | L3: =BaselineCalc!$B$7 + ROUND(Scenarios!J2*Scenarios!F2,0) -> 257 | M3: =BaselineCalc!$B$8 + Scenarios!J2 - ROUND(Scenarios!J2*Scenarios!F2,0) -> 296 | N3: =(L3-D3) + (M3-E3) -> 0 | O3: =BaselineCalc!$B$22 * N3 -> 0 | P3: =YearMap!E3 -> 800 | Q3: =IF(Scenarios!N2="lease", YearMap!F3, YearMap!G3) -> 0.35 | R3: =IF(Scenarios!D2=1, Q3*H3, H3) -> 804847.67 | S3: =IF(Scenarios!E2=1, Q3*I3, I3) -> 926984.09 | T3: =IF(C3="FY2026", (Scenarios!D2+Scenarios!E2)*BaselineCalc!$B$21, 0) -> 0 | U3: =(R3+S3+G3*F3)*J3*(1-K3) -> 5732363.1 | V3: =O3*(G3+P3) -> 0 | W3: =U3+V3+T3 -> 5732363.1 | X3: =IF(F3+O3>0, W3/(F3+O3),"") -> 10365.937 | Y3: =B3&"|"&C3 -> D_Grow_Both_0|FY2027 | Z3: =INDEX(YearMap!$I$2:$I$6, MATCH(C3, YearMap!$A$2:$A$6, 0)) -> 5215.26 | AA3: =W3-Z3*O3 -> 5732363.1
A4: =Y4 -> D_Grow_Both_0|FY2028 | B4: =Scenarios!A2 -> D_Grow_Both_0 | C4: FY2028 | D4: =IF(Scenarios!D2=1,0, L4) -> 257 | E4: =IF(Scenarios!E2=1,0, M4) -> 296 | F4: =D4+E4 -> 553 | G4: =YearMap!B4 -> 7489.9897 | H4: =YearMap!C4 -> 824968.86 | I4: =YearMap!D4 -> 950158.69 | J4: =1-BaselineCalc!$B$5 -> 0.993 | K4: =Scenarios!G2 -> 0 | L4: =BaselineCalc!$B$7 + ROUND(Scenarios!K2*Scenarios!F2,0) -> 257 | M4: =BaselineCalc!$B$8 + Scenarios!K2 - ROUND(Scenarios!K2*Scenarios!F2,0) -> 296 | N4: =(L4-D4) + (M4-E4) -> 0 | O4: =BaselineCalc!$B$22 * N4 -> 0 | P4: =YearMap!E4 -> 600 | Q4: =IF(Scenarios!N2="lease", YearMap!F4, YearMap!G4) -> 0.3 | R4: =IF(Scenarios!D2=1, Q4*H4, H4) -> 824968.86 | S4: =IF(Scenarios!E2=1, Q4*I4, I4) -> 950158.69 | T4: =IF(C4="FY2026", (Scenarios!D2+Scenarios!E2)*BaselineCalc!$B$21, 0) -> 0 | U4: =(R4+S4+G4*F4)*J4*(1-K4) -> 5875672.2 | V4: =O4*(G4+P4) -> 0 | W4: =U4+V4+T4 -> 5875672.2 | X4: =IF(F4+O4>0, W4/(F4+O4),"") -> 10625.085 | Y4: =B4&"|"&C4 -> D_Grow_Both_0|FY2028 | Z4: =INDEX(YearMap!$I$2:$I$6, MATCH(C4, YearMap!$A$2:$A$6, 0)) -> 5319.5652 | AA4: =W4-Z4*O4 -> 5875672.2
A5: =Y5 -> D_Grow_Both_0|FY2029 | B5: =Scenarios!A2 -> D_Grow_Both_0 | C5: FY2029 | D5: =IF(Scenarios!D2=1,0, L5) -> 257 | E5: =IF(Scenarios!E2=1,0, M5) -> 296 | F5: =D5+E5 -> 553 | G5: =YearMap!B5 -> 7677.2394 | H5: =YearMap!C5 -> 845593.08 | I5: =YearMap!D5 -> 973912.66 | J5: =1-BaselineCalc!$B$5 -> 0.993 | K5: =Scenarios!G2 -> 0 | L5: =BaselineCalc!$B$7 + ROUND(Scenarios!L2*Scenarios!F2,0) -> 257 | M5: =BaselineCalc!$B$8 + Scenarios!L2 - ROUND(Scenarios!L2*Scenarios!F2,0) -> 296 | N5: =(L5-D5) + (M5-E5) -> 0 | O5: =BaselineCalc!$B$22 * N5 -> 0 | P5: =YearMap!E5 -> 400 | Q5: =IF(Scenarios!N2="lease", YearMap!F5, YearMap!G5) -> 0.25 | R5: =IF(Scenarios!D2=1, Q5*H5, H5) -> 845593.08 | S5: =IF(Scenarios!E2=1, Q5*I5, I5) -> 973912.66 | T5: =IF(C5="FY2026", (Scenarios!D2+Scenarios!E2)*BaselineCalc!$B$21, 0) -> 0 | U5: =(R5+S5+G5*F5)*J5*(1-K5) -> 6022564 | V5: =O5*(G5+P5) -> 0 | W5: =U5+V5+T5 -> 6022564 | X5: =IF(F5+O5>0, W5/(F5+O5),"") -> 10890.712 | Y5: =B5&"|"&C5 -> D_Grow_Both_0|FY2029 | Z5: =INDEX(YearMap!$I$2:$I$6, MATCH(C5, YearMap!$A$2:$A$6, 0)) -> 5425.9565 | AA5: =W5-Z5*O5 -> 6022564
A6: =Y6 -> D_Grow_Both_0|FY2030 | B6: =Scenarios!A2 -> D_Grow_Both_0 | C6: FY2030 | D6: =IF(Scenarios!D2=1,0, L6) -> 257 | E6: =IF(Scenarios!E2=1,0, M6) -> 296 | F6: =D6+E6 -> 553 | G6: =YearMap!B6 -> 7869.1704 | H6: =YearMap!C6 -> 866732.91 | I6: =YearMap!D6 -> 998260.47 | J6: =1-BaselineCalc!$B$5 -> 0.993 | K6: =Scenarios!G2 -> 0 | L6: =BaselineCalc!$B$7 + ROUND(Scenarios!M2*Scenarios!F2,0) -> 257 | M6: =BaselineCalc!$B$8 + Scenarios!M2 - ROUND(Scenarios!M2*Scenarios!F2,0) -> 296 | N6: =(L6-D6) + (M6-E6) -> 0 | O6: =BaselineCalc!$B$22 * N6 -> 0 | P6: =YearMap!E6 -> 300 | Q6: =IF(Scenarios!N2="lease", YearMap!F6, YearMap!G6) -> 0.2 | R6: =IF(Scenarios!D2=1, Q6*H6, H6) -> 866732.91 | S6: =IF(Scenarios!E2=1, Q6*I6, I6) -> 998260.47 | T6: =IF(C6="FY2026", (Scenarios!D2+Scenarios!E2)*BaselineCalc!$B$21, 0) -> 0 | U6: =(R6+S6+G6*F6)*J6*(1-K6) -> 6173128.1 | V6: =O6*(G6+P6) -> 0 | W6: =U6+V6+T6 -> 6173128.1 | X6: =IF(F6+O6>0, W6/(F6+O6),"") -> 11162.98 | Y6: =B6&"|"&C6 -> D_Grow_Both_0|FY2030 | Z6: =INDEX(YearMap!$I$2:$I$6, MATCH(C6, YearMap!$A$2:$A$6, 0)) -> 5534.4756 | AA6: =W6-Z6*O6 -> 6173128.1
A7: =Y7 -> E_StatusQuo_Targets_0|FY2026 | B7: =Scenarios!A3 -> E_StatusQuo_Targets_0 | C7: FY2026 | D7: =IF(Scenarios!D3=1,0, L7) -> 257 | E7: =IF(Scenarios!E3=1,0, M7) -> 296 | F7: =D7+E7 -> 553 | G7: =YearMap!B2 -> 7129.08 | H7: =YearMap!C2 -> 785217.24 | I7: =YearMap!D2 -> 904374.72 | J7: =1-BaselineCalc!$B$5 -> 0.993 | K7: =Scenarios!G3 -> 0 | L7: =BaselineCalc!$B$7 + ROUND(Scenarios!I3*Scenarios!F3,0) -> 257 | M7: =BaselineCalc!$B$8 + Scenarios!I3 - ROUND(Scenarios!J3*Scenarios!F3,0) -> 296 | N7: =(L7-D7) + (M7-E7) -> 0 | O7: =BaselineCalc!$B$22 * N7 -> 0 | P7: =YearMap!E2 -> 1000 | Q7: =IF(Scenarios!N3="lease", YearMap!F2, YearMap!G2) -> 0.4 | R7: =IF(Scenarios!D3=1, Q7*H7, H7) -> 785217.24 | S7: =IF(Scenarios!E3=1, Q7*I7, I7) -> 904374.72 | T7: =IF(C7="FY2026", (Scenarios!D3+Scenarios!E3)*BaselineCalc!$B$21, 0) -> 0 | U7: =(R7+S7+G7*F7)*J7*(1-K7) -> 5592549.4 | V7: =O7*(G7+P7) -> 0 | W7: =U7+V7+T7 -> 5592549.4 | X7: =IF(F7+O7>0, W7/(F7+O7),"") -> 10113.109 | Y7: =B7&"|"&C7 -> E_StatusQuo_Targets_0|FY2026 | Z7: =INDEX(YearMap!$I$2:$I$6, MATCH(C7, YearMap!$A$2:$A$6, 0)) -> 5113 | AA7: =W7-Z7*O7 -> 5592549.4
A8: =Y8 -> E_StatusQuo_Targets_0|FY2027 | B8: =Scenarios!A3 -> E_StatusQuo_Targets_0 | C8: FY2027 | D8: =IF(Scenarios!D3=1,0, L8) -> 257 | E8: =IF(Scenarios!E3=1,0, M8) -> 296 | F8: =D8+E8 -> 553 | G8: =YearMap!B3 -> 7307.307 | H8: =YearMap!C3 -> 804847.67 | I8: =YearMap!D3 -> 926984.09 | J8: =1-BaselineCalc!$B$5 -> 0.993 | K8: =Scenarios!G3 -> 0 | L8: =BaselineCalc!$B$7 + ROUND(Scenarios!J3*Scenarios!F3,0) -> 257 | M8: =BaselineCalc!$B$8 + Scenarios!J3 - ROUND(Scenarios!J3*Scenarios!F3,0) -> 296 | N8: =(L8-D8) + (M8-E8) -> 0 | O8: =BaselineCalc!$B$22 * N8 -> 0 | P8: =YearMap!E3 -> 800 | Q8: =IF(Scenarios!N3="lease", YearMap!F3, YearMap!G3) -> 0.35 | R8: =IF(Scenarios!D3=1, Q8*H8, H8) -> 804847.67 | S8: =IF(Scenarios!E3=1, Q8*I8, I8) -> 926984.09 | T8: =IF(C8="FY2026", (Scenarios!D3+Scenarios!E3)*BaselineCalc!$B$21, 0) -> 0 | U8: =(R8+S8+G8*F8)*J8*(1-K8) -> 5732363.1 | V8: =O8*(G8+P8) -> 0 | W8: =U8+V8+T8 -> 5732363.1 | X8: =IF(F8+O8>0, W8/(F8+O8),"") -> 10365.937 | Y8: =B8&"|"&C8 -> E_StatusQuo_Targets_0|FY2027 | Z8: =INDEX(YearMap!$I$2:$I$6, MATCH(C8, YearMap!$A$2:$A$6, 0)) -> 5215.26 | AA8: =W8-Z8*O8 -> 5732363.1
A9: =Y9 -> E_StatusQuo_Targets_0|FY2028 | B9: =Scenarios!A3 -> E_StatusQuo_Targets_0 | C9: FY2028 | D9: =IF(Scenarios!D3=1,0, L9) -> 257 | E9: =IF(Scenarios!E3=1,0, M9) -> 296 | F9: =D9+E9 -> 553 | G9: =YearMap!B4 -> 7489.9897 | H9: =YearMap!C4 -> 824968.86 | I9: =YearMap!D4 -> 950158.69 | J9: =1-BaselineCalc!$B$5 -> 0.993 | K9: =Scenarios!G3 -> 0 | L9: =BaselineCalc!$B$7 + ROUND(Scenarios!K3*Scenarios!F3,0) -> 257 | M9: =BaselineCalc!$B$8 + Scenarios!K3 - ROUND(Scenarios!K3*Scenarios!F3,0) -> 296 | N9: =(L9-D9) + (M9-E9) -> 0 | O9: =BaselineCalc!$B$22 * N9 -> 0 | P9: =YearMap!E4 -> 600 | Q9: =IF(Scenarios!N3="lease", YearMap!F4, YearMap!G4) -> 0.3 | R9: =IF(Scenarios!D3=1, Q9*H9, H9) -> 824968.86 | S9: =IF(Scenarios!E3=1, Q9*I9, I9) -> 950158.69 | T9: =IF(C9="FY2026", (Scenarios!D3+Scenarios!E3)*BaselineCalc!$B$21, 0) -> 0 | U9: =(R9+S9+G9*F9)*J9*(1-K9) -> 5875672.2 | V9: =O9*(G9+P9) -> 0 | W9: =U9+V9+T9 -> 5875672.2 | X9: =IF(F9+O9>0, W9/(F9+O9),"") -> 10625.085 | Y9: =B9&"|"&C9 -> E_StatusQuo_Targets_0|FY2028 | Z9: =INDEX(YearMap!$I$2:$I$6, MATCH(C9, YearMap!$A$2:$A$6, 0)) -> 5319.5652 | AA9: =W9-Z9*O9 -> 5875672.2
A10: =Y10 -> E_StatusQuo_Targets_0|FY2029 | B10: =Scenarios!A3 -> E_StatusQuo_Targets_0 | C10: FY2029 | D10: =IF(Scenarios!D3=1,0, L10) -> 257 | E10: =IF(Scenarios!E3=1,0, M10) -> 296 | F10: =D10+E10 -> 553 | G10: =YearMap!B5 -> 7677.2394 | H10: =YearMap!C5 -> 845593.08 | I10: =YearMap!D5 -> 973912.66 | J10: =1-BaselineCalc!$B$5 -> 0.993 | K10: =Scenarios!G3 -> 0 | L10: =BaselineCalc!$B$7 + ROUND(Scenarios!L3*Scenarios!F3,0) -> 257 | M10: =BaselineCalc!$B$8 + Scenarios!L3 - ROUND(Scenarios!L3*Scenarios!F3,0) -> 296 | N10: =(L10-D10) + (M10-E10) -> 0 | O10: =BaselineCalc!$B$22 * N10 -> 0 | P10: =YearMap!E5 -> 400 | Q10: =IF(Scenarios!N3="lease", YearMap!F5, YearMap!G5) -> 0.25 | R10: =IF(Scenarios!D3=1, Q10*H10, H10) -> 845593.08 | S10: =IF(Scenarios!E3=1, Q10*I10, I10) -> 973912.66 | T10: =IF(C10="FY2026", (Scenarios!D3+Scenarios!E3)*BaselineCalc!$B$21, 0) -> 0 | U10: =(R10+S10+G10*F10)*J10*(1-K10) -> 6022564 | V10: =O10*(G10+P10) -> 0 | W10: =U10+V10+T10 -> 6022564 | X10: =IF(F10+O10>0, W10/(F10+O10),"") -> 10890.712 | Y10: =B10&"|"&C10 -> E_StatusQuo_Targets_0|FY2029 | Z10: =INDEX(YearMap!$I$2:$I$6, MATCH(C10, YearMap!$A$2:$A$6, 0)) -> 5425.9565 | AA10: =W10-Z10*O10 -> 6022564
A11: =Y11 -> E_StatusQuo_Targets_0|FY2030 | B11: =Scenarios!A3 -> E_StatusQuo_Targets_0 | C11: FY2030 | D11: =IF(Scenarios!D3=1,0, L11) -> 257 | E11: =IF(Scenarios!E3=1,0, M11) -> 296 | F11: =D11+E11 -> 553 | G11: =YearMap!B6 -> 7869.1704 | H11: =YearMap!C6 -> 866732.91 | I11: =YearMap!D6 -> 998260.47 | J11: =1-BaselineCalc!$B$5 -> 0.993 | K11: =Scenarios!G3 -> 0 | L11: =BaselineCalc!$B$7 + ROUND(Scenarios!M3*Scenarios!F3,0) -> 257 | M11: =BaselineCalc!$B$8 + Scenarios!M3 - ROUND(Scenarios!M3*Scenarios!F3,0) -> 296 | N11: =(L11-D11) + (M11-E11) -> 0 | O11: =BaselineCalc!$B$22 * N11 -> 0 | P11: =YearMap!E6 -> 300 | Q11: =IF(Scenarios!N3="lease", YearMap!F6, YearMap!G6) -> 0.2 | R11: =IF(Scenarios!D3=1, Q11*H11, H11) -> 866732.91 | S11: =IF(Scenarios!E3=1, Q11*I11, I11) -> 998260.47 | T11: =IF(C11="FY2026", (Scenarios!D3+Scenarios!E3)*BaselineCalc!$B$21, 0) -> 0 | U11: =(R11+S11+G11*F11)*J11*(1-K11) -> 6173128.1 | V11: =O11*(G11+P11) -> 0 | W11: =U11+V11+T11 -> 6173128.1 | X11: =IF(F11+O11>0, W11/(F11+O11),"") -> 11162.98 | Y11: =B11&"|"&C11 -> E_StatusQuo_Targets_0|FY2030 | Z11: =INDEX(YearMap!$I$2:$I$6, MATCH(C11, YearMap!$A$2:$A$6, 0)) -> 5534.4756 | AA11: =W11-Z11*O11 -> 6173128.1
A12: =Y12 -> F_CoLocation_Echo_0|FY2026 | B12: =Scenarios!A4 -> F_CoLocation_Echo_0 | C12: FY2026 | D12: =IF(Scenarios!D4=1,0, L12) -> 257 | E12: =IF(Scenarios!E4=1,0, M12) -> 296 | F12: =D12+E12 -> 553 | G12: =YearMap!B2 -> 7129.08 | H12: =YearMap!C2 -> 785217.24 | I12: =YearMap!D2 -> 904374.72 | J12: =1-BaselineCalc!$B$5 -> 0.993 | K12: =Scenarios!G4 -> 0.015 | L12: =BaselineCalc!$B$7 + ROUND(Scenarios!I4*Scenarios!F4,0) -> 257 | M12: =BaselineCalc!$B$8 + Scenarios!I4 - ROUND(Scenarios!I4*Scenarios!F4,0) -> 296 | N12: =(L12-D12) + (M12-E12) -> 0 | O12: =BaselineCalc!$B$22 * N12 -> 0 | P12: =YearMap!E2 -> 1000 | Q12: =IF(Scenarios!N4="lease", YearMap!F2, YearMap!G2) -> 0.4 | R12: =IF(Scenarios!D4=1, Q12*H12, H12) -> 785217.24 | S12: =IF(Scenarios!E4=1, Q12*I12, I12) -> 904374.72 | T12: =IF(C12="FY2026", (Scenarios!D4+Scenarios!E4)*BaselineCalc!$B$21, 0) -> 0 | U12: =(R12+S12+G12*F12)*J12*(1-K12) -> 5508661.1 | V12: =O12*(G12+P12) -> 0 | W12: =U12+V12+T12 -> 5508661.1 | X12: =IF(F12+O12>0, W12/(F12+O12),"") -> 9961.4126 | Y12: =B12&"|"&C12 -> F_CoLocation_Echo_0|FY2026 | Z12: =INDEX(YearMap!$I$2:$I$6, MATCH(C12, YearMap!$A$2:$A$6, 0)) -> 5113 | AA12: =W12-Z12*O12 -> 5508661.1
A13: =Y13 -> F_CoLocation_Echo_0|FY2027 | B13: =Scenarios!A4 -> F_CoLocation_Echo_0 | C13: FY2027 | D13: =IF(Scenarios!D4=1,0, L13) -> 257 | E13: =IF(Scenarios!E4=1,0, M13) -> 296 | F13: =D13+E13 -> 553 | G13: =YearMap!B3 -> 7307.307 | H13: =YearMap!C3 -> 804847.67 | I13: =YearMap!D3 -> 926984.09 | J13: =1-BaselineCalc!$B$5 -> 0.993 | K13: =Scenarios!G4 -> 0.015 | L13: =BaselineCalc!$B$7 + ROUND(Scenarios!J4*Scenarios!F4,0) -> 257 | M13: =BaselineCalc!$B$8 + Scenarios!J4 - ROUND(Scenarios!J4*Scenarios!F4,0) -> 296 | N13: =(L13-D13) + (M13-E13) -> 0 | O13: =BaselineCalc!$B$22 * N13 -> 0 | P13: =YearMap!E3 -> 800 | Q13: =IF(Scenarios!N4="lease", YearMap!F3, YearMap!G3) -> 0.35 | R13: =IF(Scenarios!D4=1, Q13*H13, H13) -> 804847.67 | S13: =IF(Scenarios!E4=1, Q13*I13, I13) -> 926984.09 | T13: =IF(C13="FY2026", (Scenarios!D4+Scenarios!E4)*BaselineCalc!$B$21, 0) -> 0 | U13: =(R13+S13+G13*F13)*J13*(1-K13) -> 5646377.7 | V13: =O13*(G13+P13) -> 0 | W13: =U13+V13+T13 -> 5646377.7 | X13: =IF(F13+O13>0, W13/(F13+O13),"") -> 10210.448 | Y13: =B13&"|"&C13 -> F_CoLocation_Echo_0|FY2027 | Z13: =INDEX(YearMap!$I$2:$I$6, MATCH(C13, YearMap!$A$2:$A$6, 0)) -> 5215.26 | AA13: =W13-Z13*O13 -> 5646377.7
A14: =Y14 -> F_CoLocation_Echo_0|FY2028 | B14: =Scenarios!A4 -> F_CoLocation_Echo_0 | C14: FY2028 | D14: =IF(Scenarios!D4=1,0, L14) -> 257 | E14: =IF(Scenarios!E4=1,0, M14) -> 296 | F14: =D14+E14 -> 553 | G14: =YearMap!B4 -> 7489.9897 | H14: =YearMap!C4 -> 824968.86 | I14: =YearMap!D4 -> 950158.69 | J14: =1-BaselineCalc!$B$5 -> 0.993 | K14: =Scenarios!G4 -> 0.015 | L14: =BaselineCalc!$B$7 + ROUND(Scenarios!K4*Scenarios!F4,0) -> 257 | M14: =BaselineCalc!$B$8 + Scenarios!K4 - ROUND(Scenarios!K4*Scenarios!F4,0) -> 296 | N14: =(L14-D14) + (M14-E14) -> 0 | O14: =BaselineCalc!$B$22 * N14 -> 0 | P14: =YearMap!E4 -> 600 | Q14: =IF(Scenarios!N4="lease", YearMap!F4, YearMap!G4) -> 0.3 | R14: =IF(Scenarios!D4=1, Q14*H14, H14) -> 824968.86 | S14: =IF(Scenarios!E4=1, Q14*I14, I14) -> 950158.69 | T14: =IF(C14="FY2026", (Scenarios!D4+Scenarios!E4)*BaselineCalc!$B$21, 0) -> 0 | U14: =(R14+S14+G14*F14)*J14*(1-K14) -> 5787537.1 | V14: =O14*(G14+P14) -> 0 | W14: =U14+V14+T14 -> 5787537.1 | X14: =IF(F14+O14>0, W14/(F14+O14),"") -> 10465.709 | Y14: =B14&"|"&C14 -> F_CoLocation_Echo_0|FY2028 | Z14: =INDEX(YearMap!$I$2:$I$6, MATCH(C14, YearMap!$A$2:$A$6, 0)) -> 5319.5652 | AA14: =W14-Z14*O14 -> 5787537.1
A15: =Y15 -> F_CoLocation_Echo_0|FY2029 | B15: =Scenarios!A4 -> F_CoLocation_Echo_0 | C15: FY2029 | D15: =IF(Scenarios!D4=1,0, L15) -> 257 | E15: =IF(Scenarios!E4=1,0, M15) -> 296 | F15: =D15+E15 -> 553 | G15: =YearMap!B5 -> 7677.2394 | H15: =YearMap!C5 -> 845593.08 | I15: =YearMap!D5 -> 973912.66 | J15: =1-BaselineCalc!$B$5 -> 0.993 | K15: =Scenarios!G4 -> 0.015 | L15: =BaselineCalc!$B$7 + ROUND(Scenarios!L4*Scenarios!F4,0) -> 257 | M15: =BaselineCalc!$B$8 + Scenarios!L4 - ROUND(Scenarios!L4*Scenarios!F4,0) -> 296 | N15: =(L15-D15) + (M15-E15) -> 0 | O15: =BaselineCalc!$B$22 * N15 -> 0 | P15: =YearMap!E5 -> 400 | Q15: =IF(Scenarios!N4="lease", YearMap!F5, YearMap!G5) -> 0.25 | R15: =IF(Scenarios!D4=1, Q15*H15, H15) -> 845593.08 | S15: =IF(Scenarios!E4=1, Q15*I15, I15) -> 973912.66 | T15: =IF(C15="FY2026", (Scenarios!D4+Scenarios!E4)*BaselineCalc!$B$21, 0) -> 0 | U15: =(R15+S15+G15*F15)*J15*(1-K15) -> 5932225.5 | V15: =O15*(G15+P15) -> 0 | W15: =U15+V15+T15 -> 5932225.5 | X15: =IF(F15+O15>0, W15/(F15+O15),"") -> 10727.352 | Y15: =B15&"|"&C15 -> F_CoLocation_Echo_0|FY2029 | Z15: =INDEX(YearMap!$I$2:$I$6, MATCH(C15, YearMap!$A$2:$A$6, 0)) -> 5425.9565 | AA15: =W15-Z15*O15 -> 5932225.5
A16: =Y16 -> F_CoLocation_Echo_0|FY2030 | B16: =Scenarios!A4 -> F_CoLocation_Echo_0 | C16: FY2030 | D16: =IF(Scenarios!D4=1,0, L16) -> 257 | E16: =IF(Scenarios!E4=1,0, M16) -> 296 | F16: =D16+E16 -> 553 | G16: =YearMap!B6 -> 7869.1704 | H16: =YearMap!C6 -> 866732.91 | I16: =YearMap!D6 -> 998260.47 | J16: =1-BaselineCalc!$B$5 -> 0.993 | K16: =Scenarios!G4 -> 0.015 | L16: =BaselineCalc!$B$7 + ROUND(Scenarios!M4*Scenarios!F4,0) -> 257 | M16: =BaselineCalc!$B$8 + Scenarios!M4 - ROUND(Scenarios!M4*Scenarios!F4,0) -> 296 | N16: =(L16-D16) + (M16-E16) -> 0 | O16: =BaselineCalc!$B$22 * N16 -> 0 | P16: =YearMap!E6 -> 300 | Q16: =IF(Scenarios!N4="lease", YearMap!F6, YearMap!G6) -> 0.2 | R16: =IF(Scenarios!D4=1, Q16*H16, H16) -> 866732.91 | S16: =IF(Scenarios!E4=1, Q16*I16, I16) -> 998260.47 | T16: =IF(C16="FY2026", (Scenarios!D4+Scenarios!E4)*BaselineCalc!$B$21, 0) -> 0 | U16: =(R16+S16+G16*F16)*J16*(1-K16) -> 6080531.2 | V16: =O16*(G16+P16) -> 0 | W16: =U16+V16+T16 -> 6080531.2 | X16: =IF(F16+O16>0, W16/(F16+O16),"") -> 10995.536 | Y16: =B16&"|"&C16 -> F_CoLocation_Echo_0|FY2030 | Z16: =INDEX(YearMap!$I$2:$I$6, MATCH(C16, YearMap!$A$2:$A$6, 0)) -> 5534.4756 | AA16: =W16-Z16*O16 -> 6080531.2
A17: =Y17 -> D_Grow_Both_100|FY2026 | B17: =Scenarios!A5 -> D_Grow_Both_100 | C17: FY2026 | D17: =IF(Scenarios!D5=1,0, L17) -> 307 | E17: =IF(Scenarios!E5=1,0, M17) -> 346 | F17: =D17+E17 -> 653 | G17: =YearMap!B2 -> 7129.08 | H17: =YearMap!C2 -> 785217.24 | I17: =YearMap!D2 -> 904374.72 | J17: =1-BaselineCalc!$B$5 -> 0.993 | K17: =Scenarios!G5 -> 0 | L17: =BaselineCalc!$B$7 + ROUND(Scenarios!I5*Scenarios!F5,0) -> 307 | M17: =BaselineCalc!$B$8 + Scenarios!I5 - ROUND(Scenarios!I5*Scenarios!F5,0) -> 346 | N17: =(L17-D17) + (M17-E17) -> 0 | O17: =BaselineCalc!$B$22 * N17 -> 0 | P17: =YearMap!E2 -> 1000 | Q17: =IF(Scenarios!N5="lease", YearMap!F2, YearMap!G2) -> 0.4 | R17: =IF(Scenarios!D5=1, Q17*H17, H17) -> 785217.24 | S17: =IF(Scenarios!E5=1, Q17*I17, I17) -> 904374.72 | T17: =IF(C17="FY2026", (Scenarios!D5+Scenarios!E5)*BaselineCalc!$B$21, 0) -> 0 | U17: =(R17+S17+G17*F17)*J17*(1-K17) -> 6300467 | V17: =O17*(G17+P17) -> 0 | W17: =U17+V17+T17 -> 6300467 | X17: =IF(F17+O17>0, W17/(F17+O17),"") -> 9648.4947 | Y17: =B17&"|"&C17 -> D_Grow_Both_100|FY2026 | Z17: =INDEX(YearMap!$I$2:$I$6, MATCH(C17, YearMap!$A$2:$A$6, 0)) -> 5113 | AA17: =W17-Z17*O17 -> 6300467
A18: =Y18 -> D_Grow_Both_100|FY2027 | B18: =Scenarios!A5 -> D_Grow_Both_100 | C18: FY2027 | D18: =IF(Scenarios!D5=1,0, L18) -> 307 | E18: =IF(Scenarios!E5=1,0, M18) -> 346 | F18: =D18+E18 -> 653 | G18: =YearMap!B3 -> 7307.307 | H18: =YearMap!C3 -> 804847.67 | I18: =YearMap!D3 -> 926984.09 | J18: =1-BaselineCalc!$B$5 -> 0.993 | K18: =Scenarios!G5 -> 0 | L18: =BaselineCalc!$B$7 + ROUND(Scenarios!J5*Scenarios!F5,0) -> 307 | M18: =BaselineCalc!$B$8 + Scenarios!J5 - ROUND(Scenarios!J5*Scenarios!F5,0) -> 346 | N18: =(L18-D18) + (M18-E18) -> 0 | O18: =BaselineCalc!$B$22 * N18 -> 0 | P18: =YearMap!E3 -> 800 | Q18: =IF(Scenarios!N5="lease", YearMap!F3, YearMap!G3) -> 0.35 | R18: =IF(Scenarios!D5=1, Q18*H18, H18) -> 804847.67 | S18: =IF(Scenarios!E5=1, Q18*I18, I18) -> 926984.09 | T18: =IF(C18="FY2026", (Scenarios!D5+Scenarios!E5)*BaselineCalc!$B$21, 0) -> 0 | U18: =(R18+S18+G18*F18)*J18*(1-K18) -> 6457978.7 | V18: =O18*(G18+P18) -> 0 | W18: =U18+V18+T18 -> 6457978.7 | X18: =IF(F18+O18>0, W18/(F18+O18),"") -> 9889.7071 | Y18: =B18&"|"&C18 -> D_Grow_Both_100|FY2027 | Z18: =INDEX(YearMap!$I$2:$I$6, MATCH(C18, YearMap!$A$2:$A$6, 0)) -> 5215.26 | AA18: =W18-Z18*O18 -> 6457978.7
A19: =Y19 -> D_Grow_Both_100|FY2028 | B19: =Scenarios!A5 -> D_Grow_Both_100 | C19: FY2028 | D19: =IF(Scenarios!D5=1,0, L19) -> 307 | E19: =IF(Scenarios!E5=1,0, M19) -> 346 | F19: =D19+E19 -> 653 | G19: =YearMap!B4 -> 7489.9897 | H19: =YearMap!C4 -> 824968.86 | I19: =YearMap!D4 -> 950158.69 | J19: =1-BaselineCalc!$B$5 -> 0.993 | K19: =Scenarios!G5 -> 0 | L19: =BaselineCalc!$B$7 + ROUND(Scenarios!K5*Scenarios!F5,0) -> 307 | M19: =BaselineCalc!$B$8 + Scenarios!K5 - ROUND(Scenarios!K5*Scenarios!F5,0) -> 346 | N19: =(L19-D19) + (M19-E19) -> 0 | O19: =BaselineCalc!$B$22 * N19 -> 0 | P19: =YearMap!E4 -> 600 | Q19: =IF(Scenarios!N5="lease", YearMap!F4, YearMap!G4) -> 0.3 | R19: =IF(Scenarios!D5=1, Q19*H19, H19) -> 824968.86 | S19: =IF(Scenarios!E5=1, Q19*I19, I19) -> 950158.69 | T19: =IF(C19="FY2026", (Scenarios!D5+Scenarios!E5)*BaselineCalc!$B$21, 0) -> 0 | U19: =(R19+S19+G19*F19)*J19*(1-K19) -> 6619428.2 | V19: =O19*(G19+P19) -> 0 | W19: =U19+V19+T19 -> 6619428.2 | X19: =IF(F19+O19>0, W19/(F19+O19),"") -> 10136.95 | Y19: =B19&"|"&C19 -> D_Grow_Both_100|FY2028 | Z19: =INDEX(YearMap!$I$2:$I$6, MATCH(C19, YearMap!$A$2:$A$6, 0)) -> 5319.5652 | AA19: =W19-Z19*O19 -> 6619428.2
A20: =Y20 -> D_Grow_Both_100|FY2029 | B20: =Scenarios!A5 -> D_Grow_Both_100 | C20: FY2029 | D20: =IF(Scenarios!D5=1,0, L20) -> 307 | E20: =IF(Scenarios!E5=1,0, M20) -> 346 | F20: =D20+E20 -> 653 | G20: =YearMap!B5 -> 7677.2394 | H20: =YearMap!C5 -> 845593.08 | I20: =YearMap!D5 -> 973912.66 | J20: =1-BaselineCalc!$B$5 -> 0.993 | K20: =Scenarios!G5 -> 0 | L20: =BaselineCalc!$B$7 + ROUND(Scenarios!L5*Scenarios!F5,0) -> 307 | M20: =BaselineCalc!$B$8 + Scenarios!L5 - ROUND(Scenarios!L5*Scenarios!F5,0) -> 346 | N20: =(L20-D20) + (M20-E20) -> 0 | O20: =BaselineCalc!$B$22 * N20 -> 0 | P20: =YearMap!E5 -> 400 | Q20: =IF(Scenarios!N5="lease", YearMap!F5, YearMap!G5) -> 0.25 | R20: =IF(Scenarios!D5=1, Q20*H20, H20) -> 845593.08 | S20: =IF(Scenarios!E5=1, Q20*I20, I20) -> 973912.66 | T20: =IF(C20="FY2026", (Scenarios!D5+Scenarios!E5)*BaselineCalc!$B$21, 0) -> 0 | U20: =(R20+S20+G20*F20)*J20*(1-K20) -> 6784913.9 | V20: =O20*(G20+P20) -> 0 | W20: =U20+V20+T20 -> 6784913.9 | X20: =IF(F20+O20>0, W20/(F20+O20),"") -> 10390.373 | Y20: =B20&"|"&C20 -> D_Grow_Both_100|FY2029 | Z20: =INDEX(YearMap!$I$2:$I$6, MATCH(C20, YearMap!$A$2:$A$6, 0)) -> 5425.9565 | AA20: =W20-Z20*O20 -> 6784913.9
A21: =Y21 -> D_Grow_Both_100|FY2030 | B21: =Scenarios!A5 -> D_Grow_Both_100 | C21: FY2030 | D21: =IF(Scenarios!D5=1,0, L21) -> 307 | E21: =IF(Scenarios!E5=1,0, M21) -> 346 | F21: =D21+E21 -> 653 | G21: =YearMap!B6 -> 7869.1704 | H21: =YearMap!C6 -> 866732.91 | I21: =YearMap!D6 -> 998260.47 | J21: =1-BaselineCalc!$B$5 -> 0.993 | K21: =Scenarios!G5 -> 0 | L21: =BaselineCalc!$B$7 + ROUND(Scenarios!M5*Scenarios!F5,0) -> 307 | M21: =BaselineCalc!$B$8 + Scenarios!M5 - ROUND(Scenarios!M5*Scenarios!F5,0) -> 346 | N21: =(L21-D21) + (M21-E21) -> 0 | O21: =BaselineCalc!$B$22 * N21 -> 0 | P21: =YearMap!E6 -> 300 | Q21: =IF(Scenarios!N5="lease", YearMap!F6, YearMap!G6) -> 0.2 | R21: =IF(Scenarios!D5=1, Q21*H21, H21) -> 866732.91 | S21: =IF(Scenarios!E5=1, Q21*I21, I21) -> 998260.47 | T21: =IF(C21="FY2026", (Scenarios!D5+Scenarios!E5)*BaselineCalc!$B$21, 0) -> 0 | U21: =(R21+S21+G21*F21)*J21*(1-K21) -> 6954536.7 | V21: =O21*(G21+P21) -> 0 | W21: =U21+V21+T21 -> 6954536.7 | X21: =IF(F21+O21>0, W21/(F21+O21),"") -> 10650.133 | Y21: =B21&"|"&C21 -> D_Grow_Both_100|FY2030 | Z21: =INDEX(YearMap!$I$2:$I$6, MATCH(C21, YearMap!$A$2:$A$6, 0)) -> 5534.4756 | AA21: =W21-Z21*O21 -> 6954536.7
A22: =Y22 -> D_Grow_Both_150|FY2026 | B22: =Scenarios!A6 -> D_Grow_Both_150 | C22: FY2026 | D22: =IF(Scenarios!D6=1,0, L22) -> 332 | E22: =IF(Scenarios!E6=1,0, M22) -> 371 | F22: =D22+E22 -> 703 | G22: =YearMap!B2 -> 7129.08 | H22: =YearMap!C2 -> 785217.24 | I22: =YearMap!D2 -> 904374.72 | J22: =1-BaselineCalc!$B$5 -> 0.993 | K22: =Scenarios!G6 -> 0 | L22: =BaselineCalc!$B$7 + ROUND(Scenarios!I6*Scenarios!F6,0) -> 332 | M22: =BaselineCalc!$B$8 + Scenarios!I6 - ROUND(Scenarios!I6*Scenarios!F6,0) -> 371 | N22: =(L22-D22) + (M22-E22) -> 0 | O22: =BaselineCalc!$B$22 * N22 -> 0 | P22: =YearMap!E2 -> 1000 | Q22: =IF(Scenarios!N6="lease", YearMap!F2, YearMap!G2) -> 0.4 | R22: =IF(Scenarios!D6=1, Q22*H22, H22) -> 785217.24 | S22: =IF(Scenarios!E6=1, Q22*I22, I22) -> 904374.72 | T22: =IF(C22="FY2026", (Scenarios!D6+Scenarios!E6)*BaselineCalc!$B$21, 0) -> 0 | U22: =(R22+S22+G22*F22)*J22*(1-K22) -> 6654425.9 | V22: =O22*(G22+P22) -> 0 | W22: =U22+V22+T22 -> 6654425.9 | X22: =IF(F22+O22>0, W22/(F22+O22),"") -> 9465.7551 | Y22: =B22&"|"&C22 -> D_Grow_Both_150|FY2026 | Z22: =INDEX(YearMap!$I$2:$I$6, MATCH(C22, YearMap!$A$2:$A$6, 0)) -> 5113 | AA22: =W22-Z22*O22 -> 6654425.9
A23: =Y23 -> D_Grow_Both_150|FY2027 | B23: =Scenarios!A6 -> D_Grow_Both_150 | C23: FY2027 | D23: =IF(Scenarios!D6=1,0, L23) -> 332 | E23: =IF(Scenarios!E6=1,0, M23) -> 371 | F23: =D23+E23 -> 703 | G23: =YearMap!B3 -> 7307.307 | H23: =YearMap!C3 -> 804847.67 | I23: =YearMap!D3 -> 926984.09 | J23: =1-BaselineCalc!$B$5 -> 0.993 | K23: =Scenarios!G6 -> 0 | L23: =BaselineCalc!$B$7 + ROUND(Scenarios!J6*Scenarios!F6,0) -> 332 | M23: =BaselineCalc!$B$8 + Scenarios!J6 - ROUND(Scenarios!J6*Scenarios!F6,0) -> 371 | N23: =(L23-D23) + (M23-E23) -> 0 | O23: =BaselineCalc!$B$22 * N23 -> 0 | P23: =YearMap!E3 -> 800 | Q23: =IF(Scenarios!N6="lease", YearMap!F3, YearMap!G3) -> 0.35 | R23: =IF(Scenarios!D6=1, Q23*H23, H23) -> 804847.67 | S23: =IF(Scenarios!E6=1, Q23*I23, I23) -> 926984.09 | T23: =IF(C23="FY2026", (Scenarios!D6+Scenarios!E6)*BaselineCalc!$B$21, 0) -> 0 | U23: =(R23+S23+G23*F23)*J23*(1-K23) -> 6820786.5 | V23: =O23*(G23+P23) -> 0 | W23: =U23+V23+T23 -> 6820786.5 | X23: =IF(F23+O23>0, W23/(F23+O23),"") -> 9702.399 | Y23: =B23&"|"&C23 -> D_Grow_Both_150|FY2027 | Z23: =INDEX(YearMap!$I$2:$I$6, MATCH(C23, YearMap!$A$2:$A$6, 0)) -> 5215.26 | AA23: =W23-Z23*O23 -> 6820786.5
A24: =Y24 -> D_Grow_Both_150|FY2028 | B24: =Scenarios!A6 -> D_Grow_Both_150 | C24: FY2028 | D24: =IF(Scenarios!D6=1,0, L24) -> 332 | E24: =IF(Scenarios!E6=1,0, M24) -> 371 | F24: =D24+E24 -> 703 | G24: =YearMap!B4 -> 7489.9897 | H24: =YearMap!C4 -> 824968.86 | I24: =YearMap!D4 -> 950158.69 | J24: =1-BaselineCalc!$B$5 -> 0.993 | K24: =Scenarios!G6 -> 0 | L24: =BaselineCalc!$B$7 + ROUND(Scenarios!K6*Scenarios!F6,0) -> 332 | M24: =BaselineCalc!$B$8 + Scenarios!K6 - ROUND(Scenarios!K6*Scenarios!F6,0) -> 371 | N24: =(L24-D24) + (M24-E24) -> 0 | O24: =BaselineCalc!$B$22 * N24 -> 0 | P24: =YearMap!E4 -> 600 | Q24: =IF(Scenarios!N6="lease", YearMap!F4, YearMap!G4) -> 0.3 | R24: =IF(Scenarios!D6=1, Q24*H24, H24) -> 824968.86 | S24: =IF(Scenarios!E6=1, Q24*I24, I24) -> 950158.69 | T24: =IF(C24="FY2026", (Scenarios!D6+Scenarios!E6)*BaselineCalc!$B$21, 0) -> 0 | U24: =(R24+S24+G24*F24)*J24*(1-K24) -> 6991306.2 | V24: =O24*(G24+P24) -> 0 | W24: =U24+V24+T24 -> 6991306.2 | X24: =IF(F24+O24>0, W24/(F24+O24),"") -> 9944.959 | Y24: =B24&"|"&C24 -> D_Grow_Both_150|FY2028 | Z24: =INDEX(YearMap!$I$2:$I$6, MATCH(C24, YearMap!$A$2:$A$6, 0)) -> 5319.5652 | AA24: =W24-Z24*O24 -> 6991306.2
A25: =Y25 -> D_Grow_Both_150|FY2029 | B25: =Scenarios!A6 -> D_Grow_Both_150 | C25: FY2029 | D25: =IF(Scenarios!D6=1,0, L25) -> 332 | E25: =IF(Scenarios!E6=1,0, M25) -> 371 | F25: =D25+E25 -> 703 | G25: =YearMap!B5 -> 7677.2394 | H25: =YearMap!C5 -> 845593.08 | I25: =YearMap!D5 -> 973912.66 | J25: =1-BaselineCalc!$B$5 -> 0.993 | K25: =Scenarios!G6 -> 0 | L25: =BaselineCalc!$B$7 + ROUND(Scenarios!L6*Scenarios!F6,0) -> 332 | M25: =BaselineCalc!$B$8 + Scenarios!L6 - ROUND(Scenarios!L6*Scenarios!F6,0) -> 371 | N25: =(L25-D25) + (M25-E25) -> 0 | O25: =BaselineCalc!$B$22 * N25 -> 0 | P25: =YearMap!E5 -> 400 | Q25: =IF(Scenarios!N6="lease", YearMap!F5, YearMap!G5) -> 0.25 | R25: =IF(Scenarios!D6=1, Q25*H25, H25) -> 845593.08 | S25: =IF(Scenarios!E6=1, Q25*I25, I25) -> 973912.66 | T25: =IF(C25="FY2026", (Scenarios!D6+Scenarios!E6)*BaselineCalc!$B$21, 0) -> 0 | U25: =(R25+S25+G25*F25)*J25*(1-K25) -> 7166088.8 | V25: =O25*(G25+P25) -> 0 | W25: =U25+V25+T25 -> 7166088.8 | X25: =IF(F25+O25>0, W25/(F25+O25),"") -> 10193.583 | Y25: =B25&"|"&C25 -> D_Grow_Both_150|FY2029 | Z25: =INDEX(YearMap!$I$2:$I$6, MATCH(C25, YearMap!$A$2:$A$6, 0)) -> 5425.9565 | AA25: =W25-Z25*O25 -> 7166088.8
A26: =Y26 -> D_Grow_Both_150|FY2030 | B26: =Scenarios!A6 -> D_Grow_Both_150 | C26: FY2030 | D26: =IF(Scenarios!D6=1,0, L26) -> 332 | E26: =IF(Scenarios!E6=1,0, M26) -> 371 | F26: =D26+E26 -> 703 | G26: =YearMap!B6 -> 7869.1704 | H26: =YearMap!C6 -> 866732.91 | I26: =YearMap!D6 -> 998260.47 | J26: =1-BaselineCalc!$B$5 -> 0.993 | K26: =Scenarios!G6 -> 0 | L26: =BaselineCalc!$B$7 + ROUND(Scenarios!M6*Scenarios!F6,0) -> 332 | M26: =BaselineCalc!$B$8 + Scenarios!M6 - ROUND(Scenarios!M6*Scenarios!F6,0) -> 371 | N26: =(L26-D26) + (M26-E26) -> 0 | O26: =BaselineCalc!$B$22 * N26 -> 0 | P26: =YearMap!E6 -> 300 | Q26: =IF(Scenarios!N6="lease", YearMap!F6, YearMap!G6) -> 0.2 | R26: =IF(Scenarios!D6=1, Q26*H26, H26) -> 866732.91 | S26: =IF(Scenarios!E6=1, Q26*I26, I26) -> 998260.47 | T26: =IF(C26="FY2026", (Scenarios!D6+Scenarios!E6)*BaselineCalc!$B$21, 0) -> 0 | U26: =(R26+S26+G26*F26)*J26*(1-K26) -> 7345241 | V26: =O26*(G26+P26) -> 0 | W26: =U26+V26+T26 -> 7345241 | X26: =IF(F26+O26>0, W26/(F26+O26),"") -> 10448.423 | Y26: =B26&"|"&C26 -> D_Grow_Both_150|FY2030 | Z26: =INDEX(YearMap!$I$2:$I$6, MATCH(C26, YearMap!$A$2:$A$6, 0)) -> 5534.4756 | AA26: =W26-Z26*O26 -> 7345241
A27: =Y27 -> G_DHub_EchoRamp|FY2026 | B27: =Scenarios!A7 -> G_DHub_EchoRamp | C27: FY2026 | D27: =IF(Scenarios!D7=1,0, L27) -> 292 | E27: =IF(Scenarios!E7=1,0, M27) -> 311 | F27: =D27+E27 -> 603 | G27: =YearMap!B2 -> 7129.08 | H27: =YearMap!C2 -> 785217.24 | I27: =YearMap!D2 -> 904374.72 | J27: =1-BaselineCalc!$B$5 -> 0.993 | K27: =Scenarios!G7 -> 0 | L27: =BaselineCalc!$B$7 + ROUND(Scenarios!I7*Scenarios!F7,0) -> 292 | M27: =BaselineCalc!$B$8 + Scenarios!I7 - ROUND(Scenarios!I7*Scenarios!F7,0) -> 311 | N27: =(L27-D27) + (M27-E27) -> 0 | O27: =BaselineCalc!$B$22 * N27 -> 0 | P27: =YearMap!E2 -> 1000 | Q27: =IF(Scenarios!N7="lease", YearMap!F2, YearMap!G2) -> 0.4 | R27: =IF(Scenarios!D7=1, Q27*H27, H27) -> 785217.24 | S27: =IF(Scenarios!E7=1, Q27*I27, I27) -> 904374.72 | T27: =IF(C27="FY2026", (Scenarios!D7+Scenarios!E7)*BaselineCalc!$B$21, 0) -> 0 | U27: =(R27+S27+G27*F27)*J27*(1-K27) -> 5946508.2 | V27: =O27*(G27+P27) -> 0 | W27: =U27+V27+T27 -> 5946508.2 | X27: =IF(F27+O27>0, W27/(F27+O27),"") -> 9861.5393 | Y27: =B27&"|"&C27 -> G_DHub_EchoRamp|FY2026 | Z27: =INDEX(YearMap!$I$2:$I$6, MATCH(C27, YearMap!$A$2:$A$6, 0)) -> 5113 | AA27: =W27-Z27*O27 -> 5946508.2
A28: =Y28 -> G_DHub_EchoRamp|FY2027 | B28: =Scenarios!A7 -> G_DHub_EchoRamp | C28: FY2027 | D28: =IF(Scenarios!D7=1,0, L28) -> 327 | E28: =IF(Scenarios!E7=1,0, M28) -> 326 | F28: =D28+E28 -> 653 | G28: =YearMap!B3 -> 7307.307 | H28: =YearMap!C3 -> 804847.67 | I28: =YearMap!D3 -> 926984.09 | J28: =1-BaselineCalc!$B$5 -> 0.993 | K28: =Scenarios!G7 -> 0 | L28: =BaselineCalc!$B$7 + ROUND(Scenarios!J7*Scenarios!F7,0) -> 327 | M28: =BaselineCalc!$B$8 + Scenarios!J7 - ROUND(Scenarios!J7*Scenarios!F7,0) -> 326 | N28: =(L28-D28) + (M28-E28) -> 0 | O28: =BaselineCalc!$B$22 * N28 -> 0 | P28: =YearMap!E3 -> 800 | Q28: =IF(Scenarios!N7="lease", YearMap!F3, YearMap!G3) -> 0.35 | R28: =IF(Scenarios!D7=1, Q28*H28, H28) -> 804847.67 | S28: =IF(Scenarios!E7=1, Q28*I28, I28) -> 926984.09 | T28: =IF(C28="FY2026", (Scenarios!D7+Scenarios!E7)*BaselineCalc!$B$21, 0) -> 0 | U28: =(R28+S28+G28*F28)*J28*(1-K28) -> 6457978.7 | V28: =O28*(G28+P28) -> 0 | W28: =U28+V28+T28 -> 6457978.7 | X28: =IF(F28+O28>0, W28/(F28+O28),"") -> 9889.7071 | Y28: =B28&"|"&C28 -> G_DHub_EchoRamp|FY2027 | Z28: =INDEX(YearMap!$I$2:$I$6, MATCH(C28, YearMap!$A$2:$A$6, 0)) -> 5215.26 | AA28: =W28-Z28*O28 -> 6457978.7
A29: =Y29 -> G_DHub_EchoRamp|FY2028 | B29: =Scenarios!A7 -> G_DHub_EchoRamp | C29: FY2028 | D29: =IF(Scenarios!D7=1,0, L29) -> 362 | E29: =IF(Scenarios!E7=1,0, M29) -> 341 | F29: =D29+E29 -> 703 | G29: =YearMap!B4 -> 7489.9897 | H29: =YearMap!C4 -> 824968.86 | I29: =YearMap!D4 -> 950158.69 | J29: =1-BaselineCalc!$B$5 -> 0.993 | K29: =Scenarios!G7 -> 0 | L29: =BaselineCalc!$B$7 + ROUND(Scenarios!K7*Scenarios!F7,0) -> 362 | M29: =BaselineCalc!$B$8 + Scenarios!K7 - ROUND(Scenarios!K7*Scenarios!F7,0) -> 341 | N29: =(L29-D29) + (M29-E29) -> 0 | O29: =BaselineCalc!$B$22 * N29 -> 0 | P29: =YearMap!E4 -> 600 | Q29: =IF(Scenarios!N7="lease", YearMap!F4, YearMap!G4) -> 0.3 | R29: =IF(Scenarios!D7=1, Q29*H29, H29) -> 824968.86 | S29: =IF(Scenarios!E7=1, Q29*I29, I29) -> 950158.69 | T29: =IF(C29="FY2026", (Scenarios!D7+Scenarios!E7)*BaselineCalc!$B$21, 0) -> 0 | U29: =(R29+S29+G29*F29)*J29*(1-K29) -> 6991306.2 | V29: =O29*(G29+P29) -> 0 | W29: =U29+V29+T29 -> 6991306.2 | X29: =IF(F29+O29>0, W29/(F29+O29),"") -> 9944.959 | Y29: =B29&"|"&C29 -> G_DHub_EchoRamp|FY2028 | Z29: =INDEX(YearMap!$I$2:$I$6, MATCH(C29, YearMap!$A$2:$A$6, 0)) -> 5319.5652 | AA29: =W29-Z29*O29 -> 6991306.2
A30: =Y30 -> G_DHub_EchoRamp|FY2029 | B30: =Scenarios!A7 -> G_DHub_EchoRamp | C30: FY2029 | D30: =IF(Scenarios!D7=1,0, L30) -> 362 | E30: =IF(Scenarios!E7=1,0, M30) -> 341 | F30: =D30+E30 -> 703 | G30: =YearMap!B5 -> 7677.2394 | H30: =YearMap!C5 -> 845593.08 | I30: =YearMap!D5 -> 973912.66 | J30: =1-BaselineCalc!$B$5 -> 0.993 | K30: =Scenarios!G7 -> 0 | L30: =BaselineCalc!$B$7 + ROUND(Scenarios!L7*Scenarios!F7,0) -> 362 | M30: =BaselineCalc!$B$8 + Scenarios!L7 - ROUND(Scenarios!L7*Scenarios!F7,0) -> 341 | N30: =(L30-D30) + (M30-E30) -> 0 | O30: =BaselineCalc!$B$22 * N30 -> 0 | P30: =YearMap!E5 -> 400 | Q30: =IF(Scenarios!N7="lease", YearMap!F5, YearMap!G5) -> 0.25 | R30: =IF(Scenarios!D7=1, Q30*H30, H30) -> 845593.08 | S30: =IF(Scenarios!E7=1, Q30*I30, I30) -> 973912.66 | T30: =IF(C30="FY2026", (Scenarios!D7+Scenarios!E7)*BaselineCalc!$B$21, 0) -> 0 | U30: =(R30+S30+G30*F30)*J30*(1-K30) -> 7166088.8 | V30: =O30*(G30+P30) -> 0 | W30: =U30+V30+T30 -> 7166088.8 | X30: =IF(F30+O30>0, W30/(F30+O30),"") -> 10193.583 | Y30: =B30&"|"&C30 -> G_DHub_EchoRamp|FY2029 | Z30: =INDEX(YearMap!$I$2:$I$6, MATCH(C30, YearMap!$A$2:$A$6, 0)) -> 5425.9565 | AA30: =W30-Z30*O30 -> 7166088.8
