Workbook

Sheet BaselineCalc
A1: Parameter | B1: Value | C1: Notes
A2: MO inflation | B2: 0.025 | C2: Annual inflation factor.
A3: Base MO per ADM (FY25) | B3: 9936 | C3: Working base for FY25.
A4: Fixed share of MO | B4: 0.3 | C4: Share treated as semi‑fixed (plant/insurance).
A5: Ops savings (keep‑open) | B5: 0.007 | C5: Light discipline if sites remain open (not used here).
A6: Extra savings (Co‑location) | B6: 0.015 | C6: Incremental savings for co‑location (not used here).
A7: Echo base ADM | B7: 257
A8: Pima base ADM | B8: 296
A9: Total base ADM | B9: =B7+B8 -> 553 | C9: Echo base ADM + Pima base ADM
A10: Repurpose TI per closed site (FY26) | B10: 1200000
A11: Retention r (central) | B11: 0.75
A14: Helper / Derivation | B14: FY26 | C14: FY27 | D14: FY28 | E14: FY29 | F14: FY30 | G14: Notes
A15: Base total MO (FY25) | B15: =B9*B3 -> 5494608 | C15: =C14/$B$4 -> #VALUE! | D15: =D14/$B$4 -> #VALUE! | E15: =E14/$B$4 -> #VALUE! | F15: =F14/$B$4 -> #VALUE! | G15: Total ADM × Base MO/ADM | K15: B13 = B9*B3 (Base total MO, FY25)
A16: Fixed MO (FY25) | B16: =B13*B4 -> 0 | C16: =B17 -> #VALUE! | D16: =C17 -> 0 | E16: =D17 -> 0 | F16: =E17 -> 0 | G16: Fixed = Base total × Fixed share | K16: B14 = B13*B4 (Fixed MO, FY25)
A17: Var per student (FY25) | B17: =(B13-B14)/B9 -> #VALUE! | C17: =B18 -> 0 | D17: =C18 -> 0 | E17: =D18 -> 0 | F17: =E18 -> 0 | G17: Variable = (Base total − Fixed)/Total ADM | K17: B15 = (B13–B14)/B9 (Variable $/student, FY25)
A19: Fixed total ($) | B19: =$B$14*(1+$B$2)^1 -> #VALUE! | C19: =$B$14*(1+$B$2)^2 -> #VALUE! | D19: =$B$14*(1+$B$2)^3 -> #VALUE! | E19: =$B$14*(1+$B$2)^4 -> #VALUE! | F19: =$B$14*(1+$B$2)^5 -> #VALUE!
A20: Var unit ($/student) | B20: =$B$15*(1+$B$2)^1 -> 5631973.2 | C20: =$B$15*(1+$B$2)^2 -> 5772772.5 | D20: =$B$15*(1+$B$2)^3 -> 5917091.8 | E20: =$B$15*(1+$B$2)^4 -> 6065019.1 | F20: =$B$15*(1+$B$2)^5 -> 6216644.6
A21: Echo fixed ($) | B21: =B17*($B$7/$B$9) -> #VALUE! | C21: =C17*($B$7/$B$9) -> 0 | D21: =D17*($B$7/$B$9) -> 0 | E21: =E17*($B$7/$B$9) -> 0 | F21: =F17*($B$7/$B$9) -> 0
A22: Pima fixed ($) | B22: =B17*($B$8/$B$9) -> #VALUE! | C22: =C17*($B$8/$B$9) -> 0 | D22: =D17*($B$8/$B$9) -> 0 | E22: =E17*($B$8/$B$9) -> 0 | F22: =F17*($B$8/$B$9) -> 0
A24: Notes
A25: All formulas are same‑sheet and reference the Parameter cells above.

Sheet YearMap
A1: Year | B1: VarUnit$ | C1: EchoFixed$ | D1: PimaFixed$ | E1: h | F1: f_lease | G1: f_ops | H1: YearIdx
A2: FY2026 | B2: =BaselineCalc!B18 -> 0 | C2: =BaselineCalc!B19 -> #VALUE! | D2: =BaselineCalc!B20 -> 5631973.2 | E2: 1000 | F2: 0.4 | G2: 0.4 | H2: 1
A3: FY2027 | B3: =BaselineCalc!C18 -> 0 | C3: =BaselineCalc!C19 -> #VALUE! | D3: =BaselineCalc!C20 -> 5772772.5 | E3: 800 | F3: 0.3 | G3: 0.35 | H3: 2
A4: FY2028 | B4: =BaselineCalc!D18 -> 0 | C4: =BaselineCalc!D19 -> #VALUE! | D4: =BaselineCalc!D20 -> 5917091.8 | E4: 600 | F4: 0.2 | G4: 0.3 | H4: 3
A5: FY2029 | B5: =BaselineCalc!E18 -> 0 | C5: =BaselineCalc!E19 -> #VALUE! | D5: =BaselineCalc!E20 -> 6065019.1 | E5: 400 | F5: 0.1 | G5: 0.25 | H5: 4
A6: FY2030 | B6: =BaselineCalc!F18 -> 0 | C6: =BaselineCalc!F19 -> #VALUE! | D6: =BaselineCalc!F20 -> 6216644.6 | E6: 300 | F6: 0 | G6: 0.2 | H6: 5

Sheet Scenarios
A1: ScenarioKey | B1: Label | C1: Overlay | D1: CloseEcho | E1: ClosePima | F1: EchoShareDist | G1: ExtraSave | H1: Notes | I1: Overlay_FY26 | J1: Overlay_FY27 | K1: Overlay_FY28 | L1: Overlay_FY29 | M1: Overlay_FY30 | N1: Carry
A2: D_Grow_Both_0 | B2: D. Grow Both (Overlay 0) | C2: 0 | D2: 0 | E2: 0 | F2: 0.5 | G2: 0 | H2: Baseline + outreach; no closures | I2: =$C2 -> 0 | J2: =$C2 -> 0 | K2: =$C2 -> 0 | L2: =$C2 -> 0 | M2: =$C2 -> 0
A3: E_StatusQuo_Targets_0 | B3: E. Status‑Quo + Targets (0) | C3: 0 | D3: 0 | E3: 0 | F3: 0.5 | G3: 0 | H3: Baseline + targets; no closures | I3: =$C3 -> 0 | J3: =$C3 -> 0 | K3: =$C3 -> 0 | L3: =$C3 -> 0 | M3: =$C3 -> 0
A4: F_CoLocation_Echo_0 | B4: F. Co‑Location @ Echo (0) | C4: 0 | D4: 0 | E4: 0 | F4: 0.7 | G4: 0.015 | H4: Shared‑use efficiencies later (no closure) | I4: =$C4 -> 0 | J4: =$C4 -> 0 | K4: =$C4 -> 0 | L4: =$C4 -> 0 | M4: =$C4 -> 0
A5: D_Grow_Both_100 | B5: D. Grow Both (Overlay 100) | C5: 100 | D5: 0 | E5: 0 | F5: 0.5 | G5: 0 | H5: Baseline +100 overlay | I5: =$C5 -> 100 | J5: =$C5 -> 100 | K5: =$C5 -> 100 | L5: =$C5 -> 100 | M5: =$C5 -> 100
A6: D_Grow_Both_150 | B6: D. Grow Both (Overlay 150) | C6: 150 | D6: 0 | E6: 0 | F6: 0.5 | G6: 0 | H6: Baseline +150 overlay | I6: =$C6 -> 150 | J6: =$C6 -> 150 | K6: =$C6 -> 150 | L6: =$C6 -> 150 | M6: =$C6 -> 150
A7: G_DHub_EchoRamp | B7: G. D‑Hub @ Echo (Ramp 50→100→150) | C7: 150 | D7: 0 | E7: 0 | F7: 0.7 | G7: 0 | H7: Time‑phased ramp (+50,+100,+150 years 1–3) | I7: =C7/3 -> 50 | J7: =I7+C7/3 -> 100 | K7: =J7+C7/3 -> 150 | L7: =C7 -> 150 | M7: =C7 -> 150
A8: A_Repurpose_Both_lease | B8: A. Repurpose BOTH (lease) | C8: 0 | D8: 1 | E8: 1 | F8: 0.5 | G8: 0 | H8: Repurpose both; lease/sale glide | I8: =$C8 -> 0 | J8: =$C8 -> 0 | K8: =$C8 -> 0 | L8: =$C8 -> 0 | M8: =$C8 -> 0 | N8: lease
A9: ScenarioKey | B9: Year | C9: Echo_ADM | D9: Pima_ADM | E9: Total_ADM | F9: VarUnit$ | G9: EchoFixed$ | H9: PimaFixed$ | I9: Key | J9: =$C9 -> Echo_ADM | K9: =$C9 -> Echo_ADM | L9: =$C9 -> Echo_ADM | M9: =$C9 -> Echo_ADM | N9: ops
A10: =A2 -> D_Grow_Both_0 | B10: FY2026 | C10: =IF(D2=1,0, BaselineCalc!$B$7 + ROUND(I2*F2,0)) -> 257 | D10: =IF(E2=1,0, BaselineCalc!$B$8 + I2 - ROUND(I2*F2,0)) -> 296 | E10: =C10+D10 -> 553 | F10: =YearMap!B2 -> 0 | G10: =YearMap!C2 -> #VALUE! | H10: =YearMap!D2 -> 5631973.2 | I10: =A10&"|"&B10 -> D_Grow_Both_0|FY2026 | J10: =$C10 -> 257 | K10: =$C10 -> 257 | L10: =$C10 -> 257 | M10: =$C10 -> 257 | N10: lease
A11: =A2 -> D_Grow_Both_0 | B11: FY2027 | C11: =IF(D2=1,0, BaselineCalc!$B$7 + ROUND(J2*F2,0)) -> 257 | D11: =IF(E2=1,0, BaselineCalc!$B$8 + J2 - ROUND(J2*F2,0)) -> 296 | E11: =C11+D11 -> 553 | F11: =YearMap!B3 -> 0 | G11: =YearMap!C3 -> #VALUE! | H11: =YearMap!D3 -> 5772772.5 | I11: =A11&"|"&B11 -> D_Grow_Both_0|FY2027 | J11: =$C11 -> 257 | K11: =$C11 -> 257 | L11: =$C11 -> 257 | M11: =$C11 -> 257 | N11: ops
A12: =A2 -> D_Grow_Both_0 | B12: FY2028 | C12: =IF(D2=1,0, BaselineCalc!$B$7 + ROUND(K2*F2,0)) -> 257 | D12: =IF(E2=1,0, BaselineCalc!$B$8 + K2 - ROUND(K2*F2,0)) -> 296 | E12: =C12+D12 -> 553 | F12: =YearMap!B4 -> 0 | G12: =YearMap!C4 -> #VALUE! | H12: =YearMap!D4 -> 5917091.8 | I12: =A12&"|"&B12 -> D_Grow_Both_0|FY2028 | J12: =$C12 -> 257 | K12: =$C12 -> 257 | L12: =$C12 -> 257 | M12: =$C12 -> 257 | N12: lease
A13: =A2 -> D_Grow_Both_0 | B13: FY2029 | C13: =IF(D2=1,0, BaselineCalc!$B$7 + ROUND(L2*F2,0)) -> 257 | D13: =IF(E2=1,0, BaselineCalc!$B$8 + L2 - ROUND(L2*F2,0)) -> 296 | E13: =C13+D13 -> 553 | F13: =YearMap!B5 -> 0 | G13: =YearMap!C5 -> #VALUE! | H13: =YearMap!D5 -> 6065019.1 | I13: =A13&"|"&B13 -> D_Grow_Both_0|FY2029 | J13: =$C13 -> 257 | K13: =$C13 -> 257 | L13: =$C13 -> 257 | M13: =$C13 -> 257 | N13: ops
A14: =A2 -> D_Grow_Both_0 | B14: FY2030 | C14: =IF(D2=1,0, BaselineCalc!$B$7 + ROUND(M2*F2,0)) -> 257 | D14: =IF(E2=1,0, BaselineCalc!$B$8 + M2 - ROUND(M2*F2,0)) -> 296 | E14: =C14+D14 -> 553 | F14: =YearMap!B6 -> 0 | G14: =YearMap!C6 -> #VALUE! | H14: =YearMap!D6 -> 6216644.6 | I14: =A14&"|"&B14 -> D_Grow_Both_0|FY2030
A15: =A3 -> E_StatusQuo_Targets_0 | B15: FY2026 | C15: =IF(D3=1,0, BaselineCalc!$B$7 + ROUND(I3*F3,0)) -> 257 | D15: =IF(E3=1,0, BaselineCalc!$B$8 + I3 - ROUND(I3*F3,0)) -> 296 | E15: =C15+D15 -> 553 | F15: =YearMap!B2 -> 0 | G15: =YearMap!C2 -> #VALUE! | H15: =YearMap!D2 -> 5631973.2 | I15: =A15&"|"&B15 -> E_StatusQuo_Targets_0|FY2026
A16: =A3 -> E_StatusQuo_Targets_0 | B16: FY2027 | C16: =IF(D3=1,0, BaselineCalc!$B$7 + ROUND(J3*F3,0)) -> 257 | D16: =IF(E3=1,0, BaselineCalc!$B$8 + J3 - ROUND(J3*F3,0)) -> 296 | E16: =C16+D16 -> 553 | F16: =YearMap!B3 -> 0 | G16: =YearMap!C3 -> #VALUE! | H16: =YearMap!D3 -> 5772772.5 | I16: =A16&"|"&B16 -> E_StatusQuo_Targets_0|FY2027
A17: =A3 -> E_StatusQuo_Targets_0 | B17: FY2028 | C17: =IF(D3=1,0, BaselineCalc!$B$7 + ROUND(K3*F3,0)) -> 257 | D17: =IF(E3=1,0, BaselineCalc!$B$8 + K3 - ROUND(K3*F3,0)) -> 296 | E17: =C17+D17 -> 553 | F17: =YearMap!B4 -> 0 | G17: =YearMap!C4 -> #VALUE! | H17: =YearMap!D4 -> 5917091.8 | I17: =A17&"|"&B17 -> E_StatusQuo_Targets_0|FY2028
A18: =A3 -> E_StatusQuo_Targets_0 | B18: FY2029 | C18: =IF(D3=1,0, BaselineCalc!$B$7 + ROUND(L3*F3,0)) -> 257 | D18: =IF(E3=1,0, BaselineCalc!$B$8 + L3 - ROUND(L3*F3,0)) -> 296 | E18: =C18+D18 -> 553 | F18: =YearMap!B5 -> 0 | G18: =YearMap!C5 -> #VALUE! | H18: =YearMap!D5 -> 6065019.1 | I18: =A18&"|"&B18 -> E_StatusQuo_Targets_0|FY2029
A19: =A3 -> E_StatusQuo_Targets_0 | B19: FY2030 | C19: =IF(D3=1,0, BaselineCalc!$B$7 + ROUND(M3*F3,0)) -> 257 | D19: =IF(E3=1,0, BaselineCalc!$B$8 + M3 - ROUND(M3*F3,0)) -> 296 | E19: =C19+D19 -> 553 | F19: =YearMap!B6 -> 0 | G19: =YearMap!C6 -> #VALUE! | H19: =YearMap!D6 -> 6216644.6 | I19: =A19&"|"&B19 -> E_StatusQuo_Targets_0|FY2030
A20: =A4 -> F_CoLocation_Echo_0 | B20: FY2026 | C20: =IF(D4=1,0, BaselineCalc!$B$7 + ROUND(I4*F4,0)) -> 257 | D20: =IF(E4=1,0, BaselineCalc!$B$8 + I4 - ROUND(I4*F4,0)) -> 296 | E20: =C20+D20 -> 553 | F20: =YearMap!B2 -> 0 | G20: =YearMap!C2 -> #VALUE! | H20: =YearMap!D2 -> 5631973.2 | I20: =A20&"|"&B20 -> F_CoLocation_Echo_0|FY2026
A21: =A4 -> F_CoLocation_Echo_0 | B21: FY2027 | C21: =IF(D4=1,0, BaselineCalc!$B$7 + ROUND(J4*F4,0)) -> 257 | D21: =IF(E4=1,0, BaselineCalc!$B$8 + J4 - ROUND(J4*F4,0)) -> 296 | E21: =C21+D21 -> 553 | F21: =YearMap!B3 -> 0 | G21: =YearMap!C3 -> #VALUE! | H21: =YearMap!D3 -> 5772772.5 | I21: =A21&"|"&B21 -> F_CoLocation_Echo_0|FY2027
A22: =A4 -> F_CoLocation_Echo_0 | B22: FY2028 | C22: =IF(D4=1,0, BaselineCalc!$B$7 + ROUND(K4*F4,0)) -> 257 | D22: =IF(E4=1,0, BaselineCalc!$B$8 + K4 - ROUND(K4*F4,0)) -> 296 | E22: =C22+D22 -> 553 | F22: =YearMap!B4 -> 0 | G22: =YearMap!C4 -> #VALUE! | H22: =YearMap!D4 -> 5917091.8 | I22: =A22&"|"&B22 -> F_CoLocation_Echo_0|FY2028
A23: =A4 -> F_CoLocation_Echo_0 | B23: FY2029 | C23: =IF(D4=1,0, BaselineCalc!$B$7 + ROUND(L4*F4,0)) -> 257 | D23: =IF(E4=1,0, BaselineCalc!$B$8 + L4 - ROUND(L4*F4,0)) -> 296 | E23: =C23+D23 -> 553 | F23: =YearMap!B5 -> 0 | G23: =YearMap!C5 -> #VALUE! | H23: =YearMap!D5 -> 6065019.1 | I23: =A23&"|"&B23 -> F_CoLocation_Echo_0|FY2029
A24: =A4 -> F_CoLocation_Echo_0 | B24: FY2030 | C24: =IF(D4=1,0, BaselineCalc!$B$7 + ROUND(M4*F4,0)) -> 257 | D24: =IF(E4=1,0, BaselineCalc!$B$8 + M4 - ROUND(M4*F4,0)) -> 296 | E24: =C24+D24 -> 553 | F24: =YearMap!B6 -> 0 | G24: =YearMap!C6 -> #VALUE! | H24: =YearMap!D6 -> 6216644.6 | I24: =A24&"|"&B24 -> F_CoLocation_Echo_0|FY2030
A25: =A5 -> D_Grow_Both_100 | B25: FY2026 | C25: =IF(D5=1,0, BaselineCalc!$B$7 + ROUND(I5*F5,0)) -> 307 | D25: =IF(E5=1,0, BaselineCalc!$B$8 + I5 - ROUND(I5*F5,0)) -> 346 | E25: =C25+D25 -> 653 | F25: =YearMap!B2 -> 0 | G25: =YearMap!C2 -> #VALUE! | H25: =YearMap!D2 -> 5631973.2 | I25: =A25&"|"&B25 -> D_Grow_Both_100|FY2026
A26: =A5 -> D_Grow_Both_100 | B26: FY2027 | C26: =IF(D5=1,0, BaselineCalc!$B$7 + ROUND(J5*F5,0)) -> 307 | D26: =IF(E5=1,0, BaselineCalc!$B$8 + J5 - ROUND(J5*F5,0)) -> 346 | E26: =C26+D26 -> 653 | F26: =YearMap!B3 -> 0 | G26: =YearMap!C3 -> #VALUE! | H26: =YearMap!D3 -> 5772772.5 | I26: =A26&"|"&B26 -> D_Grow_Both_100|FY2027
A27: =A5 -> D_Grow_Both_100 | B27: FY2028 | C27: =IF(D5=1,0, BaselineCalc!$B$7 + ROUND(K5*F5,0)) -> 307 | D27: =IF(E5=1,0, BaselineCalc!$B$8 + K5 - ROUND(K5*F5,0)) -> 346 | E27: =C27+D27 -> 653 | F27: =YearMap!B4 -> 0 | G27: =YearMap!C4 -> #VALUE! | H27: =YearMap!D4 -> 5917091.8 | I27: =A27&"|"&B27 -> D_Grow_Both_100|FY2028
A28: =A5 -> D_Grow_Both_100 | B28: FY2029 | C28: =IF(D5=1,0, BaselineCalc!$B$7 + ROUND(L5*F5,0)) -> 307 | D28: =IF(E5=1,0, BaselineCalc!$B$8 + L5 - ROUND(L5*F5,0)) -> 346 | E28: =C28+D28 -> 653 | F28: =YearMap!B5 -> 0 | G28: =YearMap!C5 -> #VALUE! | H28: =YearMap!D5 -> 6065019.1 | I28: =A28&"|"&B28 -> D_Grow_Both_100|FY2029
A29: =A5 -> D_Grow_Both_100 | B29: FY2030 | C29: =IF(D5=1,0, BaselineCalc!$B$7 + ROUND(M5*F5,0)) -> 307 | D29: =IF(E5=1,0, BaselineCalc!$B$8 + M5 - ROUND(M5*F5,0)) -> 346 | E29: =C29+D29 -> 653 | F29: =YearMap!B6 -> 0 | G29: =YearMap!C6 -> #VALUE! | H29: =YearMap!D6 -> 6216644.6 | I29: =A29&"|"&B29 -> D_Grow_Both_100|FY2030
A30: =A6 -> D_Grow_Both_150 | B30: FY2026 | C30: =IF(D6=1,0, BaselineCalc!$B$7 + ROUND(I6*F6,0)) -> 332 | D30: =IF(E6=1,0, BaselineCalc!$B$8 + I6 - ROUND(I6*F6,0)) -> 371 | E30: =C30+D30 -> 703 | F30: =YearMap!B2 -> 0 | G30: =YearMap!C2 -> #VALUE! | H30: =YearMap!D2 -> 5631973.2 | I30: =A30&"|"&B30 -> D_Grow_Both_150|FY2026
A31: =A6 -> D_Grow_Both_150 | B31: FY2027 | C31: =IF(D6=1,0, BaselineCalc!$B$7 + ROUND(J6*F6,0)) -> 332 | D31: =IF(E6=1,0, BaselineCalc!$B$8 + J6 - ROUND(J6*F6,0)) -> 371 | E31: =C31+D31 -> 703 | F31: =YearMap!B3 -> 0 | G31: =YearMap!C3 -> #VALUE! | H31: =YearMap!D3 -> 5772772.5 | I31: =A31&"|"&B31 -> D_Grow_Both_150|FY2027
A32: =A6 -> D_Grow_Both_150 | B32: FY2028 | C32: =IF(D6=1,0, BaselineCalc!$B$7 + ROUND(K6*F6,0)) -> 332 | D32: =IF(E6=1,0, BaselineCalc!$B$8 + K6 - ROUND(K6*F6,0)) -> 371 | E32: =C32+D32 -> 703 | F32: =YearMap!B4 -> 0 | G32: =YearMap!C4 -> #VALUE! | H32: =YearMap!D4 -> 5917091.8 | I32: =A32&"|"&B32 -> D_Grow_Both_150|FY2028
A33: =A6 -> D_Grow_Both_150 | B33: FY2029 | C33: =IF(D6=1,0, BaselineCalc!$B$7 + ROUND(L6*F6,0)) -> 332 | D33: =IF(E6=1,0, BaselineCalc!$B$8 + L6 - ROUND(L6*F6,0)) -> 371 | E33: =C33+D33 -> 703 | F33: =YearMap!B5 -> 0 | G33: =YearMap!C5 -> #VALUE! | H33: =YearMap!D5 -> 6065019.1 | I33: =A33&"|"&B33 -> D_Grow_Both_150|FY2029
A34: =A6 -> D_Grow_Both_150 | B34: FY2030 | C34: =IF(D6=1,0, BaselineCalc!$B$7 + ROUND(M6*F6,0)) -> 332 | D34: =IF(E6=1,0, BaselineCalc!$B$8 + M6 - ROUND(M6*F6,0)) -> 371 | E34: =C34+D34 -> 703 | F34: =YearMap!B6 -> 0 | G34: =YearMap!C6 -> #VALUE! | H34: =YearMap!D6 -> 6216644.6 | I34: =A34&"|"&B34 -> D_Grow_Both_150|FY2030
A35: =A7 -> G_DHub_EchoRamp | B35: FY2026 | C35: =IF(D7=1,0, BaselineCalc!$B$7 + ROUND(I7*F7,0)) -> 292 | D35: =IF(E7=1,0, BaselineCalc!$B$8 + I7 - ROUND(I7*F7,0)) -> 311 | E35: =C35+D35 -> 603 | F35: =YearMap!B2 -> 0 | G35: =YearMap!C2 -> #VALUE! | H35: =YearMap!D2 -> 5631973.2 | I35: =A35&"|"&B35 -> G_DHub_EchoRamp|FY2026
A36: =A7 -> G_DHub_EchoRamp | B36: FY2027 | C36: =IF(D7=1,0, BaselineCalc!$B$7 + ROUND(J7*F7,0)) -> 327 | D36: =IF(E7=1,0, BaselineCalc!$B$8 + J7 - ROUND(J7*F7,0)) -> 326 | E36: =C36+D36 -> 653 | F36: =YearMap!B3 -> 0 | G36: =YearMap!C3 -> #VALUE! | H36: =YearMap!D3 -> 5772772.5 | I36: =A36&"|"&B36 -> G_DHub_EchoRamp|FY2027
A37: =A7 -> G_DHub_EchoRamp | B37: FY2028 | C37: =IF(D7=1,0, BaselineCalc!$B$7 + ROUND(K7*F7,0)) -> 362 | D37: =IF(E7=1,0, BaselineCalc!$B$8 + K7 - ROUND(K7*F7,0)) -> 341 | E37: =C37+D37 -> 703 | F37: =YearMap!B4 -> 0 | G37: =YearMap!C4 -> #VALUE! | H37: =YearMap!D4 -> 5917091.8 | I37: =A37&"|"&B37 -> G_DHub_EchoRamp|FY2028
A38: =A7 -> G_DHub_EchoRamp | B38: FY2029 | C38: =IF(D7=1,0, BaselineCalc!$B$7 + ROUND(L7*F7,0)) -> 362 | D38: =IF(E7=1,0, BaselineCalc!$B$8 + L7 - ROUND(L7*F7,0)) -> 341 | E38: =C38+D38 -> 703 | F38: =YearMap!B5 -> 0 | G38: =YearMap!C5 -> #VALUE! | H38: =YearMap!D5 -> 6065019.1 | I38: =A38&"|"&B38 -> G_DHub_EchoRamp|FY2029
A39: =A7 -> G_DHub_EchoRamp | B39: FY2030 | C39: =IF(D7=1,0, BaselineCalc!$B$7 + ROUND(M7*F7,0)) -> 362 | D39: =IF(E7=1,0, BaselineCalc!$B$8 + M7 - ROUND(M7*F7,0)) -> 341 | E39: =C39+D39 -> 703 | F39: =YearMap!B6 -> 0 | G39: =YearMap!C6 -> #VALUE! | H39: =YearMap!D6 -> 6216644.6 | I39: =A39&"|"&B39 -> G_DHub_EchoRamp|FY2030
A46: =A8 -> A_Repurpose_Both_lease | B46: FY2026 | C46: =IF(D8=1,0, BaselineCalc!$B$7 + ROUND(I8*F8,0)) -> 0 | D46: =IF(E8=1,0, BaselineCalc!$B$8 + I8 - ROUND(I8*F8,0)) -> 0 | E46: =C46+D46 -> 0 | F46: =YearMap!B2 -> 0 | G46: =YearMap!C2 -> #VALUE! | H46: =YearMap!D2 -> 5631973.2 | I46: =A46&"|"&B46 -> A_Repurpose_Both_lease|FY2026
...

Sheet MultiYear_ProForma
A1: ScenarioKey | B1: Year | C1: Echo_ADM | D1: Pima_ADM | E1: Total_ADM | F1: VarUnit$ | G1: EchoFixed$ | H1: PimaFixed$ | I1: OpsFactor | J1: ExtraSave | K1: EchoPotential_ADM | L1: PimaPotential_ADM | M1: Displaced_ADM | N1: Retained_ADM | O1: h | P1: CarryFrac | Q1: EchoFixedEff$ | R1: PimaFixedEff$ | S1: TI_adds$ | T1: SiteCost$ | U1: RetainedSvc$ | V1: Comparable_MO$ | W1: Comparable_per_Student$ | X1: Key
A2: =Scenarios!A2 -> D_Grow_Both_0 | B2: FY2026 | C2: =IF(Scenarios!D2=1,0, K2) -> 257 | D2: =IF(Scenarios!E2=1,0, L2) -> 296 | E2: =C2+D2 -> 553 | F2: =YearMap!B2 -> 0 | G2: =YearMap!C2 -> #VALUE! | H2: =YearMap!D2 -> 5631973.2 | I2: =1-BaselineCalc!$B$5 -> 0.993 | J2: =Scenarios!G2 -> 0 | K2: =BaselineCalc!$B$7 + ROUND(Scenarios!J2*Scenarios!F2,0) -> 257 | L2: =BaselineCalc!$B$8 + Scenarios!J2 - ROUND(Scenarios!J2*Scenarios!F2,0) -> 296 | M2: =(K2-C2) + (L2-D2) -> 0 | N2: =BaselineCalc!$B$11 * M2 -> 0 | O2: =YearMap!E2 -> 1000 | P2: =IF(Scenarios!N2="lease", YearMap!F2, YearMap!G2) -> 0.4 | Q2: =IF(Scenarios!D2=1, P2*G2, G2) -> #VALUE! | R2: =IF(Scenarios!E2=1, P2*H2, H2) -> 5631973.2 | S2: =IF(B2="FY2026", (Scenarios!D2+Scenarios!E2)*BaselineCalc!$B$10, 0) -> 0 | T2: =(Q2+R2+F2*E2)*I2*(1-J2) -> #VALUE! | U2: =N2*(F2+O2) -> 0 | V2: =T2+U2+S2 -> #VALUE! | W2: =IF(E2+N2>0, V2/(E2+N2),"") -> #VALUE! | X2: =A2&"|"&B2 -> D_Grow_Both_0|FY2026
A3: =Scenarios!A2 -> D_Grow_Both_0 | B3: FY2027 | C3: =IF(Scenarios!D2=1,0, K3) -> 257 | D3: =IF(Scenarios!E2=1,0, L3) -> 296 | E3: =C3+D3 -> 553 | F3: =YearMap!B3 -> 0 | G3: =YearMap!C3 -> #VALUE! | H3: =YearMap!D3 -> 5772772.5 | I3: =1-BaselineCalc!$B$5 -> 0.993 | J3: =Scenarios!G2 -> 0 | K3: =BaselineCalc!$B$7 + ROUND(Scenarios!K2*Scenarios!F2,0) -> 257 | L3: =BaselineCalc!$B$8 + Scenarios!K2 - ROUND(Scenarios!K2*Scenarios!F2,0) -> 296 | M3: =(K3-C3) + (L3-D3) -> 0 | N3: =BaselineCalc!$B$11 * M3 -> 0 | O3: =YearMap!E3 -> 800 | P3: =IF(Scenarios!N2="lease", YearMap!F3, YearMap!G3) -> 0.35 | Q3: =IF(Scenarios!D2=1, P3*G3, G3) -> #VALUE! | R3: =IF(Scenarios!E2=1, P3*H3, H3) -> 5772772.5 | S3: =IF(B3="FY2026", (Scenarios!D2+Scenarios!E2)*BaselineCalc!$B$10, 0) -> 0 | T3: =(Q3+R3+F3*E3)*I3*(1-J3) -> #VALUE! | U3: =N3*(F3+O3) -> 0 | V3: =T3+U3+S3 -> #VALUE! | W3: =IF(E3+N3>0, V3/(E3+N3),"") -> #VALUE! | X3: =A3&"|"&B3 -> D_Grow_Both_0|FY2027
A4: =Scenarios!A2 -> D_Grow_Both_0 | B4: FY2028 | C4: =IF(Scenarios!D2=1,0, K4) -> 257 | D4: =IF(Scenarios!E2=1,0, L4) -> 296 | E4: =C4+D4 -> 553 | F4: =YearMap!B4 -> 0 | G4: =YearMap!C4 -> #VALUE! | H4: =YearMap!D4 -> 5917091.8 | I4: =1-BaselineCalc!$B$5 -> 0.993 | J4: =Scenarios!G2 -> 0 | K4: =BaselineCalc!$B$7 + ROUND(Scenarios!L2*Scenarios!F2,0) -> 257 | L4: =BaselineCalc!$B$8 + Scenarios!L2 - ROUND(Scenarios!L2*Scenarios!F2,0) -> 296 | M4: =(K4-C4) + (L4-D4) -> 0 | N4: =BaselineCalc!$B$11 * M4 -> 0 | O4: =YearMap!E4 -> 600 | P4: =IF(Scenarios!N2="lease", YearMap!F4, YearMap!G4) -> 0.3 | Q4: =IF(Scenarios!D2=1, P4*G4, G4) -> #VALUE! | R4: =IF(Scenarios!E2=1, P4*H4, H4) -> 5917091.8 | S4: =IF(B4="FY2026", (Scenarios!D2+Scenarios!E2)*BaselineCalc!$B$10, 0) -> 0 | T4: =(Q4+R4+F4*E4)*I4*(1-J4) -> #VALUE! | U4: =N4*(F4+O4) -> 0 | V4: =T4+U4+S4 -> #VALUE! | W4: =IF(E4+N4>0, V4/(E4+N4),"") -> #VALUE! | X4: =A4&"|"&B4 -> D_Grow_Both_0|FY2028
A5: =Scenarios!A2 -> D_Grow_Both_0 | B5: FY2029 | C5: =IF(Scenarios!D2=1,0, K5) -> 257 | D5: =IF(Scenarios!E2=1,0, L5) -> 296 | E5: =C5+D5 -> 553 | F5: =YearMap!B5 -> 0 | G5: =YearMap!C5 -> #VALUE! | H5: =YearMap!D5 -> 6065019.1 | I5: =1-BaselineCalc!$B$5 -> 0.993 | J5: =Scenarios!G2 -> 0 | K5: =BaselineCalc!$B$7 + ROUND(Scenarios!M2*Scenarios!F2,0) -> 257 | L5: =BaselineCalc!$B$8 + Scenarios!M2 - ROUND(Scenarios!M2*Scenarios!F2,0) -> 296 | M5: =(K5-C5) + (L5-D5) -> 0 | N5: =BaselineCalc!$B$11 * M5 -> 0 | O5: =YearMap!E5 -> 400 | P5: =IF(Scenarios!N2="lease", YearMap!F5, YearMap!G5) -> 0.25 | Q5: =IF(Scenarios!D2=1, P5*G5, G5) -> #VALUE! | R5: =IF(Scenarios!E2=1, P5*H5, H5) -> 6065019.1 | S5: =IF(B5="FY2026", (Scenarios!D2+Scenarios!E2)*BaselineCalc!$B$10, 0) -> 0 | T5: =(Q5+R5+F5*E5)*I5*(1-J5) -> #VALUE! | U5: =N5*(F5+O5) -> 0 | V5: =T5+U5+S5 -> #VALUE! | W5: =IF(E5+N5>0, V5/(E5+N5),"") -> #VALUE! | X5: =A5&"|"&B5 -> D_Grow_Both_0|FY2029
A6: =Scenarios!A2 -> D_Grow_Both_0 | B6: FY2030 | C6: =IF(Scenarios!D2=1,0, K6) -> 257 | D6: =IF(Scenarios!E2=1,0, L6) -> 296 | E6: =C6+D6 -> 553 | F6: =YearMap!B6 -> 0 | G6: =YearMap!C6 -> #VALUE! | H6: =YearMap!D6 -> 6216644.6 | I6: =1-BaselineCalc!$B$5 -> 0.993 | J6: =Scenarios!G2 -> 0 | K6: =BaselineCalc!$B$7 + ROUND(Scenarios!N2*Scenarios!F2,0) -> 257 | L6: =BaselineCalc!$B$8 + Scenarios!N2 - ROUND(Scenarios!N2*Scenarios!F2,0) -> 296 | M6: =(K6-C6) + (L6-D6) -> 0 | N6: =BaselineCalc!$B$11 * M6 -> 0 | O6: =YearMap!E6 -> 300 | P6: =IF(Scenarios!N2="lease", YearMap!F6, YearMap!G6) -> 0.2 | Q6: =IF(Scenarios!D2=1, P6*G6, G6) -> #VALUE! | R6: =IF(Scenarios!E2=1, P6*H6, H6) -> 6216644.6 | S6: =IF(B6="FY2026", (Scenarios!D2+Scenarios!E2)*BaselineCalc!$B$10, 0) -> 0 | T6: =(Q6+R6+F6*E6)*I6*(1-J6) -> #VALUE! | U6: =N6*(F6+O6) -> 0 | V6: =T6+U6+S6 -> #VALUE! | W6: =IF(E6+N6>0, V6/(E6+N6),"") -> #VALUE! | X6: =A6&"|"&B6 -> D_Grow_Both_0|FY2030
A7: =Scenarios!A3 -> E_StatusQuo_Targets_0 | B7: FY2026 | C7: =IF(Scenarios!D3=1,0, K7) -> 257 | D7: =IF(Scenarios!E3=1,0, L7) -> 296 | E7: =C7+D7 -> 553 | F7: =YearMap!B2 -> 0 | G7: =YearMap!C2 -> #VALUE! | H7: =YearMap!D2 -> 5631973.2 | I7: =1-BaselineCalc!$B$5 -> 0.993 | J7: =Scenarios!G3 -> 0 | K7: =BaselineCalc!$B$7 + ROUND(Scenarios!J3*Scenarios!F3,0) -> 257 | L7: =BaselineCalc!$B$8 + Scenarios!J3 - ROUND(Scenarios!J3*Scenarios!F3,0) -> 296 | M7: =(K7-C7) + (L7-D7) -> 0 | N7: =BaselineCalc!$B$11 * M7 -> 0 | O7: =YearMap!E2 -> 1000 | P7: =IF(Scenarios!N3="lease", YearMap!F2, YearMap!G2) -> 0.4 | Q7: =IF(Scenarios!D3=1, P7*G7, G7) -> #VALUE! | R7: =IF(Scenarios!E3=1, P7*H7, H7) -> 5631973.2 | S7: =IF(B7="FY2026", (Scenarios!D3+Scenarios!E3)*BaselineCalc!$B$10, 0) -> 0 | T7: =(Q7+R7+F7*E7)*I7*(1-J7) -> #VALUE! | U7: =N7*(F7+O7) -> 0 | V7: =T7+U7+S7 -> #VALUE! | W7: =IF(E7+N7>0, V7/(E7+N7),"") -> #VALUE! | X7: =A7&"|"&B7 -> E_StatusQuo_Targets_0|FY2026
A8: =Scenarios!A3 -> E_StatusQuo_Targets_0 | B8: FY2027 | C8: =IF(Scenarios!D3=1,0, K8) -> 257 | D8: =IF(Scenarios!E3=1,0, L8) -> 296 | E8: =C8+D8 -> 553 | F8: =YearMap!B3 -> 0 | G8: =YearMap!C3 -> #VALUE! | H8: =YearMap!D3 -> 5772772.5 | I8: =1-BaselineCalc!$B$5 -> 0.993 | J8: =Scenarios!G3 -> 0 | K8: =BaselineCalc!$B$7 + ROUND(Scenarios!K3*Scenarios!F3,0) -> 257 | L8: =BaselineCalc!$B$8 + Scenarios!K3 - ROUND(Scenarios!K3*Scenarios!F3,0) -> 296 | M8: =(K8-C8) + (L8-D8) -> 0 | N8: =BaselineCalc!$B$11 * M8 -> 0 | O8: =YearMap!E3 -> 800 | P8: =IF(Scenarios!N3="lease", YearMap!F3, YearMap!G3) -> 0.35 | Q8: =IF(Scenarios!D3=1, P8*G8, G8) -> #VALUE! | R8: =IF(Scenarios!E3=1, P8*H8, H8) -> 5772772.5 | S8: =IF(B8="FY2026", (Scenarios!D3+Scenarios!E3)*BaselineCalc!$B$10, 0) -> 0 | T8: =(Q8+R8+F8*E8)*I8*(1-J8) -> #VALUE! | U8: =N8*(F8+O8) -> 0 | V8: =T8+U8+S8 -> #VALUE! | W8: =IF(E8+N8>0, V8/(E8+N8),"") -> #VALUE! | X8: =A8&"|"&B8 -> E_StatusQuo_Targets_0|FY2027
A9: =Scenarios!A3 -> E_StatusQuo_Targets_0 | B9: FY2028 | C9: =IF(Scenarios!D3=1,0, K9) -> 257 | D9: =IF(Scenarios!E3=1,0, L9) -> 296 | E9: =C9+D9 -> 553 | F9: =YearMap!B4 -> 0 | G9: =YearMap!C4 -> #VALUE! | H9: =YearMap!D4 -> 5917091.8 | I9: =1-BaselineCalc!$B$5 -> 0.993 | J9: =Scenarios!G3 -> 0 | K9: =BaselineCalc!$B$7 + ROUND(Scenarios!L3*Scenarios!F3,0) -> 257 | L9: =BaselineCalc!$B$8 + Scenarios!L3 - ROUND(Scenarios!L3*Scenarios!F3,0) -> 296 | M9: =(K9-C9) + (L9-D9) -> 0 | N9: =BaselineCalc!$B$11 * M9 -> 0 | O9: =YearMap!E4 -> 600 | P9: =IF(Scenarios!N3="lease", YearMap!F4, YearMap!G4) -> 0.3 | Q9: =IF(Scenarios!D3=1, P9*G9, G9) -> #VALUE! | R9: =IF(Scenarios!E3=1, P9*H9, H9) -> 5917091.8 | S9: =IF(B9="FY2026", (Scenarios!D3+Scenarios!E3)*BaselineCalc!$B$10, 0) -> 0 | T9: =(Q9+R9+F9*E9)*I9*(1-J9) -> #VALUE! | U9: =N9*(F9+O9) -> 0 | V9: =T9+U9+S9 -> #VALUE! | W9: =IF(E9+N9>0, V9/(E9+N9),"") -> #VALUE! | X9: =A9&"|"&B9 -> E_StatusQuo_Targets_0|FY2028
A10: =Scenarios!A3 -> E_StatusQuo_Targets_0 | B10: FY2029 | C10: =IF(Scenarios!D3=1,0, K10) -> 257 | D10: =IF(Scenarios!E3=1,0, L10) -> 296 | E10: =C10+D10 -> 553 | F10: =YearMap!B5 -> 0 | G10: =YearMap!C5 -> #VALUE! | H10: =YearMap!D5 -> 6065019.1 | I10: =1-BaselineCalc!$B$5 -> 0.993 | J10: =Scenarios!G3 -> 0 | K10: =BaselineCalc!$B$7 + ROUND(Scenarios!M3*Scenarios!F3,0) -> 257 | L10: =BaselineCalc!$B$8 + Scenarios!M3 - ROUND(Scenarios!M3*Scenarios!F3,0) -> 296 | M10: =(K10-C10) + (L10-D10) -> 0 | N10: =BaselineCalc!$B$11 * M10 -> 0 | O10: =YearMap!E5 -> 400 | P10: =IF(Scenarios!N3="lease", YearMap!F5, YearMap!G5) -> 0.25 | Q10: =IF(Scenarios!D3=1, P10*G10, G10) -> #VALUE! | R10: =IF(Scenarios!E3=1, P10*H10, H10) -> 6065019.1 | S10: =IF(B10="FY2026", (Scenarios!D3+Scenarios!E3)*BaselineCalc!$B$10, 0) -> 0 | T10: =(Q10+R10+F10*E10)*I10*(1-J10) -> #VALUE! | U10: =N10*(F10+O10) -> 0 | V10: =T10+U10+S10 -> #VALUE! | W10: =IF(E10+N10>0, V10/(E10+N10),"") -> #VALUE! | X10: =A10&"|"&B10 -> E_StatusQuo_Targets_0|FY2029
A11: =Scenarios!A3 -> E_StatusQuo_Targets_0 | B11: FY2030 | C11: =IF(Scenarios!D3=1,0, K11) -> 257 | D11: =IF(Scenarios!E3=1,0, L11) -> 296 | E11: =C11+D11 -> 553 | F11: =YearMap!B6 -> 0 | G11: =YearMap!C6 -> #VALUE! | H11: =YearMap!D6 -> 6216644.6 | I11: =1-BaselineCalc!$B$5 -> 0.993 | J11: =Scenarios!G3 -> 0 | K11: =BaselineCalc!$B$7 + ROUND(Scenarios!N3*Scenarios!F3,0) -> 257 | L11: =BaselineCalc!$B$8 + Scenarios!N3 - ROUND(Scenarios!N3*Scenarios!F3,0) -> 296 | M11: =(K11-C11) + (L11-D11) -> 0 | N11: =BaselineCalc!$B$11 * M11 -> 0 | O11: =YearMap!E6 -> 300 | P11: =IF(Scenarios!N3="lease", YearMap!F6, YearMap!G6) -> 0.2 | Q11: =IF(Scenarios!D3=1, P11*G11, G11) -> #VALUE! | R11: =IF(Scenarios!E3=1, P11*H11, H11) -> 6216644.6 | S11: =IF(B11="FY2026", (Scenarios!D3+Scenarios!E3)*BaselineCalc!$B$10, 0) -> 0 | T11: =(Q11+R11+F11*E11)*I11*(1-J11) -> #VALUE! | U11: =N11*(F11+O11) -> 0 | V11: =T11+U11+S11 -> #VALUE! | W11: =IF(E11+N11>0, V11/(E11+N11),"") -> #VALUE! | X11: =A11&"|"&B11 -> E_StatusQuo_Targets_0|FY2030
A12: =Scenarios!A4 -> F_CoLocation_Echo_0 | B12: FY2026 | C12: =IF(Scenarios!D4=1,0, K12) -> 257 | D12: =IF(Scenarios!E4=1,0, L12) -> 296 | E12: =C12+D12 -> 553 | F12: =YearMap!B2 -> 0 | G12: =YearMap!C2 -> #VALUE! | H12: =YearMap!D2 -> 5631973.2 | I12: =1-BaselineCalc!$B$5 -> 0.993 | J12: =Scenarios!G4 -> 0.015 | K12: =BaselineCalc!$B$7 + ROUND(Scenarios!J4*Scenarios!F4,0) -> 257 | L12: =BaselineCalc!$B$8 + Scenarios!J4 - ROUND(Scenarios!J4*Scenarios!F4,0) -> 296 | M12: =(K12-C12) + (L12-D12) -> 0 | N12: =BaselineCalc!$B$11 * M12 -> 0 | O12: =YearMap!E2 -> 1000 | P12: =IF(Scenarios!N4="lease", YearMap!F2, YearMap!G2) -> 0.4 | Q12: =IF(Scenarios!D4=1, P12*G12, G12) -> #VALUE! | R12: =IF(Scenarios!E4=1, P12*H12, H12) -> 5631973.2 | S12: =IF(B12="FY2026", (Scenarios!D4+Scenarios!E4)*BaselineCalc!$B$10, 0) -> 0 | T12: =(Q12+R12+F12*E12)*I12*(1-J12) -> #VALUE! | U12: =N12*(F12+O12) -> 0 | V12: =T12+U12+S12 -> #VALUE! | W12: =IF(E12+N12>0, V12/(E12+N12),"") -> #VALUE! | X12: =A12&"|"&B12 -> F_CoLocation_Echo_0|FY2026
A13: =Scenarios!A4 -> F_CoLocation_Echo_0 | B13: FY2027 | C13: =IF(Scenarios!D4=1,0, K13) -> 257 | D13: =IF(Scenarios!E4=1,0, L13) -> 296 | E13: =C13+D13 -> 553 | F13: =YearMap!B3 -> 0 | G13: =YearMap!C3 -> #VALUE! | H13: =YearMap!D3 -> 5772772.5 | I13: =1-BaselineCalc!$B$5 -> 0.993 | J13: =Scenarios!G4 -> 0.015 | K13: =BaselineCalc!$B$7 + ROUND(Scenarios!K4*Scenarios!F4,0) -> 257 | L13: =BaselineCalc!$B$8 + Scenarios!K4 - ROUND(Scenarios!K4*Scenarios!F4,0) -> 296 | M13: =(K13-C13) + (L13-D13) -> 0 | N13: =BaselineCalc!$B$11 * M13 -> 0 | O13: =YearMap!E3 -> 800 | P13: =IF(Scenarios!N4="lease", YearMap!F3, YearMap!G3) -> 0.35 | Q13: =IF(Scenarios!D4=1, P13*G13, G13) -> #VALUE! | R13: =IF(Scenarios!E4=1, P13*H13, H13) -> 5772772.5 | S13: =IF(B13="FY2026", (Scenarios!D4+Scenarios!E4)*BaselineCalc!$B$10, 0) -> 0 | T13: =(Q13+R13+F13*E13)*I13*(1-J13) -> #VALUE! | U13: =N13*(F13+O13) -> 0 | V13: =T13+U13+S13 -> #VALUE! | W13: =IF(E13+N13>0, V13/(E13+N13),"") -> #VALUE! | X13: =A13&"|"&B13 -> F_CoLocation_Echo_0|FY2027
A14: =Scenarios!A4 -> F_CoLocation_Echo_0 | B14: FY2028 | C14: =IF(Scenarios!D4=1,0, K14) -> 257 | D14: =IF(Scenarios!E4=1,0, L14) -> 296 | E14: =C14+D14 -> 553 | F14: =YearMap!B4 -> 0 | G14: =YearMap!C4 -> #VALUE! | H14: =YearMap!D4 -> 5917091.8 | I14: =1-BaselineCalc!$B$5 -> 0.993 | J14: =Scenarios!G4 -> 0.015 | K14: =BaselineCalc!$B$7 + ROUND(Scenarios!L4*Scenarios!F4,0) -> 257 | L14: =BaselineCalc!$B$8 + Scenarios!L4 - ROUND(Scenarios!L4*Scenarios!F4,0) -> 296 | M14: =(K14-C14) + (L14-D14) -> 0 | N14: =BaselineCalc!$B$11 * M14 -> 0 | O14: =YearMap!E4 -> 600 | P14: =IF(Scenarios!N4="lease", YearMap!F4, YearMap!G4) -> 0.3 | Q14: =IF(Scenarios!D4=1, P14*G14, G14) -> #VALUE! | R14: =IF(Scenarios!E4=1, P14*H14, H14) -> 5917091.8 | S14: =IF(B14="FY2026", (Scenarios!D4+Scenarios!E4)*BaselineCalc!$B$10, 0) -> 0 | T14: =(Q14+R14+F14*E14)*I14*(1-J14) -> #VALUE! | U14: =N14*(F14+O14) -> 0 | V14: =T14+U14+S14 -> #VALUE! | W14: =IF(E14+N14>0, V14/(E14+N14),"") -> #VALUE! | X14: =A14&"|"&B14 -> F_CoLocation_Echo_0|FY2028
A15: =Scenarios!A4 -> F_CoLocation_Echo_0 | B15: FY2029 | C15: =IF(Scenarios!D4=1,0, K15) -> 257 | D15: =IF(Scenarios!E4=1,0, L15) -> 296 | E15: =C15+D15 -> 553 | F15: =YearMap!B5 -> 0 | G15: =YearMap!C5 -> #VALUE! | H15: =YearMap!D5 -> 6065019.1 | I15: =1-BaselineCalc!$B$5 -> 0.993 | J15: =Scenarios!G4 -> 0.015 | K15: =BaselineCalc!$B$7 + ROUND(Scenarios!M4*Scenarios!F4,0) -> 257 | L15: =BaselineCalc!$B$8 + Scenarios!M4 - ROUND(Scenarios!M4*Scenarios!F4,0) -> 296 | M15: =(K15-C15) + (L15-D15) -> 0 | N15: =BaselineCalc!$B$11 * M15 -> 0 | O15: =YearMap!E5 -> 400 | P15: =IF(Scenarios!N4="lease", YearMap!F5, YearMap!G5) -> 0.25 | Q15: =IF(Scenarios!D4=1, P15*G15, G15) -> #VALUE! | R15: =IF(Scenarios!E4=1, P15*H15, H15) -> 6065019.1 | S15: =IF(B15="FY2026", (Scenarios!D4+Scenarios!E4)*BaselineCalc!$B$10, 0) -> 0 | T15: =(Q15+R15+F15*E15)*I15*(1-J15) -> #VALUE! | U15: =N15*(F15+O15) -> 0 | V15: =T15+U15+S15 -> #VALUE! | W15: =IF(E15+N15>0, V15/(E15+N15),"") -> #VALUE! | X15: =A15&"|"&B15 -> F_CoLocation_Echo_0|FY2029
A16: =Scenarios!A4 -> F_CoLocation_Echo_0 | B16: FY2030 | C16: =IF(Scenarios!D4=1,0, K16) -> 257 | D16: =IF(Scenarios!E4=1,0, L16) -> 296 | E16: =C16+D16 -> 553 | F16: =YearMap!B6 -> 0 | G16: =YearMap!C6 -> #VALUE! | H16: =YearMap!D6 -> 6216644.6 | I16: =1-BaselineCalc!$B$5 -> 0.993 | J16: =Scenarios!G4 -> 0.015 | K16: =BaselineCalc!$B$7 + ROUND(Scenarios!N4*Scenarios!F4,0) -> 257 | L16: =BaselineCalc!$B$8 + Scenarios!N4 - ROUND(Scenarios!N4*Scenarios!F4,0) -> 296 | M16: =(K16-C16) + (L16-D16) -> 0 | N16: =BaselineCalc!$B$11 * M16 -> 0 | O16: =YearMap!E6 -> 300 | P16: =IF(Scenarios!N4="lease", YearMap!F6, YearMap!G6) -> 0.2 | Q16: =IF(Scenarios!D4=1, P16*G16, G16) -> #VALUE! | R16: =IF(Scenarios!E4=1, P16*H16, H16) -> 6216644.6 | S16: =IF(B16="FY2026", (Scenarios!D4+Scenarios!E4)*BaselineCalc!$B$10, 0) -> 0 | T16: =(Q16+R16+F16*E16)*I16*(1-J16) -> #VALUE! | U16: =N16*(F16+O16) -> 0 | V16: =T16+U16+S16 -> #VALUE! | W16: =IF(E16+N16>0, V16/(E16+N16),"") -> #VALUE! | X16: =A16&"|"&B16 -> F_CoLocation_Echo_0|FY2030
A17: =Scenarios!A5 -> D_Grow_Both_100 | B17: FY2026 | C17: =IF(Scenarios!D5=1,0, K17) -> 307 | D17: =IF(Scenarios!E5=1,0, L17) -> 346 | E17: =C17+D17 -> 653 | F17: =YearMap!B2 -> 0 | G17: =YearMap!C2 -> #VALUE! | H17: =YearMap!D2 -> 5631973.2 | I17: =1-BaselineCalc!$B$5 -> 0.993 | J17: =Scenarios!G5 -> 0 | K17: =BaselineCalc!$B$7 + ROUND(Scenarios!J5*Scenarios!F5,0) -> 307 | L17: =BaselineCalc!$B$8 + Scenarios!J5 - ROUND(Scenarios!J5*Scenarios!F5,0) -> 346 | M17: =(K17-C17) + (L17-D17) -> 0 | N17: =BaselineCalc!$B$11 * M17 -> 0 | O17: =YearMap!E2 -> 1000 | P17: =IF(Scenarios!N5="lease", YearMap!F2, YearMap!G2) -> 0.4 | Q17: =IF(Scenarios!D5=1, P17*G17, G17) -> #VALUE! | R17: =IF(Scenarios!E5=1, P17*H17, H17) -> 5631973.2 | S17: =IF(B17="FY2026", (Scenarios!D5+Scenarios!E5)*BaselineCalc!$B$10, 0) -> 0 | T17: =(Q17+R17+F17*E17)*I17*(1-J17) -> #VALUE! | U17: =N17*(F17+O17) -> 0 | V17: =T17+U17+S17 -> #VALUE! | W17: =IF(E17+N17>0, V17/(E17+N17),"") -> #VALUE! | X17: =A17&"|"&B17 -> D_Grow_Both_100|FY2026
A18: =Scenarios!A5 -> D_Grow_Both_100 | B18: FY2027 | C18: =IF(Scenarios!D5=1,0, K18) -> 307 | D18: =IF(Scenarios!E5=1,0, L18) -> 346 | E18: =C18+D18 -> 653 | F18: =YearMap!B3 -> 0 | G18: =YearMap!C3 -> #VALUE! | H18: =YearMap!D3 -> 5772772.5 | I18: =1-BaselineCalc!$B$5 -> 0.993 | J18: =Scenarios!G5 -> 0 | K18: =BaselineCalc!$B$7 + ROUND(Scenarios!K5*Scenarios!F5,0) -> 307 | L18: =BaselineCalc!$B$8 + Scenarios!K5 - ROUND(Scenarios!K5*Scenarios!F5,0) -> 346 | M18: =(K18-C18) + (L18-D18) -> 0 | N18: =BaselineCalc!$B$11 * M18 -> 0 | O18: =YearMap!E3 -> 800 | P18: =IF(Scenarios!N5="lease", YearMap!F3, YearMap!G3) -> 0.35 | Q18: =IF(Scenarios!D5=1, P18*G18, G18) -> #VALUE! | R18: =IF(Scenarios!E5=1, P18*H18, H18) -> 5772772.5 | S18: =IF(B18="FY2026", (Scenarios!D5+Scenarios!E5)*BaselineCalc!$B$10, 0) -> 0 | T18: =(Q18+R18+F18*E18)*I18*(1-J18) -> #VALUE! | U18: =N18*(F18+O18) -> 0 | V18: =T18+U18+S18 -> #VALUE! | W18: =IF(E18+N18>0, V18/(E18+N18),"") -> #VALUE! | X18: =A18&"|"&B18 -> D_Grow_Both_100|FY2027
A19: =Scenarios!A5 -> D_Grow_Both_100 | B19: FY2028 | C19: =IF(Scenarios!D5=1,0, K19) -> 307 | D19: =IF(Scenarios!E5=1,0, L19) -> 346 | E19: =C19+D19 -> 653 | F19: =YearMap!B4 -> 0 | G19: =YearMap!C4 -> #VALUE! | H19: =YearMap!D4 -> 5917091.8 | I19: =1-BaselineCalc!$B$5 -> 0.993 | J19: =Scenarios!G5 -> 0 | K19: =BaselineCalc!$B$7 + ROUND(Scenarios!L5*Scenarios!F5,0) -> 307 | L19: =BaselineCalc!$B$8 + Scenarios!L5 - ROUND(Scenarios!L5*Scenarios!F5,0) -> 346 | M19: =(K19-C19) + (L19-D19) -> 0 | N19: =BaselineCalc!$B$11 * M19 -> 0 | O19: =YearMap!E4 -> 600 | P19: =IF(Scenarios!N5="lease", YearMap!F4, YearMap!G4) -> 0.3 | Q19: =IF(Scenarios!D5=1, P19*G19, G19) -> #VALUE! | R19: =IF(Scenarios!E5=1, P19*H19, H19) -> 5917091.8 | S19: =IF(B19="FY2026", (Scenarios!D5+Scenarios!E5)*BaselineCalc!$B$10, 0) -> 0 | T19: =(Q19+R19+F19*E19)*I19*(1-J19) -> #VALUE! | U19: =N19*(F19+O19) -> 0 | V19: =T19+U19+S19 -> #VALUE! | W19: =IF(E19+N19>0, V19/(E19+N19),"") -> #VALUE! | X19: =A19&"|"&B19 -> D_Grow_Both_100|FY2028
A20: =Scenarios!A5 -> D_Grow_Both_100 | B20: FY2029 | C20: =IF(Scenarios!D5=1,0, K20) -> 307 | D20: =IF(Scenarios!E5=1,0, L20) -> 346 | E20: =C20+D20 -> 653 | F20: =YearMap!B5 -> 0 | G20: =YearMap!C5 -> #VALUE! | H20: =YearMap!D5 -> 6065019.1 | I20: =1-BaselineCalc!$B$5 -> 0.993 | J20: =Scenarios!G5 -> 0 | K20: =BaselineCalc!$B$7 + ROUND(Scenarios!M5*Scenarios!F5,0) -> 307 | L20: =BaselineCalc!$B$8 + Scenarios!M5 - ROUND(Scenarios!M5*Scenarios!F5,0) -> 346 | M20: =(K20-C20) + (L20-D20) -> 0 | N20: =BaselineCalc!$B$11 * M20 -> 0 | O20: =YearMap!E5 -> 400 | P20: =IF(Scenarios!N5="lease", YearMap!F5, YearMap!G5) -> 0.25 | Q20: =IF(Scenarios!D5=1, P20*G20, G20) -> #VALUE! | R20: =IF(Scenarios!E5=1, P20*H20, H20) -> 6065019.1 | S20: =IF(B20="FY2026", (Scenarios!D5+Scenarios!E5)*BaselineCalc!$B$10, 0) -> 0 | T20: =(Q20+R20+F20*E20)*I20*(1-J20) -> #VALUE! | U20: =N20*(F20+O20) -> 0 | V20: =T20+U20+S20 -> #VALUE! | W20: =IF(E20+N20>0, V20/(E20+N20),"") -> #VALUE! | X20: =A20&"|"&B20 -> D_Grow_Both_100|FY2029
A21: =Scenarios!A5 -> D_Grow_Both_100 | B21: FY2030 | C21: =IF(Scenarios!D5=1,0, K21) -> 257 | D21: =IF(Scenarios!E5=1,0, L21) -> 296 | E21: =C21+D21 -> 553 | F21: =YearMap!B6 -> 0 | G21: =YearMap!C6 -> #VALUE! | H21: =YearMap!D6 -> 6216644.6 | I21: =1-BaselineCalc!$B$5 -> 0.993 | J21: =Scenarios!G5 -> 0 | K21: =BaselineCalc!$B$7 + ROUND(Scenarios!N5*Scenarios!F5,0) -> 257 | L21: =BaselineCalc!$B$8 + Scenarios!N5 - ROUND(Scenarios!N5*Scenarios!F5,0) -> 296 | M21: =(K21-C21) + (L21-D21) -> 0 | N21: =BaselineCalc!$B$11 * M21 -> 0 | O21: =YearMap!E6 -> 300 | P21: =IF(Scenarios!N5="lease", YearMap!F6, YearMap!G6) -> 0.2 | Q21: =IF(Scenarios!D5=1, P21*G21, G21) -> #VALUE! | R21: =IF(Scenarios!E5=1, P21*H21, H21) -> 6216644.6 | S21: =IF(B21="FY2026", (Scenarios!D5+Scenarios!E5)*BaselineCalc!$B$10, 0) -> 0 | T21: =(Q21+R21+F21*E21)*I21*(1-J21) -> #VALUE! | U21: =N21*(F21+O21) -> 0 | V21: =T21+U21+S21 -> #VALUE! | W21: =IF(E21+N21>0, V21/(E21+N21),"") -> #VALUE! | X21: =A21&"|"&B21 -> D_Grow_Both_100|FY2030
A22: =Scenarios!A6 -> D_Grow_Both_150 | B22: FY2026 | C22: =IF(Scenarios!D6=1,0, K22) -> 332 | D22: =IF(Scenarios!E6=1,0, L22) -> 371 | E22: =C22+D22 -> 703 | F22: =YearMap!B2 -> 0 | G22: =YearMap!C2 -> #VALUE! | H22: =YearMap!D2 -> 5631973.2 | I22: =1-BaselineCalc!$B$5 -> 0.993 | J22: =Scenarios!G6 -> 0 | K22: =BaselineCalc!$B$7 + ROUND(Scenarios!J6*Scenarios!F6,0) -> 332 | L22: =BaselineCalc!$B$8 + Scenarios!J6 - ROUND(Scenarios!J6*Scenarios!F6,0) -> 371 | M22: =(K22-C22) + (L22-D22) -> 0 | N22: =BaselineCalc!$B$11 * M22 -> 0 | O22: =YearMap!E2 -> 1000 | P22: =IF(Scenarios!N6="lease", YearMap!F2, YearMap!G2) -> 0.4 | Q22: =IF(Scenarios!D6=1, P22*G22, G22) -> #VALUE! | R22: =IF(Scenarios!E6=1, P22*H22, H22) -> 5631973.2 | S22: =IF(B22="FY2026", (Scenarios!D6+Scenarios!E6)*BaselineCalc!$B$10, 0) -> 0 | T22: =(Q22+R22+F22*E22)*I22*(1-J22) -> #VALUE! | U22: =N22*(F22+O22) -> 0 | V22: =T22+U22+S22 -> #VALUE! | W22: =IF(E22+N22>0, V22/(E22+N22),"") -> #VALUE! | X22: =A22&"|"&B22 -> D_Grow_Both_150|FY2026
A23: =Scenarios!A6 -> D_Grow_Both_150 | B23: FY2027 | C23: =IF(Scenarios!D6=1,0, K23) -> 332 | D23: =IF(Scenarios!E6=1,0, L23) -> 371 | E23: =C23+D23 -> 703 | F23: =YearMap!B3 -> 0 | G23: =YearMap!C3 -> #VALUE! | H23: =YearMap!D3 -> 5772772.5 | I23: =1-BaselineCalc!$B$5 -> 0.993 | J23: =Scenarios!G6 -> 0 | K23: =BaselineCalc!$B$7 + ROUND(Scenarios!K6*Scenarios!F6,0) -> 332 | L23: =BaselineCalc!$B$8 + Scenarios!K6 - ROUND(Scenarios!K6*Scenarios!F6,0) -> 371 | M23: =(K23-C23) + (L23-D23) -> 0 | N23: =BaselineCalc!$B$11 * M23 -> 0 | O23: =YearMap!E3 -> 800 | P23: =IF(Scenarios!N6="lease", YearMap!F3, YearMap!G3) -> 0.35 | Q23: =IF(Scenarios!D6=1, P23*G23, G23) -> #VALUE! | R23: =IF(Scenarios!E6=1, P23*H23, H23) -> 5772772.5 | S23: =IF(B23="FY2026", (Scenarios!D6+Scenarios!E6)*BaselineCalc!$B$10, 0) -> 0 | T23: =(Q23+R23+F23*E23)*I23*(1-J23) -> #VALUE! | U23: =N23*(F23+O23) -> 0 | V23: =T23+U23+S23 -> #VALUE! | W23: =IF(E23+N23>0, V23/(E23+N23),"") -> #VALUE! | X23: =A23&"|"&B23 -> D_Grow_Both_150|FY2027
A24: =Scenarios!A6 -> D_Grow_Both_150 | B24: FY2028 | C24: =IF(Scenarios!D6=1,0, K24) -> 332 | D24: =IF(Scenarios!E6=1,0, L24) -> 371 | E24: =C24+D24 -> 703 | F24: =YearMap!B4 -> 0 | G24: =YearMap!C4 -> #VALUE! | H24: =YearMap!D4 -> 5917091.8 | I24: =1-BaselineCalc!$B$5 -> 0.993 | J24: =Scenarios!G6 -> 0 | K24: =BaselineCalc!$B$7 + ROUND(Scenarios!L6*Scenarios!F6,0) -> 332 | L24: =BaselineCalc!$B$8 + Scenarios!L6 - ROUND(Scenarios!L6*Scenarios!F6,0) -> 371 | M24: =(K24-C24) + (L24-D24) -> 0 | N24: =BaselineCalc!$B$11 * M24 -> 0 | O24: =YearMap!E4 -> 600 | P24: =IF(Scenarios!N6="lease", YearMap!F4, YearMap!G4) -> 0.3 | Q24: =IF(Scenarios!D6=1, P24*G24, G24) -> #VALUE! | R24: =IF(Scenarios!E6=1, P24*H24, H24) -> 5917091.8 | S24: =IF(B24="FY2026", (Scenarios!D6+Scenarios!E6)*BaselineCalc!$B$10, 0) -> 0 | T24: =(Q24+R24+F24*E24)*I24*(1-J24) -> #VALUE! | U24: =N24*(F24+O24) -> 0 | V24: =T24+U24+S24 -> #VALUE! | W24: =IF(E24+N24>0, V24/(E24+N24),"") -> #VALUE! | X24: =A24&"|"&B24 -> D_Grow_Both_150|FY2028
A25: =Scenarios!A6 -> D_Grow_Both_150 | B25: FY2029 | C25: =IF(Scenarios!D6=1,0, K25) -> 332 | D25: =IF(Scenarios!E6=1,0, L25) -> 371 | E25: =C25+D25 -> 703 | F25: =YearMap!B5 -> 0 | G25: =YearMap!C5 -> #VALUE! | H25: =YearMap!D5 -> 6065019.1 | I25: =1-BaselineCalc!$B$5 -> 0.993 | J25: =Scenarios!G6 -> 0 | K25: =BaselineCalc!$B$7 + ROUND(Scenarios!M6*Scenarios!F6,0) -> 332 | L25: =BaselineCalc!$B$8 + Scenarios!M6 - ROUND(Scenarios!M6*Scenarios!F6,0) -> 371 | M25: =(K25-C25) + (L25-D25) -> 0 | N25: =BaselineCalc!$B$11 * M25 -> 0 | O25: =YearMap!E5 -> 400 | P25: =IF(Scenarios!N6="lease", YearMap!F5, YearMap!G5) -> 0.25 | Q25: =IF(Scenarios!D6=1, P25*G25, G25) -> #VALUE! | R25: =IF(Scenarios!E6=1, P25*H25, H25) -> 6065019.1 | S25: =IF(B25="FY2026", (Scenarios!D6+Scenarios!E6)*BaselineCalc!$B$10, 0) -> 0 | T25: =(Q25+R25+F25*E25)*I25*(1-J25) -> #VALUE! | U25: =N25*(F25+O25) -> 0 | V25: =T25+U25+S25 -> #VALUE! | W25: =IF(E25+N25>0, V25/(E25+N25),"") -> #VALUE! | X25: =A25&"|"&B25 -> D_Grow_Both_150|FY2029
A26: =Scenarios!A6 -> D_Grow_Both_150 | B26: FY2030 | C26: =IF(Scenarios!D6=1,0, K26) -> 257 | D26: =IF(Scenarios!E6=1,0, L26) -> 296 | E26: =C26+D26 -> 553 | F26: =YearMap!B6 -> 0 | G26: =YearMap!C6 -> #VALUE! | H26: =YearMap!D6 -> 6216644.6 | I26: =1-BaselineCalc!$B$5 -> 0.993 | J26: =Scenarios!G6 -> 0 | K26: =BaselineCalc!$B$7 + ROUND(Scenarios!N6*Scenarios!F6,0) -> 257 | L26: =BaselineCalc!$B$8 + Scenarios!N6 - ROUND(Scenarios!N6*Scenarios!F6,0) -> 296 | M26: =(K26-C26) + (L26-D26) -> 0 | N26: =BaselineCalc!$B$11 * M26 -> 0 | O26: =YearMap!E6 -> 300 | P26: =IF(Scenarios!N6="lease", YearMap!F6, YearMap!G6) -> 0.2 | Q26: =IF(Scenarios!D6=1, P26*G26, G26) -> #VALUE! | R26: =IF(Scenarios!E6=1, P26*H26, H26) -> 6216644.6 | S26: =IF(B26="FY2026", (Scenarios!D6+Scenarios!E6)*BaselineCalc!$B$10, 0) -> 0 | T26: =(Q26+R26+F26*E26)*I26*(1-J26) -> #VALUE! | U26: =N26*(F26+O26) -> 0 | V26: =T26+U26+S26 -> #VALUE! | W26: =IF(E26+N26>0, V26/(E26+N26),"") -> #VALUE! | X26: =A26&"|"&B26 -> D_Grow_Both_150|FY2030
A27: =Scenarios!A7 -> G_DHub_EchoRamp | B27: FY2026 | C27: =IF(Scenarios!D7=1,0, K27) -> 327 | D27: =IF(Scenarios!E7=1,0, L27) -> 326 | E27: =C27+D27 -> 653 | F27: =YearMap!B2 -> 0 | G27: =YearMap!C2 -> #VALUE! | H27: =YearMap!D2 -> 5631973.2 | I27: =1-BaselineCalc!$B$5 -> 0.993 | J27: =Scenarios!G7 -> 0 | K27: =BaselineCalc!$B$7 + ROUND(Scenarios!J7*Scenarios!F7,0) -> 327 | L27: =BaselineCalc!$B$8 + Scenarios!J7 - ROUND(Scenarios!J7*Scenarios!F7,0) -> 326 | M27: =(K27-C27) + (L27-D27) -> 0 | N27: =BaselineCalc!$B$11 * M27 -> 0 | O27: =YearMap!E2 -> 1000 | P27: =IF(Scenarios!N7="lease", YearMap!F2, YearMap!G2) -> 0.4 | Q27: =IF(Scenarios!D7=1, P27*G27, G27) -> #VALUE! | R27: =IF(Scenarios!E7=1, P27*H27, H27) -> 5631973.2 | S27: =IF(B27="FY2026", (Scenarios!D7+Scenarios!E7)*BaselineCalc!$B$10, 0) -> 0 | T27: =(Q27+R27+F27*E27)*I27*(1-J27) -> #VALUE! | U27: =N27*(F27+O27) -> 0 | V27: =T27+U27+S27 -> #VALUE! | W27: =IF(E27+N27>0, V27/(E27+N27),"") -> #VALUE! | X27: =A27&"|"&B27 -> G_DHub_EchoRamp|FY2026
A28: =Scenarios!A7 -> G_DHub_EchoRamp | B28: FY2027 | C28: =IF(Scenarios!D7=1,0, K28) -> 362 | D28: =IF(Scenarios!E7=1,0, L28) -> 341 | E28: =C28+D28 -> 703 | F28: =YearMap!B3 -> 0 | G28: =YearMap!C3 -> #VALUE! | H28: =YearMap!D3 -> 5772772.5 | I28: =1-BaselineCalc!$B$5 -> 0.993 | J28: =Scenarios!G7 -> 0 | K28: =BaselineCalc!$B$7 + ROUND(Scenarios!K7*Scenarios!F7,0) -> 362 | L28: =BaselineCalc!$B$8 + Scenarios!K7 - ROUND(Scenarios!K7*Scenarios!F7,0) -> 341 | M28: =(K28-C28) + (L28-D28) -> 0 | N28: =BaselineCalc!$B$11 * M28 -> 0 | O28: =YearMap!E3 -> 800 | P28: =IF(Scenarios!N7="lease", YearMap!F3, YearMap!G3) -> 0.35 | Q28: =IF(Scenarios!D7=1, P28*G28, G28) -> #VALUE! | R28: =IF(Scenarios!E7=1, P28*H28, H28) -> 5772772.5 | S28: =IF(B28="FY2026", (Scenarios!D7+Scenarios!E7)*BaselineCalc!$B$10, 0) -> 0 | T28: =(Q28+R28+F28*E28)*I28*(1-J28) -> #VALUE! | U28: =N28*(F28+O28) -> 0 | V28: =T28+U28+S28 -> #VALUE! | W28: =IF(E28+N28>0, V28/(E28+N28),"") -> #VALUE! | X28: =A28&"|"&B28 -> G_DHub_EchoRamp|FY2027
A29: =Scenarios!A7 -> G_DHub_EchoRamp | B29: FY2028 | C29: =IF(Scenarios!D7=1,0, K29) -> 362 | D29: =IF(Scenarios!E7=1,0, L29) -> 341 | E29: =C29+D29 -> 703 | F29: =YearMap!B4 -> 0 | G29: =YearMap!C4 -> #VALUE! | H29: =YearMap!D4 -> 5917091.8 | I29: =1-BaselineCalc!$B$5 -> 0.993 | J29: =Scenarios!G7 -> 0 | K29: =BaselineCalc!$B$7 + ROUND(Scenarios!L7*Scenarios!F7,0) -> 362 | L29: =BaselineCalc!$B$8 + Scenarios!L7 - ROUND(Scenarios!L7*Scenarios!F7,0) -> 341 | M29: =(K29-C29) + (L29-D29) -> 0 | N29: =BaselineCalc!$B$11 * M29 -> 0 | O29: =YearMap!E4 -> 600 | P29: =IF(Scenarios!N7="lease", YearMap!F4, YearMap!G4) -> 0.3 | Q29: =IF(Scenarios!D7=1, P29*G29, G29) -> #VALUE! | R29: =IF(Scenarios!E7=1, P29*H29, H29) -> 5917091.8 | S29: =IF(B29="FY2026", (Scenarios!D7+Scenarios!E7)*BaselineCalc!$B$10, 0) -> 0 | T29: =(Q29+R29+F29*E29)*I29*(1-J29) -> #VALUE! | U29: =N29*(F29+O29) -> 0 | V29: =T29+U29+S29 -> #VALUE! | W29: =IF(E29+N29>0, V29/(E29+N29),"") -> #VALUE! | X29: =A29&"|"&B29 -> G_DHub_EchoRamp|FY2028
A30: =Scenarios!A7 -> G_DHub_EchoRamp | B30: FY2029 | C30: =IF(Scenarios!D7=1,0, K30) -> 362 | D30: =IF(Scenarios!E7=1,0, L30) -> 341 | E30: =C30+D30 -> 703 | F30: =YearMap!B5 -> 0 | G30: =YearMap!C5 -> #VALUE! | H30: =YearMap!D5 -> 6065019.1 | I30: =1-BaselineCalc!$B$5 -> 0.993 | J30: =Scenarios!G7 -> 0 | K30: =BaselineCalc!$B$7 + ROUND(Scenarios!M7*Scenarios!F7,0) -> 362 | L30: =BaselineCalc!$B$8 + Scenarios!M7 - ROUND(Scenarios!M7*Scenarios!F7,0) -> 341 | M30: =(K30-C30) + (L30-D30) -> 0 | N30: =BaselineCalc!$B$11 * M30 -> 0 | O30: =YearMap!E5 -> 400 | P30: =IF(Scenarios!N7="lease", YearMap!F5, YearMap!G5) -> 0.25 | Q30: =IF(Scenarios!D7=1, P30*G30, G30) -> #VALUE! | R30: =IF(Scenarios!E7=1, P30*H30, H30) -> 6065019.1 | S30: =IF(B30="FY2026", (Scenarios!D7+Scenarios!E7)*BaselineCalc!$B$10, 0) -> 0 | T30: =(Q30+R30+F30*E30)*I30*(1-J30) -> #VALUE! | U30: =N30*(F30+O30) -> 0 | V30: =T30+U30+S30 -> #VALUE! | W30: =IF(E30+N30>0, V30/(E30+N30),"") -> #VALUE! | X30: =A30&"|"&B30 -> G_DHub_EchoRamp|FY2029
A31: =Scenarios!A7 -> G_DHub_EchoRamp | B31: FY2030 | C31: =IF(Scenarios!D7=1,0, K31) -> 257 | D31: =IF(Scenarios!E7=1,0, L31) -> 296 | E31: =C31+D31 -> 553 | F31: =YearMap!B6 -> 0 | G31: =YearMap!C6 -> #VALUE! | H31: =YearMap!D6 -> 6216644.6 | I31: =1-BaselineCalc!$B$5 -> 0.993 | J31: =Scenarios!G7 -> 0 | K31: =BaselineCalc!$B$7 + ROUND(Scenarios!N7*Scenarios!F7,0) -> 257 | L31: =BaselineCalc!$B$8 + Scenarios!N7 - ROUND(Scenarios!N7*Scenarios!F7,0) -> 296 | M31: =(K31-C31) + (L31-D31) -> 0 | N31: =BaselineCalc!$B$11 * M31 -> 0 | O31: =YearMap!E6 -> 300 | P31: =IF(Scenarios!N7="lease", YearMap!F6, YearMap!G6) -> 0.2 | Q31: =IF(Scenarios!D7=1, P31*G31, G31) -> #VALUE! | R31: =IF(Scenarios!E7=1, P31*H31, H31) -> 6216644.6 | S31: =IF(B31="FY2026", (Scenarios!D7+Scenarios!E7)*BaselineCalc!$B$10, 0) -> 0 | T31: =(Q31+R31+F31*E31)*I31*(1-J31) -> #VALUE! | U31: =N31*(F31+O31) -> 0 | V31: =T31+U31+S31 -> #VALUE! | W31: =IF(E31+N31>0, V31/(E31+N31),"") -> #VALUE! | X31: =A31&"|"&B31 -> G_DHub_EchoRamp|FY2030
A32: =Scenarios!A8 -> A_Repurpose_Both_lease | B32: FY2026 | C32: =IF(Scenarios!D8=1,0, K32) -> 0 | D32: =IF(Scenarios!E8=1,0, L32) -> 0 | E32: =C32+D32 -> 0 | F32: =YearMap!B2 -> 0 | G32: =YearMap!C2 -> #VALUE! | H32: =YearMap!D2 -> 5631973.2 | I32: =1-BaselineCalc!$B$5 -> 0.993 | J32: =Scenarios!G8 -> 0 | K32: =BaselineCalc!$B$7 + ROUND(Scenarios!J8*Scenarios!F8,0) -> 257 | L32: =BaselineCalc!$B$8 + Scenarios!J8 - ROUND(Scenarios!J8*Scenarios!F8,0) -> 296 | M32: =(K32-C32) + (L32-D32) -> 553 | N32: =BaselineCalc!$B$11 * M32 -> 414.75 | O32: =YearMap!E2 -> 1000 | P32: =IF(Scenarios!N8="lease", YearMap!F2, YearMap!G2) -> 0.4 | Q32: =IF(Scenarios!D8=1, P32*G32, G32) -> #VALUE! | R32: =IF(Scenarios!E8=1, P32*H32, H32) -> 2252789.3 | S32: =IF(B32="FY2026", (Scenarios!D8+Scenarios!E8)*BaselineCalc!$B$10, 0) -> 2400000 | T32: =(Q32+R32+F32*E32)*I32*(1-J32) -> #VALUE! | U32: =N32*(F32+O32) -> 414750 | V32: =T32+U32+S32 -> #VALUE! | W32: =IF(E32+N32>0, V32/(E32+N32),"") -> #VALUE! | X32: =A32&"|"&B32 -> A_Repurpose_Both_lease|FY2026
A33: =Scenarios!A8 -> A_Repurpose_Both_lease | B33: FY2027 | C33: =IF(Scenarios!D8=1,0, K33) -> 0 | D33: =IF(Scenarios!E8=1,0, L33) -> 0 | E33: =C33+D33 -> 0 | F33: =YearMap!B3 -> 0 | G33: =YearMap!C3 -> #VALUE! | H33: =YearMap!D3 -> 5772772.5 | I33: =1-BaselineCalc!$B$5 -> 0.993 | J33: =Scenarios!G8 -> 0 | K33: =BaselineCalc!$B$7 + ROUND(Scenarios!K8*Scenarios!F8,0) -> 257 | L33: =BaselineCalc!$B$8 + Scenarios!K8 - ROUND(Scenarios!K8*Scenarios!F8,0) -> 296 | M33: =(K33-C33) + (L33-D33) -> 553 | N33: =BaselineCalc!$B$11 * M33 -> 414.75 | O33: =YearMap!E3 -> 800 | P33: =IF(Scenarios!N8="lease", YearMap!F3, YearMap!G3) -> 0.3 | Q33: =IF(Scenarios!D8=1, P33*G33, G33) -> #VALUE! | R33: =IF(Scenarios!E8=1, P33*H33, H33) -> 1731831.8 | S33: =IF(B33="FY2026", (Scenarios!D8+Scenarios!E8)*BaselineCalc!$B$10, 0) -> 0 | T33: =(Q33+R33+F33*E33)*I33*(1-J33) -> #VALUE! | U33: =N33*(F33+O33) -> 331800 | V33: =T33+U33+S33 -> #VALUE! | W33: =IF(E33+N33>0, V33/(E33+N33),"") -> #VALUE! | X33: =A33&"|"&B33 -> A_Repurpose_Both_lease|FY2027
A34: =Scenarios!A8 -> A_Repurpose_Both_lease | B34: FY2028 | C34: =IF(Scenarios!D8=1,0, K34) -> 0 | D34: =IF(Scenarios!E8=1,0, L34) -> 0 | E34: =C34+D34 -> 0 | F34: =YearMap!B4 -> 0 | G34: =YearMap!C4 -> #VALUE! | H34: =YearMap!D4 -> 5917091.8 | I34: =1-BaselineCalc!$B$5 -> 0.993 | J34: =Scenarios!G8 -> 0 | K34: =BaselineCalc!$B$7 + ROUND(Scenarios!L8*Scenarios!F8,0) -> 257 | L34: =BaselineCalc!$B$8 + Scenarios!L8 - ROUND(Scenarios!L8*Scenarios!F8,0) -> 296 | M34: =(K34-C34) + (L34-D34) -> 553 | N34: =BaselineCalc!$B$11 * M34 -> 414.75 | O34: =YearMap!E4 -> 600 | P34: =IF(Scenarios!N8="lease", YearMap!F4, YearMap!G4) -> 0.2 | Q34: =IF(Scenarios!D8=1, P34*G34, G34) -> #VALUE! | R34: =IF(Scenarios!E8=1, P34*H34, H34) -> 1183418.4 | S34: =IF(B34="FY2026", (Scenarios!D8+Scenarios!E8)*BaselineCalc!$B$10, 0) -> 0 | T34: =(Q34+R34+F34*E34)*I34*(1-J34) -> #VALUE! | U34: =N34*(F34+O34) -> 248850 | V34: =T34+U34+S34 -> #VALUE! | W34: =IF(E34+N34>0, V34/(E34+N34),"") -> #VALUE! | X34: =A34&"|"&B34 -> A_Repurpose_Both_lease|FY2028
A35: =Scenarios!A8 -> A_Repurpose_Both_lease | B35: FY2029 | C35: =IF(Scenarios!D8=1,0, K35) -> 0 | D35: =IF(Scenarios!E8=1,0, L35) -> 0 | E35: =C35+D35 -> 0 | F35: =YearMap!B5 -> 0 | G35: =YearMap!C5 -> #VALUE! | H35: =YearMap!D5 -> 6065019.1 | I35: =1-BaselineCalc!$B$5 -> 0.993 | J35: =Scenarios!G8 -> 0 | K35: =BaselineCalc!$B$7 + ROUND(Scenarios!M8*Scenarios!F8,0) -> 257 | L35: =BaselineCalc!$B$8 + Scenarios!M8 - ROUND(Scenarios!M8*Scenarios!F8,0) -> 296 | M35: =(K35-C35) + (L35-D35) -> 553 | N35: =BaselineCalc!$B$11 * M35 -> 414.75 | O35: =YearMap!E5 -> 400 | P35: =IF(Scenarios!N8="lease", YearMap!F5, YearMap!G5) -> 0.1 | Q35: =IF(Scenarios!D8=1, P35*G35, G35) -> #VALUE! | R35: =IF(Scenarios!E8=1, P35*H35, H35) -> 606501.91 | S35: =IF(B35="FY2026", (Scenarios!D8+Scenarios!E8)*BaselineCalc!$B$10, 0) -> 0 | T35: =(Q35+R35+F35*E35)*I35*(1-J35) -> #VALUE! | U35: =N35*(F35+O35) -> 165900 | V35: =T35+U35+S35 -> #VALUE! | W35: =IF(E35+N35>0, V35/(E35+N35),"") -> #VALUE! | X35: =A35&"|"&B35 -> A_Repurpose_Both_lease|FY2029
A36: =Scenarios!A8 -> A_Repurpose_Both_lease | B36: FY2030 | C36: =IF(Scenarios!D8=1,0, K36) -> 0 | D36: =IF(Scenarios!E8=1,0, L36) -> 0 | E36: =C36+D36 -> 0 | F36: =YearMap!B6 -> 0 | G36: =YearMap!C6 -> #VALUE! | H36: =YearMap!D6 -> 6216644.6 | I36: =1-BaselineCalc!$B$5 -> 0.993 | J36: =Scenarios!G8 -> 0 | K36: =BaselineCalc!$B$7 + ROUND(Scenarios!N8*Scenarios!F8,0) -> #VALUE! | L36: =BaselineCalc!$B$8 + Scenarios!N8 - ROUND(Scenarios!N8*Scenarios!F8,0) -> #VALUE! | M36: =(K36-C36) + (L36-D36) -> #VALUE! | N36: =BaselineCalc!$B$11 * M36 -> #VALUE! | O36: =YearMap!E6 -> 300 | P36: =IF(Scenarios!N8="lease", YearMap!F6, YearMap!G6) -> 0 | Q36: =IF(Scenarios!D8=1, P36*G36, G36) -> #VALUE! | R36: =IF(Scenarios!E8=1, P36*H36, H36) -> 0 | S36: =IF(B36="FY2026", (Scenarios!D8+Scenarios!E8)*BaselineCalc!$B$10, 0) -> 0 | T36: =(Q36+R36+F36*E36)*I36*(1-J36) -> #VALUE! | U36: =N36*(F36+O36) -> #VALUE! | V36: =T36+U36+S36 -> #VALUE! | W36: =IF(E36+N36>0, V36/(E36+N36),"") -> #VALUE! | X36: =A36&"|"&B36 -> A_Repurpose_Both_lease|FY2030
A37: =Scenarios!A9 -> ScenarioKey | B37: FY2026 | C37: =IF(Scenarios!D9=1,0, K37) -> #VALUE! | D37: =IF(Scenarios!E9=1,0, L37) -> #VALUE! | E37: =C37+D37 -> #VALUE! | F37: =YearMap!B2 -> 0 | G37: =YearMap!C2 -> #VALUE! | H37: =YearMap!D2 -> 5631973.2 | I37: =1-BaselineCalc!$B$5 -> 0.993 | J37: =Scenarios!G9 -> EchoFixed$ | K37: =BaselineCalc!$B$7 + ROUND(Scenarios!J9*Scenarios!F9,0) -> #VALUE! | L37: =BaselineCalc!$B$8 + Scenarios!J9 - ROUND(Scenarios!J9*Scenarios!F9,0) -> #VALUE! | M37: =(K37-C37) + (L37-D37) -> #VALUE! | N37: =BaselineCalc!$B$11 * M37 -> #VALUE! | O37: =YearMap!E2 -> 1000 | P37: =IF(Scenarios!N9="lease", YearMap!F2, YearMap!G2) -> 0.4 | Q37: =IF(Scenarios!D9=1, P37*G37, G37) -> #VALUE! | R37: =IF(Scenarios!E9=1, P37*H37, H37) -> 5631973.2 | S37: =IF(B37="FY2026", (Scenarios!D9+Scenarios!E9)*BaselineCalc!$B$10, 0) -> #VALUE! | T37: =(Q37+R37+F37*E37)*I37*(1-J37) -> #VALUE! | U37: =N37*(F37+O37) -> #VALUE! | V37: =T37+U37+S37 -> #VALUE! | W37: =IF(E37+N37>0, V37/(E37+N37),"") -> #VALUE! | X37: =A37&"|"&B37 -> ScenarioKey|FY2026
A38: =Scenarios!A9 -> ScenarioKey | B38: FY2027 | C38: =IF(Scenarios!D9=1,0, K38) -> #VALUE! | D38: =IF(Scenarios!E9=1,0, L38) -> #VALUE! | E38: =C38+D38 -> #VALUE! | F38: =YearMap!B3 -> 0 | G38: =YearMap!C3 -> #VALUE! | H38: =YearMap!D3 -> 5772772.5 | I38: =1-BaselineCalc!$B$5 -> 0.993 | J38: =Scenarios!G9 -> EchoFixed$ | K38: =BaselineCalc!$B$7 + ROUND(Scenarios!K9*Scenarios!F9,0) -> #VALUE! | L38: =BaselineCalc!$B$8 + Scenarios!K9 - ROUND(Scenarios!K9*Scenarios!F9,0) -> #VALUE! | M38: =(K38-C38) + (L38-D38) -> #VALUE! | N38: =BaselineCalc!$B$11 * M38 -> #VALUE! | O38: =YearMap!E3 -> 800 | P38: =IF(Scenarios!N9="lease", YearMap!F3, YearMap!G3) -> 0.35 | Q38: =IF(Scenarios!D9=1, P38*G38, G38) -> #VALUE! | R38: =IF(Scenarios!E9=1, P38*H38, H38) -> 5772772.5 | S38: =IF(B38="FY2026", (Scenarios!D9+Scenarios!E9)*BaselineCalc!$B$10, 0) -> 0 | T38: =(Q38+R38+F38*E38)*I38*(1-J38) -> #VALUE! | U38: =N38*(F38+O38) -> #VALUE! | V38: =T38+U38+S38 -> #VALUE! | W38: =IF(E38+N38>0, V38/(E38+N38),"") -> #VALUE! | X38: =A38&"|"&B38 -> ScenarioKey|FY2027
A39: =Scenarios!A9 -> ScenarioKey | B39: FY2028 | C39: =IF(Scenarios!D9=1,0, K39) -> #VALUE! | D39: =IF(Scenarios!E9=1,0, L39) -> #VALUE! | E39: =C39+D39 -> #VALUE! | F39: =YearMap!B4 -> 0 | G39: =YearMap!C4 -> #VALUE! | H39: =YearMap!D4 -> 5917091.8 | I39: =1-BaselineCalc!$B$5 -> 0.993 | J39: =Scenarios!G9 -> EchoFixed$ | K39: =BaselineCalc!$B$7 + ROUND(Scenarios!L9*Scenarios!F9,0) -> #VALUE! | L39: =BaselineCalc!$B$8 + Scenarios!L9 - ROUND(Scenarios!L9*Scenarios!F9,0) -> #VALUE! | M39: =(K39-C39) + (L39-D39) -> #VALUE! | N39: =BaselineCalc!$B$11 * M39 -> #VALUE! | O39: =YearMap!E4 -> 600 | P39: =IF(Scenarios!N9="lease", YearMap!F4, YearMap!G4) -> 0.3 | Q39: =IF(Scenarios!D9=1, P39*G39, G39) -> #VALUE! | R39: =IF(Scenarios!E9=1, P39*H39, H39) -> 5917091.8 | S39: =IF(B39="FY2026", (Scenarios!D9+Scenarios!E9)*BaselineCalc!$B$10, 0) -> 0 | T39: =(Q39+R39+F39*E39)*I39*(1-J39) -> #VALUE! | U39: =N39*(F39+O39) -> #VALUE! | V39: =T39+U39+S39 -> #VALUE! | W39: =IF(E39+N39>0, V39/(E39+N39),"") -> #VALUE! | X39: =A39&"|"&B39 -> ScenarioKey|FY2028
A40: =Scenarios!A9 -> ScenarioKey | B40: FY2029 | C40: =IF(Scenarios!D9=1,0, K40) -> #VALUE! | D40: =IF(Scenarios!E9=1,0, L40) -> #VALUE! | E40: =C40+D40 -> #VALUE! | F40: =YearMap!B5 -> 0 | G40: =YearMap!C5 -> #VALUE! | H40: =YearMap!D5 -> 6065019.1 | I40: =1-BaselineCalc!$B$5 -> 0.993 | J40: =Scenarios!G9 -> EchoFixed$ | K40: =BaselineCalc!$B$7 + ROUND(Scenarios!M9*Scenarios!F9,0) -> #VALUE! | L40: =BaselineCalc!$B$8 + Scenarios!M9 - ROUND(Scenarios!M9*Scenarios!F9,0) -> #VALUE! | M40: =(K40-C40) + (L40-D40) -> #VALUE! | N40: =BaselineCalc!$B$11 * M40 -> #VALUE! | O40: =YearMap!E5 -> 400 | P40: =IF(Scenarios!N9="lease", YearMap!F5, YearMap!G5) -> 0.25 | Q40: =IF(Scenarios!D9=1, P40*G40, G40) -> #VALUE! | R40: =IF(Scenarios!E9=1, P40*H40, H40) -> 6065019.1 | S40: =IF(B40="FY2026", (Scenarios!D9+Scenarios!E9)*BaselineCalc!$B$10, 0) -> 0 | T40: =(Q40+R40+F40*E40)*I40*(1-J40) -> #VALUE! | U40: =N40*(F40+O40) -> #VALUE! | V40: =T40+U40+S40 -> #VALUE! | W40: =IF(E40+N40>0, V40/(E40+N40),"") -> #VALUE! | X40: =A40&"|"&B40 -> ScenarioKey|FY2029
...

Sheet Notes
A1: FAQs
B2: Why “Fixed share of M&O = 0.30”?
B3: District M&O typically has a sizable semi‑fixed component (plant ops/custodial/insurance/admin overhead). Without site‑level detail yet, 30% is a conservative placeholder in the middle of the 25–40% range many K‑12 systems sit in. We will replace it with SUSD plant ops + insurance shares when available.
B5: Why “Ops savings (keep‑open) = 0.007 (0.7%)”?
B6: This represents “light discipline” (utilities/purchasing tweaks, route smoothing) that does not depend on closing a site. I set it very low on purpose so it doesn’t drive results. We’ll calibrate with SUSD data (e.g., last year’s utility audits) if provided.
B8: Why “Extra savings (co‑location) = 0.015 (1.5%)”?
B9: This reflects incremental savings from consolidating some services on one campus (custodial/grounds/partial routing). Again kept small and conservative; we’ll swap in real custodial (sq‑ft), grounds and route deltas when we get them.
B11: Why “Repurpose TI per closed site (FY26) = $1.2M”? What is “one‑time carry/TI”?
B12: “TI” = tenant improvements / transition investments needed to convert a K‑8 to a different use (early learning, admin consolidation) and carry costs in year one (e.g., abatement, doors/security, low‑voltage re‑work, furniture, swing space). A light‑touch repurpose can easily run $10–$20/sq‑ft; Echo’s plant is ~77k sq ft, so $1.2M is a reasonable placeholder (we are not assuming a gut remodel). We’ll replace this with SUSD’s scope/estimate if they have one.
A17: Definitions
B18: MO inflation
B19: Base MO per ADM (FY25)
B20: Fixed share of MO
B21: Ops savings (keep‑open)
B22: Extra savings (Co‑location)
B23: Echo base ADM
B24: Pima base ADM
B25: Total base ADM

Sheet Summary_Costs
A1: ScenarioKey | B1: FY2028 Comparable $/Student | C1: FY2030 Comparable $/Student | D1: 3‑yr Avg Comparable (FY26–FY28) | E1: 5‑yr Avg Comparable (FY26–FY30)
A2: =Scenarios!A2 -> D_Grow_Both_0 | B2: =INDEX(MultiYear_ProForma!$W$2:$W$61, MATCH(Scenarios!A2&"|FY2028", MultiYear_ProForma!$X$2:$X$61, 0)) -> #VALUE! | C2: =INDEX(MultiYear_ProForma!$W$2:$W$61, MATCH(Scenarios!A2&"|FY2030", MultiYear_ProForma!$X$2:$X$61, 0)) -> #VALUE! | D2: =AVERAGE(INDEX(MultiYear_ProForma!$W$2:$W$61, MATCH(Scenarios!A2&"|FY2026", MultiYear_ProForma!$X$2:$X$61, 0)),INDEX(MultiYear_ProForma!$W$2:$W$61, MATCH(Scenarios!A2&"|FY2027", MultiYear_ProForma!$X$2:$X$61, 0)),INDEX(MultiYear_ProForma!$W$2:$W$61, MATCH(Scenarios!A2&"|FY2028", MultiYear_ProForma!$X$2:$X$61, 0))) -> #VALUE! | E2: =AVERAGE(INDEX(MultiYear_ProForma!$W$2:$W$61, MATCH(Scenarios!A2&"|FY2026", MultiYear_ProForma!$X$2:$X$61, 0)),INDEX(MultiYear_ProForma!$W$2:$W$61, MATCH(Scenarios!A2&"|FY2027", MultiYear_ProForma!$X$2:$X$61, 0)),INDEX(MultiYear_ProForma!$W$2:$W$61, MATCH(Scenarios!A2&"|FY2028", MultiYear_ProForma!$X$2:$X$61, 0)),INDEX(MultiYear_ProForma!$W$2:$W$61, MATCH(Scenarios!A2&"|FY2029", MultiYear_ProForma!$X$2:$X$61, 0)),INDEX(MultiYear_ProForma!$W$2:$W$61, MATCH(Scenarios!A2&"|FY2030", MultiYear_ProForma!$X$2:$X$61, 0))) -> #VALUE!
A3: =Scenarios!A3 -> E_StatusQuo_Targets_0 | B3: =INDEX(MultiYear_ProForma!$W$2:$W$61, MATCH(Scenarios!A3&"|FY2028", MultiYear_ProForma!$X$2:$X$61, 0)) -> #VALUE! | C3: =INDEX(MultiYear_ProForma!$W$2:$W$61, MATCH(Scenarios!A3&"|FY2030", MultiYear_ProForma!$X$2:$X$61, 0)) -> #VALUE! | D3: =AVERAGE(INDEX(MultiYear_ProForma!$W$2:$W$61, MATCH(Scenarios!A3&"|FY2026", MultiYear_ProForma!$X$2:$X$61, 0)),INDEX(MultiYear_ProForma!$W$2:$W$61, MATCH(Scenarios!A3&"|FY2027", MultiYear_ProForma!$X$2:$X$61, 0)),INDEX(MultiYear_ProForma!$W$2:$W$61, MATCH(Scenarios!A3&"|FY2028", MultiYear_ProForma!$X$2:$X$61, 0))) -> #VALUE! | E3: =AVERAGE(INDEX(MultiYear_ProForma!$W$2:$W$61, MATCH(Scenarios!A3&"|FY2026", MultiYear_ProForma!$X$2:$X$61, 0)),INDEX(MultiYear_ProForma!$W$2:$W$61, MATCH(Scenarios!A3&"|FY2027", MultiYear_ProForma!$X$2:$X$61, 0)),INDEX(MultiYear_ProForma!$W$2:$W$61, MATCH(Scenarios!A3&"|FY2028", MultiYear_ProForma!$X$2:$X$61, 0)),INDEX(MultiYear_ProForma!$W$2:$W$61, MATCH(Scenarios!A3&"|FY2029", MultiYear_ProForma!$X$2:$X$61, 0)),INDEX(MultiYear_ProForma!$W$2:$W$61, MATCH(Scenarios!A3&"|FY2030", MultiYear_ProForma!$X$2:$X$61, 0))) -> #VALUE!
