Workbook
Name ADM_Day_Select: Parameters_Public!C8
Name BaseAid_per_ADM: Parameters_Public!C18
Name Capex_ArtsHub: Parameters_Public!C28
Name Capex_in_MO_Toggle: Parameters_Public!C30
Name Capex_InnovHub: Parameters_Public!C29
Name Echo_ADM0: Parameters_Public!C10
Name EchoFixed_FY25_Total: Site_Fixed!C8
Name M_O_per_ADM_Audited: Parameters_Public!C14
Name Override_per_ADM_proxy: Parameters_Public!C19
Name Override_Percent: Parameters_Public!C17
Name Override_Toggle: Parameters_Public!C20
Name Pima_ADM0: Parameters_Public!C11
Name PimaFixed_FY25_Total: Site_Fixed!C15
Name TI_in_MO_Toggle: Parameters_Public!C26
Name TI_per_Site: Parameters_Public!C27

Sheet Parameters_Public
A1: Public Inputs — Audited Baselines and Overrides (Phase A)
A3: ADM (official) | C3: Values | E3: Notes
B4: Echo 40th | C4: 257 | D4: Use Day (40 or 100) | E4: Estimate used at this point; need to replace. Official 40th day ADM for Echo (enter audited)
B5: Echo 100th | C5: 257 | D5: Echo_ADM0 (selected) | E5: Estimate used at this point; need to replace. Official 100th day ADM for Echo (enter audited)
B6: Pima 40th | C6: 296 | D6: Pima_ADM0 (selected) | E6: Estimate used at this point; need to replace. Official 40th day ADM for Pima (enter audited)
B7: Pima 100th | C7: 296 | E7: Estimate used at this point; need to replace. Official 100th day ADM for Pima (enter audited)
B8: Use Day (40 or 100) | C8: 40 | E8: Choose which count the model uses (40 or 100).
B10: Echo_ADM0 (selected) | C10: =IF(C8=40,C4,C5) -> 257 | E10: Model‑read Echo_ADM0 selected based on 40/100 day switch.
B11: Pima_ADM0 (selected) | C11: =IF(C8=40,C6,C7) -> 296 | E11: Model‑read Pima_ADM0 selected based on 40/100 day switch.
A13: M&O/ADM (district), audited (ACFR)
B14: M_O_per_ADM_Audited | C14: 11589 | E14: Enter the audited districtwide Maintenance & Operations cost per ADM from the latest ACFR/Adopted Budget. Used as the FY25 base.
A16: Override — property‑tax override
B17: Override percent | C17: 0.15 | E17: Districtwide override percent (e.g., 15%).
B18: Base aid per ADM (proxy for RCL per pupil) | C18: 5013 | E18: Proxy base for calculating per‑ADM override; replace with RCL per pupil if available.
B19: Override per ADM (proxy) | C19: =C17*C18 -> 751.95 | E19: Computed per‑ADM amount used wherever the model needs a per‑student override term.
B20: Override toggle (1=on, 0=off) | C20: 1 | E20: Global on/off switch for including override in revenue calculations (future phase).
B22: Retention r — Echo (central) | C22: 0.6 | E22: Share of displaced Echo students re-enrolling in SUSD (0–1).
B23: Retention r — Pima (central) | C23: 0.85 | E23: Share of displaced Pima students re-enrolling in SUSD (0–1).
A24: Capital Treatment & Growth Capex (DRAFT placeholders)
B26: Include TI in Operating M&O? (0/1) | C26: 0 | E26: 0 = treat TI as capital (exclude from operating nets); 1 = include TI in Comparable_MO$
B27: TI per closed site (one-time) | C27: =BaselineCalc!$B$22 -> 1200000 | E27: DRAFT Ops TI: Mirrors BaselineCalc TI unit; replace with capital plan when available
B28: Growth Capex — Arts Hub (one-time) | C28: 800000 | E28: DRAFT placeholder; enter benchmarked capital required to enable Arts hub
B29: Growth Capex — Innovation Hub (one-time) | C29: 1200000 | E29: DRAFT placeholder; enter benchmarked capital required for Innovation hub
B30: Include Growth Capex in Operating? (0/1) | C30: 0 | E30: 0 = treat growth capex as capital (recommended); 1 = include in Comparable_MO$ (what‑if only)
B31: TI per closed site (lease case) | C31: 800000 | E31: DRAFT: lease TI placeholder; separate from ops TI (C27)
B32: Portable seat cost (capital $ per seat) | C32: 12000 | E32: DRAFT: per-seat portables or TI to add seats at receivers
B33: Spare K–5 seats across receivers (FY26) | C33: 300 | E33: User input: available elementary seats to absorb retained K–5
B34: Spare 6–8 seats across receivers (FY26) | C34: 150 | E34: User input: available middle seats to absorb retained 6–8
B36: Echo K–5 share of ADM | C36: 0.7 | E36: DRAFT: distribution of Echo ADM by grade band
B37: Echo 6–8 share of ADM | C37: 0.3
B38: Pima K–5 share of ADM | C38: 1
B39: Pima 6–8 share of ADM | C39: 0
B41: MarginalFactor_for_Overlay (central source) | C41: 0.4
B42: Echo ADM trend default | C42: 0.02
B43: Pima ADM trend default | C43: 0.02

Sheet Workbook_Purpose_Overview

Sheet Capital_Summary
A1: Capital Summary (TI & Growth Capex & Portables) — Cash, not Operating
A3: ScenarioKey | B3: Year | C3: ClosedSites | D3: TI_Cash$ | E3: GrowthCapex_Echo$ | F3: GrowthCapex_Pima$ | G3: Portables$ | H3: Total_Capital$
A4: =Scenarios!$A$2 -> D_CUSTOM1 | B4: FY2026 | C4: =INDEX(Scenarios!$D:$D, MATCH($A4, Scenarios!$A:$A, 0)) + INDEX(Scenarios!$E:$E, MATCH($A4, Scenarios!$A:$A, 0)) -> 0 | D4: =IF($B4="FY2026",$C4*IF(INDEX(Scenarios!$N:$N, MATCH($A4, Scenarios!$A:$A, 0))="lease", Parameters_Public!$C$31, Parameters_Public!$C$27),0) -> 0 | E4: =IF($B4="FY2026", IF(INDEX(Scenarios!$D:$D, MATCH($A4, Scenarios!$A:$A, 0))=0, IF(LEFT(INDEX(Scenarios!$O:$O, MATCH($A4, Scenarios!$A:$A, 0)),4)="Arts", Parameters_Public!$C$28, IF(LEFT(INDEX(Scenarios!$O:$O, MATCH($A4, Scenarios!$A:$A, 0)),5)="Innov", Parameters_Public!$C$29, 0)), 0), 0) -> 0 | F4: =IF($B4="FY2026", IF(INDEX(Scenarios!$E:$E, MATCH($A4, Scenarios!$A:$A, 0))=0, IF(LEFT(INDEX(Scenarios!$P:$P, MATCH($A4, Scenarios!$A:$A, 0)),4)="Arts", Parameters_Public!$C$28, IF(LEFT(INDEX(Scenarios!$P:$P, MATCH($A4, Scenarios!$A:$A, 0)),5)="Innov", Parameters_Public!$C$29, 0)), 0), 0) -> 0 | G4: =IF($B4="FY2026", INDEX(Receiving_Capacity!$L:$L, MATCH($A4, Receiving_Capacity!$A:$A, 0)), 0) -> 0 | H4: =SUM(D4:G4) -> 0
A5: =Scenarios!$A$2 -> D_CUSTOM1 | B5: FY2027 | C5: =INDEX(Scenarios!$D:$D, MATCH($A5, Scenarios!$A:$A, 0)) + INDEX(Scenarios!$E:$E, MATCH($A5, Scenarios!$A:$A, 0)) -> 0 | D5: =IF($B5="FY2026",$C5*IF(INDEX(Scenarios!$N:$N, MATCH($A5, Scenarios!$A:$A, 0))="lease", Parameters_Public!$C$31, Parameters_Public!$C$27),0) -> 0 | E5: =IF($B5="FY2026", IF(INDEX(Scenarios!$D:$D, MATCH($A5, Scenarios!$A:$A, 0))=0, IF(LEFT(INDEX(Scenarios!$O:$O, MATCH($A5, Scenarios!$A:$A, 0)),4)="Arts", Parameters_Public!$C$28, IF(LEFT(INDEX(Scenarios!$O:$O, MATCH($A5, Scenarios!$A:$A, 0)),5)="Innov", Parameters_Public!$C$29, 0)), 0), 0) -> 0 | F5: =IF($B5="FY2026", IF(INDEX(Scenarios!$E:$E, MATCH($A5, Scenarios!$A:$A, 0))=0, IF(LEFT(INDEX(Scenarios!$P:$P, MATCH($A5, Scenarios!$A:$A, 0)),4)="Arts", Parameters_Public!$C$28, IF(LEFT(INDEX(Scenarios!$P:$P, MATCH($A5, Scenarios!$A:$A, 0)),5)="Innov", Parameters_Public!$C$29, 0)), 0), 0) -> 0 | G5: =IF($B5="FY2026", INDEX(Receiving_Capacity!$L:$L, MATCH($A5, Receiving_Capacity!$A:$A, 0)), 0) -> 0 | H5: =SUM(D5:G5) -> 0
A6: =Scenarios!$A$2 -> D_CUSTOM1 | B6: FY2028 | C6: =INDEX(Scenarios!$D:$D, MATCH($A6, Scenarios!$A:$A, 0)) + INDEX(Scenarios!$E:$E, MATCH($A6, Scenarios!$A:$A, 0)) -> 0 | D6: =IF($B6="FY2026",$C6*IF(INDEX(Scenarios!$N:$N, MATCH($A6, Scenarios!$A:$A, 0))="lease", Parameters_Public!$C$31, Parameters_Public!$C$27),0) -> 0 | E6: =IF($B6="FY2026", IF(INDEX(Scenarios!$D:$D, MATCH($A6, Scenarios!$A:$A, 0))=0, IF(LEFT(INDEX(Scenarios!$O:$O, MATCH($A6, Scenarios!$A:$A, 0)),4)="Arts", Parameters_Public!$C$28, IF(LEFT(INDEX(Scenarios!$O:$O, MATCH($A6, Scenarios!$A:$A, 0)),5)="Innov", Parameters_Public!$C$29, 0)), 0), 0) -> 0 | F6: =IF($B6="FY2026", IF(INDEX(Scenarios!$E:$E, MATCH($A6, Scenarios!$A:$A, 0))=0, IF(LEFT(INDEX(Scenarios!$P:$P, MATCH($A6, Scenarios!$A:$A, 0)),4)="Arts", Parameters_Public!$C$28, IF(LEFT(INDEX(Scenarios!$P:$P, MATCH($A6, Scenarios!$A:$A, 0)),5)="Innov", Parameters_Public!$C$29, 0)), 0), 0) -> 0 | G6: =IF($B6="FY2026", INDEX(Receiving_Capacity!$L:$L, MATCH($A6, Receiving_Capacity!$A:$A, 0)), 0) -> 0 | H6: =SUM(D6:G6) -> 0
A7: =Scenarios!$A$2 -> D_CUSTOM1 | B7: FY2029 | C7: =INDEX(Scenarios!$D:$D, MATCH($A7, Scenarios!$A:$A, 0)) + INDEX(Scenarios!$E:$E, MATCH($A7, Scenarios!$A:$A, 0)) -> 0 | D7: =IF($B7="FY2026",$C7*IF(INDEX(Scenarios!$N:$N, MATCH($A7, Scenarios!$A:$A, 0))="lease", Parameters_Public!$C$31, Parameters_Public!$C$27),0) -> 0 | E7: =IF($B7="FY2026", IF(INDEX(Scenarios!$D:$D, MATCH($A7, Scenarios!$A:$A, 0))=0, IF(LEFT(INDEX(Scenarios!$O:$O, MATCH($A7, Scenarios!$A:$A, 0)),4)="Arts", Parameters_Public!$C$28, IF(LEFT(INDEX(Scenarios!$O:$O, MATCH($A7, Scenarios!$A:$A, 0)),5)="Innov", Parameters_Public!$C$29, 0)), 0), 0) -> 0 | F7: =IF($B7="FY2026", IF(INDEX(Scenarios!$E:$E, MATCH($A7, Scenarios!$A:$A, 0))=0, IF(LEFT(INDEX(Scenarios!$P:$P, MATCH($A7, Scenarios!$A:$A, 0)),4)="Arts", Parameters_Public!$C$28, IF(LEFT(INDEX(Scenarios!$P:$P, MATCH($A7, Scenarios!$A:$A, 0)),5)="Innov", Parameters_Public!$C$29, 0)), 0), 0) -> 0 | G7: =IF($B7="FY2026", INDEX(Receiving_Capacity!$L:$L, MATCH($A7, Receiving_Capacity!$A:$A, 0)), 0) -> 0 | H7: =SUM(D7:G7) -> 0
A8: =Scenarios!$A$2 -> D_CUSTOM1 | B8: FY2030 | C8: =INDEX(Scenarios!$D:$D, MATCH($A8, Scenarios!$A:$A, 0)) + INDEX(Scenarios!$E:$E, MATCH($A8, Scenarios!$A:$A, 0)) -> 0 | D8: =IF($B8="FY2026",$C8*IF(INDEX(Scenarios!$N:$N, MATCH($A8, Scenarios!$A:$A, 0))="lease", Parameters_Public!$C$31, Parameters_Public!$C$27),0) -> 0 | E8: =IF($B8="FY2026", IF(INDEX(Scenarios!$D:$D, MATCH($A8, Scenarios!$A:$A, 0))=0, IF(LEFT(INDEX(Scenarios!$O:$O, MATCH($A8, Scenarios!$A:$A, 0)),4)="Arts", Parameters_Public!$C$28, IF(LEFT(INDEX(Scenarios!$O:$O, MATCH($A8, Scenarios!$A:$A, 0)),5)="Innov", Parameters_Public!$C$29, 0)), 0), 0) -> 0 | F8: =IF($B8="FY2026", IF(INDEX(Scenarios!$E:$E, MATCH($A8, Scenarios!$A:$A, 0))=0, IF(LEFT(INDEX(Scenarios!$P:$P, MATCH($A8, Scenarios!$A:$A, 0)),4)="Arts", Parameters_Public!$C$28, IF(LEFT(INDEX(Scenarios!$P:$P, MATCH($A8, Scenarios!$A:$A, 0)),5)="Innov", Parameters_Public!$C$29, 0)), 0), 0) -> 0 | G8: =IF($B8="FY2026", INDEX(Receiving_Capacity!$L:$L, MATCH($A8, Receiving_Capacity!$A:$A, 0)), 0) -> 0 | H8: =SUM(D8:G8) -> 0
A9: =Scenarios!$A$3 -> E_StatusQuo_Targets | B9: FY2026 | C9: =INDEX(Scenarios!$D:$D, MATCH($A9, Scenarios!$A:$A, 0)) + INDEX(Scenarios!$E:$E, MATCH($A9, Scenarios!$A:$A, 0)) -> 0 | D9: =IF($B9="FY2026",$C9*IF(INDEX(Scenarios!$N:$N, MATCH($A9, Scenarios!$A:$A, 0))="lease", Parameters_Public!$C$31, Parameters_Public!$C$27),0) -> 0 | E9: =IF($B9="FY2026", IF(INDEX(Scenarios!$D:$D, MATCH($A9, Scenarios!$A:$A, 0))=0, IF(LEFT(INDEX(Scenarios!$O:$O, MATCH($A9, Scenarios!$A:$A, 0)),4)="Arts", Parameters_Public!$C$28, IF(LEFT(INDEX(Scenarios!$O:$O, MATCH($A9, Scenarios!$A:$A, 0)),5)="Innov", Parameters_Public!$C$29, 0)), 0), 0) -> 0 | F9: =IF($B9="FY2026", IF(INDEX(Scenarios!$E:$E, MATCH($A9, Scenarios!$A:$A, 0))=0, IF(LEFT(INDEX(Scenarios!$P:$P, MATCH($A9, Scenarios!$A:$A, 0)),4)="Arts", Parameters_Public!$C$28, IF(LEFT(INDEX(Scenarios!$P:$P, MATCH($A9, Scenarios!$A:$A, 0)),5)="Innov", Parameters_Public!$C$29, 0)), 0), 0) -> 0 | G9: =IF($B9="FY2026", INDEX(Receiving_Capacity!$L:$L, MATCH($A9, Receiving_Capacity!$A:$A, 0)), 0) -> 0 | H9: =SUM(D9:G9) -> 0
A10: =Scenarios!$A$3 -> E_StatusQuo_Targets | B10: FY2027 | C10: =INDEX(Scenarios!$D:$D, MATCH($A10, Scenarios!$A:$A, 0)) + INDEX(Scenarios!$E:$E, MATCH($A10, Scenarios!$A:$A, 0)) -> 0 | D10: =IF($B10="FY2026",$C10*IF(INDEX(Scenarios!$N:$N, MATCH($A10, Scenarios!$A:$A, 0))="lease", Parameters_Public!$C$31, Parameters_Public!$C$27),0) -> 0 | E10: =IF($B10="FY2026", IF(INDEX(Scenarios!$D:$D, MATCH($A10, Scenarios!$A:$A, 0))=0, IF(LEFT(INDEX(Scenarios!$O:$O, MATCH($A10, Scenarios!$A:$A, 0)),4)="Arts", Parameters_Public!$C$28, IF(LEFT(INDEX(Scenarios!$O:$O, MATCH($A10, Scenarios!$A:$A, 0)),5)="Innov", Parameters_Public!$C$29, 0)), 0), 0) -> 0 | F10: =IF($B10="FY2026", IF(INDEX(Scenarios!$E:$E, MATCH($A10, Scenarios!$A:$A, 0))=0, IF(LEFT(INDEX(Scenarios!$P:$P, MATCH($A10, Scenarios!$A:$A, 0)),4)="Arts", Parameters_Public!$C$28, IF(LEFT(INDEX(Scenarios!$P:$P, MATCH($A10, Scenarios!$A:$A, 0)),5)="Innov", Parameters_Public!$C$29, 0)), 0), 0) -> 0 | G10: =IF($B10="FY2026", INDEX(Receiving_Capacity!$L:$L, MATCH($A10, Receiving_Capacity!$A:$A, 0)), 0) -> 0 | H10: =SUM(D10:G10) -> 0
A11: =Scenarios!$A$3 -> E_StatusQuo_Targets | B11: FY2028 | C11: =INDEX(Scenarios!$D:$D, MATCH($A11, Scenarios!$A:$A, 0)) + INDEX(Scenarios!$E:$E, MATCH($A11, Scenarios!$A:$A, 0)) -> 0 | D11: =IF($B11="FY2026",$C11*IF(INDEX(Scenarios!$N:$N, MATCH($A11, Scenarios!$A:$A, 0))="lease", Parameters_Public!$C$31, Parameters_Public!$C$27),0) -> 0 | E11: =IF($B11="FY2026", IF(INDEX(Scenarios!$D:$D, MATCH($A11, Scenarios!$A:$A, 0))=0, IF(LEFT(INDEX(Scenarios!$O:$O, MATCH($A11, Scenarios!$A:$A, 0)),4)="Arts", Parameters_Public!$C$28, IF(LEFT(INDEX(Scenarios!$O:$O, MATCH($A11, Scenarios!$A:$A, 0)),5)="Innov", Parameters_Public!$C$29, 0)), 0), 0) -> 0 | F11: =IF($B11="FY2026", IF(INDEX(Scenarios!$E:$E, MATCH($A11, Scenarios!$A:$A, 0))=0, IF(LEFT(INDEX(Scenarios!$P:$P, MATCH($A11, Scenarios!$A:$A, 0)),4)="Arts", Parameters_Public!$C$28, IF(LEFT(INDEX(Scenarios!$P:$P, MATCH($A11, Scenarios!$A:$A, 0)),5)="Innov", Parameters_Public!$C$29, 0)), 0), 0) -> 0 | G11: =IF($B11="FY2026", INDEX(Receiving_Capacity!$L:$L, MATCH($A11, Receiving_Capacity!$A:$A, 0)), 0) -> 0 | H11: =SUM(D11:G11) -> 0
A12: =Scenarios!$A$3 -> E_StatusQuo_Targets | B12: FY2029 | C12: =INDEX(Scenarios!$D:$D, MATCH($A12, Scenarios!$A:$A, 0)) + INDEX(Scenarios!$E:$E, MATCH($A12, Scenarios!$A:$A, 0)) -> 0 | D12: =IF($B12="FY2026",$C12*IF(INDEX(Scenarios!$N:$N, MATCH($A12, Scenarios!$A:$A, 0))="lease", Parameters_Public!$C$31, Parameters_Public!$C$27),0) -> 0 | E12: =IF($B12="FY2026", IF(INDEX(Scenarios!$D:$D, MATCH($A12, Scenarios!$A:$A, 0))=0, IF(LEFT(INDEX(Scenarios!$O:$O, MATCH($A12, Scenarios!$A:$A, 0)),4)="Arts", Parameters_Public!$C$28, IF(LEFT(INDEX(Scenarios!$O:$O, MATCH($A12, Scenarios!$A:$A, 0)),5)="Innov", Parameters_Public!$C$29, 0)), 0), 0) -> 0 | F12: =IF($B12="FY2026", IF(INDEX(Scenarios!$E:$E, MATCH($A12, Scenarios!$A:$A, 0))=0, IF(LEFT(INDEX(Scenarios!$P:$P, MATCH($A12, Scenarios!$A:$A, 0)),4)="Arts", Parameters_Public!$C$28, IF(LEFT(INDEX(Scenarios!$P:$P, MATCH($A12, Scenarios!$A:$A, 0)),5)="Innov", Parameters_Public!$C$29, 0)), 0), 0) -> 0 | G12: =IF($B12="FY2026", INDEX(Receiving_Capacity!$L:$L, MATCH($A12, Receiving_Capacity!$A:$A, 0)), 0) -> 0 | H12: =SUM(D12:G12) -> 0
A13: =Scenarios!$A$3 -> E_StatusQuo_Targets | B13: FY2030 | C13: =INDEX(Scenarios!$D:$D, MATCH($A13, Scenarios!$A:$A, 0)) + INDEX(Scenarios!$E:$E, MATCH($A13, Scenarios!$A:$A, 0)) -> 0 | D13: =IF($B13="FY2026",$C13*IF(INDEX(Scenarios!$N:$N, MATCH($A13, Scenarios!$A:$A, 0))="lease", Parameters_Public!$C$31, Parameters_Public!$C$27),0) -> 0 | E13: =IF($B13="FY2026", IF(INDEX(Scenarios!$D:$D, MATCH($A13, Scenarios!$A:$A, 0))=0, IF(LEFT(INDEX(Scenarios!$O:$O, MATCH($A13, Scenarios!$A:$A, 0)),4)="Arts", Parameters_Public!$C$28, IF(LEFT(INDEX(Scenarios!$O:$O, MATCH($A13, Scenarios!$A:$A, 0)),5)="Innov", Parameters_Public!$C$29, 0)), 0), 0) -> 0 | F13: =IF($B13="FY2026", IF(INDEX(Scenarios!$E:$E, MATCH($A13, Scenarios!$A:$A, 0))=0, IF(LEFT(INDEX(Scenarios!$P:$P, MATCH($A13, Scenarios!$A:$A, 0)),4)="Arts", Parameters_Public!$C$28, IF(LEFT(INDEX(Scenarios!$P:$P, MATCH($A13, Scenarios!$A:$A, 0)),5)="Innov", Parameters_Public!$C$29, 0)), 0), 0) -> 0 | G13: =IF($B13="FY2026", INDEX(Receiving_Capacity!$L:$L, MATCH($A13, Receiving_Capacity!$A:$A, 0)), 0) -> 0 | H13: =SUM(D13:G13) -> 0
A14: =Scenarios!$A$4 -> F_CoLocation_Echo_Targets | B14: FY2026 | C14: =INDEX(Scenarios!$D:$D, MATCH($A14, Scenarios!$A:$A, 0)) + INDEX(Scenarios!$E:$E, MATCH($A14, Scenarios!$A:$A, 0)) -> 0 | D14: =IF($B14="FY2026",$C14*IF(INDEX(Scenarios!$N:$N, MATCH($A14, Scenarios!$A:$A, 0))="lease", Parameters_Public!$C$31, Parameters_Public!$C$27),0) -> 0 | E14: =IF($B14="FY2026", IF(INDEX(Scenarios!$D:$D, MATCH($A14, Scenarios!$A:$A, 0))=0, IF(LEFT(INDEX(Scenarios!$O:$O, MATCH($A14, Scenarios!$A:$A, 0)),4)="Arts", Parameters_Public!$C$28, IF(LEFT(INDEX(Scenarios!$O:$O, MATCH($A14, Scenarios!$A:$A, 0)),5)="Innov", Parameters_Public!$C$29, 0)), 0), 0) -> 0 | F14: =IF($B14="FY2026", IF(INDEX(Scenarios!$E:$E, MATCH($A14, Scenarios!$A:$A, 0))=0, IF(LEFT(INDEX(Scenarios!$P:$P, MATCH($A14, Scenarios!$A:$A, 0)),4)="Arts", Parameters_Public!$C$28, IF(LEFT(INDEX(Scenarios!$P:$P, MATCH($A14, Scenarios!$A:$A, 0)),5)="Innov", Parameters_Public!$C$29, 0)), 0), 0) -> 0 | G14: =IF($B14="FY2026", INDEX(Receiving_Capacity!$L:$L, MATCH($A14, Receiving_Capacity!$A:$A, 0)), 0) -> 0 | H14: =SUM(D14:G14) -> 0
A15: =Scenarios!$A$4 -> F_CoLocation_Echo_Targets | B15: FY2027 | C15: =INDEX(Scenarios!$D:$D, MATCH($A15, Scenarios!$A:$A, 0)) + INDEX(Scenarios!$E:$E, MATCH($A15, Scenarios!$A:$A, 0)) -> 0 | D15: =IF($B15="FY2026",$C15*IF(INDEX(Scenarios!$N:$N, MATCH($A15, Scenarios!$A:$A, 0))="lease", Parameters_Public!$C$31, Parameters_Public!$C$27),0) -> 0 | E15: =IF($B15="FY2026", IF(INDEX(Scenarios!$D:$D, MATCH($A15, Scenarios!$A:$A, 0))=0, IF(LEFT(INDEX(Scenarios!$O:$O, MATCH($A15, Scenarios!$A:$A, 0)),4)="Arts", Parameters_Public!$C$28, IF(LEFT(INDEX(Scenarios!$O:$O, MATCH($A15, Scenarios!$A:$A, 0)),5)="Innov", Parameters_Public!$C$29, 0)), 0), 0) -> 0 | F15: =IF($B15="FY2026", IF(INDEX(Scenarios!$E:$E, MATCH($A15, Scenarios!$A:$A, 0))=0, IF(LEFT(INDEX(Scenarios!$P:$P, MATCH($A15, Scenarios!$A:$A, 0)),4)="Arts", Parameters_Public!$C$28, IF(LEFT(INDEX(Scenarios!$P:$P, MATCH($A15, Scenarios!$A:$A, 0)),5)="Innov", Parameters_Public!$C$29, 0)), 0), 0) -> 0 | G15: =IF($B15="FY2026", INDEX(Receiving_Capacity!$L:$L, MATCH($A15, Receiving_Capacity!$A:$A, 0)), 0) -> 0 | H15: =SUM(D15:G15) -> 0
A16: =Scenarios!$A$4 -> F_CoLocation_Echo_Targets | B16: FY2028 | C16: =INDEX(Scenarios!$D:$D, MATCH($A16, Scenarios!$A:$A, 0)) + INDEX(Scenarios!$E:$E, MATCH($A16, Scenarios!$A:$A, 0)) -> 0 | D16: =IF($B16="FY2026",$C16*IF(INDEX(Scenarios!$N:$N, MATCH($A16, Scenarios!$A:$A, 0))="lease", Parameters_Public!$C$31, Parameters_Public!$C$27),0) -> 0 | E16: =IF($B16="FY2026", IF(INDEX(Scenarios!$D:$D, MATCH($A16, Scenarios!$A:$A, 0))=0, IF(LEFT(INDEX(Scenarios!$O:$O, MATCH($A16, Scenarios!$A:$A, 0)),4)="Arts", Parameters_Public!$C$28, IF(LEFT(INDEX(Scenarios!$O:$O, MATCH($A16, Scenarios!$A:$A, 0)),5)="Innov", Parameters_Public!$C$29, 0)), 0), 0) -> 0 | F16: =IF($B16="FY2026", IF(INDEX(Scenarios!$E:$E, MATCH($A16, Scenarios!$A:$A, 0))=0, IF(LEFT(INDEX(Scenarios!$P:$P, MATCH($A16, Scenarios!$A:$A, 0)),4)="Arts", Parameters_Public!$C$28, IF(LEFT(INDEX(Scenarios!$P:$P, MATCH($A16, Scenarios!$A:$A, 0)),5)="Innov", Parameters_Public!$C$29, 0)), 0), 0) -> 0 | G16: =IF($B16="FY2026", INDEX(Receiving_Capacity!$L:$L, MATCH($A16, Receiving_Capacity!$A:$A, 0)), 0) -> 0 | H16: =SUM(D16:G16) -> 0
A17: =Scenarios!$A$4 -> F_CoLocation_Echo_Targets | B17: FY2029 | C17: =INDEX(Scenarios!$D:$D, MATCH($A17, Scenarios!$A:$A, 0)) + INDEX(Scenarios!$E:$E, MATCH($A17, Scenarios!$A:$A, 0)) -> 0 | D17: =IF($B17="FY2026",$C17*IF(INDEX(Scenarios!$N:$N, MATCH($A17, Scenarios!$A:$A, 0))="lease", Parameters_Public!$C$31, Parameters_Public!$C$27),0) -> 0 | E17: =IF($B17="FY2026", IF(INDEX(Scenarios!$D:$D, MATCH($A17, Scenarios!$A:$A, 0))=0, IF(LEFT(INDEX(Scenarios!$O:$O, MATCH($A17, Scenarios!$A:$A, 0)),4)="Arts", Parameters_Public!$C$28, IF(LEFT(INDEX(Scenarios!$O:$O, MATCH($A17, Scenarios!$A:$A, 0)),5)="Innov", Parameters_Public!$C$29, 0)), 0), 0) -> 0 | F17: =IF($B17="FY2026", IF(INDEX(Scenarios!$E:$E, MATCH($A17, Scenarios!$A:$A, 0))=0, IF(LEFT(INDEX(Scenarios!$P:$P, MATCH($A17, Scenarios!$A:$A, 0)),4)="Arts", Parameters_Public!$C$28, IF(LEFT(INDEX(Scenarios!$P:$P, MATCH($A17, Scenarios!$A:$A, 0)),5)="Innov", Parameters_Public!$C$29, 0)), 0), 0) -> 0 | G17: =IF($B17="FY2026", INDEX(Receiving_Capacity!$L:$L, MATCH($A17, Receiving_Capacity!$A:$A, 0)), 0) -> 0 | H17: =SUM(D17:G17) -> 0
A18: =Scenarios!$A$4 -> F_CoLocation_Echo_Targets | B18: FY2030 | C18: =INDEX(Scenarios!$D:$D, MATCH($A18, Scenarios!$A:$A, 0)) + INDEX(Scenarios!$E:$E, MATCH($A18, Scenarios!$A:$A, 0)) -> 0 | D18: =IF($B18="FY2026",$C18*IF(INDEX(Scenarios!$N:$N, MATCH($A18, Scenarios!$A:$A, 0))="lease", Parameters_Public!$C$31, Parameters_Public!$C$27),0) -> 0 | E18: =IF($B18="FY2026", IF(INDEX(Scenarios!$D:$D, MATCH($A18, Scenarios!$A:$A, 0))=0, IF(LEFT(INDEX(Scenarios!$O:$O, MATCH($A18, Scenarios!$A:$A, 0)),4)="Arts", Parameters_Public!$C$28, IF(LEFT(INDEX(Scenarios!$O:$O, MATCH($A18, Scenarios!$A:$A, 0)),5)="Innov", Parameters_Public!$C$29, 0)), 0), 0) -> 0 | F18: =IF($B18="FY2026", IF(INDEX(Scenarios!$E:$E, MATCH($A18, Scenarios!$A:$A, 0))=0, IF(LEFT(INDEX(Scenarios!$P:$P, MATCH($A18, Scenarios!$A:$A, 0)),4)="Arts", Parameters_Public!$C$28, IF(LEFT(INDEX(Scenarios!$P:$P, MATCH($A18, Scenarios!$A:$A, 0)),5)="Innov", Parameters_Public!$C$29, 0)), 0), 0) -> 0 | G18: =IF($B18="FY2026", INDEX(Receiving_Capacity!$L:$L, MATCH($A18, Receiving_Capacity!$A:$A, 0)), 0) -> 0 | H18: =SUM(D18:G18) -> 0
A19: =Scenarios!$A$5 -> D_Grow_Both_Targets | B19: FY2026 | C19: =INDEX(Scenarios!$D:$D, MATCH($A19, Scenarios!$A:$A, 0)) + INDEX(Scenarios!$E:$E, MATCH($A19, Scenarios!$A:$A, 0)) -> 0 | D19: =IF($B19="FY2026",$C19*IF(INDEX(Scenarios!$N:$N, MATCH($A19, Scenarios!$A:$A, 0))="lease", Parameters_Public!$C$31, Parameters_Public!$C$27),0) -> 0 | E19: =IF($B19="FY2026", IF(INDEX(Scenarios!$D:$D, MATCH($A19, Scenarios!$A:$A, 0))=0, IF(LEFT(INDEX(Scenarios!$O:$O, MATCH($A19, Scenarios!$A:$A, 0)),4)="Arts", Parameters_Public!$C$28, IF(LEFT(INDEX(Scenarios!$O:$O, MATCH($A19, Scenarios!$A:$A, 0)),5)="Innov", Parameters_Public!$C$29, 0)), 0), 0) -> 1200000 | F19: =IF($B19="FY2026", IF(INDEX(Scenarios!$E:$E, MATCH($A19, Scenarios!$A:$A, 0))=0, IF(LEFT(INDEX(Scenarios!$P:$P, MATCH($A19, Scenarios!$A:$A, 0)),4)="Arts", Parameters_Public!$C$28, IF(LEFT(INDEX(Scenarios!$P:$P, MATCH($A19, Scenarios!$A:$A, 0)),5)="Innov", Parameters_Public!$C$29, 0)), 0), 0) -> 800000 | G19: =IF($B19="FY2026", INDEX(Receiving_Capacity!$L:$L, MATCH($A19, Receiving_Capacity!$A:$A, 0)), 0) -> 0 | H19: =SUM(D19:G19) -> 2000000
A20: =Scenarios!$A$5 -> D_Grow_Both_Targets | B20: FY2027 | C20: =INDEX(Scenarios!$D:$D, MATCH($A20, Scenarios!$A:$A, 0)) + INDEX(Scenarios!$E:$E, MATCH($A20, Scenarios!$A:$A, 0)) -> 0 | D20: =IF($B20="FY2026",$C20*IF(INDEX(Scenarios!$N:$N, MATCH($A20, Scenarios!$A:$A, 0))="lease", Parameters_Public!$C$31, Parameters_Public!$C$27),0) -> 0 | E20: =IF($B20="FY2026", IF(INDEX(Scenarios!$D:$D, MATCH($A20, Scenarios!$A:$A, 0))=0, IF(LEFT(INDEX(Scenarios!$O:$O, MATCH($A20, Scenarios!$A:$A, 0)),4)="Arts", Parameters_Public!$C$28, IF(LEFT(INDEX(Scenarios!$O:$O, MATCH($A20, Scenarios!$A:$A, 0)),5)="Innov", Parameters_Public!$C$29, 0)), 0), 0) -> 0 | F20: =IF($B20="FY2026", IF(INDEX(Scenarios!$E:$E, MATCH($A20, Scenarios!$A:$A, 0))=0, IF(LEFT(INDEX(Scenarios!$P:$P, MATCH($A20, Scenarios!$A:$A, 0)),4)="Arts", Parameters_Public!$C$28, IF(LEFT(INDEX(Scenarios!$P:$P, MATCH($A20, Scenarios!$A:$A, 0)),5)="Innov", Parameters_Public!$C$29, 0)), 0), 0) -> 0 | G20: =IF($B20="FY2026", INDEX(Receiving_Capacity!$L:$L, MATCH($A20, Receiving_Capacity!$A:$A, 0)), 0) -> 0 | H20: =SUM(D20:G20) -> 0
A21: =Scenarios!$A$5 -> D_Grow_Both_Targets | B21: FY2028 | C21: =INDEX(Scenarios!$D:$D, MATCH($A21, Scenarios!$A:$A, 0)) + INDEX(Scenarios!$E:$E, MATCH($A21, Scenarios!$A:$A, 0)) -> 0 | D21: =IF($B21="FY2026",$C21*IF(INDEX(Scenarios!$N:$N, MATCH($A21, Scenarios!$A:$A, 0))="lease", Parameters_Public!$C$31, Parameters_Public!$C$27),0) -> 0 | E21: =IF($B21="FY2026", IF(INDEX(Scenarios!$D:$D, MATCH($A21, Scenarios!$A:$A, 0))=0, IF(LEFT(INDEX(Scenarios!$O:$O, MATCH($A21, Scenarios!$A:$A, 0)),4)="Arts", Parameters_Public!$C$28, IF(LEFT(INDEX(Scenarios!$O:$O, MATCH($A21, Scenarios!$A:$A, 0)),5)="Innov", Parameters_Public!$C$29, 0)), 0), 0) -> 0 | F21: =IF($B21="FY2026", IF(INDEX(Scenarios!$E:$E, MATCH($A21, Scenarios!$A:$A, 0))=0, IF(LEFT(INDEX(Scenarios!$P:$P, MATCH($A21, Scenarios!$A:$A, 0)),4)="Arts", Parameters_Public!$C$28, IF(LEFT(INDEX(Scenarios!$P:$P, MATCH($A21, Scenarios!$A:$A, 0)),5)="Innov", Parameters_Public!$C$29, 0)), 0), 0) -> 0 | G21: =IF($B21="FY2026", INDEX(Receiving_Capacity!$L:$L, MATCH($A21, Receiving_Capacity!$A:$A, 0)), 0) -> 0 | H21: =SUM(D21:G21) -> 0
A22: =Scenarios!$A$5 -> D_Grow_Both_Targets | B22: FY2029 | C22: =INDEX(Scenarios!$D:$D, MATCH($A22, Scenarios!$A:$A, 0)) + INDEX(Scenarios!$E:$E, MATCH($A22, Scenarios!$A:$A, 0)) -> 0 | D22: =IF($B22="FY2026",$C22*IF(INDEX(Scenarios!$N:$N, MATCH($A22, Scenarios!$A:$A, 0))="lease", Parameters_Public!$C$31, Parameters_Public!$C$27),0) -> 0 | E22: =IF($B22="FY2026", IF(INDEX(Scenarios!$D:$D, MATCH($A22, Scenarios!$A:$A, 0))=0, IF(LEFT(INDEX(Scenarios!$O:$O, MATCH($A22, Scenarios!$A:$A, 0)),4)="Arts", Parameters_Public!$C$28, IF(LEFT(INDEX(Scenarios!$O:$O, MATCH($A22, Scenarios!$A:$A, 0)),5)="Innov", Parameters_Public!$C$29, 0)), 0), 0) -> 0 | F22: =IF($B22="FY2026", IF(INDEX(Scenarios!$E:$E, MATCH($A22, Scenarios!$A:$A, 0))=0, IF(LEFT(INDEX(Scenarios!$P:$P, MATCH($A22, Scenarios!$A:$A, 0)),4)="Arts", Parameters_Public!$C$28, IF(LEFT(INDEX(Scenarios!$P:$P, MATCH($A22, Scenarios!$A:$A, 0)),5)="Innov", Parameters_Public!$C$29, 0)), 0), 0) -> 0 | G22: =IF($B22="FY2026", INDEX(Receiving_Capacity!$L:$L, MATCH($A22, Receiving_Capacity!$A:$A, 0)), 0) -> 0 | H22: =SUM(D22:G22) -> 0
A23: =Scenarios!$A$5 -> D_Grow_Both_Targets | B23: FY2030 | C23: =INDEX(Scenarios!$D:$D, MATCH($A23, Scenarios!$A:$A, 0)) + INDEX(Scenarios!$E:$E, MATCH($A23, Scenarios!$A:$A, 0)) -> 0 | D23: =IF($B23="FY2026",$C23*IF(INDEX(Scenarios!$N:$N, MATCH($A23, Scenarios!$A:$A, 0))="lease", Parameters_Public!$C$31, Parameters_Public!$C$27),0) -> 0 | E23: =IF($B23="FY2026", IF(INDEX(Scenarios!$D:$D, MATCH($A23, Scenarios!$A:$A, 0))=0, IF(LEFT(INDEX(Scenarios!$O:$O, MATCH($A23, Scenarios!$A:$A, 0)),4)="Arts", Parameters_Public!$C$28, IF(LEFT(INDEX(Scenarios!$O:$O, MATCH($A23, Scenarios!$A:$A, 0)),5)="Innov", Parameters_Public!$C$29, 0)), 0), 0) -> 0 | F23: =IF($B23="FY2026", IF(INDEX(Scenarios!$E:$E, MATCH($A23, Scenarios!$A:$A, 0))=0, IF(LEFT(INDEX(Scenarios!$P:$P, MATCH($A23, Scenarios!$A:$A, 0)),4)="Arts", Parameters_Public!$C$28, IF(LEFT(INDEX(Scenarios!$P:$P, MATCH($A23, Scenarios!$A:$A, 0)),5)="Innov", Parameters_Public!$C$29, 0)), 0), 0) -> 0 | G23: =IF($B23="FY2026", INDEX(Receiving_Capacity!$L:$L, MATCH($A23, Receiving_Capacity!$A:$A, 0)), 0) -> 0 | H23: =SUM(D23:G23) -> 0
A24: =Scenarios!$A$6 -> D_CUSTOM2 | B24: FY2026 | C24: =INDEX(Scenarios!$D:$D, MATCH($A24, Scenarios!$A:$A, 0)) + INDEX(Scenarios!$E:$E, MATCH($A24, Scenarios!$A:$A, 0)) -> 0 | D24: =IF($B24="FY2026",$C24*IF(INDEX(Scenarios!$N:$N, MATCH($A24, Scenarios!$A:$A, 0))="lease", Parameters_Public!$C$31, Parameters_Public!$C$27),0) -> 0 | E24: =IF($B24="FY2026", IF(INDEX(Scenarios!$D:$D, MATCH($A24, Scenarios!$A:$A, 0))=0, IF(LEFT(INDEX(Scenarios!$O:$O, MATCH($A24, Scenarios!$A:$A, 0)),4)="Arts", Parameters_Public!$C$28, IF(LEFT(INDEX(Scenarios!$O:$O, MATCH($A24, Scenarios!$A:$A, 0)),5)="Innov", Parameters_Public!$C$29, 0)), 0), 0) -> 0 | F24: =IF($B24="FY2026", IF(INDEX(Scenarios!$E:$E, MATCH($A24, Scenarios!$A:$A, 0))=0, IF(LEFT(INDEX(Scenarios!$P:$P, MATCH($A24, Scenarios!$A:$A, 0)),4)="Arts", Parameters_Public!$C$28, IF(LEFT(INDEX(Scenarios!$P:$P, MATCH($A24, Scenarios!$A:$A, 0)),5)="Innov", Parameters_Public!$C$29, 0)), 0), 0) -> 0 | G24: =IF($B24="FY2026", INDEX(Receiving_Capacity!$L:$L, MATCH($A24, Receiving_Capacity!$A:$A, 0)), 0) -> 0 | H24: =SUM(D24:G24) -> 0
A25: =Scenarios!$A$6 -> D_CUSTOM2 | B25: FY2027 | C25: =INDEX(Scenarios!$D:$D, MATCH($A25, Scenarios!$A:$A, 0)) + INDEX(Scenarios!$E:$E, MATCH($A25, Scenarios!$A:$A, 0)) -> 0 | D25: =IF($B25="FY2026",$C25*IF(INDEX(Scenarios!$N:$N, MATCH($A25, Scenarios!$A:$A, 0))="lease", Parameters_Public!$C$31, Parameters_Public!$C$27),0) -> 0 | E25: =IF($B25="FY2026", IF(INDEX(Scenarios!$D:$D, MATCH($A25, Scenarios!$A:$A, 0))=0, IF(LEFT(INDEX(Scenarios!$O:$O, MATCH($A25, Scenarios!$A:$A, 0)),4)="Arts", Parameters_Public!$C$28, IF(LEFT(INDEX(Scenarios!$O:$O, MATCH($A25, Scenarios!$A:$A, 0)),5)="Innov", Parameters_Public!$C$29, 0)), 0), 0) -> 0 | F25: =IF($B25="FY2026", IF(INDEX(Scenarios!$E:$E, MATCH($A25, Scenarios!$A:$A, 0))=0, IF(LEFT(INDEX(Scenarios!$P:$P, MATCH($A25, Scenarios!$A:$A, 0)),4)="Arts", Parameters_Public!$C$28, IF(LEFT(INDEX(Scenarios!$P:$P, MATCH($A25, Scenarios!$A:$A, 0)),5)="Innov", Parameters_Public!$C$29, 0)), 0), 0) -> 0 | G25: =IF($B25="FY2026", INDEX(Receiving_Capacity!$L:$L, MATCH($A25, Receiving_Capacity!$A:$A, 0)), 0) -> 0 | H25: =SUM(D25:G25) -> 0
A26: =Scenarios!$A$6 -> D_CUSTOM2 | B26: FY2028 | C26: =INDEX(Scenarios!$D:$D, MATCH($A26, Scenarios!$A:$A, 0)) + INDEX(Scenarios!$E:$E, MATCH($A26, Scenarios!$A:$A, 0)) -> 0 | D26: =IF($B26="FY2026",$C26*IF(INDEX(Scenarios!$N:$N, MATCH($A26, Scenarios!$A:$A, 0))="lease", Parameters_Public!$C$31, Parameters_Public!$C$27),0) -> 0 | E26: =IF($B26="FY2026", IF(INDEX(Scenarios!$D:$D, MATCH($A26, Scenarios!$A:$A, 0))=0, IF(LEFT(INDEX(Scenarios!$O:$O, MATCH($A26, Scenarios!$A:$A, 0)),4)="Arts", Parameters_Public!$C$28, IF(LEFT(INDEX(Scenarios!$O:$O, MATCH($A26, Scenarios!$A:$A, 0)),5)="Innov", Parameters_Public!$C$29, 0)), 0), 0) -> 0 | F26: =IF($B26="FY2026", IF(INDEX(Scenarios!$E:$E, MATCH($A26, Scenarios!$A:$A, 0))=0, IF(LEFT(INDEX(Scenarios!$P:$P, MATCH($A26, Scenarios!$A:$A, 0)),4)="Arts", Parameters_Public!$C$28, IF(LEFT(INDEX(Scenarios!$P:$P, MATCH($A26, Scenarios!$A:$A, 0)),5)="Innov", Parameters_Public!$C$29, 0)), 0), 0) -> 0 | G26: =IF($B26="FY2026", INDEX(Receiving_Capacity!$L:$L, MATCH($A26, Receiving_Capacity!$A:$A, 0)), 0) -> 0 | H26: =SUM(D26:G26) -> 0
A27: =Scenarios!$A$6 -> D_CUSTOM2 | B27: FY2029 | C27: =INDEX(Scenarios!$D:$D, MATCH($A27, Scenarios!$A:$A, 0)) + INDEX(Scenarios!$E:$E, MATCH($A27, Scenarios!$A:$A, 0)) -> 0 | D27: =IF($B27="FY2026",$C27*IF(INDEX(Scenarios!$N:$N, MATCH($A27, Scenarios!$A:$A, 0))="lease", Parameters_Public!$C$31, Parameters_Public!$C$27),0) -> 0 | E27: =IF($B27="FY2026", IF(INDEX(Scenarios!$D:$D, MATCH($A27, Scenarios!$A:$A, 0))=0, IF(LEFT(INDEX(Scenarios!$O:$O, MATCH($A27, Scenarios!$A:$A, 0)),4)="Arts", Parameters_Public!$C$28, IF(LEFT(INDEX(Scenarios!$O:$O, MATCH($A27, Scenarios!$A:$A, 0)),5)="Innov", Parameters_Public!$C$29, 0)), 0), 0) -> 0 | F27: =IF($B27="FY2026", IF(INDEX(Scenarios!$E:$E, MATCH($A27, Scenarios!$A:$A, 0))=0, IF(LEFT(INDEX(Scenarios!$P:$P, MATCH($A27, Scenarios!$A:$A, 0)),4)="Arts", Parameters_Public!$C$28, IF(LEFT(INDEX(Scenarios!$P:$P, MATCH($A27, Scenarios!$A:$A, 0)),5)="Innov", Parameters_Public!$C$29, 0)), 0), 0) -> 0 | G27: =IF($B27="FY2026", INDEX(Receiving_Capacity!$L:$L, MATCH($A27, Receiving_Capacity!$A:$A, 0)), 0) -> 0 | H27: =SUM(D27:G27) -> 0
A28: =Scenarios!$A$6 -> D_CUSTOM2 | B28: FY2030 | C28: =INDEX(Scenarios!$D:$D, MATCH($A28, Scenarios!$A:$A, 0)) + INDEX(Scenarios!$E:$E, MATCH($A28, Scenarios!$A:$A, 0)) -> 0 | D28: =IF($B28="FY2026",$C28*IF(INDEX(Scenarios!$N:$N, MATCH($A28, Scenarios!$A:$A, 0))="lease", Parameters_Public!$C$31, Parameters_Public!$C$27),0) -> 0 | E28: =IF($B28="FY2026", IF(INDEX(Scenarios!$D:$D, MATCH($A28, Scenarios!$A:$A, 0))=0, IF(LEFT(INDEX(Scenarios!$O:$O, MATCH($A28, Scenarios!$A:$A, 0)),4)="Arts", Parameters_Public!$C$28, IF(LEFT(INDEX(Scenarios!$O:$O, MATCH($A28, Scenarios!$A:$A, 0)),5)="Innov", Parameters_Public!$C$29, 0)), 0), 0) -> 0 | F28: =IF($B28="FY2026", IF(INDEX(Scenarios!$E:$E, MATCH($A28, Scenarios!$A:$A, 0))=0, IF(LEFT(INDEX(Scenarios!$P:$P, MATCH($A28, Scenarios!$A:$A, 0)),4)="Arts", Parameters_Public!$C$28, IF(LEFT(INDEX(Scenarios!$P:$P, MATCH($A28, Scenarios!$A:$A, 0)),5)="Innov", Parameters_Public!$C$29, 0)), 0), 0) -> 0 | G28: =IF($B28="FY2026", INDEX(Receiving_Capacity!$L:$L, MATCH($A28, Receiving_Capacity!$A:$A, 0)), 0) -> 0 | H28: =SUM(D28:G28) -> 0
A29: =Scenarios!$A$7 -> G_EchoGHubRamp_PimaTargets | B29: FY2026 | C29: =INDEX(Scenarios!$D:$D, MATCH($A29, Scenarios!$A:$A, 0)) + INDEX(Scenarios!$E:$E, MATCH($A29, Scenarios!$A:$A, 0)) -> 0 | D29: =IF($B29="FY2026",$C29*IF(INDEX(Scenarios!$N:$N, MATCH($A29, Scenarios!$A:$A, 0))="lease", Parameters_Public!$C$31, Parameters_Public!$C$27),0) -> 0 | E29: =IF($B29="FY2026", IF(INDEX(Scenarios!$D:$D, MATCH($A29, Scenarios!$A:$A, 0))=0, IF(LEFT(INDEX(Scenarios!$O:$O, MATCH($A29, Scenarios!$A:$A, 0)),4)="Arts", Parameters_Public!$C$28, IF(LEFT(INDEX(Scenarios!$O:$O, MATCH($A29, Scenarios!$A:$A, 0)),5)="Innov", Parameters_Public!$C$29, 0)), 0), 0) -> 800000 | F29: =IF($B29="FY2026", IF(INDEX(Scenarios!$E:$E, MATCH($A29, Scenarios!$A:$A, 0))=0, IF(LEFT(INDEX(Scenarios!$P:$P, MATCH($A29, Scenarios!$A:$A, 0)),4)="Arts", Parameters_Public!$C$28, IF(LEFT(INDEX(Scenarios!$P:$P, MATCH($A29, Scenarios!$A:$A, 0)),5)="Innov", Parameters_Public!$C$29, 0)), 0), 0) -> 0 | G29: =IF($B29="FY2026", INDEX(Receiving_Capacity!$L:$L, MATCH($A29, Receiving_Capacity!$A:$A, 0)), 0) -> 0 | H29: =SUM(D29:G29) -> 800000
A30: =Scenarios!$A$7 -> G_EchoGHubRamp_PimaTargets | B30: FY2027 | C30: =INDEX(Scenarios!$D:$D, MATCH($A30, Scenarios!$A:$A, 0)) + INDEX(Scenarios!$E:$E, MATCH($A30, Scenarios!$A:$A, 0)) -> 0 | D30: =IF($B30="FY2026",$C30*IF(INDEX(Scenarios!$N:$N, MATCH($A30, Scenarios!$A:$A, 0))="lease", Parameters_Public!$C$31, Parameters_Public!$C$27),0) -> 0 | E30: =IF($B30="FY2026", IF(INDEX(Scenarios!$D:$D, MATCH($A30, Scenarios!$A:$A, 0))=0, IF(LEFT(INDEX(Scenarios!$O:$O, MATCH($A30, Scenarios!$A:$A, 0)),4)="Arts", Parameters_Public!$C$28, IF(LEFT(INDEX(Scenarios!$O:$O, MATCH($A30, Scenarios!$A:$A, 0)),5)="Innov", Parameters_Public!$C$29, 0)), 0), 0) -> 0 | F30: =IF($B30="FY2026", IF(INDEX(Scenarios!$E:$E, MATCH($A30, Scenarios!$A:$A, 0))=0, IF(LEFT(INDEX(Scenarios!$P:$P, MATCH($A30, Scenarios!$A:$A, 0)),4)="Arts", Parameters_Public!$C$28, IF(LEFT(INDEX(Scenarios!$P:$P, MATCH($A30, Scenarios!$A:$A, 0)),5)="Innov", Parameters_Public!$C$29, 0)), 0), 0) -> 0 | G30: =IF($B30="FY2026", INDEX(Receiving_Capacity!$L:$L, MATCH($A30, Receiving_Capacity!$A:$A, 0)), 0) -> 0 | H30: =SUM(D30:G30) -> 0
A31: =Scenarios!$A$7 -> G_EchoGHubRamp_PimaTargets | B31: FY2028 | C31: =INDEX(Scenarios!$D:$D, MATCH($A31, Scenarios!$A:$A, 0)) + INDEX(Scenarios!$E:$E, MATCH($A31, Scenarios!$A:$A, 0)) -> 0 | D31: =IF($B31="FY2026",$C31*IF(INDEX(Scenarios!$N:$N, MATCH($A31, Scenarios!$A:$A, 0))="lease", Parameters_Public!$C$31, Parameters_Public!$C$27),0) -> 0 | E31: =IF($B31="FY2026", IF(INDEX(Scenarios!$D:$D, MATCH($A31, Scenarios!$A:$A, 0))=0, IF(LEFT(INDEX(Scenarios!$O:$O, MATCH($A31, Scenarios!$A:$A, 0)),4)="Arts", Parameters_Public!$C$28, IF(LEFT(INDEX(Scenarios!$O:$O, MATCH($A31, Scenarios!$A:$A, 0)),5)="Innov", Parameters_Public!$C$29, 0)), 0), 0) -> 0 | F31: =IF($B31="FY2026", IF(INDEX(Scenarios!$E:$E, MATCH($A31, Scenarios!$A:$A, 0))=0, IF(LEFT(INDEX(Scenarios!$P:$P, MATCH($A31, Scenarios!$A:$A, 0)),4)="Arts", Parameters_Public!$C$28, IF(LEFT(INDEX(Scenarios!$P:$P, MATCH($A31, Scenarios!$A:$A, 0)),5)="Innov", Parameters_Public!$C$29, 0)), 0), 0) -> 0 | G31: =IF($B31="FY2026", INDEX(Receiving_Capacity!$L:$L, MATCH($A31, Receiving_Capacity!$A:$A, 0)), 0) -> 0 | H31: =SUM(D31:G31) -> 0
A32: =Scenarios!$A$7 -> G_EchoGHubRamp_PimaTargets | B32: FY2029 | C32: =INDEX(Scenarios!$D:$D, MATCH($A32, Scenarios!$A:$A, 0)) + INDEX(Scenarios!$E:$E, MATCH($A32, Scenarios!$A:$A, 0)) -> 0 | D32: =IF($B32="FY2026",$C32*IF(INDEX(Scenarios!$N:$N, MATCH($A32, Scenarios!$A:$A, 0))="lease", Parameters_Public!$C$31, Parameters_Public!$C$27),0) -> 0 | E32: =IF($B32="FY2026", IF(INDEX(Scenarios!$D:$D, MATCH($A32, Scenarios!$A:$A, 0))=0, IF(LEFT(INDEX(Scenarios!$O:$O, MATCH($A32, Scenarios!$A:$A, 0)),4)="Arts", Parameters_Public!$C$28, IF(LEFT(INDEX(Scenarios!$O:$O, MATCH($A32, Scenarios!$A:$A, 0)),5)="Innov", Parameters_Public!$C$29, 0)), 0), 0) -> 0 | F32: =IF($B32="FY2026", IF(INDEX(Scenarios!$E:$E, MATCH($A32, Scenarios!$A:$A, 0))=0, IF(LEFT(INDEX(Scenarios!$P:$P, MATCH($A32, Scenarios!$A:$A, 0)),4)="Arts", Parameters_Public!$C$28, IF(LEFT(INDEX(Scenarios!$P:$P, MATCH($A32, Scenarios!$A:$A, 0)),5)="Innov", Parameters_Public!$C$29, 0)), 0), 0) -> 0 | G32: =IF($B32="FY2026", INDEX(Receiving_Capacity!$L:$L, MATCH($A32, Receiving_Capacity!$A:$A, 0)), 0) -> 0 | H32: =SUM(D32:G32) -> 0
A33: =Scenarios!$A$7 -> G_EchoGHubRamp_PimaTargets | B33: FY2030 | C33: =INDEX(Scenarios!$D:$D, MATCH($A33, Scenarios!$A:$A, 0)) + INDEX(Scenarios!$E:$E, MATCH($A33, Scenarios!$A:$A, 0)) -> 0 | D33: =IF($B33="FY2026",$C33*IF(INDEX(Scenarios!$N:$N, MATCH($A33, Scenarios!$A:$A, 0))="lease", Parameters_Public!$C$31, Parameters_Public!$C$27),0) -> 0 | E33: =IF($B33="FY2026", IF(INDEX(Scenarios!$D:$D, MATCH($A33, Scenarios!$A:$A, 0))=0, IF(LEFT(INDEX(Scenarios!$O:$O, MATCH($A33, Scenarios!$A:$A, 0)),4)="Arts", Parameters_Public!$C$28, IF(LEFT(INDEX(Scenarios!$O:$O, MATCH($A33, Scenarios!$A:$A, 0)),5)="Innov", Parameters_Public!$C$29, 0)), 0), 0) -> 0 | F33: =IF($B33="FY2026", IF(INDEX(Scenarios!$E:$E, MATCH($A33, Scenarios!$A:$A, 0))=0, IF(LEFT(INDEX(Scenarios!$P:$P, MATCH($A33, Scenarios!$A:$A, 0)),4)="Arts", Parameters_Public!$C$28, IF(LEFT(INDEX(Scenarios!$P:$P, MATCH($A33, Scenarios!$A:$A, 0)),5)="Innov", Parameters_Public!$C$29, 0)), 0), 0) -> 0 | G33: =IF($B33="FY2026", INDEX(Receiving_Capacity!$L:$L, MATCH($A33, Receiving_Capacity!$A:$A, 0)), 0) -> 0 | H33: =SUM(D33:G33) -> 0
A34: =Scenarios!$A$8 -> A_Repurpose_Both_lease | B34: FY2026 | C34: =INDEX(Scenarios!$D:$D, MATCH($A34, Scenarios!$A:$A, 0)) + INDEX(Scenarios!$E:$E, MATCH($A34, Scenarios!$A:$A, 0)) -> 2 | D34: =IF($B34="FY2026",$C34*IF(INDEX(Scenarios!$N:$N, MATCH($A34, Scenarios!$A:$A, 0))="lease", Parameters_Public!$C$31, Parameters_Public!$C$27),0) -> 1600000 | E34: =IF($B34="FY2026", IF(INDEX(Scenarios!$D:$D, MATCH($A34, Scenarios!$A:$A, 0))=0, IF(LEFT(INDEX(Scenarios!$O:$O, MATCH($A34, Scenarios!$A:$A, 0)),4)="Arts", Parameters_Public!$C$28, IF(LEFT(INDEX(Scenarios!$O:$O, MATCH($A34, Scenarios!$A:$A, 0)),5)="Innov", Parameters_Public!$C$29, 0)), 0), 0) -> 0 | F34: =IF($B34="FY2026", IF(INDEX(Scenarios!$E:$E, MATCH($A34, Scenarios!$A:$A, 0))=0, IF(LEFT(INDEX(Scenarios!$P:$P, MATCH($A34, Scenarios!$A:$A, 0)),4)="Arts", Parameters_Public!$C$28, IF(LEFT(INDEX(Scenarios!$P:$P, MATCH($A34, Scenarios!$A:$A, 0)),5)="Innov", Parameters_Public!$C$29, 0)), 0), 0) -> 0 | G34: =IF($B34="FY2026", INDEX(Receiving_Capacity!$L:$L, MATCH($A34, Receiving_Capacity!$A:$A, 0)), 0) -> 714480 | H34: =SUM(D34:G34) -> 2314480
A35: =Scenarios!$A$8 -> A_Repurpose_Both_lease | B35: FY2027 | C35: =INDEX(Scenarios!$D:$D, MATCH($A35, Scenarios!$A:$A, 0)) + INDEX(Scenarios!$E:$E, MATCH($A35, Scenarios!$A:$A, 0)) -> 2 | D35: =IF($B35="FY2026",$C35*IF(INDEX(Scenarios!$N:$N, MATCH($A35, Scenarios!$A:$A, 0))="lease", Parameters_Public!$C$31, Parameters_Public!$C$27),0) -> 0 | E35: =IF($B35="FY2026", IF(INDEX(Scenarios!$D:$D, MATCH($A35, Scenarios!$A:$A, 0))=0, IF(LEFT(INDEX(Scenarios!$O:$O, MATCH($A35, Scenarios!$A:$A, 0)),4)="Arts", Parameters_Public!$C$28, IF(LEFT(INDEX(Scenarios!$O:$O, MATCH($A35, Scenarios!$A:$A, 0)),5)="Innov", Parameters_Public!$C$29, 0)), 0), 0) -> 0 | F35: =IF($B35="FY2026", IF(INDEX(Scenarios!$E:$E, MATCH($A35, Scenarios!$A:$A, 0))=0, IF(LEFT(INDEX(Scenarios!$P:$P, MATCH($A35, Scenarios!$A:$A, 0)),4)="Arts", Parameters_Public!$C$28, IF(LEFT(INDEX(Scenarios!$P:$P, MATCH($A35, Scenarios!$A:$A, 0)),5)="Innov", Parameters_Public!$C$29, 0)), 0), 0) -> 0 | G35: =IF($B35="FY2026", INDEX(Receiving_Capacity!$L:$L, MATCH($A35, Receiving_Capacity!$A:$A, 0)), 0) -> 0 | H35: =SUM(D35:G35) -> 0
A36: =Scenarios!$A$8 -> A_Repurpose_Both_lease | B36: FY2028 | C36: =INDEX(Scenarios!$D:$D, MATCH($A36, Scenarios!$A:$A, 0)) + INDEX(Scenarios!$E:$E, MATCH($A36, Scenarios!$A:$A, 0)) -> 2 | D36: =IF($B36="FY2026",$C36*IF(INDEX(Scenarios!$N:$N, MATCH($A36, Scenarios!$A:$A, 0))="lease", Parameters_Public!$C$31, Parameters_Public!$C$27),0) -> 0 | E36: =IF($B36="FY2026", IF(INDEX(Scenarios!$D:$D, MATCH($A36, Scenarios!$A:$A, 0))=0, IF(LEFT(INDEX(Scenarios!$O:$O, MATCH($A36, Scenarios!$A:$A, 0)),4)="Arts", Parameters_Public!$C$28, IF(LEFT(INDEX(Scenarios!$O:$O, MATCH($A36, Scenarios!$A:$A, 0)),5)="Innov", Parameters_Public!$C$29, 0)), 0), 0) -> 0 | F36: =IF($B36="FY2026", IF(INDEX(Scenarios!$E:$E, MATCH($A36, Scenarios!$A:$A, 0))=0, IF(LEFT(INDEX(Scenarios!$P:$P, MATCH($A36, Scenarios!$A:$A, 0)),4)="Arts", Parameters_Public!$C$28, IF(LEFT(INDEX(Scenarios!$P:$P, MATCH($A36, Scenarios!$A:$A, 0)),5)="Innov", Parameters_Public!$C$29, 0)), 0), 0) -> 0 | G36: =IF($B36="FY2026", INDEX(Receiving_Capacity!$L:$L, MATCH($A36, Receiving_Capacity!$A:$A, 0)), 0) -> 0 | H36: =SUM(D36:G36) -> 0
A37: =Scenarios!$A$8 -> A_Repurpose_Both_lease | B37: FY2029 | C37: =INDEX(Scenarios!$D:$D, MATCH($A37, Scenarios!$A:$A, 0)) + INDEX(Scenarios!$E:$E, MATCH($A37, Scenarios!$A:$A, 0)) -> 2 | D37: =IF($B37="FY2026",$C37*IF(INDEX(Scenarios!$N:$N, MATCH($A37, Scenarios!$A:$A, 0))="lease", Parameters_Public!$C$31, Parameters_Public!$C$27),0) -> 0 | E37: =IF($B37="FY2026", IF(INDEX(Scenarios!$D:$D, MATCH($A37, Scenarios!$A:$A, 0))=0, IF(LEFT(INDEX(Scenarios!$O:$O, MATCH($A37, Scenarios!$A:$A, 0)),4)="Arts", Parameters_Public!$C$28, IF(LEFT(INDEX(Scenarios!$O:$O, MATCH($A37, Scenarios!$A:$A, 0)),5)="Innov", Parameters_Public!$C$29, 0)), 0), 0) -> 0 | F37: =IF($B37="FY2026", IF(INDEX(Scenarios!$E:$E, MATCH($A37, Scenarios!$A:$A, 0))=0, IF(LEFT(INDEX(Scenarios!$P:$P, MATCH($A37, Scenarios!$A:$A, 0)),4)="Arts", Parameters_Public!$C$28, IF(LEFT(INDEX(Scenarios!$P:$P, MATCH($A37, Scenarios!$A:$A, 0)),5)="Innov", Parameters_Public!$C$29, 0)), 0), 0) -> 0 | G37: =IF($B37="FY2026", INDEX(Receiving_Capacity!$L:$L, MATCH($A37, Receiving_Capacity!$A:$A, 0)), 0) -> 0 | H37: =SUM(D37:G37) -> 0
A38: =Scenarios!$A$8 -> A_Repurpose_Both_lease | B38: FY2030 | C38: =INDEX(Scenarios!$D:$D, MATCH($A38, Scenarios!$A:$A, 0)) + INDEX(Scenarios!$E:$E, MATCH($A38, Scenarios!$A:$A, 0)) -> 2 | D38: =IF($B38="FY2026",$C38*IF(INDEX(Scenarios!$N:$N, MATCH($A38, Scenarios!$A:$A, 0))="lease", Parameters_Public!$C$31, Parameters_Public!$C$27),0) -> 0 | E38: =IF($B38="FY2026", IF(INDEX(Scenarios!$D:$D, MATCH($A38, Scenarios!$A:$A, 0))=0, IF(LEFT(INDEX(Scenarios!$O:$O, MATCH($A38, Scenarios!$A:$A, 0)),4)="Arts", Parameters_Public!$C$28, IF(LEFT(INDEX(Scenarios!$O:$O, MATCH($A38, Scenarios!$A:$A, 0)),5)="Innov", Parameters_Public!$C$29, 0)), 0), 0) -> 0 | F38: =IF($B38="FY2026", IF(INDEX(Scenarios!$E:$E, MATCH($A38, Scenarios!$A:$A, 0))=0, IF(LEFT(INDEX(Scenarios!$P:$P, MATCH($A38, Scenarios!$A:$A, 0)),4)="Arts", Parameters_Public!$C$28, IF(LEFT(INDEX(Scenarios!$P:$P, MATCH($A38, Scenarios!$A:$A, 0)),5)="Innov", Parameters_Public!$C$29, 0)), 0), 0) -> 0 | G38: =IF($B38="FY2026", INDEX(Receiving_Capacity!$L:$L, MATCH($A38, Receiving_Capacity!$A:$A, 0)), 0) -> 0 | H38: =SUM(D38:G38) -> 0
A39: =Scenarios!$A$9 -> A_Repurpose_Both_ops | B39: FY2026 | C39: =INDEX(Scenarios!$D:$D, MATCH($A39, Scenarios!$A:$A, 0)) + INDEX(Scenarios!$E:$E, MATCH($A39, Scenarios!$A:$A, 0)) -> 2 | D39: =IF($B39="FY2026",$C39*IF(INDEX(Scenarios!$N:$N, MATCH($A39, Scenarios!$A:$A, 0))="lease", Parameters_Public!$C$31, Parameters_Public!$C$27),0) -> 2400000 | E39: =IF($B39="FY2026", IF(INDEX(Scenarios!$D:$D, MATCH($A39, Scenarios!$A:$A, 0))=0, IF(LEFT(INDEX(Scenarios!$O:$O, MATCH($A39, Scenarios!$A:$A, 0)),4)="Arts", Parameters_Public!$C$28, IF(LEFT(INDEX(Scenarios!$O:$O, MATCH($A39, Scenarios!$A:$A, 0)),5)="Innov", Parameters_Public!$C$29, 0)), 0), 0) -> 0 | F39: =IF($B39="FY2026", IF(INDEX(Scenarios!$E:$E, MATCH($A39, Scenarios!$A:$A, 0))=0, IF(LEFT(INDEX(Scenarios!$P:$P, MATCH($A39, Scenarios!$A:$A, 0)),4)="Arts", Parameters_Public!$C$28, IF(LEFT(INDEX(Scenarios!$P:$P, MATCH($A39, Scenarios!$A:$A, 0)),5)="Innov", Parameters_Public!$C$29, 0)), 0), 0) -> 0 | G39: =IF($B39="FY2026", INDEX(Receiving_Capacity!$L:$L, MATCH($A39, Receiving_Capacity!$A:$A, 0)), 0) -> 714480 | H39: =SUM(D39:G39) -> 3114480
A40: =Scenarios!$A$9 -> A_Repurpose_Both_ops | B40: FY2027 | C40: =INDEX(Scenarios!$D:$D, MATCH($A40, Scenarios!$A:$A, 0)) + INDEX(Scenarios!$E:$E, MATCH($A40, Scenarios!$A:$A, 0)) -> 2 | D40: =IF($B40="FY2026",$C40*IF(INDEX(Scenarios!$N:$N, MATCH($A40, Scenarios!$A:$A, 0))="lease", Parameters_Public!$C$31, Parameters_Public!$C$27),0) -> 0 | E40: =IF($B40="FY2026", IF(INDEX(Scenarios!$D:$D, MATCH($A40, Scenarios!$A:$A, 0))=0, IF(LEFT(INDEX(Scenarios!$O:$O, MATCH($A40, Scenarios!$A:$A, 0)),4)="Arts", Parameters_Public!$C$28, IF(LEFT(INDEX(Scenarios!$O:$O, MATCH($A40, Scenarios!$A:$A, 0)),5)="Innov", Parameters_Public!$C$29, 0)), 0), 0) -> 0 | F40: =IF($B40="FY2026", IF(INDEX(Scenarios!$E:$E, MATCH($A40, Scenarios!$A:$A, 0))=0, IF(LEFT(INDEX(Scenarios!$P:$P, MATCH($A40, Scenarios!$A:$A, 0)),4)="Arts", Parameters_Public!$C$28, IF(LEFT(INDEX(Scenarios!$P:$P, MATCH($A40, Scenarios!$A:$A, 0)),5)="Innov", Parameters_Public!$C$29, 0)), 0), 0) -> 0 | G40: =IF($B40="FY2026", INDEX(Receiving_Capacity!$L:$L, MATCH($A40, Receiving_Capacity!$A:$A, 0)), 0) -> 0 | H40: =SUM(D40:G40) -> 0
A41: =Scenarios!$A$9 -> A_Repurpose_Both_ops | B41: FY2028 | C41: =INDEX(Scenarios!$D:$D, MATCH($A41, Scenarios!$A:$A, 0)) + INDEX(Scenarios!$E:$E, MATCH($A41, Scenarios!$A:$A, 0)) -> 2 | D41: =IF($B41="FY2026",$C41*IF(INDEX(Scenarios!$N:$N, MATCH($A41, Scenarios!$A:$A, 0))="lease", Parameters_Public!$C$31, Parameters_Public!$C$27),0) -> 0 | E41: =IF($B41="FY2026", IF(INDEX(Scenarios!$D:$D, MATCH($A41, Scenarios!$A:$A, 0))=0, IF(LEFT(INDEX(Scenarios!$O:$O, MATCH($A41, Scenarios!$A:$A, 0)),4)="Arts", Parameters_Public!$C$28, IF(LEFT(INDEX(Scenarios!$O:$O, MATCH($A41, Scenarios!$A:$A, 0)),5)="Innov", Parameters_Public!$C$29, 0)), 0), 0) -> 0 | F41: =IF($B41="FY2026", IF(INDEX(Scenarios!$E:$E, MATCH($A41, Scenarios!$A:$A, 0))=0, IF(LEFT(INDEX(Scenarios!$P:$P, MATCH($A41, Scenarios!$A:$A, 0)),4)="Arts", Parameters_Public!$C$28, IF(LEFT(INDEX(Scenarios!$P:$P, MATCH($A41, Scenarios!$A:$A, 0)),5)="Innov", Parameters_Public!$C$29, 0)), 0), 0) -> 0 | G41: =IF($B41="FY2026", INDEX(Receiving_Capacity!$L:$L, MATCH($A41, Receiving_Capacity!$A:$A, 0)), 0) -> 0 | H41: =SUM(D41:G41) -> 0
...

Sheet Receiving_Capacity
A1: Receiving Capacity & Feasibility — FY2026 absorption of retained students (by grade band)
A3: ScenarioKey | B3: CloseEcho | C3: ClosePima | D3: Req_K5 | E3: Req_6_8 | G3: Spare_K5 | H3: Spare_6_8 | J3: Short_K5 | K3: Short_6_8 | L3: Portables$
A4: =Scenarios!$A$2 -> D_CUSTOM1 | B4: =INDEX(Scenarios!$D:$D, MATCH($A4, Scenarios!$A:$A, 0)) -> 0 | C4: =INDEX(Scenarios!$E:$E, MATCH($A4, Scenarios!$A:$A, 0)) -> 0 | D4: =INDEX(Scenarios!$D:$D, MATCH($A4, Scenarios!$A:$A, 0))*Parameters_Public!$C$22*Parameters_Public!$C$10*Parameters_Public!$C$36 + INDEX(Scenarios!$E:$E, MATCH($A4, Scenarios!$A:$A, 0))*Parameters_Public!$C$23*Parameters_Public!$C$11*Parameters_Public!$C$38 -> 0 | E4: =INDEX(Scenarios!$D:$D, MATCH($A4, Scenarios!$A:$A, 0))*Parameters_Public!$C$22*Parameters_Public!$C$10*Parameters_Public!$C$37 + INDEX(Scenarios!$E:$E, MATCH($A4, Scenarios!$A:$A, 0))*Parameters_Public!$C$23*Parameters_Public!$C$11*Parameters_Public!$C$39 -> 0 | G4: =Parameters_Public!$C$33 -> 300 | H4: =Parameters_Public!$C$34 -> 150 | J4: =MAX(0, D4-G4) -> 0 | K4: =MAX(0, E4-H4) -> 0 | L4: =(J4+K4)*Parameters_Public!$C$32 -> 0
A5: =Scenarios!$A$3 -> E_StatusQuo_Targets | B5: =INDEX(Scenarios!$D:$D, MATCH($A5, Scenarios!$A:$A, 0)) -> 0 | C5: =INDEX(Scenarios!$E:$E, MATCH($A5, Scenarios!$A:$A, 0)) -> 0 | D5: =INDEX(Scenarios!$D:$D, MATCH($A5, Scenarios!$A:$A, 0))*Parameters_Public!$C$22*Parameters_Public!$C$10*Parameters_Public!$C$36 + INDEX(Scenarios!$E:$E, MATCH($A5, Scenarios!$A:$A, 0))*Parameters_Public!$C$23*Parameters_Public!$C$11*Parameters_Public!$C$38 -> 0 | E5: =INDEX(Scenarios!$D:$D, MATCH($A5, Scenarios!$A:$A, 0))*Parameters_Public!$C$22*Parameters_Public!$C$10*Parameters_Public!$C$37 + INDEX(Scenarios!$E:$E, MATCH($A5, Scenarios!$A:$A, 0))*Parameters_Public!$C$23*Parameters_Public!$C$11*Parameters_Public!$C$39 -> 0 | G5: =Parameters_Public!$C$33 -> 300 | H5: =Parameters_Public!$C$34 -> 150 | J5: =MAX(0, D5-G5) -> 0 | K5: =MAX(0, E5-H5) -> 0 | L5: =(J5+K5)*Parameters_Public!$C$32 -> 0
A6: =Scenarios!$A$4 -> F_CoLocation_Echo_Targets | B6: =INDEX(Scenarios!$D:$D, MATCH($A6, Scenarios!$A:$A, 0)) -> 0 | C6: =INDEX(Scenarios!$E:$E, MATCH($A6, Scenarios!$A:$A, 0)) -> 0 | D6: =INDEX(Scenarios!$D:$D, MATCH($A6, Scenarios!$A:$A, 0))*Parameters_Public!$C$22*Parameters_Public!$C$10*Parameters_Public!$C$36 + INDEX(Scenarios!$E:$E, MATCH($A6, Scenarios!$A:$A, 0))*Parameters_Public!$C$23*Parameters_Public!$C$11*Parameters_Public!$C$38 -> 0 | E6: =INDEX(Scenarios!$D:$D, MATCH($A6, Scenarios!$A:$A, 0))*Parameters_Public!$C$22*Parameters_Public!$C$10*Parameters_Public!$C$37 + INDEX(Scenarios!$E:$E, MATCH($A6, Scenarios!$A:$A, 0))*Parameters_Public!$C$23*Parameters_Public!$C$11*Parameters_Public!$C$39 -> 0 | G6: =Parameters_Public!$C$33 -> 300 | H6: =Parameters_Public!$C$34 -> 150 | J6: =MAX(0, D6-G6) -> 0 | K6: =MAX(0, E6-H6) -> 0 | L6: =(J6+K6)*Parameters_Public!$C$32 -> 0
A7: =Scenarios!$A$5 -> D_Grow_Both_Targets | B7: =INDEX(Scenarios!$D:$D, MATCH($A7, Scenarios!$A:$A, 0)) -> 0 | C7: =INDEX(Scenarios!$E:$E, MATCH($A7, Scenarios!$A:$A, 0)) -> 0 | D7: =INDEX(Scenarios!$D:$D, MATCH($A7, Scenarios!$A:$A, 0))*Parameters_Public!$C$22*Parameters_Public!$C$10*Parameters_Public!$C$36 + INDEX(Scenarios!$E:$E, MATCH($A7, Scenarios!$A:$A, 0))*Parameters_Public!$C$23*Parameters_Public!$C$11*Parameters_Public!$C$38 -> 0 | E7: =INDEX(Scenarios!$D:$D, MATCH($A7, Scenarios!$A:$A, 0))*Parameters_Public!$C$22*Parameters_Public!$C$10*Parameters_Public!$C$37 + INDEX(Scenarios!$E:$E, MATCH($A7, Scenarios!$A:$A, 0))*Parameters_Public!$C$23*Parameters_Public!$C$11*Parameters_Public!$C$39 -> 0 | G7: =Parameters_Public!$C$33 -> 300 | H7: =Parameters_Public!$C$34 -> 150 | J7: =MAX(0, D7-G7) -> 0 | K7: =MAX(0, E7-H7) -> 0 | L7: =(J7+K7)*Parameters_Public!$C$32 -> 0
A8: =Scenarios!$A$6 -> D_CUSTOM2 | B8: =INDEX(Scenarios!$D:$D, MATCH($A8, Scenarios!$A:$A, 0)) -> 0 | C8: =INDEX(Scenarios!$E:$E, MATCH($A8, Scenarios!$A:$A, 0)) -> 0 | D8: =INDEX(Scenarios!$D:$D, MATCH($A8, Scenarios!$A:$A, 0))*Parameters_Public!$C$22*Parameters_Public!$C$10*Parameters_Public!$C$36 + INDEX(Scenarios!$E:$E, MATCH($A8, Scenarios!$A:$A, 0))*Parameters_Public!$C$23*Parameters_Public!$C$11*Parameters_Public!$C$38 -> 0 | E8: =INDEX(Scenarios!$D:$D, MATCH($A8, Scenarios!$A:$A, 0))*Parameters_Public!$C$22*Parameters_Public!$C$10*Parameters_Public!$C$37 + INDEX(Scenarios!$E:$E, MATCH($A8, Scenarios!$A:$A, 0))*Parameters_Public!$C$23*Parameters_Public!$C$11*Parameters_Public!$C$39 -> 0 | G8: =Parameters_Public!$C$33 -> 300 | H8: =Parameters_Public!$C$34 -> 150 | J8: =MAX(0, D8-G8) -> 0 | K8: =MAX(0, E8-H8) -> 0 | L8: =(J8+K8)*Parameters_Public!$C$32 -> 0
A9: =Scenarios!$A$7 -> G_EchoGHubRamp_PimaTargets | B9: =INDEX(Scenarios!$D:$D, MATCH($A9, Scenarios!$A:$A, 0)) -> 0 | C9: =INDEX(Scenarios!$E:$E, MATCH($A9, Scenarios!$A:$A, 0)) -> 0 | D9: =INDEX(Scenarios!$D:$D, MATCH($A9, Scenarios!$A:$A, 0))*Parameters_Public!$C$22*Parameters_Public!$C$10*Parameters_Public!$C$36 + INDEX(Scenarios!$E:$E, MATCH($A9, Scenarios!$A:$A, 0))*Parameters_Public!$C$23*Parameters_Public!$C$11*Parameters_Public!$C$38 -> 0 | E9: =INDEX(Scenarios!$D:$D, MATCH($A9, Scenarios!$A:$A, 0))*Parameters_Public!$C$22*Parameters_Public!$C$10*Parameters_Public!$C$37 + INDEX(Scenarios!$E:$E, MATCH($A9, Scenarios!$A:$A, 0))*Parameters_Public!$C$23*Parameters_Public!$C$11*Parameters_Public!$C$39 -> 0 | G9: =Parameters_Public!$C$33 -> 300 | H9: =Parameters_Public!$C$34 -> 150 | J9: =MAX(0, D9-G9) -> 0 | K9: =MAX(0, E9-H9) -> 0 | L9: =(J9+K9)*Parameters_Public!$C$32 -> 0
A10: =Scenarios!$A$8 -> A_Repurpose_Both_lease | B10: =INDEX(Scenarios!$D:$D, MATCH($A10, Scenarios!$A:$A, 0)) -> 1 | C10: =INDEX(Scenarios!$E:$E, MATCH($A10, Scenarios!$A:$A, 0)) -> 1 | D10: =INDEX(Scenarios!$D:$D, MATCH($A10, Scenarios!$A:$A, 0))*Parameters_Public!$C$22*Parameters_Public!$C$10*Parameters_Public!$C$36 + INDEX(Scenarios!$E:$E, MATCH($A10, Scenarios!$A:$A, 0))*Parameters_Public!$C$23*Parameters_Public!$C$11*Parameters_Public!$C$38 -> 359.54 | E10: =INDEX(Scenarios!$D:$D, MATCH($A10, Scenarios!$A:$A, 0))*Parameters_Public!$C$22*Parameters_Public!$C$10*Parameters_Public!$C$37 + INDEX(Scenarios!$E:$E, MATCH($A10, Scenarios!$A:$A, 0))*Parameters_Public!$C$23*Parameters_Public!$C$11*Parameters_Public!$C$39 -> 46.26 | G10: =Parameters_Public!$C$33 -> 300 | H10: =Parameters_Public!$C$34 -> 150 | J10: =MAX(0, D10-G10) -> 59.54 | K10: =MAX(0, E10-H10) -> 0 | L10: =(J10+K10)*Parameters_Public!$C$32 -> 714480
A11: =Scenarios!$A$9 -> A_Repurpose_Both_ops | B11: =INDEX(Scenarios!$D:$D, MATCH($A11, Scenarios!$A:$A, 0)) -> 1 | C11: =INDEX(Scenarios!$E:$E, MATCH($A11, Scenarios!$A:$A, 0)) -> 1 | D11: =INDEX(Scenarios!$D:$D, MATCH($A11, Scenarios!$A:$A, 0))*Parameters_Public!$C$22*Parameters_Public!$C$10*Parameters_Public!$C$36 + INDEX(Scenarios!$E:$E, MATCH($A11, Scenarios!$A:$A, 0))*Parameters_Public!$C$23*Parameters_Public!$C$11*Parameters_Public!$C$38 -> 359.54 | E11: =INDEX(Scenarios!$D:$D, MATCH($A11, Scenarios!$A:$A, 0))*Parameters_Public!$C$22*Parameters_Public!$C$10*Parameters_Public!$C$37 + INDEX(Scenarios!$E:$E, MATCH($A11, Scenarios!$A:$A, 0))*Parameters_Public!$C$23*Parameters_Public!$C$11*Parameters_Public!$C$39 -> 46.26 | G11: =Parameters_Public!$C$33 -> 300 | H11: =Parameters_Public!$C$34 -> 150 | J11: =MAX(0, D11-G11) -> 59.54 | K11: =MAX(0, E11-H11) -> 0 | L11: =(J11+K11)*Parameters_Public!$C$32 -> 714480
A12: =Scenarios!$A$10 -> B_Repurpose_Echo_lease_PimaTargets | B12: =INDEX(Scenarios!$D:$D, MATCH($A12, Scenarios!$A:$A, 0)) -> 1 | C12: =INDEX(Scenarios!$E:$E, MATCH($A12, Scenarios!$A:$A, 0)) -> 0 | D12: =INDEX(Scenarios!$D:$D, MATCH($A12, Scenarios!$A:$A, 0))*Parameters_Public!$C$22*Parameters_Public!$C$10*Parameters_Public!$C$36 + INDEX(Scenarios!$E:$E, MATCH($A12, Scenarios!$A:$A, 0))*Parameters_Public!$C$23*Parameters_Public!$C$11*Parameters_Public!$C$38 -> 107.94 | E12: =INDEX(Scenarios!$D:$D, MATCH($A12, Scenarios!$A:$A, 0))*Parameters_Public!$C$22*Parameters_Public!$C$10*Parameters_Public!$C$37 + INDEX(Scenarios!$E:$E, MATCH($A12, Scenarios!$A:$A, 0))*Parameters_Public!$C$23*Parameters_Public!$C$11*Parameters_Public!$C$39 -> 46.26 | G12: =Parameters_Public!$C$33 -> 300 | H12: =Parameters_Public!$C$34 -> 150 | J12: =MAX(0, D12-G12) -> 0 | K12: =MAX(0, E12-H12) -> 0 | L12: =(J12+K12)*Parameters_Public!$C$32 -> 0
A13: =Scenarios!$A$11 -> B_Repurpose_Echo_ops_PimaTargets | B13: =INDEX(Scenarios!$D:$D, MATCH($A13, Scenarios!$A:$A, 0)) -> 1 | C13: =INDEX(Scenarios!$E:$E, MATCH($A13, Scenarios!$A:$A, 0)) -> 0 | D13: =INDEX(Scenarios!$D:$D, MATCH($A13, Scenarios!$A:$A, 0))*Parameters_Public!$C$22*Parameters_Public!$C$10*Parameters_Public!$C$36 + INDEX(Scenarios!$E:$E, MATCH($A13, Scenarios!$A:$A, 0))*Parameters_Public!$C$23*Parameters_Public!$C$11*Parameters_Public!$C$38 -> 107.94 | E13: =INDEX(Scenarios!$D:$D, MATCH($A13, Scenarios!$A:$A, 0))*Parameters_Public!$C$22*Parameters_Public!$C$10*Parameters_Public!$C$37 + INDEX(Scenarios!$E:$E, MATCH($A13, Scenarios!$A:$A, 0))*Parameters_Public!$C$23*Parameters_Public!$C$11*Parameters_Public!$C$39 -> 46.26 | G13: =Parameters_Public!$C$33 -> 300 | H13: =Parameters_Public!$C$34 -> 150 | J13: =MAX(0, D13-G13) -> 0 | K13: =MAX(0, E13-H13) -> 0 | L13: =(J13+K13)*Parameters_Public!$C$32 -> 0
A14: =Scenarios!$A$12 -> C_Repurpose_Pima_lease_EchoGHub_EchoTargets | B14: =INDEX(Scenarios!$D:$D, MATCH($A14, Scenarios!$A:$A, 0)) -> 0 | C14: =INDEX(Scenarios!$E:$E, MATCH($A14, Scenarios!$A:$A, 0)) -> 1 | D14: =INDEX(Scenarios!$D:$D, MATCH($A14, Scenarios!$A:$A, 0))*Parameters_Public!$C$22*Parameters_Public!$C$10*Parameters_Public!$C$36 + INDEX(Scenarios!$E:$E, MATCH($A14, Scenarios!$A:$A, 0))*Parameters_Public!$C$23*Parameters_Public!$C$11*Parameters_Public!$C$38 -> 251.6 | E14: =INDEX(Scenarios!$D:$D, MATCH($A14, Scenarios!$A:$A, 0))*Parameters_Public!$C$22*Parameters_Public!$C$10*Parameters_Public!$C$37 + INDEX(Scenarios!$E:$E, MATCH($A14, Scenarios!$A:$A, 0))*Parameters_Public!$C$23*Parameters_Public!$C$11*Parameters_Public!$C$39 -> 0 | G14: =Parameters_Public!$C$33 -> 300 | H14: =Parameters_Public!$C$34 -> 150 | J14: =MAX(0, D14-G14) -> 0 | K14: =MAX(0, E14-H14) -> 0 | L14: =(J14+K14)*Parameters_Public!$C$32 -> 0
A15: =Scenarios!$A$13 -> C_Repurpose_Pima_ops_EchoGHub_EchoTargets | B15: =INDEX(Scenarios!$D:$D, MATCH($A15, Scenarios!$A:$A, 0)) -> 0 | C15: =INDEX(Scenarios!$E:$E, MATCH($A15, Scenarios!$A:$A, 0)) -> 1 | D15: =INDEX(Scenarios!$D:$D, MATCH($A15, Scenarios!$A:$A, 0))*Parameters_Public!$C$22*Parameters_Public!$C$10*Parameters_Public!$C$36 + INDEX(Scenarios!$E:$E, MATCH($A15, Scenarios!$A:$A, 0))*Parameters_Public!$C$23*Parameters_Public!$C$11*Parameters_Public!$C$38 -> 251.6 | E15: =INDEX(Scenarios!$D:$D, MATCH($A15, Scenarios!$A:$A, 0))*Parameters_Public!$C$22*Parameters_Public!$C$10*Parameters_Public!$C$37 + INDEX(Scenarios!$E:$E, MATCH($A15, Scenarios!$A:$A, 0))*Parameters_Public!$C$23*Parameters_Public!$C$11*Parameters_Public!$C$39 -> 0 | G15: =Parameters_Public!$C$33 -> 300 | H15: =Parameters_Public!$C$34 -> 150 | J15: =MAX(0, D15-G15) -> 0 | K15: =MAX(0, E15-H15) -> 0 | L15: =(J15+K15)*Parameters_Public!$C$32 -> 0
A16: =Scenarios!$A$14 -> H_StatusQuo_Decline | B16: =INDEX(Scenarios!$D:$D, MATCH($A16, Scenarios!$A:$A, 0)) -> 0 | C16: =INDEX(Scenarios!$E:$E, MATCH($A16, Scenarios!$A:$A, 0)) -> 0 | D16: =INDEX(Scenarios!$D:$D, MATCH($A16, Scenarios!$A:$A, 0))*Parameters_Public!$C$22*Parameters_Public!$C$10*Parameters_Public!$C$36 + INDEX(Scenarios!$E:$E, MATCH($A16, Scenarios!$A:$A, 0))*Parameters_Public!$C$23*Parameters_Public!$C$11*Parameters_Public!$C$38 -> 0 | E16: =INDEX(Scenarios!$D:$D, MATCH($A16, Scenarios!$A:$A, 0))*Parameters_Public!$C$22*Parameters_Public!$C$10*Parameters_Public!$C$37 + INDEX(Scenarios!$E:$E, MATCH($A16, Scenarios!$A:$A, 0))*Parameters_Public!$C$23*Parameters_Public!$C$11*Parameters_Public!$C$39 -> 0 | G16: =Parameters_Public!$C$33 -> 300 | H16: =Parameters_Public!$C$34 -> 150 | J16: =MAX(0, D16-G16) -> 0 | K16: =MAX(0, E16-H16) -> 0 | L16: =(J16+K16)*Parameters_Public!$C$32 -> 0
D18: =INDEX(Scenarios!$D:$D, MATCH($A4, Scenarios!$A:$A, 0))*Parameters_Public!$C$22*Echo_ADM0*Parameters_Public!$C$36 + INDEX(Scenarios!$E:$E, MATCH($A4, Scenarios!$A:$A, 0))*Parameters_Public!$C$23*Pima_ADM0*Parameters_Public!$C$38 -> 0

Sheet Control_Center
A1: Control center - yellow shaded fields are editable inputs
A3: Foundational inputs
B5: Parameter | C5: Value | H5: Notes
B6: MO inflation | C6: 0.025 | H6: Annual inflation factor.
B7: Base MO per ADM (FY25) | C7: 9936 | H7: "MO" = xx. Working base for FY25. Calculated from reported budget data and enrollment estimates - as relates to Echo Canyon and Pima only.
B8: Fixed share of MO | C8: 0.46 | H8: Share of MO treated as semi‑fixed (plant/insurance).
B9: Base State Aid per ADM (FY26) | C9: 5013 | H9: Editable; ADE base aid.
B10: Ops savings (keep‑open) | C10: 0.007 | H10: Light discipline if sites remain open (not used here).
B11: Extra savings (Co‑location) | C11: 0.015 | H11: Incremental savings for co‑location (not used here).
B12: Echo base ADM | C12: 257 | H12: "ADM" = average daily membership; roughly equivalent to enrollment. Approximate current Echo enrollment
B13: Pima base ADM | C13: 296 | H13: Approximate current Pima enrollment
B14: Total base ADM | C14: =C12+C13 -> 553 | H14: Echo base ADM + Pima base ADM
B15: Repurpose TI per closed site (FY26) | C15: 1200000 | H15: Research suggests a xx
B16: Retention r (in case of repurpose) | C16: 0.75 | H16: Research suggests a range in the 0.5-0.8 range. Since Echo is a choice school with high % of families from out of district, reality might be lower?
B17: MarginalFactor_for_Overlay | C17: =Parameters_Public!$C41 -> 0.4 | H17: Assuming there is a reduced marginal cost of adding new (growth) students, especially when the schools (Echo and Pima) have capacity. In reality this is probably a complicated step function, but we can approximate.
A19: Repurpose trajectory assumptions
B21: Year | C21: h | D21: f_lease | E21: f_ops
