Workbook

Sheet BaselineCalc
A1: Parameter | B1: Value | C1: Notes
A2: MO inflation | B2: 0.025 | C2: Annual inflation factor.
A3: Base MO per ADM (FY25) | B3: 9936 | C3: Working base for FY25.
A4: Fixed share of MO | B4: 0.3 | C4: Share treated as semi‑fixed (plant/insurance).
A5: Ops savings (keep‑open) | B5: 0.007 | C5: Light discipline if sites remain open (not used here).
A6: Extra savings (Co‑location) | B6: 0.015 | C6: Incremental savings for co‑location (not used here).
A7: Echo base ADM | B7: 257
A8: Pima base ADM | B8: 296
A9: Total base ADM | B9: =B7+B8 | C9: Echo base ADM + Pima base ADM
A12: Helper / Derivation | B12: FY26 | C12: FY27 | D12: FY28 | E12: FY29 | F12: FY30 | G12: Notes
A13: Base total MO (FY25) | B13: =B9*B3 | C13: =C14/$B$4 | D13: =D14/$B$4 | E13: =E14/$B$4 | F13: =F14/$B$4 | G13: Total ADM × Base MO/ADM | K13: B13 = B9*B3 (Base total MO, FY25)
A14: Fixed MO (FY25) | B14: =B13*B4 | C14: =B17 | D14: =C17 | E14: =D17 | F14: =E17 | G14: Fixed = Base total × Fixed share | K14: B14 = B13*B4 (Fixed MO, FY25)
A15: Var per student (FY25) | B15: =(B13-B14)/B9 | C15: =B18 | D15: =C18 | E15: =D18 | F15: =E18 | G15: Variable = (Base total − Fixed)/Total ADM | K15: B15 = (B13–B14)/B9 (Variable $/student, FY25)
A17: Fixed total ($) | B17: =$B$14*(1+$B$2)^1 | C17: =$B$14*(1+$B$2)^2 | D17: =$B$14*(1+$B$2)^3 | E17: =$B$14*(1+$B$2)^4 | F17: =$B$14*(1+$B$2)^5
A18: Var unit ($/student) | B18: =$B$15*(1+$B$2)^1 | C18: =$B$15*(1+$B$2)^2 | D18: =$B$15*(1+$B$2)^3 | E18: =$B$15*(1+$B$2)^4 | F18: =$B$15*(1+$B$2)^5
A19: Echo fixed ($) | B19: =B17*($B$7/$B$9) | C19: =C17*($B$7/$B$9) | D19: =D17*($B$7/$B$9) | E19: =E17*($B$7/$B$9) | F19: =F17*($B$7/$B$9)
A20: Pima fixed ($) | B20: =B17*($B$8/$B$9) | C20: =C17*($B$8/$B$9) | D20: =D17*($B$8/$B$9) | E20: =E17*($B$8/$B$9) | F20: =F17*($B$8/$B$9)
A22: Notes
A23: All formulas are same‑sheet and reference the Parameter cells above.

Sheet YearMap
A1: Year | B1: VarUnit$ | C1: EchoFixed$ | D1: PimaFixed$ | E1: h | F1: f_lease | G1: f_ops
A2: FY2026 | B2: =BaselineCalc!B18 | C2: =BaselineCalc!B19 | D2: =BaselineCalc!B20 | E2: 1000 | F2: 0.4 | G2: 0.4
A3: FY2027 | B3: =BaselineCalc!C18 | C3: =BaselineCalc!C19 | D3: =BaselineCalc!C20 | E3: 800 | F3: 0.3 | G3: 0.35
A4: FY2028 | B4: =BaselineCalc!D18 | C4: =BaselineCalc!D19 | D4: =BaselineCalc!D20 | E4: 600 | F4: 0.2 | G4: 0.3
A5: FY2029 | B5: =BaselineCalc!E18 | C5: =BaselineCalc!E19 | D5: =BaselineCalc!E20 | E5: 400 | F5: 0.1 | G5: 0.25
A6: FY2030 | B6: =BaselineCalc!F18 | C6: =BaselineCalc!F19 | D6: =BaselineCalc!F20 | E6: 300 | F6: 0 | G6: 0.2

Sheet Scenarios
A1: ScenarioKey | B1: Label | C1: Overlay | D1: CloseEcho | E1: ClosePima | F1: EchoShareDist | G1: ExtraSave | H1: Notes
A2: D_Grow_Both_0 | B2: D. Grow Both (Overlay 0) | C2: 0 | D2: 0 | E2: 0 | F2: 0.5 | G2: 0 | H2: Baseline + outreach; no closures
A3: E_StatusQuo_Targets_0 | B3: E. Status‑Quo + Targets (0) | C3: 0 | D3: 0 | E3: 0 | F3: 0.5 | G3: 0 | H3: Baseline + targets; no closures
A4: F_CoLocation_Echo_0 | B4: F. Co‑Location @ Echo (0) | C4: 0 | D4: 0 | E4: 0 | F4: 0.7 | G4: 0.015 | H4: Shared‑use efficiencies later (no closure)
A6: ScenarioKey | B6: Year | C6: Echo_ADM | D6: Pima_ADM | E6: Total_ADM | F6: VarUnit$ | G6: EchoFixed$ | H6: PimaFixed$ | I6: Key
A7: =A2 | B7: FY2026 | C7: =IF(D2=1,0, BaselineCalc!$B$7 + ROUND(C2*F2,0)) | D7: =IF(E2=1,0, BaselineCalc!$B$8 + C2 - ROUND(C2*F2,0)) | E7: =C7+D7 | F7: =VLOOKUP(B7,YearMap!$A$2:$B$6,2,FALSE) | G7: =VLOOKUP(B7,YearMap!$A$2:$C$6,3,FALSE) | H7: =VLOOKUP(B7,YearMap!$A$2:$D$6,4,FALSE) | I7: =A7&"|"&B7
A8: =A2 | B8: FY2027 | C8: =IF(D2=1,0, BaselineCalc!$B$7 + ROUND(C2*F2,0)) | D8: =IF(E2=1,0, BaselineCalc!$B$8 + C2 - ROUND(C2*F2,0)) | E8: =C8+D8 | F8: =VLOOKUP(B8,YearMap!$A$2:$B$6,2,FALSE) | G8: =VLOOKUP(B8,YearMap!$A$2:$C$6,3,FALSE) | H8: =VLOOKUP(B8,YearMap!$A$2:$D$6,4,FALSE) | I8: =A8&"|"&B8
A9: =A2 | B9: FY2028 | C9: =IF(D2=1,0, BaselineCalc!$B$7 + ROUND(C2*F2,0)) | D9: =IF(E2=1,0, BaselineCalc!$B$8 + C2 - ROUND(C2*F2,0)) | E9: =C9+D9 | F9: =VLOOKUP(B9,YearMap!$A$2:$B$6,2,FALSE) | G9: =VLOOKUP(B9,YearMap!$A$2:$C$6,3,FALSE) | H9: =VLOOKUP(B9,YearMap!$A$2:$D$6,4,FALSE) | I9: =A9&"|"&B9
A10: =A2 | B10: FY2029 | C10: =IF(D2=1,0, BaselineCalc!$B$7 + ROUND(C2*F2,0)) | D10: =IF(E2=1,0, BaselineCalc!$B$8 + C2 - ROUND(C2*F2,0)) | E10: =C10+D10 | F10: =VLOOKUP(B10,YearMap!$A$2:$B$6,2,FALSE) | G10: =VLOOKUP(B10,YearMap!$A$2:$C$6,3,FALSE) | H10: =VLOOKUP(B10,YearMap!$A$2:$D$6,4,FALSE) | I10: =A10&"|"&B10
A11: =A2 | B11: FY2030 | C11: =IF(D2=1,0, BaselineCalc!$B$7 + ROUND(C2*F2,0)) | D11: =IF(E2=1,0, BaselineCalc!$B$8 + C2 - ROUND(C2*F2,0)) | E11: =C11+D11 | F11: =VLOOKUP(B11,YearMap!$A$2:$B$6,2,FALSE) | G11: =VLOOKUP(B11,YearMap!$A$2:$C$6,3,FALSE) | H11: =VLOOKUP(B11,YearMap!$A$2:$D$6,4,FALSE) | I11: =A11&"|"&B11
A12: =A3 | B12: FY2026 | C12: =IF(D3=1,0, BaselineCalc!$B$7 + ROUND(C3*F3,0)) | D12: =IF(E3=1,0, BaselineCalc!$B$8 + C3 - ROUND(C3*F3,0)) | E12: =C12+D12 | F12: =VLOOKUP(B12,YearMap!$A$2:$B$6,2,FALSE) | G12: =VLOOKUP(B12,YearMap!$A$2:$C$6,3,FALSE) | H12: =VLOOKUP(B12,YearMap!$A$2:$D$6,4,FALSE) | I12: =A12&"|"&B12
A13: =A3 | B13: FY2027 | C13: =IF(D3=1,0, BaselineCalc!$B$7 + ROUND(C3*F3,0)) | D13: =IF(E3=1,0, BaselineCalc!$B$8 + C3 - ROUND(C3*F3,0)) | E13: =C13+D13 | F13: =VLOOKUP(B13,YearMap!$A$2:$B$6,2,FALSE) | G13: =VLOOKUP(B13,YearMap!$A$2:$C$6,3,FALSE) | H13: =VLOOKUP(B13,YearMap!$A$2:$D$6,4,FALSE) | I13: =A13&"|"&B13
A14: =A3 | B14: FY2028 | C14: =IF(D3=1,0, BaselineCalc!$B$7 + ROUND(C3*F3,0)) | D14: =IF(E3=1,0, BaselineCalc!$B$8 + C3 - ROUND(C3*F3,0)) | E14: =C14+D14 | F14: =VLOOKUP(B14,YearMap!$A$2:$B$6,2,FALSE) | G14: =VLOOKUP(B14,YearMap!$A$2:$C$6,3,FALSE) | H14: =VLOOKUP(B14,YearMap!$A$2:$D$6,4,FALSE) | I14: =A14&"|"&B14
A15: =A3 | B15: FY2029 | C15: =IF(D3=1,0, BaselineCalc!$B$7 + ROUND(C3*F3,0)) | D15: =IF(E3=1,0, BaselineCalc!$B$8 + C3 - ROUND(C3*F3,0)) | E15: =C15+D15 | F15: =VLOOKUP(B15,YearMap!$A$2:$B$6,2,FALSE) | G15: =VLOOKUP(B15,YearMap!$A$2:$C$6,3,FALSE) | H15: =VLOOKUP(B15,YearMap!$A$2:$D$6,4,FALSE) | I15: =A15&"|"&B15
A16: =A3 | B16: FY2030 | C16: =IF(D3=1,0, BaselineCalc!$B$7 + ROUND(C3*F3,0)) | D16: =IF(E3=1,0, BaselineCalc!$B$8 + C3 - ROUND(C3*F3,0)) | E16: =C16+D16 | F16: =VLOOKUP(B16,YearMap!$A$2:$B$6,2,FALSE) | G16: =VLOOKUP(B16,YearMap!$A$2:$C$6,3,FALSE) | H16: =VLOOKUP(B16,YearMap!$A$2:$D$6,4,FALSE) | I16: =A16&"|"&B16
A17: =A4 | B17: FY2026 | C17: =IF(D4=1,0, BaselineCalc!$B$7 + ROUND(C4*F4,0)) | D17: =IF(E4=1,0, BaselineCalc!$B$8 + C4 - ROUND(C4*F4,0)) | E17: =C17+D17 | F17: =VLOOKUP(B17,YearMap!$A$2:$B$6,2,FALSE) | G17: =VLOOKUP(B17,YearMap!$A$2:$C$6,3,FALSE) | H17: =VLOOKUP(B17,YearMap!$A$2:$D$6,4,FALSE) | I17: =A17&"|"&B17
A18: =A4 | B18: FY2027 | C18: =IF(D4=1,0, BaselineCalc!$B$7 + ROUND(C4*F4,0)) | D18: =IF(E4=1,0, BaselineCalc!$B$8 + C4 - ROUND(C4*F4,0)) | E18: =C18+D18 | F18: =VLOOKUP(B18,YearMap!$A$2:$B$6,2,FALSE) | G18: =VLOOKUP(B18,YearMap!$A$2:$C$6,3,FALSE) | H18: =VLOOKUP(B18,YearMap!$A$2:$D$6,4,FALSE) | I18: =A18&"|"&B18
A19: =A4 | B19: FY2028 | C19: =IF(D4=1,0, BaselineCalc!$B$7 + ROUND(C4*F4,0)) | D19: =IF(E4=1,0, BaselineCalc!$B$8 + C4 - ROUND(C4*F4,0)) | E19: =C19+D19 | F19: =VLOOKUP(B19,YearMap!$A$2:$B$6,2,FALSE) | G19: =VLOOKUP(B19,YearMap!$A$2:$C$6,3,FALSE) | H19: =VLOOKUP(B19,YearMap!$A$2:$D$6,4,FALSE) | I19: =A19&"|"&B19
A20: =A4 | B20: FY2029 | C20: =IF(D4=1,0, BaselineCalc!$B$7 + ROUND(C4*F4,0)) | D20: =IF(E4=1,0, BaselineCalc!$B$8 + C4 - ROUND(C4*F4,0)) | E20: =C20+D20 | F20: =VLOOKUP(B20,YearMap!$A$2:$B$6,2,FALSE) | G20: =VLOOKUP(B20,YearMap!$A$2:$C$6,3,FALSE) | H20: =VLOOKUP(B20,YearMap!$A$2:$D$6,4,FALSE) | I20: =A20&"|"&B20
A21: =A4 | B21: FY2030 | C21: =IF(D4=1,0, BaselineCalc!$B$7 + ROUND(C4*F4,0)) | D21: =IF(E4=1,0, BaselineCalc!$B$8 + C4 - ROUND(C4*F4,0)) | E21: =C21+D21 | F21: =VLOOKUP(B21,YearMap!$A$2:$B$6,2,FALSE) | G21: =VLOOKUP(B21,YearMap!$A$2:$C$6,3,FALSE) | H21: =VLOOKUP(B21,YearMap!$A$2:$D$6,4,FALSE) | I21: =A21&"|"&B21
A22: D_Grow_Both_100 | B22: D. Grow Both (Overlay 100) | C22: 100 | D22: 0 | E22: 0 | F22: 0.5 | G22: 0 | H22: Baseline +100 overlay
A23: D_Grow_Both_150 | B23: D. Grow Both (Overlay 150) | C23: 150 | D23: 0 | E23: 0 | F23: 0.5 | G23: 0 | H23: Baseline +150 overlay
A24: G_DHub_EchoRamp | B24: G. D‑Hub @ Echo (Ramp 50→100→150) | C24: 150 | D24: 0 | E24: 0 | F24: 0.7 | G24: 0 | H24: Time‑phased ramp: +50, +100, +150

Sheet Notes
A1: FAQs
B2: Why “Fixed share of M&O = 0.30”?
B3: District M&O typically has a sizable semi‑fixed component (plant ops/custodial/insurance/admin overhead). Without site‑level detail yet, 30% is a conservative placeholder in the middle of the 25–40% range many K‑12 systems sit in. We will replace it with SUSD plant ops + insurance shares when available.
B5: Why “Ops savings (keep‑open) = 0.007 (0.7%)”?
B6: This represents “light discipline” (utilities/purchasing tweaks, route smoothing) that does not depend on closing a site. I set it very low on purpose so it doesn’t drive results. We’ll calibrate with SUSD data (e.g., last year’s utility audits) if provided.
B8: Why “Extra savings (co‑location) = 0.015 (1.5%)”?
B9: This reflects incremental savings from consolidating some services on one campus (custodial/grounds/partial routing). Again kept small and conservative; we’ll swap in real custodial (sq‑ft), grounds and route deltas when we get them.
B11: Why “Repurpose TI per closed site (FY26) = $1.2M”? What is “one‑time carry/TI”?
B12: “TI” = tenant improvements / transition investments needed to convert a K‑8 to a different use (early learning, admin consolidation) and carry costs in year one (e.g., abatement, doors/security, low‑voltage re‑work, furniture, swing space). A light‑touch repurpose can easily run $10–$20/sq‑ft; Echo’s plant is ~77k sq ft, so $1.2M is a reasonable placeholder (we are not assuming a gut remodel). We’ll replace this with SUSD’s scope/estimate if they have one.
A17: Definitions
B18: MO inflation
B19: Base MO per ADM (FY25)
B20: Fixed share of MO
B21: Ops savings (keep‑open)
B22: Extra savings (Co‑location)
B23: Echo base ADM
B24: Pima base ADM
B25: Total base ADM

Sheet MultiYear_ProForma
A1: ScenarioKey | B1: Year | C1: Echo_ADM | D1: Pima_ADM | E1: Total_ADM | F1: VarUnit$ | G1: EchoFixed$ | H1: PimaFixed$ | I1: OpsFactor | J1: ExtraSave | K1: Total_MO$ | L1: MO_per_ADM$ | M1: Key
A2: =Scenarios!A2 | B2: FY2026 | C2: =IF(Scenarios!D2=1,0, BaselineCalc!$B$7 + ROUND((=IF(ISNUMBER(SEARCH("Ramp",A2)), CHOOSE(MATCH(B2,{"FY2026","FY2027","FY2028","FY2029","FY2030"},0),50,100,150,150,150), Scenarios!C2))*Scenarios!F2,0)) | D2: =IF(Scenarios!E2=1,0, BaselineCalc!$B$8 + (=IF(ISNUMBER(SEARCH("Ramp",A2)), CHOOSE(MATCH(B2,{"FY2026","FY2027","FY2028","FY2029","FY2030"},0),50,100,150,150,150), Scenarios!C2)) - ROUND((=IF(ISNUMBER(SEARCH("Ramp",A2)), CHOOSE(MATCH(B2,{"FY2026","FY2027","FY2028","FY2029","FY2030"},0),50,100,150,150,150), Scenarios!C2))*Scenarios!F2,0)) | E2: =C2+D2 | F2: =VLOOKUP(B2,YearMap!$A$2:$B$6,2,FALSE) | G2: =VLOOKUP(B2,YearMap!$A$2:$C$6,3,FALSE) | H2: =VLOOKUP(B2,YearMap!$A$2:$D$6,4,FALSE) | I2: =1-BaselineCalc!$B$5 | J2: =Scenarios!G2 | K2: =(G2+H2+F2*E2)*I2*(1-J2) | L2: =IF(E2>0, K2/E2, NA()) | M2: =A2&"|"&B2
A3: =Scenarios!A2 | B3: FY2027 | C3: =IF(Scenarios!D2=1,0, BaselineCalc!$B$7 + ROUND((=IF(ISNUMBER(SEARCH("Ramp",A3)), CHOOSE(MATCH(B3,{"FY2026","FY2027","FY2028","FY2029","FY2030"},0),50,100,150,150,150), Scenarios!C2))*Scenarios!F2,0)) | D3: =IF(Scenarios!E2=1,0, BaselineCalc!$B$8 + (=IF(ISNUMBER(SEARCH("Ramp",A3)), CHOOSE(MATCH(B3,{"FY2026","FY2027","FY2028","FY2029","FY2030"},0),50,100,150,150,150), Scenarios!C2)) - ROUND((=IF(ISNUMBER(SEARCH("Ramp",A3)), CHOOSE(MATCH(B3,{"FY2026","FY2027","FY2028","FY2029","FY2030"},0),50,100,150,150,150), Scenarios!C2))*Scenarios!F2,0)) | E3: =C3+D3 | F3: =VLOOKUP(B3,YearMap!$A$2:$B$6,2,FALSE) | G3: =VLOOKUP(B3,YearMap!$A$2:$C$6,3,FALSE) | H3: =VLOOKUP(B3,YearMap!$A$2:$D$6,4,FALSE) | I3: =1-BaselineCalc!$B$5 | J3: =Scenarios!G2 | K3: =(G3+H3+F3*E3)*I3*(1-J3) | L3: =IF(E3>0, K3/E3, NA()) | M3: =A3&"|"&B3
A4: =Scenarios!A2 | B4: FY2028 | C4: =IF(Scenarios!D2=1,0, BaselineCalc!$B$7 + ROUND((=IF(ISNUMBER(SEARCH("Ramp",A4)), CHOOSE(MATCH(B4,{"FY2026","FY2027","FY2028","FY2029","FY2030"},0),50,100,150,150,150), Scenarios!C2))*Scenarios!F2,0)) | D4: =IF(Scenarios!E2=1,0, BaselineCalc!$B$8 + (=IF(ISNUMBER(SEARCH("Ramp",A4)), CHOOSE(MATCH(B4,{"FY2026","FY2027","FY2028","FY2029","FY2030"},0),50,100,150,150,150), Scenarios!C2)) - ROUND((=IF(ISNUMBER(SEARCH("Ramp",A4)), CHOOSE(MATCH(B4,{"FY2026","FY2027","FY2028","FY2029","FY2030"},0),50,100,150,150,150), Scenarios!C2))*Scenarios!F2,0)) | E4: =C4+D4 | F4: =VLOOKUP(B4,YearMap!$A$2:$B$6,2,FALSE) | G4: =VLOOKUP(B4,YearMap!$A$2:$C$6,3,FALSE) | H4: =VLOOKUP(B4,YearMap!$A$2:$D$6,4,FALSE) | I4: =1-BaselineCalc!$B$5 | J4: =Scenarios!G2 | K4: =(G4+H4+F4*E4)*I4*(1-J4) | L4: =IF(E4>0, K4/E4, NA()) | M4: =A4&"|"&B4
A5: =Scenarios!A2 | B5: FY2029 | C5: =IF(Scenarios!D2=1,0, BaselineCalc!$B$7 + ROUND((=IF(ISNUMBER(SEARCH("Ramp",A5)), CHOOSE(MATCH(B5,{"FY2026","FY2027","FY2028","FY2029","FY2030"},0),50,100,150,150,150), Scenarios!C2))*Scenarios!F2,0)) | D5: =IF(Scenarios!E2=1,0, BaselineCalc!$B$8 + (=IF(ISNUMBER(SEARCH("Ramp",A5)), CHOOSE(MATCH(B5,{"FY2026","FY2027","FY2028","FY2029","FY2030"},0),50,100,150,150,150), Scenarios!C2)) - ROUND((=IF(ISNUMBER(SEARCH("Ramp",A5)), CHOOSE(MATCH(B5,{"FY2026","FY2027","FY2028","FY2029","FY2030"},0),50,100,150,150,150), Scenarios!C2))*Scenarios!F2,0)) | E5: =C5+D5 | F5: =VLOOKUP(B5,YearMap!$A$2:$B$6,2,FALSE) | G5: =VLOOKUP(B5,YearMap!$A$2:$C$6,3,FALSE) | H5: =VLOOKUP(B5,YearMap!$A$2:$D$6,4,FALSE) | I5: =1-BaselineCalc!$B$5 | J5: =Scenarios!G2 | K5: =(G5+H5+F5*E5)*I5*(1-J5) | L5: =IF(E5>0, K5/E5, NA()) | M5: =A5&"|"&B5
A6: =Scenarios!A2 | B6: FY2030 | C6: =IF(Scenarios!D2=1,0, BaselineCalc!$B$7 + ROUND((=IF(ISNUMBER(SEARCH("Ramp",A6)), CHOOSE(MATCH(B6,{"FY2026","FY2027","FY2028","FY2029","FY2030"},0),50,100,150,150,150), Scenarios!C2))*Scenarios!F2,0)) | D6: =IF(Scenarios!E2=1,0, BaselineCalc!$B$8 + (=IF(ISNUMBER(SEARCH("Ramp",A6)), CHOOSE(MATCH(B6,{"FY2026","FY2027","FY2028","FY2029","FY2030"},0),50,100,150,150,150), Scenarios!C2)) - ROUND((=IF(ISNUMBER(SEARCH("Ramp",A6)), CHOOSE(MATCH(B6,{"FY2026","FY2027","FY2028","FY2029","FY2030"},0),50,100,150,150,150), Scenarios!C2))*Scenarios!F2,0)) | E6: =C6+D6 | F6: =VLOOKUP(B6,YearMap!$A$2:$B$6,2,FALSE) | G6: =VLOOKUP(B6,YearMap!$A$2:$C$6,3,FALSE) | H6: =VLOOKUP(B6,YearMap!$A$2:$D$6,4,FALSE) | I6: =1-BaselineCalc!$B$5 | J6: =Scenarios!G2 | K6: =(G6+H6+F6*E6)*I6*(1-J6) | L6: =IF(E6>0, K6/E6, NA()) | M6: =A6&"|"&B6
A7: =Scenarios!A3 | B7: FY2026 | C7: =IF(Scenarios!D3=1,0, BaselineCalc!$B$7 + ROUND((=IF(ISNUMBER(SEARCH("Ramp",A7)), CHOOSE(MATCH(B7,{"FY2026","FY2027","FY2028","FY2029","FY2030"},0),50,100,150,150,150), Scenarios!C3))*Scenarios!F3,0)) | D7: =IF(Scenarios!E3=1,0, BaselineCalc!$B$8 + (=IF(ISNUMBER(SEARCH("Ramp",A7)), CHOOSE(MATCH(B7,{"FY2026","FY2027","FY2028","FY2029","FY2030"},0),50,100,150,150,150), Scenarios!C3)) - ROUND((=IF(ISNUMBER(SEARCH("Ramp",A7)), CHOOSE(MATCH(B7,{"FY2026","FY2027","FY2028","FY2029","FY2030"},0),50,100,150,150,150), Scenarios!C3))*Scenarios!F3,0)) | E7: =C7+D7 | F7: =VLOOKUP(B7,YearMap!$A$2:$B$6,2,FALSE) | G7: =VLOOKUP(B7,YearMap!$A$2:$C$6,3,FALSE) | H7: =VLOOKUP(B7,YearMap!$A$2:$D$6,4,FALSE) | I7: =1-BaselineCalc!$B$5 | J7: =Scenarios!G3 | K7: =(G7+H7+F7*E7)*I7*(1-J7) | L7: =IF(E7>0, K7/E7, NA()) | M7: =A7&"|"&B7
A8: =Scenarios!A3 | B8: FY2027 | C8: =IF(Scenarios!D3=1,0, BaselineCalc!$B$7 + ROUND((=IF(ISNUMBER(SEARCH("Ramp",A8)), CHOOSE(MATCH(B8,{"FY2026","FY2027","FY2028","FY2029","FY2030"},0),50,100,150,150,150), Scenarios!C3))*Scenarios!F3,0)) | D8: =IF(Scenarios!E3=1,0, BaselineCalc!$B$8 + (=IF(ISNUMBER(SEARCH("Ramp",A8)), CHOOSE(MATCH(B8,{"FY2026","FY2027","FY2028","FY2029","FY2030"},0),50,100,150,150,150), Scenarios!C3)) - ROUND((=IF(ISNUMBER(SEARCH("Ramp",A8)), CHOOSE(MATCH(B8,{"FY2026","FY2027","FY2028","FY2029","FY2030"},0),50,100,150,150,150), Scenarios!C3))*Scenarios!F3,0)) | E8: =C8+D8 | F8: =VLOOKUP(B8,YearMap!$A$2:$B$6,2,FALSE) | G8: =VLOOKUP(B8,YearMap!$A$2:$C$6,3,FALSE) | H8: =VLOOKUP(B8,YearMap!$A$2:$D$6,4,FALSE) | I8: =1-BaselineCalc!$B$5 | J8: =Scenarios!G3 | K8: =(G8+H8+F8*E8)*I8*(1-J8) | L8: =IF(E8>0, K8/E8, NA()) | M8: =A8&"|"&B8
A9: =Scenarios!A3 | B9: FY2028 | C9: =IF(Scenarios!D3=1,0, BaselineCalc!$B$7 + ROUND((=IF(ISNUMBER(SEARCH("Ramp",A9)), CHOOSE(MATCH(B9,{"FY2026","FY2027","FY2028","FY2029","FY2030"},0),50,100,150,150,150), Scenarios!C3))*Scenarios!F3,0)) | D9: =IF(Scenarios!E3=1,0, BaselineCalc!$B$8 + (=IF(ISNUMBER(SEARCH("Ramp",A9)), CHOOSE(MATCH(B9,{"FY2026","FY2027","FY2028","FY2029","FY2030"},0),50,100,150,150,150), Scenarios!C3)) - ROUND((=IF(ISNUMBER(SEARCH("Ramp",A9)), CHOOSE(MATCH(B9,{"FY2026","FY2027","FY2028","FY2029","FY2030"},0),50,100,150,150,150), Scenarios!C3))*Scenarios!F3,0)) | E9: =C9+D9 | F9: =VLOOKUP(B9,YearMap!$A$2:$B$6,2,FALSE) | G9: =VLOOKUP(B9,YearMap!$A$2:$C$6,3,FALSE) | H9: =VLOOKUP(B9,YearMap!$A$2:$D$6,4,FALSE) | I9: =1-BaselineCalc!$B$5 | J9: =Scenarios!G3 | K9: =(G9+H9+F9*E9)*I9*(1-J9) | L9: =IF(E9>0, K9/E9, NA()) | M9: =A9&"|"&B9
A10: =Scenarios!A3 | B10: FY2029 | C10: =IF(Scenarios!D3=1,0, BaselineCalc!$B$7 + ROUND((=IF(ISNUMBER(SEARCH("Ramp",A10)), CHOOSE(MATCH(B10,{"FY2026","FY2027","FY2028","FY2029","FY2030"},0),50,100,150,150,150), Scenarios!C3))*Scenarios!F3,0)) | D10: =IF(Scenarios!E3=1,0, BaselineCalc!$B$8 + (=IF(ISNUMBER(SEARCH("Ramp",A10)), CHOOSE(MATCH(B10,{"FY2026","FY2027","FY2028","FY2029","FY2030"},0),50,100,150,150,150), Scenarios!C3)) - ROUND((=IF(ISNUMBER(SEARCH("Ramp",A10)), CHOOSE(MATCH(B10,{"FY2026","FY2027","FY2028","FY2029","FY2030"},0),50,100,150,150,150), Scenarios!C3))*Scenarios!F3,0)) | E10: =C10+D10 | F10: =VLOOKUP(B10,YearMap!$A$2:$B$6,2,FALSE) | G10: =VLOOKUP(B10,YearMap!$A$2:$C$6,3,FALSE) | H10: =VLOOKUP(B10,YearMap!$A$2:$D$6,4,FALSE) | I10: =1-BaselineCalc!$B$5 | J10: =Scenarios!G3 | K10: =(G10+H10+F10*E10)*I10*(1-J10) | L10: =IF(E10>0, K10/E10, NA()) | M10: =A10&"|"&B10
A11: =Scenarios!A3 | B11: FY2030 | C11: =IF(Scenarios!D3=1,0, BaselineCalc!$B$7 + ROUND((=IF(ISNUMBER(SEARCH("Ramp",A11)), CHOOSE(MATCH(B11,{"FY2026","FY2027","FY2028","FY2029","FY2030"},0),50,100,150,150,150), Scenarios!C3))*Scenarios!F3,0)) | D11: =IF(Scenarios!E3=1,0, BaselineCalc!$B$8 + (=IF(ISNUMBER(SEARCH("Ramp",A11)), CHOOSE(MATCH(B11,{"FY2026","FY2027","FY2028","FY2029","FY2030"},0),50,100,150,150,150), Scenarios!C3)) - ROUND((=IF(ISNUMBER(SEARCH("Ramp",A11)), CHOOSE(MATCH(B11,{"FY2026","FY2027","FY2028","FY2029","FY2030"},0),50,100,150,150,150), Scenarios!C3))*Scenarios!F3,0)) | E11: =C11+D11 | F11: =VLOOKUP(B11,YearMap!$A$2:$B$6,2,FALSE) | G11: =VLOOKUP(B11,YearMap!$A$2:$C$6,3,FALSE) | H11: =VLOOKUP(B11,YearMap!$A$2:$D$6,4,FALSE) | I11: =1-BaselineCalc!$B$5 | J11: =Scenarios!G3 | K11: =(G11+H11+F11*E11)*I11*(1-J11) | L11: =IF(E11>0, K11/E11, NA()) | M11: =A11&"|"&B11
A12: =Scenarios!A4 | B12: FY2026 | C12: =IF(Scenarios!D4=1,0, BaselineCalc!$B$7 + ROUND((=IF(ISNUMBER(SEARCH("Ramp",A12)), CHOOSE(MATCH(B12,{"FY2026","FY2027","FY2028","FY2029","FY2030"},0),50,100,150,150,150), Scenarios!C4))*Scenarios!F4,0)) | D12: =IF(Scenarios!E4=1,0, BaselineCalc!$B$8 + (=IF(ISNUMBER(SEARCH("Ramp",A12)), CHOOSE(MATCH(B12,{"FY2026","FY2027","FY2028","FY2029","FY2030"},0),50,100,150,150,150), Scenarios!C4)) - ROUND((=IF(ISNUMBER(SEARCH("Ramp",A12)), CHOOSE(MATCH(B12,{"FY2026","FY2027","FY2028","FY2029","FY2030"},0),50,100,150,150,150), Scenarios!C4))*Scenarios!F4,0)) | E12: =C12+D12 | F12: =VLOOKUP(B12,YearMap!$A$2:$B$6,2,FALSE) | G12: =VLOOKUP(B12,YearMap!$A$2:$C$6,3,FALSE) | H12: =VLOOKUP(B12,YearMap!$A$2:$D$6,4,FALSE) | I12: =1-BaselineCalc!$B$5 | J12: =Scenarios!G4 | K12: =(G12+H12+F12*E12)*I12*(1-J12) | L12: =IF(E12>0, K12/E12, NA()) | M12: =A12&"|"&B12
A13: =Scenarios!A4 | B13: FY2027 | C13: =IF(Scenarios!D4=1,0, BaselineCalc!$B$7 + ROUND((=IF(ISNUMBER(SEARCH("Ramp",A13)), CHOOSE(MATCH(B13,{"FY2026","FY2027","FY2028","FY2029","FY2030"},0),50,100,150,150,150), Scenarios!C4))*Scenarios!F4,0)) | D13: =IF(Scenarios!E4=1,0, BaselineCalc!$B$8 + (=IF(ISNUMBER(SEARCH("Ramp",A13)), CHOOSE(MATCH(B13,{"FY2026","FY2027","FY2028","FY2029","FY2030"},0),50,100,150,150,150), Scenarios!C4)) - ROUND((=IF(ISNUMBER(SEARCH("Ramp",A13)), CHOOSE(MATCH(B13,{"FY2026","FY2027","FY2028","FY2029","FY2030"},0),50,100,150,150,150), Scenarios!C4))*Scenarios!F4,0)) | E13: =C13+D13 | F13: =VLOOKUP(B13,YearMap!$A$2:$B$6,2,FALSE) | G13: =VLOOKUP(B13,YearMap!$A$2:$C$6,3,FALSE) | H13: =VLOOKUP(B13,YearMap!$A$2:$D$6,4,FALSE) | I13: =1-BaselineCalc!$B$5 | J13: =Scenarios!G4 | K13: =(G13+H13+F13*E13)*I13*(1-J13) | L13: =IF(E13>0, K13/E13, NA()) | M13: =A13&"|"&B13
A14: =Scenarios!A4 | B14: FY2028 | C14: =IF(Scenarios!D4=1,0, BaselineCalc!$B$7 + ROUND((=IF(ISNUMBER(SEARCH("Ramp",A14)), CHOOSE(MATCH(B14,{"FY2026","FY2027","FY2028","FY2029","FY2030"},0),50,100,150,150,150), Scenarios!C4))*Scenarios!F4,0)) | D14: =IF(Scenarios!E4=1,0, BaselineCalc!$B$8 + (=IF(ISNUMBER(SEARCH("Ramp",A14)), CHOOSE(MATCH(B14,{"FY2026","FY2027","FY2028","FY2029","FY2030"},0),50,100,150,150,150), Scenarios!C4)) - ROUND((=IF(ISNUMBER(SEARCH("Ramp",A14)), CHOOSE(MATCH(B14,{"FY2026","FY2027","FY2028","FY2029","FY2030"},0),50,100,150,150,150), Scenarios!C4))*Scenarios!F4,0)) | E14: =C14+D14 | F14: =VLOOKUP(B14,YearMap!$A$2:$B$6,2,FALSE) | G14: =VLOOKUP(B14,YearMap!$A$2:$C$6,3,FALSE) | H14: =VLOOKUP(B14,YearMap!$A$2:$D$6,4,FALSE) | I14: =1-BaselineCalc!$B$5 | J14: =Scenarios!G4 | K14: =(G14+H14+F14*E14)*I14*(1-J14) | L14: =IF(E14>0, K14/E14, NA()) | M14: =A14&"|"&B14
A15: =Scenarios!A4 | B15: FY2029 | C15: =IF(Scenarios!D4=1,0, BaselineCalc!$B$7 + ROUND((=IF(ISNUMBER(SEARCH("Ramp",A15)), CHOOSE(MATCH(B15,{"FY2026","FY2027","FY2028","FY2029","FY2030"},0),50,100,150,150,150), Scenarios!C4))*Scenarios!F4,0)) | D15: =IF(Scenarios!E4=1,0, BaselineCalc!$B$8 + (=IF(ISNUMBER(SEARCH("Ramp",A15)), CHOOSE(MATCH(B15,{"FY2026","FY2027","FY2028","FY2029","FY2030"},0),50,100,150,150,150), Scenarios!C4)) - ROUND((=IF(ISNUMBER(SEARCH("Ramp",A15)), CHOOSE(MATCH(B15,{"FY2026","FY2027","FY2028","FY2029","FY2030"},0),50,100,150,150,150), Scenarios!C4))*Scenarios!F4,0)) | E15: =C15+D15 | F15: =VLOOKUP(B15,YearMap!$A$2:$B$6,2,FALSE) | G15: =VLOOKUP(B15,YearMap!$A$2:$C$6,3,FALSE) | H15: =VLOOKUP(B15,YearMap!$A$2:$D$6,4,FALSE) | I15: =1-BaselineCalc!$B$5 | J15: =Scenarios!G4 | K15: =(G15+H15+F15*E15)*I15*(1-J15) | L15: =IF(E15>0, K15/E15, NA()) | M15: =A15&"|"&B15
A16: =Scenarios!A4 | B16: FY2030 | C16: =IF(Scenarios!D4=1,0, BaselineCalc!$B$7 + ROUND((=IF(ISNUMBER(SEARCH("Ramp",A16)), CHOOSE(MATCH(B16,{"FY2026","FY2027","FY2028","FY2029","FY2030"},0),50,100,150,150,150), Scenarios!C4))*Scenarios!F4,0)) | D16: =IF(Scenarios!E4=1,0, BaselineCalc!$B$8 + (=IF(ISNUMBER(SEARCH("Ramp",A16)), CHOOSE(MATCH(B16,{"FY2026","FY2027","FY2028","FY2029","FY2030"},0),50,100,150,150,150), Scenarios!C4)) - ROUND((=IF(ISNUMBER(SEARCH("Ramp",A16)), CHOOSE(MATCH(B16,{"FY2026","FY2027","FY2028","FY2029","FY2030"},0),50,100,150,150,150), Scenarios!C4))*Scenarios!F4,0)) | E16: =C16+D16 | F16: =VLOOKUP(B16,YearMap!$A$2:$B$6,2,FALSE) | G16: =VLOOKUP(B16,YearMap!$A$2:$C$6,3,FALSE) | H16: =VLOOKUP(B16,YearMap!$A$2:$D$6,4,FALSE) | I16: =1-BaselineCalc!$B$5 | J16: =Scenarios!G4 | K16: =(G16+H16+F16*E16)*I16*(1-J16) | L16: =IF(E16>0, K16/E16, NA()) | M16: =A16&"|"&B16
A17: =Scenarios!A6 | B17: FY2026 | C17: =IF(Scenarios!D6=1,0, BaselineCalc!$B$7 + ROUND((=IF(ISNUMBER(SEARCH("Ramp",A17)), CHOOSE(MATCH(B17,{"FY2026","FY2027","FY2028","FY2029","FY2030"},0),50,100,150,150,150), Scenarios!C6))*Scenarios!F6,0)) | D17: =IF(Scenarios!E6=1,0, BaselineCalc!$B$8 + (=IF(ISNUMBER(SEARCH("Ramp",A17)), CHOOSE(MATCH(B17,{"FY2026","FY2027","FY2028","FY2029","FY2030"},0),50,100,150,150,150), Scenarios!C6)) - ROUND((=IF(ISNUMBER(SEARCH("Ramp",A17)), CHOOSE(MATCH(B17,{"FY2026","FY2027","FY2028","FY2029","FY2030"},0),50,100,150,150,150), Scenarios!C6))*Scenarios!F6,0)) | E17: =C17+D17 | F17: =VLOOKUP(B17,YearMap!$A$2:$B$6,2,FALSE) | G17: =VLOOKUP(B17,YearMap!$A$2:$C$6,3,FALSE) | H17: =VLOOKUP(B17,YearMap!$A$2:$D$6,4,FALSE) | I17: =1-BaselineCalc!$B$5 | J17: =Scenarios!G6 | K17: =(G17+H17+F17*E17)*I17*(1-J17) | L17: =IF(E17>0, K17/E17, NA()) | M17: =A17&"|"&B17
A18: =Scenarios!A6 | B18: FY2027 | C18: =IF(Scenarios!D6=1,0, BaselineCalc!$B$7 + ROUND((=IF(ISNUMBER(SEARCH("Ramp",A18)), CHOOSE(MATCH(B18,{"FY2026","FY2027","FY2028","FY2029","FY2030"},0),50,100,150,150,150), Scenarios!C6))*Scenarios!F6,0)) | D18: =IF(Scenarios!E6=1,0, BaselineCalc!$B$8 + (=IF(ISNUMBER(SEARCH("Ramp",A18)), CHOOSE(MATCH(B18,{"FY2026","FY2027","FY2028","FY2029","FY2030"},0),50,100,150,150,150), Scenarios!C6)) - ROUND((=IF(ISNUMBER(SEARCH("Ramp",A18)), CHOOSE(MATCH(B18,{"FY2026","FY2027","FY2028","FY2029","FY2030"},0),50,100,150,150,150), Scenarios!C6))*Scenarios!F6,0)) | E18: =C18+D18 | F18: =VLOOKUP(B18,YearMap!$A$2:$B$6,2,FALSE) | G18: =VLOOKUP(B18,YearMap!$A$2:$C$6,3,FALSE) | H18: =VLOOKUP(B18,YearMap!$A$2:$D$6,4,FALSE) | I18: =1-BaselineCalc!$B$5 | J18: =Scenarios!G6 | K18: =(G18+H18+F18*E18)*I18*(1-J18) | L18: =IF(E18>0, K18/E18, NA()) | M18: =A18&"|"&B18
A19: =Scenarios!A6 | B19: FY2028 | C19: =IF(Scenarios!D6=1,0, BaselineCalc!$B$7 + ROUND((=IF(ISNUMBER(SEARCH("Ramp",A19)), CHOOSE(MATCH(B19,{"FY2026","FY2027","FY2028","FY2029","FY2030"},0),50,100,150,150,150), Scenarios!C6))*Scenarios!F6,0)) | D19: =IF(Scenarios!E6=1,0, BaselineCalc!$B$8 + (=IF(ISNUMBER(SEARCH("Ramp",A19)), CHOOSE(MATCH(B19,{"FY2026","FY2027","FY2028","FY2029","FY2030"},0),50,100,150,150,150), Scenarios!C6)) - ROUND((=IF(ISNUMBER(SEARCH("Ramp",A19)), CHOOSE(MATCH(B19,{"FY2026","FY2027","FY2028","FY2029","FY2030"},0),50,100,150,150,150), Scenarios!C6))*Scenarios!F6,0)) | E19: =C19+D19 | F19: =VLOOKUP(B19,YearMap!$A$2:$B$6,2,FALSE) | G19: =VLOOKUP(B19,YearMap!$A$2:$C$6,3,FALSE) | H19: =VLOOKUP(B19,YearMap!$A$2:$D$6,4,FALSE) | I19: =1-BaselineCalc!$B$5 | J19: =Scenarios!G6 | K19: =(G19+H19+F19*E19)*I19*(1-J19) | L19: =IF(E19>0, K19/E19, NA()) | M19: =A19&"|"&B19
A20: =Scenarios!A6 | B20: FY2029 | C20: =IF(Scenarios!D6=1,0, BaselineCalc!$B$7 + ROUND((=IF(ISNUMBER(SEARCH("Ramp",A20)), CHOOSE(MATCH(B20,{"FY2026","FY2027","FY2028","FY2029","FY2030"},0),50,100,150,150,150), Scenarios!C6))*Scenarios!F6,0)) | D20: =IF(Scenarios!E6=1,0, BaselineCalc!$B$8 + (=IF(ISNUMBER(SEARCH("Ramp",A20)), CHOOSE(MATCH(B20,{"FY2026","FY2027","FY2028","FY2029","FY2030"},0),50,100,150,150,150), Scenarios!C6)) - ROUND((=IF(ISNUMBER(SEARCH("Ramp",A20)), CHOOSE(MATCH(B20,{"FY2026","FY2027","FY2028","FY2029","FY2030"},0),50,100,150,150,150), Scenarios!C6))*Scenarios!F6,0)) | E20: =C20+D20 | F20: =VLOOKUP(B20,YearMap!$A$2:$B$6,2,FALSE) | G20: =VLOOKUP(B20,YearMap!$A$2:$C$6,3,FALSE) | H20: =VLOOKUP(B20,YearMap!$A$2:$D$6,4,FALSE) | I20: =1-BaselineCalc!$B$5 | J20: =Scenarios!G6 | K20: =(G20+H20+F20*E20)*I20*(1-J20) | L20: =IF(E20>0, K20/E20, NA()) | M20: =A20&"|"&B20
A21: =Scenarios!A6 | B21: FY2030 | C21: =IF(Scenarios!D6=1,0, BaselineCalc!$B$7 + ROUND((=IF(ISNUMBER(SEARCH("Ramp",A21)), CHOOSE(MATCH(B21,{"FY2026","FY2027","FY2028","FY2029","FY2030"},0),50,100,150,150,150), Scenarios!C6))*Scenarios!F6,0)) | D21: =IF(Scenarios!E6=1,0, BaselineCalc!$B$8 + (=IF(ISNUMBER(SEARCH("Ramp",A21)), CHOOSE(MATCH(B21,{"FY2026","FY2027","FY2028","FY2029","FY2030"},0),50,100,150,150,150), Scenarios!C6)) - ROUND((=IF(ISNUMBER(SEARCH("Ramp",A21)), CHOOSE(MATCH(B21,{"FY2026","FY2027","FY2028","FY2029","FY2030"},0),50,100,150,150,150), Scenarios!C6))*Scenarios!F6,0)) | E21: =C21+D21 | F21: =VLOOKUP(B21,YearMap!$A$2:$B$6,2,FALSE) | G21: =VLOOKUP(B21,YearMap!$A$2:$C$6,3,FALSE) | H21: =VLOOKUP(B21,YearMap!$A$2:$D$6,4,FALSE) | I21: =1-BaselineCalc!$B$5 | J21: =Scenarios!G6 | K21: =(G21+H21+F21*E21)*I21*(1-J21) | L21: =IF(E21>0, K21/E21, NA()) | M21: =A21&"|"&B21
A22: =Scenarios!A7 | B22: FY2026 | C22: =IF(Scenarios!D7=1,0, BaselineCalc!$B$7 + ROUND((=IF(ISNUMBER(SEARCH("Ramp",A22)), CHOOSE(MATCH(B22,{"FY2026","FY2027","FY2028","FY2029","FY2030"},0),50,100,150,150,150), Scenarios!C7))*Scenarios!F7,0)) | D22: =IF(Scenarios!E7=1,0, BaselineCalc!$B$8 + (=IF(ISNUMBER(SEARCH("Ramp",A22)), CHOOSE(MATCH(B22,{"FY2026","FY2027","FY2028","FY2029","FY2030"},0),50,100,150,150,150), Scenarios!C7)) - ROUND((=IF(ISNUMBER(SEARCH("Ramp",A22)), CHOOSE(MATCH(B22,{"FY2026","FY2027","FY2028","FY2029","FY2030"},0),50,100,150,150,150), Scenarios!C7))*Scenarios!F7,0)) | E22: =C22+D22 | F22: =VLOOKUP(B22,YearMap!$A$2:$B$6,2,FALSE) | G22: =VLOOKUP(B22,YearMap!$A$2:$C$6,3,FALSE) | H22: =VLOOKUP(B22,YearMap!$A$2:$D$6,4,FALSE) | I22: =1-BaselineCalc!$B$5 | J22: =Scenarios!G7 | K22: =(G22+H22+F22*E22)*I22*(1-J22) | L22: =IF(E22>0, K22/E22, NA()) | M22: =A22&"|"&B22
A23: =Scenarios!A7 | B23: FY2027 | C23: =IF(Scenarios!D7=1,0, BaselineCalc!$B$7 + ROUND((=IF(ISNUMBER(SEARCH("Ramp",A23)), CHOOSE(MATCH(B23,{"FY2026","FY2027","FY2028","FY2029","FY2030"},0),50,100,150,150,150), Scenarios!C7))*Scenarios!F7,0)) | D23: =IF(Scenarios!E7=1,0, BaselineCalc!$B$8 + (=IF(ISNUMBER(SEARCH("Ramp",A23)), CHOOSE(MATCH(B23,{"FY2026","FY2027","FY2028","FY2029","FY2030"},0),50,100,150,150,150), Scenarios!C7)) - ROUND((=IF(ISNUMBER(SEARCH("Ramp",A23)), CHOOSE(MATCH(B23,{"FY2026","FY2027","FY2028","FY2029","FY2030"},0),50,100,150,150,150), Scenarios!C7))*Scenarios!F7,0)) | E23: =C23+D23 | F23: =VLOOKUP(B23,YearMap!$A$2:$B$6,2,FALSE) | G23: =VLOOKUP(B23,YearMap!$A$2:$C$6,3,FALSE) | H23: =VLOOKUP(B23,YearMap!$A$2:$D$6,4,FALSE) | I23: =1-BaselineCalc!$B$5 | J23: =Scenarios!G7 | K23: =(G23+H23+F23*E23)*I23*(1-J23) | L23: =IF(E23>0, K23/E23, NA()) | M23: =A23&"|"&B23
A24: =Scenarios!A7 | B24: FY2028 | C24: =IF(Scenarios!D7=1,0, BaselineCalc!$B$7 + ROUND((=IF(ISNUMBER(SEARCH("Ramp",A24)), CHOOSE(MATCH(B24,{"FY2026","FY2027","FY2028","FY2029","FY2030"},0),50,100,150,150,150), Scenarios!C7))*Scenarios!F7,0)) | D24: =IF(Scenarios!E7=1,0, BaselineCalc!$B$8 + (=IF(ISNUMBER(SEARCH("Ramp",A24)), CHOOSE(MATCH(B24,{"FY2026","FY2027","FY2028","FY2029","FY2030"},0),50,100,150,150,150), Scenarios!C7)) - ROUND((=IF(ISNUMBER(SEARCH("Ramp",A24)), CHOOSE(MATCH(B24,{"FY2026","FY2027","FY2028","FY2029","FY2030"},0),50,100,150,150,150), Scenarios!C7))*Scenarios!F7,0)) | E24: =C24+D24 | F24: =VLOOKUP(B24,YearMap!$A$2:$B$6,2,FALSE) | G24: =VLOOKUP(B24,YearMap!$A$2:$C$6,3,FALSE) | H24: =VLOOKUP(B24,YearMap!$A$2:$D$6,4,FALSE) | I24: =1-BaselineCalc!$B$5 | J24: =Scenarios!G7 | K24: =(G24+H24+F24*E24)*I24*(1-J24) | L24: =IF(E24>0, K24/E24, NA()) | M24: =A24&"|"&B24
A25: =Scenarios!A7 | B25: FY2029 | C25: =IF(Scenarios!D7=1,0, BaselineCalc!$B$7 + ROUND((=IF(ISNUMBER(SEARCH("Ramp",A25)), CHOOSE(MATCH(B25,{"FY2026","FY2027","FY2028","FY2029","FY2030"},0),50,100,150,150,150), Scenarios!C7))*Scenarios!F7,0)) | D25: =IF(Scenarios!E7=1,0, BaselineCalc!$B$8 + (=IF(ISNUMBER(SEARCH("Ramp",A25)), CHOOSE(MATCH(B25,{"FY2026","FY2027","FY2028","FY2029","FY2030"},0),50,100,150,150,150), Scenarios!C7)) - ROUND((=IF(ISNUMBER(SEARCH("Ramp",A25)), CHOOSE(MATCH(B25,{"FY2026","FY2027","FY2028","FY2029","FY2030"},0),50,100,150,150,150), Scenarios!C7))*Scenarios!F7,0)) | E25: =C25+D25 | F25: =VLOOKUP(B25,YearMap!$A$2:$B$6,2,FALSE) | G25: =VLOOKUP(B25,YearMap!$A$2:$C$6,3,FALSE) | H25: =VLOOKUP(B25,YearMap!$A$2:$D$6,4,FALSE) | I25: =1-BaselineCalc!$B$5 | J25: =Scenarios!G7 | K25: =(G25+H25+F25*E25)*I25*(1-J25) | L25: =IF(E25>0, K25/E25, NA()) | M25: =A25&"|"&B25
A26: =Scenarios!A7 | B26: FY2030 | C26: =IF(Scenarios!D7=1,0, BaselineCalc!$B$7 + ROUND((=IF(ISNUMBER(SEARCH("Ramp",A26)), CHOOSE(MATCH(B26,{"FY2026","FY2027","FY2028","FY2029","FY2030"},0),50,100,150,150,150), Scenarios!C7))*Scenarios!F7,0)) | D26: =IF(Scenarios!E7=1,0, BaselineCalc!$B$8 + (=IF(ISNUMBER(SEARCH("Ramp",A26)), CHOOSE(MATCH(B26,{"FY2026","FY2027","FY2028","FY2029","FY2030"},0),50,100,150,150,150), Scenarios!C7)) - ROUND((=IF(ISNUMBER(SEARCH("Ramp",A26)), CHOOSE(MATCH(B26,{"FY2026","FY2027","FY2028","FY2029","FY2030"},0),50,100,150,150,150), Scenarios!C7))*Scenarios!F7,0)) | E26: =C26+D26 | F26: =VLOOKUP(B26,YearMap!$A$2:$B$6,2,FALSE) | G26: =VLOOKUP(B26,YearMap!$A$2:$C$6,3,FALSE) | H26: =VLOOKUP(B26,YearMap!$A$2:$D$6,4,FALSE) | I26: =1-BaselineCalc!$B$5 | J26: =Scenarios!G7 | K26: =(G26+H26+F26*E26)*I26*(1-J26) | L26: =IF(E26>0, K26/E26, NA()) | M26: =A26&"|"&B26
A27: =Scenarios!A8 | B27: FY2026 | C27: =IF(Scenarios!D8=1,0, BaselineCalc!$B$7 + ROUND((=IF(ISNUMBER(SEARCH("Ramp",A27)), CHOOSE(MATCH(B27,{"FY2026","FY2027","FY2028","FY2029","FY2030"},0),50,100,150,150,150), Scenarios!C8))*Scenarios!F8,0)) | D27: =IF(Scenarios!E8=1,0, BaselineCalc!$B$8 + (=IF(ISNUMBER(SEARCH("Ramp",A27)), CHOOSE(MATCH(B27,{"FY2026","FY2027","FY2028","FY2029","FY2030"},0),50,100,150,150,150), Scenarios!C8)) - ROUND((=IF(ISNUMBER(SEARCH("Ramp",A27)), CHOOSE(MATCH(B27,{"FY2026","FY2027","FY2028","FY2029","FY2030"},0),50,100,150,150,150), Scenarios!C8))*Scenarios!F8,0)) | E27: =C27+D27 | F27: =VLOOKUP(B27,YearMap!$A$2:$B$6,2,FALSE) | G27: =VLOOKUP(B27,YearMap!$A$2:$C$6,3,FALSE) | H27: =VLOOKUP(B27,YearMap!$A$2:$D$6,4,FALSE) | I27: =1-BaselineCalc!$B$5 | J27: =Scenarios!G8 | K27: =(G27+H27+F27*E27)*I27*(1-J27) | L27: =IF(E27>0, K27/E27, NA()) | M27: =A27&"|"&B27
A28: =Scenarios!A8 | B28: FY2027 | C28: =IF(Scenarios!D8=1,0, BaselineCalc!$B$7 + ROUND((=IF(ISNUMBER(SEARCH("Ramp",A28)), CHOOSE(MATCH(B28,{"FY2026","FY2027","FY2028","FY2029","FY2030"},0),50,100,150,150,150), Scenarios!C8))*Scenarios!F8,0)) | D28: =IF(Scenarios!E8=1,0, BaselineCalc!$B$8 + (=IF(ISNUMBER(SEARCH("Ramp",A28)), CHOOSE(MATCH(B28,{"FY2026","FY2027","FY2028","FY2029","FY2030"},0),50,100,150,150,150), Scenarios!C8)) - ROUND((=IF(ISNUMBER(SEARCH("Ramp",A28)), CHOOSE(MATCH(B28,{"FY2026","FY2027","FY2028","FY2029","FY2030"},0),50,100,150,150,150), Scenarios!C8))*Scenarios!F8,0)) | E28: =C28+D28 | F28: =VLOOKUP(B28,YearMap!$A$2:$B$6,2,FALSE) | G28: =VLOOKUP(B28,YearMap!$A$2:$C$6,3,FALSE) | H28: =VLOOKUP(B28,YearMap!$A$2:$D$6,4,FALSE) | I28: =1-BaselineCalc!$B$5 | J28: =Scenarios!G8 | K28: =(G28+H28+F28*E28)*I28*(1-J28) | L28: =IF(E28>0, K28/E28, NA()) | M28: =A28&"|"&B28
A29: =Scenarios!A8 | B29: FY2028 | C29: =IF(Scenarios!D8=1,0, BaselineCalc!$B$7 + ROUND((=IF(ISNUMBER(SEARCH("Ramp",A29)), CHOOSE(MATCH(B29,{"FY2026","FY2027","FY2028","FY2029","FY2030"},0),50,100,150,150,150), Scenarios!C8))*Scenarios!F8,0)) | D29: =IF(Scenarios!E8=1,0, BaselineCalc!$B$8 + (=IF(ISNUMBER(SEARCH("Ramp",A29)), CHOOSE(MATCH(B29,{"FY2026","FY2027","FY2028","FY2029","FY2030"},0),50,100,150,150,150), Scenarios!C8)) - ROUND((=IF(ISNUMBER(SEARCH("Ramp",A29)), CHOOSE(MATCH(B29,{"FY2026","FY2027","FY2028","FY2029","FY2030"},0),50,100,150,150,150), Scenarios!C8))*Scenarios!F8,0)) | E29: =C29+D29 | F29: =VLOOKUP(B29,YearMap!$A$2:$B$6,2,FALSE) | G29: =VLOOKUP(B29,YearMap!$A$2:$C$6,3,FALSE) | H29: =VLOOKUP(B29,YearMap!$A$2:$D$6,4,FALSE) | I29: =1-BaselineCalc!$B$5 | J29: =Scenarios!G8 | K29: =(G29+H29+F29*E29)*I29*(1-J29) | L29: =IF(E29>0, K29/E29, NA()) | M29: =A29&"|"&B29
A30: =Scenarios!A8 | B30: FY2029 | C30: =IF(Scenarios!D8=1,0, BaselineCalc!$B$7 + ROUND((=IF(ISNUMBER(SEARCH("Ramp",A30)), CHOOSE(MATCH(B30,{"FY2026","FY2027","FY2028","FY2029","FY2030"},0),50,100,150,150,150), Scenarios!C8))*Scenarios!F8,0)) | D30: =IF(Scenarios!E8=1,0, BaselineCalc!$B$8 + (=IF(ISNUMBER(SEARCH("Ramp",A30)), CHOOSE(MATCH(B30,{"FY2026","FY2027","FY2028","FY2029","FY2030"},0),50,100,150,150,150), Scenarios!C8)) - ROUND((=IF(ISNUMBER(SEARCH("Ramp",A30)), CHOOSE(MATCH(B30,{"FY2026","FY2027","FY2028","FY2029","FY2030"},0),50,100,150,150,150), Scenarios!C8))*Scenarios!F8,0)) | E30: =C30+D30 | F30: =VLOOKUP(B30,YearMap!$A$2:$B$6,2,FALSE) | G30: =VLOOKUP(B30,YearMap!$A$2:$C$6,3,FALSE) | H30: =VLOOKUP(B30,YearMap!$A$2:$D$6,4,FALSE) | I30: =1-BaselineCalc!$B$5 | J30: =Scenarios!G8 | K30: =(G30+H30+F30*E30)*I30*(1-J30) | L30: =IF(E30>0, K30/E30, NA()) | M30: =A30&"|"&B30
A31: =Scenarios!A8 | B31: FY2030 | C31: =IF(Scenarios!D8=1,0, BaselineCalc!$B$7 + ROUND((=IF(ISNUMBER(SEARCH("Ramp",A31)), CHOOSE(MATCH(B31,{"FY2026","FY2027","FY2028","FY2029","FY2030"},0),50,100,150,150,150), Scenarios!C8))*Scenarios!F8,0)) | D31: =IF(Scenarios!E8=1,0, BaselineCalc!$B$8 + (=IF(ISNUMBER(SEARCH("Ramp",A31)), CHOOSE(MATCH(B31,{"FY2026","FY2027","FY2028","FY2029","FY2030"},0),50,100,150,150,150), Scenarios!C8)) - ROUND((=IF(ISNUMBER(SEARCH("Ramp",A31)), CHOOSE(MATCH(B31,{"FY2026","FY2027","FY2028","FY2029","FY2030"},0),50,100,150,150,150), Scenarios!C8))*Scenarios!F8,0)) | E31: =C31+D31 | F31: =VLOOKUP(B31,YearMap!$A$2:$B$6,2,FALSE) | G31: =VLOOKUP(B31,YearMap!$A$2:$C$6,3,FALSE) | H31: =VLOOKUP(B31,YearMap!$A$2:$D$6,4,FALSE) | I31: =1-BaselineCalc!$B$5 | J31: =Scenarios!G8 | K31: =(G31+H31+F31*E31)*I31*(1-J31) | L31: =IF(E31>0, K31/E31, NA()) | M31: =A31&"|"&B31
A32: =Scenarios!A9 | B32: FY2026 | C32: =IF(Scenarios!D9=1,0, BaselineCalc!$B$7 + ROUND((=IF(ISNUMBER(SEARCH("Ramp",A32)), CHOOSE(MATCH(B32,{"FY2026","FY2027","FY2028","FY2029","FY2030"},0),50,100,150,150,150), Scenarios!C9))*Scenarios!F9,0)) | D32: =IF(Scenarios!E9=1,0, BaselineCalc!$B$8 + (=IF(ISNUMBER(SEARCH("Ramp",A32)), CHOOSE(MATCH(B32,{"FY2026","FY2027","FY2028","FY2029","FY2030"},0),50,100,150,150,150), Scenarios!C9)) - ROUND((=IF(ISNUMBER(SEARCH("Ramp",A32)), CHOOSE(MATCH(B32,{"FY2026","FY2027","FY2028","FY2029","FY2030"},0),50,100,150,150,150), Scenarios!C9))*Scenarios!F9,0)) | E32: =C32+D32 | F32: =VLOOKUP(B32,YearMap!$A$2:$B$6,2,FALSE) | G32: =VLOOKUP(B32,YearMap!$A$2:$C$6,3,FALSE) | H32: =VLOOKUP(B32,YearMap!$A$2:$D$6,4,FALSE) | I32: =1-BaselineCalc!$B$5 | J32: =Scenarios!G9 | K32: =(G32+H32+F32*E32)*I32*(1-J32) | L32: =IF(E32>0, K32/E32, NA()) | M32: =A32&"|"&B32
A33: =Scenarios!A9 | B33: FY2027 | C33: =IF(Scenarios!D9=1,0, BaselineCalc!$B$7 + ROUND((=IF(ISNUMBER(SEARCH("Ramp",A33)), CHOOSE(MATCH(B33,{"FY2026","FY2027","FY2028","FY2029","FY2030"},0),50,100,150,150,150), Scenarios!C9))*Scenarios!F9,0)) | D33: =IF(Scenarios!E9=1,0, BaselineCalc!$B$8 + (=IF(ISNUMBER(SEARCH("Ramp",A33)), CHOOSE(MATCH(B33,{"FY2026","FY2027","FY2028","FY2029","FY2030"},0),50,100,150,150,150), Scenarios!C9)) - ROUND((=IF(ISNUMBER(SEARCH("Ramp",A33)), CHOOSE(MATCH(B33,{"FY2026","FY2027","FY2028","FY2029","FY2030"},0),50,100,150,150,150), Scenarios!C9))*Scenarios!F9,0)) | E33: =C33+D33 | F33: =VLOOKUP(B33,YearMap!$A$2:$B$6,2,FALSE) | G33: =VLOOKUP(B33,YearMap!$A$2:$C$6,3,FALSE) | H33: =VLOOKUP(B33,YearMap!$A$2:$D$6,4,FALSE) | I33: =1-BaselineCalc!$B$5 | J33: =Scenarios!G9 | K33: =(G33+H33+F33*E33)*I33*(1-J33) | L33: =IF(E33>0, K33/E33, NA()) | M33: =A33&"|"&B33
A34: =Scenarios!A9 | B34: FY2028 | C34: =IF(Scenarios!D9=1,0, BaselineCalc!$B$7 + ROUND((=IF(ISNUMBER(SEARCH("Ramp",A34)), CHOOSE(MATCH(B34,{"FY2026","FY2027","FY2028","FY2029","FY2030"},0),50,100,150,150,150), Scenarios!C9))*Scenarios!F9,0)) | D34: =IF(Scenarios!E9=1,0, BaselineCalc!$B$8 + (=IF(ISNUMBER(SEARCH("Ramp",A34)), CHOOSE(MATCH(B34,{"FY2026","FY2027","FY2028","FY2029","FY2030"},0),50,100,150,150,150), Scenarios!C9)) - ROUND((=IF(ISNUMBER(SEARCH("Ramp",A34)), CHOOSE(MATCH(B34,{"FY2026","FY2027","FY2028","FY2029","FY2030"},0),50,100,150,150,150), Scenarios!C9))*Scenarios!F9,0)) | E34: =C34+D34 | F34: =VLOOKUP(B34,YearMap!$A$2:$B$6,2,FALSE) | G34: =VLOOKUP(B34,YearMap!$A$2:$C$6,3,FALSE) | H34: =VLOOKUP(B34,YearMap!$A$2:$D$6,4,FALSE) | I34: =1-BaselineCalc!$B$5 | J34: =Scenarios!G9 | K34: =(G34+H34+F34*E34)*I34*(1-J34) | L34: =IF(E34>0, K34/E34, NA()) | M34: =A34&"|"&B34
A35: =Scenarios!A9 | B35: FY2029 | C35: =IF(Scenarios!D9=1,0, BaselineCalc!$B$7 + ROUND((=IF(ISNUMBER(SEARCH("Ramp",A35)), CHOOSE(MATCH(B35,{"FY2026","FY2027","FY2028","FY2029","FY2030"},0),50,100,150,150,150), Scenarios!C9))*Scenarios!F9,0)) | D35: =IF(Scenarios!E9=1,0, BaselineCalc!$B$8 + (=IF(ISNUMBER(SEARCH("Ramp",A35)), CHOOSE(MATCH(B35,{"FY2026","FY2027","FY2028","FY2029","FY2030"},0),50,100,150,150,150), Scenarios!C9)) - ROUND((=IF(ISNUMBER(SEARCH("Ramp",A35)), CHOOSE(MATCH(B35,{"FY2026","FY2027","FY2028","FY2029","FY2030"},0),50,100,150,150,150), Scenarios!C9))*Scenarios!F9,0)) | E35: =C35+D35 | F35: =VLOOKUP(B35,YearMap!$A$2:$B$6,2,FALSE) | G35: =VLOOKUP(B35,YearMap!$A$2:$C$6,3,FALSE) | H35: =VLOOKUP(B35,YearMap!$A$2:$D$6,4,FALSE) | I35: =1-BaselineCalc!$B$5 | J35: =Scenarios!G9 | K35: =(G35+H35+F35*E35)*I35*(1-J35) | L35: =IF(E35>0, K35/E35, NA()) | M35: =A35&"|"&B35
A36: =Scenarios!A9 | B36: FY2030 | C36: =IF(Scenarios!D9=1,0, BaselineCalc!$B$7 + ROUND((=IF(ISNUMBER(SEARCH("Ramp",A36)), CHOOSE(MATCH(B36,{"FY2026","FY2027","FY2028","FY2029","FY2030"},0),50,100,150,150,150), Scenarios!C9))*Scenarios!F9,0)) | D36: =IF(Scenarios!E9=1,0, BaselineCalc!$B$8 + (=IF(ISNUMBER(SEARCH("Ramp",A36)), CHOOSE(MATCH(B36,{"FY2026","FY2027","FY2028","FY2029","FY2030"},0),50,100,150,150,150), Scenarios!C9)) - ROUND((=IF(ISNUMBER(SEARCH("Ramp",A36)), CHOOSE(MATCH(B36,{"FY2026","FY2027","FY2028","FY2029","FY2030"},0),50,100,150,150,150), Scenarios!C9))*Scenarios!F9,0)) | E36: =C36+D36 | F36: =VLOOKUP(B36,YearMap!$A$2:$B$6,2,FALSE) | G36: =VLOOKUP(B36,YearMap!$A$2:$C$6,3,FALSE) | H36: =VLOOKUP(B36,YearMap!$A$2:$D$6,4,FALSE) | I36: =1-BaselineCalc!$B$5 | J36: =Scenarios!G9 | K36: =(G36+H36+F36*E36)*I36*(1-J36) | L36: =IF(E36>0, K36/E36, NA()) | M36: =A36&"|"&B36
A37: =Scenarios!A10 | B37: FY2026 | C37: =IF(Scenarios!D10=1,0, BaselineCalc!$B$7 + ROUND((=IF(ISNUMBER(SEARCH("Ramp",A37)), CHOOSE(MATCH(B37,{"FY2026","FY2027","FY2028","FY2029","FY2030"},0),50,100,150,150,150), Scenarios!C10))*Scenarios!F10,0)) | D37: =IF(Scenarios!E10=1,0, BaselineCalc!$B$8 + (=IF(ISNUMBER(SEARCH("Ramp",A37)), CHOOSE(MATCH(B37,{"FY2026","FY2027","FY2028","FY2029","FY2030"},0),50,100,150,150,150), Scenarios!C10)) - ROUND((=IF(ISNUMBER(SEARCH("Ramp",A37)), CHOOSE(MATCH(B37,{"FY2026","FY2027","FY2028","FY2029","FY2030"},0),50,100,150,150,150), Scenarios!C10))*Scenarios!F10,0)) | E37: =C37+D37 | F37: =VLOOKUP(B37,YearMap!$A$2:$B$6,2,FALSE) | G37: =VLOOKUP(B37,YearMap!$A$2:$C$6,3,FALSE) | H37: =VLOOKUP(B37,YearMap!$A$2:$D$6,4,FALSE) | I37: =1-BaselineCalc!$B$5 | J37: =Scenarios!G10 | K37: =(G37+H37+F37*E37)*I37*(1-J37) | L37: =IF(E37>0, K37/E37, NA()) | M37: =A37&"|"&B37
A38: =Scenarios!A10 | B38: FY2027 | C38: =IF(Scenarios!D10=1,0, BaselineCalc!$B$7 + ROUND((=IF(ISNUMBER(SEARCH("Ramp",A38)), CHOOSE(MATCH(B38,{"FY2026","FY2027","FY2028","FY2029","FY2030"},0),50,100,150,150,150), Scenarios!C10))*Scenarios!F10,0)) | D38: =IF(Scenarios!E10=1,0, BaselineCalc!$B$8 + (=IF(ISNUMBER(SEARCH("Ramp",A38)), CHOOSE(MATCH(B38,{"FY2026","FY2027","FY2028","FY2029","FY2030"},0),50,100,150,150,150), Scenarios!C10)) - ROUND((=IF(ISNUMBER(SEARCH("Ramp",A38)), CHOOSE(MATCH(B38,{"FY2026","FY2027","FY2028","FY2029","FY2030"},0),50,100,150,150,150), Scenarios!C10))*Scenarios!F10,0)) | E38: =C38+D38 | F38: =VLOOKUP(B38,YearMap!$A$2:$B$6,2,FALSE) | G38: =VLOOKUP(B38,YearMap!$A$2:$C$6,3,FALSE) | H38: =VLOOKUP(B38,YearMap!$A$2:$D$6,4,FALSE) | I38: =1-BaselineCalc!$B$5 | J38: =Scenarios!G10 | K38: =(G38+H38+F38*E38)*I38*(1-J38) | L38: =IF(E38>0, K38/E38, NA()) | M38: =A38&"|"&B38
A39: =Scenarios!A10 | B39: FY2028 | C39: =IF(Scenarios!D10=1,0, BaselineCalc!$B$7 + ROUND((=IF(ISNUMBER(SEARCH("Ramp",A39)), CHOOSE(MATCH(B39,{"FY2026","FY2027","FY2028","FY2029","FY2030"},0),50,100,150,150,150), Scenarios!C10))*Scenarios!F10,0)) | D39: =IF(Scenarios!E10=1,0, BaselineCalc!$B$8 + (=IF(ISNUMBER(SEARCH("Ramp",A39)), CHOOSE(MATCH(B39,{"FY2026","FY2027","FY2028","FY2029","FY2030"},0),50,100,150,150,150), Scenarios!C10)) - ROUND((=IF(ISNUMBER(SEARCH("Ramp",A39)), CHOOSE(MATCH(B39,{"FY2026","FY2027","FY2028","FY2029","FY2030"},0),50,100,150,150,150), Scenarios!C10))*Scenarios!F10,0)) | E39: =C39+D39 | F39: =VLOOKUP(B39,YearMap!$A$2:$B$6,2,FALSE) | G39: =VLOOKUP(B39,YearMap!$A$2:$C$6,3,FALSE) | H39: =VLOOKUP(B39,YearMap!$A$2:$D$6,4,FALSE) | I39: =1-BaselineCalc!$B$5 | J39: =Scenarios!G10 | K39: =(G39+H39+F39*E39)*I39*(1-J39) | L39: =IF(E39>0, K39/E39, NA()) | M39: =A39&"|"&B39
A40: =Scenarios!A10 | B40: FY2029 | C40: =IF(Scenarios!D10=1,0, BaselineCalc!$B$7 + ROUND((=IF(ISNUMBER(SEARCH("Ramp",A40)), CHOOSE(MATCH(B40,{"FY2026","FY2027","FY2028","FY2029","FY2030"},0),50,100,150,150,150), Scenarios!C10))*Scenarios!F10,0)) | D40: =IF(Scenarios!E10=1,0, BaselineCalc!$B$8 + (=IF(ISNUMBER(SEARCH("Ramp",A40)), CHOOSE(MATCH(B40,{"FY2026","FY2027","FY2028","FY2029","FY2030"},0),50,100,150,150,150), Scenarios!C10)) - ROUND((=IF(ISNUMBER(SEARCH("Ramp",A40)), CHOOSE(MATCH(B40,{"FY2026","FY2027","FY2028","FY2029","FY2030"},0),50,100,150,150,150), Scenarios!C10))*Scenarios!F10,0)) | E40: =C40+D40 | F40: =VLOOKUP(B40,YearMap!$A$2:$B$6,2,FALSE) | G40: =VLOOKUP(B40,YearMap!$A$2:$C$6,3,FALSE) | H40: =VLOOKUP(B40,YearMap!$A$2:$D$6,4,FALSE) | I40: =1-BaselineCalc!$B$5 | J40: =Scenarios!G10 | K40: =(G40+H40+F40*E40)*I40*(1-J40) | L40: =IF(E40>0, K40/E40, NA()) | M40: =A40&"|"&B40
...

Sheet Summary_Costs
A1: ScenarioKey | B1: FY2028 MO/ADM | C1: FY2030 MO/ADM | D1: 3-yr Avg MO/ADM (FY26–FY28) | E1: 5-yr Avg MO/ADM (FY26–FY30)
A2: =Scenarios!A2 | B2: =INDEX(MultiYear_ProForma!$L$2:$L$111, MATCH( Scenarios!A2&"|FY2028", MultiYear_ProForma!$M$2:$M$111, 0)) | C2: =INDEX(MultiYear_ProForma!$L$2:$L$111, MATCH( Scenarios!A2&"|FY2030", MultiYear_ProForma!$M$2:$M$111, 0)) | D2: =AVERAGE(INDEX(MultiYear_ProForma!$L$2:$L$111, MATCH(Scenarios!A2&"|FY2026", MultiYear_ProForma!$M$2:$M$111, 0)),INDEX(MultiYear_ProForma!$L$2:$L$111, MATCH(Scenarios!A2&"|FY2027", MultiYear_ProForma!$M$2:$M$111, 0)),INDEX(MultiYear_ProForma!$L$2:$L$111, MATCH(Scenarios!A2&"|FY2028", MultiYear_ProForma!$M$2:$M$111, 0))) | E2: =AVERAGE(INDEX(MultiYear_ProForma!$L$2:$L$111, MATCH(Scenarios!A2&"|FY2026", MultiYear_ProForma!$M$2:$M$111, 0)),INDEX(MultiYear_ProForma!$L$2:$L$111, MATCH(Scenarios!A2&"|FY2027", MultiYear_ProForma!$M$2:$M$111, 0)),INDEX(MultiYear_ProForma!$L$2:$L$111, MATCH(Scenarios!A2&"|FY2028", MultiYear_ProForma!$M$2:$M$111, 0)),INDEX(MultiYear_ProForma!$L$2:$L$111, MATCH(Scenarios!A2&"|FY2029", MultiYear_ProForma!$M$2:$M$111, 0)),INDEX(MultiYear_ProForma!$L$2:$L$111, MATCH(Scenarios!A2&"|FY2030", MultiYear_ProForma!$M$2:$M$111, 0)))
A3: =Scenarios!A3 | B3: =INDEX(MultiYear_ProForma!$L$2:$L$111, MATCH( Scenarios!A3&"|FY2028", MultiYear_ProForma!$M$2:$M$111, 0)) | C3: =INDEX(MultiYear_ProForma!$L$2:$L$111, MATCH( Scenarios!A3&"|FY2030", MultiYear_ProForma!$M$2:$M$111, 0)) | D3: =AVERAGE(INDEX(MultiYear_ProForma!$L$2:$L$111, MATCH(Scenarios!A3&"|FY2026", MultiYear_ProForma!$M$2:$M$111, 0)),INDEX(MultiYear_ProForma!$L$2:$L$111, MATCH(Scenarios!A3&"|FY2027", MultiYear_ProForma!$M$2:$M$111, 0)),INDEX(MultiYear_ProForma!$L$2:$L$111, MATCH(Scenarios!A3&"|FY2028", MultiYear_ProForma!$M$2:$M$111, 0))) | E3: =AVERAGE(INDEX(MultiYear_ProForma!$L$2:$L$111, MATCH(Scenarios!A3&"|FY2026", MultiYear_ProForma!$M$2:$M$111, 0)),INDEX(MultiYear_ProForma!$L$2:$L$111, MATCH(Scenarios!A3&"|FY2027", MultiYear_ProForma!$M$2:$M$111, 0)),INDEX(MultiYear_ProForma!$L$2:$L$111, MATCH(Scenarios!A3&"|FY2028", MultiYear_ProForma!$M$2:$M$111, 0)),INDEX(MultiYear_ProForma!$L$2:$L$111, MATCH(Scenarios!A3&"|FY2029", MultiYear_ProForma!$M$2:$M$111, 0)),INDEX(MultiYear_ProForma!$L$2:$L$111, MATCH(Scenarios!A3&"|FY2030", MultiYear_ProForma!$M$2:$M$111, 0)))
A4: =Scenarios!A4 | B4: =INDEX(MultiYear_ProForma!$L$2:$L$111, MATCH( Scenarios!A4&"|FY2028", MultiYear_ProForma!$M$2:$M$111, 0)) | C4: =INDEX(MultiYear_ProForma!$L$2:$L$111, MATCH( Scenarios!A4&"|FY2030", MultiYear_ProForma!$M$2:$M$111, 0)) | D4: =AVERAGE(INDEX(MultiYear_ProForma!$L$2:$L$111, MATCH(Scenarios!A4&"|FY2026", MultiYear_ProForma!$M$2:$M$111, 0)),INDEX(MultiYear_ProForma!$L$2:$L$111, MATCH(Scenarios!A4&"|FY2027", MultiYear_ProForma!$M$2:$M$111, 0)),INDEX(MultiYear_ProForma!$L$2:$L$111, MATCH(Scenarios!A4&"|FY2028", MultiYear_ProForma!$M$2:$M$111, 0))) | E4: =AVERAGE(INDEX(MultiYear_ProForma!$L$2:$L$111, MATCH(Scenarios!A4&"|FY2026", MultiYear_ProForma!$M$2:$M$111, 0)),INDEX(MultiYear_ProForma!$L$2:$L$111, MATCH(Scenarios!A4&"|FY2027", MultiYear_ProForma!$M$2:$M$111, 0)),INDEX(MultiYear_ProForma!$L$2:$L$111, MATCH(Scenarios!A4&"|FY2028", MultiYear_ProForma!$M$2:$M$111, 0)),INDEX(MultiYear_ProForma!$L$2:$L$111, MATCH(Scenarios!A4&"|FY2029", MultiYear_ProForma!$M$2:$M$111, 0)),INDEX(MultiYear_ProForma!$L$2:$L$111, MATCH(Scenarios!A4&"|FY2030", MultiYear_ProForma!$M$2:$M$111, 0)))
A5: =Scenarios!A6 | B5: =INDEX(MultiYear_ProForma!$L$2:$L$111, MATCH( Scenarios!A6&"|FY2028", MultiYear_ProForma!$M$2:$M$111, 0)) | C5: =INDEX(MultiYear_ProForma!$L$2:$L$111, MATCH( Scenarios!A6&"|FY2030", MultiYear_ProForma!$M$2:$M$111, 0)) | D5: =AVERAGE(INDEX(MultiYear_ProForma!$L$2:$L$111, MATCH(Scenarios!A6&"|FY2026", MultiYear_ProForma!$M$2:$M$111, 0)),INDEX(MultiYear_ProForma!$L$2:$L$111, MATCH(Scenarios!A6&"|FY2027", MultiYear_ProForma!$M$2:$M$111, 0)),INDEX(MultiYear_ProForma!$L$2:$L$111, MATCH(Scenarios!A6&"|FY2028", MultiYear_ProForma!$M$2:$M$111, 0))) | E5: =AVERAGE(INDEX(MultiYear_ProForma!$L$2:$L$111, MATCH(Scenarios!A6&"|FY2026", MultiYear_ProForma!$M$2:$M$111, 0)),INDEX(MultiYear_ProForma!$L$2:$L$111, MATCH(Scenarios!A6&"|FY2027", MultiYear_ProForma!$M$2:$M$111, 0)),INDEX(MultiYear_ProForma!$L$2:$L$111, MATCH(Scenarios!A6&"|FY2028", MultiYear_ProForma!$M$2:$M$111, 0)),INDEX(MultiYear_ProForma!$L$2:$L$111, MATCH(Scenarios!A6&"|FY2029", MultiYear_ProForma!$M$2:$M$111, 0)),INDEX(MultiYear_ProForma!$L$2:$L$111, MATCH(Scenarios!A6&"|FY2030", MultiYear_ProForma!$M$2:$M$111, 0)))
A6: =Scenarios!A7 | B6: =INDEX(MultiYear_ProForma!$L$2:$L$111, MATCH( Scenarios!A7&"|FY2028", MultiYear_ProForma!$M$2:$M$111, 0)) | C6: =INDEX(MultiYear_ProForma!$L$2:$L$111, MATCH( Scenarios!A7&"|FY2030", MultiYear_ProForma!$M$2:$M$111, 0)) | D6: =AVERAGE(INDEX(MultiYear_ProForma!$L$2:$L$111, MATCH(Scenarios!A7&"|FY2026", MultiYear_ProForma!$M$2:$M$111, 0)),INDEX(MultiYear_ProForma!$L$2:$L$111, MATCH(Scenarios!A7&"|FY2027", MultiYear_ProForma!$M$2:$M$111, 0)),INDEX(MultiYear_ProForma!$L$2:$L$111, MATCH(Scenarios!A7&"|FY2028", MultiYear_ProForma!$M$2:$M$111, 0))) | E6: =AVERAGE(INDEX(MultiYear_ProForma!$L$2:$L$111, MATCH(Scenarios!A7&"|FY2026", MultiYear_ProForma!$M$2:$M$111, 0)),INDEX(MultiYear_ProForma!$L$2:$L$111, MATCH(Scenarios!A7&"|FY2027", MultiYear_ProForma!$M$2:$M$111, 0)),INDEX(MultiYear_ProForma!$L$2:$L$111, MATCH(Scenarios!A7&"|FY2028", MultiYear_ProForma!$M$2:$M$111, 0)),INDEX(MultiYear_ProForma!$L$2:$L$111, MATCH(Scenarios!A7&"|FY2029", MultiYear_ProForma!$M$2:$M$111, 0)),INDEX(MultiYear_ProForma!$L$2:$L$111, MATCH(Scenarios!A7&"|FY2030", MultiYear_ProForma!$M$2:$M$111, 0)))
A7: =Scenarios!A8 | B7: =INDEX(MultiYear_ProForma!$L$2:$L$111, MATCH( Scenarios!A8&"|FY2028", MultiYear_ProForma!$M$2:$M$111, 0)) | C7: =INDEX(MultiYear_ProForma!$L$2:$L$111, MATCH( Scenarios!A8&"|FY2030", MultiYear_ProForma!$M$2:$M$111, 0)) | D7: =AVERAGE(INDEX(MultiYear_ProForma!$L$2:$L$111, MATCH(Scenarios!A8&"|FY2026", MultiYear_ProForma!$M$2:$M$111, 0)),INDEX(MultiYear_ProForma!$L$2:$L$111, MATCH(Scenarios!A8&"|FY2027", MultiYear_ProForma!$M$2:$M$111, 0)),INDEX(MultiYear_ProForma!$L$2:$L$111, MATCH(Scenarios!A8&"|FY2028", MultiYear_ProForma!$M$2:$M$111, 0))) | E7: =AVERAGE(INDEX(MultiYear_ProForma!$L$2:$L$111, MATCH(Scenarios!A8&"|FY2026", MultiYear_ProForma!$M$2:$M$111, 0)),INDEX(MultiYear_ProForma!$L$2:$L$111, MATCH(Scenarios!A8&"|FY2027", MultiYear_ProForma!$M$2:$M$111, 0)),INDEX(MultiYear_ProForma!$L$2:$L$111, MATCH(Scenarios!A8&"|FY2028", MultiYear_ProForma!$M$2:$M$111, 0)),INDEX(MultiYear_ProForma!$L$2:$L$111, MATCH(Scenarios!A8&"|FY2029", MultiYear_ProForma!$M$2:$M$111, 0)),INDEX(MultiYear_ProForma!$L$2:$L$111, MATCH(Scenarios!A8&"|FY2030", MultiYear_ProForma!$M$2:$M$111, 0)))
A8: =Scenarios!A9 | B8: =INDEX(MultiYear_ProForma!$L$2:$L$111, MATCH( Scenarios!A9&"|FY2028", MultiYear_ProForma!$M$2:$M$111, 0)) | C8: =INDEX(MultiYear_ProForma!$L$2:$L$111, MATCH( Scenarios!A9&"|FY2030", MultiYear_ProForma!$M$2:$M$111, 0)) | D8: =AVERAGE(INDEX(MultiYear_ProForma!$L$2:$L$111, MATCH(Scenarios!A9&"|FY2026", MultiYear_ProForma!$M$2:$M$111, 0)),INDEX(MultiYear_ProForma!$L$2:$L$111, MATCH(Scenarios!A9&"|FY2027", MultiYear_ProForma!$M$2:$M$111, 0)),INDEX(MultiYear_ProForma!$L$2:$L$111, MATCH(Scenarios!A9&"|FY2028", MultiYear_ProForma!$M$2:$M$111, 0))) | E8: =AVERAGE(INDEX(MultiYear_ProForma!$L$2:$L$111, MATCH(Scenarios!A9&"|FY2026", MultiYear_ProForma!$M$2:$M$111, 0)),INDEX(MultiYear_ProForma!$L$2:$L$111, MATCH(Scenarios!A9&"|FY2027", MultiYear_ProForma!$M$2:$M$111, 0)),INDEX(MultiYear_ProForma!$L$2:$L$111, MATCH(Scenarios!A9&"|FY2028", MultiYear_ProForma!$M$2:$M$111, 0)),INDEX(MultiYear_ProForma!$L$2:$L$111, MATCH(Scenarios!A9&"|FY2029", MultiYear_ProForma!$M$2:$M$111, 0)),INDEX(MultiYear_ProForma!$L$2:$L$111, MATCH(Scenarios!A9&"|FY2030", MultiYear_ProForma!$M$2:$M$111, 0)))
A9: =Scenarios!A10 | B9: =INDEX(MultiYear_ProForma!$L$2:$L$111, MATCH( Scenarios!A10&"|FY2028", MultiYear_ProForma!$M$2:$M$111, 0)) | C9: =INDEX(MultiYear_ProForma!$L$2:$L$111, MATCH( Scenarios!A10&"|FY2030", MultiYear_ProForma!$M$2:$M$111, 0)) | D9: =AVERAGE(INDEX(MultiYear_ProForma!$L$2:$L$111, MATCH(Scenarios!A10&"|FY2026", MultiYear_ProForma!$M$2:$M$111, 0)),INDEX(MultiYear_ProForma!$L$2:$L$111, MATCH(Scenarios!A10&"|FY2027", MultiYear_ProForma!$M$2:$M$111, 0)),INDEX(MultiYear_ProForma!$L$2:$L$111, MATCH(Scenarios!A10&"|FY2028", MultiYear_ProForma!$M$2:$M$111, 0))) | E9: =AVERAGE(INDEX(MultiYear_ProForma!$L$2:$L$111, MATCH(Scenarios!A10&"|FY2026", MultiYear_ProForma!$M$2:$M$111, 0)),INDEX(MultiYear_ProForma!$L$2:$L$111, MATCH(Scenarios!A10&"|FY2027", MultiYear_ProForma!$M$2:$M$111, 0)),INDEX(MultiYear_ProForma!$L$2:$L$111, MATCH(Scenarios!A10&"|FY2028", MultiYear_ProForma!$M$2:$M$111, 0)),INDEX(MultiYear_ProForma!$L$2:$L$111, MATCH(Scenarios!A10&"|FY2029", MultiYear_ProForma!$M$2:$M$111, 0)),INDEX(MultiYear_ProForma!$L$2:$L$111, MATCH(Scenarios!A10&"|FY2030", MultiYear_ProForma!$M$2:$M$111, 0)))
A10: =Scenarios!A11 | B10: =INDEX(MultiYear_ProForma!$L$2:$L$111, MATCH( Scenarios!A11&"|FY2028", MultiYear_ProForma!$M$2:$M$111, 0)) | C10: =INDEX(MultiYear_ProForma!$L$2:$L$111, MATCH( Scenarios!A11&"|FY2030", MultiYear_ProForma!$M$2:$M$111, 0)) | D10: =AVERAGE(INDEX(MultiYear_ProForma!$L$2:$L$111, MATCH(Scenarios!A11&"|FY2026", MultiYear_ProForma!$M$2:$M$111, 0)),INDEX(MultiYear_ProForma!$L$2:$L$111, MATCH(Scenarios!A11&"|FY2027", MultiYear_ProForma!$M$2:$M$111, 0)),INDEX(MultiYear_ProForma!$L$2:$L$111, MATCH(Scenarios!A11&"|FY2028", MultiYear_ProForma!$M$2:$M$111, 0))) | E10: =AVERAGE(INDEX(MultiYear_ProForma!$L$2:$L$111, MATCH(Scenarios!A11&"|FY2026", MultiYear_ProForma!$M$2:$M$111, 0)),INDEX(MultiYear_ProForma!$L$2:$L$111, MATCH(Scenarios!A11&"|FY2027", MultiYear_ProForma!$M$2:$M$111, 0)),INDEX(MultiYear_ProForma!$L$2:$L$111, MATCH(Scenarios!A11&"|FY2028", MultiYear_ProForma!$M$2:$M$111, 0)),INDEX(MultiYear_ProForma!$L$2:$L$111, MATCH(Scenarios!A11&"|FY2029", MultiYear_ProForma!$M$2:$M$111, 0)),INDEX(MultiYear_ProForma!$L$2:$L$111, MATCH(Scenarios!A11&"|FY2030", MultiYear_ProForma!$M$2:$M$111, 0)))
A11: =Scenarios!A12 | B11: =INDEX(MultiYear_ProForma!$L$2:$L$111, MATCH( Scenarios!A12&"|FY2028", MultiYear_ProForma!$M$2:$M$111, 0)) | C11: =INDEX(MultiYear_ProForma!$L$2:$L$111, MATCH( Scenarios!A12&"|FY2030", MultiYear_ProForma!$M$2:$M$111, 0)) | D11: =AVERAGE(INDEX(MultiYear_ProForma!$L$2:$L$111, MATCH(Scenarios!A12&"|FY2026", MultiYear_ProForma!$M$2:$M$111, 0)),INDEX(MultiYear_ProForma!$L$2:$L$111, MATCH(Scenarios!A12&"|FY2027", MultiYear_ProForma!$M$2:$M$111, 0)),INDEX(MultiYear_ProForma!$L$2:$L$111, MATCH(Scenarios!A12&"|FY2028", MultiYear_ProForma!$M$2:$M$111, 0))) | E11: =AVERAGE(INDEX(MultiYear_ProForma!$L$2:$L$111, MATCH(Scenarios!A12&"|FY2026", MultiYear_ProForma!$M$2:$M$111, 0)),INDEX(MultiYear_ProForma!$L$2:$L$111, MATCH(Scenarios!A12&"|FY2027", MultiYear_ProForma!$M$2:$M$111, 0)),INDEX(MultiYear_ProForma!$L$2:$L$111, MATCH(Scenarios!A12&"|FY2028", MultiYear_ProForma!$M$2:$M$111, 0)),INDEX(MultiYear_ProForma!$L$2:$L$111, MATCH(Scenarios!A12&"|FY2029", MultiYear_ProForma!$M$2:$M$111, 0)),INDEX(MultiYear_ProForma!$L$2:$L$111, MATCH(Scenarios!A12&"|FY2030", MultiYear_ProForma!$M$2:$M$111, 0)))
A12: =Scenarios!A13 | B12: =INDEX(MultiYear_ProForma!$L$2:$L$111, MATCH( Scenarios!A13&"|FY2028", MultiYear_ProForma!$M$2:$M$111, 0)) | C12: =INDEX(MultiYear_ProForma!$L$2:$L$111, MATCH( Scenarios!A13&"|FY2030", MultiYear_ProForma!$M$2:$M$111, 0)) | D12: =AVERAGE(INDEX(MultiYear_ProForma!$L$2:$L$111, MATCH(Scenarios!A13&"|FY2026", MultiYear_ProForma!$M$2:$M$111, 0)),INDEX(MultiYear_ProForma!$L$2:$L$111, MATCH(Scenarios!A13&"|FY2027", MultiYear_ProForma!$M$2:$M$111, 0)),INDEX(MultiYear_ProForma!$L$2:$L$111, MATCH(Scenarios!A13&"|FY2028", MultiYear_ProForma!$M$2:$M$111, 0))) | E12: =AVERAGE(INDEX(MultiYear_ProForma!$L$2:$L$111, MATCH(Scenarios!A13&"|FY2026", MultiYear_ProForma!$M$2:$M$111, 0)),INDEX(MultiYear_ProForma!$L$2:$L$111, MATCH(Scenarios!A13&"|FY2027", MultiYear_ProForma!$M$2:$M$111, 0)),INDEX(MultiYear_ProForma!$L$2:$L$111, MATCH(Scenarios!A13&"|FY2028", MultiYear_ProForma!$M$2:$M$111, 0)),INDEX(MultiYear_ProForma!$L$2:$L$111, MATCH(Scenarios!A13&"|FY2029", MultiYear_ProForma!$M$2:$M$111, 0)),INDEX(MultiYear_ProForma!$L$2:$L$111, MATCH(Scenarios!A13&"|FY2030", MultiYear_ProForma!$M$2:$M$111, 0)))
A13: =Scenarios!A14 | B13: =INDEX(MultiYear_ProForma!$L$2:$L$111, MATCH( Scenarios!A14&"|FY2028", MultiYear_ProForma!$M$2:$M$111, 0)) | C13: =INDEX(MultiYear_ProForma!$L$2:$L$111, MATCH( Scenarios!A14&"|FY2030", MultiYear_ProForma!$M$2:$M$111, 0)) | D13: =AVERAGE(INDEX(MultiYear_ProForma!$L$2:$L$111, MATCH(Scenarios!A14&"|FY2026", MultiYear_ProForma!$M$2:$M$111, 0)),INDEX(MultiYear_ProForma!$L$2:$L$111, MATCH(Scenarios!A14&"|FY2027", MultiYear_ProForma!$M$2:$M$111, 0)),INDEX(MultiYear_ProForma!$L$2:$L$111, MATCH(Scenarios!A14&"|FY2028", MultiYear_ProForma!$M$2:$M$111, 0))) | E13: =AVERAGE(INDEX(MultiYear_ProForma!$L$2:$L$111, MATCH(Scenarios!A14&"|FY2026", MultiYear_ProForma!$M$2:$M$111, 0)),INDEX(MultiYear_ProForma!$L$2:$L$111, MATCH(Scenarios!A14&"|FY2027", MultiYear_ProForma!$M$2:$M$111, 0)),INDEX(MultiYear_ProForma!$L$2:$L$111, MATCH(Scenarios!A14&"|FY2028", MultiYear_ProForma!$M$2:$M$111, 0)),INDEX(MultiYear_ProForma!$L$2:$L$111, MATCH(Scenarios!A14&"|FY2029", MultiYear_ProForma!$M$2:$M$111, 0)),INDEX(MultiYear_ProForma!$L$2:$L$111, MATCH(Scenarios!A14&"|FY2030", MultiYear_ProForma!$M$2:$M$111, 0)))
A14: =Scenarios!A15 | B14: =INDEX(MultiYear_ProForma!$L$2:$L$111, MATCH( Scenarios!A15&"|FY2028", MultiYear_ProForma!$M$2:$M$111, 0)) | C14: =INDEX(MultiYear_ProForma!$L$2:$L$111, MATCH( Scenarios!A15&"|FY2030", MultiYear_ProForma!$M$2:$M$111, 0)) | D14: =AVERAGE(INDEX(MultiYear_ProForma!$L$2:$L$111, MATCH(Scenarios!A15&"|FY2026", MultiYear_ProForma!$M$2:$M$111, 0)),INDEX(MultiYear_ProForma!$L$2:$L$111, MATCH(Scenarios!A15&"|FY2027", MultiYear_ProForma!$M$2:$M$111, 0)),INDEX(MultiYear_ProForma!$L$2:$L$111, MATCH(Scenarios!A15&"|FY2028", MultiYear_ProForma!$M$2:$M$111, 0))) | E14: =AVERAGE(INDEX(MultiYear_ProForma!$L$2:$L$111, MATCH(Scenarios!A15&"|FY2026", MultiYear_ProForma!$M$2:$M$111, 0)),INDEX(MultiYear_ProForma!$L$2:$L$111, MATCH(Scenarios!A15&"|FY2027", MultiYear_ProForma!$M$2:$M$111, 0)),INDEX(MultiYear_ProForma!$L$2:$L$111, MATCH(Scenarios!A15&"|FY2028", MultiYear_ProForma!$M$2:$M$111, 0)),INDEX(MultiYear_ProForma!$L$2:$L$111, MATCH(Scenarios!A15&"|FY2029", MultiYear_ProForma!$M$2:$M$111, 0)),INDEX(MultiYear_ProForma!$L$2:$L$111, MATCH(Scenarios!A15&"|FY2030", MultiYear_ProForma!$M$2:$M$111, 0)))
