Workbook

Sheet Parameters
A1: Parameter | B1: Value | C1: Notes
A2: MO inflation | B2: 0.025
A3: Base MO per ADM (FY25) | B3: 9936
A4: Fixed share of MO | B4: 0.3
A5: Ops savings (keep-open) | B5: 0.007
A6: Extra savings (Co-location) | B6: 0.015
A7: Echo base ADM | B7: 257
A8: Pima base ADM | B8: 296
A9: Total base ADM | B9: 553 | C9: =B6+B7 -> 0
A10: Repurpose TI per closed site (FY26) | B10: 1200000
A13: Receiving overhead taper (h) | B13: FY2026 | C13: FY2027 | D13: FY2028 | E13: FY2029 | F13: FY2030
A14: h ($/retained) | B14: 1000 | C14: 800 | D14: 600 | E14: 400 | F14: 300
A16: Fixed-carry path (Lease/Sale f) | B16: FY2026 | C16: FY2027 | D16: FY2028 | E16: FY2029 | F16: FY2030
A17: f_lease | B17: 0.4 | C17: 0.3 | D17: 0.2 | E17: 0.1 | F17: 0
A19: Fixed-carry path (Ops f) | B19: FY2026 | C19: FY2027 | D19: FY2028 | E19: FY2029 | F19: FY2030
A20: f_ops | B20: 0.4 | C20: 0.35 | D20: 0.3 | E20: 0.25 | F20: 0.2

Sheet Calc
A1: Helper | B1: FY26 | C1: FY27 | D1: FY28 | E1: FY29 | F1: FY30
A2: Fixed total ($) | B2: 1689592 | C2: 1731831.8 | D2: 1775127.6 | E2: 1819505.7 | F2: 1864993.4
A3: Var unit ($/student) | B3: 7129.08 | C3: 7307.307 | D3: 7489.9897 | E3: 7677.2394 | F3: 7869.1704
A4: Echo fixed ($) | B4: 785217.24 | C4: 804847.67 | D4: 824968.86 | E4: 845593.08 | F4: 866732.91
A5: Pima fixed ($) | B5: 904374.72 | C5: 926984.09 | D5: 950158.69 | E5: 973912.66 | F5: 998260.47

Sheet Scenarios
A1: ScenarioKey | B1: Label | C1: Overlay | D1: CloseEcho | E1: ClosePima | F1: EchoShareDist | G1: ExtraSave | H1: Ramp | I1: Umbrella
A2: A_Repurpose_Both_lease | B2: A. Repurpose Both (Lease/Sale) | C2: 0 | D2: 1 | E2: 1 | F2: 0.5 | G2: 0 | H2: 0 | I2: lease
A3: A_Repurpose_Both_ops | B3: A. Repurpose Both (Ops) | C3: 0 | D3: 1 | E3: 1 | F3: 0.5 | G3: 0 | H3: 0 | I3: ops
A4: B_Repurpose_Echo_Grow_Pima_lease | B4: B. Repurpose Echo; Grow Pima (Lease) | C4: 0 | D4: 1 | E4: 0 | F4: 0.5 | G4: 0 | H4: 0 | I4: lease
A5: B_Repurpose_Echo_Grow_Pima_ops | B5: B. Repurpose Echo; Grow Pima (Ops) | C5: 0 | D5: 1 | E5: 0 | F5: 0.5 | G5: 0 | H5: 0 | I5: ops
A6: C_Repurpose_Pima_Grow_Echo_lease | B6: C. Repurpose Pima; Grow Echo (Lease) | C6: 0 | D6: 0 | E6: 1 | F6: 0.5 | G6: 0 | H6: 0 | I6: lease
A7: C_Repurpose_Pima_Grow_Echo_ops | B7: C. Repurpose Pima; Grow Echo (Ops) | C7: 0 | D7: 0 | E7: 1 | F7: 0.5 | G7: 0 | H7: 0 | I7: ops
A8: D_Grow_Both_0 | B8: D. Grow Both (Overlay 0) | C8: 0 | D8: 0 | E8: 0 | F8: 0.5 | G8: 0 | H8: 0
A9: D_Grow_Both_100 | B9: D. Grow Both (Overlay 100) | C9: 100 | D9: 0 | E9: 0 | F9: 0.5 | G9: 0 | H9: 0
A10: D_Grow_Both_150 | B10: D. Grow Both (Overlay 150) | C10: 150 | D10: 0 | E10: 0 | F10: 0.5 | G10: 0 | H10: 0
A11: E_StatusQuo_Targets_0 | B11: E. Status-Quo + Targets (0) | C11: 0 | D11: 0 | E11: 0 | F11: 0.5 | G11: 0 | H11: 0
A12: E_StatusQuo_Targets_100 | B12: E. Status-Quo + Targets (100) | C12: 100 | D12: 0 | E12: 0 | F12: 0.5 | G12: 0 | H12: 0
A13: E_StatusQuo_Targets_150 | B13: E. Status-Quo + Targets (150) | C13: 150 | D13: 0 | E13: 0 | F13: 0.5 | G13: 0 | H13: 0
A14: F_CoLocation_Echo_0 | B14: F. Co-Location @ Echo (0) | C14: 0 | D14: 0 | E14: 0 | F14: 0.7 | G14: 0.015 | H14: 0
A15: F_CoLocation_Echo_100 | B15: F. Co-Location @ Echo (100) | C15: 100 | D15: 0 | E15: 0 | F15: 0.7 | G15: 0.015 | H15: 0
A16: F_CoLocation_Echo_150 | B16: F. Co-Location @ Echo (150) | C16: 150 | D16: 0 | E16: 0 | F16: 0.7 | G16: 0.015 | H16: 0
A17: G_DHub_EchoRamp | B17: G. D-Hub @ Echo (Ramp 70/30) | C17: 150 | D17: 0 | E17: 0 | F17: 0.7 | G17: 0 | H17: 1

Sheet MultiYear_ProForma
A1: ScenarioKey | B1: Year | C1: Overlay | D1: Echo_ADM | E1: Pima_ADM | F1: Total_ADM | G1: EchoFixed$ | H1: PimaFixed$ | I1: VarUnit$ | J1: TI_add$ | K1: OpsFactor | L1: ExtraSave | M1: Total_MO$ | N1: MO_per_ADM$ | O1: KeyYr
A2: =Scenarios!A2 -> 0 | B2: FY2026 | C2: =Scenarios!C2 -> 0 | D2: =IF(=Scenarios!D2=1,0, Parameters!B6 + =ROUNDUP(=IF(=Scenarios!H2=1, IF("FY2026"="FY2026",50, IF("FY2026"="FY2027",100,150)), =Scenarios!C2)*=Scenarios!F2,0)) -> 0 | E2: =IF(=Scenarios!E2=1,0, Parameters!B7 + ==IF(=Scenarios!H2=1, IF("FY2026"="FY2026",50, IF("FY2026"="FY2027",100,150)), =Scenarios!C2)-(=ROUNDUP(=IF(=Scenarios!H2=1, IF("FY2026"="FY2026",50, IF("FY2026"="FY2027",100,150)), =Scenarios!C2)*=Scenarios!F2,0))) -> 0 | F2: =D2+E2 -> 0 | G2: =IF(=Scenarios!D2=1, IF(=Scenarios!I2="lease", Calc!B4*Parameters!B16, Calc!B4*Parameters!B19), Calc!B4) -> 0 | H2: =IF(=Scenarios!E2=1, IF(=Scenarios!I2="lease", Calc!B5*Parameters!B16, Calc!B5*Parameters!B19), Calc!B5) -> 0 | I2: =Calc!B3 -> 0 | J2: =IF("FY2026"="FY2026", (IF(=Scenarios!D2=1, Parameters!B9,0) + IF(=Scenarios!E2=1, Parameters!B9,0)), 0) -> 0 | K2: =(1-Parameters!B4) -> 0 | L2: =Scenarios!G2 -> 0 | M2: =(IF(Scenarios!D21, IF(Scenarios!I2"lease", Calc!B4*Parameters!B16, Calc!B4*Parameters!B19), Calc!B4) + IF(Scenarios!E21, IF(Scenarios!I2"lease", Calc!B5*Parameters!B16, Calc!B5*Parameters!B19), Calc!B5) + Calc!B3*=D2+E2)*=(1-Parameters!B4)*(1-J2) + =IF("FY2026"="FY2026", (IF(=Scenarios!D2=1, Parameters!B9,0) + IF(=Scenarios!E2=1, Parameters!B9,0)), 0) -> 0 | N2: =IF(F2>0, L2/F2, NA()) -> 0 | O2: ==Scenarios!A2&"|FY2026" -> 0
A3: =Scenarios!A2 -> 0 | B3: FY2027 | C3: =Scenarios!C2 -> 0 | D3: =IF(=Scenarios!D2=1,0, Parameters!B6 + =ROUNDUP(=IF(=Scenarios!H2=1, IF("FY2027"="FY2026",50, IF("FY2027"="FY2027",100,150)), =Scenarios!C2)*=Scenarios!F2,0)) -> 0 | E3: =IF(=Scenarios!E2=1,0, Parameters!B7 + ==IF(=Scenarios!H2=1, IF("FY2027"="FY2026",50, IF("FY2027"="FY2027",100,150)), =Scenarios!C2)-(=ROUNDUP(=IF(=Scenarios!H2=1, IF("FY2027"="FY2026",50, IF("FY2027"="FY2027",100,150)), =Scenarios!C2)*=Scenarios!F2,0))) -> 0 | F3: =D3+E3 -> 0 | G3: =IF(=Scenarios!D2=1, IF(=Scenarios!I2="lease", Calc!C4*Parameters!C16, Calc!C4*Parameters!C19), Calc!C4) -> 0 | H3: =IF(=Scenarios!E2=1, IF(=Scenarios!I2="lease", Calc!C5*Parameters!C16, Calc!C5*Parameters!C19), Calc!C5) -> 0 | I3: =Calc!C3 -> 0 | J3: =IF("FY2027"="FY2026", (IF(=Scenarios!D2=1, Parameters!B9,0) + IF(=Scenarios!E2=1, Parameters!B9,0)), 0) -> 0 | K3: =(1-Parameters!B4) -> 0 | L3: =Scenarios!G2 -> 0 | M3: =(IF(Scenarios!D21, IF(Scenarios!I2"lease", Calc!C4*Parameters!C16, Calc!C4*Parameters!C19), Calc!C4) + IF(Scenarios!E21, IF(Scenarios!I2"lease", Calc!C5*Parameters!C16, Calc!C5*Parameters!C19), Calc!C5) + Calc!C3*=D3+E3)*=(1-Parameters!B4)*(1-J3) + =IF("FY2027"="FY2026", (IF(=Scenarios!D2=1, Parameters!B9,0) + IF(=Scenarios!E2=1, Parameters!B9,0)), 0) -> 0 | N3: =IF(F3>0, L3/F3, NA()) -> 0 | O3: ==Scenarios!A2&"|FY2027" -> 0
A4: =Scenarios!A2 -> 0 | B4: FY2028 | C4: =Scenarios!C2 -> 0 | D4: =IF(=Scenarios!D2=1,0, Parameters!B6 + =ROUNDUP(=IF(=Scenarios!H2=1, IF("FY2028"="FY2026",50, IF("FY2028"="FY2027",100,150)), =Scenarios!C2)*=Scenarios!F2,0)) -> 0 | E4: =IF(=Scenarios!E2=1,0, Parameters!B7 + ==IF(=Scenarios!H2=1, IF("FY2028"="FY2026",50, IF("FY2028"="FY2027",100,150)), =Scenarios!C2)-(=ROUNDUP(=IF(=Scenarios!H2=1, IF("FY2028"="FY2026",50, IF("FY2028"="FY2027",100,150)), =Scenarios!C2)*=Scenarios!F2,0))) -> 0 | F4: =D4+E4 -> 0 | G4: =IF(=Scenarios!D2=1, IF(=Scenarios!I2="lease", Calc!D4*Parameters!D16, Calc!D4*Parameters!D19), Calc!D4) -> 0 | H4: =IF(=Scenarios!E2=1, IF(=Scenarios!I2="lease", Calc!D5*Parameters!D16, Calc!D5*Parameters!D19), Calc!D5) -> 0 | I4: =Calc!D3 -> 0 | J4: =IF("FY2028"="FY2026", (IF(=Scenarios!D2=1, Parameters!B9,0) + IF(=Scenarios!E2=1, Parameters!B9,0)), 0) -> 0 | K4: =(1-Parameters!B4) -> 0 | L4: =Scenarios!G2 -> 0 | M4: =(IF(Scenarios!D21, IF(Scenarios!I2"lease", Calc!D4*Parameters!D16, Calc!D4*Parameters!D19), Calc!D4) + IF(Scenarios!E21, IF(Scenarios!I2"lease", Calc!D5*Parameters!D16, Calc!D5*Parameters!D19), Calc!D5) + Calc!D3*=D4+E4)*=(1-Parameters!B4)*(1-J4) + =IF("FY2028"="FY2026", (IF(=Scenarios!D2=1, Parameters!B9,0) + IF(=Scenarios!E2=1, Parameters!B9,0)), 0) -> 0 | N4: =IF(F4>0, L4/F4, NA()) -> 0 | O4: ==Scenarios!A2&"|FY2028" -> 0
A5: =Scenarios!A2 -> 0 | B5: FY2029 | C5: =Scenarios!C2 -> 0 | D5: =IF(=Scenarios!D2=1,0, Parameters!B6 + =ROUNDUP(=IF(=Scenarios!H2=1, IF("FY2029"="FY2026",50, IF("FY2029"="FY2027",100,150)), =Scenarios!C2)*=Scenarios!F2,0)) -> 0 | E5: =IF(=Scenarios!E2=1,0, Parameters!B7 + ==IF(=Scenarios!H2=1, IF("FY2029"="FY2026",50, IF("FY2029"="FY2027",100,150)), =Scenarios!C2)-(=ROUNDUP(=IF(=Scenarios!H2=1, IF("FY2029"="FY2026",50, IF("FY2029"="FY2027",100,150)), =Scenarios!C2)*=Scenarios!F2,0))) -> 0 | F5: =D5+E5 -> 0 | G5: =IF(=Scenarios!D2=1, IF(=Scenarios!I2="lease", Calc!E4*Parameters!E16, Calc!E4*Parameters!E19), Calc!E4) -> 0 | H5: =IF(=Scenarios!E2=1, IF(=Scenarios!I2="lease", Calc!E5*Parameters!E16, Calc!E5*Parameters!E19), Calc!E5) -> 0 | I5: =Calc!E3 -> 0 | J5: =IF("FY2029"="FY2026", (IF(=Scenarios!D2=1, Parameters!B9,0) + IF(=Scenarios!E2=1, Parameters!B9,0)), 0) -> 0 | K5: =(1-Parameters!B4) -> 0 | L5: =Scenarios!G2 -> 0 | M5: =(IF(Scenarios!D21, IF(Scenarios!I2"lease", Calc!E4*Parameters!E16, Calc!E4*Parameters!E19), Calc!E4) + IF(Scenarios!E21, IF(Scenarios!I2"lease", Calc!E5*Parameters!E16, Calc!E5*Parameters!E19), Calc!E5) + Calc!E3*=D5+E5)*=(1-Parameters!B4)*(1-J5) + =IF("FY2029"="FY2026", (IF(=Scenarios!D2=1, Parameters!B9,0) + IF(=Scenarios!E2=1, Parameters!B9,0)), 0) -> 0 | N5: =IF(F5>0, L5/F5, NA()) -> 0 | O5: ==Scenarios!A2&"|FY2029" -> 0
A6: =Scenarios!A2 -> 0 | B6: FY2030 | C6: =Scenarios!C2 -> 0 | D6: =IF(=Scenarios!D2=1,0, Parameters!B6 + =ROUNDUP(=IF(=Scenarios!H2=1, IF("FY2030"="FY2026",50, IF("FY2030"="FY2027",100,150)), =Scenarios!C2)*=Scenarios!F2,0)) -> 0 | E6: =IF(=Scenarios!E2=1,0, Parameters!B7 + ==IF(=Scenarios!H2=1, IF("FY2030"="FY2026",50, IF("FY2030"="FY2027",100,150)), =Scenarios!C2)-(=ROUNDUP(=IF(=Scenarios!H2=1, IF("FY2030"="FY2026",50, IF("FY2030"="FY2027",100,150)), =Scenarios!C2)*=Scenarios!F2,0))) -> 0 | F6: =D6+E6 -> 0 | G6: =IF(=Scenarios!D2=1, IF(=Scenarios!I2="lease", Calc!F4*Parameters!F16, Calc!F4*Parameters!F19), Calc!F4) -> 0 | H6: =IF(=Scenarios!E2=1, IF(=Scenarios!I2="lease", Calc!F5*Parameters!F16, Calc!F5*Parameters!F19), Calc!F5) -> 0 | I6: =Calc!F3 -> 0 | J6: =IF("FY2030"="FY2026", (IF(=Scenarios!D2=1, Parameters!B9,0) + IF(=Scenarios!E2=1, Parameters!B9,0)), 0) -> 0 | K6: =(1-Parameters!B4) -> 0 | L6: =Scenarios!G2 -> 0 | M6: =(IF(Scenarios!D21, IF(Scenarios!I2"lease", Calc!F4*Parameters!F16, Calc!F4*Parameters!F19), Calc!F4) + IF(Scenarios!E21, IF(Scenarios!I2"lease", Calc!F5*Parameters!F16, Calc!F5*Parameters!F19), Calc!F5) + Calc!F3*=D6+E6)*=(1-Parameters!B4)*(1-J6) + =IF("FY2030"="FY2026", (IF(=Scenarios!D2=1, Parameters!B9,0) + IF(=Scenarios!E2=1, Parameters!B9,0)), 0) -> 0 | N6: =IF(F6>0, L6/F6, NA()) -> 0 | O6: ==Scenarios!A2&"|FY2030" -> 0
A7: =Scenarios!A3 -> 0 | B7: FY2026 | C7: =Scenarios!C3 -> 0 | D7: =IF(=Scenarios!D3=1,0, Parameters!B6 + =ROUNDUP(=IF(=Scenarios!H3=1, IF("FY2026"="FY2026",50, IF("FY2026"="FY2027",100,150)), =Scenarios!C3)*=Scenarios!F3,0)) -> 0 | E7: =IF(=Scenarios!E3=1,0, Parameters!B7 + ==IF(=Scenarios!H3=1, IF("FY2026"="FY2026",50, IF("FY2026"="FY2027",100,150)), =Scenarios!C3)-(=ROUNDUP(=IF(=Scenarios!H3=1, IF("FY2026"="FY2026",50, IF("FY2026"="FY2027",100,150)), =Scenarios!C3)*=Scenarios!F3,0))) -> 0 | F7: =D7+E7 -> 0 | G7: =IF(=Scenarios!D3=1, IF(=Scenarios!I3="lease", Calc!B4*Parameters!B16, Calc!B4*Parameters!B19), Calc!B4) -> 0 | H7: =IF(=Scenarios!E3=1, IF(=Scenarios!I3="lease", Calc!B5*Parameters!B16, Calc!B5*Parameters!B19), Calc!B5) -> 0 | I7: =Calc!B3 -> 0 | J7: =IF("FY2026"="FY2026", (IF(=Scenarios!D3=1, Parameters!B9,0) + IF(=Scenarios!E3=1, Parameters!B9,0)), 0) -> 0 | K7: =(1-Parameters!B4) -> 0 | L7: =Scenarios!G3 -> 0 | M7: =(IF(Scenarios!D31, IF(Scenarios!I3"lease", Calc!B4*Parameters!B16, Calc!B4*Parameters!B19), Calc!B4) + IF(Scenarios!E31, IF(Scenarios!I3"lease", Calc!B5*Parameters!B16, Calc!B5*Parameters!B19), Calc!B5) + Calc!B3*=D7+E7)*=(1-Parameters!B4)*(1-J7) + =IF("FY2026"="FY2026", (IF(=Scenarios!D3=1, Parameters!B9,0) + IF(=Scenarios!E3=1, Parameters!B9,0)), 0) -> 0 | N7: =IF(F7>0, L7/F7, NA()) -> 0 | O7: ==Scenarios!A3&"|FY2026" -> 0
A8: =Scenarios!A3 -> 0 | B8: FY2027 | C8: =Scenarios!C3 -> 0 | D8: =IF(=Scenarios!D3=1,0, Parameters!B6 + =ROUNDUP(=IF(=Scenarios!H3=1, IF("FY2027"="FY2026",50, IF("FY2027"="FY2027",100,150)), =Scenarios!C3)*=Scenarios!F3,0)) -> 0 | E8: =IF(=Scenarios!E3=1,0, Parameters!B7 + ==IF(=Scenarios!H3=1, IF("FY2027"="FY2026",50, IF("FY2027"="FY2027",100,150)), =Scenarios!C3)-(=ROUNDUP(=IF(=Scenarios!H3=1, IF("FY2027"="FY2026",50, IF("FY2027"="FY2027",100,150)), =Scenarios!C3)*=Scenarios!F3,0))) -> 0 | F8: =D8+E8 -> 0 | G8: =IF(=Scenarios!D3=1, IF(=Scenarios!I3="lease", Calc!C4*Parameters!C16, Calc!C4*Parameters!C19), Calc!C4) -> 0 | H8: =IF(=Scenarios!E3=1, IF(=Scenarios!I3="lease", Calc!C5*Parameters!C16, Calc!C5*Parameters!C19), Calc!C5) -> 0 | I8: =Calc!C3 -> 0 | J8: =IF("FY2027"="FY2026", (IF(=Scenarios!D3=1, Parameters!B9,0) + IF(=Scenarios!E3=1, Parameters!B9,0)), 0) -> 0 | K8: =(1-Parameters!B4) -> 0 | L8: =Scenarios!G3 -> 0 | M8: =(IF(Scenarios!D31, IF(Scenarios!I3"lease", Calc!C4*Parameters!C16, Calc!C4*Parameters!C19), Calc!C4) + IF(Scenarios!E31, IF(Scenarios!I3"lease", Calc!C5*Parameters!C16, Calc!C5*Parameters!C19), Calc!C5) + Calc!C3*=D8+E8)*=(1-Parameters!B4)*(1-J8) + =IF("FY2027"="FY2026", (IF(=Scenarios!D3=1, Parameters!B9,0) + IF(=Scenarios!E3=1, Parameters!B9,0)), 0) -> 0 | N8: =IF(F8>0, L8/F8, NA()) -> 0 | O8: ==Scenarios!A3&"|FY2027" -> 0
A9: =Scenarios!A3 -> 0 | B9: FY2028 | C9: =Scenarios!C3 -> 0 | D9: =IF(=Scenarios!D3=1,0, Parameters!B6 + =ROUNDUP(=IF(=Scenarios!H3=1, IF("FY2028"="FY2026",50, IF("FY2028"="FY2027",100,150)), =Scenarios!C3)*=Scenarios!F3,0)) -> 0 | E9: =IF(=Scenarios!E3=1,0, Parameters!B7 + ==IF(=Scenarios!H3=1, IF("FY2028"="FY2026",50, IF("FY2028"="FY2027",100,150)), =Scenarios!C3)-(=ROUNDUP(=IF(=Scenarios!H3=1, IF("FY2028"="FY2026",50, IF("FY2028"="FY2027",100,150)), =Scenarios!C3)*=Scenarios!F3,0))) -> 0 | F9: =D9+E9 -> 0 | G9: =IF(=Scenarios!D3=1, IF(=Scenarios!I3="lease", Calc!D4*Parameters!D16, Calc!D4*Parameters!D19), Calc!D4) -> 0 | H9: =IF(=Scenarios!E3=1, IF(=Scenarios!I3="lease", Calc!D5*Parameters!D16, Calc!D5*Parameters!D19), Calc!D5) -> 0 | I9: =Calc!D3 -> 0 | J9: =IF("FY2028"="FY2026", (IF(=Scenarios!D3=1, Parameters!B9,0) + IF(=Scenarios!E3=1, Parameters!B9,0)), 0) -> 0 | K9: =(1-Parameters!B4) -> 0 | L9: =Scenarios!G3 -> 0 | M9: =(IF(Scenarios!D31, IF(Scenarios!I3"lease", Calc!D4*Parameters!D16, Calc!D4*Parameters!D19), Calc!D4) + IF(Scenarios!E31, IF(Scenarios!I3"lease", Calc!D5*Parameters!D16, Calc!D5*Parameters!D19), Calc!D5) + Calc!D3*=D9+E9)*=(1-Parameters!B4)*(1-J9) + =IF("FY2028"="FY2026", (IF(=Scenarios!D3=1, Parameters!B9,0) + IF(=Scenarios!E3=1, Parameters!B9,0)), 0) -> 0 | N9: =IF(F9>0, L9/F9, NA()) -> 0 | O9: ==Scenarios!A3&"|FY2028" -> 0
A10: =Scenarios!A3 -> 0 | B10: FY2029 | C10: =Scenarios!C3 -> 0 | D10: =IF(=Scenarios!D3=1,0, Parameters!B6 + =ROUNDUP(=IF(=Scenarios!H3=1, IF("FY2029"="FY2026",50, IF("FY2029"="FY2027",100,150)), =Scenarios!C3)*=Scenarios!F3,0)) -> 0 | E10: =IF(=Scenarios!E3=1,0, Parameters!B7 + ==IF(=Scenarios!H3=1, IF("FY2029"="FY2026",50, IF("FY2029"="FY2027",100,150)), =Scenarios!C3)-(=ROUNDUP(=IF(=Scenarios!H3=1, IF("FY2029"="FY2026",50, IF("FY2029"="FY2027",100,150)), =Scenarios!C3)*=Scenarios!F3,0))) -> 0 | F10: =D10+E10 -> 0 | G10: =IF(=Scenarios!D3=1, IF(=Scenarios!I3="lease", Calc!E4*Parameters!E16, Calc!E4*Parameters!E19), Calc!E4) -> 0 | H10: =IF(=Scenarios!E3=1, IF(=Scenarios!I3="lease", Calc!E5*Parameters!E16, Calc!E5*Parameters!E19), Calc!E5) -> 0 | I10: =Calc!E3 -> 0 | J10: =IF("FY2029"="FY2026", (IF(=Scenarios!D3=1, Parameters!B9,0) + IF(=Scenarios!E3=1, Parameters!B9,0)), 0) -> 0 | K10: =(1-Parameters!B4) -> 0 | L10: =Scenarios!G3 -> 0 | M10: =(IF(Scenarios!D31, IF(Scenarios!I3"lease", Calc!E4*Parameters!E16, Calc!E4*Parameters!E19), Calc!E4) + IF(Scenarios!E31, IF(Scenarios!I3"lease", Calc!E5*Parameters!E16, Calc!E5*Parameters!E19), Calc!E5) + Calc!E3*=D10+E10)*=(1-Parameters!B4)*(1-J10) + =IF("FY2029"="FY2026", (IF(=Scenarios!D3=1, Parameters!B9,0) + IF(=Scenarios!E3=1, Parameters!B9,0)), 0) -> 0 | N10: =IF(F10>0, L10/F10, NA()) -> 0 | O10: ==Scenarios!A3&"|FY2029" -> 0
A11: =Scenarios!A3 -> 0 | B11: FY2030 | C11: =Scenarios!C3 -> 0 | D11: =IF(=Scenarios!D3=1,0, Parameters!B6 + =ROUNDUP(=IF(=Scenarios!H3=1, IF("FY2030"="FY2026",50, IF("FY2030"="FY2027",100,150)), =Scenarios!C3)*=Scenarios!F3,0)) -> 0 | E11: =IF(=Scenarios!E3=1,0, Parameters!B7 + ==IF(=Scenarios!H3=1, IF("FY2030"="FY2026",50, IF("FY2030"="FY2027",100,150)), =Scenarios!C3)-(=ROUNDUP(=IF(=Scenarios!H3=1, IF("FY2030"="FY2026",50, IF("FY2030"="FY2027",100,150)), =Scenarios!C3)*=Scenarios!F3,0))) -> 0 | F11: =D11+E11 -> 0 | G11: =IF(=Scenarios!D3=1, IF(=Scenarios!I3="lease", Calc!F4*Parameters!F16, Calc!F4*Parameters!F19), Calc!F4) -> 0 | H11: =IF(=Scenarios!E3=1, IF(=Scenarios!I3="lease", Calc!F5*Parameters!F16, Calc!F5*Parameters!F19), Calc!F5) -> 0 | I11: =Calc!F3 -> 0 | J11: =IF("FY2030"="FY2026", (IF(=Scenarios!D3=1, Parameters!B9,0) + IF(=Scenarios!E3=1, Parameters!B9,0)), 0) -> 0 | K11: =(1-Parameters!B4) -> 0 | L11: =Scenarios!G3 -> 0 | M11: =(IF(Scenarios!D31, IF(Scenarios!I3"lease", Calc!F4*Parameters!F16, Calc!F4*Parameters!F19), Calc!F4) + IF(Scenarios!E31, IF(Scenarios!I3"lease", Calc!F5*Parameters!F16, Calc!F5*Parameters!F19), Calc!F5) + Calc!F3*=D11+E11)*=(1-Parameters!B4)*(1-J11) + =IF("FY2030"="FY2026", (IF(=Scenarios!D3=1, Parameters!B9,0) + IF(=Scenarios!E3=1, Parameters!B9,0)), 0) -> 0 | N11: =IF(F11>0, L11/F11, NA()) -> 0 | O11: ==Scenarios!A3&"|FY2030" -> 0
A12: =Scenarios!A4 -> 0 | B12: FY2026 | C12: =Scenarios!C4 -> 0 | D12: =IF(=Scenarios!D4=1,0, Parameters!B6 + =ROUNDUP(=IF(=Scenarios!H4=1, IF("FY2026"="FY2026",50, IF("FY2026"="FY2027",100,150)), =Scenarios!C4)*=Scenarios!F4,0)) -> 0 | E12: =IF(=Scenarios!E4=1,0, Parameters!B7 + ==IF(=Scenarios!H4=1, IF("FY2026"="FY2026",50, IF("FY2026"="FY2027",100,150)), =Scenarios!C4)-(=ROUNDUP(=IF(=Scenarios!H4=1, IF("FY2026"="FY2026",50, IF("FY2026"="FY2027",100,150)), =Scenarios!C4)*=Scenarios!F4,0))) -> 0 | F12: =D12+E12 -> 0 | G12: =IF(=Scenarios!D4=1, IF(=Scenarios!I4="lease", Calc!B4*Parameters!B16, Calc!B4*Parameters!B19), Calc!B4) -> 0 | H12: =IF(=Scenarios!E4=1, IF(=Scenarios!I4="lease", Calc!B5*Parameters!B16, Calc!B5*Parameters!B19), Calc!B5) -> 0 | I12: =Calc!B3 -> 0 | J12: =IF("FY2026"="FY2026", (IF(=Scenarios!D4=1, Parameters!B9,0) + IF(=Scenarios!E4=1, Parameters!B9,0)), 0) -> 0 | K12: =(1-Parameters!B4) -> 0 | L12: =Scenarios!G4 -> 0 | M12: =(IF(Scenarios!D41, IF(Scenarios!I4"lease", Calc!B4*Parameters!B16, Calc!B4*Parameters!B19), Calc!B4) + IF(Scenarios!E41, IF(Scenarios!I4"lease", Calc!B5*Parameters!B16, Calc!B5*Parameters!B19), Calc!B5) + Calc!B3*=D12+E12)*=(1-Parameters!B4)*(1-J12) + =IF("FY2026"="FY2026", (IF(=Scenarios!D4=1, Parameters!B9,0) + IF(=Scenarios!E4=1, Parameters!B9,0)), 0) -> 0 | N12: =IF(F12>0, L12/F12, NA()) -> 0 | O12: ==Scenarios!A4&"|FY2026" -> 0
A13: =Scenarios!A4 -> 0 | B13: FY2027 | C13: =Scenarios!C4 -> 0 | D13: =IF(=Scenarios!D4=1,0, Parameters!B6 + =ROUNDUP(=IF(=Scenarios!H4=1, IF("FY2027"="FY2026",50, IF("FY2027"="FY2027",100,150)), =Scenarios!C4)*=Scenarios!F4,0)) -> 0 | E13: =IF(=Scenarios!E4=1,0, Parameters!B7 + ==IF(=Scenarios!H4=1, IF("FY2027"="FY2026",50, IF("FY2027"="FY2027",100,150)), =Scenarios!C4)-(=ROUNDUP(=IF(=Scenarios!H4=1, IF("FY2027"="FY2026",50, IF("FY2027"="FY2027",100,150)), =Scenarios!C4)*=Scenarios!F4,0))) -> 0 | F13: =D13+E13 -> 0 | G13: =IF(=Scenarios!D4=1, IF(=Scenarios!I4="lease", Calc!C4*Parameters!C16, Calc!C4*Parameters!C19), Calc!C4) -> 0 | H13: =IF(=Scenarios!E4=1, IF(=Scenarios!I4="lease", Calc!C5*Parameters!C16, Calc!C5*Parameters!C19), Calc!C5) -> 0 | I13: =Calc!C3 -> 0 | J13: =IF("FY2027"="FY2026", (IF(=Scenarios!D4=1, Parameters!B9,0) + IF(=Scenarios!E4=1, Parameters!B9,0)), 0) -> 0 | K13: =(1-Parameters!B4) -> 0 | L13: =Scenarios!G4 -> 0 | M13: =(IF(Scenarios!D41, IF(Scenarios!I4"lease", Calc!C4*Parameters!C16, Calc!C4*Parameters!C19), Calc!C4) + IF(Scenarios!E41, IF(Scenarios!I4"lease", Calc!C5*Parameters!C16, Calc!C5*Parameters!C19), Calc!C5) + Calc!C3*=D13+E13)*=(1-Parameters!B4)*(1-J13) + =IF("FY2027"="FY2026", (IF(=Scenarios!D4=1, Parameters!B9,0) + IF(=Scenarios!E4=1, Parameters!B9,0)), 0) -> 0 | N13: =IF(F13>0, L13/F13, NA()) -> 0 | O13: ==Scenarios!A4&"|FY2027" -> 0
A14: =Scenarios!A4 -> 0 | B14: FY2028 | C14: =Scenarios!C4 -> 0 | D14: =IF(=Scenarios!D4=1,0, Parameters!B6 + =ROUNDUP(=IF(=Scenarios!H4=1, IF("FY2028"="FY2026",50, IF("FY2028"="FY2027",100,150)), =Scenarios!C4)*=Scenarios!F4,0)) -> 0 | E14: =IF(=Scenarios!E4=1,0, Parameters!B7 + ==IF(=Scenarios!H4=1, IF("FY2028"="FY2026",50, IF("FY2028"="FY2027",100,150)), =Scenarios!C4)-(=ROUNDUP(=IF(=Scenarios!H4=1, IF("FY2028"="FY2026",50, IF("FY2028"="FY2027",100,150)), =Scenarios!C4)*=Scenarios!F4,0))) -> 0 | F14: =D14+E14 -> 0 | G14: =IF(=Scenarios!D4=1, IF(=Scenarios!I4="lease", Calc!D4*Parameters!D16, Calc!D4*Parameters!D19), Calc!D4) -> 0 | H14: =IF(=Scenarios!E4=1, IF(=Scenarios!I4="lease", Calc!D5*Parameters!D16, Calc!D5*Parameters!D19), Calc!D5) -> 0 | I14: =Calc!D3 -> 0 | J14: =IF("FY2028"="FY2026", (IF(=Scenarios!D4=1, Parameters!B9,0) + IF(=Scenarios!E4=1, Parameters!B9,0)), 0) -> 0 | K14: =(1-Parameters!B4) -> 0 | L14: =Scenarios!G4 -> 0 | M14: =(IF(Scenarios!D41, IF(Scenarios!I4"lease", Calc!D4*Parameters!D16, Calc!D4*Parameters!D19), Calc!D4) + IF(Scenarios!E41, IF(Scenarios!I4"lease", Calc!D5*Parameters!D16, Calc!D5*Parameters!D19), Calc!D5) + Calc!D3*=D14+E14)*=(1-Parameters!B4)*(1-J14) + =IF("FY2028"="FY2026", (IF(=Scenarios!D4=1, Parameters!B9,0) + IF(=Scenarios!E4=1, Parameters!B9,0)), 0) -> 0 | N14: =IF(F14>0, L14/F14, NA()) -> 0 | O14: ==Scenarios!A4&"|FY2028" -> 0
A15: =Scenarios!A4 -> 0 | B15: FY2029 | C15: =Scenarios!C4 -> 0 | D15: =IF(=Scenarios!D4=1,0, Parameters!B6 + =ROUNDUP(=IF(=Scenarios!H4=1, IF("FY2029"="FY2026",50, IF("FY2029"="FY2027",100,150)), =Scenarios!C4)*=Scenarios!F4,0)) -> 0 | E15: =IF(=Scenarios!E4=1,0, Parameters!B7 + ==IF(=Scenarios!H4=1, IF("FY2029"="FY2026",50, IF("FY2029"="FY2027",100,150)), =Scenarios!C4)-(=ROUNDUP(=IF(=Scenarios!H4=1, IF("FY2029"="FY2026",50, IF("FY2029"="FY2027",100,150)), =Scenarios!C4)*=Scenarios!F4,0))) -> 0 | F15: =D15+E15 -> 0 | G15: =IF(=Scenarios!D4=1, IF(=Scenarios!I4="lease", Calc!E4*Parameters!E16, Calc!E4*Parameters!E19), Calc!E4) -> 0 | H15: =IF(=Scenarios!E4=1, IF(=Scenarios!I4="lease", Calc!E5*Parameters!E16, Calc!E5*Parameters!E19), Calc!E5) -> 0 | I15: =Calc!E3 -> 0 | J15: =IF("FY2029"="FY2026", (IF(=Scenarios!D4=1, Parameters!B9,0) + IF(=Scenarios!E4=1, Parameters!B9,0)), 0) -> 0 | K15: =(1-Parameters!B4) -> 0 | L15: =Scenarios!G4 -> 0 | M15: =(IF(Scenarios!D41, IF(Scenarios!I4"lease", Calc!E4*Parameters!E16, Calc!E4*Parameters!E19), Calc!E4) + IF(Scenarios!E41, IF(Scenarios!I4"lease", Calc!E5*Parameters!E16, Calc!E5*Parameters!E19), Calc!E5) + Calc!E3*=D15+E15)*=(1-Parameters!B4)*(1-J15) + =IF("FY2029"="FY2026", (IF(=Scenarios!D4=1, Parameters!B9,0) + IF(=Scenarios!E4=1, Parameters!B9,0)), 0) -> 0 | N15: =IF(F15>0, L15/F15, NA()) -> 0 | O15: ==Scenarios!A4&"|FY2029" -> 0
A16: =Scenarios!A4 -> 0 | B16: FY2030 | C16: =Scenarios!C4 -> 0 | D16: =IF(=Scenarios!D4=1,0, Parameters!B6 + =ROUNDUP(=IF(=Scenarios!H4=1, IF("FY2030"="FY2026",50, IF("FY2030"="FY2027",100,150)), =Scenarios!C4)*=Scenarios!F4,0)) -> 0 | E16: =IF(=Scenarios!E4=1,0, Parameters!B7 + ==IF(=Scenarios!H4=1, IF("FY2030"="FY2026",50, IF("FY2030"="FY2027",100,150)), =Scenarios!C4)-(=ROUNDUP(=IF(=Scenarios!H4=1, IF("FY2030"="FY2026",50, IF("FY2030"="FY2027",100,150)), =Scenarios!C4)*=Scenarios!F4,0))) -> 0 | F16: =D16+E16 -> 0 | G16: =IF(=Scenarios!D4=1, IF(=Scenarios!I4="lease", Calc!F4*Parameters!F16, Calc!F4*Parameters!F19), Calc!F4) -> 0 | H16: =IF(=Scenarios!E4=1, IF(=Scenarios!I4="lease", Calc!F5*Parameters!F16, Calc!F5*Parameters!F19), Calc!F5) -> 0 | I16: =Calc!F3 -> 0 | J16: =IF("FY2030"="FY2026", (IF(=Scenarios!D4=1, Parameters!B9,0) + IF(=Scenarios!E4=1, Parameters!B9,0)), 0) -> 0 | K16: =(1-Parameters!B4) -> 0 | L16: =Scenarios!G4 -> 0 | M16: =(IF(Scenarios!D41, IF(Scenarios!I4"lease", Calc!F4*Parameters!F16, Calc!F4*Parameters!F19), Calc!F4) + IF(Scenarios!E41, IF(Scenarios!I4"lease", Calc!F5*Parameters!F16, Calc!F5*Parameters!F19), Calc!F5) + Calc!F3*=D16+E16)*=(1-Parameters!B4)*(1-J16) + =IF("FY2030"="FY2026", (IF(=Scenarios!D4=1, Parameters!B9,0) + IF(=Scenarios!E4=1, Parameters!B9,0)), 0) -> 0 | N16: =IF(F16>0, L16/F16, NA()) -> 0 | O16: ==Scenarios!A4&"|FY2030" -> 0
A17: =Scenarios!A5 -> 0 | B17: FY2026 | C17: =Scenarios!C5 -> 0 | D17: =IF(=Scenarios!D5=1,0, Parameters!B6 + =ROUNDUP(=IF(=Scenarios!H5=1, IF("FY2026"="FY2026",50, IF("FY2026"="FY2027",100,150)), =Scenarios!C5)*=Scenarios!F5,0)) -> 0 | E17: =IF(=Scenarios!E5=1,0, Parameters!B7 + ==IF(=Scenarios!H5=1, IF("FY2026"="FY2026",50, IF("FY2026"="FY2027",100,150)), =Scenarios!C5)-(=ROUNDUP(=IF(=Scenarios!H5=1, IF("FY2026"="FY2026",50, IF("FY2026"="FY2027",100,150)), =Scenarios!C5)*=Scenarios!F5,0))) -> 0 | F17: =D17+E17 -> 0 | G17: =IF(=Scenarios!D5=1, IF(=Scenarios!I5="lease", Calc!B4*Parameters!B16, Calc!B4*Parameters!B19), Calc!B4) -> 0 | H17: =IF(=Scenarios!E5=1, IF(=Scenarios!I5="lease", Calc!B5*Parameters!B16, Calc!B5*Parameters!B19), Calc!B5) -> 0 | I17: =Calc!B3 -> 0 | J17: =IF("FY2026"="FY2026", (IF(=Scenarios!D5=1, Parameters!B9,0) + IF(=Scenarios!E5=1, Parameters!B9,0)), 0) -> 0 | K17: =(1-Parameters!B4) -> 0 | L17: =Scenarios!G5 -> 0 | M17: =(IF(Scenarios!D51, IF(Scenarios!I5"lease", Calc!B4*Parameters!B16, Calc!B4*Parameters!B19), Calc!B4) + IF(Scenarios!E51, IF(Scenarios!I5"lease", Calc!B5*Parameters!B16, Calc!B5*Parameters!B19), Calc!B5) + Calc!B3*=D17+E17)*=(1-Parameters!B4)*(1-J17) + =IF("FY2026"="FY2026", (IF(=Scenarios!D5=1, Parameters!B9,0) + IF(=Scenarios!E5=1, Parameters!B9,0)), 0) -> 0 | N17: =IF(F17>0, L17/F17, NA()) -> 0 | O17: ==Scenarios!A5&"|FY2026" -> 0
A18: =Scenarios!A5 -> 0 | B18: FY2027 | C18: =Scenarios!C5 -> 0 | D18: =IF(=Scenarios!D5=1,0, Parameters!B6 + =ROUNDUP(=IF(=Scenarios!H5=1, IF("FY2027"="FY2026",50, IF("FY2027"="FY2027",100,150)), =Scenarios!C5)*=Scenarios!F5,0)) -> 0 | E18: =IF(=Scenarios!E5=1,0, Parameters!B7 + ==IF(=Scenarios!H5=1, IF("FY2027"="FY2026",50, IF("FY2027"="FY2027",100,150)), =Scenarios!C5)-(=ROUNDUP(=IF(=Scenarios!H5=1, IF("FY2027"="FY2026",50, IF("FY2027"="FY2027",100,150)), =Scenarios!C5)*=Scenarios!F5,0))) -> 0 | F18: =D18+E18 -> 0 | G18: =IF(=Scenarios!D5=1, IF(=Scenarios!I5="lease", Calc!C4*Parameters!C16, Calc!C4*Parameters!C19), Calc!C4) -> 0 | H18: =IF(=Scenarios!E5=1, IF(=Scenarios!I5="lease", Calc!C5*Parameters!C16, Calc!C5*Parameters!C19), Calc!C5) -> 0 | I18: =Calc!C3 -> 0 | J18: =IF("FY2027"="FY2026", (IF(=Scenarios!D5=1, Parameters!B9,0) + IF(=Scenarios!E5=1, Parameters!B9,0)), 0) -> 0 | K18: =(1-Parameters!B4) -> 0 | L18: =Scenarios!G5 -> 0 | M18: =(IF(Scenarios!D51, IF(Scenarios!I5"lease", Calc!C4*Parameters!C16, Calc!C4*Parameters!C19), Calc!C4) + IF(Scenarios!E51, IF(Scenarios!I5"lease", Calc!C5*Parameters!C16, Calc!C5*Parameters!C19), Calc!C5) + Calc!C3*=D18+E18)*=(1-Parameters!B4)*(1-J18) + =IF("FY2027"="FY2026", (IF(=Scenarios!D5=1, Parameters!B9,0) + IF(=Scenarios!E5=1, Parameters!B9,0)), 0) -> 0 | N18: =IF(F18>0, L18/F18, NA()) -> 0 | O18: ==Scenarios!A5&"|FY2027" -> 0
A19: =Scenarios!A5 -> 0 | B19: FY2028 | C19: =Scenarios!C5 -> 0 | D19: =IF(=Scenarios!D5=1,0, Parameters!B6 + =ROUNDUP(=IF(=Scenarios!H5=1, IF("FY2028"="FY2026",50, IF("FY2028"="FY2027",100,150)), =Scenarios!C5)*=Scenarios!F5,0)) -> 0 | E19: =IF(=Scenarios!E5=1,0, Parameters!B7 + ==IF(=Scenarios!H5=1, IF("FY2028"="FY2026",50, IF("FY2028"="FY2027",100,150)), =Scenarios!C5)-(=ROUNDUP(=IF(=Scenarios!H5=1, IF("FY2028"="FY2026",50, IF("FY2028"="FY2027",100,150)), =Scenarios!C5)*=Scenarios!F5,0))) -> 0 | F19: =D19+E19 -> 0 | G19: =IF(=Scenarios!D5=1, IF(=Scenarios!I5="lease", Calc!D4*Parameters!D16, Calc!D4*Parameters!D19), Calc!D4) -> 0 | H19: =IF(=Scenarios!E5=1, IF(=Scenarios!I5="lease", Calc!D5*Parameters!D16, Calc!D5*Parameters!D19), Calc!D5) -> 0 | I19: =Calc!D3 -> 0 | J19: =IF("FY2028"="FY2026", (IF(=Scenarios!D5=1, Parameters!B9,0) + IF(=Scenarios!E5=1, Parameters!B9,0)), 0) -> 0 | K19: =(1-Parameters!B4) -> 0 | L19: =Scenarios!G5 -> 0 | M19: =(IF(Scenarios!D51, IF(Scenarios!I5"lease", Calc!D4*Parameters!D16, Calc!D4*Parameters!D19), Calc!D4) + IF(Scenarios!E51, IF(Scenarios!I5"lease", Calc!D5*Parameters!D16, Calc!D5*Parameters!D19), Calc!D5) + Calc!D3*=D19+E19)*=(1-Parameters!B4)*(1-J19) + =IF("FY2028"="FY2026", (IF(=Scenarios!D5=1, Parameters!B9,0) + IF(=Scenarios!E5=1, Parameters!B9,0)), 0) -> 0 | N19: =IF(F19>0, L19/F19, NA()) -> 0 | O19: ==Scenarios!A5&"|FY2028" -> 0
A20: =Scenarios!A5 -> 0 | B20: FY2029 | C20: =Scenarios!C5 -> 0 | D20: =IF(=Scenarios!D5=1,0, Parameters!B6 + =ROUNDUP(=IF(=Scenarios!H5=1, IF("FY2029"="FY2026",50, IF("FY2029"="FY2027",100,150)), =Scenarios!C5)*=Scenarios!F5,0)) -> 0 | E20: =IF(=Scenarios!E5=1,0, Parameters!B7 + ==IF(=Scenarios!H5=1, IF("FY2029"="FY2026",50, IF("FY2029"="FY2027",100,150)), =Scenarios!C5)-(=ROUNDUP(=IF(=Scenarios!H5=1, IF("FY2029"="FY2026",50, IF("FY2029"="FY2027",100,150)), =Scenarios!C5)*=Scenarios!F5,0))) -> 0 | F20: =D20+E20 -> 0 | G20: =IF(=Scenarios!D5=1, IF(=Scenarios!I5="lease", Calc!E4*Parameters!E16, Calc!E4*Parameters!E19), Calc!E4) -> 0 | H20: =IF(=Scenarios!E5=1, IF(=Scenarios!I5="lease", Calc!E5*Parameters!E16, Calc!E5*Parameters!E19), Calc!E5) -> 0 | I20: =Calc!E3 -> 0 | J20: =IF("FY2029"="FY2026", (IF(=Scenarios!D5=1, Parameters!B9,0) + IF(=Scenarios!E5=1, Parameters!B9,0)), 0) -> 0 | K20: =(1-Parameters!B4) -> 0 | L20: =Scenarios!G5 -> 0 | M20: =(IF(Scenarios!D51, IF(Scenarios!I5"lease", Calc!E4*Parameters!E16, Calc!E4*Parameters!E19), Calc!E4) + IF(Scenarios!E51, IF(Scenarios!I5"lease", Calc!E5*Parameters!E16, Calc!E5*Parameters!E19), Calc!E5) + Calc!E3*=D20+E20)*=(1-Parameters!B4)*(1-J20) + =IF("FY2029"="FY2026", (IF(=Scenarios!D5=1, Parameters!B9,0) + IF(=Scenarios!E5=1, Parameters!B9,0)), 0) -> 0 | N20: =IF(F20>0, L20/F20, NA()) -> 0 | O20: ==Scenarios!A5&"|FY2029" -> 0
A21: =Scenarios!A5 -> 0 | B21: FY2030 | C21: =Scenarios!C5 -> 0 | D21: =IF(=Scenarios!D5=1,0, Parameters!B6 + =ROUNDUP(=IF(=Scenarios!H5=1, IF("FY2030"="FY2026",50, IF("FY2030"="FY2027",100,150)), =Scenarios!C5)*=Scenarios!F5,0)) -> 0 | E21: =IF(=Scenarios!E5=1,0, Parameters!B7 + ==IF(=Scenarios!H5=1, IF("FY2030"="FY2026",50, IF("FY2030"="FY2027",100,150)), =Scenarios!C5)-(=ROUNDUP(=IF(=Scenarios!H5=1, IF("FY2030"="FY2026",50, IF("FY2030"="FY2027",100,150)), =Scenarios!C5)*=Scenarios!F5,0))) -> 0 | F21: =D21+E21 -> 0 | G21: =IF(=Scenarios!D5=1, IF(=Scenarios!I5="lease", Calc!F4*Parameters!F16, Calc!F4*Parameters!F19), Calc!F4) -> 0 | H21: =IF(=Scenarios!E5=1, IF(=Scenarios!I5="lease", Calc!F5*Parameters!F16, Calc!F5*Parameters!F19), Calc!F5) -> 0 | I21: =Calc!F3 -> 0 | J21: =IF("FY2030"="FY2026", (IF(=Scenarios!D5=1, Parameters!B9,0) + IF(=Scenarios!E5=1, Parameters!B9,0)), 0) -> 0 | K21: =(1-Parameters!B4) -> 0 | L21: =Scenarios!G5 -> 0 | M21: =(IF(Scenarios!D51, IF(Scenarios!I5"lease", Calc!F4*Parameters!F16, Calc!F4*Parameters!F19), Calc!F4) + IF(Scenarios!E51, IF(Scenarios!I5"lease", Calc!F5*Parameters!F16, Calc!F5*Parameters!F19), Calc!F5) + Calc!F3*=D21+E21)*=(1-Parameters!B4)*(1-J21) + =IF("FY2030"="FY2026", (IF(=Scenarios!D5=1, Parameters!B9,0) + IF(=Scenarios!E5=1, Parameters!B9,0)), 0) -> 0 | N21: =IF(F21>0, L21/F21, NA()) -> 0 | O21: ==Scenarios!A5&"|FY2030" -> 0
A22: =Scenarios!A6 -> 0 | B22: FY2026 | C22: =Scenarios!C6 -> 0 | D22: =IF(=Scenarios!D6=1,0, Parameters!B6 + =ROUNDUP(=IF(=Scenarios!H6=1, IF("FY2026"="FY2026",50, IF("FY2026"="FY2027",100,150)), =Scenarios!C6)*=Scenarios!F6,0)) -> 0 | E22: =IF(=Scenarios!E6=1,0, Parameters!B7 + ==IF(=Scenarios!H6=1, IF("FY2026"="FY2026",50, IF("FY2026"="FY2027",100,150)), =Scenarios!C6)-(=ROUNDUP(=IF(=Scenarios!H6=1, IF("FY2026"="FY2026",50, IF("FY2026"="FY2027",100,150)), =Scenarios!C6)*=Scenarios!F6,0))) -> 0 | F22: =D22+E22 -> 0 | G22: =IF(=Scenarios!D6=1, IF(=Scenarios!I6="lease", Calc!B4*Parameters!B16, Calc!B4*Parameters!B19), Calc!B4) -> 0 | H22: =IF(=Scenarios!E6=1, IF(=Scenarios!I6="lease", Calc!B5*Parameters!B16, Calc!B5*Parameters!B19), Calc!B5) -> 0 | I22: =Calc!B3 -> 0 | J22: =IF("FY2026"="FY2026", (IF(=Scenarios!D6=1, Parameters!B9,0) + IF(=Scenarios!E6=1, Parameters!B9,0)), 0) -> 0 | K22: =(1-Parameters!B4) -> 0 | L22: =Scenarios!G6 -> 0 | M22: =(IF(Scenarios!D61, IF(Scenarios!I6"lease", Calc!B4*Parameters!B16, Calc!B4*Parameters!B19), Calc!B4) + IF(Scenarios!E61, IF(Scenarios!I6"lease", Calc!B5*Parameters!B16, Calc!B5*Parameters!B19), Calc!B5) + Calc!B3*=D22+E22)*=(1-Parameters!B4)*(1-J22) + =IF("FY2026"="FY2026", (IF(=Scenarios!D6=1, Parameters!B9,0) + IF(=Scenarios!E6=1, Parameters!B9,0)), 0) -> 0 | N22: =IF(F22>0, L22/F22, NA()) -> 0 | O22: ==Scenarios!A6&"|FY2026" -> 0
A23: =Scenarios!A6 -> 0 | B23: FY2027 | C23: =Scenarios!C6 -> 0 | D23: =IF(=Scenarios!D6=1,0, Parameters!B6 + =ROUNDUP(=IF(=Scenarios!H6=1, IF("FY2027"="FY2026",50, IF("FY2027"="FY2027",100,150)), =Scenarios!C6)*=Scenarios!F6,0)) -> 0 | E23: =IF(=Scenarios!E6=1,0, Parameters!B7 + ==IF(=Scenarios!H6=1, IF("FY2027"="FY2026",50, IF("FY2027"="FY2027",100,150)), =Scenarios!C6)-(=ROUNDUP(=IF(=Scenarios!H6=1, IF("FY2027"="FY2026",50, IF("FY2027"="FY2027",100,150)), =Scenarios!C6)*=Scenarios!F6,0))) -> 0 | F23: =D23+E23 -> 0 | G23: =IF(=Scenarios!D6=1, IF(=Scenarios!I6="lease", Calc!C4*Parameters!C16, Calc!C4*Parameters!C19), Calc!C4) -> 0 | H23: =IF(=Scenarios!E6=1, IF(=Scenarios!I6="lease", Calc!C5*Parameters!C16, Calc!C5*Parameters!C19), Calc!C5) -> 0 | I23: =Calc!C3 -> 0 | J23: =IF("FY2027"="FY2026", (IF(=Scenarios!D6=1, Parameters!B9,0) + IF(=Scenarios!E6=1, Parameters!B9,0)), 0) -> 0 | K23: =(1-Parameters!B4) -> 0 | L23: =Scenarios!G6 -> 0 | M23: =(IF(Scenarios!D61, IF(Scenarios!I6"lease", Calc!C4*Parameters!C16, Calc!C4*Parameters!C19), Calc!C4) + IF(Scenarios!E61, IF(Scenarios!I6"lease", Calc!C5*Parameters!C16, Calc!C5*Parameters!C19), Calc!C5) + Calc!C3*=D23+E23)*=(1-Parameters!B4)*(1-J23) + =IF("FY2027"="FY2026", (IF(=Scenarios!D6=1, Parameters!B9,0) + IF(=Scenarios!E6=1, Parameters!B9,0)), 0) -> 0 | N23: =IF(F23>0, L23/F23, NA()) -> 0 | O23: ==Scenarios!A6&"|FY2027" -> 0
A24: =Scenarios!A6 -> 0 | B24: FY2028 | C24: =Scenarios!C6 -> 0 | D24: =IF(=Scenarios!D6=1,0, Parameters!B6 + =ROUNDUP(=IF(=Scenarios!H6=1, IF("FY2028"="FY2026",50, IF("FY2028"="FY2027",100,150)), =Scenarios!C6)*=Scenarios!F6,0)) -> 0 | E24: =IF(=Scenarios!E6=1,0, Parameters!B7 + ==IF(=Scenarios!H6=1, IF("FY2028"="FY2026",50, IF("FY2028"="FY2027",100,150)), =Scenarios!C6)-(=ROUNDUP(=IF(=Scenarios!H6=1, IF("FY2028"="FY2026",50, IF("FY2028"="FY2027",100,150)), =Scenarios!C6)*=Scenarios!F6,0))) -> 0 | F24: =D24+E24 -> 0 | G24: =IF(=Scenarios!D6=1, IF(=Scenarios!I6="lease", Calc!D4*Parameters!D16, Calc!D4*Parameters!D19), Calc!D4) -> 0 | H24: =IF(=Scenarios!E6=1, IF(=Scenarios!I6="lease", Calc!D5*Parameters!D16, Calc!D5*Parameters!D19), Calc!D5) -> 0 | I24: =Calc!D3 -> 0 | J24: =IF("FY2028"="FY2026", (IF(=Scenarios!D6=1, Parameters!B9,0) + IF(=Scenarios!E6=1, Parameters!B9,0)), 0) -> 0 | K24: =(1-Parameters!B4) -> 0 | L24: =Scenarios!G6 -> 0 | M24: =(IF(Scenarios!D61, IF(Scenarios!I6"lease", Calc!D4*Parameters!D16, Calc!D4*Parameters!D19), Calc!D4) + IF(Scenarios!E61, IF(Scenarios!I6"lease", Calc!D5*Parameters!D16, Calc!D5*Parameters!D19), Calc!D5) + Calc!D3*=D24+E24)*=(1-Parameters!B4)*(1-J24) + =IF("FY2028"="FY2026", (IF(=Scenarios!D6=1, Parameters!B9,0) + IF(=Scenarios!E6=1, Parameters!B9,0)), 0) -> 0 | N24: =IF(F24>0, L24/F24, NA()) -> 0 | O24: ==Scenarios!A6&"|FY2028" -> 0
A25: =Scenarios!A6 -> 0 | B25: FY2029 | C25: =Scenarios!C6 -> 0 | D25: =IF(=Scenarios!D6=1,0, Parameters!B6 + =ROUNDUP(=IF(=Scenarios!H6=1, IF("FY2029"="FY2026",50, IF("FY2029"="FY2027",100,150)), =Scenarios!C6)*=Scenarios!F6,0)) -> 0 | E25: =IF(=Scenarios!E6=1,0, Parameters!B7 + ==IF(=Scenarios!H6=1, IF("FY2029"="FY2026",50, IF("FY2029"="FY2027",100,150)), =Scenarios!C6)-(=ROUNDUP(=IF(=Scenarios!H6=1, IF("FY2029"="FY2026",50, IF("FY2029"="FY2027",100,150)), =Scenarios!C6)*=Scenarios!F6,0))) -> 0 | F25: =D25+E25 -> 0 | G25: =IF(=Scenarios!D6=1, IF(=Scenarios!I6="lease", Calc!E4*Parameters!E16, Calc!E4*Parameters!E19), Calc!E4) -> 0 | H25: =IF(=Scenarios!E6=1, IF(=Scenarios!I6="lease", Calc!E5*Parameters!E16, Calc!E5*Parameters!E19), Calc!E5) -> 0 | I25: =Calc!E3 -> 0 | J25: =IF("FY2029"="FY2026", (IF(=Scenarios!D6=1, Parameters!B9,0) + IF(=Scenarios!E6=1, Parameters!B9,0)), 0) -> 0 | K25: =(1-Parameters!B4) -> 0 | L25: =Scenarios!G6 -> 0 | M25: =(IF(Scenarios!D61, IF(Scenarios!I6"lease", Calc!E4*Parameters!E16, Calc!E4*Parameters!E19), Calc!E4) + IF(Scenarios!E61, IF(Scenarios!I6"lease", Calc!E5*Parameters!E16, Calc!E5*Parameters!E19), Calc!E5) + Calc!E3*=D25+E25)*=(1-Parameters!B4)*(1-J25) + =IF("FY2029"="FY2026", (IF(=Scenarios!D6=1, Parameters!B9,0) + IF(=Scenarios!E6=1, Parameters!B9,0)), 0) -> 0 | N25: =IF(F25>0, L25/F25, NA()) -> 0 | O25: ==Scenarios!A6&"|FY2029" -> 0
A26: =Scenarios!A6 -> 0 | B26: FY2030 | C26: =Scenarios!C6 -> 0 | D26: =IF(=Scenarios!D6=1,0, Parameters!B6 + =ROUNDUP(=IF(=Scenarios!H6=1, IF("FY2030"="FY2026",50, IF("FY2030"="FY2027",100,150)), =Scenarios!C6)*=Scenarios!F6,0)) -> 0 | E26: =IF(=Scenarios!E6=1,0, Parameters!B7 + ==IF(=Scenarios!H6=1, IF("FY2030"="FY2026",50, IF("FY2030"="FY2027",100,150)), =Scenarios!C6)-(=ROUNDUP(=IF(=Scenarios!H6=1, IF("FY2030"="FY2026",50, IF("FY2030"="FY2027",100,150)), =Scenarios!C6)*=Scenarios!F6,0))) -> 0 | F26: =D26+E26 -> 0 | G26: =IF(=Scenarios!D6=1, IF(=Scenarios!I6="lease", Calc!F4*Parameters!F16, Calc!F4*Parameters!F19), Calc!F4) -> 0 | H26: =IF(=Scenarios!E6=1, IF(=Scenarios!I6="lease", Calc!F5*Parameters!F16, Calc!F5*Parameters!F19), Calc!F5) -> 0 | I26: =Calc!F3 -> 0 | J26: =IF("FY2030"="FY2026", (IF(=Scenarios!D6=1, Parameters!B9,0) + IF(=Scenarios!E6=1, Parameters!B9,0)), 0) -> 0 | K26: =(1-Parameters!B4) -> 0 | L26: =Scenarios!G6 -> 0 | M26: =(IF(Scenarios!D61, IF(Scenarios!I6"lease", Calc!F4*Parameters!F16, Calc!F4*Parameters!F19), Calc!F4) + IF(Scenarios!E61, IF(Scenarios!I6"lease", Calc!F5*Parameters!F16, Calc!F5*Parameters!F19), Calc!F5) + Calc!F3*=D26+E26)*=(1-Parameters!B4)*(1-J26) + =IF("FY2030"="FY2026", (IF(=Scenarios!D6=1, Parameters!B9,0) + IF(=Scenarios!E6=1, Parameters!B9,0)), 0) -> 0 | N26: =IF(F26>0, L26/F26, NA()) -> 0 | O26: ==Scenarios!A6&"|FY2030" -> 0
A27: =Scenarios!A7 -> 0 | B27: FY2026 | C27: =Scenarios!C7 -> 0 | D27: =IF(=Scenarios!D7=1,0, Parameters!B6 + =ROUNDUP(=IF(=Scenarios!H7=1, IF("FY2026"="FY2026",50, IF("FY2026"="FY2027",100,150)), =Scenarios!C7)*=Scenarios!F7,0)) -> 0 | E27: =IF(=Scenarios!E7=1,0, Parameters!B7 + ==IF(=Scenarios!H7=1, IF("FY2026"="FY2026",50, IF("FY2026"="FY2027",100,150)), =Scenarios!C7)-(=ROUNDUP(=IF(=Scenarios!H7=1, IF("FY2026"="FY2026",50, IF("FY2026"="FY2027",100,150)), =Scenarios!C7)*=Scenarios!F7,0))) -> 0 | F27: =D27+E27 -> 0 | G27: =IF(=Scenarios!D7=1, IF(=Scenarios!I7="lease", Calc!B4*Parameters!B16, Calc!B4*Parameters!B19), Calc!B4) -> 0 | H27: =IF(=Scenarios!E7=1, IF(=Scenarios!I7="lease", Calc!B5*Parameters!B16, Calc!B5*Parameters!B19), Calc!B5) -> 0 | I27: =Calc!B3 -> 0 | J27: =IF("FY2026"="FY2026", (IF(=Scenarios!D7=1, Parameters!B9,0) + IF(=Scenarios!E7=1, Parameters!B9,0)), 0) -> 0 | K27: =(1-Parameters!B4) -> 0 | L27: =Scenarios!G7 -> 0 | M27: =(IF(Scenarios!D71, IF(Scenarios!I7"lease", Calc!B4*Parameters!B16, Calc!B4*Parameters!B19), Calc!B4) + IF(Scenarios!E71, IF(Scenarios!I7"lease", Calc!B5*Parameters!B16, Calc!B5*Parameters!B19), Calc!B5) + Calc!B3*=D27+E27)*=(1-Parameters!B4)*(1-J27) + =IF("FY2026"="FY2026", (IF(=Scenarios!D7=1, Parameters!B9,0) + IF(=Scenarios!E7=1, Parameters!B9,0)), 0) -> 0 | N27: =IF(F27>0, L27/F27, NA()) -> 0 | O27: ==Scenarios!A7&"|FY2026" -> 0
A28: =Scenarios!A7 -> 0 | B28: FY2027 | C28: =Scenarios!C7 -> 0 | D28: =IF(=Scenarios!D7=1,0, Parameters!B6 + =ROUNDUP(=IF(=Scenarios!H7=1, IF("FY2027"="FY2026",50, IF("FY2027"="FY2027",100,150)), =Scenarios!C7)*=Scenarios!F7,0)) -> 0 | E28: =IF(=Scenarios!E7=1,0, Parameters!B7 + ==IF(=Scenarios!H7=1, IF("FY2027"="FY2026",50, IF("FY2027"="FY2027",100,150)), =Scenarios!C7)-(=ROUNDUP(=IF(=Scenarios!H7=1, IF("FY2027"="FY2026",50, IF("FY2027"="FY2027",100,150)), =Scenarios!C7)*=Scenarios!F7,0))) -> 0 | F28: =D28+E28 -> 0 | G28: =IF(=Scenarios!D7=1, IF(=Scenarios!I7="lease", Calc!C4*Parameters!C16, Calc!C4*Parameters!C19), Calc!C4) -> 0 | H28: =IF(=Scenarios!E7=1, IF(=Scenarios!I7="lease", Calc!C5*Parameters!C16, Calc!C5*Parameters!C19), Calc!C5) -> 0 | I28: =Calc!C3 -> 0 | J28: =IF("FY2027"="FY2026", (IF(=Scenarios!D7=1, Parameters!B9,0) + IF(=Scenarios!E7=1, Parameters!B9,0)), 0) -> 0 | K28: =(1-Parameters!B4) -> 0 | L28: =Scenarios!G7 -> 0 | M28: =(IF(Scenarios!D71, IF(Scenarios!I7"lease", Calc!C4*Parameters!C16, Calc!C4*Parameters!C19), Calc!C4) + IF(Scenarios!E71, IF(Scenarios!I7"lease", Calc!C5*Parameters!C16, Calc!C5*Parameters!C19), Calc!C5) + Calc!C3*=D28+E28)*=(1-Parameters!B4)*(1-J28) + =IF("FY2027"="FY2026", (IF(=Scenarios!D7=1, Parameters!B9,0) + IF(=Scenarios!E7=1, Parameters!B9,0)), 0) -> 0 | N28: =IF(F28>0, L28/F28, NA()) -> 0 | O28: ==Scenarios!A7&"|FY2027" -> 0
A29: =Scenarios!A7 -> 0 | B29: FY2028 | C29: =Scenarios!C7 -> 0 | D29: =IF(=Scenarios!D7=1,0, Parameters!B6 + =ROUNDUP(=IF(=Scenarios!H7=1, IF("FY2028"="FY2026",50, IF("FY2028"="FY2027",100,150)), =Scenarios!C7)*=Scenarios!F7,0)) -> 0 | E29: =IF(=Scenarios!E7=1,0, Parameters!B7 + ==IF(=Scenarios!H7=1, IF("FY2028"="FY2026",50, IF("FY2028"="FY2027",100,150)), =Scenarios!C7)-(=ROUNDUP(=IF(=Scenarios!H7=1, IF("FY2028"="FY2026",50, IF("FY2028"="FY2027",100,150)), =Scenarios!C7)*=Scenarios!F7,0))) -> 0 | F29: =D29+E29 -> 0 | G29: =IF(=Scenarios!D7=1, IF(=Scenarios!I7="lease", Calc!D4*Parameters!D16, Calc!D4*Parameters!D19), Calc!D4) -> 0 | H29: =IF(=Scenarios!E7=1, IF(=Scenarios!I7="lease", Calc!D5*Parameters!D16, Calc!D5*Parameters!D19), Calc!D5) -> 0 | I29: =Calc!D3 -> 0 | J29: =IF("FY2028"="FY2026", (IF(=Scenarios!D7=1, Parameters!B9,0) + IF(=Scenarios!E7=1, Parameters!B9,0)), 0) -> 0 | K29: =(1-Parameters!B4) -> 0 | L29: =Scenarios!G7 -> 0 | M29: =(IF(Scenarios!D71, IF(Scenarios!I7"lease", Calc!D4*Parameters!D16, Calc!D4*Parameters!D19), Calc!D4) + IF(Scenarios!E71, IF(Scenarios!I7"lease", Calc!D5*Parameters!D16, Calc!D5*Parameters!D19), Calc!D5) + Calc!D3*=D29+E29)*=(1-Parameters!B4)*(1-J29) + =IF("FY2028"="FY2026", (IF(=Scenarios!D7=1, Parameters!B9,0) + IF(=Scenarios!E7=1, Parameters!B9,0)), 0) -> 0 | N29: =IF(F29>0, L29/F29, NA()) -> 0 | O29: ==Scenarios!A7&"|FY2028" -> 0
A30: =Scenarios!A7 -> 0 | B30: FY2029 | C30: =Scenarios!C7 -> 0 | D30: =IF(=Scenarios!D7=1,0, Parameters!B6 + =ROUNDUP(=IF(=Scenarios!H7=1, IF("FY2029"="FY2026",50, IF("FY2029"="FY2027",100,150)), =Scenarios!C7)*=Scenarios!F7,0)) -> 0 | E30: =IF(=Scenarios!E7=1,0, Parameters!B7 + ==IF(=Scenarios!H7=1, IF("FY2029"="FY2026",50, IF("FY2029"="FY2027",100,150)), =Scenarios!C7)-(=ROUNDUP(=IF(=Scenarios!H7=1, IF("FY2029"="FY2026",50, IF("FY2029"="FY2027",100,150)), =Scenarios!C7)*=Scenarios!F7,0))) -> 0 | F30: =D30+E30 -> 0 | G30: =IF(=Scenarios!D7=1, IF(=Scenarios!I7="lease", Calc!E4*Parameters!E16, Calc!E4*Parameters!E19), Calc!E4) -> 0 | H30: =IF(=Scenarios!E7=1, IF(=Scenarios!I7="lease", Calc!E5*Parameters!E16, Calc!E5*Parameters!E19), Calc!E5) -> 0 | I30: =Calc!E3 -> 0 | J30: =IF("FY2029"="FY2026", (IF(=Scenarios!D7=1, Parameters!B9,0) + IF(=Scenarios!E7=1, Parameters!B9,0)), 0) -> 0 | K30: =(1-Parameters!B4) -> 0 | L30: =Scenarios!G7 -> 0 | M30: =(IF(Scenarios!D71, IF(Scenarios!I7"lease", Calc!E4*Parameters!E16, Calc!E4*Parameters!E19), Calc!E4) + IF(Scenarios!E71, IF(Scenarios!I7"lease", Calc!E5*Parameters!E16, Calc!E5*Parameters!E19), Calc!E5) + Calc!E3*=D30+E30)*=(1-Parameters!B4)*(1-J30) + =IF("FY2029"="FY2026", (IF(=Scenarios!D7=1, Parameters!B9,0) + IF(=Scenarios!E7=1, Parameters!B9,0)), 0) -> 0 | N30: =IF(F30>0, L30/F30, NA()) -> 0 | O30: ==Scenarios!A7&"|FY2029" -> 0
A31: =Scenarios!A7 -> 0 | B31: FY2030 | C31: =Scenarios!C7 -> 0 | D31: =IF(=Scenarios!D7=1,0, Parameters!B6 + =ROUNDUP(=IF(=Scenarios!H7=1, IF("FY2030"="FY2026",50, IF("FY2030"="FY2027",100,150)), =Scenarios!C7)*=Scenarios!F7,0)) -> 0 | E31: =IF(=Scenarios!E7=1,0, Parameters!B7 + ==IF(=Scenarios!H7=1, IF("FY2030"="FY2026",50, IF("FY2030"="FY2027",100,150)), =Scenarios!C7)-(=ROUNDUP(=IF(=Scenarios!H7=1, IF("FY2030"="FY2026",50, IF("FY2030"="FY2027",100,150)), =Scenarios!C7)*=Scenarios!F7,0))) -> 0 | F31: =D31+E31 -> 0 | G31: =IF(=Scenarios!D7=1, IF(=Scenarios!I7="lease", Calc!F4*Parameters!F16, Calc!F4*Parameters!F19), Calc!F4) -> 0 | H31: =IF(=Scenarios!E7=1, IF(=Scenarios!I7="lease", Calc!F5*Parameters!F16, Calc!F5*Parameters!F19), Calc!F5) -> 0 | I31: =Calc!F3 -> 0 | J31: =IF("FY2030"="FY2026", (IF(=Scenarios!D7=1, Parameters!B9,0) + IF(=Scenarios!E7=1, Parameters!B9,0)), 0) -> 0 | K31: =(1-Parameters!B4) -> 0 | L31: =Scenarios!G7 -> 0 | M31: =(IF(Scenarios!D71, IF(Scenarios!I7"lease", Calc!F4*Parameters!F16, Calc!F4*Parameters!F19), Calc!F4) + IF(Scenarios!E71, IF(Scenarios!I7"lease", Calc!F5*Parameters!F16, Calc!F5*Parameters!F19), Calc!F5) + Calc!F3*=D31+E31)*=(1-Parameters!B4)*(1-J31) + =IF("FY2030"="FY2026", (IF(=Scenarios!D7=1, Parameters!B9,0) + IF(=Scenarios!E7=1, Parameters!B9,0)), 0) -> 0 | N31: =IF(F31>0, L31/F31, NA()) -> 0 | O31: ==Scenarios!A7&"|FY2030" -> 0
A32: =Scenarios!A8 -> 0 | B32: FY2026 | C32: =Scenarios!C8 -> 0 | D32: =IF(=Scenarios!D8=1,0, Parameters!B6 + =ROUNDUP(=IF(=Scenarios!H8=1, IF("FY2026"="FY2026",50, IF("FY2026"="FY2027",100,150)), =Scenarios!C8)*=Scenarios!F8,0)) -> 0 | E32: =IF(=Scenarios!E8=1,0, Parameters!B7 + ==IF(=Scenarios!H8=1, IF("FY2026"="FY2026",50, IF("FY2026"="FY2027",100,150)), =Scenarios!C8)-(=ROUNDUP(=IF(=Scenarios!H8=1, IF("FY2026"="FY2026",50, IF("FY2026"="FY2027",100,150)), =Scenarios!C8)*=Scenarios!F8,0))) -> 0 | F32: =D32+E32 -> 0 | G32: =IF(=Scenarios!D8=1, IF(=Scenarios!I8="lease", Calc!B4*Parameters!B16, Calc!B4*Parameters!B19), Calc!B4) -> 0 | H32: =IF(=Scenarios!E8=1, IF(=Scenarios!I8="lease", Calc!B5*Parameters!B16, Calc!B5*Parameters!B19), Calc!B5) -> 0 | I32: =Calc!B3 -> 0 | J32: =IF("FY2026"="FY2026", (IF(=Scenarios!D8=1, Parameters!B9,0) + IF(=Scenarios!E8=1, Parameters!B9,0)), 0) -> 0 | K32: =(1-Parameters!B4) -> 0 | L32: =Scenarios!G8 -> 0 | M32: =(IF(Scenarios!D81, IF(Scenarios!I8"lease", Calc!B4*Parameters!B16, Calc!B4*Parameters!B19), Calc!B4) + IF(Scenarios!E81, IF(Scenarios!I8"lease", Calc!B5*Parameters!B16, Calc!B5*Parameters!B19), Calc!B5) + Calc!B3*=D32+E32)*=(1-Parameters!B4)*(1-J32) + =IF("FY2026"="FY2026", (IF(=Scenarios!D8=1, Parameters!B9,0) + IF(=Scenarios!E8=1, Parameters!B9,0)), 0) -> 0 | N32: =IF(F32>0, L32/F32, NA()) -> 0 | O32: ==Scenarios!A8&"|FY2026" -> 0
A33: =Scenarios!A8 -> 0 | B33: FY2027 | C33: =Scenarios!C8 -> 0 | D33: =IF(=Scenarios!D8=1,0, Parameters!B6 + =ROUNDUP(=IF(=Scenarios!H8=1, IF("FY2027"="FY2026",50, IF("FY2027"="FY2027",100,150)), =Scenarios!C8)*=Scenarios!F8,0)) -> 0 | E33: =IF(=Scenarios!E8=1,0, Parameters!B7 + ==IF(=Scenarios!H8=1, IF("FY2027"="FY2026",50, IF("FY2027"="FY2027",100,150)), =Scenarios!C8)-(=ROUNDUP(=IF(=Scenarios!H8=1, IF("FY2027"="FY2026",50, IF("FY2027"="FY2027",100,150)), =Scenarios!C8)*=Scenarios!F8,0))) -> 0 | F33: =D33+E33 -> 0 | G33: =IF(=Scenarios!D8=1, IF(=Scenarios!I8="lease", Calc!C4*Parameters!C16, Calc!C4*Parameters!C19), Calc!C4) -> 0 | H33: =IF(=Scenarios!E8=1, IF(=Scenarios!I8="lease", Calc!C5*Parameters!C16, Calc!C5*Parameters!C19), Calc!C5) -> 0 | I33: =Calc!C3 -> 0 | J33: =IF("FY2027"="FY2026", (IF(=Scenarios!D8=1, Parameters!B9,0) + IF(=Scenarios!E8=1, Parameters!B9,0)), 0) -> 0 | K33: =(1-Parameters!B4) -> 0 | L33: =Scenarios!G8 -> 0 | M33: =(IF(Scenarios!D81, IF(Scenarios!I8"lease", Calc!C4*Parameters!C16, Calc!C4*Parameters!C19), Calc!C4) + IF(Scenarios!E81, IF(Scenarios!I8"lease", Calc!C5*Parameters!C16, Calc!C5*Parameters!C19), Calc!C5) + Calc!C3*=D33+E33)*=(1-Parameters!B4)*(1-J33) + =IF("FY2027"="FY2026", (IF(=Scenarios!D8=1, Parameters!B9,0) + IF(=Scenarios!E8=1, Parameters!B9,0)), 0) -> 0 | N33: =IF(F33>0, L33/F33, NA()) -> 0 | O33: ==Scenarios!A8&"|FY2027" -> 0
A34: =Scenarios!A8 -> 0 | B34: FY2028 | C34: =Scenarios!C8 -> 0 | D34: =IF(=Scenarios!D8=1,0, Parameters!B6 + =ROUNDUP(=IF(=Scenarios!H8=1, IF("FY2028"="FY2026",50, IF("FY2028"="FY2027",100,150)), =Scenarios!C8)*=Scenarios!F8,0)) -> 0 | E34: =IF(=Scenarios!E8=1,0, Parameters!B7 + ==IF(=Scenarios!H8=1, IF("FY2028"="FY2026",50, IF("FY2028"="FY2027",100,150)), =Scenarios!C8)-(=ROUNDUP(=IF(=Scenarios!H8=1, IF("FY2028"="FY2026",50, IF("FY2028"="FY2027",100,150)), =Scenarios!C8)*=Scenarios!F8,0))) -> 0 | F34: =D34+E34 -> 0 | G34: =IF(=Scenarios!D8=1, IF(=Scenarios!I8="lease", Calc!D4*Parameters!D16, Calc!D4*Parameters!D19), Calc!D4) -> 0 | H34: =IF(=Scenarios!E8=1, IF(=Scenarios!I8="lease", Calc!D5*Parameters!D16, Calc!D5*Parameters!D19), Calc!D5) -> 0 | I34: =Calc!D3 -> 0 | J34: =IF("FY2028"="FY2026", (IF(=Scenarios!D8=1, Parameters!B9,0) + IF(=Scenarios!E8=1, Parameters!B9,0)), 0) -> 0 | K34: =(1-Parameters!B4) -> 0 | L34: =Scenarios!G8 -> 0 | M34: =(IF(Scenarios!D81, IF(Scenarios!I8"lease", Calc!D4*Parameters!D16, Calc!D4*Parameters!D19), Calc!D4) + IF(Scenarios!E81, IF(Scenarios!I8"lease", Calc!D5*Parameters!D16, Calc!D5*Parameters!D19), Calc!D5) + Calc!D3*=D34+E34)*=(1-Parameters!B4)*(1-J34) + =IF("FY2028"="FY2026", (IF(=Scenarios!D8=1, Parameters!B9,0) + IF(=Scenarios!E8=1, Parameters!B9,0)), 0) -> 0 | N34: =IF(F34>0, L34/F34, NA()) -> 0 | O34: ==Scenarios!A8&"|FY2028" -> 0
A35: =Scenarios!A8 -> 0 | B35: FY2029 | C35: =Scenarios!C8 -> 0 | D35: =IF(=Scenarios!D8=1,0, Parameters!B6 + =ROUNDUP(=IF(=Scenarios!H8=1, IF("FY2029"="FY2026",50, IF("FY2029"="FY2027",100,150)), =Scenarios!C8)*=Scenarios!F8,0)) -> 0 | E35: =IF(=Scenarios!E8=1,0, Parameters!B7 + ==IF(=Scenarios!H8=1, IF("FY2029"="FY2026",50, IF("FY2029"="FY2027",100,150)), =Scenarios!C8)-(=ROUNDUP(=IF(=Scenarios!H8=1, IF("FY2029"="FY2026",50, IF("FY2029"="FY2027",100,150)), =Scenarios!C8)*=Scenarios!F8,0))) -> 0 | F35: =D35+E35 -> 0 | G35: =IF(=Scenarios!D8=1, IF(=Scenarios!I8="lease", Calc!E4*Parameters!E16, Calc!E4*Parameters!E19), Calc!E4) -> 0 | H35: =IF(=Scenarios!E8=1, IF(=Scenarios!I8="lease", Calc!E5*Parameters!E16, Calc!E5*Parameters!E19), Calc!E5) -> 0 | I35: =Calc!E3 -> 0 | J35: =IF("FY2029"="FY2026", (IF(=Scenarios!D8=1, Parameters!B9,0) + IF(=Scenarios!E8=1, Parameters!B9,0)), 0) -> 0 | K35: =(1-Parameters!B4) -> 0 | L35: =Scenarios!G8 -> 0 | M35: =(IF(Scenarios!D81, IF(Scenarios!I8"lease", Calc!E4*Parameters!E16, Calc!E4*Parameters!E19), Calc!E4) + IF(Scenarios!E81, IF(Scenarios!I8"lease", Calc!E5*Parameters!E16, Calc!E5*Parameters!E19), Calc!E5) + Calc!E3*=D35+E35)*=(1-Parameters!B4)*(1-J35) + =IF("FY2029"="FY2026", (IF(=Scenarios!D8=1, Parameters!B9,0) + IF(=Scenarios!E8=1, Parameters!B9,0)), 0) -> 0 | N35: =IF(F35>0, L35/F35, NA()) -> 0 | O35: ==Scenarios!A8&"|FY2029" -> 0
A36: =Scenarios!A8 -> 0 | B36: FY2030 | C36: =Scenarios!C8 -> 0 | D36: =IF(=Scenarios!D8=1,0, Parameters!B6 + =ROUNDUP(=IF(=Scenarios!H8=1, IF("FY2030"="FY2026",50, IF("FY2030"="FY2027",100,150)), =Scenarios!C8)*=Scenarios!F8,0)) -> 0 | E36: =IF(=Scenarios!E8=1,0, Parameters!B7 + ==IF(=Scenarios!H8=1, IF("FY2030"="FY2026",50, IF("FY2030"="FY2027",100,150)), =Scenarios!C8)-(=ROUNDUP(=IF(=Scenarios!H8=1, IF("FY2030"="FY2026",50, IF("FY2030"="FY2027",100,150)), =Scenarios!C8)*=Scenarios!F8,0))) -> 0 | F36: =D36+E36 -> 0 | G36: =IF(=Scenarios!D8=1, IF(=Scenarios!I8="lease", Calc!F4*Parameters!F16, Calc!F4*Parameters!F19), Calc!F4) -> 0 | H36: =IF(=Scenarios!E8=1, IF(=Scenarios!I8="lease", Calc!F5*Parameters!F16, Calc!F5*Parameters!F19), Calc!F5) -> 0 | I36: =Calc!F3 -> 0 | J36: =IF("FY2030"="FY2026", (IF(=Scenarios!D8=1, Parameters!B9,0) + IF(=Scenarios!E8=1, Parameters!B9,0)), 0) -> 0 | K36: =(1-Parameters!B4) -> 0 | L36: =Scenarios!G8 -> 0 | M36: =(IF(Scenarios!D81, IF(Scenarios!I8"lease", Calc!F4*Parameters!F16, Calc!F4*Parameters!F19), Calc!F4) + IF(Scenarios!E81, IF(Scenarios!I8"lease", Calc!F5*Parameters!F16, Calc!F5*Parameters!F19), Calc!F5) + Calc!F3*=D36+E36)*=(1-Parameters!B4)*(1-J36) + =IF("FY2030"="FY2026", (IF(=Scenarios!D8=1, Parameters!B9,0) + IF(=Scenarios!E8=1, Parameters!B9,0)), 0) -> 0 | N36: =IF(F36>0, L36/F36, NA()) -> 0 | O36: ==Scenarios!A8&"|FY2030" -> 0
A37: =Scenarios!A9 -> 0 | B37: FY2026 | C37: =Scenarios!C9 -> 0 | D37: =IF(=Scenarios!D9=1,0, Parameters!B6 + =ROUNDUP(=IF(=Scenarios!H9=1, IF("FY2026"="FY2026",50, IF("FY2026"="FY2027",100,150)), =Scenarios!C9)*=Scenarios!F9,0)) -> 0 | E37: =IF(=Scenarios!E9=1,0, Parameters!B7 + ==IF(=Scenarios!H9=1, IF("FY2026"="FY2026",50, IF("FY2026"="FY2027",100,150)), =Scenarios!C9)-(=ROUNDUP(=IF(=Scenarios!H9=1, IF("FY2026"="FY2026",50, IF("FY2026"="FY2027",100,150)), =Scenarios!C9)*=Scenarios!F9,0))) -> 0 | F37: =D37+E37 -> 0 | G37: =IF(=Scenarios!D9=1, IF(=Scenarios!I9="lease", Calc!B4*Parameters!B16, Calc!B4*Parameters!B19), Calc!B4) -> 0 | H37: =IF(=Scenarios!E9=1, IF(=Scenarios!I9="lease", Calc!B5*Parameters!B16, Calc!B5*Parameters!B19), Calc!B5) -> 0 | I37: =Calc!B3 -> 0 | J37: =IF("FY2026"="FY2026", (IF(=Scenarios!D9=1, Parameters!B9,0) + IF(=Scenarios!E9=1, Parameters!B9,0)), 0) -> 0 | K37: =(1-Parameters!B4) -> 0 | L37: =Scenarios!G9 -> 0 | M37: =(IF(Scenarios!D91, IF(Scenarios!I9"lease", Calc!B4*Parameters!B16, Calc!B4*Parameters!B19), Calc!B4) + IF(Scenarios!E91, IF(Scenarios!I9"lease", Calc!B5*Parameters!B16, Calc!B5*Parameters!B19), Calc!B5) + Calc!B3*=D37+E37)*=(1-Parameters!B4)*(1-J37) + =IF("FY2026"="FY2026", (IF(=Scenarios!D9=1, Parameters!B9,0) + IF(=Scenarios!E9=1, Parameters!B9,0)), 0) -> 0 | N37: =IF(F37>0, L37/F37, NA()) -> 0 | O37: ==Scenarios!A9&"|FY2026" -> 0
A38: =Scenarios!A9 -> 0 | B38: FY2027 | C38: =Scenarios!C9 -> 0 | D38: =IF(=Scenarios!D9=1,0, Parameters!B6 + =ROUNDUP(=IF(=Scenarios!H9=1, IF("FY2027"="FY2026",50, IF("FY2027"="FY2027",100,150)), =Scenarios!C9)*=Scenarios!F9,0)) -> 0 | E38: =IF(=Scenarios!E9=1,0, Parameters!B7 + ==IF(=Scenarios!H9=1, IF("FY2027"="FY2026",50, IF("FY2027"="FY2027",100,150)), =Scenarios!C9)-(=ROUNDUP(=IF(=Scenarios!H9=1, IF("FY2027"="FY2026",50, IF("FY2027"="FY2027",100,150)), =Scenarios!C9)*=Scenarios!F9,0))) -> 0 | F38: =D38+E38 -> 0 | G38: =IF(=Scenarios!D9=1, IF(=Scenarios!I9="lease", Calc!C4*Parameters!C16, Calc!C4*Parameters!C19), Calc!C4) -> 0 | H38: =IF(=Scenarios!E9=1, IF(=Scenarios!I9="lease", Calc!C5*Parameters!C16, Calc!C5*Parameters!C19), Calc!C5) -> 0 | I38: =Calc!C3 -> 0 | J38: =IF("FY2027"="FY2026", (IF(=Scenarios!D9=1, Parameters!B9,0) + IF(=Scenarios!E9=1, Parameters!B9,0)), 0) -> 0 | K38: =(1-Parameters!B4) -> 0 | L38: =Scenarios!G9 -> 0 | M38: =(IF(Scenarios!D91, IF(Scenarios!I9"lease", Calc!C4*Parameters!C16, Calc!C4*Parameters!C19), Calc!C4) + IF(Scenarios!E91, IF(Scenarios!I9"lease", Calc!C5*Parameters!C16, Calc!C5*Parameters!C19), Calc!C5) + Calc!C3*=D38+E38)*=(1-Parameters!B4)*(1-J38) + =IF("FY2027"="FY2026", (IF(=Scenarios!D9=1, Parameters!B9,0) + IF(=Scenarios!E9=1, Parameters!B9,0)), 0) -> 0 | N38: =IF(F38>0, L38/F38, NA()) -> 0 | O38: ==Scenarios!A9&"|FY2027" -> 0
A39: =Scenarios!A9 -> 0 | B39: FY2028 | C39: =Scenarios!C9 -> 0 | D39: =IF(=Scenarios!D9=1,0, Parameters!B6 + =ROUNDUP(=IF(=Scenarios!H9=1, IF("FY2028"="FY2026",50, IF("FY2028"="FY2027",100,150)), =Scenarios!C9)*=Scenarios!F9,0)) -> 0 | E39: =IF(=Scenarios!E9=1,0, Parameters!B7 + ==IF(=Scenarios!H9=1, IF("FY2028"="FY2026",50, IF("FY2028"="FY2027",100,150)), =Scenarios!C9)-(=ROUNDUP(=IF(=Scenarios!H9=1, IF("FY2028"="FY2026",50, IF("FY2028"="FY2027",100,150)), =Scenarios!C9)*=Scenarios!F9,0))) -> 0 | F39: =D39+E39 -> 0 | G39: =IF(=Scenarios!D9=1, IF(=Scenarios!I9="lease", Calc!D4*Parameters!D16, Calc!D4*Parameters!D19), Calc!D4) -> 0 | H39: =IF(=Scenarios!E9=1, IF(=Scenarios!I9="lease", Calc!D5*Parameters!D16, Calc!D5*Parameters!D19), Calc!D5) -> 0 | I39: =Calc!D3 -> 0 | J39: =IF("FY2028"="FY2026", (IF(=Scenarios!D9=1, Parameters!B9,0) + IF(=Scenarios!E9=1, Parameters!B9,0)), 0) -> 0 | K39: =(1-Parameters!B4) -> 0 | L39: =Scenarios!G9 -> 0 | M39: =(IF(Scenarios!D91, IF(Scenarios!I9"lease", Calc!D4*Parameters!D16, Calc!D4*Parameters!D19), Calc!D4) + IF(Scenarios!E91, IF(Scenarios!I9"lease", Calc!D5*Parameters!D16, Calc!D5*Parameters!D19), Calc!D5) + Calc!D3*=D39+E39)*=(1-Parameters!B4)*(1-J39) + =IF("FY2028"="FY2026", (IF(=Scenarios!D9=1, Parameters!B9,0) + IF(=Scenarios!E9=1, Parameters!B9,0)), 0) -> 0 | N39: =IF(F39>0, L39/F39, NA()) -> 0 | O39: ==Scenarios!A9&"|FY2028" -> 0
A40: =Scenarios!A9 -> 0 | B40: FY2029 | C40: =Scenarios!C9 -> 0 | D40: =IF(=Scenarios!D9=1,0, Parameters!B6 + =ROUNDUP(=IF(=Scenarios!H9=1, IF("FY2029"="FY2026",50, IF("FY2029"="FY2027",100,150)), =Scenarios!C9)*=Scenarios!F9,0)) -> 0 | E40: =IF(=Scenarios!E9=1,0, Parameters!B7 + ==IF(=Scenarios!H9=1, IF("FY2029"="FY2026",50, IF("FY2029"="FY2027",100,150)), =Scenarios!C9)-(=ROUNDUP(=IF(=Scenarios!H9=1, IF("FY2029"="FY2026",50, IF("FY2029"="FY2027",100,150)), =Scenarios!C9)*=Scenarios!F9,0))) -> 0 | F40: =D40+E40 -> 0 | G40: =IF(=Scenarios!D9=1, IF(=Scenarios!I9="lease", Calc!E4*Parameters!E16, Calc!E4*Parameters!E19), Calc!E4) -> 0 | H40: =IF(=Scenarios!E9=1, IF(=Scenarios!I9="lease", Calc!E5*Parameters!E16, Calc!E5*Parameters!E19), Calc!E5) -> 0 | I40: =Calc!E3 -> 0 | J40: =IF("FY2029"="FY2026", (IF(=Scenarios!D9=1, Parameters!B9,0) + IF(=Scenarios!E9=1, Parameters!B9,0)), 0) -> 0 | K40: =(1-Parameters!B4) -> 0 | L40: =Scenarios!G9 -> 0 | M40: =(IF(Scenarios!D91, IF(Scenarios!I9"lease", Calc!E4*Parameters!E16, Calc!E4*Parameters!E19), Calc!E4) + IF(Scenarios!E91, IF(Scenarios!I9"lease", Calc!E5*Parameters!E16, Calc!E5*Parameters!E19), Calc!E5) + Calc!E3*=D40+E40)*=(1-Parameters!B4)*(1-J40) + =IF("FY2029"="FY2026", (IF(=Scenarios!D9=1, Parameters!B9,0) + IF(=Scenarios!E9=1, Parameters!B9,0)), 0) -> 0 | N40: =IF(F40>0, L40/F40, NA()) -> 0 | O40: ==Scenarios!A9&"|FY2029" -> 0
...

Sheet Summary_Costs
A1: ScenarioKey | B1: Overlay | C1: Key | D1: Comparable_$FY2028 | E1: Comparable_$FY2030 | F1: Comparable_3yrAvg_$
