Workbook
Name ADM_Day_Select: Parameters_Public!C8
Name Aid_growth: BaselineCalc!B28
Name Base_Aid_per_ADM: Parameters_Public!C18
Name BaseAid_per_ADM: Parameters_Public!C18
Name Capex_ArtsHub: Parameters_Public!C28
Name Capex_in_MO_Toggle: Parameters_Public!C30
Name Capex_InnovHub: Parameters_Public!C29
Name Echo_ADM0: Parameters_Public!C10
Name Echo_ADM0_selected: Parameters_Public!C10
Name Echo_retention_r: Parameters_Public!C23
Name EchoFixed_FY25_Total: Site_Fixed!C8
Name f_lease_profile: Control_Center!$D$23:$H$23
Name f_ops_profile: Control_Center!$D$22:$H$22
Name Growth_overhead_alpha: Parameters_Public!C47
Name h_taper_profile: Control_Center!$C$22:$G$26
Name Incremental_uplift_alpha: Parameters_Public!C49
Name M_O_per_ADM_Audited: Parameters_Public!C14
Name MarginalFactor_for_Overlay: Parameters_Public!C43
Name MO_inflation: Control_Center!C6
Name Override_per_ADM_proxy: Parameters_Public!C19
Name Override_percent: Parameters_Public!C17
Name Override_toggle: Parameters_Public!C20
Name Pima_ADM0: Parameters_Public!C11
Name Pima_ADM0_selected: Parameters_Public!C11
Name Pima_retention_r: Parameters_Public!C24
Name PimaFixed_FY25_Total: Site_Fixed!C15
Name Portable_seat_cost: Parameters_Public!C34
Name TI_in_MO_Toggle: Parameters_Public!C26
Name TI_per_Site: Parameters_Public!C27
Name Uplift_base_per_ADM: Parameters_Public!C21

Sheet Workbook_Purpose_Overview

Sheet How_To_Use_The_Workbook
B1: How to use the workbook
B2: Start on Scenario_Comparison: choose two scenarios to compare; review the operational, capital, and student-related results.
B3: Test assumptions (override switch, retention r, trend flags) only if you would like to check sensitivity.
B4: Check capacity gates (receiving bands).
B5: Open Budget_Neutral_Calculator if you’re considering a non‑repurpose plan: it shows N⁰—how many students are needed to be Net ≥ 0.
B6: Look at Summary_Figures to scan all scenarios with the same signals.
B7: Use Inputs_Definitions_Sources for terms, references, and what’s still awaiting audited paste.
B8: Check What_Is_$900K_Savings if you are curious xxxxxx

Sheet Dashboard
B1: Go-forward scenario summary view* | C1: *SUSD-sourced data used wherever possible. Sources and assumptions are noted in Inputs_Definitions_Sources
B2: Choose view >> | C2: 2030
J3: SUMMARY (Selected View) | N3: INTUITION (quick read)
B4: ="FY"&IF(C2=2026, "26", IF(C2=2030, "30", "Average 2026-2030"))&" simulated P&L and capital spend by scenario" | C4: A2 | D4: B2 | E4: C2 | F4: D1 | G4: E1 | J4: Operating Net | K4: =C33 | L4: =D33 | N4: B2<C2 in FY26: Echo r lower → fewer served; h applies.
C5: Scenario A (Repurpose Both Lease) | D5: Scenario B (Repurpose Echo Lease; Grow Pima) | E5: Scenario C (Repurpose Pima Lease; Grow Echo) | F5: Scenario D (Grow Both) | G5: Scenario E (Continued Decline) | H5: Source / Confidence Level | I5: Model sensitivity | J5: Revenue | K5: =C14 | L5: =D14 | N5: Grow Both FY26 negative: Yr‑1 deficit + small overlay; improves by FY30.
B6: Baseline ADM Echo | C6: =IF($C$2=2026,C$67,IF($C$2=2030,C$103,C$67)) | D6: =IF($C$2=2026,D$67,IF($C$2=2030,D$103,D$67)) | E6: =IF($C$2=2026,E$67,IF($C$2=2030,E$103,E$67)) | F6: =IF($C$2=2026,F$67,IF($C$2=2030,F$103,F$67)) | G6: =IF($C$2=2026,G$67,IF($C$2=2030,G$103,G$67)) | H6: *** | J6: Variable M&O + h | K6: =C28 | L6: =D28
B7: Baseline ADM Pima | C7: =IF($C$2=2026,C$68,IF($C$2=2030,C$104,C$68)) | D7: =IF($C$2=2026,D$68,IF($C$2=2030,D$104,D$68)) | E7: =IF($C$2=2026,E$68,IF($C$2=2030,E$104,E$68)) | F7: =IF($C$2=2026,F$68,IF($C$2=2030,F$104,F$68)) | G7: =IF($C$2=2026,G$68,IF($C$2=2030,G$104,G$68)) | J7: Fixed M&O (net) | K7: =C31 | L7: =D31
B8: ADM change FY26 | C8: =IF($C$2=2026,C$69,IF($C$2=2030,C$105,C$69)) | D8: =IF($C$2=2026,D$69,IF($C$2=2030,D$105,D$69)) | E8: =IF($C$2=2026,E$69,IF($C$2=2030,E$105,E$69)) | F8: =IF($C$2=2026,F$69,IF($C$2=2030,F$105,F$69)) | G8: =IF($C$2=2026,G$69,IF($C$2=2030,G$105,G$69)) | J8: One-time Capital (FY26) | K8: =C36 | L8: =D36
B9: Echo retention ratio | C9: =IF($C$2=2026,C$70,IF($C$2=2030,C$106,C$70)) | D9: =IF($C$2=2026,D$70,IF($C$2=2030,D$106,D$70)) | E9: =IF($C$2=2026,E$70,IF($C$2=2030,E$106,E$70)) | F9: =IF($C$2=2026,F$70,IF($C$2=2030,F$106,F$70)) | G9: =IF($C$2=2026,G$70,IF($C$2=2030,G$106,G$70)) | H9: *
B10: Pima retention ratio | C10: =IF($C$2=2026,C$71,IF($C$2=2030,C$107,C$71)) | D10: =IF($C$2=2026,D$71,IF($C$2=2030,D$107,D$71)) | E10: =IF($C$2=2026,E$71,IF($C$2=2030,E$107,E$71)) | F10: =IF($C$2=2026,F$71,IF($C$2=2030,F$107,F$71)) | G10: =IF($C$2=2026,G$71,IF($C$2=2030,G$107,G$71)) | H10: **
B11: Number of students transitioning | C11: =IF($C$2=2026,C$72,IF($C$2=2030,C$108,C$72)) | D11: =IF($C$2=2026,D$72,IF($C$2=2030,D$108,D$72)) | E11: =IF($C$2=2026,E$72,IF($C$2=2030,E$108,E$72)) | F11: =IF($C$2=2026,F$72,IF($C$2=2030,F$108,F$72)) | G11: =IF($C$2=2026,G$72,IF($C$2=2030,G$108,G$72))
B12: Students served FY26 | C12: =IF($C$2=2026,C$73,IF($C$2=2030,C$109,C$73)) | D12: =IF($C$2=2026,D$73,IF($C$2=2030,D$109,D$73)) | E12: =IF($C$2=2026,E$73,IF($C$2=2030,E$109,E$73)) | F12: =IF($C$2=2026,F$73,IF($C$2=2030,F$109,F$73)) | G12: =IF($C$2=2026,G$73,IF($C$2=2030,G$109,G$73)) | J12: Sensitivity (Δ Net FY2030)
B13: Revenue per served student ($/ADM) | C13: =IF($C$2=2026,C$74,IF($C$2=2030,C$110,"")) | D13: =IF($C$2=2026,D$74,IF($C$2=2030,D$110,"")) | E13: =IF($C$2=2026,E$74,IF($C$2=2030,E$110,"")) | F13: =IF($C$2=2026,F$74,IF($C$2=2030,F$110,"")) | G13: =IF($C$2=2026,G$74,IF($C$2=2030,G$110,"")) | J13: Site‑Fixed ±$100k/site
B14: Total 'revenue' | C14: =IF($C$2=2026,C$75,IF($C$2=2030,C$111,C$75)) | D14: =IF($C$2=2026,D$75,IF($C$2=2030,D$111,D$75)) | E14: =IF($C$2=2026,E$75,IF($C$2=2030,E$111,E$75)) | F14: =IF($C$2=2026,F$75,IF($C$2=2030,F$111,F$75)) | G14: =IF($C$2=2026,G$75,IF($C$2=2030,G$111,G$75)) | J14: f_ops / f_lease ±0.05
B15: Districtwide gross Maint & Operations cost per non-new ADM | C15: =IF($C$2=2026,C$76,IF($C$2=2030,C$112,C$76)) | D15: =IF($C$2=2026,D$76,IF($C$2=2030,D$112,D$76)) | E15: =IF($C$2=2026,E$76,IF($C$2=2030,E$112,E$76)) | F15: =IF($C$2=2026,F$76,IF($C$2=2030,F$112,F$76)) | G15: =IF($C$2=2026,G$76,IF($C$2=2030,G$112,G$76)) | J15: Retention r ±10 pp
B16: Variable M&O per non-new student ($/ADM) | C16: =IF($C$2=2026,C$77,IF($C$2=2030,C$113,"")) | D16: =IF($C$2=2026,D$77,IF($C$2=2030,D$113,"")) | E16: =IF($C$2=2026,E$77,IF($C$2=2030,E$113,"")) | F16: =IF($C$2=2026,F$77,IF($C$2=2030,F$113,"")) | G16: =IF($C$2=2026,G$77,IF($C$2=2030,G$113,"")) | J16: MFO {0.5, 0.6, 0.8}
B17: Non-new students | C17: =IF($C$2=2026,C$78,IF($C$2=2030,C$114,C$78)) | D17: =IF($C$2=2026,D$78,IF($C$2=2030,D$114,D$78)) | E17: =IF($C$2=2026,E$78,IF($C$2=2030,E$114,E$78)) | F17: =IF($C$2=2026,F$78,IF($C$2=2030,F$114,F$78)) | G17: =IF($C$2=2026,G$78,IF($C$2=2030,G$114,G$78)) | J17: Uplift ±10%
B18: Total variable gross cost of non-new students | C18: =IF($C$2=2026,C$79,IF($C$2=2030,C$115,C$79)) | D18: =IF($C$2=2026,D$79,IF($C$2=2030,D$115,D$79)) | E18: =IF($C$2=2026,E$79,IF($C$2=2030,E$115,E$79)) | F18: =IF($C$2=2026,F$79,IF($C$2=2030,F$115,F$79)) | G18: =IF($C$2=2026,G$79,IF($C$2=2030,G$115,G$79)) | J18: After discounting estimated fixed, adjusting for inflation
B19: New students | C19: =IF($C$2=2026,C$80,IF($C$2=2030,C$116,C$80)) | D19: =IF($C$2=2026,D$80,IF($C$2=2030,D$116,D$80)) | E19: =IF($C$2=2026,E$80,IF($C$2=2030,E$116,E$80)) | F19: =IF($C$2=2026,F$80,IF($C$2=2030,F$116,F$80)) | G19: =IF($C$2=2026,G$80,IF($C$2=2030,G$116,G$80))
B20: Marginal variable cost to add new students | C20: =IF($C$2=2026,C$81,IF($C$2=2030,C$117,C$81)) | D20: =IF($C$2=2026,D$81,IF($C$2=2030,D$117,D$81)) | E20: =IF($C$2=2026,E$81,IF($C$2=2030,E$117,E$81)) | F20: =IF($C$2=2026,F$81,IF($C$2=2030,F$117,F$81)) | G20: =IF($C$2=2026,G$81,IF($C$2=2030,G$117,G$81)) | H20: ** | J20: Estimated proportion of full cost
B21: Variable gross M&O / new student | C21: =IF($C$2=2026,C$82,IF($C$2=2030,C$118,C$82)) | D21: =IF($C$2=2026,D$82,IF($C$2=2030,D$118,D$82)) | E21: =IF($C$2=2026,E$82,IF($C$2=2030,E$118,E$82)) | F21: =IF($C$2=2026,F$82,IF($C$2=2030,F$118,F$82)) | G21: =IF($C$2=2026,G$82,IF($C$2=2030,G$118,G$82)) | J21: M&O = Maintenance & Operations cost
B22: Incremental overhead per new student | C22: =IF($C$2=2026,C$83,IF($C$2=2030,C$119,C$83)) | D22: =IF($C$2=2026,D$83,IF($C$2=2030,D$119,D$83)) | E22: =IF($C$2=2026,E$83,IF($C$2=2030,E$119,E$83)) | F22: =IF($C$2=2026,F$83,IF($C$2=2030,F$119,F$83)) | G22: =IF($C$2=2026,G$83,IF($C$2=2030,G$119,G$83)) | J22: Estimted in model as proportion of repurpose transition cost
B23: Per new student cost (m + routing) | C23: =IF($C$2=2026,C$84,IF($C$2=2030,C$120,"")) | D23: =IF($C$2=2026,D$84,IF($C$2=2030,D$120,"")) | E23: =IF($C$2=2026,E$84,IF($C$2=2030,E$120,"")) | F23: =IF($C$2=2026,F$84,IF($C$2=2030,F$120,"")) | G23: =IF($C$2=2026,G$84,IF($C$2=2030,G$120,""))
B24: Total variable gross cost of new students | C24: =IF($C$2=2026,C$85,IF($C$2=2030,C$121,C$85)) | D24: =IF($C$2=2026,D$85,IF($C$2=2030,D$121,D$85)) | E24: =IF($C$2=2026,E$85,IF($C$2=2030,E$121,E$85)) | F24: =IF($C$2=2026,F$85,IF($C$2=2030,F$121,F$85)) | G24: =IF($C$2=2026,G$85,IF($C$2=2030,G$121,G$85))
B25: Total variable gross M&O cost | C25: =IF($C$2=2026,C$86,IF($C$2=2030,C$122,C$86)) | D25: =IF($C$2=2026,D$86,IF($C$2=2030,D$122,D$86)) | E25: =IF($C$2=2026,E$86,IF($C$2=2030,E$122,E$86)) | F25: =IF($C$2=2026,F$86,IF($C$2=2030,F$122,F$86)) | G25: =IF($C$2=2026,G$86,IF($C$2=2030,G$122,G$86))
B26: Transition cost (routing, transportation, etc.) FY26 | C26: =IF($C$2=2026,C$87,IF($C$2=2030,C$123,C$87)) | D26: =IF($C$2=2026,D$87,IF($C$2=2030,D$123,D$87)) | E26: =IF($C$2=2026,E$87,IF($C$2=2030,E$123,E$87)) | F26: =IF($C$2=2026,F$87,IF($C$2=2030,F$123,F$87)) | G26: =IF($C$2=2026,G$87,IF($C$2=2030,G$123,G$87)) | H26: ** | J26: Assuming adjustments in routing or other transportation investment needed for students displaced from repurpose; tapers over time
B27: Routing/Admin cost FYxx (h) | C27: =IF($C$2=2026,C$88,IF($C$2=2030,C$124,"")) | D27: =IF($C$2=2026,D$88,IF($C$2=2030,D$124,"")) | E27: =IF($C$2=2026,E$88,IF($C$2=2030,E$124,"")) | F27: =IF($C$2=2026,F$88,IF($C$2=2030,F$124,"")) | G27: =IF($C$2=2026,G$88,IF($C$2=2030,G$124,""))
B28: Total gross M&O + transition cost | C28: =IF($C$2=2026,C$89,IF($C$2=2030,C$125,C$89)) | D28: =IF($C$2=2026,D$89,IF($C$2=2030,D$125,D$89)) | E28: =IF($C$2=2026,E$89,IF($C$2=2030,E$125,E$89)) | F28: =IF($C$2=2026,F$89,IF($C$2=2030,F$125,F$89)) | G28: =IF($C$2=2026,G$89,IF($C$2=2030,G$125,G$89))
B29: Base open site fixed total | C29: =IF($C$2=2026,C$90,IF($C$2=2030,C$126,C$90)) | D29: =IF($C$2=2026,D$90,IF($C$2=2030,D$126,D$90)) | E29: =IF($C$2=2026,E$90,IF($C$2=2030,E$126,E$90)) | F29: =IF($C$2=2026,F$90,IF($C$2=2030,F$126,F$90)) | G29: =IF($C$2=2026,G$90,IF($C$2=2030,G$126,G$90)) | H29: *
B30: Estimated repurpose site fixed cost carry ratio | C30: =IF($C$2=2026,C$91,IF($C$2=2030,C$127,C$91)) | D30: =IF($C$2=2026,D$91,IF($C$2=2030,D$127,D$91)) | E30: =IF($C$2=2026,E$91,IF($C$2=2030,E$127,E$91)) | F30: =IF($C$2=2026,F$91,IF($C$2=2030,F$127,F$91)) | G30: =IF($C$2=2026,G$91,IF($C$2=2030,G$127,G$91)) | H30: **
B31: Fixed M&O (net) | C31: =IF($C$2=2026,C$92,IF($C$2=2030,C$128,"")) | D31: =IF($C$2=2026,D$92,IF($C$2=2030,D$128,"")) | E31: =IF($C$2=2026,E$92,IF($C$2=2030,E$128,"")) | F31: =IF($C$2=2026,F$92,IF($C$2=2030,F$128,"")) | G31: =IF($C$2=2026,G$92,IF($C$2=2030,G$128,""))
B32: Net total cost | C32: =IF($C$2=2026,C$93,IF($C$2=2030,C$129,C$93)) | D32: =IF($C$2=2026,D$93,IF($C$2=2030,D$129,D$93)) | E32: =IF($C$2=2026,E$93,IF($C$2=2030,E$129,E$93)) | F32: =IF($C$2=2026,F$93,IF($C$2=2030,F$129,F$93)) | G32: =IF($C$2=2026,G$93,IF($C$2=2030,G$129,G$93))
B33: Net operating $ FY26 | C33: =IF($C$2=2026,C$94,IF($C$2=2030,C$130,C$94)) | D33: =IF($C$2=2026,D$94,IF($C$2=2030,D$130,D$94)) | E33: =IF($C$2=2026,E$94,IF($C$2=2030,E$130,E$94)) | F33: =IF($C$2=2026,F$94,IF($C$2=2030,F$130,F$94)) | G33: =IF($C$2=2026,G$94,IF($C$2=2030,G$130,G$94))
B36: FY26 Capital investment | C36: =Capital_Summary!$B$77 | D36: =Capital_Summary!$B$79 | E36: =Capital_Summary!B81 | F36: =Capital_Summary!B74 | G36: =Capital_Summary!B83
B41: (Check-MultiYear_Proforma) Net operating $ / year | C41: =IF($C$2=2026,MultiYear_ProForma!$AF$32,IF($C$2=2030,MultiYear_ProForma!$AF$36,"")) | D41: =IF($C$2=2026,MultiYear_ProForma!$AF$42,IF($C$2=2030,MultiYear_ProForma!$AF$46,"")) | E41: =IF($C$2=2026,MultiYear_ProForma!$AF$52,IF($C$2=2030,MultiYear_ProForma!$AF$56,"")) | F41: =IF($C$2=2026,MultiYear_ProForma!$AF$17,IF($C$2=2030,MultiYear_ProForma!$AF$21,"")) | G41: =IF($C$2=2026,MultiYear_ProForma!$AF$62,IF($C$2=2030,MultiYear_ProForma!$AF$66,""))
B42: Difference in MYP net vs. Dashboard net | C42: =C41-C33 | D42: =D41-D33 | E42: =E41-E33 | F42: =F41-F33 | G42: =G41-G33
B43: % difference in MYP net vs. Dashboard net | C43: =C42/C41 | D43: =D42/D41 | E43: =E42/E41 | F43: =F42/F41 | G43: =G42/G41
B65: FY2026 | C65: A2 | D65: B2 | E65: C2 | F65: D1 | G65: E1
C66: Scenario A (Repurpose Both Lease) | D66: Scenario B (Repurpose Echo Lease; Grow Pima) | E66: Scenario C (Repurpose Pima Lease; Grow Echo) | F66: Scenario D (Grow Both) | G66: Scenario E (Continued Decline) | H66: Source / Confidence Level | I66: Model sensitivity | J66: Note
B67: Baseline ADM Echo | C67: =Parameters_Public!$C$10 | D67: =Parameters_Public!$C$10 | E67: =Parameters_Public!$C$10 | F67: =Parameters_Public!$C$10 | G67: =Parameters_Public!$C$10 | H67: ***
...

Sheet Working_test
B1: FY26 simulated P&L by scenario
C2: Scenario A2 (Repurpose Both Lease) | D2: Scenario D1 (Grow Both) | E2: Scenario E1 (Continued Decline) | F2: Scenario B2 (Repurpose Echo Lease; Grow Pima) | G2: Scenario C2 (Repurpose Pima Lease; Grow Echo) | H2: Source / Confidence Level
B3: Baseline ADM Echo | C3: =Parameters_Public!$C$10 | D3: =Parameters_Public!$C$10 | E3: =Parameters_Public!$C$10 | F3: =Parameters_Public!$C$10 | G3: =Parameters_Public!$C$10 | H3: ***
B4: Baseline ADM Pima | C4: =Parameters_Public!$C$11 | D4: =Parameters_Public!$C$11 | E4: =Parameters_Public!$C$11 | F4: =Parameters_Public!$C$11 | G4: =Parameters_Public!$C$11
B5: ADM change FY26 | C5: 0 | D5: =MultiYear_ProForma!$AB$17 | E5: 0 | F5: =MultiYear_ProForma!$AB$42 | G5: =MultiYear_ProForma!$AB$52
B6: r_e (Echo retention ratio) | C6: =Parameters_Public!$C$23 | D6: ="N/A" | E6: ="N/A" | F6: =Parameters_Public!$C$23 | G6: ="N/A" | H6: *
B7: r_p (Pima retention ratio) | C7: =Parameters_Public!$C$24 | D7: ="N/A" | E7: ="N/A" | F7: N/A | G7: =Parameters_Public!$C$24 | H7: **
B8: Number of students transitioning | C8: =Parameters_Public!$C$10*Parameters_Public!$C$23+Parameters_Public!$C$11*Parameters_Public!$C$24 | D8: ="N/A" | E8: ="N/A" | F8: =Parameters_Public!$C$10*Parameters_Public!$C$23 | G8: =Parameters_Public!$C$11*Parameters_Public!$C$24
B9: Students served FY26 | C9: =C8+C5 | D9: =D5+D4+D3 | E9: =E4+E3+E5 | F9: =F4+F8+F5 | G9: =G8+G3+G5
B10: Funding/student (base+override; to be conservative, small adjustment down for new students) | C10: =MultiYear_ProForma!$AD$32/Working_test!C9 | D10: =MultiYear_ProForma!$AD$17/Working_test!D9 | E10: =MultiYear_ProForma!$AD$62/Working_test!E9 | F10: =MultiYear_ProForma!$AD$42/Working_test!F9 | G10: =MultiYear_ProForma!$AD$52/Working_test!G9
B11: Implied total 'revenue' | C11: =C10*C9 | D11: =D10*D9 | E11: =E10*E9 | F11: =F10*F9 | G11: =G10*G9
B12: Districtwide gross Maintenance & Operations cost per non-new ADM | C12: =Parameters_Public!$C$14 | D12: =Parameters_Public!$C$14 | E12: =Parameters_Public!$C$14 | F12: =Parameters_Public!$C$14 | G12: =Parameters_Public!$C$14
B13: Variable cost / non-new ADM after discounting estimated fixed, adjusting for inflation | C13: =BaselineCalc!$B$18 | D13: =BaselineCalc!$B$18 | E13: =BaselineCalc!$B$18 | F13: =BaselineCalc!$B$18 | G13: =BaselineCalc!$B$18
B14: Non-new students | C14: =C8 | D14: =D3+D4 | E14: =E9 | F14: =F3+F4 | G14: =G3+G4
B15: Implied total variable gross cost of non-new students | C15: =C14*C13 | D15: =D14*D13 | E15: =E14*E13 | F15: =F14*F13 | G15: =G14*G13
B16: New students | C16: =C5 | D16: =D5 | E16: =E5 | F16: =F5 | G16: =G5
B17: Marginal variable cost to add new students (as proportion of full cost) | C17: =Parameters_Public!$C$43 | D17: =Parameters_Public!$C$43 | E17: =Parameters_Public!$C$43 | F17: =Parameters_Public!$C$43 | G17: =Parameters_Public!$C$43 | H17: **
B18: Implied variable gross M&O / new student | C18: =IFERROR((C13*C17), "N/A") | D18: =IFERROR((D13*D17), "N/A") | E18: =IFERROR((E13*E17), "N/A") | F18: =IFERROR((F13*F17), "N/A") | G18: =IFERROR((G13*G17), "N/A")
B19: Implied total variable gross cost of new students | C19: =IF(C18*C5=0, "N/A", C18*C5) | D19: =IF(D18*D5=0, "N/A", D18*D5) | E19: =IF(E18*E5=0, "N/A", E18*E5) | F19: =IF(F18*F5=0, "N/A", F18*F5) | G19: =IF(G18*G5=0, "N/A", G18*G5)
B20: Total variable gross M&O | C20: =IF(C19="N/A", 0, C19)+C15 | D20: =IF(D19="N/A", 0, D19)+D15 | E20: =IF(E19="N/A", 0, E19)+E15 | F20: =IF(F19="N/A", 0, F19)+F15 | G20: =IF(G19="N/A", 0, G19)+G15
B21: h (Transition cost (routing, transportation, etc.) FY26) | C21: ="$"&YearMap!$E$2&"/student" | D21: ="N/A" | E21: ="N/A" | F21: ="$"&YearMap!$E$2&"/student" | G21: ="$"&YearMap!$E$2&"/student" | H21: **
B22: Implied total transition cost FY26 | C22: =YearMap!$E$2*C8 | D22: ="N/A" | E22: ="N/A" | F22: =YearMap!$E$2*F8 | G22: =YearMap!$E$2*G8
B23: Total gross M&O + transition cost | C23: =C20+IF(C22="N/A", 0, C22) | D23: =D20+IF(D22="N/A", 0, D22) | E23: =E20+IF(E22="N/A", 0, E22) | F23: =F20+IF(F22="N/A", 0, F22) | G23: =G20+IF(G22="N/A", 0, G22)
B24: Base open site fixed total | C24: =Site_Fixed!$D$10+Site_Fixed!$D$17 | D24: =Site_Fixed!$D$10+Site_Fixed!$D$17 | E24: =Site_Fixed!$D$10+Site_Fixed!$D$17 | F24: =Site_Fixed!$D$10 | G24: =Site_Fixed!$D$17 | H24: *
B25: Estimated repurpose site fixed carry ratio | C25: =YearMap!$F$2 | D25: ="N/A" | E25: ="N/A" | F25: =YearMap!$F$2 | G25: =YearMap!$F$2 | H25: **
B26: Net fixed total | C26: =IFERROR(C24*(C25), C24) | D26: =IFERROR(D24*(D25), D24) | E26: =IFERROR(E24*(E25), E24) | F26: =F24+IFERROR(G24*(F25), G24) | G26: =F24+IFERROR(F24*(G25), F24)
B27: Net total cost | C27: =C26+C23 | D27: =D26+D23 | E27: =E26+E23 | F27: =F26+F23 | G27: =G26+G23
B28: Net operating $ / year FY26 | C28: =C11-C27 | D28: =D11-D27 | E28: =E11-E27 | F28: =F11-F27 | G28: =G11-G27
B31: Net cost | C31: =C23-C26
B33: Net operating $ / year FY26 | C33: =MultiYear_ProForma!$AF$32 | D33: =MultiYear_ProForma!$AF$17 | E33: =MultiYear_ProForma!$AF$62 | F33: =MultiYear_ProForma!$AF$42 | G33: =MultiYear_ProForma!$AF$52
B35: Implied fixed cost savings / student | C35: =IFERROR(C26/C9, 0) | D35: =IFERROR(D26/D9, 0) | E35: =IFERROR(E26/E9, 0) | F35: =IFERROR(F26/F9, 0) | G35: =IFERROR(G26/G9, 0)
B36: Net cost / student | C36: =C18-C35
B37: Total net cost
B39: FY26 Capital Cost | H39: **
B40: Execution Feasibility | C40: HIGH RISK (Logistics / Community) | D40: HIGH RISK (Marketing / Enrollment) | E40: LOW RISK (Passive) | F40: MEDIUM RISK | G40: MEDIUM RISK | H40: **
B41: Distinctiveness / reputation impact | C41: Very negative | D41: Very positive | E41: Positive | F41: Neutral to positive | G41: Neutral to positive
B42: District financial 'health' impact | C42: Positive | D42: Positive | E42: Negative | F42: Neutral to positive | G42: Neutral to positive
B44: h (Transition cost (routing, transportation, etc.) FY30) | C44: ="$"&YearMap!$E$6&"/student" | D44: ="N/A" | E44: ="N/A" | F44: ="$"&YearMap!$E$6&"/student" | G44: ="$"&YearMap!$E$6&"/student"
B45: Implied total transition cost FY30 | C45: =YearMap!$E$6*C8 | D45: ="N/A" | E45: ="N/A" | F45: =YearMap!$E$6*F8 | G45: =YearMap!$E$6*G8
B47: f_lease (Proportion of fixed cost carried FY30) | C47: =YearMap!$F$6 | D47: ="N/A" | E47: ="N/A" | F47: =YearMap!$F$6 | G47: =YearMap!$F$6 | H47: **
...

Sheet Scenario_Comparison
B1: Echo & Pima — Go-forward scenario comparison view
B3: Scenarios (CHOOSE) | C3: Description | I3: Assumed enrollment change (over 3 yrs)
B4: A2_Repurpose_Both_lease | C4: =VLOOKUP($B4,Scenarios!$A$2:$C$15, 2, 0) | J4: =IF(ROUND(SUMIFS(MultiYear_ProForma!$AC:$AC,MultiYear_ProForma!$B:$B,$B4,MultiYear_ProForma!$C:$C,"FY2030")-BaselineCalc!$B$9, 0)>0, "+"&ROUND(SUMIFS(MultiYear_ProForma!$AC:$AC,MultiYear_ProForma!$B:$B,$B4,MultiYear_ProForma!$C:$C,"FY2030")-BaselineCalc!$B$9, 0), ROUND(SUMIFS(MultiYear_ProForma!$AC:$AC,MultiYear_ProForma!$B:$B,$B4,MultiYear_ProForma!$C:$C,"FY2030")-BaselineCalc!$B$9, 0))
B5: E1_StatusQuo_Decline | C5: =VLOOKUP($B5,Scenarios!$A$2:$C$15, 2, 0) | J5: =IF(ROUND(SUMIFS(MultiYear_ProForma!$AC:$AC,MultiYear_ProForma!$B:$B,$B5,MultiYear_ProForma!$C:$C,"FY2030")-BaselineCalc!$B$9, 0)>0, "+"&ROUND(SUMIFS(MultiYear_ProForma!$AC:$AC,MultiYear_ProForma!$B:$B,$B5,MultiYear_ProForma!$C:$C,"FY2030")-BaselineCalc!$B$9, 0), ROUND(SUMIFS(MultiYear_ProForma!$AC:$AC,MultiYear_ProForma!$B:$B,$B5,MultiYear_ProForma!$C:$C,"FY2030")-BaselineCalc!$B$9, 0))
B24: Notes: Assumptions reflect: r (retention assumptions), override, marginal factor (e.g. assumed reduced variable cost to add new students), trend flags; h (receiving schools transportation route adjustment premium) tapers yearly. Receiving site should not exceed spare seats + portables
B26: Year | C26: Operating Net$ (Base) | D26: Operating Net$ (Comparator)
B27: FY2026 | C27: =SUMIFS(MultiYear_ProForma!$AF$2:$AF$66, MultiYear_ProForma!$B$2:$B$66, $B$4, MultiYear_ProForma!$C$2:$C$66, "FY2026") | D27: =SUMIFS(MultiYear_ProForma!$AF$2:$AF$66, MultiYear_ProForma!$B$2:$B$66, $B$5, MultiYear_ProForma!$C$2:$C$66, "FY2026")
B28: FY2027 | C28: =SUMIFS(MultiYear_ProForma!$AF$2:$AF$66, MultiYear_ProForma!$B$2:$B$66, $B$4, MultiYear_ProForma!$C$2:$C$66, "FY2027") | D28: =SUMIFS(MultiYear_ProForma!$AF$2:$AF$66, MultiYear_ProForma!$B$2:$B$66, $B$5, MultiYear_ProForma!$C$2:$C$66, "FY2027")
B29: FY2028 | C29: =SUMIFS(MultiYear_ProForma!$AF$2:$AF$66, MultiYear_ProForma!$B$2:$B$66, $B$4, MultiYear_ProForma!$C$2:$C$66, "FY2028") | D29: =SUMIFS(MultiYear_ProForma!$AF$2:$AF$66, MultiYear_ProForma!$B$2:$B$66, $B$5, MultiYear_ProForma!$C$2:$C$66, "FY2028")
B30: FY2029 | C30: =SUMIFS(MultiYear_ProForma!$AF$2:$AF$66, MultiYear_ProForma!$B$2:$B$66, $B$4, MultiYear_ProForma!$C$2:$C$66, "FY2029") | D30: =SUMIFS(MultiYear_ProForma!$AF$2:$AF$66, MultiYear_ProForma!$B$2:$B$66, $B$5, MultiYear_ProForma!$C$2:$C$66, "FY2029")
B31: FY2030 | C31: =SUMIFS(MultiYear_ProForma!$AF$2:$AF$66, MultiYear_ProForma!$B$2:$B$66, $B$4, MultiYear_ProForma!$C$2:$C$66, "FY2030") | D31: =SUMIFS(MultiYear_ProForma!$AF$2:$AF$66, MultiYear_ProForma!$B$2:$B$66, $B$5, MultiYear_ProForma!$C$2:$C$66, "FY2030")
B33: Assumptions (from Parameters_Public / Control_Center)
B34: Retention r (Echo central) | C34: =Parameters_Public!C23
B35: Retention r (Pima central) | C35: =Parameters_Public!C24
B36: MarginalFactor_for_Overlay | C36: =Parameters_Public!C43
B37: Override % | C37: =Parameters_Public!C17
B38: Override toggle (0/1) | C38: =Parameters_Public!C20
B39: Keep-open ops savings (fraction of MO) | C39: =Control_Center!C10
B40: Extra savings for co-location (fraction of MO) | C40: =Control_Center!C11
B41: • Routing/admin overhead h tapers by year (see YearMap). Try ±20% sensitivity when routing assumptions are uncertain.
D43: Interpretation
B44: One-time Capital FY 2026 (Base) | C44: =SUMIFS(Capital_Summary!$H$4:$H$83, Capital_Summary!$A$4:$A$83, B4, Capital_Summary!$B$4:$B$83, "FY2026") | D44: =""&$B$5&" will be $"&TEXT(ROUND(ABS(C45-C44),0), "#,##0")&" "&IF(C45>C44,"MORE COSTLY","LESS COSTLY")&" than "&$B$4&" in terms of capital investment required "
B45: One-time Capital FY 2026 (Comparator) | C45: =SUMIFS(Capital_Summary!$H$4:$H$83, Capital_Summary!$A$4:$A$83, B5, Capital_Summary!$B$4:$B$83, "FY2026")
B47: Avg Net (FY26–30) (Base)—rounded | C47: =ROUND((SUMIFS(MultiYear_ProForma!$AF$2:$AF$66,MultiYear_ProForma!$B$2:$B$66,$B$4,MultiYear_ProForma!$C$2:$C$66,"FY2026")+SUMIFS(MultiYear_ProForma!$AF$2:$AF$66,MultiYear_ProForma!$B$2:$B$66,$B$4,MultiYear_ProForma!$C$2:$C$66,"FY2027")+SUMIFS(MultiYear_ProForma!$AF$2:$AF$66,MultiYear_ProForma!$B$2:$B$66,$B$4,MultiYear_ProForma!$C$2:$C$66,"FY2028")+SUMIFS(MultiYear_ProForma!$AF$2:$AF$66,MultiYear_ProForma!$B$2:$B$66,$B$4,MultiYear_ProForma!$C$2:$C$66,"FY2029")+SUMIFS(MultiYear_ProForma!$AF$2:$AF$66,MultiYear_ProForma!$B$2:$B$66,$B$4,MultiYear_ProForma!$C$2:$C$66,"FY2030"))/5,-4) | D47: ="On average from 2026 through 2030, "&$B$5&" will be $"&TEXT(ABS(ROUND(C49,0)), "#,##0")&" "&IF(C49<0,"MORE COSTLY","LESS COSTLY")&" to operate annually than "&$B$4&""
B48: Avg Net (FY26–30) (Comparator)—rounded | C48: =ROUND((SUMIFS(MultiYear_ProForma!$AF$2:$AF$66, MultiYear_ProForma!$B$2:$B$66, $B$5, MultiYear_ProForma!$C$2:$C$66, "FY2026")+SUMIFS(MultiYear_ProForma!$AF$2:$AF$66, MultiYear_ProForma!$B$2:$B$66, $C$5, MultiYear_ProForma!$C$2:$C$66, "FY2027")+SUMIFS(MultiYear_ProForma!$AF$2:$AF$66, MultiYear_ProForma!$B$2:$B$66, $B$5, MultiYear_ProForma!$C$2:$C$66, "FY2028")+SUMIFS(MultiYear_ProForma!$AF$2:$AF$66, MultiYear_ProForma!$B$2:$B$66, $B$5, MultiYear_ProForma!$C$2:$C$66, "FY2029")+SUMIFS(MultiYear_ProForma!$AF$2:$AF$66, MultiYear_ProForma!$B$2:$B$66, $B$5, MultiYear_ProForma!$C$2:$C$66, "FY2030"))/5, -4)
B49: Δ vs Base (Avg FY26–30)—rounded | C49: =ROUND(C48-C47, -4)
B52: FY2030 Net (Base)—rounded | C52: =ROUND(SUMIFS(MultiYear_ProForma!$AF$2:$AF$66, MultiYear_ProForma!$B$2:$B$66, $B$4, MultiYear_ProForma!$C$2:$C$66, "FY2030"), -4) | D52: ="By 2030, "&$B$5&" will be $"&TEXT(ABS(ROUND(C54,0)), "#,##0")&" "&IF(C54<0,"MORE COSTLY","LESS COSTLY")&" to operate annually than "&$B$4&""
B53: FY2030 Net (Comparator)—rounded | C53: =ROUND(SUMIFS(MultiYear_ProForma!$AF$2:$AF$66, MultiYear_ProForma!$B$2:$B$66, $B$5, MultiYear_ProForma!$C$2:$C$66, "FY2030"), -4)
B54: Δ vs Base (FY2030)—rounded | C54: =ROUND(C53-C52, -4)
B56: Students displaced (FY26) (Base) | C56: =SUMIFS(MultiYear_ProForma!$N$2:$N$66, MultiYear_ProForma!$B$2:$B$66, $B$4, MultiYear_ProForma!$C$2:$C$66, "FY2026") | D56: =""&$B$5&" will displace "&ROUND(ABS(C57-C56),0)&" "&IF(C57>C56,"MORE STUDENTS","FEWER STUDENTS")&" than "&$B$4&""
B57: Students displaced (FY26) (Comparator) | C57: =SUMIFS(MultiYear_ProForma!$N$2:$N$66, MultiYear_ProForma!$B$2:$B$66, $B$5, MultiYear_ProForma!$C$2:$C$66, "FY2026")
B59: Students served (FY2030) (Base) | C59: =SUMIFS(MultiYear_ProForma!$AC$2:$AC$66, MultiYear_ProForma!$B$2:$B$66, $B$4, MultiYear_ProForma!$C$2:$C$66, "FY2030") | D59: =""&$B$5&" will serve "&ROUND(ABS(C60-C59),0)&" "&IF(C60>C59,"MORE STUDENTS","FEWER STUDENTS")&" than "&$B$4&""
B60: Students served (FY2030) (Comparator) | C60: =SUMIFS(MultiYear_ProForma!$AC$2:$AC$66, MultiYear_ProForma!$B$2:$B$66, $B$5, MultiYear_ProForma!$C$2:$C$66, "FY2030")

Sheet Budget_Neutral_Calculator
B1: Budget‑Neutral Calculator (Operating $)
B3: Scenario (Choose one): | C3: E1_StatusQuo_Decline
B5: Metric | C5: FY2026 | D5: FY2030
B6: mᵗ: Incremental margin per added ADM | C6: =INDEX(YearMap!$I$2:$I$6, MATCH("FY2026",YearMap!$A$2:$A$6,0))+IF(Override_toggle=1, INDEX(YearMap!$O$2:$O$6, MATCH("FY2026",YearMap!$A$2:$A$6,0)),0)+INDEX(YearMap!$P$2:$P$6, MATCH("FY2026",YearMap!$A$2:$A$6,0))-INDEX(YearMap!$B$2:$B$6, MATCH("FY2026",YearMap!$A$2:$A$6,0))-INDEX(YearMap!$Q$2:$Q$6, MATCH("FY2026",YearMap!$A$2:$A$6,0)) | D6: =INDEX(YearMap!$I$2:$I$6, MATCH("FY2030",YearMap!$A$2:$A$6,0))+IF(Override_toggle=1, INDEX(YearMap!$O$2:$O$6, MATCH("FY2030",YearMap!$A$2:$A$6,0)),0)+INDEX(YearMap!$P$2:$P$6, MATCH("FY2030",YearMap!$A$2:$A$6,0))-INDEX(YearMap!$B$2:$B$6, MATCH("FY2030",YearMap!$A$2:$A$6,0))-INDEX(YearMap!$Q$2:$Q$6, MATCH("FY2030",YearMap!$A$2:$A$6,0))
B7: Net (operating) | C7: =SUMIFS(MultiYear_ProForma!$AF$2:$AF$66,MultiYear_ProForma!$B$2:$B$66,$C$3,MultiYear_ProForma!$C$2:$C$66,"FY2026") | D7: =SUMIFS(MultiYear_ProForma!$AF$2:$AF$66,MultiYear_ProForma!$B$2:$B$66,$C$3,MultiYear_ProForma!$C$2:$C$66,"FY2030")
B8: N⁰: Additional students needed for Net ≥ 0 | C8: =IFERROR(MAX(0,-$C$7/$C$6),"") | D8: =IFERROR(MAX(0,-$D$7/$D$6),"")
B10: Interpretation
B11: =IF(D8=0, "The "&C3&" is budget neutral or better given current assumptions in the model; additional enrollment is not necessary.", "Given current assumptions in the model, to be budget neutral by FY2030, the "&C3&" scenario requires enrollment of "&ROUND(D8, 0)&" additional students.")
B13: Notes:
B14: This tool tests budget neutrality for any scenario: N⁰ = max(0, −Netₜ / mᵗ).
B15: mᵗ uses YearMap (Aid + Override_if_on + Uplift − VarUnit$ − Growth_overhead). Net excludes capital.

Sheet Summary_Figures
B1: Choose base scenario (for comparison): | C1: E1_StatusQuo_Decline | P1: Chart titles
A2: Net = (M&O operating) − (Aid + Override + Uplift). Capital is excluded. Uplift is indexed to Aid growth. | P2: ="(Comparison) Change in ops net $ by scenario compared to "&C1&" (Positive = savings)"
A3: Students: Displaced = FY2026; Served = FY2030 (open + retained). | P3: ="(Nominal) One-time capital (FY26) & Average 5-yr net ops $ by scenario"
A4: Scenario key | B4: Scenario | C4: One-time Capital (FY26) | D4: Net FY26 Operational $ | E4: Net FY28 Operational $ | F4: Net FY30 Operational $ | G4: AVG 5-yr net operational $ | H4: 5-yr Operating Net $ (sum FY26-30) | I4: Displaced students | J4: Served students FY30 | K4: Net Op $ / Served (FY2030) | L4: Δ vs Base (FY2030 Net) | M4: Δ vs Base (5-yr Avg Net)
A5: =LEFT(B5, 2) | B5: =Scenarios!A3 | C5: =SUMIFS(Capital_Summary!$H$4:$H$83, Capital_Summary!$A$4:$A$83, B5, Capital_Summary!$B$4:$B$83, "FY2026")*-1 | D5: =SUMIFS(MultiYear_ProForma!$AF$2:$AF$66, MultiYear_ProForma!$B$2:$B$66, B5, MultiYear_ProForma!$C$2:$C$66, "FY2026") | E5: =SUMIFS(MultiYear_ProForma!$AF$2:$AF$66, MultiYear_ProForma!$B$2:$B$66, B5, MultiYear_ProForma!$C$2:$C$66, "FY2028") | F5: =SUMIFS(MultiYear_ProForma!$AF$2:$AF$66, MultiYear_ProForma!$B$2:$B$66, B5, MultiYear_ProForma!$C$2:$C$66, "FY2030") | G5: =(SUMIFS(MultiYear_ProForma!$AF$2:$AF$66, MultiYear_ProForma!$B$2:$B$66, B5, MultiYear_ProForma!$C$2:$C$66, "FY2026")+SUMIFS(MultiYear_ProForma!$AF$2:$AF$66, MultiYear_ProForma!$B$2:$B$66, B5, MultiYear_ProForma!$C$2:$C$66, "FY2027")+SUMIFS(MultiYear_ProForma!$AF$2:$AF$66, MultiYear_ProForma!$B$2:$B$66, B5, MultiYear_ProForma!$C$2:$C$66, "FY2028")+SUMIFS(MultiYear_ProForma!$AF$2:$AF$66, MultiYear_ProForma!$B$2:$B$66, B5, MultiYear_ProForma!$C$2:$C$66, "FY2029")+SUMIFS(MultiYear_ProForma!$AF$2:$AF$66, MultiYear_ProForma!$B$2:$B$66, B5, MultiYear_ProForma!$C$2:$C$66, "FY2030"))/5 | H5: =(SUMIFS(MultiYear_ProForma!$AF$2:$AF$66, MultiYear_ProForma!$B$2:$B$66, B5, MultiYear_ProForma!$C$2:$C$66, "FY2026")+SUMIFS(MultiYear_ProForma!$AF$2:$AF$66, MultiYear_ProForma!$B$2:$B$66, B5, MultiYear_ProForma!$C$2:$C$66, "FY2027")+SUMIFS(MultiYear_ProForma!$AF$2:$AF$66, MultiYear_ProForma!$B$2:$B$66, B5, MultiYear_ProForma!$C$2:$C$66, "FY2028")+SUMIFS(MultiYear_ProForma!$AF$2:$AF$66, MultiYear_ProForma!$B$2:$B$66, B5, MultiYear_ProForma!$C$2:$C$66, "FY2029")+SUMIFS(MultiYear_ProForma!$AF$2:$AF$66, MultiYear_ProForma!$B$2:$B$66, B5, MultiYear_ProForma!$C$2:$C$66, "FY2030")) | I5: =SUMIFS(MultiYear_ProForma!$N$2:$N$66, MultiYear_ProForma!$B$2:$B$66, B5, MultiYear_ProForma!$C$2:$C$66, "FY2026") | J5: =SUMIFS(MultiYear_ProForma!$AC$2:$AC$66, MultiYear_ProForma!$B$2:$B$66, B5, MultiYear_ProForma!$C$2:$C$66, "FY2030") | K5: =F5/J5 | L5: =F5-(VLOOKUP($C$1,$B$5:$G$17,5, 0)) | M5: =G5-(VLOOKUP($C$1,$B$5:$J$17,6, 0))
A6: =LEFT(B6, 2) | B6: =Scenarios!A4 | C6: =SUMIFS(Capital_Summary!$H$4:$H$83, Capital_Summary!$A$4:$A$83, B6, Capital_Summary!$B$4:$B$83, "FY2026")*-1 | D6: =SUMIFS(MultiYear_ProForma!$AF$2:$AF$66, MultiYear_ProForma!$B$2:$B$66, B6, MultiYear_ProForma!$C$2:$C$66, "FY2026") | E6: =SUMIFS(MultiYear_ProForma!$AF$2:$AF$66, MultiYear_ProForma!$B$2:$B$66, B6, MultiYear_ProForma!$C$2:$C$66, "FY2028") | F6: =SUMIFS(MultiYear_ProForma!$AF$2:$AF$66, MultiYear_ProForma!$B$2:$B$66, B6, MultiYear_ProForma!$C$2:$C$66, "FY2030") | G6: =(SUMIFS(MultiYear_ProForma!$AF$2:$AF$66, MultiYear_ProForma!$B$2:$B$66, B6, MultiYear_ProForma!$C$2:$C$66, "FY2026")+SUMIFS(MultiYear_ProForma!$AF$2:$AF$66, MultiYear_ProForma!$B$2:$B$66, B6, MultiYear_ProForma!$C$2:$C$66, "FY2027")+SUMIFS(MultiYear_ProForma!$AF$2:$AF$66, MultiYear_ProForma!$B$2:$B$66, B6, MultiYear_ProForma!$C$2:$C$66, "FY2028")+SUMIFS(MultiYear_ProForma!$AF$2:$AF$66, MultiYear_ProForma!$B$2:$B$66, B6, MultiYear_ProForma!$C$2:$C$66, "FY2029")+SUMIFS(MultiYear_ProForma!$AF$2:$AF$66, MultiYear_ProForma!$B$2:$B$66, B6, MultiYear_ProForma!$C$2:$C$66, "FY2030"))/5 | H6: =(SUMIFS(MultiYear_ProForma!$AF$2:$AF$66, MultiYear_ProForma!$B$2:$B$66, B6, MultiYear_ProForma!$C$2:$C$66, "FY2026")+SUMIFS(MultiYear_ProForma!$AF$2:$AF$66, MultiYear_ProForma!$B$2:$B$66, B6, MultiYear_ProForma!$C$2:$C$66, "FY2027")+SUMIFS(MultiYear_ProForma!$AF$2:$AF$66, MultiYear_ProForma!$B$2:$B$66, B6, MultiYear_ProForma!$C$2:$C$66, "FY2028")+SUMIFS(MultiYear_ProForma!$AF$2:$AF$66, MultiYear_ProForma!$B$2:$B$66, B6, MultiYear_ProForma!$C$2:$C$66, "FY2029")+SUMIFS(MultiYear_ProForma!$AF$2:$AF$66, MultiYear_ProForma!$B$2:$B$66, B6, MultiYear_ProForma!$C$2:$C$66, "FY2030")) | I6: =SUMIFS(MultiYear_ProForma!$N$2:$N$66, MultiYear_ProForma!$B$2:$B$66, B6, MultiYear_ProForma!$C$2:$C$66, "FY2026") | J6: =SUMIFS(MultiYear_ProForma!$AC$2:$AC$66, MultiYear_ProForma!$B$2:$B$66, B6, MultiYear_ProForma!$C$2:$C$66, "FY2030") | K6: =F6/J6 | L6: =F6-(VLOOKUP($C$1,$B$5:$G$17,5, 0)) | M6: =G6-(VLOOKUP($C$1,$B$5:$J$17,6, 0))
A7: =LEFT(B7, 2) | B7: =Scenarios!A5 | C7: =SUMIFS(Capital_Summary!$H$4:$H$83, Capital_Summary!$A$4:$A$83, B7, Capital_Summary!$B$4:$B$83, "FY2026")*-1 | D7: =SUMIFS(MultiYear_ProForma!$AF$2:$AF$66, MultiYear_ProForma!$B$2:$B$66, B7, MultiYear_ProForma!$C$2:$C$66, "FY2026") | E7: =SUMIFS(MultiYear_ProForma!$AF$2:$AF$66, MultiYear_ProForma!$B$2:$B$66, B7, MultiYear_ProForma!$C$2:$C$66, "FY2028") | F7: =SUMIFS(MultiYear_ProForma!$AF$2:$AF$66, MultiYear_ProForma!$B$2:$B$66, B7, MultiYear_ProForma!$C$2:$C$66, "FY2030") | G7: =(SUMIFS(MultiYear_ProForma!$AF$2:$AF$66, MultiYear_ProForma!$B$2:$B$66, B7, MultiYear_ProForma!$C$2:$C$66, "FY2026")+SUMIFS(MultiYear_ProForma!$AF$2:$AF$66, MultiYear_ProForma!$B$2:$B$66, B7, MultiYear_ProForma!$C$2:$C$66, "FY2027")+SUMIFS(MultiYear_ProForma!$AF$2:$AF$66, MultiYear_ProForma!$B$2:$B$66, B7, MultiYear_ProForma!$C$2:$C$66, "FY2028")+SUMIFS(MultiYear_ProForma!$AF$2:$AF$66, MultiYear_ProForma!$B$2:$B$66, B7, MultiYear_ProForma!$C$2:$C$66, "FY2029")+SUMIFS(MultiYear_ProForma!$AF$2:$AF$66, MultiYear_ProForma!$B$2:$B$66, B7, MultiYear_ProForma!$C$2:$C$66, "FY2030"))/5 | H7: =(SUMIFS(MultiYear_ProForma!$AF$2:$AF$66, MultiYear_ProForma!$B$2:$B$66, B7, MultiYear_ProForma!$C$2:$C$66, "FY2026")+SUMIFS(MultiYear_ProForma!$AF$2:$AF$66, MultiYear_ProForma!$B$2:$B$66, B7, MultiYear_ProForma!$C$2:$C$66, "FY2027")+SUMIFS(MultiYear_ProForma!$AF$2:$AF$66, MultiYear_ProForma!$B$2:$B$66, B7, MultiYear_ProForma!$C$2:$C$66, "FY2028")+SUMIFS(MultiYear_ProForma!$AF$2:$AF$66, MultiYear_ProForma!$B$2:$B$66, B7, MultiYear_ProForma!$C$2:$C$66, "FY2029")+SUMIFS(MultiYear_ProForma!$AF$2:$AF$66, MultiYear_ProForma!$B$2:$B$66, B7, MultiYear_ProForma!$C$2:$C$66, "FY2030")) | I7: =SUMIFS(MultiYear_ProForma!$N$2:$N$66, MultiYear_ProForma!$B$2:$B$66, B7, MultiYear_ProForma!$C$2:$C$66, "FY2026") | J7: =SUMIFS(MultiYear_ProForma!$AC$2:$AC$66, MultiYear_ProForma!$B$2:$B$66, B7, MultiYear_ProForma!$C$2:$C$66, "FY2030") | K7: =F7/J7 | L7: =F7-(VLOOKUP($C$1,$B$5:$G$17,5, 0)) | M7: =G7-(VLOOKUP($C$1,$B$5:$J$17,6, 0))
A8: =LEFT(B8, 2) | B8: =Scenarios!A6 | C8: =SUMIFS(Capital_Summary!$H$4:$H$83, Capital_Summary!$A$4:$A$83, B8, Capital_Summary!$B$4:$B$83, "FY2026")*-1 | D8: =SUMIFS(MultiYear_ProForma!$AF$2:$AF$66, MultiYear_ProForma!$B$2:$B$66, B8, MultiYear_ProForma!$C$2:$C$66, "FY2026") | E8: =SUMIFS(MultiYear_ProForma!$AF$2:$AF$66, MultiYear_ProForma!$B$2:$B$66, B8, MultiYear_ProForma!$C$2:$C$66, "FY2028") | F8: =SUMIFS(MultiYear_ProForma!$AF$2:$AF$66, MultiYear_ProForma!$B$2:$B$66, B8, MultiYear_ProForma!$C$2:$C$66, "FY2030") | G8: =(SUMIFS(MultiYear_ProForma!$AF$2:$AF$66, MultiYear_ProForma!$B$2:$B$66, B8, MultiYear_ProForma!$C$2:$C$66, "FY2026")+SUMIFS(MultiYear_ProForma!$AF$2:$AF$66, MultiYear_ProForma!$B$2:$B$66, B8, MultiYear_ProForma!$C$2:$C$66, "FY2027")+SUMIFS(MultiYear_ProForma!$AF$2:$AF$66, MultiYear_ProForma!$B$2:$B$66, B8, MultiYear_ProForma!$C$2:$C$66, "FY2028")+SUMIFS(MultiYear_ProForma!$AF$2:$AF$66, MultiYear_ProForma!$B$2:$B$66, B8, MultiYear_ProForma!$C$2:$C$66, "FY2029")+SUMIFS(MultiYear_ProForma!$AF$2:$AF$66, MultiYear_ProForma!$B$2:$B$66, B8, MultiYear_ProForma!$C$2:$C$66, "FY2030"))/5 | H8: =(SUMIFS(MultiYear_ProForma!$AF$2:$AF$66, MultiYear_ProForma!$B$2:$B$66, B8, MultiYear_ProForma!$C$2:$C$66, "FY2026")+SUMIFS(MultiYear_ProForma!$AF$2:$AF$66, MultiYear_ProForma!$B$2:$B$66, B8, MultiYear_ProForma!$C$2:$C$66, "FY2027")+SUMIFS(MultiYear_ProForma!$AF$2:$AF$66, MultiYear_ProForma!$B$2:$B$66, B8, MultiYear_ProForma!$C$2:$C$66, "FY2028")+SUMIFS(MultiYear_ProForma!$AF$2:$AF$66, MultiYear_ProForma!$B$2:$B$66, B8, MultiYear_ProForma!$C$2:$C$66, "FY2029")+SUMIFS(MultiYear_ProForma!$AF$2:$AF$66, MultiYear_ProForma!$B$2:$B$66, B8, MultiYear_ProForma!$C$2:$C$66, "FY2030")) | I8: =SUMIFS(MultiYear_ProForma!$N$2:$N$66, MultiYear_ProForma!$B$2:$B$66, B8, MultiYear_ProForma!$C$2:$C$66, "FY2026") | J8: =SUMIFS(MultiYear_ProForma!$AC$2:$AC$66, MultiYear_ProForma!$B$2:$B$66, B8, MultiYear_ProForma!$C$2:$C$66, "FY2030") | K8: =F8/J8 | L8: =F8-(VLOOKUP($C$1,$B$5:$G$17,5, 0)) | M8: =G8-(VLOOKUP($C$1,$B$5:$J$17,6, 0))
A9: =LEFT(B9, 2) | B9: =Scenarios!A7 | C9: =SUMIFS(Capital_Summary!$H$4:$H$83, Capital_Summary!$A$4:$A$83, B9, Capital_Summary!$B$4:$B$83, "FY2026")*-1 | D9: =SUMIFS(MultiYear_ProForma!$AF$2:$AF$66, MultiYear_ProForma!$B$2:$B$66, B9, MultiYear_ProForma!$C$2:$C$66, "FY2026") | E9: =SUMIFS(MultiYear_ProForma!$AF$2:$AF$66, MultiYear_ProForma!$B$2:$B$66, B9, MultiYear_ProForma!$C$2:$C$66, "FY2028") | F9: =SUMIFS(MultiYear_ProForma!$AF$2:$AF$66, MultiYear_ProForma!$B$2:$B$66, B9, MultiYear_ProForma!$C$2:$C$66, "FY2030") | G9: =(SUMIFS(MultiYear_ProForma!$AF$2:$AF$66, MultiYear_ProForma!$B$2:$B$66, B9, MultiYear_ProForma!$C$2:$C$66, "FY2026")+SUMIFS(MultiYear_ProForma!$AF$2:$AF$66, MultiYear_ProForma!$B$2:$B$66, B9, MultiYear_ProForma!$C$2:$C$66, "FY2027")+SUMIFS(MultiYear_ProForma!$AF$2:$AF$66, MultiYear_ProForma!$B$2:$B$66, B9, MultiYear_ProForma!$C$2:$C$66, "FY2028")+SUMIFS(MultiYear_ProForma!$AF$2:$AF$66, MultiYear_ProForma!$B$2:$B$66, B9, MultiYear_ProForma!$C$2:$C$66, "FY2029")+SUMIFS(MultiYear_ProForma!$AF$2:$AF$66, MultiYear_ProForma!$B$2:$B$66, B9, MultiYear_ProForma!$C$2:$C$66, "FY2030"))/5 | H9: =(SUMIFS(MultiYear_ProForma!$AF$2:$AF$66, MultiYear_ProForma!$B$2:$B$66, B9, MultiYear_ProForma!$C$2:$C$66, "FY2026")+SUMIFS(MultiYear_ProForma!$AF$2:$AF$66, MultiYear_ProForma!$B$2:$B$66, B9, MultiYear_ProForma!$C$2:$C$66, "FY2027")+SUMIFS(MultiYear_ProForma!$AF$2:$AF$66, MultiYear_ProForma!$B$2:$B$66, B9, MultiYear_ProForma!$C$2:$C$66, "FY2028")+SUMIFS(MultiYear_ProForma!$AF$2:$AF$66, MultiYear_ProForma!$B$2:$B$66, B9, MultiYear_ProForma!$C$2:$C$66, "FY2029")+SUMIFS(MultiYear_ProForma!$AF$2:$AF$66, MultiYear_ProForma!$B$2:$B$66, B9, MultiYear_ProForma!$C$2:$C$66, "FY2030")) | I9: =SUMIFS(MultiYear_ProForma!$N$2:$N$66, MultiYear_ProForma!$B$2:$B$66, B9, MultiYear_ProForma!$C$2:$C$66, "FY2026") | J9: =SUMIFS(MultiYear_ProForma!$AC$2:$AC$66, MultiYear_ProForma!$B$2:$B$66, B9, MultiYear_ProForma!$C$2:$C$66, "FY2030") | K9: =F9/J9 | L9: =F9-(VLOOKUP($C$1,$B$5:$G$17,5, 0)) | M9: =G9-(VLOOKUP($C$1,$B$5:$J$17,6, 0))
A10: =LEFT(B10, 2) | B10: =Scenarios!A8 | C10: =SUMIFS(Capital_Summary!$H$4:$H$83, Capital_Summary!$A$4:$A$83, B10, Capital_Summary!$B$4:$B$83, "FY2026")*-1 | D10: =SUMIFS(MultiYear_ProForma!$AF$2:$AF$66, MultiYear_ProForma!$B$2:$B$66, B10, MultiYear_ProForma!$C$2:$C$66, "FY2026") | E10: =SUMIFS(MultiYear_ProForma!$AF$2:$AF$66, MultiYear_ProForma!$B$2:$B$66, B10, MultiYear_ProForma!$C$2:$C$66, "FY2028") | F10: =SUMIFS(MultiYear_ProForma!$AF$2:$AF$66, MultiYear_ProForma!$B$2:$B$66, B10, MultiYear_ProForma!$C$2:$C$66, "FY2030") | G10: =(SUMIFS(MultiYear_ProForma!$AF$2:$AF$66, MultiYear_ProForma!$B$2:$B$66, B10, MultiYear_ProForma!$C$2:$C$66, "FY2026")+SUMIFS(MultiYear_ProForma!$AF$2:$AF$66, MultiYear_ProForma!$B$2:$B$66, B10, MultiYear_ProForma!$C$2:$C$66, "FY2027")+SUMIFS(MultiYear_ProForma!$AF$2:$AF$66, MultiYear_ProForma!$B$2:$B$66, B10, MultiYear_ProForma!$C$2:$C$66, "FY2028")+SUMIFS(MultiYear_ProForma!$AF$2:$AF$66, MultiYear_ProForma!$B$2:$B$66, B10, MultiYear_ProForma!$C$2:$C$66, "FY2029")+SUMIFS(MultiYear_ProForma!$AF$2:$AF$66, MultiYear_ProForma!$B$2:$B$66, B10, MultiYear_ProForma!$C$2:$C$66, "FY2030"))/5 | H10: =(SUMIFS(MultiYear_ProForma!$AF$2:$AF$66, MultiYear_ProForma!$B$2:$B$66, B10, MultiYear_ProForma!$C$2:$C$66, "FY2026")+SUMIFS(MultiYear_ProForma!$AF$2:$AF$66, MultiYear_ProForma!$B$2:$B$66, B10, MultiYear_ProForma!$C$2:$C$66, "FY2027")+SUMIFS(MultiYear_ProForma!$AF$2:$AF$66, MultiYear_ProForma!$B$2:$B$66, B10, MultiYear_ProForma!$C$2:$C$66, "FY2028")+SUMIFS(MultiYear_ProForma!$AF$2:$AF$66, MultiYear_ProForma!$B$2:$B$66, B10, MultiYear_ProForma!$C$2:$C$66, "FY2029")+SUMIFS(MultiYear_ProForma!$AF$2:$AF$66, MultiYear_ProForma!$B$2:$B$66, B10, MultiYear_ProForma!$C$2:$C$66, "FY2030")) | I10: =SUMIFS(MultiYear_ProForma!$N$2:$N$66, MultiYear_ProForma!$B$2:$B$66, B10, MultiYear_ProForma!$C$2:$C$66, "FY2026") | J10: =SUMIFS(MultiYear_ProForma!$AC$2:$AC$66, MultiYear_ProForma!$B$2:$B$66, B10, MultiYear_ProForma!$C$2:$C$66, "FY2030") | K10: =F10/J10 | L10: =F10-(VLOOKUP($C$1,$B$5:$G$17,5, 0)) | M10: =G10-(VLOOKUP($C$1,$B$5:$J$17,6, 0))
A11: =LEFT(B11, 2) | B11: =Scenarios!A9 | C11: =SUMIFS(Capital_Summary!$H$4:$H$83, Capital_Summary!$A$4:$A$83, B11, Capital_Summary!$B$4:$B$83, "FY2026")*-1 | D11: =SUMIFS(MultiYear_ProForma!$AF$2:$AF$66, MultiYear_ProForma!$B$2:$B$66, B11, MultiYear_ProForma!$C$2:$C$66, "FY2026") | E11: =SUMIFS(MultiYear_ProForma!$AF$2:$AF$66, MultiYear_ProForma!$B$2:$B$66, B11, MultiYear_ProForma!$C$2:$C$66, "FY2028") | F11: =SUMIFS(MultiYear_ProForma!$AF$2:$AF$66, MultiYear_ProForma!$B$2:$B$66, B11, MultiYear_ProForma!$C$2:$C$66, "FY2030") | G11: =(SUMIFS(MultiYear_ProForma!$AF$2:$AF$66, MultiYear_ProForma!$B$2:$B$66, B11, MultiYear_ProForma!$C$2:$C$66, "FY2026")+SUMIFS(MultiYear_ProForma!$AF$2:$AF$66, MultiYear_ProForma!$B$2:$B$66, B11, MultiYear_ProForma!$C$2:$C$66, "FY2027")+SUMIFS(MultiYear_ProForma!$AF$2:$AF$66, MultiYear_ProForma!$B$2:$B$66, B11, MultiYear_ProForma!$C$2:$C$66, "FY2028")+SUMIFS(MultiYear_ProForma!$AF$2:$AF$66, MultiYear_ProForma!$B$2:$B$66, B11, MultiYear_ProForma!$C$2:$C$66, "FY2029")+SUMIFS(MultiYear_ProForma!$AF$2:$AF$66, MultiYear_ProForma!$B$2:$B$66, B11, MultiYear_ProForma!$C$2:$C$66, "FY2030"))/5 | H11: =(SUMIFS(MultiYear_ProForma!$AF$2:$AF$66, MultiYear_ProForma!$B$2:$B$66, B11, MultiYear_ProForma!$C$2:$C$66, "FY2026")+SUMIFS(MultiYear_ProForma!$AF$2:$AF$66, MultiYear_ProForma!$B$2:$B$66, B11, MultiYear_ProForma!$C$2:$C$66, "FY2027")+SUMIFS(MultiYear_ProForma!$AF$2:$AF$66, MultiYear_ProForma!$B$2:$B$66, B11, MultiYear_ProForma!$C$2:$C$66, "FY2028")+SUMIFS(MultiYear_ProForma!$AF$2:$AF$66, MultiYear_ProForma!$B$2:$B$66, B11, MultiYear_ProForma!$C$2:$C$66, "FY2029")+SUMIFS(MultiYear_ProForma!$AF$2:$AF$66, MultiYear_ProForma!$B$2:$B$66, B11, MultiYear_ProForma!$C$2:$C$66, "FY2030")) | I11: =SUMIFS(MultiYear_ProForma!$N$2:$N$66, MultiYear_ProForma!$B$2:$B$66, B11, MultiYear_ProForma!$C$2:$C$66, "FY2026") | J11: =SUMIFS(MultiYear_ProForma!$AC$2:$AC$66, MultiYear_ProForma!$B$2:$B$66, B11, MultiYear_ProForma!$C$2:$C$66, "FY2030") | K11: =F11/J11 | L11: =F11-(VLOOKUP($C$1,$B$5:$G$17,5, 0)) | M11: =G11-(VLOOKUP($C$1,$B$5:$J$17,6, 0))
A12: =LEFT(B12, 2) | B12: =Scenarios!A10 | C12: =SUMIFS(Capital_Summary!$H$4:$H$83, Capital_Summary!$A$4:$A$83, B12, Capital_Summary!$B$4:$B$83, "FY2026")*-1 | D12: =SUMIFS(MultiYear_ProForma!$AF$2:$AF$66, MultiYear_ProForma!$B$2:$B$66, B12, MultiYear_ProForma!$C$2:$C$66, "FY2026") | E12: =SUMIFS(MultiYear_ProForma!$AF$2:$AF$66, MultiYear_ProForma!$B$2:$B$66, B12, MultiYear_ProForma!$C$2:$C$66, "FY2028") | F12: =SUMIFS(MultiYear_ProForma!$AF$2:$AF$66, MultiYear_ProForma!$B$2:$B$66, B12, MultiYear_ProForma!$C$2:$C$66, "FY2030") | G12: =(SUMIFS(MultiYear_ProForma!$AF$2:$AF$66, MultiYear_ProForma!$B$2:$B$66, B12, MultiYear_ProForma!$C$2:$C$66, "FY2026")+SUMIFS(MultiYear_ProForma!$AF$2:$AF$66, MultiYear_ProForma!$B$2:$B$66, B12, MultiYear_ProForma!$C$2:$C$66, "FY2027")+SUMIFS(MultiYear_ProForma!$AF$2:$AF$66, MultiYear_ProForma!$B$2:$B$66, B12, MultiYear_ProForma!$C$2:$C$66, "FY2028")+SUMIFS(MultiYear_ProForma!$AF$2:$AF$66, MultiYear_ProForma!$B$2:$B$66, B12, MultiYear_ProForma!$C$2:$C$66, "FY2029")+SUMIFS(MultiYear_ProForma!$AF$2:$AF$66, MultiYear_ProForma!$B$2:$B$66, B12, MultiYear_ProForma!$C$2:$C$66, "FY2030"))/5 | H12: =(SUMIFS(MultiYear_ProForma!$AF$2:$AF$66, MultiYear_ProForma!$B$2:$B$66, B12, MultiYear_ProForma!$C$2:$C$66, "FY2026")+SUMIFS(MultiYear_ProForma!$AF$2:$AF$66, MultiYear_ProForma!$B$2:$B$66, B12, MultiYear_ProForma!$C$2:$C$66, "FY2027")+SUMIFS(MultiYear_ProForma!$AF$2:$AF$66, MultiYear_ProForma!$B$2:$B$66, B12, MultiYear_ProForma!$C$2:$C$66, "FY2028")+SUMIFS(MultiYear_ProForma!$AF$2:$AF$66, MultiYear_ProForma!$B$2:$B$66, B12, MultiYear_ProForma!$C$2:$C$66, "FY2029")+SUMIFS(MultiYear_ProForma!$AF$2:$AF$66, MultiYear_ProForma!$B$2:$B$66, B12, MultiYear_ProForma!$C$2:$C$66, "FY2030")) | I12: =SUMIFS(MultiYear_ProForma!$N$2:$N$66, MultiYear_ProForma!$B$2:$B$66, B12, MultiYear_ProForma!$C$2:$C$66, "FY2026") | J12: =SUMIFS(MultiYear_ProForma!$AC$2:$AC$66, MultiYear_ProForma!$B$2:$B$66, B12, MultiYear_ProForma!$C$2:$C$66, "FY2030") | K12: =F12/J12 | L12: =F12-(VLOOKUP($C$1,$B$5:$G$17,5, 0)) | M12: =G12-(VLOOKUP($C$1,$B$5:$J$17,6, 0))
A13: =LEFT(B13, 2) | B13: =Scenarios!A11 | C13: =SUMIFS(Capital_Summary!$H$4:$H$83, Capital_Summary!$A$4:$A$83, B13, Capital_Summary!$B$4:$B$83, "FY2026")*-1 | D13: =SUMIFS(MultiYear_ProForma!$AF$2:$AF$66, MultiYear_ProForma!$B$2:$B$66, B13, MultiYear_ProForma!$C$2:$C$66, "FY2026") | E13: =SUMIFS(MultiYear_ProForma!$AF$2:$AF$66, MultiYear_ProForma!$B$2:$B$66, B13, MultiYear_ProForma!$C$2:$C$66, "FY2028") | F13: =SUMIFS(MultiYear_ProForma!$AF$2:$AF$66, MultiYear_ProForma!$B$2:$B$66, B13, MultiYear_ProForma!$C$2:$C$66, "FY2030") | G13: =(SUMIFS(MultiYear_ProForma!$AF$2:$AF$66, MultiYear_ProForma!$B$2:$B$66, B13, MultiYear_ProForma!$C$2:$C$66, "FY2026")+SUMIFS(MultiYear_ProForma!$AF$2:$AF$66, MultiYear_ProForma!$B$2:$B$66, B13, MultiYear_ProForma!$C$2:$C$66, "FY2027")+SUMIFS(MultiYear_ProForma!$AF$2:$AF$66, MultiYear_ProForma!$B$2:$B$66, B13, MultiYear_ProForma!$C$2:$C$66, "FY2028")+SUMIFS(MultiYear_ProForma!$AF$2:$AF$66, MultiYear_ProForma!$B$2:$B$66, B13, MultiYear_ProForma!$C$2:$C$66, "FY2029")+SUMIFS(MultiYear_ProForma!$AF$2:$AF$66, MultiYear_ProForma!$B$2:$B$66, B13, MultiYear_ProForma!$C$2:$C$66, "FY2030"))/5 | H13: =(SUMIFS(MultiYear_ProForma!$AF$2:$AF$66, MultiYear_ProForma!$B$2:$B$66, B13, MultiYear_ProForma!$C$2:$C$66, "FY2026")+SUMIFS(MultiYear_ProForma!$AF$2:$AF$66, MultiYear_ProForma!$B$2:$B$66, B13, MultiYear_ProForma!$C$2:$C$66, "FY2027")+SUMIFS(MultiYear_ProForma!$AF$2:$AF$66, MultiYear_ProForma!$B$2:$B$66, B13, MultiYear_ProForma!$C$2:$C$66, "FY2028")+SUMIFS(MultiYear_ProForma!$AF$2:$AF$66, MultiYear_ProForma!$B$2:$B$66, B13, MultiYear_ProForma!$C$2:$C$66, "FY2029")+SUMIFS(MultiYear_ProForma!$AF$2:$AF$66, MultiYear_ProForma!$B$2:$B$66, B13, MultiYear_ProForma!$C$2:$C$66, "FY2030")) | I13: =SUMIFS(MultiYear_ProForma!$N$2:$N$66, MultiYear_ProForma!$B$2:$B$66, B13, MultiYear_ProForma!$C$2:$C$66, "FY2026") | J13: =SUMIFS(MultiYear_ProForma!$AC$2:$AC$66, MultiYear_ProForma!$B$2:$B$66, B13, MultiYear_ProForma!$C$2:$C$66, "FY2030") | K13: =F13/J13 | L13: =F13-(VLOOKUP($C$1,$B$5:$G$17,5, 0)) | M13: =G13-(VLOOKUP($C$1,$B$5:$J$17,6, 0))
A14: =LEFT(B14, 2) | B14: =Scenarios!A12 | C14: =SUMIFS(Capital_Summary!$H$4:$H$83, Capital_Summary!$A$4:$A$83, B14, Capital_Summary!$B$4:$B$83, "FY2026")*-1 | D14: =SUMIFS(MultiYear_ProForma!$AF$2:$AF$66, MultiYear_ProForma!$B$2:$B$66, B14, MultiYear_ProForma!$C$2:$C$66, "FY2026") | E14: =SUMIFS(MultiYear_ProForma!$AF$2:$AF$66, MultiYear_ProForma!$B$2:$B$66, B14, MultiYear_ProForma!$C$2:$C$66, "FY2028") | F14: =SUMIFS(MultiYear_ProForma!$AF$2:$AF$66, MultiYear_ProForma!$B$2:$B$66, B14, MultiYear_ProForma!$C$2:$C$66, "FY2030") | G14: =(SUMIFS(MultiYear_ProForma!$AF$2:$AF$66, MultiYear_ProForma!$B$2:$B$66, B14, MultiYear_ProForma!$C$2:$C$66, "FY2026")+SUMIFS(MultiYear_ProForma!$AF$2:$AF$66, MultiYear_ProForma!$B$2:$B$66, B14, MultiYear_ProForma!$C$2:$C$66, "FY2027")+SUMIFS(MultiYear_ProForma!$AF$2:$AF$66, MultiYear_ProForma!$B$2:$B$66, B14, MultiYear_ProForma!$C$2:$C$66, "FY2028")+SUMIFS(MultiYear_ProForma!$AF$2:$AF$66, MultiYear_ProForma!$B$2:$B$66, B14, MultiYear_ProForma!$C$2:$C$66, "FY2029")+SUMIFS(MultiYear_ProForma!$AF$2:$AF$66, MultiYear_ProForma!$B$2:$B$66, B14, MultiYear_ProForma!$C$2:$C$66, "FY2030"))/5 | H14: =(SUMIFS(MultiYear_ProForma!$AF$2:$AF$66, MultiYear_ProForma!$B$2:$B$66, B14, MultiYear_ProForma!$C$2:$C$66, "FY2026")+SUMIFS(MultiYear_ProForma!$AF$2:$AF$66, MultiYear_ProForma!$B$2:$B$66, B14, MultiYear_ProForma!$C$2:$C$66, "FY2027")+SUMIFS(MultiYear_ProForma!$AF$2:$AF$66, MultiYear_ProForma!$B$2:$B$66, B14, MultiYear_ProForma!$C$2:$C$66, "FY2028")+SUMIFS(MultiYear_ProForma!$AF$2:$AF$66, MultiYear_ProForma!$B$2:$B$66, B14, MultiYear_ProForma!$C$2:$C$66, "FY2029")+SUMIFS(MultiYear_ProForma!$AF$2:$AF$66, MultiYear_ProForma!$B$2:$B$66, B14, MultiYear_ProForma!$C$2:$C$66, "FY2030")) | I14: =SUMIFS(MultiYear_ProForma!$N$2:$N$66, MultiYear_ProForma!$B$2:$B$66, B14, MultiYear_ProForma!$C$2:$C$66, "FY2026") | J14: =SUMIFS(MultiYear_ProForma!$AC$2:$AC$66, MultiYear_ProForma!$B$2:$B$66, B14, MultiYear_ProForma!$C$2:$C$66, "FY2030") | K14: =F14/J14 | L14: =F14-(VLOOKUP($C$1,$B$5:$G$17,5, 0)) | M14: =G14-(VLOOKUP($C$1,$B$5:$J$17,6, 0))
A15: =LEFT(B15, 2) | B15: =Scenarios!A13 | C15: =SUMIFS(Capital_Summary!$H$4:$H$83, Capital_Summary!$A$4:$A$83, B15, Capital_Summary!$B$4:$B$83, "FY2026")*-1 | D15: =SUMIFS(MultiYear_ProForma!$AF$2:$AF$66, MultiYear_ProForma!$B$2:$B$66, B15, MultiYear_ProForma!$C$2:$C$66, "FY2026") | E15: =SUMIFS(MultiYear_ProForma!$AF$2:$AF$66, MultiYear_ProForma!$B$2:$B$66, B15, MultiYear_ProForma!$C$2:$C$66, "FY2028") | F15: =SUMIFS(MultiYear_ProForma!$AF$2:$AF$66, MultiYear_ProForma!$B$2:$B$66, B15, MultiYear_ProForma!$C$2:$C$66, "FY2030") | G15: =(SUMIFS(MultiYear_ProForma!$AF$2:$AF$66, MultiYear_ProForma!$B$2:$B$66, B15, MultiYear_ProForma!$C$2:$C$66, "FY2026")+SUMIFS(MultiYear_ProForma!$AF$2:$AF$66, MultiYear_ProForma!$B$2:$B$66, B15, MultiYear_ProForma!$C$2:$C$66, "FY2027")+SUMIFS(MultiYear_ProForma!$AF$2:$AF$66, MultiYear_ProForma!$B$2:$B$66, B15, MultiYear_ProForma!$C$2:$C$66, "FY2028")+SUMIFS(MultiYear_ProForma!$AF$2:$AF$66, MultiYear_ProForma!$B$2:$B$66, B15, MultiYear_ProForma!$C$2:$C$66, "FY2029")+SUMIFS(MultiYear_ProForma!$AF$2:$AF$66, MultiYear_ProForma!$B$2:$B$66, B15, MultiYear_ProForma!$C$2:$C$66, "FY2030"))/5 | H15: =(SUMIFS(MultiYear_ProForma!$AF$2:$AF$66, MultiYear_ProForma!$B$2:$B$66, B15, MultiYear_ProForma!$C$2:$C$66, "FY2026")+SUMIFS(MultiYear_ProForma!$AF$2:$AF$66, MultiYear_ProForma!$B$2:$B$66, B15, MultiYear_ProForma!$C$2:$C$66, "FY2027")+SUMIFS(MultiYear_ProForma!$AF$2:$AF$66, MultiYear_ProForma!$B$2:$B$66, B15, MultiYear_ProForma!$C$2:$C$66, "FY2028")+SUMIFS(MultiYear_ProForma!$AF$2:$AF$66, MultiYear_ProForma!$B$2:$B$66, B15, MultiYear_ProForma!$C$2:$C$66, "FY2029")+SUMIFS(MultiYear_ProForma!$AF$2:$AF$66, MultiYear_ProForma!$B$2:$B$66, B15, MultiYear_ProForma!$C$2:$C$66, "FY2030")) | I15: =SUMIFS(MultiYear_ProForma!$N$2:$N$66, MultiYear_ProForma!$B$2:$B$66, B15, MultiYear_ProForma!$C$2:$C$66, "FY2026") | J15: =SUMIFS(MultiYear_ProForma!$AC$2:$AC$66, MultiYear_ProForma!$B$2:$B$66, B15, MultiYear_ProForma!$C$2:$C$66, "FY2030") | K15: =F15/J15 | L15: =F15-(VLOOKUP($C$1,$B$5:$G$17,5, 0)) | M15: =G15-(VLOOKUP($C$1,$B$5:$J$17,6, 0))
A16: =LEFT(B16, 2) | B16: =Scenarios!A14 | C16: =SUMIFS(Capital_Summary!$H$4:$H$83, Capital_Summary!$A$4:$A$83, B16, Capital_Summary!$B$4:$B$83, "FY2026")*-1 | D16: =SUMIFS(MultiYear_ProForma!$AF$2:$AF$66, MultiYear_ProForma!$B$2:$B$66, B16, MultiYear_ProForma!$C$2:$C$66, "FY2026") | E16: =SUMIFS(MultiYear_ProForma!$AF$2:$AF$66, MultiYear_ProForma!$B$2:$B$66, B16, MultiYear_ProForma!$C$2:$C$66, "FY2028") | F16: =SUMIFS(MultiYear_ProForma!$AF$2:$AF$66, MultiYear_ProForma!$B$2:$B$66, B16, MultiYear_ProForma!$C$2:$C$66, "FY2030") | G16: =(SUMIFS(MultiYear_ProForma!$AF$2:$AF$66, MultiYear_ProForma!$B$2:$B$66, B16, MultiYear_ProForma!$C$2:$C$66, "FY2026")+SUMIFS(MultiYear_ProForma!$AF$2:$AF$66, MultiYear_ProForma!$B$2:$B$66, B16, MultiYear_ProForma!$C$2:$C$66, "FY2027")+SUMIFS(MultiYear_ProForma!$AF$2:$AF$66, MultiYear_ProForma!$B$2:$B$66, B16, MultiYear_ProForma!$C$2:$C$66, "FY2028")+SUMIFS(MultiYear_ProForma!$AF$2:$AF$66, MultiYear_ProForma!$B$2:$B$66, B16, MultiYear_ProForma!$C$2:$C$66, "FY2029")+SUMIFS(MultiYear_ProForma!$AF$2:$AF$66, MultiYear_ProForma!$B$2:$B$66, B16, MultiYear_ProForma!$C$2:$C$66, "FY2030"))/5 | H16: =(SUMIFS(MultiYear_ProForma!$AF$2:$AF$66, MultiYear_ProForma!$B$2:$B$66, B16, MultiYear_ProForma!$C$2:$C$66, "FY2026")+SUMIFS(MultiYear_ProForma!$AF$2:$AF$66, MultiYear_ProForma!$B$2:$B$66, B16, MultiYear_ProForma!$C$2:$C$66, "FY2027")+SUMIFS(MultiYear_ProForma!$AF$2:$AF$66, MultiYear_ProForma!$B$2:$B$66, B16, MultiYear_ProForma!$C$2:$C$66, "FY2028")+SUMIFS(MultiYear_ProForma!$AF$2:$AF$66, MultiYear_ProForma!$B$2:$B$66, B16, MultiYear_ProForma!$C$2:$C$66, "FY2029")+SUMIFS(MultiYear_ProForma!$AF$2:$AF$66, MultiYear_ProForma!$B$2:$B$66, B16, MultiYear_ProForma!$C$2:$C$66, "FY2030")) | I16: =SUMIFS(MultiYear_ProForma!$N$2:$N$66, MultiYear_ProForma!$B$2:$B$66, B16, MultiYear_ProForma!$C$2:$C$66, "FY2026") | J16: =SUMIFS(MultiYear_ProForma!$AC$2:$AC$66, MultiYear_ProForma!$B$2:$B$66, B16, MultiYear_ProForma!$C$2:$C$66, "FY2030") | K16: =F16/J16 | L16: =F16-(VLOOKUP($C$1,$B$5:$G$17,5, 0)) | M16: =G16-(VLOOKUP($C$1,$B$5:$J$17,6, 0))
A17: =LEFT(B17, 2) | B17: =Scenarios!A15 | C17: =SUMIFS(Capital_Summary!$H$4:$H$83, Capital_Summary!$A$4:$A$83, B17, Capital_Summary!$B$4:$B$83, "FY2026")*-1 | D17: =SUMIFS(MultiYear_ProForma!$AF$2:$AF$66, MultiYear_ProForma!$B$2:$B$66, B17, MultiYear_ProForma!$C$2:$C$66, "FY2026") | E17: =SUMIFS(MultiYear_ProForma!$AF$2:$AF$66, MultiYear_ProForma!$B$2:$B$66, B17, MultiYear_ProForma!$C$2:$C$66, "FY2028") | F17: =SUMIFS(MultiYear_ProForma!$AF$2:$AF$66, MultiYear_ProForma!$B$2:$B$66, B17, MultiYear_ProForma!$C$2:$C$66, "FY2030") | G17: =(SUMIFS(MultiYear_ProForma!$AF$2:$AF$66, MultiYear_ProForma!$B$2:$B$66, B17, MultiYear_ProForma!$C$2:$C$66, "FY2026")+SUMIFS(MultiYear_ProForma!$AF$2:$AF$66, MultiYear_ProForma!$B$2:$B$66, B17, MultiYear_ProForma!$C$2:$C$66, "FY2027")+SUMIFS(MultiYear_ProForma!$AF$2:$AF$66, MultiYear_ProForma!$B$2:$B$66, B17, MultiYear_ProForma!$C$2:$C$66, "FY2028")+SUMIFS(MultiYear_ProForma!$AF$2:$AF$66, MultiYear_ProForma!$B$2:$B$66, B17, MultiYear_ProForma!$C$2:$C$66, "FY2029")+SUMIFS(MultiYear_ProForma!$AF$2:$AF$66, MultiYear_ProForma!$B$2:$B$66, B17, MultiYear_ProForma!$C$2:$C$66, "FY2030"))/5 | H17: =(SUMIFS(MultiYear_ProForma!$AF$2:$AF$66, MultiYear_ProForma!$B$2:$B$66, B17, MultiYear_ProForma!$C$2:$C$66, "FY2026")+SUMIFS(MultiYear_ProForma!$AF$2:$AF$66, MultiYear_ProForma!$B$2:$B$66, B17, MultiYear_ProForma!$C$2:$C$66, "FY2027")+SUMIFS(MultiYear_ProForma!$AF$2:$AF$66, MultiYear_ProForma!$B$2:$B$66, B17, MultiYear_ProForma!$C$2:$C$66, "FY2028")+SUMIFS(MultiYear_ProForma!$AF$2:$AF$66, MultiYear_ProForma!$B$2:$B$66, B17, MultiYear_ProForma!$C$2:$C$66, "FY2029")+SUMIFS(MultiYear_ProForma!$AF$2:$AF$66, MultiYear_ProForma!$B$2:$B$66, B17, MultiYear_ProForma!$C$2:$C$66, "FY2030")) | I17: =SUMIFS(MultiYear_ProForma!$N$2:$N$66, MultiYear_ProForma!$B$2:$B$66, B17, MultiYear_ProForma!$C$2:$C$66, "FY2026") | J17: =SUMIFS(MultiYear_ProForma!$AC$2:$AC$66, MultiYear_ProForma!$B$2:$B$66, B17, MultiYear_ProForma!$C$2:$C$66, "FY2030") | K17: =F17/J17 | L17: =F17-(VLOOKUP($C$1,$B$5:$G$17,5, 0)) | M17: =G17-(VLOOKUP($C$1,$B$5:$J$17,6, 0))
B19: Note: Displaced = FY26; Served = FY30. Net = M&O − (Aid + Override + Uplift); showing one-time capital (fy26) as negative number for visualization purposes

Sheet What_Is_The_$900K-$1M_Savings

Sheet Parameters_Public
A1: Public Inputs — Audited Baselines and Overrides (Phase A) | C1: Yellow fields are editable
A3: ADM (official) | C3: Values | E3: Notes | I3: Notes2
B4: Echo 40th | C4: 257 | E4: Estimate used at this point; need to replace. Find official 40th day ADM for Echo (enter audited)
B5: Echo 100th | C5: 257 | E5: Estimate used at this point; need to replace. Find official 100th day ADM for Echo (enter audited)
B6: Pima 40th | C6: 296 | E6: Estimate used at this point; need to replace. Find official 40th day ADM for Pima (enter audited)
B7: Pima 100th | C7: 296 | E7: Estimate used at this point; need to replace. Find official 100th day ADM for Pima (enter audited)
B8: Use Day (40 or 100) | C8: 40 | E8: Choose which count the model uses (40 or 100).
B10: Echo_ADM0 (selected) | C10: =IF(C8=40,C4,C5) | E10: Model‑read Echo_ADM0 selected based on 40/100 day switch.
B11: Pima_ADM0 (selected) | C11: =IF(C8=40,C6,C7) | E11: Model‑read Pima_ADM0 selected based on 40/100 day switch.
A13: M&O/ADM (district), audited (ACFR)
B14: M_O_per_ADM_Audited | C14: 11589 | E14: Estimate used at this point. Enter the audited districtwide Maintenance & Operations cost per ADM from the latest ACFR/Adopted Budget. Used as the FY25 base.
A16: Override — property‑tax override
B17: Override percent | C17: 0.15 | E17: Districtwide override percent (e.g., 15%).
B18: Base aid per ADM (proxy for RCL per pupil) | C18: 5013 | E18: Proxy base for calculating per‑ADM override; replace with RCL per pupil if available.
B19: Override per ADM (proxy) | C19: =C17*C18 | E19: Computed per‑ADM amount used wherever the model needs a per‑student override term.
B20: Override toggle (1=on, 0=off) | C20: 1 | E20: Global on/off switch for including override in revenue calculations.
