Workbook
Name ADM_Day_Select: Parameters_Public!C8
Name BaseAid_per_ADM: Parameters_Public!C18
Name Capex_ArtsHub: Parameters_Public!C28
Name Capex_in_MO_Toggle: Parameters_Public!C30
Name Capex_InnovHub: Parameters_Public!C29
Name Echo_ADM0: Parameters_Public!C10
Name EchoFixed_FY25_Total: Site_Fixed!C8
Name M_O_per_ADM_Audited: Parameters_Public!C14
Name Override_per_ADM_proxy: Parameters_Public!C19
Name Override_Percent: Parameters_Public!C17
Name Override_Toggle: Parameters_Public!C20
Name Pima_ADM0: Parameters_Public!C11
Name PimaFixed_FY25_Total: Site_Fixed!C15
Name TI_in_MO_Toggle: Parameters_Public!C26
Name TI_per_Site: Parameters_Public!C27

Sheet Workbook_Purpose_Overview
B2: Why this workbook exists
B3: This model helps the Board weigh three postures for Echo Canyon and Pima: managed decline, strategic consolidation (repurpose), and strategic growth. It separates operating (Fund 001) from one‑time capital (FY26) and makes people impacts visible (Displaced FY26; Served FY30). Net (operating) is M&O − (Aid + Override + Uplift); capital is shown separately. Assumptions (r retention, h overhead with taper, trend gates, override toggle) are visible on comparison views; receiving capacity gates are enforced by band.
B5: How to use it (start here)
B6: Scenario_Comparison – pick Base and Comparator to see the curves; Δ‑cards (FY2030 and 5‑yr avg); FY26 capital; Displaced FY26; Served FY30. Summary_Figures – a ranked table of all scenarios with the same decision signals (useful for board packets). BreakEven – see (i) how many students a growth lane must add to tie a repurpose baseline (N*), and (ii) the minimum retention a repurpose baseline needs to tie growth (r*), for FY26 and FY30.
B8: What the data say right now
B9: We assume a positive marginal contribution per added student where capacity exists (per‑ADM revenues indexed by policy exceed incremental operating cost). This is a reasonable working assumption in AZ’s funding structure. Arizona Legislature • Repurpose is credited with conservative fixed‑savings via a fixed‑share fallback and carry fractions (f_ops, f_lease) that decline over time; we’ll replace those dollars with audited site‑fixed ledgers for Echo/Pima. • To keep comparisons balanced, repurpose bears a tapering retention overhead (h) for displaced students who stay in SUSD, and growth bears a modest growth overhead (g = α × h) for routing/admin. • Use BreakEven to read the trade space: fixed‑savings vs. retention overhead (repurpose) and growth‑driven contribution (growth). Revenue matters too (why a growth lane belongs next to fiscal discipline) The budget hole isn’t just costs; it’s also top line (ADM). At about $5.0k per pupil Base Level Amount (FY2025), 100 K‑8 students ≈ $0.50M/year in base aid ignoring weights; 200 ≈ $1.0M. Weights, override, and other GF elements lift the true marginal revenue further.
B11: Other important context (recent precedents & lessons)
B12: • Chicago (2013 closures): studies report negative short‑term academic effects and no long‑term positive gains on average; some analyses note math effects persisting for students from closed schools, with better outcomes only when receiving schools were substantially higher‑performing. Lesson: overshoot/disruption has real costs. consortium.uchicago.edu +2 consortium.uchicago.edu +2 • Denver (2024–25): after a 2024 closure vote, the board paused further closures until 2030 amid community/legal pushback and governance churn. Lesson: force without consensus begets drag; iterate policy with stakeholders. Chalkbeat +1 • Kyrene (2025): district scheduled multiple public hearings on consolidation/boundaries and revised proposals after feedback. Lesson: iterate, publish, adjust before the final vote. kyrene.org +1 • Innovation hub option (analogy): Campbell School of Innovation (Campbell Union SD, CA) launched a district‑run innovation hub focused on design thinking, grew enrollment, and exported practices across the district. Lesson: a credible hub can strengthen brand and pull.
B14: Decision gates (apply before selecting a path)
B19: Revenue matters too. The budget hole isn’t just costs; it’s also top line (ADM). Capturing even 100 additional K‑8 students ≈ $511k/year in base state aid (ignoring weights) at the FY26 base of $5,113 is real money; 200 ≈ $1.02M. (Add grade/need weights and it’s higher.) That’s why a growth lane belongs next to a fiscal discipline lane. Arizona Department of Education
B20: Chicago (2013): Long‑term negative math effects for students from closed schools; many displaced students did not land in top‑tier schools. Lesson: Overshoot has real, lasting costs. UChicago Consortium on School Research+2WTTW News+2
B21: Denver (2024–25): Rapid closures triggered community/legal blowback and ongoing governance churn; boards are now haggling over pauses and re‑plans midstream. Lesson: Force without consensus begets drag. Denver Public Schools+2Chalkbeat+2
... B184: If the question is “why not put the hub where there’s no enrollment problem?”—the answer is speed-to-value: Echo’s assets mean lower startup friction, faster prototypes, and cleaner measurement, while preserving community value.

Sheet Scenario_Comparison
B1: Echo & Pima — Go-forward scenario comparison view
B3: Scenarios (CHOOSE) | C3: Description | I3: Assumed enrollment change (over 3 yrs)
B4: E1_StatusQuo_Decline | C4: =VLOOKUP($B4,Scenarios!$A$1:$C$14, 2, 0) -> Echo & Pima open; no operational or strategic growth actions; enrollment decline trend continues | J4: =IF(ROUND(SUMIFS(MultiYear_ProForma!$AC:$AC,MultiYear_ProForma!$B:$B,$B4,MultiYear_ProForma!$C:$C,"FY2030")-BaselineCalc!$B$9, 0)>0, "+"&ROUND(SUMIFS(MultiYear_ProForma!$AC:$AC,MultiYear_ProForma!$B:$B,$B4,MultiYear_ProForma!$C:$C,"FY2030")-BaselineCalc!$B$9, 0), ROUND(SUMIFS(MultiYear_ProForma!$AC:$AC,MultiYear_ProForma!$B:$B,$B4,MultiYear_ProForma!$C:$C,"FY2030")-BaselineCalc!$B$9, 0)) -> -43
B5: A2_Repurpose_Both_lease | C5: =VLOOKUP($B5,Scenarios!$A$1:$C$14, 2, 0) -> Repurpose both Echo & Pima; lease both properties; fixed cost reduction rate, retention %, and transition cost assumptions are key drivers | J5: =IF(ROUND(SUMIFS(MultiYear_ProForma!$AC:$AC,MultiYear_ProForma!$B:$B,$B5,MultiYear_ProForma!$C:$C,"FY2030")-BaselineCalc!$B$9, 0)>0, "+"&ROUND(SUMIFS(MultiYear_ProForma!$AC:$AC,MultiYear_ProForma!$B:$B,$B5,MultiYear_ProForma!$C:$C,"FY2030")-BaselineCalc!$B$9, 0), ROUND(SUMIFS(MultiYear_ProForma!$AC:$AC,MultiYear_ProForma!$B:$B,$B5,MultiYear_ProForma!$C:$C,"FY2030")-BaselineCalc!$B$9, 0)) -> -147
B24: Notes: Assumptions reflect: r (retention assumptions), override, marginal factor (e.g. assumed reduced variable cost to add new students), trend flags; h (receiving schools transportation route adjustment premium) tapers yearly. Receiving site should not exceed spare seats + portables
B26: Year | C26: Operating Net$ (Base) | D26: Operating Net$ (Comparator)
B27: FY2026 | C27: =SUMIFS(MultiYear_ProForma!$AF$2:$AF$66, MultiYear_ProForma!$B$2:$B$66, $B$4, MultiYear_ProForma!$C$2:$C$66, "FY2026") -> -459335.03 | D27: =SUMIFS(MultiYear_ProForma!$AF$2:$AF$66, MultiYear_ProForma!$B$2:$B$66, $B$5, MultiYear_ProForma!$C$2:$C$66, "FY2026") -> 840656.32
B28: FY2027 | C28: =SUMIFS(MultiYear_ProForma!$AF$2:$AF$66, MultiYear_ProForma!$B$2:$B$66, $B$4, MultiYear_ProForma!$C$2:$C$66, "FY2027") -> -522913.48 | D28: =SUMIFS(MultiYear_ProForma!$AF$2:$AF$66, MultiYear_ProForma!$B$2:$B$66, $B$5, MultiYear_ProForma!$C$2:$C$66, "FY2027") -> 952977.73
B29: FY2028 | C29: =SUMIFS(MultiYear_ProForma!$AF$2:$AF$66, MultiYear_ProForma!$B$2:$B$66, $B$4, MultiYear_ProForma!$C$2:$C$66, "FY2028") -> -588315.82 | D29: =SUMIFS(MultiYear_ProForma!$AF$2:$AF$66, MultiYear_ProForma!$B$2:$B$66, $B$5, MultiYear_ProForma!$C$2:$C$66, "FY2028") -> 1223701.2
B30: FY2029 | C30: =SUMIFS(MultiYear_ProForma!$AF$2:$AF$66, MultiYear_ProForma!$B$2:$B$66, $B$4, MultiYear_ProForma!$C$2:$C$66, "FY2029") -> -655588.7 | D30: =SUMIFS(MultiYear_ProForma!$AF$2:$AF$66, MultiYear_ProForma!$B$2:$B$66, $B$5, MultiYear_ProForma!$C$2:$C$66, "FY2029") -> 1462524.4
B31: FY2030 | C31: =SUMIFS(MultiYear_ProForma!$AF$2:$AF$66, MultiYear_ProForma!$B$2:$B$66, $B$4, MultiYear_ProForma!$C$2:$C$66, "FY2030") -> -724779.94 | D31: =SUMIFS(MultiYear_ProForma!$AF$2:$AF$66, MultiYear_ProForma!$B$2:$B$66, $B$5, MultiYear_ProForma!$C$2:$C$66, "FY2030") -> 1585320
B33: Assumptions (from Parameters_Public / Control_Center)
B34: Retention r (Echo central) | C34: =Parameters_Public!C23 -> 0.6
B35: Retention r (Pima central) | C35: =Parameters_Public!C24 -> 0.85
B36: MarginalFactor_for_Overlay | C36: =Parameters_Public!C43 -> 0.6
B37: Override % | C37: =Parameters_Public!C17 -> 0.15
B38: Override toggle (0/1) | C38: =Parameters_Public!C20 -> 1
B39: • Keep-open ops savings (fraction of MO): | C39: =Control_Center!C10 -> 0.007
B40: • Extra savings for co-location (fraction of MO): | C40: =Control_Center!C11 -> 0.015
B41: • Routing/admin overhead h tapers by year (see YearMap). Try ±20% sensitivity when routing assumptions are uncertain.
D43: Interpretation
B44: One-time Capital FY 2026 (Base) | C44: =SUMIFS(Capital_Summary!$H$4:$H$83, Capital_Summary!$A$4:$A$83, B4, Capital_Summary!$B$4:$B$83, "FY2026") -> 0 | D44: =""&$B$5&" will be $"&TEXT(ROUND(ABS(C45-C44),0), "#,##0")&" "&IF(C45>C44,"MORE COSTLY","LESS COSTLY")&" than "&$B$4&" in terms of capital investment required " -> A2_Repurpose_Both_lease will be $1,600,000 MORE COSTLY than E1_StatusQuo_Decline in terms of capital investment required
B45: One-time Capital FY 2026 (Comparator) | C45: =SUMIFS(Capital_Summary!$H$4:$H$83, Capital_Summary!$A$4:$A$83, B5, Capital_Summary!$B$4:$B$83, "FY2026") -> 1600000
B47: Avg Net (FY26–30) (Base)—rounded | C47: =ROUND((SUMIFS(MultiYear_ProForma!$AF$2:$AF$66,MultiYear_ProForma!$B$2:$B$66,$B$4,MultiYear_ProForma!$C$2:$C$66,"FY2026")+SUMIFS(MultiYear_ProForma!$AF$2:$AF$66,MultiYear_ProForma!$B$2:$B$66,$B$4,MultiYear_ProForma!$C$2:$C$66,"FY2027")+SUMIFS(MultiYear_ProForma!$AF$2:$AF$66,MultiYear_ProForma!$B$2:$B$66,$B$4,MultiYear_ProForma!$C$2:$C$66,"FY2028")+SUMIFS(MultiYear_ProForma!$AF$2:$AF$66,MultiYear_ProForma!$B$2:$B$66,$B$4,MultiYear_ProForma!$C$2:$C$66,"FY2029")+SUMIFS(MultiYear_ProForma!$AF$2:$AF$66,MultiYear_ProForma!$B$2:$B$66,$B$4,MultiYear_ProForma!$C$2:$C$66,"FY2030"))/5,-4) -> -590000 | D47: ="On average from 2026 through 2030, "&$B$5&" will be $"&TEXT(ABS(ROUND(C49,0)), "#,##0")&" "&IF(C49<0,"MORE COSTLY","LESS COSTLY")&" to operate annually than "&$B$4&"" -> On average from 2026 through 2030, A2_Repurpose_Both_lease will be $1,610,000 LESS COSTLY to operate annually than E1_StatusQuo_Decline
B48: Avg Net (FY26–30) (Comparator)—rounded | C48: =ROUND((SUMIFS(MultiYear_ProForma!$AF$2:$AF$66, MultiYear_ProForma!$B$2:$B$66, $B$5, MultiYear_ProForma!$C$2:$C$66, "FY2026")+SUMIFS(MultiYear_ProForma!$AF$2:$AF$66, MultiYear_ProForma!$B$2:$B$66, $C$5, MultiYear_ProForma!$C$2:$C$66, "FY2027")+SUMIFS(MultiYear_ProForma!$AF$2:$AF$66, MultiYear_ProForma!$B$2:$B$66, $B$5, MultiYear_ProForma!$C$2:$C$66, "FY2028")+SUMIFS(MultiYear_ProForma!$AF$2:$AF$66, MultiYear_ProForma!$B$2:$B$66, $B$5, MultiYear_ProForma!$C$2:$C$66, "FY2029")+SUMIFS(MultiYear_ProForma!$AF$2:$AF$66, MultiYear_ProForma!$B$2:$B$66, $B$5, MultiYear_ProForma!$C$2:$C$66, "FY2030"))/5, -4) -> 1020000
B49: Δ vs Base (Avg FY26–30)—rounded | C49: =ROUND(C48-C47, -4) -> 1610000
B52: FY2030 Net (Base)—rounded | C52: =ROUND(SUMIFS(MultiYear_ProForma!$AF$2:$AF$66, MultiYear_ProForma!$B$2:$B$66, $B$4, MultiYear_ProForma!$C$2:$C$66, "FY2030"), -4) -> -720000 | D52: ="By 2030, "&$B$5&" will be $"&TEXT(ABS(ROUND(C54,0)), "#,##0")&" "&IF(C54<0,"MORE COSTLY","LESS COSTLY")&" to operate annually than "&$B$4&"" -> By 2030, A2_Repurpose_Both_lease will be $2,310,000 LESS COSTLY to operate annually than E1_StatusQuo_Decline
B53: FY2030 Net (Comparator)—rounded | C53: =ROUND(SUMIFS(MultiYear_ProForma!$AF$2:$AF$66, MultiYear_ProForma!$B$2:$B$66, $B$5, MultiYear_ProForma!$C$2:$C$66, "FY2030"), -4) -> 1590000
B54: Δ vs Base (FY2030)—rounded | C54: =ROUND(C53-C52, -4) -> 2310000
B56: Students displaced (FY26) (Base) | C56: =SUMIFS(MultiYear_ProForma!$N$2:$N$66, MultiYear_ProForma!$B$2:$B$66, $B$4, MultiYear_ProForma!$C$2:$C$66, "FY2026") -> 0 | D56: =""&$B$5&" will displace "&ROUND(ABS(C57-C56),0)&" "&IF(C57>C56,"MORE STUDENTS","FEWER STUDENTS")&" than "&$B$4&"" -> A2_Repurpose_Both_lease will displace 553 MORE STUDENTS than E1_StatusQuo_Decline
B57: Students displaced (FY26) (Comparator) | C57: =SUMIFS(MultiYear_ProForma!$N$2:$N$66, MultiYear_ProForma!$B$2:$B$66, $B$5, MultiYear_ProForma!$C$2:$C$66, "FY2026") -> 553
B59: Students served (FY2030) (Base) | C59: =SUMIFS(MultiYear_ProForma!$AC$2:$AC$66, MultiYear_ProForma!$B$2:$B$66, $B$4, MultiYear_ProForma!$C$2:$C$66, "FY2030") -> 510.06959 | D59: =""&$B$5&" will serve "&ROUND(ABS(C60-C59),0)&" "&IF(C60>C59,"MORE STUDENTS","FEWER STUDENTS")&" than "&$B$4&"" -> A2_Repurpose_Both_lease will serve 104 FEWER STUDENTS than E1_StatusQuo_Decline
B60: Students served (FY2030) (Comparator) | C60: =SUMIFS(MultiYear_ProForma!$AC$2:$AC$66, MultiYear_ProForma!$B$2:$B$66, $B$5, MultiYear_ProForma!$C$2:$C$66, "FY2030") -> 405.8

Sheet BreakEven
A1: Break‑Even Calculator (Operating)
A3: Baseline (repurpose) Scenario | B3: A2_Repurpose_Both_lease
A4: Years shown | B4: FY2026 & FY2030
A6: Metric | B6: FY2026 | C6: FY2030
A7: mᵗ: Incremental margin per added ADM | B7: =INDEX(YearMap!$I$2:$I$6, MATCH("FY2026",YearMap!$A$2:$A$6,0))+IF(Parameters_Public!C20=1, INDEX(YearMap!$O$2:$O$6, MATCH("FY2026",YearMap!$A$2:$A$6,0)),0)+INDEX(YearMap!$P$2:$P$6, MATCH("FY2026",YearMap!$A$2:$A$6,0))-INDEX(YearMap!$B$2:$B$6, MATCH("FY2026",YearMap!$A$2:$A$6,0))-INDEX(YearMap!$Q$2:$Q$6, MATCH("FY2026",YearMap!$A$2:$A$6,0)) -> 4350.4385 | C7: =INDEX(YearMap!$I$2:$I$6, MATCH("FY2030",YearMap!$A$2:$A$6,0))+IF(Parameters_Public!C20=1, INDEX(YearMap!$O$2:$O$6, MATCH("FY2030",YearMap!$A$2:$A$6,0)),0)+INDEX(YearMap!$P$2:$P$6, MATCH("FY2030",YearMap!$A$2:$A$6,0))-INDEX(YearMap!$B$2:$B$6, MATCH("FY2030",YearMap!$A$2:$A$6,0))-INDEX(YearMap!$Q$2:$Q$6, MATCH("FY2030",YearMap!$A$2:$A$6,0)) -> 4962.8327
A8: Sᵗ: Fixed savings − retention overhead | B8: =(SUMIFS(MultiYear_ProForma!$H$2:$H$66,MultiYear_ProForma!$B$2:$B$66,$B$3,MultiYear_ProForma!$C$2:$C$66,"FY2026")+SUMIFS(MultiYear_ProForma!$I$2:$I$66,MultiYear_ProForma!$B$2:$B$66,$B$3,MultiYear_ProForma!$C$2:$C$66,"FY2026")-SUMIFS(MultiYear_ProForma!$R$2:$R$66,MultiYear_ProForma!$B$2:$B$66,$B$3,MultiYear_ProForma!$C$2:$C$66,"FY2026")-SUMIFS(MultiYear_ProForma!$S$2:$S$66,MultiYear_ProForma!$B$2:$B$66,$B$3,MultiYear_ProForma!$C$2:$C$66,"FY2026"))-SUMIFS(MultiYear_ProForma!$O$2:$O$66,MultiYear_ProForma!$B$2:$B$66,$B$3,MultiYear_ProForma!$C$2:$C$66,"FY2026")*INDEX(YearMap!$E$2:$E$6, MATCH("FY2026",YearMap!$A$2:$A$6,0)) -> 2011568.1 | C8: =(SUMIFS(MultiYear_ProForma!$H$2:$H$66,MultiYear_ProForma!$B$2:$B$66,$B$3,MultiYear_ProForma!$C$2:$C$66,"FY2030")+SUMIFS(MultiYear_ProForma!$I$2:$I$66,MultiYear_ProForma!$B$2:$B$66,$B$3,MultiYear_ProForma!$C$2:$C$66,"FY2030")-SUMIFS(MultiYear_ProForma!$R$2:$R$66,MultiYear_ProForma!$B$2:$B$66,$B$3,MultiYear_ProForma!$C$2:$C$66,"FY2030")-SUMIFS(MultiYear_ProForma!$S$2:$S$66,MultiYear_ProForma!$B$2:$B$66,$B$3,MultiYear_ProForma!$C$2:$C$66,"FY2030"))-SUMIFS(MultiYear_ProForma!$O$2:$O$66,MultiYear_ProForma!$B$2:$B$66,$B$3,MultiYear_ProForma!$C$2:$C$66,"FY2030")*INDEX(YearMap!$E$2:$E$6, MATCH("FY2030",YearMap!$A$2:$A$6,0)) -> 2880122.3
A9: ΔADM_disp: Displaced under baseline repurpose | B9: =SUMIFS(MultiYear_ProForma!$N$2:$N$66,MultiYear_ProForma!$B$2:$B$66,$B$3,MultiYear_ProForma!$C$2:$C$66,"FY2026") -> 553 | C9: =SUMIFS(MultiYear_ProForma!$N$2:$N$66,MultiYear_ProForma!$B$2:$B$66,$B$3,MultiYear_ProForma!$C$2:$C$66,"FY2030") -> 553
A11: N*: Added students growth needs to tie baseline repurpose | B11: =IFERROR($B$8/$B$7,"") -> 462.38283 | C11: =IFERROR($C$8/$C$7,"") -> 580.33838
A12: r*: Minimum retention for repurpose to tie growth | B12: =IFERROR(1 - $B$8/($B$9*$B$7),"") -> 0.16386469 | C12: =IFERROR(1 - $C$8/($C$9*$C$7),"") -> -0.04943649
A14: Notes:
A15: Baseline must be a repurpose scenario (A1/A2).
A16: mᵗ uses YearMap (Aid + Override_if_on + Uplift − VarUnit$ − Growth_overhead).
A17: Sᵗ = fixed savings credited (Echo+Pima) minus retention overhead (Retained_ADM × h).
A18: N* and r* are shown for FY2026 (transition year) and FY2030 (steady state).

Sheet Summary_Figures
B1: Base (for comparison): | C1: E1_StatusQuo_Decline | N1: Chart titles
N2: ="(Comparison) Change in ops net $ by scenario compared to "&C1&" (Positive = savings)" -> (Comparison) Change in ops net $ by scenario compared to E1_StatusQuo_Decline (Positive = savings)
N3: ="(Nominal) One-time capital (FY26) & Average 5-yr net ops $ by scenario" -> (Nominal) One-time capital (FY26) & Average 5-yr net ops $ by scenario
A4: Scenario key | B4: Scenario | C4: One-time Capital (FY26) | D4: Net FY26 Operational $ | E4: Net FY28 Operational $ | F4: Net FY30 Operational $ | G4: AVG 5-yr net operational $ | H4: Displaced students | I4: Served students FY30 | J4: Δ vs Base (FY2030 Net) | K4: Δ vs Base (5-yr Avg Net)
A5: =LEFT(B5, 2) -> F1 | B5: F1_CUSTOM1 | C5: =SUMIFS(Capital_Summary!$H$4:$H$83, Capital_Summary!$A$4:$A$83, B5, Capital_Summary!$B$4:$B$83, "FY2026")*-1 -> 0 | D5: =SUMIFS(MultiYear_ProForma!$AF$2:$AF$66, MultiYear_ProForma!$B$2:$B$66, B5, MultiYear_ProForma!$C$2:$C$66, "FY2026") -> -459335.03 | E5: =SUMIFS(MultiYear_ProForma!$AF$2:$AF$66, MultiYear_ProForma!$B$2:$B$66, B5, MultiYear_ProForma!$C$2:$C$66, "FY2028") -> -482588.87 | F5: =SUMIFS(MultiYear_ProForma!$AF$2:$AF$66, MultiYear_ProForma!$B$2:$B$66, B5, MultiYear_ProForma!$C$2:$C$66, "FY2030") -> -507019.93 | G5: =(SUMIFS(MultiYear_ProForma!$AF$2:$AF$66, MultiYear_ProForma!$B$2:$B$66, B5, MultiYear_ProForma!$C$2:$C$66, "FY2026")+SUMIFS(MultiYear_ProForma!$AF$2:$AF$66, MultiYear_ProForma!$B$2:$B$66, B5, MultiYear_ProForma!$C$2:$C$66, "FY2027")+SUMIFS(MultiYear_ProForma!$AF$2:$AF$66, MultiYear_ProForma!$B$2:$B$66, B5, MultiYear_ProForma!$C$2:$C$66, "FY2028")+SUMIFS(MultiYear_ProForma!$AF$2:$AF$66, MultiYear_ProForma!$B$2:$B$66, B5, MultiYear_ProForma!$C$2:$C$66, "FY2029")+SUMIFS(MultiYear_ProForma!$AF$2:$AF$66, MultiYear_ProForma!$B$2:$B$66, B5, MultiYear_ProForma!$C$2:$C$66, "FY2030"))/5 -> -482883.16 | H5: =SUMIFS(MultiYear_ProForma!$N$2:$N$66, MultiYear_ProForma!$B$2:$B$66, B5, MultiYear_ProForma!$C$2:$C$66, "FY2026") -> 0 | I5: =SUMIFS(MultiYear_ProForma!$AC$2:$AC$66, MultiYear_ProForma!$B$2:$B$66, B5, MultiYear_ProForma!$C$2:$C$66, "FY2030") -> 553 | J5: =F5-(VLOOKUP($C$1,$B$5:$G$17,5, 0)) -> 217760.01 | K5: =G5-(VLOOKUP($C$1,$B$5:$I$17,6, 0)) -> 107303.43
A6: =LEFT(B6, 2) -> E3 | B6: E3_StatusQuo_Targets | C6: =SUMIFS(Capital_Summary!$H$4:$H$83, Capital_Summary!$A$4:$A$83, B6, Capital_Summary!$B$4:$B$83, "FY2026")*-1 -> 0 | D6: =SUMIFS(MultiYear_ProForma!$AF$2:$AF$66, MultiYear_ProForma!$B$2:$B$66, B6, MultiYear_ProForma!$C$2:$C$66, "FY2030") -> 331651 | E6: =SUMIFS(MultiYear_ProForma!$AF$2:$AF$66, MultiYear_ProForma!$B$2:$B$66, B6, MultiYear_ProForma!$C$2:$C$66, "FY2028") -> 310953.37 | F6: =SUMIFS(MultiYear_ProForma!$AF$2:$AF$66, MultiYear_ProForma!$B$2:$B$66, B6, MultiYear_ProForma!$C$2:$C$66, "FY2030") -> 331651 | G6: =(SUMIFS(MultiYear_ProForma!$AF$2:$AF$66, MultiYear_ProForma!$B$2:$B$66, B6, MultiYear_ProForma!$C$2:$C$66, "FY2026")+SUMIFS(MultiYear_ProForma!$AF$2:$AF$66, MultiYear_ProForma!$B$2:$B$66, B6, MultiYear_ProForma!$C$2:$C$66, "FY2027")+SUMIFS(MultiYear_ProForma!$AF$2:$AF$66, MultiYear_ProForma!$B$2:$B$66, B6, MultiYear_ProForma!$C$2:$C$66, "FY2028")+SUMIFS(MultiYear_ProForma!$AF$2:$AF$66, MultiYear_ProForma!$B$2:$B$66, B6, MultiYear_ProForma!$C$2:$C$66, "FY2029")+SUMIFS(MultiYear_ProForma!$AF$2:$AF$66, MultiYear_ProForma!$B$2:$B$66, B6, MultiYear_ProForma!$C$2:$C$66, "FY2030"))/5 -> 159301.11 | H6: =SUMIFS(MultiYear_ProForma!$N$2:$N$66, MultiYear_ProForma!$B$2:$B$66, B6, MultiYear_ProForma!$C$2:$C$66, "FY2026") -> 0 | I6: =SUMIFS(MultiYear_ProForma!$AC$2:$AC$66, MultiYear_ProForma!$B$2:$B$66, B6, MultiYear_ProForma!$C$2:$C$66, "FY2030") -> 628 | J6: =F6-(VLOOKUP($C$1,$B$5:$G$17,5, 0)) -> 1056430.9 | K6: =G6-(VLOOKUP($C$1,$B$5:$I$17,6, 0)) -> 749487.71
A7: =LEFT(B7, 2) -> D3 | B7: D3_CoLocation_Echo_Targets | C7: =SUMIFS(Capital_Summary!$H$4:$H$83, Capital_Summary!$A$4:$A$83, B7, Capital_Summary!$B$4:$B$83, "FY2026")*-1 -> 0 | D7: =SUMIFS(MultiYear_ProForma!$AF$2:$AF$66, MultiYear_ProForma!$B$2:$B$66, B7, MultiYear_ProForma!$C$2:$C$66, "FY2030") -> 412099.97 | E7: =SUMIFS(MultiYear_ProForma!$AF$2:$AF$66, MultiYear_ProForma!$B$2:$B$66, B7, MultiYear_ProForma!$C$2:$C$66, "FY2028") -> 389098.13 | F7: =SUMIFS(MultiYear_ProForma!$AF$2:$AF$66, MultiYear_ProForma!$B$2:$B$66, B7, MultiYear_ProForma!$C$2:$C$66, "FY2030") -> 412099.97 | G7: =(SUMIFS(MultiYear_ProForma!$AF$2:$AF$66, MultiYear_ProForma!$B$2:$B$66, B7, MultiYear_ProForma!$C$2:$C$66, "FY2026")+SUMIFS(MultiYear_ProForma!$AF$2:$AF$66, MultiYear_ProForma!$B$2:$B$66, B7, MultiYear_ProForma!$C$2:$C$66, "FY2027")+SUMIFS(MultiYear_ProForma!$AF$2:$AF$66, MultiYear_ProForma!$B$2:$B$66, B7, MultiYear_ProForma!$C$2:$C$66, "FY2028")+SUMIFS(MultiYear_ProForma!$AF$2:$AF$66, MultiYear_ProForma!$B$2:$B$66, B7, MultiYear_ProForma!$C$2:$C$66, "FY2029")+SUMIFS(MultiYear_ProForma!$AF$2:$AF$66, MultiYear_ProForma!$B$2:$B$66, B7, MultiYear_ProForma!$C$2:$C$66, "FY2030"))/5 -> 288107.49 | H7: =SUMIFS(MultiYear_ProForma!$N$2:$N$66, MultiYear_ProForma!$B$2:$B$66, B7, MultiYear_ProForma!$C$2:$C$66, "FY2026") -> 0 | I7: =SUMIFS(MultiYear_ProForma!$AC$2:$AC$66, MultiYear_ProForma!$B$2:$B$66, B7, MultiYear_ProForma!$C$2:$C$66, "FY2030") -> 603 | J7: =F7-(VLOOKUP($C$1,$B$5:$G$17,5, 0)) -> 1136879.9 | K7: =G7-(VLOOKUP($C$1,$B$5:$I$17,6, 0)) -> 878294.09
A8: =LEFT(B8, 2) -> D1 | B8: D1_Grow_Both_Targets | C8: =SUMIFS(Capital_Summary!$H$4:$H$83, Capital_Summary!$A$4:$A$83, B8, Capital_Summary!$B$4:$B$83, "FY2026")*-1 -> -2000000 | D8: =SUMIFS(MultiYear_ProForma!$AF$2:$AF$66, MultiYear_ProForma!$B$2:$B$66, B8, MultiYear_ProForma!$C$2:$C$66, "FY2030") -> 1170321.9 | E8: =SUMIFS(MultiYear_ProForma!$AF$2:$AF$66, MultiYear_ProForma!$B$2:$B$66, B8, MultiYear_ProForma!$C$2:$C$66, "FY2028") -> 1104495.6 | F8: =SUMIFS(MultiYear_ProForma!$AF$2:$AF$66, MultiYear_ProForma!$B$2:$B$66, B8, MultiYear_ProForma!$C$2:$C$66, "FY2030") -> 1170321.9 | G8: =(SUMIFS(MultiYear_ProForma!$AF$2:$AF$66, MultiYear_ProForma!$B$2:$B$66, B8, MultiYear_ProForma!$C$2:$C$66, "FY2026")+SUMIFS(MultiYear_ProForma!$AF$2:$AF$66, MultiYear_ProForma!$B$2:$B$66, B8, MultiYear_ProForma!$C$2:$C$66, "FY2027")+SUMIFS(MultiYear_ProForma!$AF$2:$AF$66, MultiYear_ProForma!$B$2:$B$66, B8, MultiYear_ProForma!$C$2:$C$66, "FY2028")+SUMIFS(MultiYear_ProForma!$AF$2:$AF$66, MultiYear_ProForma!$B$2:$B$66, B8, MultiYear_ProForma!$C$2:$C$66, "FY2029")+SUMIFS(MultiYear_ProForma!$AF$2:$AF$66, MultiYear_ProForma!$B$2:$B$66, B8, MultiYear_ProForma!$C$2:$C$66, "FY2030"))/5 -> 801485.39 | H8: =SUMIFS(MultiYear_ProForma!$N$2:$N$66, MultiYear_ProForma!$B$2:$B$66, B8, MultiYear_ProForma!$C$2:$C$66, "FY2026") -> 0 | I8: =SUMIFS(MultiYear_ProForma!$AC$2:$AC$66, MultiYear_ProForma!$B$2:$B$66, B8, MultiYear_ProForma!$C$2:$C$66, "FY2030") -> 703 | J8: =F8-(VLOOKUP($C$1,$B$5:$G$17,5, 0)) -> 1895101.9 | K8: =G8-(VLOOKUP($C$1,$B$5:$I$17,6, 0)) -> 1391672
A9: =LEFT(B9, 2) -> E2 | B9: E2_StatusQuo_Steady | C9: =SUMIFS(Capital_Summary!$H$4:$H$83, Capital_Summary!$A$4:$A$83, B9, Capital_Summary!$B$4:$B$83, "FY2026")*-1 -> 0 | D9: =SUMIFS(MultiYear_ProForma!$AF$2:$AF$66, MultiYear_ProForma!$B$2:$B$66, B9, MultiYear_ProForma!$C$2:$C$66, "FY2030") -> -507019.93 | E9: =SUMIFS(MultiYear_ProForma!$AF$2:$AF$66, MultiYear_ProForma!$B$2:$B$66, B9, MultiYear_ProForma!$C$2:$C$66, "FY2028") -> -482588.87 | F9: =SUMIFS(MultiYear_ProForma!$AF$2:$AF$66, MultiYear_ProForma!$B$2:$B$66, B9, MultiYear_ProForma!$C$2:$C$66, "FY2030") -> -507019.93 | G9: =(SUMIFS(MultiYear_ProForma!$AF$2:$AF$66, MultiYear_ProForma!$B$2:$B$66, B9, MultiYear_ProForma!$C$2:$C$66, "FY2026")+SUMIFS(MultiYear_ProForma!$AF$2:$AF$66, MultiYear_ProForma!$B$2:$B$66, B9, MultiYear_ProForma!$C$2:$C$66, "FY2027")+SUMIFS(MultiYear_ProForma!$AF$2:$AF$66, MultiYear_ProForma!$B$2:$B$66, B9, MultiYear_ProForma!$C$2:$C$66, "FY2028")+SUMIFS(MultiYear_ProForma!$AF$2:$AF$66, MultiYear_ProForma!$B$2:$B$66, B9, MultiYear_ProForma!$C$2:$C$66, "FY2029")+SUMIFS(MultiYear_ProForma!$AF$2:$AF$66, MultiYear_ProForma!$B$2:$B$66, B9, MultiYear_ProForma!$C$2:$C$66, "FY2030"))/5 -> -482883.16 | H9: =SUMIFS(MultiYear_ProForma!$N$2:$N$66, MultiYear_ProForma!$B$2:$B$66, B9, MultiYear_ProForma!$C$2:$C$66, "FY2026") -> 0 | I9: =SUMIFS(MultiYear_ProForma!$AC$2:$AC$66, MultiYear_ProForma!$B$2:$B$66, B9, MultiYear_ProForma!$C$2:$C$66, "FY2030") -> 553 | J9: =F9-(VLOOKUP($C$1,$B$5:$G$17,5, 0)) -> 217760.01 | K9: =G9-(VLOOKUP($C$1,$B$5:$I$17,6, 0)) -> 107303.43
A10: =LEFT(B10, 2) -> D2 | B10: D2_EchoGHubRamp_PimaTargets | C10: =SUMIFS(Capital_Summary!$H$4:$H$83, Capital_Summary!$A$4:$A$83, B10, Capital_Summary!$B$4:$B$83, "FY2026")*-1 -> -800000 | D10: =SUMIFS(MultiYear_ProForma!$AF$2:$AF$66, MultiYear_ProForma!$B$2:$B$66, B10, MultiYear_ProForma!$C$2:$C$66, "FY2030") -> 890764.96 | E10: =SUMIFS(MultiYear_ProForma!$AF$2:$AF$66, MultiYear_ProForma!$B$2:$B$66, B10, MultiYear_ProForma!$C$2:$C$66, "FY2028") -> 839981.52 | F10: =SUMIFS(MultiYear_ProForma!$AF$2:$AF$66, MultiYear_ProForma!$B$2:$B$66, B10, MultiYear_ProForma!$C$2:$C$66, "FY2030") -> 890764.96 | G10: =(SUMIFS(MultiYear_ProForma!$AF$2:$AF$66, MultiYear_ProForma!$B$2:$B$66, B10, MultiYear_ProForma!$C$2:$C$66, "FY2026")+SUMIFS(MultiYear_ProForma!$AF$2:$AF$66, MultiYear_ProForma!$B$2:$B$66, B10, MultiYear_ProForma!$C$2:$C$66, "FY2027")+SUMIFS(MultiYear_ProForma!$AF$2:$AF$66, MultiYear_ProForma!$B$2:$B$66, B10, MultiYear_ProForma!$C$2:$C$66, "FY2028")+SUMIFS(MultiYear_ProForma!$AF$2:$AF$66, MultiYear_ProForma!$B$2:$B$66, B10, MultiYear_ProForma!$C$2:$C$66, "FY2029")+SUMIFS(MultiYear_ProForma!$AF$2:$AF$66, MultiYear_ProForma!$B$2:$B$66, B10, MultiYear_ProForma!$C$2:$C$66, "FY2030"))/5 -> 587423.97 | H10: =SUMIFS(MultiYear_ProForma!$N$2:$N$66, MultiYear_ProForma!$B$2:$B$66, B10, MultiYear_ProForma!$C$2:$C$66, "FY2026") -> 0 | I10: =SUMIFS(MultiYear_ProForma!$AC$2:$AC$66, MultiYear_ProForma!$B$2:$B$66, B10, MultiYear_ProForma!$C$2:$C$66, "FY2030") -> 678 | J10: =F10-(VLOOKUP($C$1,$B$5:$G$17,5, 0)) -> 1615544.9 | K10: =G10-(VLOOKUP($C$1,$B$5:$I$17,6, 0)) -> 1177610.6
A11: =LEFT(B11, 2) -> A2 | B11: A2_Repurpose_Both_lease | C11: =SUMIFS(Capital_Summary!$H$4:$H$83, Capital_Summary!$A$4:$A$83, B11, Capital_Summary!$B$4:$B$83, "FY2026")*-1 -> -1600000 | D11: =SUMIFS(MultiYear_ProForma!$AF$2:$AF$66, MultiYear_ProForma!$B$2:$B$66, B11, MultiYear_ProForma!$C$2:$C$66, "FY2030") -> 1585320 | E11: =SUMIFS(MultiYear_ProForma!$AF$2:$AF$66, MultiYear_ProForma!$B$2:$B$66, B11, MultiYear_ProForma!$C$2:$C$66, "FY2028") -> 1223701.2 | F11: =SUMIFS(MultiYear_ProForma!$AF$2:$AF$66, MultiYear_ProForma!$B$2:$B$66, B11, MultiYear_ProForma!$C$2:$C$66, "FY2030") -> 1585320 | G11: =(SUMIFS(MultiYear_ProForma!$AF$2:$AF$66, MultiYear_ProForma!$B$2:$B$66, B11, MultiYear_ProForma!$C$2:$C$66, "FY2026")+SUMIFS(MultiYear_ProForma!$AF$2:$AF$66, MultiYear_ProForma!$B$2:$B$66, B11, MultiYear_ProForma!$C$2:$C$66, "FY2027")+SUMIFS(MultiYear_ProForma!$AF$2:$AF$66, MultiYear_ProForma!$B$2:$B$66, B11, MultiYear_ProForma!$C$2:$C$66, "FY2028")+SUMIFS(MultiYear_ProForma!$AF$2:$AF$66, MultiYear_ProForma!$B$2:$B$66, B11, MultiYear_ProForma!$C$2:$C$66, "FY2029")+SUMIFS(MultiYear_ProForma!$AF$2:$AF$66, MultiYear_ProForma!$B$2:$B$66, B11, MultiYear_ProForma!$C$2:$C$66, "FY2030"))/5 -> 1213035.9 | H11: =SUMIFS(MultiYear_ProForma!$N$2:$N$66, MultiYear_ProForma!$B$2:$B$66, B11, MultiYear_ProForma!$C$2:$C$66, "FY2026") -> 553 | I11: =SUMIFS(MultiYear_ProForma!$AC$2:$AC$66, MultiYear_ProForma!$B$2:$B$66, B11, MultiYear_ProForma!$C$2:$C$66, "FY2030") -> 405.8 | J11: =F11-(VLOOKUP($C$1,$B$5:$G$17,5, 0)) -> 2310100 | K11: =G11-(VLOOKUP($C$1,$B$5:$I$17,6, 0)) -> 1803222.5
A12: =LEFT(B12, 2) -> A1 | B12: A1_Repurpose_Both_ops | C12: =SUMIFS(Capital_Summary!$H$4:$H$83, Capital_Summary!$A$4:$A$83, B12, Capital_Summary!$B$4:$B$83, "FY2026")*-1 -> -2400000 | D12: =SUMIFS(MultiYear_ProForma!$AF$2:$AF$66, MultiYear_ProForma!$B$2:$B$66, B12, MultiYear_ProForma!$C$2:$C$66, "FY2030") -> 922909.09 | E12: =SUMIFS(MultiYear_ProForma!$AF$2:$AF$66, MultiYear_ProForma!$B$2:$B$66, B12, MultiYear_ProForma!$C$2:$C$66, "FY2028") -> 593208.97 | F12: =SUMIFS(MultiYear_ProForma!$AF$2:$AF$66, MultiYear_ProForma!$B$2:$B$66, B12, MultiYear_ProForma!$C$2:$C$66, "FY2030") -> 922909.09 | G12: =(SUMIFS(MultiYear_ProForma!$AF$2:$AF$66, MultiYear_ProForma!$B$2:$B$66, B12, MultiYear_ProForma!$C$2:$C$66, "FY2026")+SUMIFS(MultiYear_ProForma!$AF$2:$AF$66, MultiYear_ProForma!$B$2:$B$66, B12, MultiYear_ProForma!$C$2:$C$66, "FY2027")+SUMIFS(MultiYear_ProForma!$AF$2:$AF$66, MultiYear_ProForma!$B$2:$B$66, B12, MultiYear_ProForma!$C$2:$C$66, "FY2028")+SUMIFS(MultiYear_ProForma!$AF$2:$AF$66, MultiYear_ProForma!$B$2:$B$66, B12, MultiYear_ProForma!$C$2:$C$66, "FY2029")+SUMIFS(MultiYear_ProForma!$AF$2:$AF$66, MultiYear_ProForma!$B$2:$B$66, B12, MultiYear_ProForma!$C$2:$C$66, "FY2030"))/5 -> 552153.61 | H12: =SUMIFS(MultiYear_ProForma!$N$2:$N$66, MultiYear_ProForma!$B$2:$B$66, B12, MultiYear_ProForma!$C$2:$C$66, "FY2026") -> 553 | I12: =SUMIFS(MultiYear_ProForma!$AC$2:$AC$66, MultiYear_ProForma!$B$2:$B$66, B12, MultiYear_ProForma!$C$2:$C$66, "FY2030") -> 405.8 | J12: =F12-(VLOOKUP($C$1,$B$5:$G$17,5, 0)) -> 1647689 | K12: =G12-(VLOOKUP($C$1,$B$5:$I$17,6, 0)) -> 1142340.2
A13: =LEFT(B13, 2) -> B2 | B13: B2_Repurpose_Echo_lease_PimaTargets | C13: =SUMIFS(Capital_Summary!$H$4:$H$83, Capital_Summary!$A$4:$A$83, B13, Capital_Summary!$B$4:$B$83, "FY2026")*-1 -> -800000 | D13: =SUMIFS(MultiYear_ProForma!$AF$2:$AF$66, MultiYear_ProForma!$B$2:$B$66, B13, MultiYear_ProForma!$C$2:$C$66, "FY2030") -> 302948.49 | E13: =SUMIFS(MultiYear_ProForma!$AF$2:$AF$66, MultiYear_ProForma!$B$2:$B$66, B13, MultiYear_ProForma!$C$2:$C$66, "FY2028") -> 166608.27 | F13: =SUMIFS(MultiYear_ProForma!$AF$2:$AF$66, MultiYear_ProForma!$B$2:$B$66, B13, MultiYear_ProForma!$C$2:$C$66, "FY2030") -> 302948.49 | G13: =(SUMIFS(MultiYear_ProForma!$AF$2:$AF$66, MultiYear_ProForma!$B$2:$B$66, B13, MultiYear_ProForma!$C$2:$C$66, "FY2026")+SUMIFS(MultiYear_ProForma!$AF$2:$AF$66, MultiYear_ProForma!$B$2:$B$66, B13, MultiYear_ProForma!$C$2:$C$66, "FY2027")+SUMIFS(MultiYear_ProForma!$AF$2:$AF$66, MultiYear_ProForma!$B$2:$B$66, B13, MultiYear_ProForma!$C$2:$C$66, "FY2028")+SUMIFS(MultiYear_ProForma!$AF$2:$AF$66, MultiYear_ProForma!$B$2:$B$66, B13, MultiYear_ProForma!$C$2:$C$66, "FY2029")+SUMIFS(MultiYear_ProForma!$AF$2:$AF$66, MultiYear_ProForma!$B$2:$B$66, B13, MultiYear_ProForma!$C$2:$C$66, "FY2030"))/5 -> 162769.54 | H13: =SUMIFS(MultiYear_ProForma!$N$2:$N$66, MultiYear_ProForma!$B$2:$B$66, B13, MultiYear_ProForma!$C$2:$C$66, "FY2026") -> 257 | I13: =SUMIFS(MultiYear_ProForma!$AC$2:$AC$66, MultiYear_ProForma!$B$2:$B$66, B13, MultiYear_ProForma!$C$2:$C$66, "FY2030") -> 450.2 | J13: =F13-(VLOOKUP($C$1,$B$5:$G$17,5, 0)) -> 1027728.4 | K13: =G13-(VLOOKUP($C$1,$B$5:$I$17,6, 0)) -> 752956.13
A14: =LEFT(B14, 2) -> B1 | B14: B1_Repurpose_Echo_ops_PimaTargets | C14: =SUMIFS(Capital_Summary!$H$4:$H$83, Capital_Summary!$A$4:$A$83, B14, Capital_Summary!$B$4:$B$83, "FY2026")*-1 -> -1200000 | D14: =SUMIFS(MultiYear_ProForma!$AF$2:$AF$66, MultiYear_ProForma!$B$2:$B$66, B14, MultiYear_ProForma!$C$2:$C$66, "FY2030") -> 408845.42 | E14: =SUMIFS(MultiYear_ProForma!$AF$2:$AF$66, MultiYear_ProForma!$B$2:$B$66, B14, MultiYear_ProForma!$C$2:$C$66, "FY2028") -> 265075.52 | F14: =SUMIFS(MultiYear_ProForma!$AF$2:$AF$66, MultiYear_ProForma!$B$2:$B$66, B14, MultiYear_ProForma!$C$2:$C$66, "FY2030") -> 408845.42 | G14: =(SUMIFS(MultiYear_ProForma!$AF$2:$AF$66, MultiYear_ProForma!$B$2:$B$66, B14, MultiYear_ProForma!$C$2:$C$66, "FY2026")+SUMIFS(MultiYear_ProForma!$AF$2:$AF$66, MultiYear_ProForma!$B$2:$B$66, B14, MultiYear_ProForma!$C$2:$C$66, "FY2027")+SUMIFS(MultiYear_ProForma!$AF$2:$AF$66, MultiYear_ProForma!$B$2:$B$66, B14, MultiYear_ProForma!$C$2:$C$66, "FY2028")+SUMIFS(MultiYear_ProForma!$AF$2:$AF$66, MultiYear_ProForma!$B$2:$B$66, B14, MultiYear_ProForma!$C$2:$C$66, "FY2029")+SUMIFS(MultiYear_ProForma!$AF$2:$AF$66, MultiYear_ProForma!$B$2:$B$66, B14, MultiYear_ProForma!$C$2:$C$66, "FY2030"))/5 -> 172443.45 | H14: =SUMIFS(MultiYear_ProForma!$N$2:$N$66, MultiYear_ProForma!$B$2:$B$66, B14, MultiYear_ProForma!$C$2:$C$66, "FY2026") -> 257 | I14: =SUMIFS(MultiYear_ProForma!$AC$2:$AC$66, MultiYear_ProForma!$B$2:$B$66, B14, MultiYear_ProForma!$C$2:$C$66, "FY2030") -> 487.2 | J14: =F14-(VLOOKUP($C$1,$B$5:$G$17,5, 0)) -> 1133625.4 | K14: =G14-(VLOOKUP($C$1,$B$5:$I$17,6, 0)) -> 762630.04
A15: =LEFT(B15, 2) -> C2 | B15: C2_Repurpose_Pima_lease_EchoGHub_EchoTargets | C15: =SUMIFS(Capital_Summary!$H$4:$H$83, Capital_Summary!$A$4:$A$83, B15, Capital_Summary!$B$4:$B$83, "FY2026")*-1 -> -1600000 | D15: =SUMIFS(MultiYear_ProForma!$AF$2:$AF$66, MultiYear_ProForma!$B$2:$B$66, B15, MultiYear_ProForma!$C$2:$C$66, "FY2030") -> 775351.61 | E15: =SUMIFS(MultiYear_ProForma!$AF$2:$AF$66, MultiYear_ProForma!$B$2:$B$66, B15, MultiYear_ProForma!$C$2:$C$66, "FY2028") -> 574504.1 | F15: =SUMIFS(MultiYear_ProForma!$AF$2:$AF$66, MultiYear_ProForma!$B$2:$B$66, B15, MultiYear_ProForma!$C$2:$C$66, "FY2030") -> 775351.61 | G15: =(SUMIFS(MultiYear_ProForma!$AF$2:$AF$66, MultiYear_ProForma!$B$2:$B$66, B15, MultiYear_ProForma!$C$2:$C$66, "FY2026")+SUMIFS(MultiYear_ProForma!$AF$2:$AF$66, MultiYear_ProForma!$B$2:$B$66, B15, MultiYear_ProForma!$C$2:$C$66, "FY2027")+SUMIFS(MultiYear_ProForma!$AF$2:$AF$66, MultiYear_ProForma!$B$2:$B$66, B15, MultiYear_ProForma!$C$2:$C$66, "FY2028")+SUMIFS(MultiYear_ProForma!$AF$2:$AF$66, MultiYear_ProForma!$B$2:$B$66, B15, MultiYear_ProForma!$C$2:$C$66, "FY2029")+SUMIFS(MultiYear_ProForma!$AF$2:$AF$66, MultiYear_ProForma!$B$2:$B$66, B15, MultiYear_ProForma!$C$2:$C$66, "FY2030"))/5 -> 567383.24 | H15: =SUMIFS(MultiYear_ProForma!$N$2:$N$66, MultiYear_ProForma!$B$2:$B$66, B15, MultiYear_ProForma!$C$2:$C$66, "FY2026") -> 296 | I15: =SUMIFS(MultiYear_ProForma!$AC$2:$AC$66, MultiYear_ProForma!$B$2:$B$66, B15, MultiYear_ProForma!$C$2:$C$66, "FY2030") -> 508.6 | J15: =F15-(VLOOKUP($C$1,$B$5:$G$17,5, 0)) -> 1500131.5 | K15: =G15-(VLOOKUP($C$1,$B$5:$I$17,6, 0)) -> 1157569.8
A16: =LEFT(B16, 2) -> C1 | B16: C1_Repurpose_Pima_ops_EchoGHub_EchoTargets | C16: =SUMIFS(Capital_Summary!$H$4:$H$83, Capital_Summary!$A$4:$A$83, B16, Capital_Summary!$B$4:$B$83, "FY2026")*-1 -> -2000000 | D16: =SUMIFS(MultiYear_ProForma!$AF$2:$AF$66, MultiYear_ProForma!$B$2:$B$66, B16, MultiYear_ProForma!$C$2:$C$66, "FY2030") -> 979902.02 | E16: =SUMIFS(MultiYear_ProForma!$AF$2:$AF$66, MultiYear_ProForma!$B$2:$B$66, B16, MultiYear_ProForma!$C$2:$C$66, "FY2028") -> 766053.57 | F16: =SUMIFS(MultiYear_ProForma!$AF$2:$AF$66, MultiYear_ProForma!$B$2:$B$66, B16, MultiYear_ProForma!$C$2:$C$66, "FY2030") -> 979902.02 | G16: =(SUMIFS(MultiYear_ProForma!$AF$2:$AF$66, MultiYear_ProForma!$B$2:$B$66, B16, MultiYear_ProForma!$C$2:$C$66, "FY2026")+SUMIFS(MultiYear_ProForma!$AF$2:$AF$66, MultiYear_ProForma!$B$2:$B$66, B16, MultiYear_ProForma!$C$2:$C$66, "FY2027")+SUMIFS(MultiYear_ProForma!$AF$2:$AF$66, MultiYear_ProForma!$B$2:$B$66, B16, MultiYear_ProForma!$C$2:$C$66, "FY2028")+SUMIFS(MultiYear_ProForma!$AF$2:$AF$66, MultiYear_ProForma!$B$2:$B$66, B16, MultiYear_ProForma!$C$2:$C$66, "FY2029")+SUMIFS(MultiYear_ProForma!$AF$2:$AF$66, MultiYear_ProForma!$B$2:$B$66, B16, MultiYear_ProForma!$C$2:$C$66, "FY2030"))/5 -> 641758.89 | H16: =SUMIFS(MultiYear_ProForma!$N$2:$N$66, MultiYear_ProForma!$B$2:$B$66, B16, MultiYear_ProForma!$C$2:$C$66, "FY2026") -> 295.66667 | I16: =SUMIFS(MultiYear_ProForma!$AC$2:$AC$66, MultiYear_ProForma!$B$2:$B$66, B16, MultiYear_ProForma!$C$2:$C$66, "FY2030") -> 558.6 | J16: =F16-(VLOOKUP($C$1,$B$5:$G$17,5, 0)) -> 1704682 | K16: =G16-(VLOOKUP($C$1,$B$5:$I$17,6, 0)) -> 1231945.5
A17: =LEFT(B17, 2) -> E1 | B17: E1_StatusQuo_Decline | C17: =SUMIFS(Capital_Summary!$H$4:$H$83, Capital_Summary!$A$4:$A$83, B17, Capital_Summary!$B$4:$B$83, "FY2026")*-1 -> 0 | D17: =SUMIFS(MultiYear_ProForma!$AF$2:$AF$66, MultiYear_ProForma!$B$2:$B$66, B17, MultiYear_ProForma!$C$2:$C$66, "FY2030") -> -724779.94 | E17: =SUMIFS(MultiYear_ProForma!$AF$2:$AF$66, MultiYear_ProForma!$B$2:$B$66, B17, MultiYear_ProForma!$C$2:$C$66, "FY2028") -> -588315.82 | F17: =SUMIFS(MultiYear_ProForma!$AF$2:$AF$66, MultiYear_ProForma!$B$2:$B$66, B17, MultiYear_ProForma!$C$2:$C$66, "FY2030") -> -724779.94 | G17: =(SUMIFS(MultiYear_ProForma!$AF$2:$AF$66, MultiYear_ProForma!$B$2:$B$66, B17, MultiYear_ProForma!$C$2:$C$66, "FY2026")+SUMIFS(MultiYear_ProForma!$AF$2:$AF$66, MultiYear_ProForma!$B$2:$B$66, B17, MultiYear_ProForma!$C$2:$C$66, "FY2027")+SUMIFS(MultiYear_ProForma!$AF$2:$AF$66, MultiYear_ProForma!$B$2:$B$66, B17, MultiYear_ProForma!$C$2:$C$66, "FY2028")+SUMIFS(MultiYear_ProForma!$AF$2:$AF$66, MultiYear_ProForma!$B$2:$B$66, B17, MultiYear_ProForma!$C$2:$C$66, "FY2029")+SUMIFS(MultiYear_ProForma!$AF$2:$AF$66, MultiYear_ProForma!$B$2:$B$66, B17, MultiYear_ProForma!$C$2:$C$66, "FY2030"))/5 -> -590186.59 | H17: =SUMIFS(MultiYear_ProForma!$N$2:$N$66, MultiYear_ProForma!$B$2:$B$66, B17, MultiYear_ProForma!$C$2:$C$66, "FY2026") -> 0 | I17: =SUMIFS(MultiYear_ProForma!$AC$2:$AC$66, MultiYear_ProForma!$B$2:$B$66, B17, MultiYear_ProForma!$C$2:$C$66, "FY2030") -> 510.06959 | J17: =F17-(VLOOKUP($C$1,$B$5:$G$17,5, 0)) -> 0 | K17: =G17-(VLOOKUP($C$1,$B$5:$I$17,6, 0)) -> 0
B19: Note: Displaced = FY26; Served = FY30. Net = M&O − (Aid + Override + Uplift); showing one-time capital (fy26) as negative number for visualization purposes

Sheet Scenarios
A1: ScenarioKey | B1: Label | C1: Overlay | D1: CloseEcho | E1: ClosePima | F1: EchoShareDist | G1: ExtraSave | H1: Notes | I1: Overlay_FY26 | J1: Overlay_FY27 | K1: Overlay_FY28 | L1: Overlay_FY29 | M1: Overlay_FY30 | N1: Carry | O1: Growth_Echo | P1: Growth_Pima | Q1: Apply_Echo_Trend | R1: Apply_Pima_Trend
A2: F1_CUSTOM1 | B2: =Control_Center!B31 -> CUSTOM_KeepOpen_v1 | C2: =Control_Center!C31 -> 0 | D2: =Control_Center!D31 -> 0 | E2: =Control_Center!E31 -> 0 | F2: =Control_Center!F31 -> 0.5 | G2: =Control_Center!G31 -> 0 | H2: Baseline + outreach; no closures | I2: =C2/3 -> 0 | J2: =I2+C2/3 -> 0 | K2: =J2+C2/3 -> 0 | L2: =C2 -> 0 | M2: =C2 -> 0 | O2: None | P2: None | Q2: 0 | R2: 0
A3: E3_StatusQuo_Targets | B3: =Control_Center!B32 -> Echo & Pima open; uplift warm handoff effort (intra-SUSD); initiate cross-district marketing | C3: =Control_Center!C32 -> 75 | D3: =Control_Center!D32 -> 0 | E3: =Control_Center!E32 -> 0 | F3: =Control_Center!F32 -> 0.5 | G3: =Control_Center!G32 -> 0 | H3: Baseline + targets; no closures | I3: =C3/3 -> 25 | J3: =I3+C3/3 -> 50 | K3: =J3+C3/3 -> 75 | L3: =C3 -> 75 | M3: =C3 -> 75 | O3: None | P3: None | Q3: 0 | R3: 0
A4: D3_CoLocation_Echo_Targets | B4: =Control_Center!B33 -> Echo & Pima open; co-locate e.g. district teacher learning center at Echo; uplift warm handoff effort (intra-SUSD); initiate cross-district marketing | C4: =Control_Center!C33 -> 50 | D4: =Control_Center!D33 -> 0 | E4: =Control_Center!E33 -> 0 | F4: =Control_Center!F33 -> 0.5 | G4: =Control_Center!G33 -> 0.05 | H4: Shared‑use efficiencies later (no closure) | I4: =C4/3 -> 16.666667 | J4: =I4+C4/3 -> 33.333333 | K4: =J4+C4/3 -> 50 | L4: =C4 -> 50 | M4: =C4 -> 50 | O4: None | P4: None | Q4: 0 | R4: 0
A5: D1_Grow_Both_Targets | B5: =Control_Center!B34 -> Echo & Pima open; growth initiatives Echo (e.g. innovation) & Pima (e.g. arts); uplift warm handoff effort (intra-SUSD); initiate cross-district marketing | C5: =Control_Center!C34 -> 150 | D5: =Control_Center!D34 -> 0 | E5: =Control_Center!E34 -> 0 | F5: =Control_Center!F34 -> 0.5 | G5: =Control_Center!G34 -> 0 | H5: Baseline +100 overlay | I5: =C5/3 -> 50 | J5: =I5+C5/3 -> 100 | K5: =J5+C5/3 -> 150 | L5: =C5 -> 150 | M5: =C5 -> 150 | O5: Innov | P5: Arts | Q5: 0 | R5: 0
A6: E2_StatusQuo_Steady | B6: =Control_Center!B35 -> Echo & Pima open; no operational or strategic growth actions; no change in enrollment | C6: =Control_Center!C35 -> 0 | D6: =Control_Center!D35 -> 0 | E6: =Control_Center!E35 -> 0 | F6: =Control_Center!F35 -> 0.5 | G6: =Control_Center!G35 -> 0 | H6: Baseline +150 overlay | I6: =C6/3 -> 0 | J6: =I6+C6/3 -> 0 | K6: =J6+C6/3 -> 0 | L6: =C6 -> 0 | M6: =C6 -> 0 | O6: None | P6: None | Q6: 0 | R6: 0
A7: D2_EchoGHubRamp_PimaTargets | B7: =Control_Center!B36 -> Echo & Pima open; growth initiative Echo (e.g. innovation); no growth initiative Pima; uplift warm handoff effort (intra-SUSD); initiate cross-district marketing | C7: =Control_Center!C36 -> 125 | D7: =Control_Center!D36 -> 0 | E7: =Control_Center!E36 -> 0 | F7: =Control_Center!F36 -> 0.7 | G7: =Control_Center!G36 -> 0 | H7: Time‑phased ramp (+50,+100,+150 years 1–3) | I7: =C7/3 -> 41.666667 | J7: =I7+C7/3 -> 83.333333 | K7: =J7+C7/3 -> 125 | L7: =C7 -> 125 | M7: =C7 -> 125 | O7: Arts | P7: None | Q7: 0 | R7: 0
A8: A2_Repurpose_Both_lease | B8: =Control_Center!B37 -> Repurpose both Echo & Pima; lease both properties; fixed cost reduction rate, retention %, and transition cost assumptions are key drivers | C8: =Control_Center!C37 -> 0 | D8: =Control_Center!D37 -> 1 | E8: =Control_Center!E37 -> 1 | F8: =Control_Center!F37 -> 0.5 | G8: =Control_Center!G37 -> 0 | H8: Repurpose both; lease/sale glide | I8: =C8/3 -> 0 | J8: =I8+C8/3 -> 0 | K8: =J8+C8/3 -> 0 | L8: =C8 -> 0 | M8: =C8 -> 0 | N8: lease | O8: None | P8: None | Q8: 0 | R8: 0
A9: A1_Repurpose_Both_ops | B9: =Control_Center!B38 -> Repurpose both Echo & Pima; operationally convert both properties (e.g. early learning center); fixed cost reduction rate, retention %, and transition cost assumptions are key drivers | C9: =Control_Center!C38 -> 0 | D9: =Control_Center!D38 -> 1 | E9: =Control_Center!E38 -> 1 | F9: =Control_Center!F38 -> 0.5 | G9: =Control_Center!G38 -> 0 | H9: Repurpose both; operations carry | I9: =C9/3 -> 0 | J9: =I9+C9/3 -> 0 | K9: =J9+C9/3 -> 0 | L9: =C9 -> 0 | M9: =C9 -> 0 | N9: ops | O9: None | P9: None | Q9: 0 | R9: 0
A10: B2_Repurpose_Echo_lease_PimaTargets | B10: =Control_Center!B39 -> Repurpose ECHO (lease) + Status-Quo Pima + Pima Op Growth Targets | C10: =Control_Center!C39 -> 0 | D10: =Control_Center!D39 -> 1 | E10: =Control_Center!E39 -> 0 | F10: =Control_Center!F39 -> 0 | G10: =Control_Center!G39 -> 0 | H10: Repurpose Echo only; lease glide | I10: =C10/3 -> 0 | J10: =I10+C10/3 -> 0 | K10: =J10+C10/3 -> 0 | L10: =C10 -> 0 | M10: =C10 -> 0 | N10: lease | O10: None | P10: None | Q10: 0 | R10: 0
A11: B1_Repurpose_Echo_ops_PimaTargets | B11: =Control_Center!B40 -> Repurpose ECHO (ops) + Status-Quo Pima + Pima Op Growth Targets | C11: =Control_Center!C40 -> 37 | D11: =Control_Center!D40 -> 1 | E11: =Control_Center!E40 -> 0 | F11: =Control_Center!F40 -> 0 | G11: =Control_Center!G40 -> 0 | H11: Repurpose Echo only; ops carry | I11: =C11/3 -> 12.333333 | J11: =I11+C11/3 -> 24.666667 | K11: =J11+C11/3 -> 37 | L11: =C11 -> 37 | M11: =C11 -> 37 | N11: ops | O11: None | P11: None | Q11: 0 | R11: 0
A12: C2_Repurpose_Pima_lease_EchoGHub_EchoTargets | B12: =Control_Center!B41 -> Repurpose PIMA (lease) + Growth Hub @ Echo + Echo Op Growth Targets | C12: =Control_Center!C41 -> 0 | D12: =Control_Center!D41 -> 0 | E12: =Control_Center!E41 -> 1 | F12: =Control_Center!F41 -> 1 | G12: =Control_Center!G41 -> 0 | H12: Repurpose Pima only; lease glide | I12: =C12/3 -> 0 | J12: =I12+C12/3 -> 0 | K12: =J12+C12/3 -> 0 | L12: =C12 -> 0 | M12: =C12 -> 0 | N12: lease | O12: Arts | P12: None | Q12: 0 | R12: 0
A13: C1_Repurpose_Pima_ops_EchoGHub_EchoTargets | B13: =Control_Center!B42 -> Repurpose PIMA (ops) + Growth Hub @ Echo + Echo Op Growth Targets | C13: =Control_Center!C42 -> 50 | D13: =Control_Center!D42 -> 0 | E13: =Control_Center!E42 -> 1 | F13: =Control_Center!F42 -> 1 | G13: =Control_Center!G42 -> 0 | H13: Repurpose Pima only; ops carry | I13: =C13/3 -> 16.666667 | J13: =I13+C13/3 -> 33.333333 | K13: =J13+C13/3 -> 50 | L13: =C13 -> 50 | M13: =C13 -> 50 | N13: ops | O13: Arts | P13: None | Q13: 0 | R13: 0
A14: E1_StatusQuo_Decline | B14: Echo & Pima open; no operational or strategic growth actions; enrollment decline trend continues | C14: 0 | D14: 0 | E14: 0 | F14: 0 | G14: 0 | H14: Keep open but decline per district forecast | I14: =C14/3 -> 0 | J14: =I14+C14/3 -> 0 | K14: =J14+C14/3 -> 0 | L14: =C14 -> 0 | M14: =C14 -> 0 | O14: None | P14: None | Q14: 1 | R14: 1
A16: ScenarioKey | B16: Year | C16: Echo_ADM | D16: Pima_ADM | E16: Total_ADM | F16: VarUnit$ | G16: EchoFixed$ | H16: PimaFixed$ | I16: Key | O16: None | P16: None
A17: =A2 -> F1_CUSTOM1 | B17: FY2026 | C17: =IF(D2=1,0, BaselineCalc!$B$7 + ROUND(I2*F2,0)) -> 257 | D17: =IF(E2=1,0, BaselineCalc!$B$8 + I2 - ROUND(I2*F2,0)) -> 296 | E17: =C17+D17 -> 553 | F17: =YearMap!B2 -> 6414.5115 | G17: =YearMap!C2 -> 1404302.9 | H17: =YearMap!D2 -> 1617407.2 | I17: =A17&"|"&B17 -> F1_CUSTOM1|FY2026 | O17: None | P17: None
A18: =A2 -> F1_CUSTOM1 | B18: FY2027 | C18: =IF(D2=1,0, BaselineCalc!$B$7 + ROUND(J2*F2,0)) -> 257 | D18: =IF(E2=1,0, BaselineCalc!$B$8 + J2 - ROUND(J2*F2,0)) -> 296 | E18: =C18+D18 -> 553 | F18: =YearMap!B3 -> 6574.8743 | G18: =YearMap!C3 -> 1439410.4 | H18: =YearMap!D3 -> 1657842.4 | I18: =A18&"|"&B18 -> F1_CUSTOM1|FY2027 | O18: None | P18: None
A19: =A2 -> F1_CUSTOM1 | B19: FY2028 | C19: =IF(D2=1,0, BaselineCalc!$B$7 + ROUND(K2*F2,0)) -> 257 | D19: =IF(E2=1,0, BaselineCalc!$B$8 + K2 - ROUND(K2*F2,0)) -> 296 | E19: =C19+D19 -> 553 | F19: =YearMap!B4 -> 6739.2461 | G19: =YearMap!C4 -> 1475395.7 | H19: =YearMap!D4 -> 1699288.4 | I19: =A19&"|"&B19 -> F1_CUSTOM1|FY2028 | O19: None | P19: None
A20: =A2 -> F1_CUSTOM1 | B20: FY2029 | C20: =IF(D2=1,0, BaselineCalc!$B$7 + ROUND(L2*F2,0)) -> 257 | D20: =IF(E2=1,0, BaselineCalc!$B$8 + L2 - ROUND(L2*F2,0)) -> 296 | E20: =C20+D20 -> 553 | F20: =YearMap!B5 -> 6907.7273 | G20: =YearMap!C5 -> 1512280.6 | H20: =YearMap!D5 -> 1741770.6 | I20: =A20&"|"&B20 -> F1_CUSTOM1|FY2029 | O20: None | P20: None
A21: =A2 -> F1_CUSTOM1 | B21: FY2030 | C21: =IF(D2=1,0, BaselineCalc!$B$7 + ROUND(M2*F2,0)) -> 257 | D21: =IF(E2=1,0, BaselineCalc!$B$8 + M2 - ROUND(M2*F2,0)) -> 296 | E21: =C21+D21 -> 553 | F21: =YearMap!B6 -> 7080.4205 | G21: =YearMap!C6 -> 1550087.6 | H21: =YearMap!D6 -> 1785314.9 | I21: =A21&"|"&B21 -> F1_CUSTOM1|FY2030 | O21: None | P21: None
A22: =A3 -> E3_StatusQuo_Targets | B22: FY2026 | C22: =IF(D3=1,0, BaselineCalc!$B$7 + ROUND(I3*F3,0)) -> 270 | D22: =IF(E3=1,0, BaselineCalc!$B$8 + I3 - ROUND(I3*F3,0)) -> 308 | E22: =C22+D22 -> 578 | F22: =YearMap!B2 -> 6414.5115 | G22: =YearMap!C2 -> 1404302.9 | H22: =YearMap!D2 -> 1617407.2 | I22: =A22&"|"&B22 -> E3_StatusQuo_Targets|FY2026 | O22: None | P22: None
A23: =A3 -> E3_StatusQuo_Targets | B23: FY2027 | C23: =IF(D3=1,0, BaselineCalc!$B$7 + ROUND(J3*F3,0)) -> 282 | D23: =IF(E3=1,0, BaselineCalc!$B$8 + J3 - ROUND(J3*F3,0)) -> 321 | E23: =C23+D23 -> 603 | F23: =YearMap!B3 -> 6574.8743 | G23: =YearMap!C3 -> 1439410.4 | H23: =YearMap!D3 -> 1657842.4 | I23: =A23&"|"&B23 -> E3_StatusQuo_Targets|FY2027 | O23: None | P23: None
A24: =A3 -> E3_StatusQuo_Targets | B24: FY2028 | C24: =IF(D3=1,0, BaselineCalc!$B$7 + ROUND(K3*F3,0)) -> 295 | D24: =IF(E3=1,0, BaselineCalc!$B$8 + K3 - ROUND(K3*F3,0)) -> 333 | E24: =C24+D24 -> 628 | F24: =YearMap!B4 -> 6739.2461 | G24: =YearMap!C4 -> 1475395.7 | H24: =YearMap!D4 -> 1699288.4 | I24: =A24&"|"&B24 -> E3_StatusQuo_Targets|FY2028 | O24: None | P24: None
A25: =A3 -> E3_StatusQuo_Targets | B25: FY2029 | C25: =IF(D3=1,0, BaselineCalc!$B$7 + ROUND(L3*F3,0)) -> 295 | D25: =IF(E3=1,0, BaselineCalc!$B$8 + L3 - ROUND(L3*F3,0)) -> 333 | E25: =C25+D25 -> 628 | F25: =YearMap!B5 -> 6907.7273 | G25: =YearMap!C5 -> 1512280.6 | H25: =YearMap!D5 -> 1741770.6 | I25: =A25&"|"&B25 -> E3_StatusQuo_Targets|FY2029 | O25: None | P25: None
A26: =A3 -> E3_StatusQuo_Targets | B26: FY2030 | C26: =IF(D3=1,0, BaselineCalc!$B$7 + ROUND(M3*F3,0)) -> 295 | D26: =IF(E3=1,0, BaselineCalc!$B$8 + M3 - ROUND(M3*F3,0)) -> 333 | E26: =C26+D26 -> 628 | F26: =YearMap!B6 -> 7080.4205 | G26: =YearMap!C6 -> 1550087.6 | H26: =YearMap!D6 -> 1785314.9 | I26: =A26&"|"&B26 -> E3_StatusQuo_Targets|FY2030 | O26: None | P26: None
A27: =A4 -> D3_CoLocation_Echo_Targets | B27: FY2026 | C27: =IF(D4=1,0, BaselineCalc!$B$7 + ROUND(I4*F4,0)) -> 265 | D27: =IF(E4=1,0, BaselineCalc!$B$8 + I4 - ROUND(I4*F4,0)) -> 304.66667 | E27: =C27+D27 -> 569.66667 | F27: =YearMap!B2 -> 6414.5115 | G27: =YearMap!C2 -> 1404302.9 | H27: =YearMap!D2 -> 1617407.2 | I27: =A27&"|"&B27 -> D3_CoLocation_Echo_Targets|FY2026 | O27: None | P27: None
A28: =A4 -> D3_CoLocation_Echo_Targets | B28: FY2027 | C28: =IF(D4=1,0, BaselineCalc!$B$7 + ROUND(J4*F4,0)) -> 274 | D28: =IF(E4=1,0, BaselineCalc!$B$8 + J4 - ROUND(J4*F4,0)) -> 312.33333 | E28: =C28+D28 -> 586.33333 | F28: =YearMap!B3 -> 6574.8743 | G28: =YearMap!C3 -> 1439410.4 | H28: =YearMap!D3 -> 1657842.4 | I28: =A28&"|"&B28 -> D3_CoLocation_Echo_Targets|FY2027 | O28: None | P28: None
A29: =A4 -> D3_CoLocation_Echo_Targets | B29: FY2028 | C29: =IF(D4=1,0, BaselineCalc!$B$7 + ROUND(K4*F4,0)) -> 282 | D29: =IF(E4=1,0, BaselineCalc!$B$8 + K4 - ROUND(K4*F4,0)) -> 321 | E29: =C29+D29 -> 603 | F29: =YearMap!B4 -> 6739.2461 | G29: =YearMap!C4 -> 1475395.7 | H29: =YearMap!D4 -> 1699288.4 | I29: =A29&"|"&B29 -> D3_CoLocation_Echo_Targets|FY2028 | O29: None | P29: None
A30: =A4 -> D3_CoLocation_Echo_Targets | B30: FY2029 | C30: =IF(D4=1,0, BaselineCalc!$B$7 + ROUND(L4*F4,0)) -> 282 | D30: =IF(E4=1,0, BaselineCalc!$B$8 + L4 - ROUND(L4*F4,0)) -> 321 | E30: =C30+D30 -> 603 | F30: =YearMap!B5 -> 6907.7273 | G30: =YearMap!C5 -> 1512280.6 | H30: =YearMap!D5 -> 1741770.6 | I30: =A30&"|"&B30 -> D3_CoLocation_Echo_Targets|FY2029 | O30: None | P30: None
A31: =A4 -> D3_CoLocation_Echo_Targets | B31: FY2030 | C31: =IF(D4=1,0, BaselineCalc!$B$7 + ROUND(M4*F4,0)) -> 282 | D31: =IF(E4=1,0, BaselineCalc!$B$8 + M4 - ROUND(M4*F4,0)) -> 321 | E31: =C31+D31 -> 603 | F31: =YearMap!B6 -> 7080.4205 | G31: =YearMap!C6 -> 1550087.6 | H31: =YearMap!D6 -> 1785314.9 | I31: =A31&"|"&B31 -> D3_CoLocation_Echo_Targets|FY2030 | O31: None | P31: None
A32: =A5 -> D1_Grow_Both_Targets | B32: FY2026 | C32: =IF(D5=1,0, BaselineCalc!$B$7 + ROUND(I5*F5,0)) -> 282 | D32: =IF(E5=1,0, BaselineCalc!$B$8 + I5 - ROUND(I5*F5,0)) -> 321 | E32: =C32+D32 -> 603 | F32: =YearMap!B2 -> 6414.5115 | G32: =YearMap!C2 -> 1404302.9 | H32: =YearMap!D2 -> 1617407.2 | I32: =A32&"|"&B32 -> D1_Grow_Both_Targets|FY2026 | O32: None | P32: None
A33: =A5 -> D1_Grow_Both_Targets | B33: FY2027 | C33: =IF(D5=1,0, BaselineCalc!$B$7 + ROUND(J5*F5,0)) -> 307 | D33: =IF(E5=1,0, BaselineCalc!$B$8 + J5 - ROUND(J5*F5,0)) -> 346 | E33: =C33+D33 -> 653 | F33: =YearMap!B3 -> 6574.8743 | G33: =YearMap!C3 -> 1439410.4 | H33: =YearMap!D3 -> 1657842.4 | I33: =A33&"|"&B33 -> D1_Grow_Both_Targets|FY2027 | O33: None | P33: None
A34: =A5 -> D1_Grow_Both_Targets | B34: FY2028 | C34: =IF(D5=1,0, BaselineCalc!$B$7 + ROUND(K5*F5,0)) -> 332 | D34: =IF(E5=1,0, BaselineCalc!$B$8 + K5 - ROUND(K5*F5,0)) -> 371 | E34: =C34+D34 -> 703 | F34: =YearMap!B4 -> 6739.2461 | G34: =YearMap!C4 -> 1475395.7 | H34: =YearMap!D4 -> 1699288.4 | I34: =A34&"|"&B34 -> D1_Grow_Both_Targets|FY2028 | O34: None | P34: None
A35: =A5 -> D1_Grow_Both_Targets | B35: FY2029 | C35: =IF(D5=1,0, BaselineCalc!$B$7 + ROUND(L5*F5,0)) -> 332 | D35: =IF(E5=1,0, BaselineCalc!$B$8 + L5 - ROUND(L5*F5,0)) -> 371 | E35: =C35+D35 -> 703 | F35: =YearMap!B5 -> 6907.7273 | G35: =YearMap!C5 -> 1512280.6 | H35: =YearMap!D5 -> 1741770.6 | I35: =A35&"|"&B35 -> D1_Grow_Both_Targets|FY2029 | O35: None | P35: None
A36: =A5 -> D1_Grow_Both_Targets | B36: FY2030 | C36: =IF(D5=1,0, BaselineCalc!$B$7 + ROUND(M5*F5,0)) -> 332 | D36: =IF(E5=1,0, BaselineCalc!$B$8 + M5 - ROUND(M5*F5,0)) -> 371 | E36: =C36+D36 -> 703 | F36: =YearMap!B6 -> 7080.4205 | G36: =YearMap!C6 -> 1550087.6 | H36: =YearMap!D6 -> 1785314.9 | I36: =A36&"|"&B36 -> D1_Grow_Both_Targets|FY2030 | O36: None | P36: None
A37: =A6 -> E2_StatusQuo_Steady | B37: FY2026 | C37: =IF(D6=1,0, BaselineCalc!$B$7 + ROUND(I6*F6,0)) -> 257 | D37: =IF(E6=1,0, BaselineCalc!$B$8 + I6 - ROUND(I6*F6,0)) -> 296 | E37: =C37+D37 -> 553 | F37: =YearMap!B2 -> 6414.5115 | G37: =YearMap!C2 -> 1404302.9 | H37: =YearMap!D2 -> 1617407.2 | I37: =A37&"|"&B37 -> E2_StatusQuo_Steady|FY2026 | O37: None | P37: None
A38: =A6 -> E2_StatusQuo_Steady | B38: FY2027 | C38: =IF(D6=1,0, BaselineCalc!$B$7 + ROUND(J6*F6,0)) -> 257 | D38: =IF(E6=1,0, BaselineCalc!$B$8 + J6 - ROUND(J6*F6,0)) -> 296 | E38: =C38+D38 -> 553 | F38: =YearMap!B3 -> 6574.8743 | G38: =YearMap!C3 -> 1439410.4 | H38: =YearMap!D3 -> 1657842.4 | I38: =A38&"|"&B38 -> E2_StatusQuo_Steady|FY2027 | O38: None | P38: None
A39: =A6 -> E2_StatusQuo_Steady | B39: FY2028 | C39: =IF(D6=1,0, BaselineCalc!$B$7 + ROUND(K6*F6,0)) -> 257 | D39: =IF(E6=1,0, BaselineCalc!$B$8 + K6 - ROUND(K6*F6,0)) -> 296 | E39: =C39+D39 -> 553 | F39: =YearMap!B4 -> 6739.2461 | G39: =YearMap!C4 -> 1475395.7 | H39: =YearMap!D4 -> 1699288.4 | I39: =A39&"|"&B39 -> E2_StatusQuo_Steady|FY2028 | O39: None | P39: None
A40: =A6 -> E2_StatusQuo_Steady | B40: FY2029 | C40: =IF(D6=1,0, BaselineCalc!$B$7 + ROUND(L6*F6,0)) -> 257 | D40: =IF(E6=1,0, BaselineCalc!$B$8 + L6 - ROUND(L6*F6,0)) -> 296 | E40: =C40+D40 -> 553 | F40: =YearMap!B5 -> 6907.7273 | G40: =YearMap!C5 -> 1512280.6 | H40: =YearMap!D5 -> 1741770.6 | I40: =A40&"|"&B40 -> E2_StatusQuo_Steady|FY2029 | O40: None | P40: None
A41: =A6 -> E2_StatusQuo_Steady | B41: FY2030 | C41: =IF(D6=1,0, BaselineCalc!$B$7 + ROUND(M6*F6,0)) -> 257 | D41: =IF(E6=1,0, BaselineCalc!$B$8 + M6 - ROUND(M6*F6,0)) -> 296 | E41: =C41+D41 -> 553 | F41: =YearMap!B6 -> 7080.4205 | G41: =YearMap!C6 -> 1550087.6 | H41: =YearMap!D6 -> 1785314.9 | I41: =A41&"|"&B41 -> E2_StatusQuo_Steady|FY2030 | O41: None | P41: None
...

Sheet MultiYear_ProForma
A1: =AG1 -> Key | B1: ScenarioKey | C1: Year | D1: Echo_ADM | E1: Pima_ADM | F1: Total_ADM | G1: VarUnit$ | H1: EchoFixed$ | I1: PimaFixed$ | J1: OpsFactor | K1: ExtraSave | L1: EchoPotential_ADM | M1: PimaPotential_ADM | N1: Displaced_ADM | O1: Retained_ADM | P1: h | Q1: CarryFrac | R1: EchoFixedEff$ | S1: PimaFixedEff$ | T1: TI_adds$ | U1: SiteCost$ | V1: RetainedSvc$ | W1: Comparable_MO$ | X1: Comparable_per_Student$ | Y1: Aid_per_ADM | Z1: Net_MO_after_aid$ | AA1: Net_per_served$ | AB1: Overlay_ADM | AC1: Served_ADM | AD1: Revenue$ | AE1: Adj_MO$ | AF1: Net$ | AG1: Key
A2: =AG2 -> F1_CUSTOM1|FY2026 | B2: =Scenarios!A2 -> F1_CUSTOM1 | C2: FY2026 | D2: =IF(Scenarios!D2=1,0, L2) -> 257 | E2: =IF(Scenarios!E2=1,0, M2) -> 296 | F2: =D2+E2 -> 553 | G2: =YearMap!B2 -> 6414.5115 | H2: =YearMap!C2 -> 1404302.9 | I2: =YearMap!D2 -> 1617407.2 | J2: =1-BaselineCalc!$B$5 -> 0.993 | K2: =Scenarios!G2 -> 0 | L2: =IF(Scenarios!$Q2=1,BaselineCalc!$B$7*(1+Parameters_Public!$C44)^(IF($C2="FY2026",0,IF($C2="FY2027",1,IF($C2="FY2028",2,IF($C2="FY2029",3,IF($C2="FY2030",4,0))))))+ROUND(Scenarios!I2*Scenarios!$F2,0),BaselineCalc!$B$7+ROUND(Scenarios!I2*Scenarios!$F2,0)) -> 257 | M2: =IF(Scenarios!$R2=1,BaselineCalc!$B$8*(1+Parameters_Public!$C45)^(IF($C2="FY2026",0,IF($C2="FY2027",1,IF($C2="FY2028",2,IF($C2="FY2029",3,IF($C2="FY2030",4,0))))))+Scenarios!I2-ROUND(Scenarios!I2*Scenarios!$F2,0),BaselineCalc!$B$8+Scenarios!I2-ROUND(Scenarios!I2*Scenarios!$F2,0)) -> 296 | N2: =(L2-D2) + (M2-E2) -> 0 | O2: =(Parameters_Public!$C$23*(L2-D2)+Parameters_Public!$C$24*(M2-E2)) -> 0 | P2: =YearMap!E2 -> 1000 | Q2: =IF(Scenarios!N2="lease", YearMap!F2, YearMap!G2) -> 0.45 | R2: =IF(Scenarios!D2=1, Q2*H2, H2) -> 1404302.9 | S2: =IF(Scenarios!E2=1, Q2*I2, I2) -> 1617407.2 | T2: =IF(C2="FY2026", (Scenarios!D2+Scenarios!E2)*BaselineCalc!$B$22, 0) -> 0 | U2: =(R2+S2+G2*F2)*J2*(1-K2) -> 6522952.4 | V2: =O2*(G2+P2) -> 0 | W2: =U2+V2+IF(Parameters_Public!$C$26=1, T2, 0) -> 6522952.4 | X2: =IF(F2+O2>0, W2/(F2+O2),"") -> 11795.574 | Y2: =INDEX(YearMap!$I$2:$I$6, MATCH(C2, YearMap!$A$2:$A$6, 0)) -> 5013 | Z2: =W2 - ((Y2 + IF(Parameters_Public!$C$20=1, Parameters_Public!$C$19, 0))*AC2) -> 3334935 | AA2: =IF($AC2>0, $Z2/$AC2, 0) -> 6030.6239 | AB2: =MAX(0, (MAX(0, $D2-BaselineCalc!$B$7) + MAX(0, $E2-BaselineCalc!$B$8))) -> 0 | AC2: =L2+M2-N2+O2 -> 553 | AD2: =( (Y2 + IF(Parameters_Public!$C20=1, INDEX(YearMap!$O$2:$O$6, MATCH(C2, YearMap!$A$2:$A$6, 0)), 0)) * AC2 ) + AC2*INDEX(YearMap!$P$2:$P$6, MATCH(C2, YearMap!$A$2:$A$6, 0)) + AB2*( INDEX(YearMap!$R$2:$R$6, MATCH(C2, YearMap!$A$2:$A$6, 0)) - INDEX(YearMap!$P$2:$P$6, MATCH(C2, YearMap!$A$2:$A$6, 0)) ) -> 6063617.3 | AE2: =(W2 - (1-Parameters_Public!$C42)*$G2*$AB2*$J2*(1-$K2)) + AB2*INDEX(YearMap!$Q$2:$Q$6, MATCH(C2, YearMap!$A$2:$A$6, 0)) -> 6522952.4 | AF2: =AD2-AE2 -> -459335.03 | AG2: =B2&"|"&C2 -> F1_CUSTOM1|FY2026
A3: =AG3 -> F1_CUSTOM1|FY2027 | B3: =Scenarios!A2 -> F1_CUSTOM1 | C3: FY2027 | D3: =IF(Scenarios!D2=1,0, L3) -> 257 | E3: =IF(Scenarios!E2=1,0, M3) -> 296 | F3: =D3+E3 -> 553 | G3: =YearMap!B3 -> 6574.8743 | H3: =YearMap!C3 -> 1439410.4 | I3: =YearMap!D3 -> 1657842.4 | J3: =1-BaselineCalc!$B$5 -> 0.993 | K3: =Scenarios!G2 -> 0 | L3: =IF(Scenarios!$Q2=1,BaselineCalc!$B$7*(1+Parameters_Public!$C44)^(IF($C3="FY2026",0,IF($C3="FY2027",1,IF($C3="FY2028",2,IF($C3="FY2029",3,IF($C3="FY2030",4,0))))))+ROUND(Scenarios!J2*Scenarios!$F2,0),BaselineCalc!$B$7+ROUND(Scenarios!J2*Scenarios!$F2,0)) -> 257 | M3: =IF(Scenarios!$R2=1,BaselineCalc!$B$8*(1+Parameters_Public!$C45)^(IF($C3="FY2026",0,IF($C3="FY2027",1,IF($C3="FY2028",2,IF($C3="FY2029",3,IF($C3="FY2030",4,0))))))+Scenarios!J2-ROUND(Scenarios!J2*Scenarios!$F2,0),BaselineCalc!$B$8+Scenarios!J2-ROUND(Scenarios!J2*Scenarios!$F2,0)) -> 296 | N3: =(L3-D3) + (M3-E3) -> 0 | O3: =(Parameters_Public!$C$23*(L3-D3)+Parameters_Public!$C$24*(M3-E3)) -> 0 | P3: =YearMap!E3 -> 800 | Q3: =IF(Scenarios!N2="lease", YearMap!F3, YearMap!G3) -> 0.4 | R3: =IF(Scenarios!D2=1, Q3*H3, H3) -> 1439410.4 | S3: =IF(Scenarios!E2=1, Q3*I3, I3) -> 1657842.4 | T3: =IF(C3="FY2026", (Scenarios!D2+Scenarios!E2)*BaselineCalc!$B$22, 0) -> 0 | U3: =(R3+S3+G3*F3)*J3*(1-K3) -> 6686026.2 | V3: =O3*(G3+P3) -> 0 | W3: =U3+V3+IF(Parameters_Public!$C$26=1, T3, 0) -> 6686026.2 | X3: =IF(F3+O3>0, W3/(F3+O3),"") -> 12090.463 | Y3: =INDEX(YearMap!$I$2:$I$6, MATCH(C3, YearMap!$A$2:$A$6, 0)) -> 5138.325 | Z3: =W3 - ((Y3 + IF(Parameters_Public!$C$20=1, Parameters_Public!$C$19, 0))*AC3) -> 3428704.1 | AA3: =IF($AC3>0, $Z3/$AC3, 0) -> 6200.1883 | AB3: =MAX(0, (MAX(0, $D3-BaselineCalc!$B$7) + MAX(0, $E3-BaselineCalc!$B$8))) -> 0 | AC3: =L3+M3-N3+O3 -> 553 | AD3: =( (Y3 + IF(Parameters_Public!$C20=1, INDEX(YearMap!$O$2:$O$6, MATCH(C3, YearMap!$A$2:$A$6, 0)), 0)) * AC3 ) + AC3*INDEX(YearMap!$P$2:$P$6, MATCH(C3, YearMap!$A$2:$A$6, 0)) + AB3*( INDEX(YearMap!$R$2:$R$6, MATCH(C3, YearMap!$A$2:$A$6, 0)) - INDEX(YearMap!$P$2:$P$6, MATCH(C3, YearMap!$A$2:$A$6, 0)) ) -> 6215207.8 | AE3: =(W3 - (1-Parameters_Public!$C42)*$G3*$AB3*$J3*(1-$K3)) + AB3*INDEX(YearMap!$Q$2:$Q$6, MATCH(C3, YearMap!$A$2:$A$6, 0)) -> 6686026.2 | AF3: =AD3-AE3 -> -470818.41 | AG3: =B3&"|"&C3 -> F1_CUSTOM1|FY2027
